Workbook

Sheet README
A1: PLANNED STUDY / SIMULATED PLANNING DATA: the Excel route of Workshop 9 (study design, consent, and the IRB)
A2: Built by make_excel_workbook.py from the CSV files that plan_power.R wrote (seed 20270208). No real person was recorded; ALTAVO and BRENLOW are invented brands; participant codes (P01, R01) and staff codes (S1 to S6) are placeholders. Dates are placeholders.
A3: The follow up study: 12 ads (6 per brand), every participant sees every ad in a Williams order, one participant at a time at the single Smart Eye Aurora seat; 48 participants analyzed.
A5: Sheets
A6: SampleSize A. sample size of a paired comparison (normal approximation with the small sample correction), with and without a Holm family of three; B. approximate power of the brand test when ads are a random factor
A7: Attrition sessions to book from the Workshop 7 exclusion rate; reserve, cap, days; the remote comparison from Workshop 6
A8: LatinSquare the Williams design for 12 ads (MOD formulas), the ad labels, and the balance checks
A9: Assignment the Latin square row of each participant code (drawn in R with a fixed seed) and the block check
A10: Calendar one row per session slot: WORKDAY dates, slot times, codes, rows, and the staff pair
A11: Check every Excel result next to the value plan_power.R produced, with OK or CHECK
A13: Colors: blue headers = column names; yellow cells are typed by you (inputs); gray cells are values copied from R for comparison.
A14: The walkthrough excel_walkthrough.md explains every formula with its cell address.

Sheet SampleSize
A1: A. Sample size of a paired comparison (each participant gives one score in each condition)
A2: Normal approximation n = ((z_alpha + z_power) / d_z)^2, plus z_alpha^2 / 2 as the small sample correction; power at n from the same formula solved for the power. Compare with R's power.t.test on the Check sheet.
A4: Alpha (two tailed) | B4: 0.05
A5: Power target | B5: 0.8
A6: Tests in the Holm family | B6: 3
A7: Participants for the power columns | B7: 48
A9: z for alpha (two tailed) | B9: =_xlfn.NORM.S.INV(1-B4/2)
A10: z at the strictest Holm step | B10: =_xlfn.NORM.S.INV(1-B4/B6/2)
A11: z for the power target | B11: =_xlfn.NORM.S.INV(B5)
A13: Effect | B13: d_z | C13: n, normal approximation | D13: n, with the small sample correction | E13: n needed (round up) | F13: Holm: n, normal | G13: Holm: n, corrected | H13: Holm: n needed | I13: Power at B7 (approximate) | J13: Holm: power at B7 (approximate)
A14: small (0.30) | B14: 0.3 | C14: =(($B$9+$B$11)/B14)^2 | D14: =C14+$B$9^2/2 | E14: =ROUNDUP(D14,0) | F14: =(($B$10+$B$11)/B14)^2 | G14: =F14+$B$10^2/2 | H14: =ROUNDUP(G14,0) | I14: =_xlfn.NORM.S.DIST(B14*SQRT($B$7-$B$9^2/2)-$B$9,TRUE) | J14: =_xlfn.NORM.S.DIST(B14*SQRT($B$7-$B$10^2/2)-$B$10,TRUE)
A15: moderate (0.50) | B15: 0.5 | C15: =(($B$9+$B$11)/B15)^2 | D15: =C15+$B$9^2/2 | E15: =ROUNDUP(D15,0) | F15: =(($B$10+$B$11)/B15)^2 | G15: =F15+$B$10^2/2 | H15: =ROUNDUP(G15,0) | I15: =_xlfn.NORM.S.DIST(B15*SQRT($B$7-$B$9^2/2)-$B$9,TRUE) | J15: =_xlfn.NORM.S.DIST(B15*SQRT($B$7-$B$10^2/2)-$B$10,TRUE)
A16: Workshop 8 liking estimate (Q6) | B16: 0.35543902 | C16: =(($B$9+$B$11)/B16)^2 | D16: =C16+$B$9^2/2 | E16: =ROUNDUP(D16,0) | F16: =(($B$10+$B$11)/B16)^2 | G16: =F16+$B$10^2/2 | H16: =ROUNDUP(G16,0) | I16: =_xlfn.NORM.S.DIST(B16*SQRT($B$7-$B$9^2/2)-$B$9,TRUE) | J16: =_xlfn.NORM.S.DIST(B16*SQRT($B$7-$B$10^2/2)-$B$10,TRUE)
A17: Workshop 7 GSR estimate (H3, Ad_A) | B17: 0.82599164 | C17: =(($B$9+$B$11)/B17)^2 | D17: =C17+$B$9^2/2 | E17: =ROUNDUP(D17,0) | F17: =(($B$10+$B$11)/B17)^2 | G17: =F17+$B$10^2/2 | H17: =ROUNDUP(G17,0) | I17: =_xlfn.NORM.S.DIST(B17*SQRT($B$7-$B$9^2/2)-$B$9,TRUE) | J17: =_xlfn.NORM.S.DIST(B17*SQRT($B$7-$B$10^2/2)-$B$10,TRUE)
A20: B. The brand test when ads are a random factor: approximate power (balanced design, every participant rates every ad)
A21: Brand difference to detect (scale points) | B21: 0.5
A22: SD of the ads within a brand (judgment) | B22: 0.2
A23: Residual SD of liking (Workshop 7) | B23: 1.085
A25: Participants | B25: Ads per brand | C25: df = 2 x ads - 2 | D25: SE of the brand difference | E25: Noncentrality | F25: Critical t | G25: Approximate power
A26: 48 | B26: 2 | C26: =2*B26-2 | D26: =SQRT(2*($B$22^2+$B$23^2/A26)/B26) | E26: =$B$21/D26 | F26: =_xlfn.T.INV.2T($B$4,C26) | G26: =1-_xlfn.NORM.S.DIST((F26*(1-1/(4*C26))-E26)/SQRT(1+F26^2/(2*C26)),TRUE)
A27: 48 | B27: 3 | C27: =2*B27-2 | D27: =SQRT(2*($B$22^2+$B$23^2/A27)/B27) | E27: =$B$21/D27 | F27: =_xlfn.T.INV.2T($B$4,C27) | G27: =1-_xlfn.NORM.S.DIST((F27*(1-1/(4*C27))-E27)/SQRT(1+F27^2/(2*C27)),TRUE)
A28: 48 | B28: 4 | C28: =2*B28-2 | D28: =SQRT(2*($B$22^2+$B$23^2/A28)/B28) | E28: =$B$21/D28 | F28: =_xlfn.T.INV.2T($B$4,C28) | G28: =1-_xlfn.NORM.S.DIST((F28*(1-1/(4*C28))-E28)/SQRT(1+F28^2/(2*C28)),TRUE)
A29: 48 | B29: 6 | C29: =2*B29-2 | D29: =SQRT(2*($B$22^2+$B$23^2/A29)/B29) | E29: =$B$21/D29 | F29: =_xlfn.T.INV.2T($B$4,C29) | G29: =1-_xlfn.NORM.S.DIST((F29*(1-1/(4*C29))-E29)/SQRT(1+F29^2/(2*C29)),TRUE)
A30: 72 | B30: 2 | C30: =2*B30-2 | D30: =SQRT(2*($B$22^2+$B$23^2/A30)/B30) | E30: =$B$21/D30 | F30: =_xlfn.T.INV.2T($B$4,C30) | G30: =1-_xlfn.NORM.S.DIST((F30*(1-1/(4*C30))-E30)/SQRT(1+F30^2/(2*C30)),TRUE)
A31: 72 | B31: 3 | C31: =2*B31-2 | D31: =SQRT(2*($B$22^2+$B$23^2/A31)/B31) | E31: =$B$21/D31 | F31: =_xlfn.T.INV.2T($B$4,C31) | G31: =1-_xlfn.NORM.S.DIST((F31*(1-1/(4*C31))-E31)/SQRT(1+F31^2/(2*C31)),TRUE)
A32: 72 | B32: 4 | C32: =2*B32-2 | D32: =SQRT(2*($B$22^2+$B$23^2/A32)/B32) | E32: =$B$21/D32 | F32: =_xlfn.T.INV.2T($B$4,C32) | G32: =1-_xlfn.NORM.S.DIST((F32*(1-1/(4*C32))-E32)/SQRT(1+F32^2/(2*C32)),TRUE)
A33: 72 | B33: 6 | C33: =2*B33-2 | D33: =SQRT(2*($B$22^2+$B$23^2/A33)/B33) | E33: =$B$21/D33 | F33: =_xlfn.T.INV.2T($B$4,C33) | G33: =1-_xlfn.NORM.S.DIST((F33*(1-1/(4*C33))-E33)/SQRT(1+F33^2/(2*C33)),TRUE)
A35: The power uses a normal approximation to the noncentral t distribution (Abramowitz and Stegun, 1964, chapter 26); R computes it exactly with pt(..., ncp). Read down column G: going from 48 to 72 participants changes little; going from 3 to 6 ads per brand changes a lot.

Sheet Attrition
A1: Sessions to book, reserve, cap, and the remote comparison
A4: Participants to analyze (target) | B4: 48
A5: Workshop 7: participants excluded by rule R2 | B5: 2
A6: Workshop 7: participants recorded | B6: 24
A7: Rows of the Williams design (block size) | B7: 12
A8: Cap as a multiple of the target | B8: 1.25
A9: Workshop 6: sessions that opened the link | B9: 260
A10: Workshop 6: completed | B10: 178
A11: Workshop 6: kept after the exclusion rule | B11: 142
A12: Session slots per day (one Aurora seat) | B12: 5
A14: Results
A15: Exclusion rate in the lab (Workshop 7) | B15: =B5/B6
A16: Sessions expected to end with the target | B16: =B4/(1-B15)
A17: Sessions to book (main + reserve) | B17: =ROUNDUP(B16,0)
A18: Reserve sessions | B18: =B17-B4
A19: Hard cap on sessions | B19: =B4*B8
A20: Weekdays of data collection | B20: =ROUNDUP(B17/B12,0)
A21: Slots on those days | B21: =B20*B12
A22: Open slots for rebooking no shows | B22: =B21-B17
A24: If the same study were run remotely (Workshop 6 rates)
A25: Remote: completed share of those who opened the link | B25: =B10/B9
A26: Remote: share of completed respondents excluded | B26: =(B10-B11)/B10
A27: Remote: kept share of those who opened the link | B27: =B11/B9
A28: Remote: people who must open the link to keep the target | B28: =ROUNDUP(B4/B27,0)

Sheet LatinSquare
A1: Williams design for 12 ads: row 1 = 0, 1, 11, 2, 10, 3, ...; row r adds r - 1 (mod 12). Labels: even symbols ALTAVO, odd symbols BRENLOW.
A3: Number of ads (t) | B3: 12 | C3: Fixed at 12 for this layout (the chosen design). The construction works for any even t.
B5: Position | C5: 1 | D5: 2 | E5: 3 | F5: 4 | G5: 5 | H5: 6 | I5: 7 | J5: 8 | K5: 9 | L5: 10 | M5: 11 | N5: 12
B6: Row 1 (symbols) | C6: =IF(C$5=1,0,IF(MOD(C$5,2)=0,C$5/2,$B$3-(C$5-1)/2)) | D6: =IF(D$5=1,0,IF(MOD(D$5,2)=0,D$5/2,$B$3-(D$5-1)/2)) | E6: =IF(E$5=1,0,IF(MOD(E$5,2)=0,E$5/2,$B$3-(E$5-1)/2)) | F6: =IF(F$5=1,0,IF(MOD(F$5,2)=0,F$5/2,$B$3-(F$5-1)/2)) | G6: =IF(G$5=1,0,IF(MOD(G$5,2)=0,G$5/2,$B$3-(G$5-1)/2)) | H6: =IF(H$5=1,0,IF(MOD(H$5,2)=0,H$5/2,$B$3-(H$5-1)/2)) | I6: =IF(I$5=1,0,IF(MOD(I$5,2)=0,I$5/2,$B$3-(I$5-1)/2)) | J6: =IF(J$5=1,0,IF(MOD(J$5,2)=0,J$5/2,$B$3-(J$5-1)/2)) | ... N6: =IF(N$5=1,0,IF(MOD(N$5,2)=0,N$5/2,$B$3-(N$5-1)/2))
A8: Symbols | B8: 1 | C8: =MOD(C$6+$B8-1,$B$3) | D8: =MOD(D$6+$B8-1,$B$3) | E8: =MOD(E$6+$B8-1,$B$3) | F8: =MOD(F$6+$B8-1,$B$3) | G8: =MOD(G$6+$B8-1,$B$3) | H8: =MOD(H$6+$B8-1,$B$3) | I8: =MOD(I$6+$B8-1,$B$3) | J8: =MOD(J$6+$B8-1,$B$3) | ... N8: =MOD(N$6+$B8-1,$B$3)
B9: 2 | C9: =MOD(C$6+$B9-1,$B$3) | D9: =MOD(D$6+$B9-1,$B$3) | E9: =MOD(E$6+$B9-1,$B$3) | F9: =MOD(F$6+$B9-1,$B$3) | G9: =MOD(G$6+$B9-1,$B$3) | H9: =MOD(H$6+$B9-1,$B$3) | I9: =MOD(I$6+$B9-1,$B$3) | J9: =MOD(J$6+$B9-1,$B$3) | ... N9: =MOD(N$6+$B9-1,$B$3)
B10: 3 | C10: =MOD(C$6+$B10-1,$B$3) | D10: =MOD(D$6+$B10-1,$B$3) | E10: =MOD(E$6+$B10-1,$B$3) | F10: =MOD(F$6+$B10-1,$B$3) | G10: =MOD(G$6+$B10-1,$B$3) | H10: =MOD(H$6+$B10-1,$B$3) | I10: =MOD(I$6+$B10-1,$B$3) | J10: =MOD(J$6+$B10-1,$B$3) | ... N10: =MOD(N$6+$B10-1,$B$3)
B11: 4 | C11: =MOD(C$6+$B11-1,$B$3) | D11: =MOD(D$6+$B11-1,$B$3) | E11: =MOD(E$6+$B11-1,$B$3) | F11: =MOD(F$6+$B11-1,$B$3) | G11: =MOD(G$6+$B11-1,$B$3) | H11: =MOD(H$6+$B11-1,$B$3) | I11: =MOD(I$6+$B11-1,$B$3) | J11: =MOD(J$6+$B11-1,$B$3) | ... N11: =MOD(N$6+$B11-1,$B$3)
B12: 5 | C12: =MOD(C$6+$B12-1,$B$3) | D12: =MOD(D$6+$B12-1,$B$3) | E12: =MOD(E$6+$B12-1,$B$3) | F12: =MOD(F$6+$B12-1,$B$3) | G12: =MOD(G$6+$B12-1,$B$3) | H12: =MOD(H$6+$B12-1,$B$3) | I12: =MOD(I$6+$B12-1,$B$3) | J12: =MOD(J$6+$B12-1,$B$3) | ... N12: =MOD(N$6+$B12-1,$B$3)
B13: 6 | C13: =MOD(C$6+$B13-1,$B$3) | D13: =MOD(D$6+$B13-1,$B$3) | E13: =MOD(E$6+$B13-1,$B$3) | F13: =MOD(F$6+$B13-1,$B$3) | G13: =MOD(G$6+$B13-1,$B$3) | H13: =MOD(H$6+$B13-1,$B$3) | I13: =MOD(I$6+$B13-1,$B$3) | J13: =MOD(J$6+$B13-1,$B$3) | ... N13: =MOD(N$6+$B13-1,$B$3)
B14: 7 | C14: =MOD(C$6+$B14-1,$B$3) | D14: =MOD(D$6+$B14-1,$B$3) | E14: =MOD(E$6+$B14-1,$B$3) | F14: =MOD(F$6+$B14-1,$B$3) | G14: =MOD(G$6+$B14-1,$B$3) | H14: =MOD(H$6+$B14-1,$B$3) | I14: =MOD(I$6+$B14-1,$B$3) | J14: =MOD(J$6+$B14-1,$B$3) | ... N14: =MOD(N$6+$B14-1,$B$3)
B15: 8 | C15: =MOD(C$6+$B15-1,$B$3) | D15: =MOD(D$6+$B15-1,$B$3) | E15: =MOD(E$6+$B15-1,$B$3) | F15: =MOD(F$6+$B15-1,$B$3) | G15: =MOD(G$6+$B15-1,$B$3) | H15: =MOD(H$6+$B15-1,$B$3) | I15: =MOD(I$6+$B15-1,$B$3) | J15: =MOD(J$6+$B15-1,$B$3) | ... N15: =MOD(N$6+$B15-1,$B$3)
B16: 9 | C16: =MOD(C$6+$B16-1,$B$3) | D16: =MOD(D$6+$B16-1,$B$3) | E16: =MOD(E$6+$B16-1,$B$3) | F16: =MOD(F$6+$B16-1,$B$3) | G16: =MOD(G$6+$B16-1,$B$3) | H16: =MOD(H$6+$B16-1,$B$3) | I16: =MOD(I$6+$B16-1,$B$3) | J16: =MOD(J$6+$B16-1,$B$3) | ... N16: =MOD(N$6+$B16-1,$B$3)
B17: 10 | C17: =MOD(C$6+$B17-1,$B$3) | D17: =MOD(D$6+$B17-1,$B$3) | E17: =MOD(E$6+$B17-1,$B$3) | F17: =MOD(F$6+$B17-1,$B$3) | G17: =MOD(G$6+$B17-1,$B$3) | H17: =MOD(H$6+$B17-1,$B$3) | I17: =MOD(I$6+$B17-1,$B$3) | J17: =MOD(J$6+$B17-1,$B$3) | ... N17: =MOD(N$6+$B17-1,$B$3)
B18: 11 | C18: =MOD(C$6+$B18-1,$B$3) | D18: =MOD(D$6+$B18-1,$B$3) | E18: =MOD(E$6+$B18-1,$B$3) | F18: =MOD(F$6+$B18-1,$B$3) | G18: =MOD(G$6+$B18-1,$B$3) | H18: =MOD(H$6+$B18-1,$B$3) | I18: =MOD(I$6+$B18-1,$B$3) | J18: =MOD(J$6+$B18-1,$B$3) | ... N18: =MOD(N$6+$B18-1,$B$3)
B19: 12 | C19: =MOD(C$6+$B19-1,$B$3) | D19: =MOD(D$6+$B19-1,$B$3) | E19: =MOD(E$6+$B19-1,$B$3) | F19: =MOD(F$6+$B19-1,$B$3) | G19: =MOD(G$6+$B19-1,$B$3) | H19: =MOD(H$6+$B19-1,$B$3) | I19: =MOD(I$6+$B19-1,$B$3) | J19: =MOD(J$6+$B19-1,$B$3) | ... N19: =MOD(N$6+$B19-1,$B$3)
O21: Brand sequence
A22: Ad labels | B22: 1 | C22: =IF(MOD(C8,2)=0,"ALTAVO_"&(C8/2+1),"BRENLOW_"&((C8+1)/2)) | D22: =IF(MOD(D8,2)=0,"ALTAVO_"&(D8/2+1),"BRENLOW_"&((D8+1)/2)) | E22: =IF(MOD(E8,2)=0,"ALTAVO_"&(E8/2+1),"BRENLOW_"&((E8+1)/2)) | F22: =IF(MOD(F8,2)=0,"ALTAVO_"&(F8/2+1),"BRENLOW_"&((F8+1)/2)) | G22: =IF(MOD(G8,2)=0,"ALTAVO_"&(G8/2+1),"BRENLOW_"&((G8+1)/2)) | H22: =IF(MOD(H8,2)=0,"ALTAVO_"&(H8/2+1),"BRENLOW_"&((H8+1)/2)) | I22: =IF(MOD(I8,2)=0,"ALTAVO_"&(I8/2+1),"BRENLOW_"&((I8+1)/2)) | J22: =IF(MOD(J8,2)=0,"ALTAVO_"&(J8/2+1),"BRENLOW_"&((J8+1)/2)) | ... N22: =IF(MOD(N8,2)=0,"ALTAVO_"&(N8/2+1),"BRENLOW_"&((N8+1)/2)) | O22: =IF(MOD(C8,2)=0,"A","B")&IF(MOD(D8,2)=0,"A","B")&IF(MOD(E8,2)=0,"A","B")&IF(MOD(F8,2)=0,"A","B")&IF(MOD(G8,2)=0,"A","B")&IF(MOD(H8,2)=0,"A","B")&IF(MOD(I8,2)=0,"A","B")&IF(MOD(J8,2)=0,"A","B")&IF(MOD(K8,2)=0,"A","B")&IF(MOD(L8,2)=0,"A","B")&IF(MOD(M8,2)=0,"A","B")&IF(MOD(N8,2)=0,"A","B")
B23: 2 | C23: =IF(MOD(C9,2)=0,"ALTAVO_"&(C9/2+1),"BRENLOW_"&((C9+1)/2)) | D23: =IF(MOD(D9,2)=0,"ALTAVO_"&(D9/2+1),"BRENLOW_"&((D9+1)/2)) | E23: =IF(MOD(E9,2)=0,"ALTAVO_"&(E9/2+1),"BRENLOW_"&((E9+1)/2)) | F23: =IF(MOD(F9,2)=0,"ALTAVO_"&(F9/2+1),"BRENLOW_"&((F9+1)/2)) | G23: =IF(MOD(G9,2)=0,"ALTAVO_"&(G9/2+1),"BRENLOW_"&((G9+1)/2)) | H23: =IF(MOD(H9,2)=0,"ALTAVO_"&(H9/2+1),"BRENLOW_"&((H9+1)/2)) | I23: =IF(MOD(I9,2)=0,"ALTAVO_"&(I9/2+1),"BRENLOW_"&((I9+1)/2)) | J23: =IF(MOD(J9,2)=0,"ALTAVO_"&(J9/2+1),"BRENLOW_"&((J9+1)/2)) | ... N23: =IF(MOD(N9,2)=0,"ALTAVO_"&(N9/2+1),"BRENLOW_"&((N9+1)/2)) | O23: =IF(MOD(C9,2)=0,"A","B")&IF(MOD(D9,2)=0,"A","B")&IF(MOD(E9,2)=0,"A","B")&IF(MOD(F9,2)=0,"A","B")&IF(MOD(G9,2)=0,"A","B")&IF(MOD(H9,2)=0,"A","B")&IF(MOD(I9,2)=0,"A","B")&IF(MOD(J9,2)=0,"A","B")&IF(MOD(K9,2)=0,"A","B")&IF(MOD(L9,2)=0,"A","B")&IF(MOD(M9,2)=0,"A","B")&IF(MOD(N9,2)=0,"A","B")
B24: 3 | C24: =IF(MOD(C10,2)=0,"ALTAVO_"&(C10/2+1),"BRENLOW_"&((C10+1)/2)) | D24: =IF(MOD(D10,2)=0,"ALTAVO_"&(D10/2+1),"BRENLOW_"&((D10+1)/2)) | E24: =IF(MOD(E10,2)=0,"ALTAVO_"&(E10/2+1),"BRENLOW_"&((E10+1)/2)) | F24: =IF(MOD(F10,2)=0,"ALTAVO_"&(F10/2+1),"BRENLOW_"&((F10+1)/2)) | G24: =IF(MOD(G10,2)=0,"ALTAVO_"&(G10/2+1),"BRENLOW_"&((G10+1)/2)) | H24: =IF(MOD(H10,2)=0,"ALTAVO_"&(H10/2+1),"BRENLOW_"&((H10+1)/2)) | I24: =IF(MOD(I10,2)=0,"ALTAVO_"&(I10/2+1),"BRENLOW_"&((I10+1)/2)) | J24: =IF(MOD(J10,2)=0,"ALTAVO_"&(J10/2+1),"BRENLOW_"&((J10+1)/2)) | ... N24: =IF(MOD(N10,2)=0,"ALTAVO_"&(N10/2+1),"BRENLOW_"&((N10+1)/2)) | O24: =IF(MOD(C10,2)=0,"A","B")&IF(MOD(D10,2)=0,"A","B")&IF(MOD(E10,2)=0,"A","B")&IF(MOD(F10,2)=0,"A","B")&IF(MOD(G10,2)=0,"A","B")&IF(MOD(H10,2)=0,"A","B")&IF(MOD(I10,2)=0,"A","B")&IF(MOD(J10,2)=0,"A","B")&IF(MOD(K10,2)=0,"A","B")&IF(MOD(L10,2)=0,"A","B")&IF(MOD(M10,2)=0,"A","B")&IF(MOD(N10,2)=0,"A","B")
B25: 4 | C25: =IF(MOD(C11,2)=0,"ALTAVO_"&(C11/2+1),"BRENLOW_"&((C11+1)/2)) | D25: =IF(MOD(D11,2)=0,"ALTAVO_"&(D11/2+1),"BRENLOW_"&((D11+1)/2)) | E25: =IF(MOD(E11,2)=0,"ALTAVO_"&(E11/2+1),"BRENLOW_"&((E11+1)/2)) | F25: =IF(MOD(F11,2)=0,"ALTAVO_"&(F11/2+1),"BRENLOW_"&((F11+1)/2)) | G25: =IF(MOD(G11,2)=0,"ALTAVO_"&(G11/2+1),"BRENLOW_"&((G11+1)/2)) | H25: =IF(MOD(H11,2)=0,"ALTAVO_"&(H11/2+1),"BRENLOW_"&((H11+1)/2)) | I25: =IF(MOD(I11,2)=0,"ALTAVO_"&(I11/2+1),"BRENLOW_"&((I11+1)/2)) | J25: =IF(MOD(J11,2)=0,"ALTAVO_"&(J11/2+1),"BRENLOW_"&((J11+1)/2)) | ... N25: =IF(MOD(N11,2)=0,"ALTAVO_"&(N11/2+1),"BRENLOW_"&((N11+1)/2)) | O25: =IF(MOD(C11,2)=0,"A","B")&IF(MOD(D11,2)=0,"A","B")&IF(MOD(E11,2)=0,"A","B")&IF(MOD(F11,2)=0,"A","B")&IF(MOD(G11,2)=0,"A","B")&IF(MOD(H11,2)=0,"A","B")&IF(MOD(I11,2)=0,"A","B")&IF(MOD(J11,2)=0,"A","B")&IF(MOD(K11,2)=0,"A","B")&IF(MOD(L11,2)=0,"A","B")&IF(MOD(M11,2)=0,"A","B")&IF(MOD(N11,2)=0,"A","B")
B26: 5 | C26: =IF(MOD(C12,2)=0,"ALTAVO_"&(C12/2+1),"BRENLOW_"&((C12+1)/2)) | D26: =IF(MOD(D12,2)=0,"ALTAVO_"&(D12/2+1),"BRENLOW_"&((D12+1)/2)) | E26: =IF(MOD(E12,2)=0,"ALTAVO_"&(E12/2+1),"BRENLOW_"&((E12+1)/2)) | F26: =IF(MOD(F12,2)=0,"ALTAVO_"&(F12/2+1),"BRENLOW_"&((F12+1)/2)) | G26: =IF(MOD(G12,2)=0,"ALTAVO_"&(G12/2+1),"BRENLOW_"&((G12+1)/2)) | H26: =IF(MOD(H12,2)=0,"ALTAVO_"&(H12/2+1),"BRENLOW_"&((H12+1)/2)) | I26: =IF(MOD(I12,2)=0,"ALTAVO_"&(I12/2+1),"BRENLOW_"&((I12+1)/2)) | J26: =IF(MOD(J12,2)=0,"ALTAVO_"&(J12/2+1),"BRENLOW_"&((J12+1)/2)) | ... N26: =IF(MOD(N12,2)=0,"ALTAVO_"&(N12/2+1),"BRENLOW_"&((N12+1)/2)) | O26: =IF(MOD(C12,2)=0,"A","B")&IF(MOD(D12,2)=0,"A","B")&IF(MOD(E12,2)=0,"A","B")&IF(MOD(F12,2)=0,"A","B")&IF(MOD(G12,2)=0,"A","B")&IF(MOD(H12,2)=0,"A","B")&IF(MOD(I12,2)=0,"A","B")&IF(MOD(J12,2)=0,"A","B")&IF(MOD(K12,2)=0,"A","B")&IF(MOD(L12,2)=0,"A","B")&IF(MOD(M12,2)=0,"A","B")&IF(MOD(N12,2)=0,"A","B")
B27: 6 | C27: =IF(MOD(C13,2)=0,"ALTAVO_"&(C13/2+1),"BRENLOW_"&((C13+1)/2)) | D27: =IF(MOD(D13,2)=0,"ALTAVO_"&(D13/2+1),"BRENLOW_"&((D13+1)/2)) | E27: =IF(MOD(E13,2)=0,"ALTAVO_"&(E13/2+1),"BRENLOW_"&((E13+1)/2)) | F27: =IF(MOD(F13,2)=0,"ALTAVO_"&(F13/2+1),"BRENLOW_"&((F13+1)/2)) | G27: =IF(MOD(G13,2)=0,"ALTAVO_"&(G13/2+1),"BRENLOW_"&((G13+1)/2)) | H27: =IF(MOD(H13,2)=0,"ALTAVO_"&(H13/2+1),"BRENLOW_"&((H13+1)/2)) | I27: =IF(MOD(I13,2)=0,"ALTAVO_"&(I13/2+1),"BRENLOW_"&((I13+1)/2)) | J27: =IF(MOD(J13,2)=0,"ALTAVO_"&(J13/2+1),"BRENLOW_"&((J13+1)/2)) | ... N27: =IF(MOD(N13,2)=0,"ALTAVO_"&(N13/2+1),"BRENLOW_"&((N13+1)/2)) | O27: =IF(MOD(C13,2)=0,"A","B")&IF(MOD(D13,2)=0,"A","B")&IF(MOD(E13,2)=0,"A","B")&IF(MOD(F13,2)=0,"A","B")&IF(MOD(G13,2)=0,"A","B")&IF(MOD(H13,2)=0,"A","B")&IF(MOD(I13,2)=0,"A","B")&IF(MOD(J13,2)=0,"A","B")&IF(MOD(K13,2)=0,"A","B")&IF(MOD(L13,2)=0,"A","B")&IF(MOD(M13,2)=0,"A","B")&IF(MOD(N13,2)=0,"A","B")
B28: 7 | C28: =IF(MOD(C14,2)=0,"ALTAVO_"&(C14/2+1),"BRENLOW_"&((C14+1)/2)) | D28: =IF(MOD(D14,2)=0,"ALTAVO_"&(D14/2+1),"BRENLOW_"&((D14+1)/2)) | E28: =IF(MOD(E14,2)=0,"ALTAVO_"&(E14/2+1),"BRENLOW_"&((E14+1)/2)) | F28: =IF(MOD(F14,2)=0,"ALTAVO_"&(F14/2+1),"BRENLOW_"&((F14+1)/2)) | G28: =IF(MOD(G14,2)=0,"ALTAVO_"&(G14/2+1),"BRENLOW_"&((G14+1)/2)) | H28: =IF(MOD(H14,2)=0,"ALTAVO_"&(H14/2+1),"BRENLOW_"&((H14+1)/2)) | I28: =IF(MOD(I14,2)=0,"ALTAVO_"&(I14/2+1),"BRENLOW_"&((I14+1)/2)) | J28: =IF(MOD(J14,2)=0,"ALTAVO_"&(J14/2+1),"BRENLOW_"&((J14+1)/2)) | ... N28: =IF(MOD(N14,2)=0,"ALTAVO_"&(N14/2+1),"BRENLOW_"&((N14+1)/2)) | O28: =IF(MOD(C14,2)=0,"A","B")&IF(MOD(D14,2)=0,"A","B")&IF(MOD(E14,2)=0,"A","B")&IF(MOD(F14,2)=0,"A","B")&IF(MOD(G14,2)=0,"A","B")&IF(MOD(H14,2)=0,"A","B")&IF(MOD(I14,2)=0,"A","B")&IF(MOD(J14,2)=0,"A","B")&IF(MOD(K14,2)=0,"A","B")&IF(MOD(L14,2)=0,"A","B")&IF(MOD(M14,2)=0,"A","B")&IF(MOD(N14,2)=0,"A","B")
B29: 8 | C29: =IF(MOD(C15,2)=0,"ALTAVO_"&(C15/2+1),"BRENLOW_"&((C15+1)/2)) | D29: =IF(MOD(D15,2)=0,"ALTAVO_"&(D15/2+1),"BRENLOW_"&((D15+1)/2)) | E29: =IF(MOD(E15,2)=0,"ALTAVO_"&(E15/2+1),"BRENLOW_"&((E15+1)/2)) | F29: =IF(MOD(F15,2)=0,"ALTAVO_"&(F15/2+1),"BRENLOW_"&((F15+1)/2)) | G29: =IF(MOD(G15,2)=0,"ALTAVO_"&(G15/2+1),"BRENLOW_"&((G15+1)/2)) | H29: =IF(MOD(H15,2)=0,"ALTAVO_"&(H15/2+1),"BRENLOW_"&((H15+1)/2)) | I29: =IF(MOD(I15,2)=0,"ALTAVO_"&(I15/2+1),"BRENLOW_"&((I15+1)/2)) | J29: =IF(MOD(J15,2)=0,"ALTAVO_"&(J15/2+1),"BRENLOW_"&((J15+1)/2)) | ... N29: =IF(MOD(N15,2)=0,"ALTAVO_"&(N15/2+1),"BRENLOW_"&((N15+1)/2)) | O29: =IF(MOD(C15,2)=0,"A","B")&IF(MOD(D15,2)=0,"A","B")&IF(MOD(E15,2)=0,"A","B")&IF(MOD(F15,2)=0,"A","B")&IF(MOD(G15,2)=0,"A","B")&IF(MOD(H15,2)=0,"A","B")&IF(MOD(I15,2)=0,"A","B")&IF(MOD(J15,2)=0,"A","B")&IF(MOD(K15,2)=0,"A","B")&IF(MOD(L15,2)=0,"A","B")&IF(MOD(M15,2)=0,"A","B")&IF(MOD(N15,2)=0,"A","B")
B30: 9 | C30: =IF(MOD(C16,2)=0,"ALTAVO_"&(C16/2+1),"BRENLOW_"&((C16+1)/2)) | D30: =IF(MOD(D16,2)=0,"ALTAVO_"&(D16/2+1),"BRENLOW_"&((D16+1)/2)) | E30: =IF(MOD(E16,2)=0,"ALTAVO_"&(E16/2+1),"BRENLOW_"&((E16+1)/2)) | F30: =IF(MOD(F16,2)=0,"ALTAVO_"&(F16/2+1),"BRENLOW_"&((F16+1)/2)) | G30: =IF(MOD(G16,2)=0,"ALTAVO_"&(G16/2+1),"BRENLOW_"&((G16+1)/2)) | H30: =IF(MOD(H16,2)=0,"ALTAVO_"&(H16/2+1),"BRENLOW_"&((H16+1)/2)) | I30: =IF(MOD(I16,2)=0,"ALTAVO_"&(I16/2+1),"BRENLOW_"&((I16+1)/2)) | J30: =IF(MOD(J16,2)=0,"ALTAVO_"&(J16/2+1),"BRENLOW_"&((J16+1)/2)) | ... N30: =IF(MOD(N16,2)=0,"ALTAVO_"&(N16/2+1),"BRENLOW_"&((N16+1)/2)) | O30: =IF(MOD(C16,2)=0,"A","B")&IF(MOD(D16,2)=0,"A","B")&IF(MOD(E16,2)=0,"A","B")&IF(MOD(F16,2)=0,"A","B")&IF(MOD(G16,2)=0,"A","B")&IF(MOD(H16,2)=0,"A","B")&IF(MOD(I16,2)=0,"A","B")&IF(MOD(J16,2)=0,"A","B")&IF(MOD(K16,2)=0,"A","B")&IF(MOD(L16,2)=0,"A","B")&IF(MOD(M16,2)=0,"A","B")&IF(MOD(N16,2)=0,"A","B")
B31: 10 | C31: =IF(MOD(C17,2)=0,"ALTAVO_"&(C17/2+1),"BRENLOW_"&((C17+1)/2)) | D31: =IF(MOD(D17,2)=0,"ALTAVO_"&(D17/2+1),"BRENLOW_"&((D17+1)/2)) | E31: =IF(MOD(E17,2)=0,"ALTAVO_"&(E17/2+1),"BRENLOW_"&((E17+1)/2)) | F31: =IF(MOD(F17,2)=0,"ALTAVO_"&(F17/2+1),"BRENLOW_"&((F17+1)/2)) | G31: =IF(MOD(G17,2)=0,"ALTAVO_"&(G17/2+1),"BRENLOW_"&((G17+1)/2)) | H31: =IF(MOD(H17,2)=0,"ALTAVO_"&(H17/2+1),"BRENLOW_"&((H17+1)/2)) | I31: =IF(MOD(I17,2)=0,"ALTAVO_"&(I17/2+1),"BRENLOW_"&((I17+1)/2)) | J31: =IF(MOD(J17,2)=0,"ALTAVO_"&(J17/2+1),"BRENLOW_"&((J17+1)/2)) | ... N31: =IF(MOD(N17,2)=0,"ALTAVO_"&(N17/2+1),"BRENLOW_"&((N17+1)/2)) | O31: =IF(MOD(C17,2)=0,"A","B")&IF(MOD(D17,2)=0,"A","B")&IF(MOD(E17,2)=0,"A","B")&IF(MOD(F17,2)=0,"A","B")&IF(MOD(G17,2)=0,"A","B")&IF(MOD(H17,2)=0,"A","B")&IF(MOD(I17,2)=0,"A","B")&IF(MOD(J17,2)=0,"A","B")&IF(MOD(K17,2)=0,"A","B")&IF(MOD(L17,2)=0,"A","B")&IF(MOD(M17,2)=0,"A","B")&IF(MOD(N17,2)=0,"A","B")
B32: 11 | C32: =IF(MOD(C18,2)=0,"ALTAVO_"&(C18/2+1),"BRENLOW_"&((C18+1)/2)) | D32: =IF(MOD(D18,2)=0,"ALTAVO_"&(D18/2+1),"BRENLOW_"&((D18+1)/2)) | E32: =IF(MOD(E18,2)=0,"ALTAVO_"&(E18/2+1),"BRENLOW_"&((E18+1)/2)) | F32: =IF(MOD(F18,2)=0,"ALTAVO_"&(F18/2+1),"BRENLOW_"&((F18+1)/2)) | G32: =IF(MOD(G18,2)=0,"ALTAVO_"&(G18/2+1),"BRENLOW_"&((G18+1)/2)) | H32: =IF(MOD(H18,2)=0,"ALTAVO_"&(H18/2+1),"BRENLOW_"&((H18+1)/2)) | I32: =IF(MOD(I18,2)=0,"ALTAVO_"&(I18/2+1),"BRENLOW_"&((I18+1)/2)) | J32: =IF(MOD(J18,2)=0,"ALTAVO_"&(J18/2+1),"BRENLOW_"&((J18+1)/2)) | ... N32: =IF(MOD(N18,2)=0,"ALTAVO_"&(N18/2+1),"BRENLOW_"&((N18+1)/2)) | O32: =IF(MOD(C18,2)=0,"A","B")&IF(MOD(D18,2)=0,"A","B")&IF(MOD(E18,2)=0,"A","B")&IF(MOD(F18,2)=0,"A","B")&IF(MOD(G18,2)=0,"A","B")&IF(MOD(H18,2)=0,"A","B")&IF(MOD(I18,2)=0,"A","B")&IF(MOD(J18,2)=0,"A","B")&IF(MOD(K18,2)=0,"A","B")&IF(MOD(L18,2)=0,"A","B")&IF(MOD(M18,2)=0,"A","B")&IF(MOD(N18,2)=0,"A","B")
B33: 12 | C33: =IF(MOD(C19,2)=0,"ALTAVO_"&(C19/2+1),"BRENLOW_"&((C19+1)/2)) | D33: =IF(MOD(D19,2)=0,"ALTAVO_"&(D19/2+1),"BRENLOW_"&((D19+1)/2)) | E33: =IF(MOD(E19,2)=0,"ALTAVO_"&(E19/2+1),"BRENLOW_"&((E19+1)/2)) | F33: =IF(MOD(F19,2)=0,"ALTAVO_"&(F19/2+1),"BRENLOW_"&((F19+1)/2)) | G33: =IF(MOD(G19,2)=0,"ALTAVO_"&(G19/2+1),"BRENLOW_"&((G19+1)/2)) | H33: =IF(MOD(H19,2)=0,"ALTAVO_"&(H19/2+1),"BRENLOW_"&((H19+1)/2)) | I33: =IF(MOD(I19,2)=0,"ALTAVO_"&(I19/2+1),"BRENLOW_"&((I19+1)/2)) | J33: =IF(MOD(J19,2)=0,"ALTAVO_"&(J19/2+1),"BRENLOW_"&((J19+1)/2)) | ... N33: =IF(MOD(N19,2)=0,"ALTAVO_"&(N19/2+1),"BRENLOW_"&((N19+1)/2)) | O33: =IF(MOD(C19,2)=0,"A","B")&IF(MOD(D19,2)=0,"A","B")&IF(MOD(E19,2)=0,"A","B")&IF(MOD(F19,2)=0,"A","B")&IF(MOD(G19,2)=0,"A","B")&IF(MOD(H19,2)=0,"A","B")&IF(MOD(I19,2)=0,"A","B")&IF(MOD(J19,2)=0,"A","B")&IF(MOD(K19,2)=0,"A","B")&IF(MOD(L19,2)=0,"A","B")&IF(MOD(M19,2)=0,"A","B")&IF(MOD(N19,2)=0,"A","B")
A35: Checks
B36: Symbol -> | C36: 0 | D36: 1 | E36: 2 | F36: 3 | G36: 4 | H36: 5 | I36: 6 | J36: 7 | K36: 8 | L36: 9 | M36: 10 | N36: 11
B37: row 1 | C37: =COUNTIF($C8:$N8,C$36) | D37: =COUNTIF($C8:$N8,D$36) | E37: =COUNTIF($C8:$N8,E$36) | F37: =COUNTIF($C8:$N8,F$36) | G37: =COUNTIF($C8:$N8,G$36) | H37: =COUNTIF($C8:$N8,H$36) | I37: =COUNTIF($C8:$N8,I$36) | J37: =COUNTIF($C8:$N8,J$36) | ... N37: =COUNTIF($C8:$N8,N$36)
B38: row 2 | C38: =COUNTIF($C9:$N9,C$36) | D38: =COUNTIF($C9:$N9,D$36) | E38: =COUNTIF($C9:$N9,E$36) | F38: =COUNTIF($C9:$N9,F$36) | G38: =COUNTIF($C9:$N9,G$36) | H38: =COUNTIF($C9:$N9,H$36) | I38: =COUNTIF($C9:$N9,I$36) | J38: =COUNTIF($C9:$N9,J$36) | ... N38: =COUNTIF($C9:$N9,N$36)
B39: row 3 | C39: =COUNTIF($C10:$N10,C$36) | D39: =COUNTIF($C10:$N10,D$36) | E39: =COUNTIF($C10:$N10,E$36) | F39: =COUNTIF($C10:$N10,F$36) | G39: =COUNTIF($C10:$N10,G$36) | H39: =COUNTIF($C10:$N10,H$36) | I39: =COUNTIF($C10:$N10,I$36) | J39: =COUNTIF($C10:$N10,J$36) | ... N39: =COUNTIF($C10:$N10,N$36)
B40: row 4 | C40: =COUNTIF($C11:$N11,C$36) | D40: =COUNTIF($C11:$N11,D$36) | E40: =COUNTIF($C11:$N11,E$36) | F40: =COUNTIF($C11:$N11,F$36) | G40: =COUNTIF($C11:$N11,G$36) | H40: =COUNTIF($C11:$N11,H$36) | I40: =COUNTIF($C11:$N11,I$36) | J40: =COUNTIF($C11:$N11,J$36) | ... N40: =COUNTIF($C11:$N11,N$36)
B41: row 5 | C41: =COUNTIF($C12:$N12,C$36) | D41: =COUNTIF($C12:$N12,D$36) | E41: =COUNTIF($C12:$N12,E$36) | F41: =COUNTIF($C12:$N12,F$36) | G41: =COUNTIF($C12:$N12,G$36) | H41: =COUNTIF($C12:$N12,H$36) | I41: =COUNTIF($C12:$N12,I$36) | J41: =COUNTIF($C12:$N12,J$36) | ... N41: =COUNTIF($C12:$N12,N$36)
B42: row 6 | C42: =COUNTIF($C13:$N13,C$36) | D42: =COUNTIF($C13:$N13,D$36) | E42: =COUNTIF($C13:$N13,E$36) | F42: =COUNTIF($C13:$N13,F$36) | G42: =COUNTIF($C13:$N13,G$36) | H42: =COUNTIF($C13:$N13,H$36) | I42: =COUNTIF($C13:$N13,I$36) | J42: =COUNTIF($C13:$N13,J$36) | ... N42: =COUNTIF($C13:$N13,N$36)
B43: row 7 | C43: =COUNTIF($C14:$N14,C$36) | D43: =COUNTIF($C14:$N14,D$36) | E43: =COUNTIF($C14:$N14,E$36) | F43: =COUNTIF($C14:$N14,F$36) | G43: =COUNTIF($C14:$N14,G$36) | H43: =COUNTIF($C14:$N14,H$36) | I43: =COUNTIF($C14:$N14,I$36) | J43: =COUNTIF($C14:$N14,J$36) | ... N43: =COUNTIF($C14:$N14,N$36)
B44: row 8 | C44: =COUNTIF($C15:$N15,C$36) | D44: =COUNTIF($C15:$N15,D$36) | E44: =COUNTIF($C15:$N15,E$36) | F44: =COUNTIF($C15:$N15,F$36) | G44: =COUNTIF($C15:$N15,G$36) | H44: =COUNTIF($C15:$N15,H$36) | I44: =COUNTIF($C15:$N15,I$36) | J44: =COUNTIF($C15:$N15,J$36) | ... N44: =COUNTIF($C15:$N15,N$36)
B45: row 9 | C45: =COUNTIF($C16:$N16,C$36) | D45: =COUNTIF($C16:$N16,D$36) | E45: =COUNTIF($C16:$N16,E$36) | F45: =COUNTIF($C16:$N16,F$36) | G45: =COUNTIF($C16:$N16,G$36) | H45: =COUNTIF($C16:$N16,H$36) | I45: =COUNTIF($C16:$N16,I$36) | J45: =COUNTIF($C16:$N16,J$36) | ... N45: =COUNTIF($C16:$N16,N$36)
...

Sheet Assignment
A1: Latin square row of each participant code: blocks of 12, every row once per block, random order within a block (drawn in R, seed fixed)
A3: Participant code | B3: Block | C3: Latin square row | D3: First ad | E3: First brand | G3: Row (down) x block (across): participants
A4: P01 | B4: 1 | C4: 4 | D4: =INDEX(LatinSquare!$C$22:$C$33,C4) | E4: =IF(LEFT(D4,6)="ALTAVO","ALTAVO","BRENLOW") | H4: 1 | I4: 2 | J4: 3 | K4: 4
A5: P02 | B5: 1 | C5: 3 | D5: =INDEX(LatinSquare!$C$22:$C$33,C5) | E5: =IF(LEFT(D5,6)="ALTAVO","ALTAVO","BRENLOW") | G5: 1 | H5: =COUNTIFS($B$4:$B$51,H$4,$C$4:$C$51,$G5) | I5: =COUNTIFS($B$4:$B$51,I$4,$C$4:$C$51,$G5) | J5: =COUNTIFS($B$4:$B$51,J$4,$C$4:$C$51,$G5) | K5: =COUNTIFS($B$4:$B$51,K$4,$C$4:$C$51,$G5)
A6: P03 | B6: 1 | C6: 2 | D6: =INDEX(LatinSquare!$C$22:$C$33,C6) | E6: =IF(LEFT(D6,6)="ALTAVO","ALTAVO","BRENLOW") | G6: 2 | H6: =COUNTIFS($B$4:$B$51,H$4,$C$4:$C$51,$G6) | I6: =COUNTIFS($B$4:$B$51,I$4,$C$4:$C$51,$G6) | J6: =COUNTIFS($B$4:$B$51,J$4,$C$4:$C$51,$G6) | K6: =COUNTIFS($B$4:$B$51,K$4,$C$4:$C$51,$G6)
A7: P04 | B7: 1 | C7: 9 | D7: =INDEX(LatinSquare!$C$22:$C$33,C7) | E7: =IF(LEFT(D7,6)="ALTAVO","ALTAVO","BRENLOW") | G7: 3 | H7: =COUNTIFS($B$4:$B$51,H$4,$C$4:$C$51,$G7) | I7: =COUNTIFS($B$4:$B$51,I$4,$C$4:$C$51,$G7) | J7: =COUNTIFS($B$4:$B$51,J$4,$C$4:$C$51,$G7) | K7: =COUNTIFS($B$4:$B$51,K$4,$C$4:$C$51,$G7)
A8: P05 | B8: 1 | C8: 1 | D8: =INDEX(LatinSquare!$C$22:$C$33,C8) | E8: =IF(LEFT(D8,6)="ALTAVO","ALTAVO","BRENLOW") | G8: 4 | H8: =COUNTIFS($B$4:$B$51,H$4,$C$4:$C$51,$G8) | I8: =COUNTIFS($B$4:$B$51,I$4,$C$4:$C$51,$G8) | J8: =COUNTIFS($B$4:$B$51,J$4,$C$4:$C$51,$G8) | K8: =COUNTIFS($B$4:$B$51,K$4,$C$4:$C$51,$G8)
A9: P06 | B9: 1 | C9: 5 | D9: =INDEX(LatinSquare!$C$22:$C$33,C9) | E9: =IF(LEFT(D9,6)="ALTAVO","ALTAVO","BRENLOW") | G9: 5 | H9: =COUNTIFS($B$4:$B$51,H$4,$C$4:$C$51,$G9) | I9: =COUNTIFS($B$4:$B$51,I$4,$C$4:$C$51,$G9) | J9: =COUNTIFS($B$4:$B$51,J$4,$C$4:$C$51,$G9) | K9: =COUNTIFS($B$4:$B$51,K$4,$C$4:$C$51,$G9)
A10: P07 | B10: 1 | C10: 12 | D10: =INDEX(LatinSquare!$C$22:$C$33,C10) | E10: =IF(LEFT(D10,6)="ALTAVO","ALTAVO","BRENLOW") | G10: 6 | H10: =COUNTIFS($B$4:$B$51,H$4,$C$4:$C$51,$G10) | I10: =COUNTIFS($B$4:$B$51,I$4,$C$4:$C$51,$G10) | J10: =COUNTIFS($B$4:$B$51,J$4,$C$4:$C$51,$G10) | K10: =COUNTIFS($B$4:$B$51,K$4,$C$4:$C$51,$G10)
A11: P08 | B11: 1 | C11: 8 | D11: =INDEX(LatinSquare!$C$22:$C$33,C11) | E11: =IF(LEFT(D11,6)="ALTAVO","ALTAVO","BRENLOW") | G11: 7 | H11: =COUNTIFS($B$4:$B$51,H$4,$C$4:$C$51,$G11) | I11: =COUNTIFS($B$4:$B$51,I$4,$C$4:$C$51,$G11) | J11: =COUNTIFS($B$4:$B$51,J$4,$C$4:$C$51,$G11) | K11: =COUNTIFS($B$4:$B$51,K$4,$C$4:$C$51,$G11)
A12: P09 | B12: 1 | C12: 7 | D12: =INDEX(LatinSquare!$C$22:$C$33,C12) | E12: =IF(LEFT(D12,6)="ALTAVO","ALTAVO","BRENLOW") | G12: 8 | H12: =COUNTIFS($B$4:$B$51,H$4,$C$4:$C$51,$G12) | I12: =COUNTIFS($B$4:$B$51,I$4,$C$4:$C$51,$G12) | J12: =COUNTIFS($B$4:$B$51,J$4,$C$4:$C$51,$G12) | K12: =COUNTIFS($B$4:$B$51,K$4,$C$4:$C$51,$G12)
A13: P10 | B13: 1 | C13: 11 | D13: =INDEX(LatinSquare!$C$22:$C$33,C13) | E13: =IF(LEFT(D13,6)="ALTAVO","ALTAVO","BRENLOW") | G13: 9 | H13: =COUNTIFS($B$4:$B$51,H$4,$C$4:$C$51,$G13) | I13: =COUNTIFS($B$4:$B$51,I$4,$C$4:$C$51,$G13) | J13: =COUNTIFS($B$4:$B$51,J$4,$C$4:$C$51,$G13) | K13: =COUNTIFS($B$4:$B$51,K$4,$C$4:$C$51,$G13)
A14: P11 | B14: 1 | C14: 6 | D14: =INDEX(LatinSquare!$C$22:$C$33,C14) | E14: =IF(LEFT(D14,6)="ALTAVO","ALTAVO","BRENLOW") | G14: 10 | H14: =COUNTIFS($B$4:$B$51,H$4,$C$4:$C$51,$G14) | I14: =COUNTIFS($B$4:$B$51,I$4,$C$4:$C$51,$G14) | J14: =COUNTIFS($B$4:$B$51,J$4,$C$4:$C$51,$G14) | K14: =COUNTIFS($B$4:$B$51,K$4,$C$4:$C$51,$G14)
A15: P12 | B15: 1 | C15: 10 | D15: =INDEX(LatinSquare!$C$22:$C$33,C15) | E15: =IF(LEFT(D15,6)="ALTAVO","ALTAVO","BRENLOW") | G15: 11 | H15: =COUNTIFS($B$4:$B$51,H$4,$C$4:$C$51,$G15) | I15: =COUNTIFS($B$4:$B$51,I$4,$C$4:$C$51,$G15) | J15: =COUNTIFS($B$4:$B$51,J$4,$C$4:$C$51,$G15) | K15: =COUNTIFS($B$4:$B$51,K$4,$C$4:$C$51,$G15)
A16: P13 | B16: 2 | C16: 7 | D16: =INDEX(LatinSquare!$C$22:$C$33,C16) | E16: =IF(LEFT(D16,6)="ALTAVO","ALTAVO","BRENLOW") | G16: 12 | H16: =COUNTIFS($B$4:$B$51,H$4,$C$4:$C$51,$G16) | I16: =COUNTIFS($B$4:$B$51,I$4,$C$4:$C$51,$G16) | J16: =COUNTIFS($B$4:$B$51,J$4,$C$4:$C$51,$G16) | K16: =COUNTIFS($B$4:$B$51,K$4,$C$4:$C$51,$G16)
A17: P14 | B17: 2 | C17: 9 | D17: =INDEX(LatinSquare!$C$22:$C$33,C17) | E17: =IF(LEFT(D17,6)="ALTAVO","ALTAVO","BRENLOW")
A18: P15 | B18: 2 | C18: 6 | D18: =INDEX(LatinSquare!$C$22:$C$33,C18) | E18: =IF(LEFT(D18,6)="ALTAVO","ALTAVO","BRENLOW") | G18: smallest count | H18: =MIN(H5:K16)
A19: P16 | B19: 2 | C19: 3 | D19: =INDEX(LatinSquare!$C$22:$C$33,C19) | E19: =IF(LEFT(D19,6)="ALTAVO","ALTAVO","BRENLOW") | G19: largest count | H19: =MAX(H5:K16)
A20: P17 | B20: 2 | C20: 12 | D20: =INDEX(LatinSquare!$C$22:$C$33,C20) | E20: =IF(LEFT(D20,6)="ALTAVO","ALTAVO","BRENLOW") | G20: ALTAVO first | H20: =COUNTIF(E4:E51,"ALTAVO")
A21: P18 | B21: 2 | C21: 5 | D21: =INDEX(LatinSquare!$C$22:$C$33,C21) | E21: =IF(LEFT(D21,6)="ALTAVO","ALTAVO","BRENLOW")
A22: P19 | B22: 2 | C22: 11 | D22: =INDEX(LatinSquare!$C$22:$C$33,C22) | E22: =IF(LEFT(D22,6)="ALTAVO","ALTAVO","BRENLOW")
A23: P20 | B23: 2 | C23: 4 | D23: =INDEX(LatinSquare!$C$22:$C$33,C23) | E23: =IF(LEFT(D23,6)="ALTAVO","ALTAVO","BRENLOW")
A24: P21 | B24: 2 | C24: 8 | D24: =INDEX(LatinSquare!$C$22:$C$33,C24) | E24: =IF(LEFT(D24,6)="ALTAVO","ALTAVO","BRENLOW")
A25: P22 | B25: 2 | C25: 1 | D25: =INDEX(LatinSquare!$C$22:$C$33,C25) | E25: =IF(LEFT(D25,6)="ALTAVO","ALTAVO","BRENLOW")
A26: P23 | B26: 2 | C26: 2 | D26: =INDEX(LatinSquare!$C$22:$C$33,C26) | E26: =IF(LEFT(D26,6)="ALTAVO","ALTAVO","BRENLOW")
A27: P24 | B27: 2 | C27: 10 | D27: =INDEX(LatinSquare!$C$22:$C$33,C27) | E27: =IF(LEFT(D27,6)="ALTAVO","ALTAVO","BRENLOW")
A28: P25 | B28: 3 | C28: 11 | D28: =INDEX(LatinSquare!$C$22:$C$33,C28) | E28: =IF(LEFT(D28,6)="ALTAVO","ALTAVO","BRENLOW")
A29: P26 | B29: 3 | C29: 10 | D29: =INDEX(LatinSquare!$C$22:$C$33,C29) | E29: =IF(LEFT(D29,6)="ALTAVO","ALTAVO","BRENLOW")
A30: P27 | B30: 3 | C30: 5 | D30: =INDEX(LatinSquare!$C$22:$C$33,C30) | E30: =IF(LEFT(D30,6)="ALTAVO","ALTAVO","BRENLOW")
A31: P28 | B31: 3 | C31: 8 | D31: =INDEX(LatinSquare!$C$22:$C$33,C31) | E31: =IF(LEFT(D31,6)="ALTAVO","ALTAVO","BRENLOW")
A32: P29 | B32: 3 | C32: 3 | D32: =INDEX(LatinSquare!$C$22:$C$33,C32) | E32: =IF(LEFT(D32,6)="ALTAVO","ALTAVO","BRENLOW")
... A51: P48 | B51: 4 | C51: 3 | D51: =INDEX(LatinSquare!$C$22:$C$33,C51) | E51: =IF(LEFT(D51,6)="ALTAVO","ALTAVO","BRENLOW")

Sheet Calendar
A1: Session calendar for one Aurora seat (PLACEHOLDER dates: set them after IRB approval; check the JSU academic calendar for closures)
A3: First day of data collection | B3: 46426 | S3: dates that differ from R | T3: =SUMPRODUCT(--(C12:C66<>T12:T66))
A4: Slots per day | B4: =Attrition!B12 | S4: arrival times that differ from R | T4: =SUMPRODUCT(--(ROUND(F12:F66*1440,0)<>ROUND(U12:U66*1440,0)))
A5: First slot | B5: 0.375 | S5: participant codes that differ from R | T5: =SUMPRODUCT(--(L12:L66&""<>V12:V66&""))
A6: Slot length (minutes) | B6: 90 | S6: Latin square rows that differ from R | T6: =SUMPRODUCT(--(M12:M66&""<>W12:W66&""))
A7: Main participants | B7: =Attrition!B4 | S7: lead operators that differ from R | T7: =SUMPRODUCT(--(P12:P66<>X12:X66))
A8: Reserve sessions | B8: =Attrition!B18 | S8: assistants that differ from R | T8: =SUMPRODUCT(--(Q12:Q66<>Y12:Y66))
A9: Slots in all | B9: =Attrition!B21 | S9: last day of data collection | T9: =MAX(C12:C66)
A11: k | B11: Day index | C11: Date | D11: Weekday | E11: Slot | F11: Arrive | G11: Recording starts | H11: Recording ends | I11: Participant leaves | J11: Room ready | K11: Phase | L11: Participant code | M11: Latin square row | N11: Shift | O11: Staff pair | P11: Lead operator | Q11: Assistant | T11: R: date | U11: R: arrive | V11: R: code | W11: R: row | X11: R: lead | Y11: R: assistant
A12: 1 | B12: =INT((A12-1)/$B$4) | C12: =WORKDAY($B$3,B12) | D12: =TEXT(C12,"dddd") | E12: =MOD(A12-1,$B$4)+1 | F12: =$B$5+(E12-1)*$B$6/1440 | G12: =F12+25/1440 | H12: =F12+45/1440 | I12: =F12+60/1440 | J12: =F12+$B$6/1440 | K12: =IF(A12<=$B$7,"main",IF(A12<=$B$7+$B$8,"reserve","open")) | L12: =IF(K12="main","P"&TEXT(A12,"00"),IF(K12="reserve","R"&TEXT(A12-$B$7,"00"),"")) | M12: =IF(K12="main",INDEX(Assignment!$C$4:$C$51,MATCH(L12,Assignment!$A$4:$A$51,0)),"") | N12: =2*B12+IF(E12>=4,1,0) | O12: =MOD(N12,3)+1 | P12: =CHOOSE(O12,"S1","S3","S5") | Q12: =CHOOSE(O12,"S2","S4","S6") | T12: 46426 | U12: 0.375 | V12: P01 | W12: 4 | X12: S1 | Y12: S2
A13: 2 | B13: =INT((A13-1)/$B$4) | C13: =WORKDAY($B$3,B13) | D13: =TEXT(C13,"dddd") | E13: =MOD(A13-1,$B$4)+1 | F13: =$B$5+(E13-1)*$B$6/1440 | G13: =F13+25/1440 | H13: =F13+45/1440 | I13: =F13+60/1440 | J13: =F13+$B$6/1440 | K13: =IF(A13<=$B$7,"main",IF(A13<=$B$7+$B$8,"reserve","open")) | L13: =IF(K13="main","P"&TEXT(A13,"00"),IF(K13="reserve","R"&TEXT(A13-$B$7,"00"),"")) | M13: =IF(K13="main",INDEX(Assignment!$C$4:$C$51,MATCH(L13,Assignment!$A$4:$A$51,0)),"") | N13: =2*B13+IF(E13>=4,1,0) | O13: =MOD(N13,3)+1 | P13: =CHOOSE(O13,"S1","S3","S5") | Q13: =CHOOSE(O13,"S2","S4","S6") | T13: 46426 | U13: 0.4375 | V13: P02 | W13: 3 | X13: S1 | Y13: S2
A14: 3 | B14: =INT((A14-1)/$B$4) | C14: =WORKDAY($B$3,B14) | D14: =TEXT(C14,"dddd") | E14: =MOD(A14-1,$B$4)+1 | F14: =$B$5+(E14-1)*$B$6/1440 | G14: =F14+25/1440 | H14: =F14+45/1440 | I14: =F14+60/1440 | J14: =F14+$B$6/1440 | K14: =IF(A14<=$B$7,"main",IF(A14<=$B$7+$B$8,"reserve","open")) | L14: =IF(K14="main","P"&TEXT(A14,"00"),IF(K14="reserve","R"&TEXT(A14-$B$7,"00"),"")) | M14: =IF(K14="main",INDEX(Assignment!$C$4:$C$51,MATCH(L14,Assignment!$A$4:$A$51,0)),"") | N14: =2*B14+IF(E14>=4,1,0) | O14: =MOD(N14,3)+1 | P14: =CHOOSE(O14,"S1","S3","S5") | Q14: =CHOOSE(O14,"S2","S4","S6") | T14: 46426 | U14: 0.5 | V14: P03 | W14: 2 | X14: S1 | Y14: S2
A15: 4 | B15: =INT((A15-1)/$B$4) | C15: =WORKDAY($B$3,B15) | D15: =TEXT(C15,"dddd") | E15: =MOD(A15-1,$B$4)+1 | F15: =$B$5+(E15-1)*$B$6/1440 | G15: =F15+25/1440 | H15: =F15+45/1440 | I15: =F15+60/1440 | J15: =F15+$B$6/1440 | K15: =IF(A15<=$B$7,"main",IF(A15<=$B$7+$B$8,"reserve","open")) | L15: =IF(K15="main","P"&TEXT(A15,"00"),IF(K15="reserve","R"&TEXT(A15-$B$7,"00"),"")) | M15: =IF(K15="main",INDEX(Assignment!$C$4:$C$51,MATCH(L15,Assignment!$A$4:$A$51,0)),"") | N15: =2*B15+IF(E15>=4,1,0) | O15: =MOD(N15,3)+1 | P15: =CHOOSE(O15,"S1","S3","S5") | Q15: =CHOOSE(O15,"S2","S4","S6") | T15: 46426 | U15: 0.5625 | V15: P04 | W15: 9 | X15: S3 | Y15: S4
A16: 5 | B16: =INT((A16-1)/$B$4) | C16: =WORKDAY($B$3,B16) | D16: =TEXT(C16,"dddd") | E16: =MOD(A16-1,$B$4)+1 | F16: =$B$5+(E16-1)*$B$6/1440 | G16: =F16+25/1440 | H16: =F16+45/1440 | I16: =F16+60/1440 | J16: =F16+$B$6/1440 | K16: =IF(A16<=$B$7,"main",IF(A16<=$B$7+$B$8,"reserve","open")) | L16: =IF(K16="main","P"&TEXT(A16,"00"),IF(K16="reserve","R"&TEXT(A16-$B$7,"00"),"")) | M16: =IF(K16="main",INDEX(Assignment!$C$4:$C$51,MATCH(L16,Assignment!$A$4:$A$51,0)),"") | N16: =2*B16+IF(E16>=4,1,0) | O16: =MOD(N16,3)+1 | P16: =CHOOSE(O16,"S1","S3","S5") | Q16: =CHOOSE(O16,"S2","S4","S6") | T16: 46426 | U16: 0.625 | V16: P05 | W16: 1 | X16: S3 | Y16: S4
A17: 6 | B17: =INT((A17-1)/$B$4) | C17: =WORKDAY($B$3,B17) | D17: =TEXT(C17,"dddd") | E17: =MOD(A17-1,$B$4)+1 | F17: =$B$5+(E17-1)*$B$6/1440 | G17: =F17+25/1440 | H17: =F17+45/1440 | I17: =F17+60/1440 | J17: =F17+$B$6/1440 | K17: =IF(A17<=$B$7,"main",IF(A17<=$B$7+$B$8,"reserve","open")) | L17: =IF(K17="main","P"&TEXT(A17,"00"),IF(K17="reserve","R"&TEXT(A17-$B$7,"00"),"")) | M17: =IF(K17="main",INDEX(Assignment!$C$4:$C$51,MATCH(L17,Assignment!$A$4:$A$51,0)),"") | N17: =2*B17+IF(E17>=4,1,0) | O17: =MOD(N17,3)+1 | P17: =CHOOSE(O17,"S1","S3","S5") | Q17: =CHOOSE(O17,"S2","S4","S6") | T17: 46427 | U17: 0.375 | V17: P06 | W17: 5 | X17: S5 | Y17: S6
A18: 7 | B18: =INT((A18-1)/$B$4) | C18: =WORKDAY($B$3,B18) | D18: =TEXT(C18,"dddd") | E18: =MOD(A18-1,$B$4)+1 | F18: =$B$5+(E18-1)*$B$6/1440 | G18: =F18+25/1440 | H18: =F18+45/1440 | I18: =F18+60/1440 | J18: =F18+$B$6/1440 | K18: =IF(A18<=$B$7,"main",IF(A18<=$B$7+$B$8,"reserve","open")) | L18: =IF(K18="main","P"&TEXT(A18,"00"),IF(K18="reserve","R"&TEXT(A18-$B$7,"00"),"")) | M18: =IF(K18="main",INDEX(Assignment!$C$4:$C$51,MATCH(L18,Assignment!$A$4:$A$51,0)),"") | N18: =2*B18+IF(E18>=4,1,0) | O18: =MOD(N18,3)+1 | P18: =CHOOSE(O18,"S1","S3","S5") | Q18: =CHOOSE(O18,"S2","S4","S6") | T18: 46427 | U18: 0.4375 | V18: P07 | W18: 12 | X18: S5 | Y18: S6
A19: 8 | B19: =INT((A19-1)/$B$4) | C19: =WORKDAY($B$3,B19) | D19: =TEXT(C19,"dddd") | E19: =MOD(A19-1,$B$4)+1 | F19: =$B$5+(E19-1)*$B$6/1440 | G19: =F19+25/1440 | H19: =F19+45/1440 | I19: =F19+60/1440 | J19: =F19+$B$6/1440 | K19: =IF(A19<=$B$7,"main",IF(A19<=$B$7+$B$8,"reserve","open")) | L19: =IF(K19="main","P"&TEXT(A19,"00"),IF(K19="reserve","R"&TEXT(A19-$B$7,"00"),"")) | M19: =IF(K19="main",INDEX(Assignment!$C$4:$C$51,MATCH(L19,Assignment!$A$4:$A$51,0)),"") | N19: =2*B19+IF(E19>=4,1,0) | O19: =MOD(N19,3)+1 | P19: =CHOOSE(O19,"S1","S3","S5") | Q19: =CHOOSE(O19,"S2","S4","S6") | T19: 46427 | U19: 0.5 | V19: P08 | W19: 8 | X19: S5 | Y19: S6
A20: 9 | B20: =INT((A20-1)/$B$4) | C20: =WORKDAY($B$3,B20) | D20: =TEXT(C20,"dddd") | E20: =MOD(A20-1,$B$4)+1 | F20: =$B$5+(E20-1)*$B$6/1440 | G20: =F20+25/1440 | H20: =F20+45/1440 | I20: =F20+60/1440 | J20: =F20+$B$6/1440 | K20: =IF(A20<=$B$7,"main",IF(A20<=$B$7+$B$8,"reserve","open")) | L20: =IF(K20="main","P"&TEXT(A20,"00"),IF(K20="reserve","R"&TEXT(A20-$B$7,"00"),"")) | M20: =IF(K20="main",INDEX(Assignment!$C$4:$C$51,MATCH(L20,Assignment!$A$4:$A$51,0)),"") | N20: =2*B20+IF(E20>=4,1,0) | O20: =MOD(N20,3)+1 | P20: =CHOOSE(O20,"S1","S3","S5") | Q20: =CHOOSE(O20,"S2","S4","S6") | T20: 46427 | U20: 0.5625 | V20: P09 | W20: 7 | X20: S1 | Y20: S2
A21: 10 | B21: =INT((A21-1)/$B$4) | C21: =WORKDAY($B$3,B21) | D21: =TEXT(C21,"dddd") | E21: =MOD(A21-1,$B$4)+1 | F21: =$B$5+(E21-1)*$B$6/1440 | G21: =F21+25/1440 | H21: =F21+45/1440 | I21: =F21+60/1440 | J21: =F21+$B$6/1440 | K21: =IF(A21<=$B$7,"main",IF(A21<=$B$7+$B$8,"reserve","open")) | L21: =IF(K21="main","P"&TEXT(A21,"00"),IF(K21="reserve","R"&TEXT(A21-$B$7,"00"),"")) | M21: =IF(K21="main",INDEX(Assignment!$C$4:$C$51,MATCH(L21,Assignment!$A$4:$A$51,0)),"") | N21: =2*B21+IF(E21>=4,1,0) | O21: =MOD(N21,3)+1 | P21: =CHOOSE(O21,"S1","S3","S5") | Q21: =CHOOSE(O21,"S2","S4","S6") | T21: 46427 | U21: 0.625 | V21: P10 | W21: 11 | X21: S1 | Y21: S2
A22: 11 | B22: =INT((A22-1)/$B$4) | C22: =WORKDAY($B$3,B22) | D22: =TEXT(C22,"dddd") | E22: =MOD(A22-1,$B$4)+1 | F22: =$B$5+(E22-1)*$B$6/1440 | G22: =F22+25/1440 | H22: =F22+45/1440 | I22: =F22+60/1440 | J22: =F22+$B$6/1440 | K22: =IF(A22<=$B$7,"main",IF(A22<=$B$7+$B$8,"reserve","open")) | L22: =IF(K22="main","P"&TEXT(A22,"00"),IF(K22="reserve","R"&TEXT(A22-$B$7,"00"),"")) | M22: =IF(K22="main",INDEX(Assignment!$C$4:$C$51,MATCH(L22,Assignment!$A$4:$A$51,0)),"") | N22: =2*B22+IF(E22>=4,1,0) | O22: =MOD(N22,3)+1 | P22: =CHOOSE(O22,"S1","S3","S5") | Q22: =CHOOSE(O22,"S2","S4","S6") | T22: 46428 | U22: 0.375 | V22: P11 | W22: 6 | X22: S3 | Y22: S4
A23: 12 | B23: =INT((A23-1)/$B$4) | C23: =WORKDAY($B$3,B23) | D23: =TEXT(C23,"dddd") | E23: =MOD(A23-1,$B$4)+1 | F23: =$B$5+(E23-1)*$B$6/1440 | G23: =F23+25/1440 | H23: =F23+45/1440 | I23: =F23+60/1440 | J23: =F23+$B$6/1440 | K23: =IF(A23<=$B$7,"main",IF(A23<=$B$7+$B$8,"reserve","open")) | L23: =IF(K23="main","P"&TEXT(A23,"00"),IF(K23="reserve","R"&TEXT(A23-$B$7,"00"),"")) | M23: =IF(K23="main",INDEX(Assignment!$C$4:$C$51,MATCH(L23,Assignment!$A$4:$A$51,0)),"") | N23: =2*B23+IF(E23>=4,1,0) | O23: =MOD(N23,3)+1 | P23: =CHOOSE(O23,"S1","S3","S5") | Q23: =CHOOSE(O23,"S2","S4","S6") | T23: 46428 | U23: 0.4375 | V23: P12 | W23: 10 | X23: S3 | Y23: S4
... A59: 48 | B59: =INT((A59-1)/$B$4) | C59: =WORKDAY($B$3,B59) | D59: =TEXT(C59,"dddd") | E59: =MOD(A59-1,$B$4)+1 | F59: =$B$5+(E59-1)*$B$6/1440 | G59: =F59+25/1440 | H59: =F59+45/1440 | I59: =F59+60/1440 | J59: =F59+$B$6/1440 | K59: =IF(A59<=$B$7,"main",IF(A59<=$B$7+$B$8,"reserve","open")) | L59: =IF(K59="main","P"&TEXT(A59,"00"),IF(K59="reserve","R"&TEXT(A59-$B$7,"00"),"")) | M59: =IF(K59="main",INDEX(Assignment!$C$4:$C$51,MATCH(L59,Assignment!$A$4:$A$51,0)),"") | N59: =2*B59+IF(E59>=4,1,0) | O59: =MOD(N59,3)+1 | P59: =CHOOSE(O59,"S1","S3","S5") | Q59: =CHOOSE(O59,"S2","S4","S6") | T59: 46437 | U59: 0.5 | V59: P48 | W59: 3 | X59: S1 | Y59: S2
A60: 49 | B60: =INT((A60-1)/$B$4) | C60: =WORKDAY($B$3,B60) | D60: =TEXT(C60,"dddd") | E60: =MOD(A60-1,$B$4)+1 | F60: =$B$5+(E60-1)*$B$6/1440 | G60: =F60+25/1440 | H60: =F60+45/1440 | I60: =F60+60/1440 | J60: =F60+$B$6/1440 | K60: =IF(A60<=$B$7,"main",IF(A60<=$B$7+$B$8,"reserve","open")) | L60: =IF(K60="main","P"&TEXT(A60,"00"),IF(K60="reserve","R"&TEXT(A60-$B$7,"00"),"")) | M60: =IF(K60="main",INDEX(Assignment!$C$4:$C$51,MATCH(L60,Assignment!$A$4:$A$51,0)),"") | N60: =2*B60+IF(E60>=4,1,0) | O60: =MOD(N60,3)+1 | P60: =CHOOSE(O60,"S1","S3","S5") | Q60: =CHOOSE(O60,"S2","S4","S6") | T60: 46437 | U60: 0.5625 | V60: R01 | X60: S3 | Y60: S4
A61: 50 | B61: =INT((A61-1)/$B$4) | C61: =WORKDAY($B$3,B61) | D61: =TEXT(C61,"dddd") | E61: =MOD(A61-1,$B$4)+1 | F61: =$B$5+(E61-1)*$B$6/1440 | G61: =F61+25/1440 | H61: =F61+45/1440 | I61: =F61+60/1440 | J61: =F61+$B$6/1440 | K61: =IF(A61<=$B$7,"main",IF(A61<=$B$7+$B$8,"reserve","open")) | L61: =IF(K61="main","P"&TEXT(A61,"00"),IF(K61="reserve","R"&TEXT(A61-$B$7,"00"),"")) | M61: =IF(K61="main",INDEX(Assignment!$C$4:$C$51,MATCH(L61,Assignment!$A$4:$A$51,0)),"") | N61: =2*B61+IF(E61>=4,1,0) | O61: =MOD(N61,3)+1 | P61: =CHOOSE(O61,"S1","S3","S5") | Q61: =CHOOSE(O61,"S2","S4","S6") | T61: 46437 | U61: 0.625 | V61: R02 | X61: S3 | Y61: S4
A62: 51 | B62: =INT((A62-1)/$B$4) | C62: =WORKDAY($B$3,B62) | D62: =TEXT(C62,"dddd") | E62: =MOD(A62-1,$B$4)+1 | F62: =$B$5+(E62-1)*$B$6/1440 | G62: =F62+25/1440 | H62: =F62+45/1440 | I62: =F62+60/1440 | J62: =F62+$B$6/1440 | K62: =IF(A62<=$B$7,"main",IF(A62<=$B$7+$B$8,"reserve","open")) | L62: =IF(K62="main","P"&TEXT(A62,"00"),IF(K62="reserve","R"&TEXT(A62-$B$7,"00"),"")) | M62: =IF(K62="main",INDEX(Assignment!$C$4:$C$51,MATCH(L62,Assignment!$A$4:$A$51,0)),"") | N62: =2*B62+IF(E62>=4,1,0) | O62: =MOD(N62,3)+1 | P62: =CHOOSE(O62,"S1","S3","S5") | Q62: =CHOOSE(O62,"S2","S4","S6") | T62: 46440 | U62: 0.375 | V62: R03 | X62: S5 | Y62: S6
A63: 52 | B63: =INT((A63-1)/$B$4) | C63: =WORKDAY($B$3,B63) | D63: =TEXT(C63,"dddd") | E63: =MOD(A63-1,$B$4)+1 | F63: =$B$5+(E63-1)*$B$6/1440 | G63: =F63+25/1440 | H63: =F63+45/1440 | I63: =F63+60/1440 | J63: =F63+$B$6/1440 | K63: =IF(A63<=$B$7,"main",IF(A63<=$B$7+$B$8,"reserve","open")) | L63: =IF(K63="main","P"&TEXT(A63,"00"),IF(K63="reserve","R"&TEXT(A63-$B$7,"00"),"")) | M63: =IF(K63="main",INDEX(Assignment!$C$4:$C$51,MATCH(L63,Assignment!$A$4:$A$51,0)),"") | N63: =2*B63+IF(E63>=4,1,0) | O63: =MOD(N63,3)+1 | P63: =CHOOSE(O63,"S1","S3","S5") | Q63: =CHOOSE(O63,"S2","S4","S6") | T63: 46440 | U63: 0.4375 | V63: R04 | X63: S5 | Y63: S6
A64: 53 | B64: =INT((A64-1)/$B$4) | C64: =WORKDAY($B$3,B64) | D64: =TEXT(C64,"dddd") | E64: =MOD(A64-1,$B$4)+1 | F64: =$B$5+(E64-1)*$B$6/1440 | G64: =F64+25/1440 | H64: =F64+45/1440 | I64: =F64+60/1440 | J64: =F64+$B$6/1440 | K64: =IF(A64<=$B$7,"main",IF(A64<=$B$7+$B$8,"reserve","open")) | L64: =IF(K64="main","P"&TEXT(A64,"00"),IF(K64="reserve","R"&TEXT(A64-$B$7,"00"),"")) | M64: =IF(K64="main",INDEX(Assignment!$C$4:$C$51,MATCH(L64,Assignment!$A$4:$A$51,0)),"") | N64: =2*B64+IF(E64>=4,1,0) | O64: =MOD(N64,3)+1 | P64: =CHOOSE(O64,"S1","S3","S5") | Q64: =CHOOSE(O64,"S2","S4","S6") | T64: 46440 | U64: 0.5 | V64: R05 | X64: S5 | Y64: S6
A65: 54 | B65: =INT((A65-1)/$B$4) | C65: =WORKDAY($B$3,B65) | D65: =TEXT(C65,"dddd") | E65: =MOD(A65-1,$B$4)+1 | F65: =$B$5+(E65-1)*$B$6/1440 | G65: =F65+25/1440 | H65: =F65+45/1440 | I65: =F65+60/1440 | J65: =F65+$B$6/1440 | K65: =IF(A65<=$B$7,"main",IF(A65<=$B$7+$B$8,"reserve","open")) | L65: =IF(K65="main","P"&TEXT(A65,"00"),IF(K65="reserve","R"&TEXT(A65-$B$7,"00"),"")) | M65: =IF(K65="main",INDEX(Assignment!$C$4:$C$51,MATCH(L65,Assignment!$A$4:$A$51,0)),"") | N65: =2*B65+IF(E65>=4,1,0) | O65: =MOD(N65,3)+1 | P65: =CHOOSE(O65,"S1","S3","S5") | Q65: =CHOOSE(O65,"S2","S4","S6") | T65: 46440 | U65: 0.5625 | X65: S1 | Y65: S2
A66: 55 | B66: =INT((A66-1)/$B$4) | C66: =WORKDAY($B$3,B66) | D66: =TEXT(C66,"dddd") | E66: =MOD(A66-1,$B$4)+1 | F66: =$B$5+(E66-1)*$B$6/1440 | G66: =F66+25/1440 | H66: =F66+45/1440 | I66: =F66+60/1440 | J66: =F66+$B$6/1440 | K66: =IF(A66<=$B$7,"main",IF(A66<=$B$7+$B$8,"reserve","open")) | L66: =IF(K66="main","P"&TEXT(A66,"00"),IF(K66="reserve","R"&TEXT(A66-$B$7,"00"),"")) | M66: =IF(K66="main",INDEX(Assignment!$C$4:$C$51,MATCH(L66,Assignment!$A$4:$A$51,0)),"") | N66: =2*B66+IF(E66>=4,1,0) | O66: =MOD(N66,3)+1 | P66: =CHOOSE(O66,"S1","S3","S5") | Q66: =CHOOSE(O66,"S2","S4","S6") | T66: 46440 | U66: 0.625 | X66: S1 | Y66: S2

Sheet Check
A1: Excel results next to the values that plan_power.R produced (PLANNED / SIMULATED). Tolerance: half a unit in the last printed decimal, or the stated tolerance for an approximation.
A3: Result | B3: Excel | C3: R | D3: Difference | E3: Tolerance | F3: Status
A4: SampleSize: n, corrected, d_z = 0.300 (R: power.t.test n) | B4: =SampleSize!D14 | C4: 89.149577 | D4: =B4-C4 | E4: 0.25 | F4: =IF(ABS(D4)<=E4+1E-12,"OK","CHECK")
A5: SampleSize: n needed, d_z = 0.300 | B5: =SampleSize!E14 | C5: 90 | D5: =B5-C5 | E5: 1e-09 | F5: =IF(ABS(D5)<=E5+1E-12,"OK","CHECK")
A6: SampleSize: Holm: n, corrected, d_z = 0.300 (R: power.t.test n) | B6: =SampleSize!G14 | C6: 119.20402 | D6: =B6-C6 | E6: 0.25 | F6: =IF(ABS(D6)<=E6+1E-12,"OK","CHECK")
A7: SampleSize: Holm: n needed, d_z = 0.300 | B7: =SampleSize!H14 | C7: 120 | D7: =B7-C7 | E7: 1e-09 | F7: =IF(ABS(D7)<=E7+1E-12,"OK","CHECK")
A8: SampleSize: power at 48, d_z = 0.300 (R: power.t.test) | B8: =SampleSize!I14 | C8: 0.53026278 | D8: =B8-C8 | E8: 0.005 | F8: =IF(ABS(D8)<=E8+1E-12,"OK","CHECK")
A9: SampleSize: Holm: power at 48, d_z = 0.300 (R: power.t.test) | B9: =SampleSize!J14 | C9: 0.35246395 | D9: =B9-C9 | E9: 0.005 | F9: =IF(ABS(D9)<=E9+1E-12,"OK","CHECK")
A10: SampleSize: n, corrected, d_z = 0.500 (R: power.t.test n) | B10: =SampleSize!D15 | C10: 33.367204 | D10: =B10-C10 | E10: 0.25 | F10: =IF(ABS(D10)<=E10+1E-12,"OK","CHECK")
A11: SampleSize: n needed, d_z = 0.500 | B11: =SampleSize!E15 | C11: 34 | D11: =B11-C11 | E11: 1e-09 | F11: =IF(ABS(D11)<=E11+1E-12,"OK","CHECK")
A12: SampleSize: Holm: n, corrected, d_z = 0.500 (R: power.t.test n) | B12: =SampleSize!G15 | C12: 44.780871 | D12: =B12-C12 | E12: 0.25 | F12: =IF(ABS(D12)<=E12+1E-12,"OK","CHECK")
A13: SampleSize: Holm: n needed, d_z = 0.500 | B13: =SampleSize!H15 | C13: 45 | D13: =B13-C13 | E13: 1e-09 | F13: =IF(ABS(D13)<=E13+1E-12,"OK","CHECK")
A14: SampleSize: power at 48, d_z = 0.500 (R: power.t.test) | B14: =SampleSize!I15 | C14: 0.92400332 | D14: =B14-C14 | E14: 0.005 | F14: =IF(ABS(D14)<=E14+1E-12,"OK","CHECK")
A15: SampleSize: Holm: power at 48, d_z = 0.500 (R: power.t.test) | B15: =SampleSize!J15 | C15: 0.83239367 | D15: =B15-C15 | E15: 0.005 | F15: =IF(ABS(D15)<=E15+1E-12,"OK","CHECK")
A16: SampleSize: n, corrected, d_z = 0.355 (R: power.t.test n) | B16: =SampleSize!D16 | C16: 64.073852 | D16: =B16-C16 | E16: 0.25 | F16: =IF(ABS(D16)<=E16+1E-12,"OK","CHECK")
A17: SampleSize: n needed, d_z = 0.355 | B17: =SampleSize!E16 | C17: 65 | D17: =B17-C17 | E17: 1e-09 | F17: =IF(ABS(D17)<=E17+1E-12,"OK","CHECK")
A18: SampleSize: Holm: n, corrected, d_z = 0.355 (R: power.t.test n) | B18: =SampleSize!G16 | C18: 85.752885 | D18: =B18-C18 | E18: 0.25 | F18: =IF(ABS(D18)<=E18+1E-12,"OK","CHECK")
A19: SampleSize: Holm: n needed, d_z = 0.355 | B19: =SampleSize!H16 | C19: 86 | D19: =B19-C19 | E19: 1e-09 | F19: =IF(ABS(D19)<=E19+1E-12,"OK","CHECK")
A20: SampleSize: power at 48, d_z = 0.355 (R: power.t.test) | B20: =SampleSize!I16 | C20: 0.6743747 | D20: =B20-C20 | E20: 0.005 | F20: =IF(ABS(D20)<=E20+1E-12,"OK","CHECK")
A21: SampleSize: Holm: power at 48, d_z = 0.355 (R: power.t.test) | B21: =SampleSize!J16 | C21: 0.4974108 | D21: =B21-C21 | E21: 0.005 | F21: =IF(ABS(D21)<=E21+1E-12,"OK","CHECK")
A22: SampleSize: n, corrected, d_z = 0.826 (R: power.t.test n) | B22: =SampleSize!D17 | C22: 13.549554 | D22: =B22-C22 | E22: 0.25 | F22: =IF(ABS(D22)<=E22+1E-12,"OK","CHECK")
A23: SampleSize: n needed, d_z = 0.826 | B23: =SampleSize!E17 | C23: 14 | D23: =B23-C23 | E23: 1e-09 | F23: =IF(ABS(D23)<=E23+1E-12,"OK","CHECK")
A24: SampleSize: Holm: n, corrected, d_z = 0.826 (R: power.t.test n) | B24: =SampleSize!G17 | C24: 18.29882 | D24: =B24-C24 | E24: 0.25 | F24: =IF(ABS(D24)<=E24+1E-12,"OK","CHECK")
A25: SampleSize: Holm: n needed, d_z = 0.826 | B25: =SampleSize!H17 | C25: 19 | D25: =B25-C25 | E25: 1e-09 | F25: =IF(ABS(D25)<=E25+1E-12,"OK","CHECK")
A26: SampleSize: power at 48, d_z = 0.826 (R: power.t.test) | B26: =SampleSize!I17 | C26: 0.99986504 | D26: =B26-C26 | E26: 0.005 | F26: =IF(ABS(D26)<=E26+1E-12,"OK","CHECK")
A27: SampleSize: Holm: power at 48, d_z = 0.826 (R: power.t.test) | B27: =SampleSize!J17 | C27: 0.99918253 | D27: =B27-C27 | E27: 0.005 | F27: =IF(ABS(D27)<=E27+1E-12,"OK","CHECK")
A28: SampleSize: approximate power, 48 participants, 2 ads per brand (R: exact formula) | B28: =SampleSize!G26 | C28: 0.2134948 | D28: =B28-C28 | E28: 0.02 | F28: =IF(ABS(D28)<=E28+1E-12,"OK","CHECK")
A29: SampleSize: approximate power, 48 participants, 3 ads per brand (R: exact formula) | B29: =SampleSize!G27 | C29: 0.45141084 | D29: =B29-C29 | E29: 0.02 | F29: =IF(ABS(D29)<=E29+1E-12,"OK","CHECK")
A30: SampleSize: approximate power, 48 participants, 4 ads per brand (R: exact formula) | B30: =SampleSize!G28 | C30: 0.64330912 | D30: =B30-C30 | E30: 0.02 | F30: =IF(ABS(D30)<=E30+1E-12,"OK","CHECK")
A31: SampleSize: approximate power, 48 participants, 6 ads per brand (R: exact formula) | B31: =SampleSize!G29 | C31: 0.86614042 | D31: =B31-C31 | E31: 0.02 | F31: =IF(ABS(D31)<=E31+1E-12,"OK","CHECK")
A32: SampleSize: approximate power, 72 participants, 2 ads per brand (R: exact formula) | B32: =SampleSize!G30 | C32: 0.23475562 | D32: =B32-C32 | E32: 0.02 | F32: =IF(ABS(D32)<=E32+1E-12,"OK","CHECK")
A33: SampleSize: approximate power, 72 participants, 3 ads per brand (R: exact formula) | B33: =SampleSize!G31 | C33: 0.50030817 | D33: =B33-C33 | E33: 0.02 | F33: =IF(ABS(D33)<=E33+1E-12,"OK","CHECK")
A34: SampleSize: approximate power, 72 participants, 4 ads per brand (R: exact formula) | B34: =SampleSize!G32 | C34: 0.70070855 | D34: =B34-C34 | E34: 0.02 | F34: =IF(ABS(D34)<=E34+1E-12,"OK","CHECK")
A35: SampleSize: approximate power, 72 participants, 6 ads per brand (R: exact formula) | B35: =SampleSize!G33 | C35: 0.90675158 | D35: =B35-C35 | E35: 0.02 | F35: =IF(ABS(D35)<=E35+1E-12,"OK","CHECK")
A36: Attrition: Exclusion rate in the lab (Workshop 7) | B36: =Attrition!B15 | C36: 0.0833 | D36: =B36-C36 | E36: 5e-05 | F36: =IF(ABS(D36)<=E36+1E-12,"OK","CHECK")
A37: Attrition: Sessions to book (main + reserve) | B37: =Attrition!B17 | C37: 53 | D37: =B37-C37 | E37: 1e-09 | F37: =IF(ABS(D37)<=E37+1E-12,"OK","CHECK")
A38: Attrition: Reserve sessions | B38: =Attrition!B18 | C38: 5 | D38: =B38-C38 | E38: 1e-09 | F38: =IF(ABS(D38)<=E38+1E-12,"OK","CHECK")
A39: Attrition: Hard cap on sessions | B39: =Attrition!B19 | C39: 60 | D39: =B39-C39 | E39: 1e-09 | F39: =IF(ABS(D39)<=E39+1E-12,"OK","CHECK")
A40: Attrition: Weekdays of data collection | B40: =Attrition!B20 | C40: 11 | D40: =B40-C40 | E40: 1e-09 | F40: =IF(ABS(D40)<=E40+1E-12,"OK","CHECK")
A41: Attrition: Slots on those days | B41: =Attrition!B21 | C41: 55 | D41: =B41-C41 | E41: 1e-09 | F41: =IF(ABS(D41)<=E41+1E-12,"OK","CHECK")
...
