Workbook

Sheet README
A1: SIMULATED remote study workbook (teaching material): webcam eye tracking and webcam facial expression analysis
A3: Every number in this workbook is SIMULATED. It was generated by make_simulated_data.py (seed 20276200) in the style of the iMotions
A4: vendor demo (DEMO) Food Waste_webET_FEA_voice: every respondent saw two one minute food waste videos (foodwaste_narrative and
A5: foodwaste_visual) in random order, then an infographic with four tips (15 s), then a questionnaire. Remote Data Collection study built in
A6: iMotions Lab 11.1, run through my.imotions.com, downloaded, and processed in Lab (Post Processing > Affectiva, FEA thresholding at 50).
A7: No real person was recorded.
A9: Each order of the videos is its own study flow: Study flow 1 = narrative first, Study flow 2 = visual first (the Block column).
A11: Sheets:
A12: Session Session data as downloaded (columns A to J, rows 2 to 261); helper columns K to O are live formulas.
A13: Funnel Sessions entering and stopping at each step of the respondent funnel; completion by order (chi square); by device.
A14: Quality Quality table (MODELED layout): accuracy at the two calibrations, eye tracking quality and face quality per slide.
A15: Screening The exclusion rule, one row per completed respondent; the thresholds are in yellow cells and can be changed.
... A30: Companion files: analysis_excel_walkthrough.md (step by step), analysis.R, analysis_output.txt, results_text.md.

Sheet Session
A1: Id | B1: Started | C1: Ended | D1: Eye tracking | E1: Est. face % | F1: Block | G1: Status | H1: Last funnel step (modeled) | I1: Device type (modeled) | J1: Browser (modeled) | K1: Step number | L1: Completed (1 = yes) | M1: Order | N1: Session accuracy (degrees) | O1: Session quality (%)
A2: RESP0001 | B2: 46447.421 | C2: 46447.427 | D2: 1.3, 95% | E2: 99 | F2: Study flow 2 | G2: Processed | H2: Completed | I2: Laptop | J2: Firefox | K2: =IF(H2="Completed",11,VALUE(MID(H2,6,FIND(" ",H2,6)-6))) | L2: =IF(G2="Processed",1,0) | M2: =IF(F2="Study flow 1","Narrative first","Visual first") | N2: =IF(D2="","",VALUE(LEFT(D2,FIND(",",D2)-1))) | O2: =IF(D2="","",VALUE(SUBSTITUTE(MID(D2,FIND(",",D2)+2,10),"%","")))
A3: RESP0002 | B3: 46447.429 | C3: 46447.435 | D3: 2.7, 95% | E3: 98 | F3: Study flow 1 | G3: Processed | H3: Completed | I3: Laptop | J3: Chrome | K3: =IF(H3="Completed",11,VALUE(MID(H3,6,FIND(" ",H3,6)-6))) | L3: =IF(G3="Processed",1,0) | M3: =IF(F3="Study flow 1","Narrative first","Visual first") | N3: =IF(D3="","",VALUE(LEFT(D3,FIND(",",D3)-1))) | O3: =IF(D3="","",VALUE(SUBSTITUTE(MID(D3,FIND(",",D3)+2,10),"%","")))
A4: RESP0003 | B4: 46447.465 | C4: 46447.471 | D4: 1.5, 96% | E4: 86 | F4: Study flow 2 | G4: Processed | H4: Completed | I4: Laptop | J4: Safari | K4: =IF(H4="Completed",11,VALUE(MID(H4,6,FIND(" ",H4,6)-6))) | L4: =IF(G4="Processed",1,0) | M4: =IF(F4="Study flow 1","Narrative first","Visual first") | N4: =IF(D4="","",VALUE(LEFT(D4,FIND(",",D4)-1))) | O4: =IF(D4="","",VALUE(SUBSTITUTE(MID(D4,FIND(",",D4)+2,10),"%","")))
A5: RESP0004 | B5: 46447.49 | C5: 46447.496 | D5: 3.0, 95% | E5: 96 | F5: Study flow 2 | G5: Processed | H5: Completed | I5: Desktop | J5: Safari | K5: =IF(H5="Completed",11,VALUE(MID(H5,6,FIND(" ",H5,6)-6))) | L5: =IF(G5="Processed",1,0) | M5: =IF(F5="Study flow 1","Narrative first","Visual first") | N5: =IF(D5="","",VALUE(LEFT(D5,FIND(",",D5)-1))) | O5: =IF(D5="","",VALUE(SUBSTITUTE(MID(D5,FIND(",",D5)+2,10),"%","")))
A6: RESP0005 | B6: 46447.503 | C6: 46447.509 | D6: 1.1, 99% | E6: 92 | F6: Study flow 2 | G6: Processed | H6: Completed | I6: Laptop | J6: Safari | K6: =IF(H6="Completed",11,VALUE(MID(H6,6,FIND(" ",H6,6)-6))) | L6: =IF(G6="Processed",1,0) | M6: =IF(F6="Study flow 1","Narrative first","Visual first") | N6: =IF(D6="","",VALUE(LEFT(D6,FIND(",",D6)-1))) | O6: =IF(D6="","",VALUE(SUBSTITUTE(MID(D6,FIND(",",D6)+2,10),"%","")))
A7: RESP0006 | B7: 46447.53 | C7: 46447.536 | D7: 1.7, 97% | E7: 99 | F7: Study flow 2 | G7: Processed | H7: Completed | I7: Laptop | J7: Chrome | K7: =IF(H7="Completed",11,VALUE(MID(H7,6,FIND(" ",H7,6)-6))) | L7: =IF(G7="Processed",1,0) | M7: =IF(F7="Study flow 1","Narrative first","Visual first") | N7: =IF(D7="","",VALUE(LEFT(D7,FIND(",",D7)-1))) | O7: =IF(D7="","",VALUE(SUBSTITUTE(MID(D7,FIND(",",D7)+2,10),"%","")))
A8: RESP0007 | B8: 46447.59 | C8: 46447.596 | D8: 1.8, 97% | E8: 96 | F8: Study flow 1 | G8: Processed | H8: Completed | I8: Laptop | J8: Chrome | K8: =IF(H8="Completed",11,VALUE(MID(H8,6,FIND(" ",H8,6)-6))) | L8: =IF(G8="Processed",1,0) | M8: =IF(F8="Study flow 1","Narrative first","Visual first") | N8: =IF(D8="","",VALUE(LEFT(D8,FIND(",",D8)-1))) | O8: =IF(D8="","",VALUE(SUBSTITUTE(MID(D8,FIND(",",D8)+2,10),"%","")))
A9: RESP0008 | B9: 46447.683 | F9: Study flow 1 | G9: Abandoned | H9: STEP 8 Positioning check | I9: Laptop | J9: Edge | K9: =IF(H9="Completed",11,VALUE(MID(H9,6,FIND(" ",H9,6)-6))) | L9: =IF(G9="Processed",1,0) | M9: =IF(F9="Study flow 1","Narrative first","Visual first") | N9: =IF(D9="","",VALUE(LEFT(D9,FIND(",",D9)-1))) | O9: =IF(D9="","",VALUE(SUBSTITUTE(MID(D9,FIND(",",D9)+2,10),"%","")))
A10: RESP0009 | B10: 46447.689 | C10: 46447.695 | D10: 3.1, 94% | E10: 97 | F10: Study flow 1 | G10: Processed | H10: Completed | I10: Laptop | J10: Firefox | K10: =IF(H10="Completed",11,VALUE(MID(H10,6,FIND(" ",H10,6)-6))) | L10: =IF(G10="Processed",1,0) | M10: =IF(F10="Study flow 1","Narrative first","Visual first") | N10: =IF(D10="","",VALUE(LEFT(D10,FIND(",",D10)-1))) | O10: =IF(D10="","",VALUE(SUBSTITUTE(MID(D10,FIND(",",D10)+2,10),"%","")))
A11: RESP0010 | B11: 46447.713 | C11: 46447.718 | D11: 2.3, 97% | E11: 99 | F11: Study flow 1 | G11: Processed | H11: Completed | I11: Laptop | J11: Chrome | K11: =IF(H11="Completed",11,VALUE(MID(H11,6,FIND(" ",H11,6)-6))) | L11: =IF(G11="Processed",1,0) | M11: =IF(F11="Study flow 1","Narrative first","Visual first") | N11: =IF(D11="","",VALUE(LEFT(D11,FIND(",",D11)-1))) | O11: =IF(D11="","",VALUE(SUBSTITUTE(MID(D11,FIND(",",D11)+2,10),"%","")))
A12: RESP0011 | B12: 46447.739 | F12: Study flow 2 | G12: Abandoned | H12: STEP 4 Respondent camera setup | I12: Laptop | J12: Safari | K12: =IF(H12="Completed",11,VALUE(MID(H12,6,FIND(" ",H12,6)-6))) | L12: =IF(G12="Processed",1,0) | M12: =IF(F12="Study flow 1","Narrative first","Visual first") | N12: =IF(D12="","",VALUE(LEFT(D12,FIND(",",D12)-1))) | O12: =IF(D12="","",VALUE(SUBSTITUTE(MID(D12,FIND(",",D12)+2,10),"%","")))
A13: RESP0012 | B13: 46447.747 | C13: 46447.753 | D13: 1.7, 97% | E13: 99 | F13: Study flow 2 | G13: Processed | H13: Completed | I13: Desktop | J13: Chrome | K13: =IF(H13="Completed",11,VALUE(MID(H13,6,FIND(" ",H13,6)-6))) | L13: =IF(G13="Processed",1,0) | M13: =IF(F13="Study flow 1","Narrative first","Visual first") | N13: =IF(D13="","",VALUE(LEFT(D13,FIND(",",D13)-1))) | O13: =IF(D13="","",VALUE(SUBSTITUTE(MID(D13,FIND(",",D13)+2,10),"%","")))
A14: RESP0013 | B14: 46447.761 | C14: 46447.767 | D14: 2.2, 90% | E14: 96 | F14: Study flow 2 | G14: Processed | H14: Completed | I14: Laptop | J14: Chrome | K14: =IF(H14="Completed",11,VALUE(MID(H14,6,FIND(" ",H14,6)-6))) | L14: =IF(G14="Processed",1,0) | M14: =IF(F14="Study flow 1","Narrative first","Visual first") | N14: =IF(D14="","",VALUE(LEFT(D14,FIND(",",D14)-1))) | O14: =IF(D14="","",VALUE(SUBSTITUTE(MID(D14,FIND(",",D14)+2,10),"%","")))
A15: RESP0014 | B15: 46447.764 | C15: 46447.77 | D15: 2.0, 96% | E15: 99 | F15: Study flow 2 | G15: Processed | H15: Completed | I15: Laptop | J15: Chrome | K15: =IF(H15="Completed",11,VALUE(MID(H15,6,FIND(" ",H15,6)-6))) | L15: =IF(G15="Processed",1,0) | M15: =IF(F15="Study flow 1","Narrative first","Visual first") | N15: =IF(D15="","",VALUE(LEFT(D15,FIND(",",D15)-1))) | O15: =IF(D15="","",VALUE(SUBSTITUTE(MID(D15,FIND(",",D15)+2,10),"%","")))
A16: RESP0015 | B16: 46447.769 | C16: 46447.775 | D16: 1.5, 93% | E16: 90 | F16: Study flow 1 | G16: Processed | H16: Completed | I16: Laptop | J16: Safari | K16: =IF(H16="Completed",11,VALUE(MID(H16,6,FIND(" ",H16,6)-6))) | L16: =IF(G16="Processed",1,0) | M16: =IF(F16="Study flow 1","Narrative first","Visual first") | N16: =IF(D16="","",VALUE(LEFT(D16,FIND(",",D16)-1))) | O16: =IF(D16="","",VALUE(SUBSTITUTE(MID(D16,FIND(",",D16)+2,10),"%","")))
A17: RESP0016 | B17: 46447.779 | C17: 46447.785 | D17: 0.7, 97% | E17: 99 | F17: Study flow 2 | G17: Processed | H17: Completed | I17: Desktop | J17: Chrome | K17: =IF(H17="Completed",11,VALUE(MID(H17,6,FIND(" ",H17,6)-6))) | L17: =IF(G17="Processed",1,0) | M17: =IF(F17="Study flow 1","Narrative first","Visual first") | N17: =IF(D17="","",VALUE(LEFT(D17,FIND(",",D17)-1))) | O17: =IF(D17="","",VALUE(SUBSTITUTE(MID(D17,FIND(",",D17)+2,10),"%","")))
A18: RESP0017 | B18: 46447.797 | F18: Study flow 2 | G18: Abandoned | H18: STEP 5 Screen size | I18: Phone | J18: Chrome | K18: =IF(H18="Completed",11,VALUE(MID(H18,6,FIND(" ",H18,6)-6))) | L18: =IF(G18="Processed",1,0) | M18: =IF(F18="Study flow 1","Narrative first","Visual first") | N18: =IF(D18="","",VALUE(LEFT(D18,FIND(",",D18)-1))) | O18: =IF(D18="","",VALUE(SUBSTITUTE(MID(D18,FIND(",",D18)+2,10),"%","")))
A19: RESP0018 | B19: 46447.805 | F19: Study flow 2 | G19: Abandoned | H19: STEP 4 Respondent camera setup | I19: Laptop | J19: Chrome | K19: =IF(H19="Completed",11,VALUE(MID(H19,6,FIND(" ",H19,6)-6))) | L19: =IF(G19="Processed",1,0) | M19: =IF(F19="Study flow 1","Narrative first","Visual first") | N19: =IF(D19="","",VALUE(LEFT(D19,FIND(",",D19)-1))) | O19: =IF(D19="","",VALUE(SUBSTITUTE(MID(D19,FIND(",",D19)+2,10),"%","")))
A20: RESP0019 | B20: 46447.831 | C20: 46447.837 | D20: 2.9, 97% | E20: 99 | F20: Study flow 1 | G20: Processed | H20: Completed | I20: Desktop | J20: Chrome | K20: =IF(H20="Completed",11,VALUE(MID(H20,6,FIND(" ",H20,6)-6))) | L20: =IF(G20="Processed",1,0) | M20: =IF(F20="Study flow 1","Narrative first","Visual first") | N20: =IF(D20="","",VALUE(LEFT(D20,FIND(",",D20)-1))) | O20: =IF(D20="","",VALUE(SUBSTITUTE(MID(D20,FIND(",",D20)+2,10),"%","")))
A21: RESP0020 | B21: 46447.832 | C21: 46447.837 | D21: 3.6, 94% | E21: 98 | F21: Study flow 1 | G21: Processed | H21: Completed | I21: Laptop | J21: Chrome | K21: =IF(H21="Completed",11,VALUE(MID(H21,6,FIND(" ",H21,6)-6))) | L21: =IF(G21="Processed",1,0) | M21: =IF(F21="Study flow 1","Narrative first","Visual first") | N21: =IF(D21="","",VALUE(LEFT(D21,FIND(",",D21)-1))) | O21: =IF(D21="","",VALUE(SUBSTITUTE(MID(D21,FIND(",",D21)+2,10),"%","")))
A22: RESP0021 | B22: 46447.836 | F22: Study flow 2 | G22: Abandoned | H22: STEP 4 Respondent camera setup | I22: Laptop | J22: Safari | K22: =IF(H22="Completed",11,VALUE(MID(H22,6,FIND(" ",H22,6)-6))) | L22: =IF(G22="Processed",1,0) | M22: =IF(F22="Study flow 1","Narrative first","Visual first") | N22: =IF(D22="","",VALUE(LEFT(D22,FIND(",",D22)-1))) | O22: =IF(D22="","",VALUE(SUBSTITUTE(MID(D22,FIND(",",D22)+2,10),"%","")))
A23: RESP0022 | B23: 46447.841 | C23: 46447.847 | D23: 2.5, 95% | E23: 99 | F23: Study flow 1 | G23: Processed | H23: Completed | I23: Laptop | J23: Edge | K23: =IF(H23="Completed",11,VALUE(MID(H23,6,FIND(" ",H23,6)-6))) | L23: =IF(G23="Processed",1,0) | M23: =IF(F23="Study flow 1","Narrative first","Visual first") | N23: =IF(D23="","",VALUE(LEFT(D23,FIND(",",D23)-1))) | O23: =IF(D23="","",VALUE(SUBSTITUTE(MID(D23,FIND(",",D23)+2,10),"%","")))
A24: RESP0023 | B24: 46447.842 | C24: 46447.848 | D24: 1.7, 94% | E24: 93 | F24: Study flow 1 | G24: Processed | H24: Completed | I24: Desktop | J24: Chrome | K24: =IF(H24="Completed",11,VALUE(MID(H24,6,FIND(" ",H24,6)-6))) | L24: =IF(G24="Processed",1,0) | M24: =IF(F24="Study flow 1","Narrative first","Visual first") | N24: =IF(D24="","",VALUE(LEFT(D24,FIND(",",D24)-1))) | O24: =IF(D24="","",VALUE(SUBSTITUTE(MID(D24,FIND(",",D24)+2,10),"%","")))
A25: RESP0024 | B25: 46447.886 | C25: 46447.891 | D25: 1.8, 99% | E25: 99 | F25: Study flow 2 | G25: Processed | H25: Completed | I25: Desktop | J25: Edge | K25: =IF(H25="Completed",11,VALUE(MID(H25,6,FIND(" ",H25,6)-6))) | L25: =IF(G25="Processed",1,0) | M25: =IF(F25="Study flow 1","Narrative first","Visual first") | N25: =IF(D25="","",VALUE(LEFT(D25,FIND(",",D25)-1))) | O25: =IF(D25="","",VALUE(SUBSTITUTE(MID(D25,FIND(",",D25)+2,10),"%","")))
A26: RESP0025 | B26: 46447.888 | C26: 46447.894 | D26: 1.2, 99% | E26: 99 | F26: Study flow 1 | G26: Processed | H26: Completed | I26: Laptop | J26: Chrome | K26: =IF(H26="Completed",11,VALUE(MID(H26,6,FIND(" ",H26,6)-6))) | L26: =IF(G26="Processed",1,0) | M26: =IF(F26="Study flow 1","Narrative first","Visual first") | N26: =IF(D26="","",VALUE(LEFT(D26,FIND(",",D26)-1))) | O26: =IF(D26="","",VALUE(SUBSTITUTE(MID(D26,FIND(",",D26)+2,10),"%","")))
A27: RESP0026 | B27: 46447.889 | C27: 46447.896 | D27: 1.7, 94% | E27: 95 | F27: Study flow 1 | G27: Processed | H27: Completed | I27: Desktop | J27: Chrome | K27: =IF(H27="Completed",11,VALUE(MID(H27,6,FIND(" ",H27,6)-6))) | L27: =IF(G27="Processed",1,0) | M27: =IF(F27="Study flow 1","Narrative first","Visual first") | N27: =IF(D27="","",VALUE(LEFT(D27,FIND(",",D27)-1))) | O27: =IF(D27="","",VALUE(SUBSTITUTE(MID(D27,FIND(",",D27)+2,10),"%","")))
A28: RESP0027 | B28: 46447.904 | F28: Study flow 1 | G28: Abandoned | H28: STEP 2 Consent screen | I28: Laptop | J28: Edge | K28: =IF(H28="Completed",11,VALUE(MID(H28,6,FIND(" ",H28,6)-6))) | L28: =IF(G28="Processed",1,0) | M28: =IF(F28="Study flow 1","Narrative first","Visual first") | N28: =IF(D28="","",VALUE(LEFT(D28,FIND(",",D28)-1))) | O28: =IF(D28="","",VALUE(SUBSTITUTE(MID(D28,FIND(",",D28)+2,10),"%","")))
A29: RESP0028 | B29: 46448.508 | C29: 46448.515 | D29: 3.2, 84% | E29: 99 | F29: Study flow 1 | G29: Processed | H29: Completed | I29: Laptop | J29: Edge | K29: =IF(H29="Completed",11,VALUE(MID(H29,6,FIND(" ",H29,6)-6))) | L29: =IF(G29="Processed",1,0) | M29: =IF(F29="Study flow 1","Narrative first","Visual first") | N29: =IF(D29="","",VALUE(LEFT(D29,FIND(",",D29)-1))) | O29: =IF(D29="","",VALUE(SUBSTITUTE(MID(D29,FIND(",",D29)+2,10),"%","")))
A30: RESP0029 | B30: 46448.545 | C30: 46448.551 | D30: 2.4, 97% | E30: 99 | F30: Study flow 2 | G30: Processed | H30: Completed | I30: Laptop | J30: Chrome | K30: =IF(H30="Completed",11,VALUE(MID(H30,6,FIND(" ",H30,6)-6))) | L30: =IF(G30="Processed",1,0) | M30: =IF(F30="Study flow 1","Narrative first","Visual first") | N30: =IF(D30="","",VALUE(LEFT(D30,FIND(",",D30)-1))) | O30: =IF(D30="","",VALUE(SUBSTITUTE(MID(D30,FIND(",",D30)+2,10),"%","")))
A31: RESP0030 | B31: 46448.606 | F31: Study flow 1 | G31: Abandoned | H31: STEP 5 Screen size | I31: Phone | J31: Safari | K31: =IF(H31="Completed",11,VALUE(MID(H31,6,FIND(" ",H31,6)-6))) | L31: =IF(G31="Processed",1,0) | M31: =IF(F31="Study flow 1","Narrative first","Visual first") | N31: =IF(D31="","",VALUE(LEFT(D31,FIND(",",D31)-1))) | O31: =IF(D31="","",VALUE(SUBSTITUTE(MID(D31,FIND(",",D31)+2,10),"%","")))
A32: RESP0031 | B32: 46448.657 | C32: 46448.662 | D32: 2.9, 93% | E32: 100 | F32: Study flow 1 | G32: Processed | H32: Completed | I32: Desktop | J32: Chrome | K32: =IF(H32="Completed",11,VALUE(MID(H32,6,FIND(" ",H32,6)-6))) | L32: =IF(G32="Processed",1,0) | M32: =IF(F32="Study flow 1","Narrative first","Visual first") | N32: =IF(D32="","",VALUE(LEFT(D32,FIND(",",D32)-1))) | O32: =IF(D32="","",VALUE(SUBSTITUTE(MID(D32,FIND(",",D32)+2,10),"%","")))
A33: RESP0032 | B33: 46448.658 | C33: 46448.665 | D33: 1.7, 95% | E33: 85 | F33: Study flow 1 | G33: Processed | H33: Completed | I33: Laptop | J33: Chrome | K33: =IF(H33="Completed",11,VALUE(MID(H33,6,FIND(" ",H33,6)-6))) | L33: =IF(G33="Processed",1,0) | M33: =IF(F33="Study flow 1","Narrative first","Visual first") | N33: =IF(D33="","",VALUE(LEFT(D33,FIND(",",D33)-1))) | O33: =IF(D33="","",VALUE(SUBSTITUTE(MID(D33,FIND(",",D33)+2,10),"%","")))
A34: RESP0033 | B34: 46448.662 | F34: Study flow 2 | G34: Abandoned | H34: STEP 5 Screen size | I34: Tablet | J34: Safari | K34: =IF(H34="Completed",11,VALUE(MID(H34,6,FIND(" ",H34,6)-6))) | L34: =IF(G34="Processed",1,0) | M34: =IF(F34="Study flow 1","Narrative first","Visual first") | N34: =IF(D34="","",VALUE(LEFT(D34,FIND(",",D34)-1))) | O34: =IF(D34="","",VALUE(SUBSTITUTE(MID(D34,FIND(",",D34)+2,10),"%","")))
A35: RESP0034 | B35: 46448.7 | F35: Study flow 1 | G35: Abandoned | H35: STEP 5 Screen size | I35: Tablet | J35: Chrome | K35: =IF(H35="Completed",11,VALUE(MID(H35,6,FIND(" ",H35,6)-6))) | L35: =IF(G35="Processed",1,0) | M35: =IF(F35="Study flow 1","Narrative first","Visual first") | N35: =IF(D35="","",VALUE(LEFT(D35,FIND(",",D35)-1))) | O35: =IF(D35="","",VALUE(SUBSTITUTE(MID(D35,FIND(",",D35)+2,10),"%","")))
A36: RESP0035 | B36: 46448.704 | C36: 46448.71 | D36: 1.4, 98% | E36: 99 | F36: Study flow 1 | G36: Processed | H36: Completed | I36: Laptop | J36: Chrome | K36: =IF(H36="Completed",11,VALUE(MID(H36,6,FIND(" ",H36,6)-6))) | L36: =IF(G36="Processed",1,0) | M36: =IF(F36="Study flow 1","Narrative first","Visual first") | N36: =IF(D36="","",VALUE(LEFT(D36,FIND(",",D36)-1))) | O36: =IF(D36="","",VALUE(SUBSTITUTE(MID(D36,FIND(",",D36)+2,10),"%","")))
A37: RESP0036 | B37: 46448.715 | C37: 46448.722 | D37: 1.5, 96% | E37: 99 | F37: Study flow 1 | G37: Processed | H37: Completed | I37: Desktop | J37: Edge | K37: =IF(H37="Completed",11,VALUE(MID(H37,6,FIND(" ",H37,6)-6))) | L37: =IF(G37="Processed",1,0) | M37: =IF(F37="Study flow 1","Narrative first","Visual first") | N37: =IF(D37="","",VALUE(LEFT(D37,FIND(",",D37)-1))) | O37: =IF(D37="","",VALUE(SUBSTITUTE(MID(D37,FIND(",",D37)+2,10),"%","")))
A38: RESP0037 | B38: 46448.729 | C38: 46448.735 | D38: 1.6, 97% | E38: 99 | F38: Study flow 2 | G38: Processed | H38: Completed | I38: Desktop | J38: Firefox | K38: =IF(H38="Completed",11,VALUE(MID(H38,6,FIND(" ",H38,6)-6))) | L38: =IF(G38="Processed",1,0) | M38: =IF(F38="Study flow 1","Narrative first","Visual first") | N38: =IF(D38="","",VALUE(LEFT(D38,FIND(",",D38)-1))) | O38: =IF(D38="","",VALUE(SUBSTITUTE(MID(D38,FIND(",",D38)+2,10),"%","")))
A39: RESP0038 | B39: 46448.751 | C39: 46448.758 | D39: 1.9, 98% | E39: 98 | F39: Study flow 1 | G39: Processed | H39: Completed | I39: Desktop | J39: Firefox | K39: =IF(H39="Completed",11,VALUE(MID(H39,6,FIND(" ",H39,6)-6))) | L39: =IF(G39="Processed",1,0) | M39: =IF(F39="Study flow 1","Narrative first","Visual first") | N39: =IF(D39="","",VALUE(LEFT(D39,FIND(",",D39)-1))) | O39: =IF(D39="","",VALUE(SUBSTITUTE(MID(D39,FIND(",",D39)+2,10),"%","")))
A40: RESP0039 | B40: 46448.781 | C40: 46448.786 | D40: 3.5, 93% | E40: 97 | F40: Study flow 2 | G40: Processed | H40: Completed | I40: Desktop | J40: Chrome | K40: =IF(H40="Completed",11,VALUE(MID(H40,6,FIND(" ",H40,6)-6))) | L40: =IF(G40="Processed",1,0) | M40: =IF(F40="Study flow 1","Narrative first","Visual first") | N40: =IF(D40="","",VALUE(LEFT(D40,FIND(",",D40)-1))) | O40: =IF(D40="","",VALUE(SUBSTITUTE(MID(D40,FIND(",",D40)+2,10),"%","")))
...

Sheet Quality
A1: Respondent Name | B1: Block | C1: Slide position | D1: Slide | E1: Eye tracking accuracy (degrees) | F1: Eye tracking quality (%) | G1: Face quality (%)
A2: RESP0001 | B2: Study flow 2 | C2: 1 | D2: Pre-study calibration | E2: 0.94 | F2: 93.9 | G2: 98.9
A3: RESP0001 | B3: Study flow 2 | C3: 2 | D3: Instructions1 | E3: NA | F3: 90 | G3: 98.5
A4: RESP0001 | B4: Study flow 2 | C4: 3 | D4: foodwaste_visual | E4: NA | F4: 97.8 | G4: 99
A5: RESP0001 | B5: Study flow 2 | C5: 4 | D5: foodwaste_narrative | E5: NA | F5: 95.3 | G5: 98.8
A6: RESP0001 | B6: Study flow 2 | C6: 5 | D6: infographic | E6: NA | F6: 96.5 | G6: 98.8
A7: RESP0001 | B7: Study flow 2 | C7: 6 | D7: Questionnaire | E7: NA | F7: 96.2 | G7: 98.4
A8: RESP0001 | B8: Study flow 2 | C8: 7 | D8: Post-study calibration | E8: 1.7 | F8: 95.2 | G8: 98.9
A9: RESP0002 | B9: Study flow 1 | C9: 1 | D9: Pre-study calibration | E9: 2 | F9: 91.5 | G9: 98.8
A10: RESP0002 | B10: Study flow 1 | C10: 2 | D10: Instructions1 | E10: NA | F10: 94.4 | G10: 98.2
A11: RESP0002 | B11: Study flow 1 | C11: 3 | D11: foodwaste_narrative | E11: NA | F11: 96.3 | G11: 97.6
A12: RESP0002 | B12: Study flow 1 | C12: 4 | D12: foodwaste_visual | E12: NA | F12: 94.3 | G12: 98.8
A13: RESP0002 | B13: Study flow 1 | C13: 5 | D13: infographic | E13: NA | F13: 96.8 | G13: 98.3
A14: RESP0002 | B14: Study flow 1 | C14: 6 | D14: Questionnaire | E14: NA | F14: 95.9 | G14: 98.3
A15: RESP0002 | B15: Study flow 1 | C15: 7 | D15: Post-study calibration | E15: 3.45 | F15: 93.3 | G15: 98.3
A16: RESP0003 | B16: Study flow 2 | C16: 1 | D16: Pre-study calibration | E16: 0.89 | F16: 95.2 | G16: 72
A17: RESP0003 | B17: Study flow 2 | C17: 2 | D17: Instructions1 | E17: NA | F17: 97.2 | G17: 89.7
A18: RESP0003 | B18: Study flow 2 | C18: 3 | D18: foodwaste_visual | E18: NA | F18: 94 | G18: 87.4
A19: RESP0003 | B19: Study flow 2 | C19: 4 | D19: foodwaste_narrative | E19: NA | F19: 95 | G19: 79.7
A20: RESP0003 | B20: Study flow 2 | C20: 5 | D20: infographic | E20: NA | F20: 96.9 | G20: 92.6
A21: RESP0003 | B21: Study flow 2 | C21: 6 | D21: Questionnaire | E21: NA | F21: 96.9 | G21: 87.1
A22: RESP0003 | B22: Study flow 2 | C22: 7 | D22: Post-study calibration | E22: 2.06 | F22: 94.4 | G22: 95.2
A23: RESP0004 | B23: Study flow 2 | C23: 1 | D23: Pre-study calibration | E23: 2.31 | F23: 96.8 | G23: 93.8
A24: RESP0004 | B24: Study flow 2 | C24: 2 | D24: Instructions1 | E24: NA | F24: 96 | G24: 96.9
A25: RESP0004 | B25: Study flow 2 | C25: 3 | D25: foodwaste_visual | E25: NA | F25: 93.5 | G25: 96.5
A26: RESP0004 | B26: Study flow 2 | C26: 4 | D26: foodwaste_narrative | E26: NA | F26: 91.2 | G26: 96.6
A27: RESP0004 | B27: Study flow 2 | C27: 5 | D27: infographic | E27: NA | F27: 97.4 | G27: 95.4
A28: RESP0004 | B28: Study flow 2 | C28: 6 | D28: Questionnaire | E28: NA | F28: 97.1 | G28: 94.3
A29: RESP0004 | B29: Study flow 2 | C29: 7 | D29: Post-study calibration | E29: 3.73 | F29: 96.4 | G29: 95.2
A30: RESP0005 | B30: Study flow 2 | C30: 1 | D30: Pre-study calibration | E30: 0.93 | F30: 98.4 | G30: 93.3
A31: RESP0005 | B31: Study flow 2 | C31: 2 | D31: Instructions1 | E31: NA | F31: 98.9 | G31: 88.3
A32: RESP0005 | B32: Study flow 2 | C32: 3 | D32: foodwaste_visual | E32: NA | F32: 98.9 | G32: 93
A33: RESP0005 | B33: Study flow 2 | C33: 4 | D33: foodwaste_narrative | E33: NA | F33: 98.7 | G33: 90.6
A34: RESP0005 | B34: Study flow 2 | C34: 5 | D34: infographic | E34: NA | F34: 99.1 | G34: 93.4
A35: RESP0005 | B35: Study flow 2 | C35: 6 | D35: Questionnaire | E35: NA | F35: 98.7 | G35: 92.7
A36: RESP0005 | B36: Study flow 2 | C36: 7 | D36: Post-study calibration | E36: 1.19 | F36: 99 | G36: 90.1
A37: RESP0006 | B37: Study flow 2 | C37: 1 | D37: Pre-study calibration | E37: 1.6 | F37: 96.5 | G37: 98.4
A38: RESP0006 | B38: Study flow 2 | C38: 2 | D38: Instructions1 | E38: NA | F38: 97.3 | G38: 98.2
A39: RESP0006 | B39: Study flow 2 | C39: 3 | D39: foodwaste_visual | E39: NA | F39: 97.4 | G39: 99
A40: RESP0006 | B40: Study flow 2 | C40: 4 | D40: foodwaste_narrative | E40: NA | F40: 98.1 | G40: 99.3
...

Sheet FEA
A1: Study Name | B1: Respondent Name | C1: Interval type | D1: Interval label | E1: Interval duration (s) | F1: Expression | G1: Threshold | H1: Percent of time present | I1: Number of segments | J1: Mean raw score (0-100) | K1: Data quality (%)
A2: SIMULATED Food Waste Remote Study | B2: RESP0001 | C2: Stimulus | D2: foodwaste_narrative | E2: 60 | F2: Engagement | G2: 50 | H2: 32.56 | I2: 9 | J2: NA | K2: 98.8
A3: SIMULATED Food Waste Remote Study | B3: RESP0001 | C3: Stimulus | D3: foodwaste_narrative | E3: 60 | F3: Joy | G3: 50 | H3: 0 | I3: 0 | J3: NA | K3: 98.8
A4: SIMULATED Food Waste Remote Study | B4: RESP0001 | C4: Stimulus | D4: foodwaste_narrative | E4: 60 | F4: Brow Furrow | G4: 50 | H4: 3.22 | I4: 1 | J4: NA | K4: 98.8
A5: SIMULATED Food Waste Remote Study | B5: RESP0001 | C5: Stimulus | D5: foodwaste_narrative | E5: 60 | F5: Positive Valence | G5: 50 | H5: 7.5 | I5: 2 | J5: NA | K5: 98.8
A6: SIMULATED Food Waste Remote Study | B6: RESP0001 | C6: Stimulus | D6: foodwaste_narrative | E6: 60 | F6: Negative Valence | G6: -50 | H6: 0 | I6: 0 | J6: NA | K6: 98.8
A7: SIMULATED Food Waste Remote Study | B7: RESP0001 | C7: Stimulus | D7: foodwaste_visual | E7: 62 | F7: Engagement | G7: 50 | H7: 65.32 | I7: 17 | J7: NA | K7: 99
A8: SIMULATED Food Waste Remote Study | B8: RESP0001 | C8: Stimulus | D8: foodwaste_visual | E8: 62 | F8: Joy | G8: 50 | H8: 0.48 | I8: 1 | J8: NA | K8: 99
A9: SIMULATED Food Waste Remote Study | B9: RESP0001 | C9: Stimulus | D9: foodwaste_visual | E9: 62 | F9: Brow Furrow | G9: 50 | H9: 14.14 | I9: 3 | J9: NA | K9: 99
A10: SIMULATED Food Waste Remote Study | B10: RESP0001 | C10: Stimulus | D10: foodwaste_visual | E10: 62 | F10: Positive Valence | G10: 50 | H10: 0 | I10: 0 | J10: NA | K10: 99
A11: SIMULATED Food Waste Remote Study | B11: RESP0001 | C11: Stimulus | D11: foodwaste_visual | E11: 62 | F11: Negative Valence | G11: -50 | H11: 5.81 | I11: 2 | J11: NA | K11: 99
A12: SIMULATED Food Waste Remote Study | B12: RESP0002 | C12: Stimulus | D12: foodwaste_narrative | E12: 60 | F12: Engagement | G12: 50 | H12: 20.5 | I12: 5 | J12: NA | K12: 97.6
A13: SIMULATED Food Waste Remote Study | B13: RESP0002 | C13: Stimulus | D13: foodwaste_narrative | E13: 60 | F13: Joy | G13: 50 | H13: 2.06 | I13: 1 | J13: NA | K13: 97.6
... A1781: SIMULATED Food Waste Remote Study | B1781: RESP0260 | C1781: Stimulus | D1781: foodwaste_visual | E1781: 62 | F1781: Negative Valence | G1781: -50 | H1781: 3.82 | I1781: 6 | J1781: NA | K1781: 65.9

Sheet Survey
A1: Study Name | B1: Respondent Name | C1: Age | D1: Gender | E1: Intention_reduce_food_waste_1to7 | F1: More_persuasive_video | G1: Tips_recalled_0to4
A2: SIMULATED Food Waste Remote Study | B2: RESP0001 | C2: 61 | D2: F | E2: 5 | F2: Visual | G2: 2
A3: SIMULATED Food Waste Remote Study | B3: RESP0002 | C3: 21 | D3: M | E3: 7 | F3: Visual | G3: 4
A4: SIMULATED Food Waste Remote Study | B4: RESP0003 | C4: 49 | D4: M | E4: 7 | F4: Visual | G4: 0
A5: SIMULATED Food Waste Remote Study | B5: RESP0004 | C5: 38 | D5: M | E5: 5 | F5: Narrative | G5: 4
A6: SIMULATED Food Waste Remote Study | B6: RESP0005 | C6: 64 | D6: M | E6: 3 | F6: Visual | G6: 1
A7: SIMULATED Food Waste Remote Study | B7: RESP0006 | C7: 21 | D7: F | E7: 5 | F7: Narrative | G7: 3
A8: SIMULATED Food Waste Remote Study | B8: RESP0007 | C8: 19 | D8: M | E8: 6 | F8: Visual | G8: 4
A9: SIMULATED Food Waste Remote Study | B9: RESP0009 | C9: 64 | D9: F | E9: 6 | F9: Visual | G9: 3
A10: SIMULATED Food Waste Remote Study | B10: RESP0010 | C10: 42 | D10: F | E10: 6 | F10: Narrative | G10: 3
A11: SIMULATED Food Waste Remote Study | B11: RESP0012 | C11: 20 | D11: F | E11: 7 | F11: Narrative | G11: 3
A12: SIMULATED Food Waste Remote Study | B12: RESP0013 | C12: 23 | D12: F | E12: 7 | F12: Narrative | G12: 0
A13: SIMULATED Food Waste Remote Study | B13: RESP0014 | C13: 64 | D13: F | E13: 4 | F13: Narrative | G13: 3
... A179: SIMULATED Food Waste Remote Study | B179: RESP0260 | C179: 20 | D179: F | E179: 6 | F179: Narrative | G179: 4

Sheet Funnel
A1: The respondent funnel, rebuilt from the session data (one row per session that opened a link). SIMULATED data.
A2: Entered = sessions whose last step is this step or a later one (Step number on the Session sheet; 11 = completed). Stopped here = sessions that ended at this step. Step names are those of the iMotions Respondent funnel.
A4: Step | B4: Step name | C4: Entered | D4: Stopped here | E4: Continued | F4: Percent of opened | G4: Percent of previous step
A5: 1 | B5: STEP 1 Testing upload | C5: =COUNTIF(Session!$K$2:$K$261,">="&A5) | D5: =COUNTIF(Session!$K$2:$K$261,A5) | E5: =C5-D5 | F5: =100*C5/COUNTA(Session!$A$2:$A$261) | G5: =100*C5/COUNTA(Session!$A$2:$A$261)
A6: 2 | B6: STEP 2 Consent screen | C6: =COUNTIF(Session!$K$2:$K$261,">="&A6) | D6: =COUNTIF(Session!$K$2:$K$261,A6) | E6: =C6-D6 | F6: =100*C6/COUNTA(Session!$A$2:$A$261) | G6: =100*C6/C5
A7: 3 | B7: STEP 3 Screen recording setup | C7: =COUNTIF(Session!$K$2:$K$261,">="&A7) | D7: =COUNTIF(Session!$K$2:$K$261,A7) | E7: =C7-D7 | F7: =100*C7/COUNTA(Session!$A$2:$A$261) | G7: =100*C7/C6
A8: 4 | B8: STEP 4 Respondent camera setup | C8: =COUNTIF(Session!$K$2:$K$261,">="&A8) | D8: =COUNTIF(Session!$K$2:$K$261,A8) | E8: =C8-D8 | F8: =100*C8/COUNTA(Session!$A$2:$A$261) | G8: =100*C8/C7
A9: 5 | B9: STEP 5 Screen size | C9: =COUNTIF(Session!$K$2:$K$261,">="&A9) | D9: =COUNTIF(Session!$K$2:$K$261,A9) | E9: =C9-D9 | F9: =100*C9/COUNTA(Session!$A$2:$A$261) | G9: =100*C9/C8
A10: 6 | B10: STEP 6 Enter fullscreen | C10: =COUNTIF(Session!$K$2:$K$261,">="&A10) | D10: =COUNTIF(Session!$K$2:$K$261,A10) | E10: =C10-D10 | F10: =100*C10/COUNTA(Session!$A$2:$A$261) | G10: =100*C10/C9
A11: 7 | B11: STEP 7 Prepare positioning | C11: =COUNTIF(Session!$K$2:$K$261,">="&A11) | D11: =COUNTIF(Session!$K$2:$K$261,A11) | E11: =C11-D11 | F11: =100*C11/COUNTA(Session!$A$2:$A$261) | G11: =100*C11/C10
A12: 8 | B12: STEP 8 Positioning check | C12: =COUNTIF(Session!$K$2:$K$261,">="&A12) | D12: =COUNTIF(Session!$K$2:$K$261,A12) | E12: =C12-D12 | F12: =100*C12/COUNTA(Session!$A$2:$A$261) | G12: =100*C12/C11
A13: 9 | B13: STEP 9 Stimuli presentation* | C13: =COUNTIF(Session!$K$2:$K$261,">="&A13) | D13: =COUNTIF(Session!$K$2:$K$261,A13) | E13: =C13-D13 | F13: =100*C13/COUNTA(Session!$A$2:$A$261) | G13: =100*C13/C12
A14: 10 | B14: STEP 10 Study data upload | C14: =COUNTIF(Session!$K$2:$K$261,">="&A14) | D14: =COUNTIF(Session!$K$2:$K$261,A14) | E14: =C14-D14 | F14: =100*C14/COUNTA(Session!$A$2:$A$261) | G14: =100*C14/C13
B15: Completed (Status Processed) | C15: =COUNTIF(Session!$G$2:$G$261,"Processed") | F15: =100*C15/COUNTA(Session!$A$2:$A$261) | G15: =100*C15/C14
B16: Check: Continued after STEP 10 = Completed (must be 0) | C16: =E14-C15
B17: Status Abandoned | C17: =COUNTIF(Session!$G$2:$G$261,"Abandoned")
B18: Status Errors | C18: =COUNTIF(Session!$G$2:$G$261,"Errors")
B19: Sessions that opened a link | C19: =COUNTA(Session!$A$2:$A$261)
A20: Completion by order (differential attrition): all sessions
A21: Order | B21: Opened | C21: Reached STEP 9 | D21: Completed | E21: Not completed | F21: Percent completed | H21: Expected: completed | I21: Expected: not completed | K21: Statistic | L21: Value | M21: Formula shown | N21: Note
A22: Narrative first | B22: =COUNTIF(Session!$M$2:$M$261,A22) | C22: =COUNTIFS(Session!$M$2:$M$261,A22,Session!$K$2:$K$261,">=9") | D22: =COUNTIFS(Session!$M$2:$M$261,A22,Session!$L$2:$L$261,1) | E22: =B22-D22 | F22: =100*D22/B22 | H22: =B22*$D$24/$B$24 | I22: =B22*$E$24/$B$24 | K22: Chi square test of independence: order x completed (all sessions)
A23: Visual first | B23: =COUNTIF(Session!$M$2:$M$261,A23) | C23: =COUNTIFS(Session!$M$2:$M$261,A23,Session!$K$2:$K$261,">=9") | D23: =COUNTIFS(Session!$M$2:$M$261,A23,Session!$L$2:$L$261,1) | E23: =B23-D23 | F23: =100*D23/B23 | H23: =B23*$D$24/$B$24 | I23: =B23*$E$24/$B$24 | K23: Chi square (Pearson, no continuity correction) | L23: =SUMPRODUCT((D22:E23-H22:I23)^2/H22:I23) | M23: =SUMPRODUCT((D22:E23-H22:I23)^2/H22:I23) | N23: sum of (observed - expected)^2 / expected
A24: Total | B24: =SUM(B22:B23) | C24: =SUM(C22:C23) | D24: =SUM(D22:D23) | E24: =SUM(E22:E23) | K24: df | L24: =1 | M24: =1 | N24: (rows - 1) x (columns - 1)
K25: p (CHISQ.DIST.RT) | L25: =_xlfn.CHISQ.DIST.RT(L23,L24) | M25: =CHISQ.DIST.RT(L23,L24) | N25: right tail of the chi square distribution
K26: p (CHISQ.TEST on observed and expected) | L26: =_xlfn.CHISQ.TEST(D22:E23,H22:I23) | M26: =CHISQ.TEST(D22:E23,H22:I23) | N26: must match the cell above
K27: phi (effect size) | L27: =SQRT(L23/B24) | M27: =SQRT(L23/B24) | N27: sqrt(chi square / N); .1 small, .3 medium
K28: Percent completed, Narrative first minus Visual first | L28: =F22-F23 | M28: =F22-F23 | N28: percentage points
K29: Smallest expected count | L29: =MIN(H22:I23) | M29: =MIN(H22:I23) | N29: 5 or more: the chi square approximation is fine
A35: Completion by order among the sessions that reached STEP 9 (the videos started)
A36: Order | B36: Reached STEP 9 | C36: Completed | D36: Not completed | E36: Percent completed | H36: Expected: completed | I36: Expected: not completed | K36: Statistic | L36: Value | M36: Formula shown | N36: Note
A37: Narrative first | B37: =C22 | C37: =D22 | D37: =B37-C37 | E37: =100*C37/B37 | H37: =B37*$C$39/$B$39 | I37: =B37*$D$39/$B$39 | K37: Chi square test: order x completed, sessions that reached STEP 9
A38: Visual first | B38: =C23 | C38: =D23 | D38: =B38-C38 | E38: =100*C38/B38 | H38: =B38*$C$39/$B$39 | I38: =B38*$D$39/$B$39 | K38: Chi square (Pearson, no continuity correction) | L38: =SUMPRODUCT((C37:D38-H37:I38)^2/H37:I38) | M38: =SUMPRODUCT((C37:D38-H37:I38)^2/H37:I38)
A39: Total | B39: =SUM(B37:B38) | C39: =SUM(C37:C38) | D39: =SUM(D37:D38) | K39: p (CHISQ.DIST.RT) | L39: =_xlfn.CHISQ.DIST.RT(L38,1) | M39: =CHISQ.DIST.RT(L38,1)
K40: Smallest expected count | L40: =MIN(H37:I38) | M40: =MIN(H37:I38) | N40: below 5: report the Fisher exact test from R
K41: Percent completed, Narrative first minus Visual first | L41: =E37-E38 | M41: =E37-E38 | N41: percentage points
A51: Completion by device (modeled column)
A52: Device type (modeled) | B52: Opened | C52: Completed | D52: Percent completed
A53: Laptop | B53: =COUNTIF(Session!$I$2:$I$261,A53) | C53: =COUNTIFS(Session!$I$2:$I$261,A53,Session!$L$2:$L$261,1) | D53: =IF(B53=0,"",100*C53/B53)
A54: Desktop | B54: =COUNTIF(Session!$I$2:$I$261,A54) | C54: =COUNTIFS(Session!$I$2:$I$261,A54,Session!$L$2:$L$261,1) | D54: =IF(B54=0,"",100*C54/B54)
A55: Phone | B55: =COUNTIF(Session!$I$2:$I$261,A55) | C55: =COUNTIFS(Session!$I$2:$I$261,A55,Session!$L$2:$L$261,1) | D55: =IF(B55=0,"",100*C55/B55)
...

Sheet Screening
A1: The exclusion rule, one row per completed respondent (Status Processed). SIMULATED data. Yellow cells hold the thresholds.
A2: Accuracy limit (degrees) | B2: 4 | C2: Sensitivity limit (degrees) | D2: 3 | E2: Eye tracking quality minimum (%) | F2: 90 | G2: Face quality minimum (%) | H2: 80
A4: Respondent Name | B4: Order | C4: Pre-study accuracy | D4: Post-study accuracy | E4: Eye tracking quality, infographic | F4: Face quality, narrative | G4: Face quality, visual | H4: Fail: Pre-study accuracy | I4: Fail: Post-study accuracy | J4: Fail: eye tracking quality | K4: Fail: face quality | L4: Decision | M4: First reason | N4: Largest accuracy | O4: Decision at 3.0 | P4: Drift (Post minus Pre)
A5: RESP0001 | B5: =INDEX(Session!$M$2:$M$261,MATCH($A5,Session!$A$2:$A$261,0)) | C5: =SUMIFS(Quality!$E$2:$E$1247,Quality!$A$2:$A$1247,$A5,Quality!$D$2:$D$1247,"Pre-study calibration") | D5: =SUMIFS(Quality!$E$2:$E$1247,Quality!$A$2:$A$1247,$A5,Quality!$D$2:$D$1247,"Post-study calibration") | E5: =SUMIFS(Quality!$F$2:$F$1247,Quality!$A$2:$A$1247,$A5,Quality!$D$2:$D$1247,"infographic") | F5: =SUMIFS(Quality!$G$2:$G$1247,Quality!$A$2:$A$1247,$A5,Quality!$D$2:$D$1247,"foodwaste_narrative") | G5: =SUMIFS(Quality!$G$2:$G$1247,Quality!$A$2:$A$1247,$A5,Quality!$D$2:$D$1247,"foodwaste_visual") | H5: =IF(C5>$B$2,1,0) | I5: =IF(D5>$B$2,1,0) | J5: =IF(E5<$F$2,1,0) | K5: =IF(OR(F5<$H$2,G5<$H$2),1,0) | L5: =IF(SUM(H5:K5)>0,"Exclude","Keep") | M5: =IF(H5=1,"Pre-study accuracy",IF(I5=1,"Post-study accuracy",IF(J5=1,"Eye tracking quality",IF(K5=1,"Face quality","")))) | N5: =MAX(C5:D5) | O5: =IF(AND(L5="Keep",N5<=$D$2),"Keep","Exclude") | P5: =D5-C5 | R5: Statistic | S5: Value | T5: Formula shown | U5: Note
A6: RESP0002 | B6: =INDEX(Session!$M$2:$M$261,MATCH($A6,Session!$A$2:$A$261,0)) | C6: =SUMIFS(Quality!$E$2:$E$1247,Quality!$A$2:$A$1247,$A6,Quality!$D$2:$D$1247,"Pre-study calibration") | D6: =SUMIFS(Quality!$E$2:$E$1247,Quality!$A$2:$A$1247,$A6,Quality!$D$2:$D$1247,"Post-study calibration") | E6: =SUMIFS(Quality!$F$2:$F$1247,Quality!$A$2:$A$1247,$A6,Quality!$D$2:$D$1247,"infographic") | F6: =SUMIFS(Quality!$G$2:$G$1247,Quality!$A$2:$A$1247,$A6,Quality!$D$2:$D$1247,"foodwaste_narrative") | G6: =SUMIFS(Quality!$G$2:$G$1247,Quality!$A$2:$A$1247,$A6,Quality!$D$2:$D$1247,"foodwaste_visual") | H6: =IF(C6>$B$2,1,0) | I6: =IF(D6>$B$2,1,0) | J6: =IF(E6<$F$2,1,0) | K6: =IF(OR(F6<$H$2,G6<$H$2),1,0) | L6: =IF(SUM(H6:K6)>0,"Exclude","Keep") | M6: =IF(H6=1,"Pre-study accuracy",IF(I6=1,"Post-study accuracy",IF(J6=1,"Eye tracking quality",IF(K6=1,"Face quality","")))) | N6: =MAX(C6:D6) | O6: =IF(AND(L6="Keep",N6<=$D$2),"Keep","Exclude") | P6: =D6-C6 | R6: Counts
A7: RESP0003 | B7: =INDEX(Session!$M$2:$M$261,MATCH($A7,Session!$A$2:$A$261,0)) | C7: =SUMIFS(Quality!$E$2:$E$1247,Quality!$A$2:$A$1247,$A7,Quality!$D$2:$D$1247,"Pre-study calibration") | D7: =SUMIFS(Quality!$E$2:$E$1247,Quality!$A$2:$A$1247,$A7,Quality!$D$2:$D$1247,"Post-study calibration") | E7: =SUMIFS(Quality!$F$2:$F$1247,Quality!$A$2:$A$1247,$A7,Quality!$D$2:$D$1247,"infographic") | F7: =SUMIFS(Quality!$G$2:$G$1247,Quality!$A$2:$A$1247,$A7,Quality!$D$2:$D$1247,"foodwaste_narrative") | G7: =SUMIFS(Quality!$G$2:$G$1247,Quality!$A$2:$A$1247,$A7,Quality!$D$2:$D$1247,"foodwaste_visual") | H7: =IF(C7>$B$2,1,0) | I7: =IF(D7>$B$2,1,0) | J7: =IF(E7<$F$2,1,0) | K7: =IF(OR(F7<$H$2,G7<$H$2),1,0) | L7: =IF(SUM(H7:K7)>0,"Exclude","Keep") | M7: =IF(H7=1,"Pre-study accuracy",IF(I7=1,"Post-study accuracy",IF(J7=1,"Eye tracking quality",IF(K7=1,"Face quality","")))) | N7: =MAX(C7:D7) | O7: =IF(AND(L7="Keep",N7<=$D$2),"Keep","Exclude") | P7: =D7-C7 | R7: Completed respondents screened | S7: =COUNTA(A5:A182) | T7: =COUNTA(A5:A182)
A8: RESP0004 | B8: =INDEX(Session!$M$2:$M$261,MATCH($A8,Session!$A$2:$A$261,0)) | C8: =SUMIFS(Quality!$E$2:$E$1247,Quality!$A$2:$A$1247,$A8,Quality!$D$2:$D$1247,"Pre-study calibration") | D8: =SUMIFS(Quality!$E$2:$E$1247,Quality!$A$2:$A$1247,$A8,Quality!$D$2:$D$1247,"Post-study calibration") | E8: =SUMIFS(Quality!$F$2:$F$1247,Quality!$A$2:$A$1247,$A8,Quality!$D$2:$D$1247,"infographic") | F8: =SUMIFS(Quality!$G$2:$G$1247,Quality!$A$2:$A$1247,$A8,Quality!$D$2:$D$1247,"foodwaste_narrative") | G8: =SUMIFS(Quality!$G$2:$G$1247,Quality!$A$2:$A$1247,$A8,Quality!$D$2:$D$1247,"foodwaste_visual") | H8: =IF(C8>$B$2,1,0) | I8: =IF(D8>$B$2,1,0) | J8: =IF(E8<$F$2,1,0) | K8: =IF(OR(F8<$H$2,G8<$H$2),1,0) | L8: =IF(SUM(H8:K8)>0,"Exclude","Keep") | M8: =IF(H8=1,"Pre-study accuracy",IF(I8=1,"Post-study accuracy",IF(J8=1,"Eye tracking quality",IF(K8=1,"Face quality","")))) | N8: =MAX(C8:D8) | O8: =IF(AND(L8="Keep",N8<=$D$2),"Keep","Exclude") | P8: =D8-C8 | R8: Excluded | S8: =COUNTIF($L$5:$L$182,"Exclude") | T8: =COUNTIF($L$5:$L$182,"Exclude")
A9: RESP0005 | B9: =INDEX(Session!$M$2:$M$261,MATCH($A9,Session!$A$2:$A$261,0)) | C9: =SUMIFS(Quality!$E$2:$E$1247,Quality!$A$2:$A$1247,$A9,Quality!$D$2:$D$1247,"Pre-study calibration") | D9: =SUMIFS(Quality!$E$2:$E$1247,Quality!$A$2:$A$1247,$A9,Quality!$D$2:$D$1247,"Post-study calibration") | E9: =SUMIFS(Quality!$F$2:$F$1247,Quality!$A$2:$A$1247,$A9,Quality!$D$2:$D$1247,"infographic") | F9: =SUMIFS(Quality!$G$2:$G$1247,Quality!$A$2:$A$1247,$A9,Quality!$D$2:$D$1247,"foodwaste_narrative") | G9: =SUMIFS(Quality!$G$2:$G$1247,Quality!$A$2:$A$1247,$A9,Quality!$D$2:$D$1247,"foodwaste_visual") | H9: =IF(C9>$B$2,1,0) | I9: =IF(D9>$B$2,1,0) | J9: =IF(E9<$F$2,1,0) | K9: =IF(OR(F9<$H$2,G9<$H$2),1,0) | L9: =IF(SUM(H9:K9)>0,"Exclude","Keep") | M9: =IF(H9=1,"Pre-study accuracy",IF(I9=1,"Post-study accuracy",IF(J9=1,"Eye tracking quality",IF(K9=1,"Face quality","")))) | N9: =MAX(C9:D9) | O9: =IF(AND(L9="Keep",N9<=$D$2),"Keep","Exclude") | P9: =D9-C9 | R9: Kept | S9: =COUNTIF($L$5:$L$182,"Keep") | T9: =COUNTIF($L$5:$L$182,"Keep")
A10: RESP0006 | B10: =INDEX(Session!$M$2:$M$261,MATCH($A10,Session!$A$2:$A$261,0)) | C10: =SUMIFS(Quality!$E$2:$E$1247,Quality!$A$2:$A$1247,$A10,Quality!$D$2:$D$1247,"Pre-study calibration") | D10: =SUMIFS(Quality!$E$2:$E$1247,Quality!$A$2:$A$1247,$A10,Quality!$D$2:$D$1247,"Post-study calibration") | E10: =SUMIFS(Quality!$F$2:$F$1247,Quality!$A$2:$A$1247,$A10,Quality!$D$2:$D$1247,"infographic") | F10: =SUMIFS(Quality!$G$2:$G$1247,Quality!$A$2:$A$1247,$A10,Quality!$D$2:$D$1247,"foodwaste_narrative") | G10: =SUMIFS(Quality!$G$2:$G$1247,Quality!$A$2:$A$1247,$A10,Quality!$D$2:$D$1247,"foodwaste_visual") | H10: =IF(C10>$B$2,1,0) | I10: =IF(D10>$B$2,1,0) | J10: =IF(E10<$F$2,1,0) | K10: =IF(OR(F10<$H$2,G10<$H$2),1,0) | L10: =IF(SUM(H10:K10)>0,"Exclude","Keep") | M10: =IF(H10=1,"Pre-study accuracy",IF(I10=1,"Post-study accuracy",IF(J10=1,"Eye tracking quality",IF(K10=1,"Face quality","")))) | N10: =MAX(C10:D10) | O10: =IF(AND(L10="Keep",N10<=$D$2),"Keep","Exclude") | P10: =D10-C10 | R10: First reason: Pre-study accuracy | S10: =COUNTIF($M$5:$M$182,"Pre-study accuracy") | T10: =COUNTIF($M$5:$M$182,"Pre-study accuracy")
A11: RESP0007 | B11: =INDEX(Session!$M$2:$M$261,MATCH($A11,Session!$A$2:$A$261,0)) | C11: =SUMIFS(Quality!$E$2:$E$1247,Quality!$A$2:$A$1247,$A11,Quality!$D$2:$D$1247,"Pre-study calibration") | D11: =SUMIFS(Quality!$E$2:$E$1247,Quality!$A$2:$A$1247,$A11,Quality!$D$2:$D$1247,"Post-study calibration") | E11: =SUMIFS(Quality!$F$2:$F$1247,Quality!$A$2:$A$1247,$A11,Quality!$D$2:$D$1247,"infographic") | F11: =SUMIFS(Quality!$G$2:$G$1247,Quality!$A$2:$A$1247,$A11,Quality!$D$2:$D$1247,"foodwaste_narrative") | G11: =SUMIFS(Quality!$G$2:$G$1247,Quality!$A$2:$A$1247,$A11,Quality!$D$2:$D$1247,"foodwaste_visual") | H11: =IF(C11>$B$2,1,0) | I11: =IF(D11>$B$2,1,0) | J11: =IF(E11<$F$2,1,0) | K11: =IF(OR(F11<$H$2,G11<$H$2),1,0) | L11: =IF(SUM(H11:K11)>0,"Exclude","Keep") | M11: =IF(H11=1,"Pre-study accuracy",IF(I11=1,"Post-study accuracy",IF(J11=1,"Eye tracking quality",IF(K11=1,"Face quality","")))) | N11: =MAX(C11:D11) | O11: =IF(AND(L11="Keep",N11<=$D$2),"Keep","Exclude") | P11: =D11-C11 | R11: First reason: Post-study accuracy | S11: =COUNTIF($M$5:$M$182,"Post-study accuracy") | T11: =COUNTIF($M$5:$M$182,"Post-study accuracy")
A12: RESP0009 | B12: =INDEX(Session!$M$2:$M$261,MATCH($A12,Session!$A$2:$A$261,0)) | C12: =SUMIFS(Quality!$E$2:$E$1247,Quality!$A$2:$A$1247,$A12,Quality!$D$2:$D$1247,"Pre-study calibration") | D12: =SUMIFS(Quality!$E$2:$E$1247,Quality!$A$2:$A$1247,$A12,Quality!$D$2:$D$1247,"Post-study calibration") | E12: =SUMIFS(Quality!$F$2:$F$1247,Quality!$A$2:$A$1247,$A12,Quality!$D$2:$D$1247,"infographic") | F12: =SUMIFS(Quality!$G$2:$G$1247,Quality!$A$2:$A$1247,$A12,Quality!$D$2:$D$1247,"foodwaste_narrative") | G12: =SUMIFS(Quality!$G$2:$G$1247,Quality!$A$2:$A$1247,$A12,Quality!$D$2:$D$1247,"foodwaste_visual") | H12: =IF(C12>$B$2,1,0) | I12: =IF(D12>$B$2,1,0) | J12: =IF(E12<$F$2,1,0) | K12: =IF(OR(F12<$H$2,G12<$H$2),1,0) | L12: =IF(SUM(H12:K12)>0,"Exclude","Keep") | M12: =IF(H12=1,"Pre-study accuracy",IF(I12=1,"Post-study accuracy",IF(J12=1,"Eye tracking quality",IF(K12=1,"Face quality","")))) | N12: =MAX(C12:D12) | O12: =IF(AND(L12="Keep",N12<=$D$2),"Keep","Exclude") | P12: =D12-C12 | R12: First reason: Eye tracking quality | S12: =COUNTIF($M$5:$M$182,"Eye tracking quality") | T12: =COUNTIF($M$5:$M$182,"Eye tracking quality")
A13: RESP0010 | B13: =INDEX(Session!$M$2:$M$261,MATCH($A13,Session!$A$2:$A$261,0)) | C13: =SUMIFS(Quality!$E$2:$E$1247,Quality!$A$2:$A$1247,$A13,Quality!$D$2:$D$1247,"Pre-study calibration") | D13: =SUMIFS(Quality!$E$2:$E$1247,Quality!$A$2:$A$1247,$A13,Quality!$D$2:$D$1247,"Post-study calibration") | E13: =SUMIFS(Quality!$F$2:$F$1247,Quality!$A$2:$A$1247,$A13,Quality!$D$2:$D$1247,"infographic") | F13: =SUMIFS(Quality!$G$2:$G$1247,Quality!$A$2:$A$1247,$A13,Quality!$D$2:$D$1247,"foodwaste_narrative") | G13: =SUMIFS(Quality!$G$2:$G$1247,Quality!$A$2:$A$1247,$A13,Quality!$D$2:$D$1247,"foodwaste_visual") | H13: =IF(C13>$B$2,1,0) | I13: =IF(D13>$B$2,1,0) | J13: =IF(E13<$F$2,1,0) | K13: =IF(OR(F13<$H$2,G13<$H$2),1,0) | L13: =IF(SUM(H13:K13)>0,"Exclude","Keep") | M13: =IF(H13=1,"Pre-study accuracy",IF(I13=1,"Post-study accuracy",IF(J13=1,"Eye tracking quality",IF(K13=1,"Face quality","")))) | N13: =MAX(C13:D13) | O13: =IF(AND(L13="Keep",N13<=$D$2),"Keep","Exclude") | P13: =D13-C13 | R13: First reason: Face quality | S13: =COUNTIF($M$5:$M$182,"Face quality") | T13: =COUNTIF($M$5:$M$182,"Face quality")
A14: RESP0012 | B14: =INDEX(Session!$M$2:$M$261,MATCH($A14,Session!$A$2:$A$261,0)) | C14: =SUMIFS(Quality!$E$2:$E$1247,Quality!$A$2:$A$1247,$A14,Quality!$D$2:$D$1247,"Pre-study calibration") | D14: =SUMIFS(Quality!$E$2:$E$1247,Quality!$A$2:$A$1247,$A14,Quality!$D$2:$D$1247,"Post-study calibration") | E14: =SUMIFS(Quality!$F$2:$F$1247,Quality!$A$2:$A$1247,$A14,Quality!$D$2:$D$1247,"infographic") | F14: =SUMIFS(Quality!$G$2:$G$1247,Quality!$A$2:$A$1247,$A14,Quality!$D$2:$D$1247,"foodwaste_narrative") | G14: =SUMIFS(Quality!$G$2:$G$1247,Quality!$A$2:$A$1247,$A14,Quality!$D$2:$D$1247,"foodwaste_visual") | H14: =IF(C14>$B$2,1,0) | I14: =IF(D14>$B$2,1,0) | J14: =IF(E14<$F$2,1,0) | K14: =IF(OR(F14<$H$2,G14<$H$2),1,0) | L14: =IF(SUM(H14:K14)>0,"Exclude","Keep") | M14: =IF(H14=1,"Pre-study accuracy",IF(I14=1,"Post-study accuracy",IF(J14=1,"Eye tracking quality",IF(K14=1,"Face quality","")))) | N14: =MAX(C14:D14) | O14: =IF(AND(L14="Keep",N14<=$D$2),"Keep","Exclude") | P14: =D14-C14 | R14: Failed (any): Pre-study accuracy | S14: =SUM(H5:H182) | T14: =SUM(H5:H182)
A15: RESP0013 | B15: =INDEX(Session!$M$2:$M$261,MATCH($A15,Session!$A$2:$A$261,0)) | C15: =SUMIFS(Quality!$E$2:$E$1247,Quality!$A$2:$A$1247,$A15,Quality!$D$2:$D$1247,"Pre-study calibration") | D15: =SUMIFS(Quality!$E$2:$E$1247,Quality!$A$2:$A$1247,$A15,Quality!$D$2:$D$1247,"Post-study calibration") | E15: =SUMIFS(Quality!$F$2:$F$1247,Quality!$A$2:$A$1247,$A15,Quality!$D$2:$D$1247,"infographic") | F15: =SUMIFS(Quality!$G$2:$G$1247,Quality!$A$2:$A$1247,$A15,Quality!$D$2:$D$1247,"foodwaste_narrative") | G15: =SUMIFS(Quality!$G$2:$G$1247,Quality!$A$2:$A$1247,$A15,Quality!$D$2:$D$1247,"foodwaste_visual") | H15: =IF(C15>$B$2,1,0) | I15: =IF(D15>$B$2,1,0) | J15: =IF(E15<$F$2,1,0) | K15: =IF(OR(F15<$H$2,G15<$H$2),1,0) | L15: =IF(SUM(H15:K15)>0,"Exclude","Keep") | M15: =IF(H15=1,"Pre-study accuracy",IF(I15=1,"Post-study accuracy",IF(J15=1,"Eye tracking quality",IF(K15=1,"Face quality","")))) | N15: =MAX(C15:D15) | O15: =IF(AND(L15="Keep",N15<=$D$2),"Keep","Exclude") | P15: =D15-C15 | R15: Failed (any): Post-study accuracy | S15: =SUM(I5:I182) | T15: =SUM(I5:I182)
A16: RESP0014 | B16: =INDEX(Session!$M$2:$M$261,MATCH($A16,Session!$A$2:$A$261,0)) | C16: =SUMIFS(Quality!$E$2:$E$1247,Quality!$A$2:$A$1247,$A16,Quality!$D$2:$D$1247,"Pre-study calibration") | D16: =SUMIFS(Quality!$E$2:$E$1247,Quality!$A$2:$A$1247,$A16,Quality!$D$2:$D$1247,"Post-study calibration") | E16: =SUMIFS(Quality!$F$2:$F$1247,Quality!$A$2:$A$1247,$A16,Quality!$D$2:$D$1247,"infographic") | F16: =SUMIFS(Quality!$G$2:$G$1247,Quality!$A$2:$A$1247,$A16,Quality!$D$2:$D$1247,"foodwaste_narrative") | G16: =SUMIFS(Quality!$G$2:$G$1247,Quality!$A$2:$A$1247,$A16,Quality!$D$2:$D$1247,"foodwaste_visual") | H16: =IF(C16>$B$2,1,0) | I16: =IF(D16>$B$2,1,0) | J16: =IF(E16<$F$2,1,0) | K16: =IF(OR(F16<$H$2,G16<$H$2),1,0) | L16: =IF(SUM(H16:K16)>0,"Exclude","Keep") | M16: =IF(H16=1,"Pre-study accuracy",IF(I16=1,"Post-study accuracy",IF(J16=1,"Eye tracking quality",IF(K16=1,"Face quality","")))) | N16: =MAX(C16:D16) | O16: =IF(AND(L16="Keep",N16<=$D$2),"Keep","Exclude") | P16: =D16-C16 | R16: Failed (any): Eye tracking quality | S16: =SUM(J5:J182) | T16: =SUM(J5:J182)
A17: RESP0015 | B17: =INDEX(Session!$M$2:$M$261,MATCH($A17,Session!$A$2:$A$261,0)) | C17: =SUMIFS(Quality!$E$2:$E$1247,Quality!$A$2:$A$1247,$A17,Quality!$D$2:$D$1247,"Pre-study calibration") | D17: =SUMIFS(Quality!$E$2:$E$1247,Quality!$A$2:$A$1247,$A17,Quality!$D$2:$D$1247,"Post-study calibration") | E17: =SUMIFS(Quality!$F$2:$F$1247,Quality!$A$2:$A$1247,$A17,Quality!$D$2:$D$1247,"infographic") | F17: =SUMIFS(Quality!$G$2:$G$1247,Quality!$A$2:$A$1247,$A17,Quality!$D$2:$D$1247,"foodwaste_narrative") | G17: =SUMIFS(Quality!$G$2:$G$1247,Quality!$A$2:$A$1247,$A17,Quality!$D$2:$D$1247,"foodwaste_visual") | H17: =IF(C17>$B$2,1,0) | I17: =IF(D17>$B$2,1,0) | J17: =IF(E17<$F$2,1,0) | K17: =IF(OR(F17<$H$2,G17<$H$2),1,0) | L17: =IF(SUM(H17:K17)>0,"Exclude","Keep") | M17: =IF(H17=1,"Pre-study accuracy",IF(I17=1,"Post-study accuracy",IF(J17=1,"Eye tracking quality",IF(K17=1,"Face quality","")))) | N17: =MAX(C17:D17) | O17: =IF(AND(L17="Keep",N17<=$D$2),"Keep","Exclude") | P17: =D17-C17 | R17: Failed (any): Face quality | S17: =SUM(K5:K182) | T17: =SUM(K5:K182)
A18: RESP0016 | B18: =INDEX(Session!$M$2:$M$261,MATCH($A18,Session!$A$2:$A$261,0)) | C18: =SUMIFS(Quality!$E$2:$E$1247,Quality!$A$2:$A$1247,$A18,Quality!$D$2:$D$1247,"Pre-study calibration") | D18: =SUMIFS(Quality!$E$2:$E$1247,Quality!$A$2:$A$1247,$A18,Quality!$D$2:$D$1247,"Post-study calibration") | E18: =SUMIFS(Quality!$F$2:$F$1247,Quality!$A$2:$A$1247,$A18,Quality!$D$2:$D$1247,"infographic") | F18: =SUMIFS(Quality!$G$2:$G$1247,Quality!$A$2:$A$1247,$A18,Quality!$D$2:$D$1247,"foodwaste_narrative") | G18: =SUMIFS(Quality!$G$2:$G$1247,Quality!$A$2:$A$1247,$A18,Quality!$D$2:$D$1247,"foodwaste_visual") | H18: =IF(C18>$B$2,1,0) | I18: =IF(D18>$B$2,1,0) | J18: =IF(E18<$F$2,1,0) | K18: =IF(OR(F18<$H$2,G18<$H$2),1,0) | L18: =IF(SUM(H18:K18)>0,"Exclude","Keep") | M18: =IF(H18=1,"Pre-study accuracy",IF(I18=1,"Post-study accuracy",IF(J18=1,"Eye tracking quality",IF(K18=1,"Face quality","")))) | N18: =MAX(C18:D18) | O18: =IF(AND(L18="Keep",N18<=$D$2),"Keep","Exclude") | P18: =D18-C18 | R18: Failed more than one criterion | S18: =SUMPRODUCT(--((H5:H182+I5:I182+J5:J182+K5:K182)>1)) | T18: =SUMPRODUCT(--((H5:H182+I5:I182+J5:J182+K5:K182)>1))
A19: RESP0019 | B19: =INDEX(Session!$M$2:$M$261,MATCH($A19,Session!$A$2:$A$261,0)) | C19: =SUMIFS(Quality!$E$2:$E$1247,Quality!$A$2:$A$1247,$A19,Quality!$D$2:$D$1247,"Pre-study calibration") | D19: =SUMIFS(Quality!$E$2:$E$1247,Quality!$A$2:$A$1247,$A19,Quality!$D$2:$D$1247,"Post-study calibration") | E19: =SUMIFS(Quality!$F$2:$F$1247,Quality!$A$2:$A$1247,$A19,Quality!$D$2:$D$1247,"infographic") | F19: =SUMIFS(Quality!$G$2:$G$1247,Quality!$A$2:$A$1247,$A19,Quality!$D$2:$D$1247,"foodwaste_narrative") | G19: =SUMIFS(Quality!$G$2:$G$1247,Quality!$A$2:$A$1247,$A19,Quality!$D$2:$D$1247,"foodwaste_visual") | H19: =IF(C19>$B$2,1,0) | I19: =IF(D19>$B$2,1,0) | J19: =IF(E19<$F$2,1,0) | K19: =IF(OR(F19<$H$2,G19<$H$2),1,0) | L19: =IF(SUM(H19:K19)>0,"Exclude","Keep") | M19: =IF(H19=1,"Pre-study accuracy",IF(I19=1,"Post-study accuracy",IF(J19=1,"Eye tracking quality",IF(K19=1,"Face quality","")))) | N19: =MAX(C19:D19) | O19: =IF(AND(L19="Keep",N19<=$D$2),"Keep","Exclude") | P19: =D19-C19 | R19: Failed only at the Post-study calibration | S19: =COUNTIFS(H5:H182,0,I5:I182,1) | T19: =COUNTIFS(H5:H182,0,I5:I182,1) | U19: fine at the start, drifted
A20: RESP0020 | B20: =INDEX(Session!$M$2:$M$261,MATCH($A20,Session!$A$2:$A$261,0)) | C20: =SUMIFS(Quality!$E$2:$E$1247,Quality!$A$2:$A$1247,$A20,Quality!$D$2:$D$1247,"Pre-study calibration") | D20: =SUMIFS(Quality!$E$2:$E$1247,Quality!$A$2:$A$1247,$A20,Quality!$D$2:$D$1247,"Post-study calibration") | E20: =SUMIFS(Quality!$F$2:$F$1247,Quality!$A$2:$A$1247,$A20,Quality!$D$2:$D$1247,"infographic") | F20: =SUMIFS(Quality!$G$2:$G$1247,Quality!$A$2:$A$1247,$A20,Quality!$D$2:$D$1247,"foodwaste_narrative") | G20: =SUMIFS(Quality!$G$2:$G$1247,Quality!$A$2:$A$1247,$A20,Quality!$D$2:$D$1247,"foodwaste_visual") | H20: =IF(C20>$B$2,1,0) | I20: =IF(D20>$B$2,1,0) | J20: =IF(E20<$F$2,1,0) | K20: =IF(OR(F20<$H$2,G20<$H$2),1,0) | L20: =IF(SUM(H20:K20)>0,"Exclude","Keep") | M20: =IF(H20=1,"Pre-study accuracy",IF(I20=1,"Post-study accuracy",IF(J20=1,"Eye tracking quality",IF(K20=1,"Face quality","")))) | N20: =MAX(C20:D20) | O20: =IF(AND(L20="Keep",N20<=$D$2),"Keep","Exclude") | P20: =D20-C20 | R20: Kept, Narrative first | S20: =COUNTIFS($B$5:$B$182,"Narrative first",$L$5:$L$182,"Keep") | T20: =COUNTIFS($B$5:$B$182,"Narrative first",$L$5:$L$182,"Keep")
A21: RESP0022 | B21: =INDEX(Session!$M$2:$M$261,MATCH($A21,Session!$A$2:$A$261,0)) | C21: =SUMIFS(Quality!$E$2:$E$1247,Quality!$A$2:$A$1247,$A21,Quality!$D$2:$D$1247,"Pre-study calibration") | D21: =SUMIFS(Quality!$E$2:$E$1247,Quality!$A$2:$A$1247,$A21,Quality!$D$2:$D$1247,"Post-study calibration") | E21: =SUMIFS(Quality!$F$2:$F$1247,Quality!$A$2:$A$1247,$A21,Quality!$D$2:$D$1247,"infographic") | F21: =SUMIFS(Quality!$G$2:$G$1247,Quality!$A$2:$A$1247,$A21,Quality!$D$2:$D$1247,"foodwaste_narrative") | G21: =SUMIFS(Quality!$G$2:$G$1247,Quality!$A$2:$A$1247,$A21,Quality!$D$2:$D$1247,"foodwaste_visual") | H21: =IF(C21>$B$2,1,0) | I21: =IF(D21>$B$2,1,0) | J21: =IF(E21<$F$2,1,0) | K21: =IF(OR(F21<$H$2,G21<$H$2),1,0) | L21: =IF(SUM(H21:K21)>0,"Exclude","Keep") | M21: =IF(H21=1,"Pre-study accuracy",IF(I21=1,"Post-study accuracy",IF(J21=1,"Eye tracking quality",IF(K21=1,"Face quality","")))) | N21: =MAX(C21:D21) | O21: =IF(AND(L21="Keep",N21<=$D$2),"Keep","Exclude") | P21: =D21-C21 | R21: Kept, Visual first | S21: =COUNTIFS($B$5:$B$182,"Visual first",$L$5:$L$182,"Keep") | T21: =COUNTIFS($B$5:$B$182,"Visual first",$L$5:$L$182,"Keep")
A22: RESP0023 | B22: =INDEX(Session!$M$2:$M$261,MATCH($A22,Session!$A$2:$A$261,0)) | C22: =SUMIFS(Quality!$E$2:$E$1247,Quality!$A$2:$A$1247,$A22,Quality!$D$2:$D$1247,"Pre-study calibration") | D22: =SUMIFS(Quality!$E$2:$E$1247,Quality!$A$2:$A$1247,$A22,Quality!$D$2:$D$1247,"Post-study calibration") | E22: =SUMIFS(Quality!$F$2:$F$1247,Quality!$A$2:$A$1247,$A22,Quality!$D$2:$D$1247,"infographic") | F22: =SUMIFS(Quality!$G$2:$G$1247,Quality!$A$2:$A$1247,$A22,Quality!$D$2:$D$1247,"foodwaste_narrative") | G22: =SUMIFS(Quality!$G$2:$G$1247,Quality!$A$2:$A$1247,$A22,Quality!$D$2:$D$1247,"foodwaste_visual") | H22: =IF(C22>$B$2,1,0) | I22: =IF(D22>$B$2,1,0) | J22: =IF(E22<$F$2,1,0) | K22: =IF(OR(F22<$H$2,G22<$H$2),1,0) | L22: =IF(SUM(H22:K22)>0,"Exclude","Keep") | M22: =IF(H22=1,"Pre-study accuracy",IF(I22=1,"Post-study accuracy",IF(J22=1,"Eye tracking quality",IF(K22=1,"Face quality","")))) | N22: =MAX(C22:D22) | O22: =IF(AND(L22="Keep",N22<=$D$2),"Keep","Exclude") | P22: =D22-C22 | R22: Kept at 3.0 degrees | S22: =COUNTIF($O$5:$O$182,"Keep") | T22: =COUNTIF($O$5:$O$182,"Keep")
A23: RESP0024 | B23: =INDEX(Session!$M$2:$M$261,MATCH($A23,Session!$A$2:$A$261,0)) | C23: =SUMIFS(Quality!$E$2:$E$1247,Quality!$A$2:$A$1247,$A23,Quality!$D$2:$D$1247,"Pre-study calibration") | D23: =SUMIFS(Quality!$E$2:$E$1247,Quality!$A$2:$A$1247,$A23,Quality!$D$2:$D$1247,"Post-study calibration") | E23: =SUMIFS(Quality!$F$2:$F$1247,Quality!$A$2:$A$1247,$A23,Quality!$D$2:$D$1247,"infographic") | F23: =SUMIFS(Quality!$G$2:$G$1247,Quality!$A$2:$A$1247,$A23,Quality!$D$2:$D$1247,"foodwaste_narrative") | G23: =SUMIFS(Quality!$G$2:$G$1247,Quality!$A$2:$A$1247,$A23,Quality!$D$2:$D$1247,"foodwaste_visual") | H23: =IF(C23>$B$2,1,0) | I23: =IF(D23>$B$2,1,0) | J23: =IF(E23<$F$2,1,0) | K23: =IF(OR(F23<$H$2,G23<$H$2),1,0) | L23: =IF(SUM(H23:K23)>0,"Exclude","Keep") | M23: =IF(H23=1,"Pre-study accuracy",IF(I23=1,"Post-study accuracy",IF(J23=1,"Eye tracking quality",IF(K23=1,"Face quality","")))) | N23: =MAX(C23:D23) | O23: =IF(AND(L23="Keep",N23<=$D$2),"Keep","Exclude") | P23: =D23-C23 | R23: Further removed at 3.0 degrees | S23: =S9-S22 | T23: =S9-S22
A24: RESP0025 | B24: =INDEX(Session!$M$2:$M$261,MATCH($A24,Session!$A$2:$A$261,0)) | C24: =SUMIFS(Quality!$E$2:$E$1247,Quality!$A$2:$A$1247,$A24,Quality!$D$2:$D$1247,"Pre-study calibration") | D24: =SUMIFS(Quality!$E$2:$E$1247,Quality!$A$2:$A$1247,$A24,Quality!$D$2:$D$1247,"Post-study calibration") | E24: =SUMIFS(Quality!$F$2:$F$1247,Quality!$A$2:$A$1247,$A24,Quality!$D$2:$D$1247,"infographic") | F24: =SUMIFS(Quality!$G$2:$G$1247,Quality!$A$2:$A$1247,$A24,Quality!$D$2:$D$1247,"foodwaste_narrative") | G24: =SUMIFS(Quality!$G$2:$G$1247,Quality!$A$2:$A$1247,$A24,Quality!$D$2:$D$1247,"foodwaste_visual") | H24: =IF(C24>$B$2,1,0) | I24: =IF(D24>$B$2,1,0) | J24: =IF(E24<$F$2,1,0) | K24: =IF(OR(F24<$H$2,G24<$H$2),1,0) | L24: =IF(SUM(H24:K24)>0,"Exclude","Keep") | M24: =IF(H24=1,"Pre-study accuracy",IF(I24=1,"Post-study accuracy",IF(J24=1,"Eye tracking quality",IF(K24=1,"Face quality","")))) | N24: =MAX(C24:D24) | O24: =IF(AND(L24="Keep",N24<=$D$2),"Keep","Exclude") | P24: =D24-C24
A25: RESP0026 | B25: =INDEX(Session!$M$2:$M$261,MATCH($A25,Session!$A$2:$A$261,0)) | C25: =SUMIFS(Quality!$E$2:$E$1247,Quality!$A$2:$A$1247,$A25,Quality!$D$2:$D$1247,"Pre-study calibration") | D25: =SUMIFS(Quality!$E$2:$E$1247,Quality!$A$2:$A$1247,$A25,Quality!$D$2:$D$1247,"Post-study calibration") | E25: =SUMIFS(Quality!$F$2:$F$1247,Quality!$A$2:$A$1247,$A25,Quality!$D$2:$D$1247,"infographic") | F25: =SUMIFS(Quality!$G$2:$G$1247,Quality!$A$2:$A$1247,$A25,Quality!$D$2:$D$1247,"foodwaste_narrative") | G25: =SUMIFS(Quality!$G$2:$G$1247,Quality!$A$2:$A$1247,$A25,Quality!$D$2:$D$1247,"foodwaste_visual") | H25: =IF(C25>$B$2,1,0) | I25: =IF(D25>$B$2,1,0) | J25: =IF(E25<$F$2,1,0) | K25: =IF(OR(F25<$H$2,G25<$H$2),1,0) | L25: =IF(SUM(H25:K25)>0,"Exclude","Keep") | M25: =IF(H25=1,"Pre-study accuracy",IF(I25=1,"Post-study accuracy",IF(J25=1,"Eye tracking quality",IF(K25=1,"Face quality","")))) | N25: =MAX(C25:D25) | O25: =IF(AND(L25="Keep",N25<=$D$2),"Keep","Exclude") | P25: =D25-C25
A26: RESP0028 | B26: =INDEX(Session!$M$2:$M$261,MATCH($A26,Session!$A$2:$A$261,0)) | C26: =SUMIFS(Quality!$E$2:$E$1247,Quality!$A$2:$A$1247,$A26,Quality!$D$2:$D$1247,"Pre-study calibration") | D26: =SUMIFS(Quality!$E$2:$E$1247,Quality!$A$2:$A$1247,$A26,Quality!$D$2:$D$1247,"Post-study calibration") | E26: =SUMIFS(Quality!$F$2:$F$1247,Quality!$A$2:$A$1247,$A26,Quality!$D$2:$D$1247,"infographic") | F26: =SUMIFS(Quality!$G$2:$G$1247,Quality!$A$2:$A$1247,$A26,Quality!$D$2:$D$1247,"foodwaste_narrative") | G26: =SUMIFS(Quality!$G$2:$G$1247,Quality!$A$2:$A$1247,$A26,Quality!$D$2:$D$1247,"foodwaste_visual") | H26: =IF(C26>$B$2,1,0) | I26: =IF(D26>$B$2,1,0) | J26: =IF(E26<$F$2,1,0) | K26: =IF(OR(F26<$H$2,G26<$H$2),1,0) | L26: =IF(SUM(H26:K26)>0,"Exclude","Keep") | M26: =IF(H26=1,"Pre-study accuracy",IF(I26=1,"Post-study accuracy",IF(J26=1,"Eye tracking quality",IF(K26=1,"Face quality","")))) | N26: =MAX(C26:D26) | O26: =IF(AND(L26="Keep",N26<=$D$2),"Keep","Exclude") | P26: =D26-C26 | R26: Statistic | S26: Value | T26: Formula shown | U26: Note
A27: RESP0029 | B27: =INDEX(Session!$M$2:$M$261,MATCH($A27,Session!$A$2:$A$261,0)) | C27: =SUMIFS(Quality!$E$2:$E$1247,Quality!$A$2:$A$1247,$A27,Quality!$D$2:$D$1247,"Pre-study calibration") | D27: =SUMIFS(Quality!$E$2:$E$1247,Quality!$A$2:$A$1247,$A27,Quality!$D$2:$D$1247,"Post-study calibration") | E27: =SUMIFS(Quality!$F$2:$F$1247,Quality!$A$2:$A$1247,$A27,Quality!$D$2:$D$1247,"infographic") | F27: =SUMIFS(Quality!$G$2:$G$1247,Quality!$A$2:$A$1247,$A27,Quality!$D$2:$D$1247,"foodwaste_narrative") | G27: =SUMIFS(Quality!$G$2:$G$1247,Quality!$A$2:$A$1247,$A27,Quality!$D$2:$D$1247,"foodwaste_visual") | H27: =IF(C27>$B$2,1,0) | I27: =IF(D27>$B$2,1,0) | J27: =IF(E27<$F$2,1,0) | K27: =IF(OR(F27<$H$2,G27<$H$2),1,0) | L27: =IF(SUM(H27:K27)>0,"Exclude","Keep") | M27: =IF(H27=1,"Pre-study accuracy",IF(I27=1,"Post-study accuracy",IF(J27=1,"Eye tracking quality",IF(K27=1,"Face quality","")))) | N27: =MAX(C27:D27) | O27: =IF(AND(L27="Keep",N27<=$D$2),"Keep","Exclude") | P27: =D27-C27 | R27: Calibration drift: Pre-study versus Post-study accuracy (all completed respondents)
