Workbook

Sheet README
A1: SIMULATED GSR and heart rate workbook (teaching material)
A3: Every number in this workbook is SIMULATED. It was generated by make_simulated_data.py (seed 20278504) to
A4: resemble a two commercial arousal test in the style of the lab's own library studies Nike Campaign Ad Evaluation and
A5: e.l.f. Campaign Ad Evaluation: a 60 s Baseline, the commercial (Nike 60 s, e.l.f. 30 s), a 15 s Recovery, and a short
A6: questionnaire, recorded with two Shimmer3 GSR+ units (GSR plus PPG heart rate). No real person was recorded.
A8: Sheets:
A9: Data GSR Peak Metrics export as exported (columns A to O, rows 2 to 181). Columns P to T hold the Device,
A10: Signal-to-Noise ratio, Signal missing, mean PPG heart rate, and self reported arousal matched to each row (pasted values).
A11: Helper columns U to AA are live formulas: Phase, Brand, Position (first or second sequence), Keep (exclusion rule),
A12: Nonresponder (Has Peaks = 0 in at least 4 of 6 stimuli), PPM_recalc, PPM_if_Duration.
A13: Summary Mean, SD, n by stimulus (COUNTIFS, AVERAGEIFS, STDEV.S(IF(...))), the Signal Duration check, the device check.
A14: H1 Arousal response. Paired t tests of each commercial against its own baseline (Peaks Per Minute), the sensitivity analysis
... A30: analysis_output.txt (its console output), results_text.md (model paragraphs).

Sheet Data
A1: Study Name | B1: Respondent Name | C1: Gender | D1: Age | E1: Group | F1: Type | G1: Label | H1: Start (ms) | I1: Duration (ms) | J1: Signal Duration (ms) | K1: Parent Stimulus | L1: Has Peaks | M1: Peak Count | N1: Peaks Per Minute | O1: Average Peak Amplitude (microSiemens) | P1: Device | Q1: Signal-to-Noise ratio (dB) | R1: Signal missing (%) | S1: Mean PPG Heart Rate (BPM) | T1: Arousal_1to9 (survey) | U1: Phase | V1: Brand | W1: Position | X1: Keep | Y1: Nonresponder | Z1: PPM_recalc | AA1: PPM_if_Duration
A2: SIMULATED_Arousal_Nike_vs_elf | B2: P01 | C2: M | D2: 35 | E2: B | F2: Stimulus | G2: Baseline_Nike | H2: 303859 | I2: 60000 | J2: 60000 | K2: Baseline_Nike | L2: 1 | M2: 3 | N2: 3 | O2: 0.2683 | P2: Shimmer3-8956 | Q2: 23.3 | R2: 0 | S2: 81.6 | T2: NA | U2: =IF(LEFT(G2,8)="Baseline","Baseline",IF(LEFT(G2,8)="Recovery","Recovery","Commercial")) | V2: =IF(ISNUMBER(SEARCH("Nike",G2)),"Nike","elf") | W2: =IF(OR(AND(E2="A",V2="Nike"),AND(E2="B",V2="elf")),"first","second") | X2: =IF(COUNTIFS(Data!$B$2:$B$181,B2,Data!$U$2:$U$181,"Commercial",Data!$Q$2:$Q$181,"<0")+COUNTIFS(Data!$B$2:$B$181,B2,Data!$U$2:$U$181,"Commercial",Data!$R$2:$R$181,">20")>0,"No","Yes") | Y2: =IF(COUNTIFS(Data!$B$2:$B$181,B2,Data!$L$2:$L$181,0)>=4,1,0) | Z2: =M2/(J2/60000) | AA2: =M2/(I2/60000)
A3: SIMULATED_Arousal_Nike_vs_elf | B3: P01 | C3: M | D3: 35 | E3: B | F3: Stimulus | G3: Nike_Commercial | H3: 363859 | I3: 60000 | J3: 60000 | K3: Nike_Commercial | L3: 1 | M3: 7 | N3: 7 | O3: 0.5089 | P3: Shimmer3-8956 | Q3: 20.8 | R3: 0 | S3: 82.1 | T3: 5 | U3: =IF(LEFT(G3,8)="Baseline","Baseline",IF(LEFT(G3,8)="Recovery","Recovery","Commercial")) | V3: =IF(ISNUMBER(SEARCH("Nike",G3)),"Nike","elf") | W3: =IF(OR(AND(E3="A",V3="Nike"),AND(E3="B",V3="elf")),"first","second") | X3: =IF(COUNTIFS(Data!$B$2:$B$181,B3,Data!$U$2:$U$181,"Commercial",Data!$Q$2:$Q$181,"<0")+COUNTIFS(Data!$B$2:$B$181,B3,Data!$U$2:$U$181,"Commercial",Data!$R$2:$R$181,">20")>0,"No","Yes") | Y3: =IF(COUNTIFS(Data!$B$2:$B$181,B3,Data!$L$2:$L$181,0)>=4,1,0) | Z3: =M3/(J3/60000) | AA3: =M3/(I3/60000)
A4: SIMULATED_Arousal_Nike_vs_elf | B4: P01 | C4: M | D4: 35 | E4: B | F4: Stimulus | G4: Recovery_Nike | H4: 423859 | I4: 15000 | J4: 15000 | K4: Recovery_Nike | L4: 0 | M4: 0 | N4: 0 | O4: NA | P4: Shimmer3-8956 | Q4: 22.2 | R4: 0 | S4: 84.3 | T4: NA | U4: =IF(LEFT(G4,8)="Baseline","Baseline",IF(LEFT(G4,8)="Recovery","Recovery","Commercial")) | V4: =IF(ISNUMBER(SEARCH("Nike",G4)),"Nike","elf") | W4: =IF(OR(AND(E4="A",V4="Nike"),AND(E4="B",V4="elf")),"first","second") | X4: =IF(COUNTIFS(Data!$B$2:$B$181,B4,Data!$U$2:$U$181,"Commercial",Data!$Q$2:$Q$181,"<0")+COUNTIFS(Data!$B$2:$B$181,B4,Data!$U$2:$U$181,"Commercial",Data!$R$2:$R$181,">20")>0,"No","Yes") | Y4: =IF(COUNTIFS(Data!$B$2:$B$181,B4,Data!$L$2:$L$181,0)>=4,1,0) | Z4: =M4/(J4/60000) | AA4: =M4/(I4/60000)
A5: SIMULATED_Arousal_Nike_vs_elf | B5: P01 | C5: M | D5: 35 | E5: B | F5: Stimulus | G5: Baseline_elf | H5: 36744 | I5: 60000 | J5: 60000 | K5: Baseline_elf | L5: 0 | M5: 0 | N5: 0 | O5: NA | P5: Shimmer3-8956 | Q5: 23 | R5: 2.6 | S5: 82.7 | T5: NA | U5: =IF(LEFT(G5,8)="Baseline","Baseline",IF(LEFT(G5,8)="Recovery","Recovery","Commercial")) | V5: =IF(ISNUMBER(SEARCH("Nike",G5)),"Nike","elf") | W5: =IF(OR(AND(E5="A",V5="Nike"),AND(E5="B",V5="elf")),"first","second") | X5: =IF(COUNTIFS(Data!$B$2:$B$181,B5,Data!$U$2:$U$181,"Commercial",Data!$Q$2:$Q$181,"<0")+COUNTIFS(Data!$B$2:$B$181,B5,Data!$U$2:$U$181,"Commercial",Data!$R$2:$R$181,">20")>0,"No","Yes") | Y5: =IF(COUNTIFS(Data!$B$2:$B$181,B5,Data!$L$2:$L$181,0)>=4,1,0) | Z5: =M5/(J5/60000) | AA5: =M5/(I5/60000)
A6: SIMULATED_Arousal_Nike_vs_elf | B6: P01 | C6: M | D6: 35 | E6: B | F6: Stimulus | G6: elf_Commercial | H6: 96744 | I6: 30000 | J6: 30000 | K6: elf_Commercial | L6: 1 | M6: 1 | N6: 2 | O6: 0.4461 | P6: Shimmer3-8956 | Q6: 19.5 | R6: 0 | S6: 79.7 | T6: 3 | U6: =IF(LEFT(G6,8)="Baseline","Baseline",IF(LEFT(G6,8)="Recovery","Recovery","Commercial")) | V6: =IF(ISNUMBER(SEARCH("Nike",G6)),"Nike","elf") | W6: =IF(OR(AND(E6="A",V6="Nike"),AND(E6="B",V6="elf")),"first","second") | X6: =IF(COUNTIFS(Data!$B$2:$B$181,B6,Data!$U$2:$U$181,"Commercial",Data!$Q$2:$Q$181,"<0")+COUNTIFS(Data!$B$2:$B$181,B6,Data!$U$2:$U$181,"Commercial",Data!$R$2:$R$181,">20")>0,"No","Yes") | Y6: =IF(COUNTIFS(Data!$B$2:$B$181,B6,Data!$L$2:$L$181,0)>=4,1,0) | Z6: =M6/(J6/60000) | AA6: =M6/(I6/60000)
A7: SIMULATED_Arousal_Nike_vs_elf | B7: P01 | C7: M | D7: 35 | E7: B | F7: Stimulus | G7: Recovery_elf | H7: 126744 | I7: 15000 | J7: 15000 | K7: Recovery_elf | L7: 0 | M7: 0 | N7: 0 | O7: NA | P7: Shimmer3-8956 | Q7: 20.7 | R7: 3.7 | S7: 81.2 | T7: NA | U7: =IF(LEFT(G7,8)="Baseline","Baseline",IF(LEFT(G7,8)="Recovery","Recovery","Commercial")) | V7: =IF(ISNUMBER(SEARCH("Nike",G7)),"Nike","elf") | W7: =IF(OR(AND(E7="A",V7="Nike"),AND(E7="B",V7="elf")),"first","second") | X7: =IF(COUNTIFS(Data!$B$2:$B$181,B7,Data!$U$2:$U$181,"Commercial",Data!$Q$2:$Q$181,"<0")+COUNTIFS(Data!$B$2:$B$181,B7,Data!$U$2:$U$181,"Commercial",Data!$R$2:$R$181,">20")>0,"No","Yes") | Y7: =IF(COUNTIFS(Data!$B$2:$B$181,B7,Data!$L$2:$L$181,0)>=4,1,0) | Z7: =M7/(J7/60000) | AA7: =M7/(I7/60000)
A8: SIMULATED_Arousal_Nike_vs_elf | B8: P02 | C8: F | D8: 22 | E8: A | F8: Stimulus | G8: Baseline_Nike | H8: 37605 | I8: 60000 | J8: 54900 | K8: Baseline_Nike | L8: 1 | M8: 3 | N8: 3.279 | O8: 0.1754 | P8: Shimmer3-B | Q8: 21.7 | R8: 8.5 | S8: 74.6 | T8: NA | U8: =IF(LEFT(G8,8)="Baseline","Baseline",IF(LEFT(G8,8)="Recovery","Recovery","Commercial")) | V8: =IF(ISNUMBER(SEARCH("Nike",G8)),"Nike","elf") | W8: =IF(OR(AND(E8="A",V8="Nike"),AND(E8="B",V8="elf")),"first","second") | X8: =IF(COUNTIFS(Data!$B$2:$B$181,B8,Data!$U$2:$U$181,"Commercial",Data!$Q$2:$Q$181,"<0")+COUNTIFS(Data!$B$2:$B$181,B8,Data!$U$2:$U$181,"Commercial",Data!$R$2:$R$181,">20")>0,"No","Yes") | Y8: =IF(COUNTIFS(Data!$B$2:$B$181,B8,Data!$L$2:$L$181,0)>=4,1,0) | Z8: =M8/(J8/60000) | AA8: =M8/(I8/60000)
A9: SIMULATED_Arousal_Nike_vs_elf | B9: P02 | C9: F | D9: 22 | E9: A | F9: Stimulus | G9: Nike_Commercial | H9: 97605 | I9: 60000 | J9: 60000 | K9: Nike_Commercial | L9: 1 | M9: 3 | N9: 3 | O9: 0.2869 | P9: Shimmer3-B | Q9: 21.3 | R9: 0 | S9: 73.5 | T9: 5 | U9: =IF(LEFT(G9,8)="Baseline","Baseline",IF(LEFT(G9,8)="Recovery","Recovery","Commercial")) | V9: =IF(ISNUMBER(SEARCH("Nike",G9)),"Nike","elf") | W9: =IF(OR(AND(E9="A",V9="Nike"),AND(E9="B",V9="elf")),"first","second") | X9: =IF(COUNTIFS(Data!$B$2:$B$181,B9,Data!$U$2:$U$181,"Commercial",Data!$Q$2:$Q$181,"<0")+COUNTIFS(Data!$B$2:$B$181,B9,Data!$U$2:$U$181,"Commercial",Data!$R$2:$R$181,">20")>0,"No","Yes") | Y9: =IF(COUNTIFS(Data!$B$2:$B$181,B9,Data!$L$2:$L$181,0)>=4,1,0) | Z9: =M9/(J9/60000) | AA9: =M9/(I9/60000)
A10: SIMULATED_Arousal_Nike_vs_elf | B10: P02 | C10: F | D10: 22 | E10: A | F10: Stimulus | G10: Recovery_Nike | H10: 157605 | I10: 15000 | J10: 15000 | K10: Recovery_Nike | L10: 1 | M10: 1 | N10: 4 | O10: 0.1389 | P10: Shimmer3-B | Q10: 26.1 | R10: 0 | S10: 74.4 | T10: NA | U10: =IF(LEFT(G10,8)="Baseline","Baseline",IF(LEFT(G10,8)="Recovery","Recovery","Commercial")) | V10: =IF(ISNUMBER(SEARCH("Nike",G10)),"Nike","elf") | W10: =IF(OR(AND(E10="A",V10="Nike"),AND(E10="B",V10="elf")),"first","second") | X10: =IF(COUNTIFS(Data!$B$2:$B$181,B10,Data!$U$2:$U$181,"Commercial",Data!$Q$2:$Q$181,"<0")+COUNTIFS(Data!$B$2:$B$181,B10,Data!$U$2:$U$181,"Commercial",Data!$R$2:$R$181,">20")>0,"No","Yes") | Y10: =IF(COUNTIFS(Data!$B$2:$B$181,B10,Data!$L$2:$L$181,0)>=4,1,0) | Z10: =M10/(J10/60000) | AA10: =M10/(I10/60000)
A11: SIMULATED_Arousal_Nike_vs_elf | B11: P02 | C11: F | D11: 22 | E11: A | F11: Stimulus | G11: Baseline_elf | H11: 345129 | I11: 60000 | J11: 60000 | K11: Baseline_elf | L11: 1 | M11: 2 | N11: 2 | O11: 0.1886 | P11: Shimmer3-B | Q11: 20.9 | R11: 0 | S11: 73.5 | T11: NA | U11: =IF(LEFT(G11,8)="Baseline","Baseline",IF(LEFT(G11,8)="Recovery","Recovery","Commercial")) | V11: =IF(ISNUMBER(SEARCH("Nike",G11)),"Nike","elf") | W11: =IF(OR(AND(E11="A",V11="Nike"),AND(E11="B",V11="elf")),"first","second") | X11: =IF(COUNTIFS(Data!$B$2:$B$181,B11,Data!$U$2:$U$181,"Commercial",Data!$Q$2:$Q$181,"<0")+COUNTIFS(Data!$B$2:$B$181,B11,Data!$U$2:$U$181,"Commercial",Data!$R$2:$R$181,">20")>0,"No","Yes") | Y11: =IF(COUNTIFS(Data!$B$2:$B$181,B11,Data!$L$2:$L$181,0)>=4,1,0) | Z11: =M11/(J11/60000) | AA11: =M11/(I11/60000)
A12: SIMULATED_Arousal_Nike_vs_elf | B12: P02 | C12: F | D12: 22 | E12: A | F12: Stimulus | G12: elf_Commercial | H12: 405129 | I12: 30000 | J12: 30000 | K12: elf_Commercial | L12: 1 | M12: 2 | N12: 4 | O12: 0.2249 | P12: Shimmer3-B | Q12: 22.2 | R12: 0 | S12: 70.4 | T12: 4 | U12: =IF(LEFT(G12,8)="Baseline","Baseline",IF(LEFT(G12,8)="Recovery","Recovery","Commercial")) | V12: =IF(ISNUMBER(SEARCH("Nike",G12)),"Nike","elf") | W12: =IF(OR(AND(E12="A",V12="Nike"),AND(E12="B",V12="elf")),"first","second") | X12: =IF(COUNTIFS(Data!$B$2:$B$181,B12,Data!$U$2:$U$181,"Commercial",Data!$Q$2:$Q$181,"<0")+COUNTIFS(Data!$B$2:$B$181,B12,Data!$U$2:$U$181,"Commercial",Data!$R$2:$R$181,">20")>0,"No","Yes") | Y12: =IF(COUNTIFS(Data!$B$2:$B$181,B12,Data!$L$2:$L$181,0)>=4,1,0) | Z12: =M12/(J12/60000) | AA12: =M12/(I12/60000)
A13: SIMULATED_Arousal_Nike_vs_elf | B13: P02 | C13: F | D13: 22 | E13: A | F13: Stimulus | G13: Recovery_elf | H13: 435129 | I13: 15000 | J13: 15000 | K13: Recovery_elf | L13: 1 | M13: 1 | N13: 4 | O13: 0.237 | P13: Shimmer3-B | Q13: 19.2 | R13: 0 | S13: 74.6 | T13: NA | U13: =IF(LEFT(G13,8)="Baseline","Baseline",IF(LEFT(G13,8)="Recovery","Recovery","Commercial")) | V13: =IF(ISNUMBER(SEARCH("Nike",G13)),"Nike","elf") | W13: =IF(OR(AND(E13="A",V13="Nike"),AND(E13="B",V13="elf")),"first","second") | X13: =IF(COUNTIFS(Data!$B$2:$B$181,B13,Data!$U$2:$U$181,"Commercial",Data!$Q$2:$Q$181,"<0")+COUNTIFS(Data!$B$2:$B$181,B13,Data!$U$2:$U$181,"Commercial",Data!$R$2:$R$181,">20")>0,"No","Yes") | Y13: =IF(COUNTIFS(Data!$B$2:$B$181,B13,Data!$L$2:$L$181,0)>=4,1,0) | Z13: =M13/(J13/60000) | AA13: =M13/(I13/60000)
A14: SIMULATED_Arousal_Nike_vs_elf | B14: P03 | C14: F | D14: 31 | E14: B | F14: Stimulus | G14: Baseline_Nike | H14: 319025 | I14: 60000 | J14: 60000 | K14: Baseline_Nike | L14: 1 | M14: 1 | N14: 1 | O14: 0.0668 | P14: Shimmer3-B | Q14: 16 | R14: 0.6 | S14: 74 | T14: NA | U14: =IF(LEFT(G14,8)="Baseline","Baseline",IF(LEFT(G14,8)="Recovery","Recovery","Commercial")) | V14: =IF(ISNUMBER(SEARCH("Nike",G14)),"Nike","elf") | W14: =IF(OR(AND(E14="A",V14="Nike"),AND(E14="B",V14="elf")),"first","second") | X14: =IF(COUNTIFS(Data!$B$2:$B$181,B14,Data!$U$2:$U$181,"Commercial",Data!$Q$2:$Q$181,"<0")+COUNTIFS(Data!$B$2:$B$181,B14,Data!$U$2:$U$181,"Commercial",Data!$R$2:$R$181,">20")>0,"No","Yes") | Y14: =IF(COUNTIFS(Data!$B$2:$B$181,B14,Data!$L$2:$L$181,0)>=4,1,0) | Z14: =M14/(J14/60000) | AA14: =M14/(I14/60000)
A15: SIMULATED_Arousal_Nike_vs_elf | B15: P03 | C15: F | D15: 31 | E15: B | F15: Stimulus | G15: Nike_Commercial | H15: 379025 | I15: 60000 | J15: 60000 | K15: Nike_Commercial | L15: 0 | M15: 0 | N15: 0 | O15: NA | P15: Shimmer3-B | Q15: 17.8 | R15: 0.5 | S15: 74 | T15: 5 | U15: =IF(LEFT(G15,8)="Baseline","Baseline",IF(LEFT(G15,8)="Recovery","Recovery","Commercial")) | V15: =IF(ISNUMBER(SEARCH("Nike",G15)),"Nike","elf") | W15: =IF(OR(AND(E15="A",V15="Nike"),AND(E15="B",V15="elf")),"first","second") | X15: =IF(COUNTIFS(Data!$B$2:$B$181,B15,Data!$U$2:$U$181,"Commercial",Data!$Q$2:$Q$181,"<0")+COUNTIFS(Data!$B$2:$B$181,B15,Data!$U$2:$U$181,"Commercial",Data!$R$2:$R$181,">20")>0,"No","Yes") | Y15: =IF(COUNTIFS(Data!$B$2:$B$181,B15,Data!$L$2:$L$181,0)>=4,1,0) | Z15: =M15/(J15/60000) | AA15: =M15/(I15/60000)
A16: SIMULATED_Arousal_Nike_vs_elf | B16: P03 | C16: F | D16: 31 | E16: B | F16: Stimulus | G16: Recovery_Nike | H16: 439025 | I16: 15000 | J16: 15000 | K16: Recovery_Nike | L16: 0 | M16: 0 | N16: 0 | O16: NA | P16: Shimmer3-B | Q16: 15.9 | R16: 0 | S16: 71.6 | T16: NA | U16: =IF(LEFT(G16,8)="Baseline","Baseline",IF(LEFT(G16,8)="Recovery","Recovery","Commercial")) | V16: =IF(ISNUMBER(SEARCH("Nike",G16)),"Nike","elf") | W16: =IF(OR(AND(E16="A",V16="Nike"),AND(E16="B",V16="elf")),"first","second") | X16: =IF(COUNTIFS(Data!$B$2:$B$181,B16,Data!$U$2:$U$181,"Commercial",Data!$Q$2:$Q$181,"<0")+COUNTIFS(Data!$B$2:$B$181,B16,Data!$U$2:$U$181,"Commercial",Data!$R$2:$R$181,">20")>0,"No","Yes") | Y16: =IF(COUNTIFS(Data!$B$2:$B$181,B16,Data!$L$2:$L$181,0)>=4,1,0) | Z16: =M16/(J16/60000) | AA16: =M16/(I16/60000)
A17: SIMULATED_Arousal_Nike_vs_elf | B17: P03 | C17: F | D17: 31 | E17: B | F17: Stimulus | G17: Baseline_elf | H17: 39501 | I17: 60000 | J17: 60000 | K17: Baseline_elf | L17: 0 | M17: 0 | N17: 0 | O17: NA | P17: Shimmer3-B | Q17: 15.5 | R17: 0 | S17: 73.9 | T17: NA | U17: =IF(LEFT(G17,8)="Baseline","Baseline",IF(LEFT(G17,8)="Recovery","Recovery","Commercial")) | V17: =IF(ISNUMBER(SEARCH("Nike",G17)),"Nike","elf") | W17: =IF(OR(AND(E17="A",V17="Nike"),AND(E17="B",V17="elf")),"first","second") | X17: =IF(COUNTIFS(Data!$B$2:$B$181,B17,Data!$U$2:$U$181,"Commercial",Data!$Q$2:$Q$181,"<0")+COUNTIFS(Data!$B$2:$B$181,B17,Data!$U$2:$U$181,"Commercial",Data!$R$2:$R$181,">20")>0,"No","Yes") | Y17: =IF(COUNTIFS(Data!$B$2:$B$181,B17,Data!$L$2:$L$181,0)>=4,1,0) | Z17: =M17/(J17/60000) | AA17: =M17/(I17/60000)
A18: SIMULATED_Arousal_Nike_vs_elf | B18: P03 | C18: F | D18: 31 | E18: B | F18: Stimulus | G18: elf_Commercial | H18: 99501 | I18: 30000 | J18: 30000 | K18: elf_Commercial | L18: 0 | M18: 0 | N18: 0 | O18: NA | P18: Shimmer3-B | Q18: 14.5 | R18: 0 | S18: 74.4 | T18: 4 | U18: =IF(LEFT(G18,8)="Baseline","Baseline",IF(LEFT(G18,8)="Recovery","Recovery","Commercial")) | V18: =IF(ISNUMBER(SEARCH("Nike",G18)),"Nike","elf") | W18: =IF(OR(AND(E18="A",V18="Nike"),AND(E18="B",V18="elf")),"first","second") | X18: =IF(COUNTIFS(Data!$B$2:$B$181,B18,Data!$U$2:$U$181,"Commercial",Data!$Q$2:$Q$181,"<0")+COUNTIFS(Data!$B$2:$B$181,B18,Data!$U$2:$U$181,"Commercial",Data!$R$2:$R$181,">20")>0,"No","Yes") | Y18: =IF(COUNTIFS(Data!$B$2:$B$181,B18,Data!$L$2:$L$181,0)>=4,1,0) | Z18: =M18/(J18/60000) | AA18: =M18/(I18/60000)
A19: SIMULATED_Arousal_Nike_vs_elf | B19: P03 | C19: F | D19: 31 | E19: B | F19: Stimulus | G19: Recovery_elf | H19: 129501 | I19: 15000 | J19: 15000 | K19: Recovery_elf | L19: 0 | M19: 0 | N19: 0 | O19: NA | P19: Shimmer3-B | Q19: 16.6 | R19: 0 | S19: 73.6 | T19: NA | U19: =IF(LEFT(G19,8)="Baseline","Baseline",IF(LEFT(G19,8)="Recovery","Recovery","Commercial")) | V19: =IF(ISNUMBER(SEARCH("Nike",G19)),"Nike","elf") | W19: =IF(OR(AND(E19="A",V19="Nike"),AND(E19="B",V19="elf")),"first","second") | X19: =IF(COUNTIFS(Data!$B$2:$B$181,B19,Data!$U$2:$U$181,"Commercial",Data!$Q$2:$Q$181,"<0")+COUNTIFS(Data!$B$2:$B$181,B19,Data!$U$2:$U$181,"Commercial",Data!$R$2:$R$181,">20")>0,"No","Yes") | Y19: =IF(COUNTIFS(Data!$B$2:$B$181,B19,Data!$L$2:$L$181,0)>=4,1,0) | Z19: =M19/(J19/60000) | AA19: =M19/(I19/60000)
A20: SIMULATED_Arousal_Nike_vs_elf | B20: P04 | C20: M | D20: 33 | E20: A | F20: Stimulus | G20: Baseline_Nike | H20: 27608 | I20: 60000 | J20: 60000 | K20: Baseline_Nike | L20: 1 | M20: 2 | N20: 2 | O20: 0.1484 | P20: Shimmer3-8956 | Q20: 20.8 | R20: 0 | S20: 80.1 | T20: NA | U20: =IF(LEFT(G20,8)="Baseline","Baseline",IF(LEFT(G20,8)="Recovery","Recovery","Commercial")) | V20: =IF(ISNUMBER(SEARCH("Nike",G20)),"Nike","elf") | W20: =IF(OR(AND(E20="A",V20="Nike"),AND(E20="B",V20="elf")),"first","second") | X20: =IF(COUNTIFS(Data!$B$2:$B$181,B20,Data!$U$2:$U$181,"Commercial",Data!$Q$2:$Q$181,"<0")+COUNTIFS(Data!$B$2:$B$181,B20,Data!$U$2:$U$181,"Commercial",Data!$R$2:$R$181,">20")>0,"No","Yes") | Y20: =IF(COUNTIFS(Data!$B$2:$B$181,B20,Data!$L$2:$L$181,0)>=4,1,0) | Z20: =M20/(J20/60000) | AA20: =M20/(I20/60000)
A21: SIMULATED_Arousal_Nike_vs_elf | B21: P04 | C21: M | D21: 33 | E21: A | F21: Stimulus | G21: Nike_Commercial | H21: 87608 | I21: 60000 | J21: 60000 | K21: Nike_Commercial | L21: 1 | M21: 5 | N21: 5 | O21: 0.2084 | P21: Shimmer3-8956 | Q21: 25 | R21: 0.9 | S21: 76.5 | T21: 5 | U21: =IF(LEFT(G21,8)="Baseline","Baseline",IF(LEFT(G21,8)="Recovery","Recovery","Commercial")) | V21: =IF(ISNUMBER(SEARCH("Nike",G21)),"Nike","elf") | W21: =IF(OR(AND(E21="A",V21="Nike"),AND(E21="B",V21="elf")),"first","second") | X21: =IF(COUNTIFS(Data!$B$2:$B$181,B21,Data!$U$2:$U$181,"Commercial",Data!$Q$2:$Q$181,"<0")+COUNTIFS(Data!$B$2:$B$181,B21,Data!$U$2:$U$181,"Commercial",Data!$R$2:$R$181,">20")>0,"No","Yes") | Y21: =IF(COUNTIFS(Data!$B$2:$B$181,B21,Data!$L$2:$L$181,0)>=4,1,0) | Z21: =M21/(J21/60000) | AA21: =M21/(I21/60000)
A22: SIMULATED_Arousal_Nike_vs_elf | B22: P04 | C22: M | D22: 33 | E22: A | F22: Stimulus | G22: Recovery_Nike | H22: 147608 | I22: 15000 | J22: 15000 | K22: Recovery_Nike | L22: 1 | M22: 1 | N22: 4 | O22: 0.158 | P22: Shimmer3-8956 | Q22: 20 | R22: 0 | S22: 77.1 | T22: NA | U22: =IF(LEFT(G22,8)="Baseline","Baseline",IF(LEFT(G22,8)="Recovery","Recovery","Commercial")) | V22: =IF(ISNUMBER(SEARCH("Nike",G22)),"Nike","elf") | W22: =IF(OR(AND(E22="A",V22="Nike"),AND(E22="B",V22="elf")),"first","second") | X22: =IF(COUNTIFS(Data!$B$2:$B$181,B22,Data!$U$2:$U$181,"Commercial",Data!$Q$2:$Q$181,"<0")+COUNTIFS(Data!$B$2:$B$181,B22,Data!$U$2:$U$181,"Commercial",Data!$R$2:$R$181,">20")>0,"No","Yes") | Y22: =IF(COUNTIFS(Data!$B$2:$B$181,B22,Data!$L$2:$L$181,0)>=4,1,0) | Z22: =M22/(J22/60000) | AA22: =M22/(I22/60000)
A23: SIMULATED_Arousal_Nike_vs_elf | B23: P04 | C23: M | D23: 33 | E23: A | F23: Stimulus | G23: Baseline_elf | H23: 330113 | I23: 60000 | J23: 60000 | K23: Baseline_elf | L23: 1 | M23: 2 | N23: 2 | O23: 0.153 | P23: Shimmer3-8956 | Q23: 19.3 | R23: 0.1 | S23: 74.1 | T23: NA | U23: =IF(LEFT(G23,8)="Baseline","Baseline",IF(LEFT(G23,8)="Recovery","Recovery","Commercial")) | V23: =IF(ISNUMBER(SEARCH("Nike",G23)),"Nike","elf") | W23: =IF(OR(AND(E23="A",V23="Nike"),AND(E23="B",V23="elf")),"first","second") | X23: =IF(COUNTIFS(Data!$B$2:$B$181,B23,Data!$U$2:$U$181,"Commercial",Data!$Q$2:$Q$181,"<0")+COUNTIFS(Data!$B$2:$B$181,B23,Data!$U$2:$U$181,"Commercial",Data!$R$2:$R$181,">20")>0,"No","Yes") | Y23: =IF(COUNTIFS(Data!$B$2:$B$181,B23,Data!$L$2:$L$181,0)>=4,1,0) | Z23: =M23/(J23/60000) | AA23: =M23/(I23/60000)
A24: SIMULATED_Arousal_Nike_vs_elf | B24: P04 | C24: M | D24: 33 | E24: A | F24: Stimulus | G24: elf_Commercial | H24: 390113 | I24: 30000 | J24: 30000 | K24: elf_Commercial | L24: 1 | M24: 2 | N24: 4 | O24: 0.2476 | P24: Shimmer3-8956 | Q24: 21.7 | R24: 0 | S24: 72.1 | T24: 2 | U24: =IF(LEFT(G24,8)="Baseline","Baseline",IF(LEFT(G24,8)="Recovery","Recovery","Commercial")) | V24: =IF(ISNUMBER(SEARCH("Nike",G24)),"Nike","elf") | W24: =IF(OR(AND(E24="A",V24="Nike"),AND(E24="B",V24="elf")),"first","second") | X24: =IF(COUNTIFS(Data!$B$2:$B$181,B24,Data!$U$2:$U$181,"Commercial",Data!$Q$2:$Q$181,"<0")+COUNTIFS(Data!$B$2:$B$181,B24,Data!$U$2:$U$181,"Commercial",Data!$R$2:$R$181,">20")>0,"No","Yes") | Y24: =IF(COUNTIFS(Data!$B$2:$B$181,B24,Data!$L$2:$L$181,0)>=4,1,0) | Z24: =M24/(J24/60000) | AA24: =M24/(I24/60000)
A25: SIMULATED_Arousal_Nike_vs_elf | B25: P04 | C25: M | D25: 33 | E25: A | F25: Stimulus | G25: Recovery_elf | H25: 420113 | I25: 15000 | J25: 15000 | K25: Recovery_elf | L25: 1 | M25: 1 | N25: 4 | O25: 0.1323 | P25: Shimmer3-8956 | Q25: 18.5 | R25: 1.1 | S25: 73.5 | T25: NA | U25: =IF(LEFT(G25,8)="Baseline","Baseline",IF(LEFT(G25,8)="Recovery","Recovery","Commercial")) | V25: =IF(ISNUMBER(SEARCH("Nike",G25)),"Nike","elf") | W25: =IF(OR(AND(E25="A",V25="Nike"),AND(E25="B",V25="elf")),"first","second") | X25: =IF(COUNTIFS(Data!$B$2:$B$181,B25,Data!$U$2:$U$181,"Commercial",Data!$Q$2:$Q$181,"<0")+COUNTIFS(Data!$B$2:$B$181,B25,Data!$U$2:$U$181,"Commercial",Data!$R$2:$R$181,">20")>0,"No","Yes") | Y25: =IF(COUNTIFS(Data!$B$2:$B$181,B25,Data!$L$2:$L$181,0)>=4,1,0) | Z25: =M25/(J25/60000) | AA25: =M25/(I25/60000)
A26: SIMULATED_Arousal_Nike_vs_elf | B26: P05 | C26: F | D26: 19 | E26: B | F26: Stimulus | G26: Baseline_Nike | H26: 296987 | I26: 60000 | J26: 60000 | K26: Baseline_Nike | L26: 1 | M26: 3 | N26: 3 | O26: 0.274 | P26: Shimmer3-B | Q26: 27.9 | R26: 0 | S26: 85.6 | T26: NA | U26: =IF(LEFT(G26,8)="Baseline","Baseline",IF(LEFT(G26,8)="Recovery","Recovery","Commercial")) | V26: =IF(ISNUMBER(SEARCH("Nike",G26)),"Nike","elf") | W26: =IF(OR(AND(E26="A",V26="Nike"),AND(E26="B",V26="elf")),"first","second") | X26: =IF(COUNTIFS(Data!$B$2:$B$181,B26,Data!$U$2:$U$181,"Commercial",Data!$Q$2:$Q$181,"<0")+COUNTIFS(Data!$B$2:$B$181,B26,Data!$U$2:$U$181,"Commercial",Data!$R$2:$R$181,">20")>0,"No","Yes") | Y26: =IF(COUNTIFS(Data!$B$2:$B$181,B26,Data!$L$2:$L$181,0)>=4,1,0) | Z26: =M26/(J26/60000) | AA26: =M26/(I26/60000)
A27: SIMULATED_Arousal_Nike_vs_elf | B27: P05 | C27: F | D27: 19 | E27: B | F27: Stimulus | G27: Nike_Commercial | H27: 356987 | I27: 60000 | J27: 60000 | K27: Nike_Commercial | L27: 1 | M27: 6 | N27: 6 | O27: 0.3949 | P27: Shimmer3-B | Q27: 28.3 | R27: 0 | S27: 84.3 | T27: 6 | U27: =IF(LEFT(G27,8)="Baseline","Baseline",IF(LEFT(G27,8)="Recovery","Recovery","Commercial")) | V27: =IF(ISNUMBER(SEARCH("Nike",G27)),"Nike","elf") | W27: =IF(OR(AND(E27="A",V27="Nike"),AND(E27="B",V27="elf")),"first","second") | X27: =IF(COUNTIFS(Data!$B$2:$B$181,B27,Data!$U$2:$U$181,"Commercial",Data!$Q$2:$Q$181,"<0")+COUNTIFS(Data!$B$2:$B$181,B27,Data!$U$2:$U$181,"Commercial",Data!$R$2:$R$181,">20")>0,"No","Yes") | Y27: =IF(COUNTIFS(Data!$B$2:$B$181,B27,Data!$L$2:$L$181,0)>=4,1,0) | Z27: =M27/(J27/60000) | AA27: =M27/(I27/60000)
A28: SIMULATED_Arousal_Nike_vs_elf | B28: P05 | C28: F | D28: 19 | E28: B | F28: Stimulus | G28: Recovery_Nike | H28: 416987 | I28: 15000 | J28: 15000 | K28: Recovery_Nike | L28: 1 | M28: 2 | N28: 8 | O28: 0.2062 | P28: Shimmer3-B | Q28: 26.4 | R28: 0 | S28: 87.7 | T28: NA | U28: =IF(LEFT(G28,8)="Baseline","Baseline",IF(LEFT(G28,8)="Recovery","Recovery","Commercial")) | V28: =IF(ISNUMBER(SEARCH("Nike",G28)),"Nike","elf") | W28: =IF(OR(AND(E28="A",V28="Nike"),AND(E28="B",V28="elf")),"first","second") | X28: =IF(COUNTIFS(Data!$B$2:$B$181,B28,Data!$U$2:$U$181,"Commercial",Data!$Q$2:$Q$181,"<0")+COUNTIFS(Data!$B$2:$B$181,B28,Data!$U$2:$U$181,"Commercial",Data!$R$2:$R$181,">20")>0,"No","Yes") | Y28: =IF(COUNTIFS(Data!$B$2:$B$181,B28,Data!$L$2:$L$181,0)>=4,1,0) | Z28: =M28/(J28/60000) | AA28: =M28/(I28/60000)
A29: SIMULATED_Arousal_Nike_vs_elf | B29: P05 | C29: F | D29: 19 | E29: B | F29: Stimulus | G29: Baseline_elf | H29: 35702 | I29: 60000 | J29: 60000 | K29: Baseline_elf | L29: 1 | M29: 1 | N29: 1 | O29: 0.3101 | P29: Shimmer3-B | Q29: 29.3 | R29: 1.1 | S29: 86.8 | T29: NA | U29: =IF(LEFT(G29,8)="Baseline","Baseline",IF(LEFT(G29,8)="Recovery","Recovery","Commercial")) | V29: =IF(ISNUMBER(SEARCH("Nike",G29)),"Nike","elf") | W29: =IF(OR(AND(E29="A",V29="Nike"),AND(E29="B",V29="elf")),"first","second") | X29: =IF(COUNTIFS(Data!$B$2:$B$181,B29,Data!$U$2:$U$181,"Commercial",Data!$Q$2:$Q$181,"<0")+COUNTIFS(Data!$B$2:$B$181,B29,Data!$U$2:$U$181,"Commercial",Data!$R$2:$R$181,">20")>0,"No","Yes") | Y29: =IF(COUNTIFS(Data!$B$2:$B$181,B29,Data!$L$2:$L$181,0)>=4,1,0) | Z29: =M29/(J29/60000) | AA29: =M29/(I29/60000)
A30: SIMULATED_Arousal_Nike_vs_elf | B30: P05 | C30: F | D30: 19 | E30: B | F30: Stimulus | G30: elf_Commercial | H30: 95702 | I30: 30000 | J30: 30000 | K30: elf_Commercial | L30: 1 | M30: 3 | N30: 6 | O30: 0.4185 | P30: Shimmer3-B | Q30: 28.1 | R30: 0 | S30: 82.8 | T30: 5 | U30: =IF(LEFT(G30,8)="Baseline","Baseline",IF(LEFT(G30,8)="Recovery","Recovery","Commercial")) | V30: =IF(ISNUMBER(SEARCH("Nike",G30)),"Nike","elf") | W30: =IF(OR(AND(E30="A",V30="Nike"),AND(E30="B",V30="elf")),"first","second") | X30: =IF(COUNTIFS(Data!$B$2:$B$181,B30,Data!$U$2:$U$181,"Commercial",Data!$Q$2:$Q$181,"<0")+COUNTIFS(Data!$B$2:$B$181,B30,Data!$U$2:$U$181,"Commercial",Data!$R$2:$R$181,">20")>0,"No","Yes") | Y30: =IF(COUNTIFS(Data!$B$2:$B$181,B30,Data!$L$2:$L$181,0)>=4,1,0) | Z30: =M30/(J30/60000) | AA30: =M30/(I30/60000)
A31: SIMULATED_Arousal_Nike_vs_elf | B31: P05 | C31: F | D31: 19 | E31: B | F31: Stimulus | G31: Recovery_elf | H31: 125702 | I31: 15000 | J31: 15000 | K31: Recovery_elf | L31: 0 | M31: 0 | N31: 0 | O31: NA | P31: Shimmer3-B | Q31: 28.3 | R31: 1.3 | S31: 88.4 | T31: NA | U31: =IF(LEFT(G31,8)="Baseline","Baseline",IF(LEFT(G31,8)="Recovery","Recovery","Commercial")) | V31: =IF(ISNUMBER(SEARCH("Nike",G31)),"Nike","elf") | W31: =IF(OR(AND(E31="A",V31="Nike"),AND(E31="B",V31="elf")),"first","second") | X31: =IF(COUNTIFS(Data!$B$2:$B$181,B31,Data!$U$2:$U$181,"Commercial",Data!$Q$2:$Q$181,"<0")+COUNTIFS(Data!$B$2:$B$181,B31,Data!$U$2:$U$181,"Commercial",Data!$R$2:$R$181,">20")>0,"No","Yes") | Y31: =IF(COUNTIFS(Data!$B$2:$B$181,B31,Data!$L$2:$L$181,0)>=4,1,0) | Z31: =M31/(J31/60000) | AA31: =M31/(I31/60000)
A32: SIMULATED_Arousal_Nike_vs_elf | B32: P06 | C32: M | D32: 45 | E32: A | F32: Stimulus | G32: Baseline_Nike | H32: 38406 | I32: 60000 | J32: 60000 | K32: Baseline_Nike | L32: 1 | M32: 1 | N32: 1 | O32: 0.1736 | P32: Shimmer3-8956 | Q32: 19.7 | R32: 0.8 | S32: 69.6 | T32: NA | U32: =IF(LEFT(G32,8)="Baseline","Baseline",IF(LEFT(G32,8)="Recovery","Recovery","Commercial")) | V32: =IF(ISNUMBER(SEARCH("Nike",G32)),"Nike","elf") | W32: =IF(OR(AND(E32="A",V32="Nike"),AND(E32="B",V32="elf")),"first","second") | X32: =IF(COUNTIFS(Data!$B$2:$B$181,B32,Data!$U$2:$U$181,"Commercial",Data!$Q$2:$Q$181,"<0")+COUNTIFS(Data!$B$2:$B$181,B32,Data!$U$2:$U$181,"Commercial",Data!$R$2:$R$181,">20")>0,"No","Yes") | Y32: =IF(COUNTIFS(Data!$B$2:$B$181,B32,Data!$L$2:$L$181,0)>=4,1,0) | Z32: =M32/(J32/60000) | AA32: =M32/(I32/60000)
A33: SIMULATED_Arousal_Nike_vs_elf | B33: P06 | C33: M | D33: 45 | E33: A | F33: Stimulus | G33: Nike_Commercial | H33: 98406 | I33: 60000 | J33: 60000 | K33: Nike_Commercial | L33: 1 | M33: 1 | N33: 1 | O33: 0.2445 | P33: Shimmer3-8956 | Q33: 23.2 | R33: 3.2 | S33: 69.9 | T33: 3 | U33: =IF(LEFT(G33,8)="Baseline","Baseline",IF(LEFT(G33,8)="Recovery","Recovery","Commercial")) | V33: =IF(ISNUMBER(SEARCH("Nike",G33)),"Nike","elf") | W33: =IF(OR(AND(E33="A",V33="Nike"),AND(E33="B",V33="elf")),"first","second") | X33: =IF(COUNTIFS(Data!$B$2:$B$181,B33,Data!$U$2:$U$181,"Commercial",Data!$Q$2:$Q$181,"<0")+COUNTIFS(Data!$B$2:$B$181,B33,Data!$U$2:$U$181,"Commercial",Data!$R$2:$R$181,">20")>0,"No","Yes") | Y33: =IF(COUNTIFS(Data!$B$2:$B$181,B33,Data!$L$2:$L$181,0)>=4,1,0) | Z33: =M33/(J33/60000) | AA33: =M33/(I33/60000)
A34: SIMULATED_Arousal_Nike_vs_elf | B34: P06 | C34: M | D34: 45 | E34: A | F34: Stimulus | G34: Recovery_Nike | H34: 158406 | I34: 15000 | J34: 15000 | K34: Recovery_Nike | L34: 1 | M34: 2 | N34: 8 | O34: 0.2235 | P34: Shimmer3-8956 | Q34: 23.6 | R34: 0 | S34: 71 | T34: NA | U34: =IF(LEFT(G34,8)="Baseline","Baseline",IF(LEFT(G34,8)="Recovery","Recovery","Commercial")) | V34: =IF(ISNUMBER(SEARCH("Nike",G34)),"Nike","elf") | W34: =IF(OR(AND(E34="A",V34="Nike"),AND(E34="B",V34="elf")),"first","second") | X34: =IF(COUNTIFS(Data!$B$2:$B$181,B34,Data!$U$2:$U$181,"Commercial",Data!$Q$2:$Q$181,"<0")+COUNTIFS(Data!$B$2:$B$181,B34,Data!$U$2:$U$181,"Commercial",Data!$R$2:$R$181,">20")>0,"No","Yes") | Y34: =IF(COUNTIFS(Data!$B$2:$B$181,B34,Data!$L$2:$L$181,0)>=4,1,0) | Z34: =M34/(J34/60000) | AA34: =M34/(I34/60000)
A35: SIMULATED_Arousal_Nike_vs_elf | B35: P06 | C35: M | D35: 45 | E35: A | F35: Stimulus | G35: Baseline_elf | H35: 351264 | I35: 60000 | J35: 60000 | K35: Baseline_elf | L35: 1 | M35: 3 | N35: 3 | O35: 0.1489 | P35: Shimmer3-8956 | Q35: 20.9 | R35: 0.9 | S35: 70.2 | T35: NA | U35: =IF(LEFT(G35,8)="Baseline","Baseline",IF(LEFT(G35,8)="Recovery","Recovery","Commercial")) | V35: =IF(ISNUMBER(SEARCH("Nike",G35)),"Nike","elf") | W35: =IF(OR(AND(E35="A",V35="Nike"),AND(E35="B",V35="elf")),"first","second") | X35: =IF(COUNTIFS(Data!$B$2:$B$181,B35,Data!$U$2:$U$181,"Commercial",Data!$Q$2:$Q$181,"<0")+COUNTIFS(Data!$B$2:$B$181,B35,Data!$U$2:$U$181,"Commercial",Data!$R$2:$R$181,">20")>0,"No","Yes") | Y35: =IF(COUNTIFS(Data!$B$2:$B$181,B35,Data!$L$2:$L$181,0)>=4,1,0) | Z35: =M35/(J35/60000) | AA35: =M35/(I35/60000)
A36: SIMULATED_Arousal_Nike_vs_elf | B36: P06 | C36: M | D36: 45 | E36: A | F36: Stimulus | G36: elf_Commercial | H36: 411264 | I36: 30000 | J36: 30000 | K36: elf_Commercial | L36: 1 | M36: 1 | N36: 2 | O36: 0.4101 | P36: Shimmer3-8956 | Q36: 18.5 | R36: 0 | S36: 73 | T36: 2 | U36: =IF(LEFT(G36,8)="Baseline","Baseline",IF(LEFT(G36,8)="Recovery","Recovery","Commercial")) | V36: =IF(ISNUMBER(SEARCH("Nike",G36)),"Nike","elf") | W36: =IF(OR(AND(E36="A",V36="Nike"),AND(E36="B",V36="elf")),"first","second") | X36: =IF(COUNTIFS(Data!$B$2:$B$181,B36,Data!$U$2:$U$181,"Commercial",Data!$Q$2:$Q$181,"<0")+COUNTIFS(Data!$B$2:$B$181,B36,Data!$U$2:$U$181,"Commercial",Data!$R$2:$R$181,">20")>0,"No","Yes") | Y36: =IF(COUNTIFS(Data!$B$2:$B$181,B36,Data!$L$2:$L$181,0)>=4,1,0) | Z36: =M36/(J36/60000) | AA36: =M36/(I36/60000)
A37: SIMULATED_Arousal_Nike_vs_elf | B37: P06 | C37: M | D37: 45 | E37: A | F37: Stimulus | G37: Recovery_elf | H37: 441264 | I37: 15000 | J37: 15000 | K37: Recovery_elf | L37: 1 | M37: 1 | N37: 4 | O37: 0.2115 | P37: Shimmer3-8956 | Q37: 21.9 | R37: 0 | S37: 72.4 | T37: NA | U37: =IF(LEFT(G37,8)="Baseline","Baseline",IF(LEFT(G37,8)="Recovery","Recovery","Commercial")) | V37: =IF(ISNUMBER(SEARCH("Nike",G37)),"Nike","elf") | W37: =IF(OR(AND(E37="A",V37="Nike"),AND(E37="B",V37="elf")),"first","second") | X37: =IF(COUNTIFS(Data!$B$2:$B$181,B37,Data!$U$2:$U$181,"Commercial",Data!$Q$2:$Q$181,"<0")+COUNTIFS(Data!$B$2:$B$181,B37,Data!$U$2:$U$181,"Commercial",Data!$R$2:$R$181,">20")>0,"No","Yes") | Y37: =IF(COUNTIFS(Data!$B$2:$B$181,B37,Data!$L$2:$L$181,0)>=4,1,0) | Z37: =M37/(J37/60000) | AA37: =M37/(I37/60000)
A38: SIMULATED_Arousal_Nike_vs_elf | B38: P07 | C38: M | D38: 23 | E38: A | F38: Stimulus | G38: Baseline_Nike | H38: 24276 | I38: 60000 | J38: 60000 | K38: Baseline_Nike | L38: 1 | M38: 3 | N38: 3 | O38: 0.1573 | P38: Shimmer3-8956 | Q38: 22.9 | R38: 0 | S38: 68.6 | T38: NA | U38: =IF(LEFT(G38,8)="Baseline","Baseline",IF(LEFT(G38,8)="Recovery","Recovery","Commercial")) | V38: =IF(ISNUMBER(SEARCH("Nike",G38)),"Nike","elf") | W38: =IF(OR(AND(E38="A",V38="Nike"),AND(E38="B",V38="elf")),"first","second") | X38: =IF(COUNTIFS(Data!$B$2:$B$181,B38,Data!$U$2:$U$181,"Commercial",Data!$Q$2:$Q$181,"<0")+COUNTIFS(Data!$B$2:$B$181,B38,Data!$U$2:$U$181,"Commercial",Data!$R$2:$R$181,">20")>0,"No","Yes") | Y38: =IF(COUNTIFS(Data!$B$2:$B$181,B38,Data!$L$2:$L$181,0)>=4,1,0) | Z38: =M38/(J38/60000) | AA38: =M38/(I38/60000)
A39: SIMULATED_Arousal_Nike_vs_elf | B39: P07 | C39: M | D39: 23 | E39: A | F39: Stimulus | G39: Nike_Commercial | H39: 84276 | I39: 60000 | J39: 60000 | K39: Nike_Commercial | L39: 1 | M39: 6 | N39: 6 | O39: 0.1439 | P39: Shimmer3-8956 | Q39: 23.2 | R39: 1.4 | S39: 67.6 | T39: 4 | U39: =IF(LEFT(G39,8)="Baseline","Baseline",IF(LEFT(G39,8)="Recovery","Recovery","Commercial")) | V39: =IF(ISNUMBER(SEARCH("Nike",G39)),"Nike","elf") | W39: =IF(OR(AND(E39="A",V39="Nike"),AND(E39="B",V39="elf")),"first","second") | X39: =IF(COUNTIFS(Data!$B$2:$B$181,B39,Data!$U$2:$U$181,"Commercial",Data!$Q$2:$Q$181,"<0")+COUNTIFS(Data!$B$2:$B$181,B39,Data!$U$2:$U$181,"Commercial",Data!$R$2:$R$181,">20")>0,"No","Yes") | Y39: =IF(COUNTIFS(Data!$B$2:$B$181,B39,Data!$L$2:$L$181,0)>=4,1,0) | Z39: =M39/(J39/60000) | AA39: =M39/(I39/60000)
A40: SIMULATED_Arousal_Nike_vs_elf | B40: P07 | C40: M | D40: 23 | E40: A | F40: Stimulus | G40: Recovery_Nike | H40: 144276 | I40: 15000 | J40: 15000 | K40: Recovery_Nike | L40: 1 | M40: 1 | N40: 4 | O40: 0.1043 | P40: Shimmer3-8956 | Q40: 20.7 | R40: 1.1 | S40: 68.4 | T40: NA | U40: =IF(LEFT(G40,8)="Baseline","Baseline",IF(LEFT(G40,8)="Recovery","Recovery","Commercial")) | V40: =IF(ISNUMBER(SEARCH("Nike",G40)),"Nike","elf") | W40: =IF(OR(AND(E40="A",V40="Nike"),AND(E40="B",V40="elf")),"first","second") | X40: =IF(COUNTIFS(Data!$B$2:$B$181,B40,Data!$U$2:$U$181,"Commercial",Data!$Q$2:$Q$181,"<0")+COUNTIFS(Data!$B$2:$B$181,B40,Data!$U$2:$U$181,"Commercial",Data!$R$2:$R$181,">20")>0,"No","Yes") | Y40: =IF(COUNTIFS(Data!$B$2:$B$181,B40,Data!$L$2:$L$181,0)>=4,1,0) | Z40: =M40/(J40/60000) | AA40: =M40/(I40/60000)
...

Sheet Summary
A1: Descriptive table by stimulus (kept respondents only). SIMULATED data.
A2: n = kept respondents. Peaks Per Minute statistics use every kept respondent (nonresponders included). Average Peak Amplitude averages the respondent values that exist (the text NA, a stimulus without a peak, is ignored).
A4: Stimulus | B4: n | C4: PPM mean | D4: PPM SD | E4: Has Peaks (%) | F4: Peak Count mean | G4: Peak amplitude mean (microSiemens) | H4: n with amplitude | I4: Heart rate mean (BPM) | J4: Heart rate SD (BPM) | K4: SNR mean (dB) | L4: Signal missing mean (%)
A5: Baseline_Nike | B5: =COUNTIFS(Data!$G$2:$G$181,$A5,Data!$X$2:$X$181,"Yes") | C5: =AVERAGEIFS(Data!$N$2:$N$181,Data!$G$2:$G$181,$A5,Data!$X$2:$X$181,"Yes") | D5: {=_xlfn.STDEV.S(IF((Data!$G$2:$G$181=$A5)*(Data!$X$2:$X$181="Yes"),Data!$N$2:$N$181))} | E5: =100*AVERAGEIFS(Data!$L$2:$L$181,Data!$G$2:$G$181,$A5,Data!$X$2:$X$181,"Yes") | F5: =AVERAGEIFS(Data!$M$2:$M$181,Data!$G$2:$G$181,$A5,Data!$X$2:$X$181,"Yes") | G5: =AVERAGEIFS(Data!$O$2:$O$181,Data!$G$2:$G$181,$A5,Data!$X$2:$X$181,"Yes") | H5: =COUNTIFS(Data!$G$2:$G$181,$A5,Data!$X$2:$X$181,"Yes",Data!$O$2:$O$181,">0") | I5: =AVERAGEIFS(Data!$S$2:$S$181,Data!$G$2:$G$181,$A5,Data!$X$2:$X$181,"Yes") | J5: {=_xlfn.STDEV.S(IF((Data!$G$2:$G$181=$A5)*(Data!$X$2:$X$181="Yes"),Data!$S$2:$S$181))} | K5: =AVERAGEIFS(Data!$Q$2:$Q$181,Data!$G$2:$G$181,$A5,Data!$X$2:$X$181,"Yes") | L5: =AVERAGEIFS(Data!$R$2:$R$181,Data!$G$2:$G$181,$A5,Data!$X$2:$X$181,"Yes")
A6: Nike_Commercial | B6: =COUNTIFS(Data!$G$2:$G$181,$A6,Data!$X$2:$X$181,"Yes") | C6: =AVERAGEIFS(Data!$N$2:$N$181,Data!$G$2:$G$181,$A6,Data!$X$2:$X$181,"Yes") | D6: {=_xlfn.STDEV.S(IF((Data!$G$2:$G$181=$A6)*(Data!$X$2:$X$181="Yes"),Data!$N$2:$N$181))} | E6: =100*AVERAGEIFS(Data!$L$2:$L$181,Data!$G$2:$G$181,$A6,Data!$X$2:$X$181,"Yes") | F6: =AVERAGEIFS(Data!$M$2:$M$181,Data!$G$2:$G$181,$A6,Data!$X$2:$X$181,"Yes") | G6: =AVERAGEIFS(Data!$O$2:$O$181,Data!$G$2:$G$181,$A6,Data!$X$2:$X$181,"Yes") | H6: =COUNTIFS(Data!$G$2:$G$181,$A6,Data!$X$2:$X$181,"Yes",Data!$O$2:$O$181,">0") | I6: =AVERAGEIFS(Data!$S$2:$S$181,Data!$G$2:$G$181,$A6,Data!$X$2:$X$181,"Yes") | J6: {=_xlfn.STDEV.S(IF((Data!$G$2:$G$181=$A6)*(Data!$X$2:$X$181="Yes"),Data!$S$2:$S$181))} | K6: =AVERAGEIFS(Data!$Q$2:$Q$181,Data!$G$2:$G$181,$A6,Data!$X$2:$X$181,"Yes") | L6: =AVERAGEIFS(Data!$R$2:$R$181,Data!$G$2:$G$181,$A6,Data!$X$2:$X$181,"Yes")
A7: Recovery_Nike | B7: =COUNTIFS(Data!$G$2:$G$181,$A7,Data!$X$2:$X$181,"Yes") | C7: =AVERAGEIFS(Data!$N$2:$N$181,Data!$G$2:$G$181,$A7,Data!$X$2:$X$181,"Yes") | D7: {=_xlfn.STDEV.S(IF((Data!$G$2:$G$181=$A7)*(Data!$X$2:$X$181="Yes"),Data!$N$2:$N$181))} | E7: =100*AVERAGEIFS(Data!$L$2:$L$181,Data!$G$2:$G$181,$A7,Data!$X$2:$X$181,"Yes") | F7: =AVERAGEIFS(Data!$M$2:$M$181,Data!$G$2:$G$181,$A7,Data!$X$2:$X$181,"Yes") | G7: =AVERAGEIFS(Data!$O$2:$O$181,Data!$G$2:$G$181,$A7,Data!$X$2:$X$181,"Yes") | H7: =COUNTIFS(Data!$G$2:$G$181,$A7,Data!$X$2:$X$181,"Yes",Data!$O$2:$O$181,">0") | I7: =AVERAGEIFS(Data!$S$2:$S$181,Data!$G$2:$G$181,$A7,Data!$X$2:$X$181,"Yes") | J7: {=_xlfn.STDEV.S(IF((Data!$G$2:$G$181=$A7)*(Data!$X$2:$X$181="Yes"),Data!$S$2:$S$181))} | K7: =AVERAGEIFS(Data!$Q$2:$Q$181,Data!$G$2:$G$181,$A7,Data!$X$2:$X$181,"Yes") | L7: =AVERAGEIFS(Data!$R$2:$R$181,Data!$G$2:$G$181,$A7,Data!$X$2:$X$181,"Yes")
A8: Baseline_elf | B8: =COUNTIFS(Data!$G$2:$G$181,$A8,Data!$X$2:$X$181,"Yes") | C8: =AVERAGEIFS(Data!$N$2:$N$181,Data!$G$2:$G$181,$A8,Data!$X$2:$X$181,"Yes") | D8: {=_xlfn.STDEV.S(IF((Data!$G$2:$G$181=$A8)*(Data!$X$2:$X$181="Yes"),Data!$N$2:$N$181))} | E8: =100*AVERAGEIFS(Data!$L$2:$L$181,Data!$G$2:$G$181,$A8,Data!$X$2:$X$181,"Yes") | F8: =AVERAGEIFS(Data!$M$2:$M$181,Data!$G$2:$G$181,$A8,Data!$X$2:$X$181,"Yes") | G8: =AVERAGEIFS(Data!$O$2:$O$181,Data!$G$2:$G$181,$A8,Data!$X$2:$X$181,"Yes") | H8: =COUNTIFS(Data!$G$2:$G$181,$A8,Data!$X$2:$X$181,"Yes",Data!$O$2:$O$181,">0") | I8: =AVERAGEIFS(Data!$S$2:$S$181,Data!$G$2:$G$181,$A8,Data!$X$2:$X$181,"Yes") | J8: {=_xlfn.STDEV.S(IF((Data!$G$2:$G$181=$A8)*(Data!$X$2:$X$181="Yes"),Data!$S$2:$S$181))} | K8: =AVERAGEIFS(Data!$Q$2:$Q$181,Data!$G$2:$G$181,$A8,Data!$X$2:$X$181,"Yes") | L8: =AVERAGEIFS(Data!$R$2:$R$181,Data!$G$2:$G$181,$A8,Data!$X$2:$X$181,"Yes")
A9: elf_Commercial | B9: =COUNTIFS(Data!$G$2:$G$181,$A9,Data!$X$2:$X$181,"Yes") | C9: =AVERAGEIFS(Data!$N$2:$N$181,Data!$G$2:$G$181,$A9,Data!$X$2:$X$181,"Yes") | D9: {=_xlfn.STDEV.S(IF((Data!$G$2:$G$181=$A9)*(Data!$X$2:$X$181="Yes"),Data!$N$2:$N$181))} | E9: =100*AVERAGEIFS(Data!$L$2:$L$181,Data!$G$2:$G$181,$A9,Data!$X$2:$X$181,"Yes") | F9: =AVERAGEIFS(Data!$M$2:$M$181,Data!$G$2:$G$181,$A9,Data!$X$2:$X$181,"Yes") | G9: =AVERAGEIFS(Data!$O$2:$O$181,Data!$G$2:$G$181,$A9,Data!$X$2:$X$181,"Yes") | H9: =COUNTIFS(Data!$G$2:$G$181,$A9,Data!$X$2:$X$181,"Yes",Data!$O$2:$O$181,">0") | I9: =AVERAGEIFS(Data!$S$2:$S$181,Data!$G$2:$G$181,$A9,Data!$X$2:$X$181,"Yes") | J9: {=_xlfn.STDEV.S(IF((Data!$G$2:$G$181=$A9)*(Data!$X$2:$X$181="Yes"),Data!$S$2:$S$181))} | K9: =AVERAGEIFS(Data!$Q$2:$Q$181,Data!$G$2:$G$181,$A9,Data!$X$2:$X$181,"Yes") | L9: =AVERAGEIFS(Data!$R$2:$R$181,Data!$G$2:$G$181,$A9,Data!$X$2:$X$181,"Yes")
A10: Recovery_elf | B10: =COUNTIFS(Data!$G$2:$G$181,$A10,Data!$X$2:$X$181,"Yes") | C10: =AVERAGEIFS(Data!$N$2:$N$181,Data!$G$2:$G$181,$A10,Data!$X$2:$X$181,"Yes") | D10: {=_xlfn.STDEV.S(IF((Data!$G$2:$G$181=$A10)*(Data!$X$2:$X$181="Yes"),Data!$N$2:$N$181))} | E10: =100*AVERAGEIFS(Data!$L$2:$L$181,Data!$G$2:$G$181,$A10,Data!$X$2:$X$181,"Yes") | F10: =AVERAGEIFS(Data!$M$2:$M$181,Data!$G$2:$G$181,$A10,Data!$X$2:$X$181,"Yes") | G10: =AVERAGEIFS(Data!$O$2:$O$181,Data!$G$2:$G$181,$A10,Data!$X$2:$X$181,"Yes") | H10: =COUNTIFS(Data!$G$2:$G$181,$A10,Data!$X$2:$X$181,"Yes",Data!$O$2:$O$181,">0") | I10: =AVERAGEIFS(Data!$S$2:$S$181,Data!$G$2:$G$181,$A10,Data!$X$2:$X$181,"Yes") | J10: {=_xlfn.STDEV.S(IF((Data!$G$2:$G$181=$A10)*(Data!$X$2:$X$181="Yes"),Data!$S$2:$S$181))} | K10: =AVERAGEIFS(Data!$Q$2:$Q$181,Data!$G$2:$G$181,$A10,Data!$X$2:$X$181,"Yes") | L10: =AVERAGEIFS(Data!$R$2:$R$181,Data!$G$2:$G$181,$A10,Data!$X$2:$X$181,"Yes")
A12: Array formulas (columns D and J): Excel 365 evaluates them with Enter; Excel 2019 or older needs Ctrl+Shift+Enter after editing.
A13: Why Peaks Per Minute uses Signal Duration (kept respondents)
A14: Rows with Signal Duration shorter than Duration | B14: =SUMPRODUCT(--(Data!$J$2:$J$181<Data!$I$2:$I$181),--(Data!$X$2:$X$181="Yes"))
A15: Largest understatement if Duration were used (peaks per minute) | B15: =SUMPRODUCT(MAX((Data!$X$2:$X$181="Yes")*(Data!$Z$2:$Z$181-Data!$AA$2:$AA$181)))
A16: Largest gap between the exported Peaks Per Minute and PPM_recalc (all rows) | B16: =SUMPRODUCT(MAX(ABS(Data!$N$2:$N$181-Data!$Z$2:$Z$181)))
A17: Device check (kept respondents; the analysis pools the two devices)
A18: Device | B18: Rows | C18: SNR mean (dB) | D18: PPM mean (baselines and commercials)
A19: Shimmer3-8956 | B19: =COUNTIFS(Data!$P$2:$P$181,$A19,Data!$X$2:$X$181,"Yes") | C19: =AVERAGEIFS(Data!$Q$2:$Q$181,Data!$P$2:$P$181,$A19,Data!$X$2:$X$181,"Yes") | D19: =AVERAGEIFS(Data!$N$2:$N$181,Data!$P$2:$P$181,$A19,Data!$X$2:$X$181,"Yes",Data!$U$2:$U$181,"<>Recovery")
A20: Shimmer3-B | B20: =COUNTIFS(Data!$P$2:$P$181,$A20,Data!$X$2:$X$181,"Yes") | C20: =AVERAGEIFS(Data!$Q$2:$Q$181,Data!$P$2:$P$181,$A20,Data!$X$2:$X$181,"Yes") | D20: =AVERAGEIFS(Data!$N$2:$N$181,Data!$P$2:$P$181,$A20,Data!$X$2:$X$181,"Yes",Data!$U$2:$U$181,"<>Recovery")
A23: Chart table: mean Peaks Per Minute by stimulus
A24: Stimulus | B24: Mean PPM
A25: Baseline_Nike | B25: =C5
A26: Nike_Commercial | B26: =C6
A27: Recovery_Nike | B27: =C7
A28: Baseline_elf | B28: =C8
A29: elf_Commercial | B29: =C9
A30: Recovery_elf | B30: =C10

Sheet H1
A1: H1. Peaks Per Minute in each commercial versus its own baseline, kept respondents. SIMULATED data.
A2: One row per kept respondent; responders in rows 5 to 29, the 3 nonresponders in rows 30 to 32. Columns D, E, G, H pull Peaks Per Minute from the Data sheet with SUMIFS (each respondent has exactly one row per stimulus); J and K pull the self reported arousal. Differences are commercial MINUS baseline.
A4: Respondent Name | B4: Group (order) | C4: Nonresponder | D4: Baseline_Nike PPM | E4: Nike_Commercial PPM | F4: Difference Nike (commercial minus baseline) | G4: Baseline_elf PPM | H4: elf_Commercial PPM | I4: Difference e.l.f. (commercial minus baseline) | J4: Arousal_Nike_1to9 | K4: Arousal_elf_1to9 | L4: Mean arousal (both commercials) | M4: Mean commercial PPM (both) | O4: Statistic | P4: Value | Q4: Formula shown | R4: Note
A5: P01 | B5: =INDEX(Data!$E$2:$E$181,MATCH($A5,Data!$B$2:$B$181,0)) | C5: =INDEX(Data!$Y$2:$Y$181,MATCH($A5,Data!$B$2:$B$181,0)) | D5: =SUMIFS(Data!$N$2:$N$181,Data!$B$2:$B$181,$A5,Data!$G$2:$G$181,"Baseline_Nike") | E5: =SUMIFS(Data!$N$2:$N$181,Data!$B$2:$B$181,$A5,Data!$G$2:$G$181,"Nike_Commercial") | F5: =E5-D5 | G5: =SUMIFS(Data!$N$2:$N$181,Data!$B$2:$B$181,$A5,Data!$G$2:$G$181,"Baseline_elf") | H5: =SUMIFS(Data!$N$2:$N$181,Data!$B$2:$B$181,$A5,Data!$G$2:$G$181,"elf_Commercial") | I5: =H5-G5 | J5: =SUMIFS(Data!$T$2:$T$181,Data!$B$2:$B$181,$A5,Data!$G$2:$G$181,"Nike_Commercial") | K5: =SUMIFS(Data!$T$2:$T$181,Data!$B$2:$B$181,$A5,Data!$G$2:$G$181,"elf_Commercial") | L5: =(J5+K5)/2 | M5: =(E5+H5)/2 | O5: Nike: paired t test and d_z, all kept respondents (Peaks Per Minute)
A6: P02 | B6: =INDEX(Data!$E$2:$E$181,MATCH($A6,Data!$B$2:$B$181,0)) | C6: =INDEX(Data!$Y$2:$Y$181,MATCH($A6,Data!$B$2:$B$181,0)) | D6: =SUMIFS(Data!$N$2:$N$181,Data!$B$2:$B$181,$A6,Data!$G$2:$G$181,"Baseline_Nike") | E6: =SUMIFS(Data!$N$2:$N$181,Data!$B$2:$B$181,$A6,Data!$G$2:$G$181,"Nike_Commercial") | F6: =E6-D6 | G6: =SUMIFS(Data!$N$2:$N$181,Data!$B$2:$B$181,$A6,Data!$G$2:$G$181,"Baseline_elf") | H6: =SUMIFS(Data!$N$2:$N$181,Data!$B$2:$B$181,$A6,Data!$G$2:$G$181,"elf_Commercial") | I6: =H6-G6 | J6: =SUMIFS(Data!$T$2:$T$181,Data!$B$2:$B$181,$A6,Data!$G$2:$G$181,"Nike_Commercial") | K6: =SUMIFS(Data!$T$2:$T$181,Data!$B$2:$B$181,$A6,Data!$G$2:$G$181,"elf_Commercial") | L6: =(J6+K6)/2 | M6: =(E6+H6)/2 | O6: Baseline_Nike mean (peaks per minute) | P6: =AVERAGE(D5:D32) | Q6: =AVERAGE(D5:D32) | R6: AVERAGE of the reference column
A7: P04 | B7: =INDEX(Data!$E$2:$E$181,MATCH($A7,Data!$B$2:$B$181,0)) | C7: =INDEX(Data!$Y$2:$Y$181,MATCH($A7,Data!$B$2:$B$181,0)) | D7: =SUMIFS(Data!$N$2:$N$181,Data!$B$2:$B$181,$A7,Data!$G$2:$G$181,"Baseline_Nike") | E7: =SUMIFS(Data!$N$2:$N$181,Data!$B$2:$B$181,$A7,Data!$G$2:$G$181,"Nike_Commercial") | F7: =E7-D7 | G7: =SUMIFS(Data!$N$2:$N$181,Data!$B$2:$B$181,$A7,Data!$G$2:$G$181,"Baseline_elf") | H7: =SUMIFS(Data!$N$2:$N$181,Data!$B$2:$B$181,$A7,Data!$G$2:$G$181,"elf_Commercial") | I7: =H7-G7 | J7: =SUMIFS(Data!$T$2:$T$181,Data!$B$2:$B$181,$A7,Data!$G$2:$G$181,"Nike_Commercial") | K7: =SUMIFS(Data!$T$2:$T$181,Data!$B$2:$B$181,$A7,Data!$G$2:$G$181,"elf_Commercial") | L7: =(J7+K7)/2 | M7: =(E7+H7)/2 | O7: Baseline_Nike SD (peaks per minute) | P7: =_xlfn.STDEV.S(D5:D32) | Q7: =STDEV.S(D5:D32) | R7: STDEV.S = sample standard deviation
A8: P05 | B8: =INDEX(Data!$E$2:$E$181,MATCH($A8,Data!$B$2:$B$181,0)) | C8: =INDEX(Data!$Y$2:$Y$181,MATCH($A8,Data!$B$2:$B$181,0)) | D8: =SUMIFS(Data!$N$2:$N$181,Data!$B$2:$B$181,$A8,Data!$G$2:$G$181,"Baseline_Nike") | E8: =SUMIFS(Data!$N$2:$N$181,Data!$B$2:$B$181,$A8,Data!$G$2:$G$181,"Nike_Commercial") | F8: =E8-D8 | G8: =SUMIFS(Data!$N$2:$N$181,Data!$B$2:$B$181,$A8,Data!$G$2:$G$181,"Baseline_elf") | H8: =SUMIFS(Data!$N$2:$N$181,Data!$B$2:$B$181,$A8,Data!$G$2:$G$181,"elf_Commercial") | I8: =H8-G8 | J8: =SUMIFS(Data!$T$2:$T$181,Data!$B$2:$B$181,$A8,Data!$G$2:$G$181,"Nike_Commercial") | K8: =SUMIFS(Data!$T$2:$T$181,Data!$B$2:$B$181,$A8,Data!$G$2:$G$181,"elf_Commercial") | L8: =(J8+K8)/2 | M8: =(E8+H8)/2 | O8: Nike_Commercial mean (peaks per minute) | P8: =AVERAGE(E5:E32) | Q8: =AVERAGE(E5:E32)
A9: P06 | B9: =INDEX(Data!$E$2:$E$181,MATCH($A9,Data!$B$2:$B$181,0)) | C9: =INDEX(Data!$Y$2:$Y$181,MATCH($A9,Data!$B$2:$B$181,0)) | D9: =SUMIFS(Data!$N$2:$N$181,Data!$B$2:$B$181,$A9,Data!$G$2:$G$181,"Baseline_Nike") | E9: =SUMIFS(Data!$N$2:$N$181,Data!$B$2:$B$181,$A9,Data!$G$2:$G$181,"Nike_Commercial") | F9: =E9-D9 | G9: =SUMIFS(Data!$N$2:$N$181,Data!$B$2:$B$181,$A9,Data!$G$2:$G$181,"Baseline_elf") | H9: =SUMIFS(Data!$N$2:$N$181,Data!$B$2:$B$181,$A9,Data!$G$2:$G$181,"elf_Commercial") | I9: =H9-G9 | J9: =SUMIFS(Data!$T$2:$T$181,Data!$B$2:$B$181,$A9,Data!$G$2:$G$181,"Nike_Commercial") | K9: =SUMIFS(Data!$T$2:$T$181,Data!$B$2:$B$181,$A9,Data!$G$2:$G$181,"elf_Commercial") | L9: =(J9+K9)/2 | M9: =(E9+H9)/2 | O9: Nike_Commercial SD (peaks per minute) | P9: =_xlfn.STDEV.S(E5:E32) | Q9: =STDEV.S(E5:E32)
A10: P07 | B10: =INDEX(Data!$E$2:$E$181,MATCH($A10,Data!$B$2:$B$181,0)) | C10: =INDEX(Data!$Y$2:$Y$181,MATCH($A10,Data!$B$2:$B$181,0)) | D10: =SUMIFS(Data!$N$2:$N$181,Data!$B$2:$B$181,$A10,Data!$G$2:$G$181,"Baseline_Nike") | E10: =SUMIFS(Data!$N$2:$N$181,Data!$B$2:$B$181,$A10,Data!$G$2:$G$181,"Nike_Commercial") | F10: =E10-D10 | G10: =SUMIFS(Data!$N$2:$N$181,Data!$B$2:$B$181,$A10,Data!$G$2:$G$181,"Baseline_elf") | H10: =SUMIFS(Data!$N$2:$N$181,Data!$B$2:$B$181,$A10,Data!$G$2:$G$181,"elf_Commercial") | I10: =H10-G10 | J10: =SUMIFS(Data!$T$2:$T$181,Data!$B$2:$B$181,$A10,Data!$G$2:$G$181,"Nike_Commercial") | K10: =SUMIFS(Data!$T$2:$T$181,Data!$B$2:$B$181,$A10,Data!$G$2:$G$181,"elf_Commercial") | L10: =(J10+K10)/2 | M10: =(E10+H10)/2 | O10: n pairs | P10: =COUNT(F5:F32) | Q10: =COUNT(F5:F32) | R10: COUNT of the difference column; must equal the check below
A11: P08 | B11: =INDEX(Data!$E$2:$E$181,MATCH($A11,Data!$B$2:$B$181,0)) | C11: =INDEX(Data!$Y$2:$Y$181,MATCH($A11,Data!$B$2:$B$181,0)) | D11: =SUMIFS(Data!$N$2:$N$181,Data!$B$2:$B$181,$A11,Data!$G$2:$G$181,"Baseline_Nike") | E11: =SUMIFS(Data!$N$2:$N$181,Data!$B$2:$B$181,$A11,Data!$G$2:$G$181,"Nike_Commercial") | F11: =E11-D11 | G11: =SUMIFS(Data!$N$2:$N$181,Data!$B$2:$B$181,$A11,Data!$G$2:$G$181,"Baseline_elf") | H11: =SUMIFS(Data!$N$2:$N$181,Data!$B$2:$B$181,$A11,Data!$G$2:$G$181,"elf_Commercial") | I11: =H11-G11 | J11: =SUMIFS(Data!$T$2:$T$181,Data!$B$2:$B$181,$A11,Data!$G$2:$G$181,"Nike_Commercial") | K11: =SUMIFS(Data!$T$2:$T$181,Data!$B$2:$B$181,$A11,Data!$G$2:$G$181,"elf_Commercial") | L11: =(J11+K11)/2 | M11: =(E11+H11)/2 | O11: Mean difference, Nike_Commercial minus Baseline_Nike (peaks per minute) | P11: =AVERAGE(F5:F32) | Q11: =AVERAGE(F5:F32)
A12: P09 | B12: =INDEX(Data!$E$2:$E$181,MATCH($A12,Data!$B$2:$B$181,0)) | C12: =INDEX(Data!$Y$2:$Y$181,MATCH($A12,Data!$B$2:$B$181,0)) | D12: =SUMIFS(Data!$N$2:$N$181,Data!$B$2:$B$181,$A12,Data!$G$2:$G$181,"Baseline_Nike") | E12: =SUMIFS(Data!$N$2:$N$181,Data!$B$2:$B$181,$A12,Data!$G$2:$G$181,"Nike_Commercial") | F12: =E12-D12 | G12: =SUMIFS(Data!$N$2:$N$181,Data!$B$2:$B$181,$A12,Data!$G$2:$G$181,"Baseline_elf") | H12: =SUMIFS(Data!$N$2:$N$181,Data!$B$2:$B$181,$A12,Data!$G$2:$G$181,"elf_Commercial") | I12: =H12-G12 | J12: =SUMIFS(Data!$T$2:$T$181,Data!$B$2:$B$181,$A12,Data!$G$2:$G$181,"Nike_Commercial") | K12: =SUMIFS(Data!$T$2:$T$181,Data!$B$2:$B$181,$A12,Data!$G$2:$G$181,"elf_Commercial") | L12: =(J12+K12)/2 | M12: =(E12+H12)/2 | O12: SD of the differences (peaks per minute) | P12: =_xlfn.STDEV.S(F5:F32) | Q12: =STDEV.S(F5:F32) | R12: the SD that matters in a paired test
A13: P10 | B13: =INDEX(Data!$E$2:$E$181,MATCH($A13,Data!$B$2:$B$181,0)) | C13: =INDEX(Data!$Y$2:$Y$181,MATCH($A13,Data!$B$2:$B$181,0)) | D13: =SUMIFS(Data!$N$2:$N$181,Data!$B$2:$B$181,$A13,Data!$G$2:$G$181,"Baseline_Nike") | E13: =SUMIFS(Data!$N$2:$N$181,Data!$B$2:$B$181,$A13,Data!$G$2:$G$181,"Nike_Commercial") | F13: =E13-D13 | G13: =SUMIFS(Data!$N$2:$N$181,Data!$B$2:$B$181,$A13,Data!$G$2:$G$181,"Baseline_elf") | H13: =SUMIFS(Data!$N$2:$N$181,Data!$B$2:$B$181,$A13,Data!$G$2:$G$181,"elf_Commercial") | I13: =H13-G13 | J13: =SUMIFS(Data!$T$2:$T$181,Data!$B$2:$B$181,$A13,Data!$G$2:$G$181,"Nike_Commercial") | K13: =SUMIFS(Data!$T$2:$T$181,Data!$B$2:$B$181,$A13,Data!$G$2:$G$181,"elf_Commercial") | L13: =(J13+K13)/2 | M13: =(E13+H13)/2 | O13: SE of the mean difference | P13: =P12/SQRT(P10) | Q13: =P12/SQRT(P10) | R13: SD of differences / sqrt(n)
A14: P12 | B14: =INDEX(Data!$E$2:$E$181,MATCH($A14,Data!$B$2:$B$181,0)) | C14: =INDEX(Data!$Y$2:$Y$181,MATCH($A14,Data!$B$2:$B$181,0)) | D14: =SUMIFS(Data!$N$2:$N$181,Data!$B$2:$B$181,$A14,Data!$G$2:$G$181,"Baseline_Nike") | E14: =SUMIFS(Data!$N$2:$N$181,Data!$B$2:$B$181,$A14,Data!$G$2:$G$181,"Nike_Commercial") | F14: =E14-D14 | G14: =SUMIFS(Data!$N$2:$N$181,Data!$B$2:$B$181,$A14,Data!$G$2:$G$181,"Baseline_elf") | H14: =SUMIFS(Data!$N$2:$N$181,Data!$B$2:$B$181,$A14,Data!$G$2:$G$181,"elf_Commercial") | I14: =H14-G14 | J14: =SUMIFS(Data!$T$2:$T$181,Data!$B$2:$B$181,$A14,Data!$G$2:$G$181,"Nike_Commercial") | K14: =SUMIFS(Data!$T$2:$T$181,Data!$B$2:$B$181,$A14,Data!$G$2:$G$181,"elf_Commercial") | L14: =(J14+K14)/2 | M14: =(E14+H14)/2 | O14: Paired t | P14: =P11/P13 | Q14: =P11/P13 | R14: t = mean difference / SE
A15: P13 | B15: =INDEX(Data!$E$2:$E$181,MATCH($A15,Data!$B$2:$B$181,0)) | C15: =INDEX(Data!$Y$2:$Y$181,MATCH($A15,Data!$B$2:$B$181,0)) | D15: =SUMIFS(Data!$N$2:$N$181,Data!$B$2:$B$181,$A15,Data!$G$2:$G$181,"Baseline_Nike") | E15: =SUMIFS(Data!$N$2:$N$181,Data!$B$2:$B$181,$A15,Data!$G$2:$G$181,"Nike_Commercial") | F15: =E15-D15 | G15: =SUMIFS(Data!$N$2:$N$181,Data!$B$2:$B$181,$A15,Data!$G$2:$G$181,"Baseline_elf") | H15: =SUMIFS(Data!$N$2:$N$181,Data!$B$2:$B$181,$A15,Data!$G$2:$G$181,"elf_Commercial") | I15: =H15-G15 | J15: =SUMIFS(Data!$T$2:$T$181,Data!$B$2:$B$181,$A15,Data!$G$2:$G$181,"Nike_Commercial") | K15: =SUMIFS(Data!$T$2:$T$181,Data!$B$2:$B$181,$A15,Data!$G$2:$G$181,"elf_Commercial") | L15: =(J15+K15)/2 | M15: =(E15+H15)/2 | O15: df | P15: =P10-1 | Q15: =P10-1 | R15: n pairs minus 1
A16: P14 | B16: =INDEX(Data!$E$2:$E$181,MATCH($A16,Data!$B$2:$B$181,0)) | C16: =INDEX(Data!$Y$2:$Y$181,MATCH($A16,Data!$B$2:$B$181,0)) | D16: =SUMIFS(Data!$N$2:$N$181,Data!$B$2:$B$181,$A16,Data!$G$2:$G$181,"Baseline_Nike") | E16: =SUMIFS(Data!$N$2:$N$181,Data!$B$2:$B$181,$A16,Data!$G$2:$G$181,"Nike_Commercial") | F16: =E16-D16 | G16: =SUMIFS(Data!$N$2:$N$181,Data!$B$2:$B$181,$A16,Data!$G$2:$G$181,"Baseline_elf") | H16: =SUMIFS(Data!$N$2:$N$181,Data!$B$2:$B$181,$A16,Data!$G$2:$G$181,"elf_Commercial") | I16: =H16-G16 | J16: =SUMIFS(Data!$T$2:$T$181,Data!$B$2:$B$181,$A16,Data!$G$2:$G$181,"Nike_Commercial") | K16: =SUMIFS(Data!$T$2:$T$181,Data!$B$2:$B$181,$A16,Data!$G$2:$G$181,"elf_Commercial") | L16: =(J16+K16)/2 | M16: =(E16+H16)/2 | O16: p, two tailed (T.TEST type 1) | P16: =_xlfn.T.TEST(D5:D32,E5:E32,2,1) | Q16: =T.TEST(D5:D32,E5:E32,2,1) | R16: tails = 2, type = 1 means paired
A17: P15 | B17: =INDEX(Data!$E$2:$E$181,MATCH($A17,Data!$B$2:$B$181,0)) | C17: =INDEX(Data!$Y$2:$Y$181,MATCH($A17,Data!$B$2:$B$181,0)) | D17: =SUMIFS(Data!$N$2:$N$181,Data!$B$2:$B$181,$A17,Data!$G$2:$G$181,"Baseline_Nike") | E17: =SUMIFS(Data!$N$2:$N$181,Data!$B$2:$B$181,$A17,Data!$G$2:$G$181,"Nike_Commercial") | F17: =E17-D17 | G17: =SUMIFS(Data!$N$2:$N$181,Data!$B$2:$B$181,$A17,Data!$G$2:$G$181,"Baseline_elf") | H17: =SUMIFS(Data!$N$2:$N$181,Data!$B$2:$B$181,$A17,Data!$G$2:$G$181,"elf_Commercial") | I17: =H17-G17 | J17: =SUMIFS(Data!$T$2:$T$181,Data!$B$2:$B$181,$A17,Data!$G$2:$G$181,"Nike_Commercial") | K17: =SUMIFS(Data!$T$2:$T$181,Data!$B$2:$B$181,$A17,Data!$G$2:$G$181,"elf_Commercial") | L17: =(J17+K17)/2 | M17: =(E17+H17)/2 | O17: p from the hand computed t | P17: =_xlfn.T.DIST.2T(ABS(P14),P15) | Q17: =T.DIST.2T(ABS(P14),P15) | R17: should match the T.TEST cell
A18: P17 | B18: =INDEX(Data!$E$2:$E$181,MATCH($A18,Data!$B$2:$B$181,0)) | C18: =INDEX(Data!$Y$2:$Y$181,MATCH($A18,Data!$B$2:$B$181,0)) | D18: =SUMIFS(Data!$N$2:$N$181,Data!$B$2:$B$181,$A18,Data!$G$2:$G$181,"Baseline_Nike") | E18: =SUMIFS(Data!$N$2:$N$181,Data!$B$2:$B$181,$A18,Data!$G$2:$G$181,"Nike_Commercial") | F18: =E18-D18 | G18: =SUMIFS(Data!$N$2:$N$181,Data!$B$2:$B$181,$A18,Data!$G$2:$G$181,"Baseline_elf") | H18: =SUMIFS(Data!$N$2:$N$181,Data!$B$2:$B$181,$A18,Data!$G$2:$G$181,"elf_Commercial") | I18: =H18-G18 | J18: =SUMIFS(Data!$T$2:$T$181,Data!$B$2:$B$181,$A18,Data!$G$2:$G$181,"Nike_Commercial") | K18: =SUMIFS(Data!$T$2:$T$181,Data!$B$2:$B$181,$A18,Data!$G$2:$G$181,"elf_Commercial") | L18: =(J18+K18)/2 | M18: =(E18+H18)/2 | O18: Critical t (95%) | P18: =_xlfn.T.INV.2T(0.05,P15) | Q18: =T.INV.2T(0.05,P15) | R18: two tailed, alpha = .05
A19: P18 | B19: =INDEX(Data!$E$2:$E$181,MATCH($A19,Data!$B$2:$B$181,0)) | C19: =INDEX(Data!$Y$2:$Y$181,MATCH($A19,Data!$B$2:$B$181,0)) | D19: =SUMIFS(Data!$N$2:$N$181,Data!$B$2:$B$181,$A19,Data!$G$2:$G$181,"Baseline_Nike") | E19: =SUMIFS(Data!$N$2:$N$181,Data!$B$2:$B$181,$A19,Data!$G$2:$G$181,"Nike_Commercial") | F19: =E19-D19 | G19: =SUMIFS(Data!$N$2:$N$181,Data!$B$2:$B$181,$A19,Data!$G$2:$G$181,"Baseline_elf") | H19: =SUMIFS(Data!$N$2:$N$181,Data!$B$2:$B$181,$A19,Data!$G$2:$G$181,"elf_Commercial") | I19: =H19-G19 | J19: =SUMIFS(Data!$T$2:$T$181,Data!$B$2:$B$181,$A19,Data!$G$2:$G$181,"Nike_Commercial") | K19: =SUMIFS(Data!$T$2:$T$181,Data!$B$2:$B$181,$A19,Data!$G$2:$G$181,"elf_Commercial") | L19: =(J19+K19)/2 | M19: =(E19+H19)/2 | O19: Mean difference 95% CI lower | P19: =P11-P18*P13 | Q19: =P11-P18*P13
A20: P19 | B20: =INDEX(Data!$E$2:$E$181,MATCH($A20,Data!$B$2:$B$181,0)) | C20: =INDEX(Data!$Y$2:$Y$181,MATCH($A20,Data!$B$2:$B$181,0)) | D20: =SUMIFS(Data!$N$2:$N$181,Data!$B$2:$B$181,$A20,Data!$G$2:$G$181,"Baseline_Nike") | E20: =SUMIFS(Data!$N$2:$N$181,Data!$B$2:$B$181,$A20,Data!$G$2:$G$181,"Nike_Commercial") | F20: =E20-D20 | G20: =SUMIFS(Data!$N$2:$N$181,Data!$B$2:$B$181,$A20,Data!$G$2:$G$181,"Baseline_elf") | H20: =SUMIFS(Data!$N$2:$N$181,Data!$B$2:$B$181,$A20,Data!$G$2:$G$181,"elf_Commercial") | I20: =H20-G20 | J20: =SUMIFS(Data!$T$2:$T$181,Data!$B$2:$B$181,$A20,Data!$G$2:$G$181,"Nike_Commercial") | K20: =SUMIFS(Data!$T$2:$T$181,Data!$B$2:$B$181,$A20,Data!$G$2:$G$181,"elf_Commercial") | L20: =(J20+K20)/2 | M20: =(E20+H20)/2 | O20: Mean difference 95% CI upper | P20: =P11+P18*P13 | Q20: =P11+P18*P13
A21: P20 | B21: =INDEX(Data!$E$2:$E$181,MATCH($A21,Data!$B$2:$B$181,0)) | C21: =INDEX(Data!$Y$2:$Y$181,MATCH($A21,Data!$B$2:$B$181,0)) | D21: =SUMIFS(Data!$N$2:$N$181,Data!$B$2:$B$181,$A21,Data!$G$2:$G$181,"Baseline_Nike") | E21: =SUMIFS(Data!$N$2:$N$181,Data!$B$2:$B$181,$A21,Data!$G$2:$G$181,"Nike_Commercial") | F21: =E21-D21 | G21: =SUMIFS(Data!$N$2:$N$181,Data!$B$2:$B$181,$A21,Data!$G$2:$G$181,"Baseline_elf") | H21: =SUMIFS(Data!$N$2:$N$181,Data!$B$2:$B$181,$A21,Data!$G$2:$G$181,"elf_Commercial") | I21: =H21-G21 | J21: =SUMIFS(Data!$T$2:$T$181,Data!$B$2:$B$181,$A21,Data!$G$2:$G$181,"Nike_Commercial") | K21: =SUMIFS(Data!$T$2:$T$181,Data!$B$2:$B$181,$A21,Data!$G$2:$G$181,"elf_Commercial") | L21: =(J21+K21)/2 | M21: =(E21+H21)/2 | O21: Cohen's d_z | P21: =P11/P12 | Q21: =P11/P12 | R21: d_z = mean difference / SD of differences
A22: P22 | B22: =INDEX(Data!$E$2:$E$181,MATCH($A22,Data!$B$2:$B$181,0)) | C22: =INDEX(Data!$Y$2:$Y$181,MATCH($A22,Data!$B$2:$B$181,0)) | D22: =SUMIFS(Data!$N$2:$N$181,Data!$B$2:$B$181,$A22,Data!$G$2:$G$181,"Baseline_Nike") | E22: =SUMIFS(Data!$N$2:$N$181,Data!$B$2:$B$181,$A22,Data!$G$2:$G$181,"Nike_Commercial") | F22: =E22-D22 | G22: =SUMIFS(Data!$N$2:$N$181,Data!$B$2:$B$181,$A22,Data!$G$2:$G$181,"Baseline_elf") | H22: =SUMIFS(Data!$N$2:$N$181,Data!$B$2:$B$181,$A22,Data!$G$2:$G$181,"elf_Commercial") | I22: =H22-G22 | J22: =SUMIFS(Data!$T$2:$T$181,Data!$B$2:$B$181,$A22,Data!$G$2:$G$181,"Nike_Commercial") | K22: =SUMIFS(Data!$T$2:$T$181,Data!$B$2:$B$181,$A22,Data!$G$2:$G$181,"elf_Commercial") | L22: =(J22+K22)/2 | M22: =(E22+H22)/2 | O22: SE of d_z (approximation) | P22: =SQRT(1/P10+P21^2/(2*P10)) | Q22: =SQRT(1/P10+P21^2/(2*P10)) | R22: sqrt(1/n + d_z^2 / (2 n))
A23: P23 | B23: =INDEX(Data!$E$2:$E$181,MATCH($A23,Data!$B$2:$B$181,0)) | C23: =INDEX(Data!$Y$2:$Y$181,MATCH($A23,Data!$B$2:$B$181,0)) | D23: =SUMIFS(Data!$N$2:$N$181,Data!$B$2:$B$181,$A23,Data!$G$2:$G$181,"Baseline_Nike") | E23: =SUMIFS(Data!$N$2:$N$181,Data!$B$2:$B$181,$A23,Data!$G$2:$G$181,"Nike_Commercial") | F23: =E23-D23 | G23: =SUMIFS(Data!$N$2:$N$181,Data!$B$2:$B$181,$A23,Data!$G$2:$G$181,"Baseline_elf") | H23: =SUMIFS(Data!$N$2:$N$181,Data!$B$2:$B$181,$A23,Data!$G$2:$G$181,"elf_Commercial") | I23: =H23-G23 | J23: =SUMIFS(Data!$T$2:$T$181,Data!$B$2:$B$181,$A23,Data!$G$2:$G$181,"Nike_Commercial") | K23: =SUMIFS(Data!$T$2:$T$181,Data!$B$2:$B$181,$A23,Data!$G$2:$G$181,"elf_Commercial") | L23: =(J23+K23)/2 | M23: =(E23+H23)/2 | O23: d_z 95% CI lower | P23: =P21-1.96*P22 | Q23: =P21-1.96*P22 | R23: large sample approximation; R uses the noncentral t interval
A24: P25 | B24: =INDEX(Data!$E$2:$E$181,MATCH($A24,Data!$B$2:$B$181,0)) | C24: =INDEX(Data!$Y$2:$Y$181,MATCH($A24,Data!$B$2:$B$181,0)) | D24: =SUMIFS(Data!$N$2:$N$181,Data!$B$2:$B$181,$A24,Data!$G$2:$G$181,"Baseline_Nike") | E24: =SUMIFS(Data!$N$2:$N$181,Data!$B$2:$B$181,$A24,Data!$G$2:$G$181,"Nike_Commercial") | F24: =E24-D24 | G24: =SUMIFS(Data!$N$2:$N$181,Data!$B$2:$B$181,$A24,Data!$G$2:$G$181,"Baseline_elf") | H24: =SUMIFS(Data!$N$2:$N$181,Data!$B$2:$B$181,$A24,Data!$G$2:$G$181,"elf_Commercial") | I24: =H24-G24 | J24: =SUMIFS(Data!$T$2:$T$181,Data!$B$2:$B$181,$A24,Data!$G$2:$G$181,"Nike_Commercial") | K24: =SUMIFS(Data!$T$2:$T$181,Data!$B$2:$B$181,$A24,Data!$G$2:$G$181,"elf_Commercial") | L24: =(J24+K24)/2 | M24: =(E24+H24)/2 | O24: d_z 95% CI upper | P24: =P21+1.96*P22 | Q24: =P21+1.96*P22
A25: P26 | B25: =INDEX(Data!$E$2:$E$181,MATCH($A25,Data!$B$2:$B$181,0)) | C25: =INDEX(Data!$Y$2:$Y$181,MATCH($A25,Data!$B$2:$B$181,0)) | D25: =SUMIFS(Data!$N$2:$N$181,Data!$B$2:$B$181,$A25,Data!$G$2:$G$181,"Baseline_Nike") | E25: =SUMIFS(Data!$N$2:$N$181,Data!$B$2:$B$181,$A25,Data!$G$2:$G$181,"Nike_Commercial") | F25: =E25-D25 | G25: =SUMIFS(Data!$N$2:$N$181,Data!$B$2:$B$181,$A25,Data!$G$2:$G$181,"Baseline_elf") | H25: =SUMIFS(Data!$N$2:$N$181,Data!$B$2:$B$181,$A25,Data!$G$2:$G$181,"elf_Commercial") | I25: =H25-G25 | J25: =SUMIFS(Data!$T$2:$T$181,Data!$B$2:$B$181,$A25,Data!$G$2:$G$181,"Nike_Commercial") | K25: =SUMIFS(Data!$T$2:$T$181,Data!$B$2:$B$181,$A25,Data!$G$2:$G$181,"elf_Commercial") | L25: =(J25+K25)/2 | M25: =(E25+H25)/2 | O25: Correlation of the two columns | P25: =CORREL(D5:D32,E5:E32) | Q25: =CORREL(D5:D32,E5:E32) | R25: within respondent correlation
