Workbook

Sheet README
A1: SIMULATED EEG frontal alpha asymmetry workbook (teaching material)
A3: Every number in this workbook is SIMULATED. It was generated by make_simulated_data.py (seed 20267088) in the style of the
A4: iMotions demo study DEMO - SonyBravia: a commercial with a key scene (Version A, Commercial_1A) against the same commercial with the
A5: key scene cut (Version B, Commercial_1B), between subjects; a second commercial (Commercial_2) for everyone, within subjects; two
A6: neutral 1 minute nature videos as baselines; the last 10 s of each commercial (EndScene). Device: Neuroelectrics Enobio 8 through
A7: NIC2 and Lab Streaming Layer, iMotions device name Enobio EEG, 500 Hz. No real person was recorded.
A9: FA = ln(alpha power at the RIGHT frontal electrode) - ln(alpha power at the LEFT frontal electrode). Higher = relatively more left
A10: frontal activity, read as approach motivation. ASSUMED channel map (verify in NIC2): Ch5 = F3 (left), Ch6 = F4 (right).
A12: Sheets:
A13: Data EEG Frontal Asymmetry Metrics export as exported (columns A to L, rows 2 to 313); helper columns M to Q are live formulas:
A14: Version, Order, Role (which part of the design the row is), Keep (exclusion rule), Keep15 (stricter sensitivity rule).
A15: Default The same export made with the notebook DEFAULT channels (Ch1 = Fz, Ch7 = P3), for the teaching contrast only.
... A34: analysis_output.txt (its console output), results_text.md (model paragraphs).

Sheet Data
A1: Study Name | B1: Respondent Name | C1: Gender | D1: Age | E1: Group | F1: Type | G1: Label | H1: Start (ms) | I1: Duration (ms) | J1: Parent Stimulus | K1: Mean Frontal Asymmetry Alpha | L1: Algorithm Device Name | M1: Version | N1: Order | O1: Role | P1: Keep | Q1: Keep15
A2: SIMULATED Commercial FA Study | B2: P01 | C2: F | D2: 22 | E2: B_C2first | F2: Stimulus | G2: Baseline_1 | H2: 35000 | I2: 60000 | J2: Baseline_1 | K2: -0.0603 | L2: Frontal Asymmetry (Enobio EEG) | M2: =LEFT(E2,1) | N2: =MID(E2,3,10) | O2: =IF(F2="Stimulus",IF(LEFT(G2,8)="Baseline",G2,IF(LEFT(G2,12)="Commercial_1","C1","C2")),IF(G2="KeyScene","KeyScene",IF(LEFT(J2,12)="Commercial_1","EndScene_C1","EndScene_C2"))) | P2: =IF(COUNTIFS(Artifact!$B$2:$B$385,B2,Artifact!$K$2:$K$385,">25")+COUNTIFS(Log!$A$2:$A$49,B2,Log!$H$2:$H$49,"Red")+COUNTIFS(Log!$A$2:$A$49,B2,Log!$I$2:$I$49,"Red")>0,"No","Yes") | Q2: =IF(COUNTIFS(Artifact!$B$2:$B$385,B2,Artifact!$K$2:$K$385,">15")+COUNTIFS(Log!$A$2:$A$49,B2,Log!$H$2:$H$49,"Red")+COUNTIFS(Log!$A$2:$A$49,B2,Log!$I$2:$I$49,"Red")>0,"No","Yes")
A3: SIMULATED Commercial FA Study | B3: P01 | C3: F | D3: 22 | E3: B_C2first | F3: Stimulus | G3: Commercial_2 | H3: 95000 | I3: 60000 | J3: Commercial_2 | K3: 0.0166 | L3: Frontal Asymmetry (Enobio EEG) | M3: =LEFT(E3,1) | N3: =MID(E3,3,10) | O3: =IF(F3="Stimulus",IF(LEFT(G3,8)="Baseline",G3,IF(LEFT(G3,12)="Commercial_1","C1","C2")),IF(G3="KeyScene","KeyScene",IF(LEFT(J3,12)="Commercial_1","EndScene_C1","EndScene_C2"))) | P3: =IF(COUNTIFS(Artifact!$B$2:$B$385,B3,Artifact!$K$2:$K$385,">25")+COUNTIFS(Log!$A$2:$A$49,B3,Log!$H$2:$H$49,"Red")+COUNTIFS(Log!$A$2:$A$49,B3,Log!$I$2:$I$49,"Red")>0,"No","Yes") | Q3: =IF(COUNTIFS(Artifact!$B$2:$B$385,B3,Artifact!$K$2:$K$385,">15")+COUNTIFS(Log!$A$2:$A$49,B3,Log!$H$2:$H$49,"Red")+COUNTIFS(Log!$A$2:$A$49,B3,Log!$I$2:$I$49,"Red")>0,"No","Yes")
A4: SIMULATED Commercial FA Study | B4: P01 | C4: F | D4: 22 | E4: B_C2first | F4: Stimulus | G4: Baseline_2 | H4: 203000 | I4: 60000 | J4: Baseline_2 | K4: 0.0787 | L4: Frontal Asymmetry (Enobio EEG) | M4: =LEFT(E4,1) | N4: =MID(E4,3,10) | O4: =IF(F4="Stimulus",IF(LEFT(G4,8)="Baseline",G4,IF(LEFT(G4,12)="Commercial_1","C1","C2")),IF(G4="KeyScene","KeyScene",IF(LEFT(J4,12)="Commercial_1","EndScene_C1","EndScene_C2"))) | P4: =IF(COUNTIFS(Artifact!$B$2:$B$385,B4,Artifact!$K$2:$K$385,">25")+COUNTIFS(Log!$A$2:$A$49,B4,Log!$H$2:$H$49,"Red")+COUNTIFS(Log!$A$2:$A$49,B4,Log!$I$2:$I$49,"Red")>0,"No","Yes") | Q4: =IF(COUNTIFS(Artifact!$B$2:$B$385,B4,Artifact!$K$2:$K$385,">15")+COUNTIFS(Log!$A$2:$A$49,B4,Log!$H$2:$H$49,"Red")+COUNTIFS(Log!$A$2:$A$49,B4,Log!$I$2:$I$49,"Red")>0,"No","Yes")
A5: SIMULATED Commercial FA Study | B5: P01 | C5: F | D5: 22 | E5: B_C2first | F5: Stimulus | G5: Commercial_1B | H5: 263000 | I5: 54000 | J5: Commercial_1B | K5: 0.0081 | L5: Frontal Asymmetry (Enobio EEG) | M5: =LEFT(E5,1) | N5: =MID(E5,3,10) | O5: =IF(F5="Stimulus",IF(LEFT(G5,8)="Baseline",G5,IF(LEFT(G5,12)="Commercial_1","C1","C2")),IF(G5="KeyScene","KeyScene",IF(LEFT(J5,12)="Commercial_1","EndScene_C1","EndScene_C2"))) | P5: =IF(COUNTIFS(Artifact!$B$2:$B$385,B5,Artifact!$K$2:$K$385,">25")+COUNTIFS(Log!$A$2:$A$49,B5,Log!$H$2:$H$49,"Red")+COUNTIFS(Log!$A$2:$A$49,B5,Log!$I$2:$I$49,"Red")>0,"No","Yes") | Q5: =IF(COUNTIFS(Artifact!$B$2:$B$385,B5,Artifact!$K$2:$K$385,">15")+COUNTIFS(Log!$A$2:$A$49,B5,Log!$H$2:$H$49,"Red")+COUNTIFS(Log!$A$2:$A$49,B5,Log!$I$2:$I$49,"Red")>0,"No","Yes")
A6: SIMULATED Commercial FA Study | B6: P01 | C6: F | D6: 22 | E6: B_C2first | F6: Annotation | G6: EndScene | H6: 145000 | I6: 10000 | J6: Commercial_2 | K6: 0.0379 | L6: Frontal Asymmetry (Enobio EEG) | M6: =LEFT(E6,1) | N6: =MID(E6,3,10) | O6: =IF(F6="Stimulus",IF(LEFT(G6,8)="Baseline",G6,IF(LEFT(G6,12)="Commercial_1","C1","C2")),IF(G6="KeyScene","KeyScene",IF(LEFT(J6,12)="Commercial_1","EndScene_C1","EndScene_C2"))) | P6: =IF(COUNTIFS(Artifact!$B$2:$B$385,B6,Artifact!$K$2:$K$385,">25")+COUNTIFS(Log!$A$2:$A$49,B6,Log!$H$2:$H$49,"Red")+COUNTIFS(Log!$A$2:$A$49,B6,Log!$I$2:$I$49,"Red")>0,"No","Yes") | Q6: =IF(COUNTIFS(Artifact!$B$2:$B$385,B6,Artifact!$K$2:$K$385,">15")+COUNTIFS(Log!$A$2:$A$49,B6,Log!$H$2:$H$49,"Red")+COUNTIFS(Log!$A$2:$A$49,B6,Log!$I$2:$I$49,"Red")>0,"No","Yes")
A7: SIMULATED Commercial FA Study | B7: P01 | C7: F | D7: 22 | E7: B_C2first | F7: Annotation | G7: EndScene | H7: 307000 | I7: 10000 | J7: Commercial_1B | K7: -0.0869 | L7: Frontal Asymmetry (Enobio EEG) | M7: =LEFT(E7,1) | N7: =MID(E7,3,10) | O7: =IF(F7="Stimulus",IF(LEFT(G7,8)="Baseline",G7,IF(LEFT(G7,12)="Commercial_1","C1","C2")),IF(G7="KeyScene","KeyScene",IF(LEFT(J7,12)="Commercial_1","EndScene_C1","EndScene_C2"))) | P7: =IF(COUNTIFS(Artifact!$B$2:$B$385,B7,Artifact!$K$2:$K$385,">25")+COUNTIFS(Log!$A$2:$A$49,B7,Log!$H$2:$H$49,"Red")+COUNTIFS(Log!$A$2:$A$49,B7,Log!$I$2:$I$49,"Red")>0,"No","Yes") | Q7: =IF(COUNTIFS(Artifact!$B$2:$B$385,B7,Artifact!$K$2:$K$385,">15")+COUNTIFS(Log!$A$2:$A$49,B7,Log!$H$2:$H$49,"Red")+COUNTIFS(Log!$A$2:$A$49,B7,Log!$I$2:$I$49,"Red")>0,"No","Yes")
A8: SIMULATED Commercial FA Study | B8: P02 | C8: F | D8: 22 | E8: A_C2first | F8: Stimulus | G8: Baseline_1 | H8: 35000 | I8: 60000 | J8: Baseline_1 | K8: -0.1065 | L8: Frontal Asymmetry (Enobio EEG) | M8: =LEFT(E8,1) | N8: =MID(E8,3,10) | O8: =IF(F8="Stimulus",IF(LEFT(G8,8)="Baseline",G8,IF(LEFT(G8,12)="Commercial_1","C1","C2")),IF(G8="KeyScene","KeyScene",IF(LEFT(J8,12)="Commercial_1","EndScene_C1","EndScene_C2"))) | P8: =IF(COUNTIFS(Artifact!$B$2:$B$385,B8,Artifact!$K$2:$K$385,">25")+COUNTIFS(Log!$A$2:$A$49,B8,Log!$H$2:$H$49,"Red")+COUNTIFS(Log!$A$2:$A$49,B8,Log!$I$2:$I$49,"Red")>0,"No","Yes") | Q8: =IF(COUNTIFS(Artifact!$B$2:$B$385,B8,Artifact!$K$2:$K$385,">15")+COUNTIFS(Log!$A$2:$A$49,B8,Log!$H$2:$H$49,"Red")+COUNTIFS(Log!$A$2:$A$49,B8,Log!$I$2:$I$49,"Red")>0,"No","Yes")
A9: SIMULATED Commercial FA Study | B9: P02 | C9: F | D9: 22 | E9: A_C2first | F9: Stimulus | G9: Commercial_2 | H9: 95000 | I9: 60000 | J9: Commercial_2 | K9: -0.1198 | L9: Frontal Asymmetry (Enobio EEG) | M9: =LEFT(E9,1) | N9: =MID(E9,3,10) | O9: =IF(F9="Stimulus",IF(LEFT(G9,8)="Baseline",G9,IF(LEFT(G9,12)="Commercial_1","C1","C2")),IF(G9="KeyScene","KeyScene",IF(LEFT(J9,12)="Commercial_1","EndScene_C1","EndScene_C2"))) | P9: =IF(COUNTIFS(Artifact!$B$2:$B$385,B9,Artifact!$K$2:$K$385,">25")+COUNTIFS(Log!$A$2:$A$49,B9,Log!$H$2:$H$49,"Red")+COUNTIFS(Log!$A$2:$A$49,B9,Log!$I$2:$I$49,"Red")>0,"No","Yes") | Q9: =IF(COUNTIFS(Artifact!$B$2:$B$385,B9,Artifact!$K$2:$K$385,">15")+COUNTIFS(Log!$A$2:$A$49,B9,Log!$H$2:$H$49,"Red")+COUNTIFS(Log!$A$2:$A$49,B9,Log!$I$2:$I$49,"Red")>0,"No","Yes")
A10: SIMULATED Commercial FA Study | B10: P02 | C10: F | D10: 22 | E10: A_C2first | F10: Stimulus | G10: Baseline_2 | H10: 197000 | I10: 60000 | J10: Baseline_2 | K10: -0.177 | L10: Frontal Asymmetry (Enobio EEG) | M10: =LEFT(E10,1) | N10: =MID(E10,3,10) | O10: =IF(F10="Stimulus",IF(LEFT(G10,8)="Baseline",G10,IF(LEFT(G10,12)="Commercial_1","C1","C2")),IF(G10="KeyScene","KeyScene",IF(LEFT(J10,12)="Commercial_1","EndScene_C1","EndScene_C2"))) | P10: =IF(COUNTIFS(Artifact!$B$2:$B$385,B10,Artifact!$K$2:$K$385,">25")+COUNTIFS(Log!$A$2:$A$49,B10,Log!$H$2:$H$49,"Red")+COUNTIFS(Log!$A$2:$A$49,B10,Log!$I$2:$I$49,"Red")>0,"No","Yes") | Q10: =IF(COUNTIFS(Artifact!$B$2:$B$385,B10,Artifact!$K$2:$K$385,">15")+COUNTIFS(Log!$A$2:$A$49,B10,Log!$H$2:$H$49,"Red")+COUNTIFS(Log!$A$2:$A$49,B10,Log!$I$2:$I$49,"Red")>0,"No","Yes")
A11: SIMULATED Commercial FA Study | B11: P02 | C11: F | D11: 22 | E11: A_C2first | F11: Stimulus | G11: Commercial_1A | H11: 257000 | I11: 60000 | J11: Commercial_1A | K11: -0.2164 | L11: Frontal Asymmetry (Enobio EEG) | M11: =LEFT(E11,1) | N11: =MID(E11,3,10) | O11: =IF(F11="Stimulus",IF(LEFT(G11,8)="Baseline",G11,IF(LEFT(G11,12)="Commercial_1","C1","C2")),IF(G11="KeyScene","KeyScene",IF(LEFT(J11,12)="Commercial_1","EndScene_C1","EndScene_C2"))) | P11: =IF(COUNTIFS(Artifact!$B$2:$B$385,B11,Artifact!$K$2:$K$385,">25")+COUNTIFS(Log!$A$2:$A$49,B11,Log!$H$2:$H$49,"Red")+COUNTIFS(Log!$A$2:$A$49,B11,Log!$I$2:$I$49,"Red")>0,"No","Yes") | Q11: =IF(COUNTIFS(Artifact!$B$2:$B$385,B11,Artifact!$K$2:$K$385,">15")+COUNTIFS(Log!$A$2:$A$49,B11,Log!$H$2:$H$49,"Red")+COUNTIFS(Log!$A$2:$A$49,B11,Log!$I$2:$I$49,"Red")>0,"No","Yes")
A12: SIMULATED Commercial FA Study | B12: P02 | C12: F | D12: 22 | E12: A_C2first | F12: Annotation | G12: EndScene | H12: 145000 | I12: 10000 | J12: Commercial_2 | K12: -0.1272 | L12: Frontal Asymmetry (Enobio EEG) | M12: =LEFT(E12,1) | N12: =MID(E12,3,10) | O12: =IF(F12="Stimulus",IF(LEFT(G12,8)="Baseline",G12,IF(LEFT(G12,12)="Commercial_1","C1","C2")),IF(G12="KeyScene","KeyScene",IF(LEFT(J12,12)="Commercial_1","EndScene_C1","EndScene_C2"))) | P12: =IF(COUNTIFS(Artifact!$B$2:$B$385,B12,Artifact!$K$2:$K$385,">25")+COUNTIFS(Log!$A$2:$A$49,B12,Log!$H$2:$H$49,"Red")+COUNTIFS(Log!$A$2:$A$49,B12,Log!$I$2:$I$49,"Red")>0,"No","Yes") | Q12: =IF(COUNTIFS(Artifact!$B$2:$B$385,B12,Artifact!$K$2:$K$385,">15")+COUNTIFS(Log!$A$2:$A$49,B12,Log!$H$2:$H$49,"Red")+COUNTIFS(Log!$A$2:$A$49,B12,Log!$I$2:$I$49,"Red")>0,"No","Yes")
A13: SIMULATED Commercial FA Study | B13: P02 | C13: F | D13: 22 | E13: A_C2first | F13: Annotation | G13: KeyScene | H13: 289000 | I13: 6000 | J13: Commercial_1A | K13: -0.1678 | L13: Frontal Asymmetry (Enobio EEG) | M13: =LEFT(E13,1) | N13: =MID(E13,3,10) | O13: =IF(F13="Stimulus",IF(LEFT(G13,8)="Baseline",G13,IF(LEFT(G13,12)="Commercial_1","C1","C2")),IF(G13="KeyScene","KeyScene",IF(LEFT(J13,12)="Commercial_1","EndScene_C1","EndScene_C2"))) | P13: =IF(COUNTIFS(Artifact!$B$2:$B$385,B13,Artifact!$K$2:$K$385,">25")+COUNTIFS(Log!$A$2:$A$49,B13,Log!$H$2:$H$49,"Red")+COUNTIFS(Log!$A$2:$A$49,B13,Log!$I$2:$I$49,"Red")>0,"No","Yes") | Q13: =IF(COUNTIFS(Artifact!$B$2:$B$385,B13,Artifact!$K$2:$K$385,">15")+COUNTIFS(Log!$A$2:$A$49,B13,Log!$H$2:$H$49,"Red")+COUNTIFS(Log!$A$2:$A$49,B13,Log!$I$2:$I$49,"Red")>0,"No","Yes")
... A313: SIMULATED Commercial FA Study | B313: P48 | C313: F | D313: 21 | E313: B_C1first | F313: Annotation | G313: EndScene | H313: 299000 | I313: 10000 | J313: Commercial_2 | K313: -0.1907 | L313: Frontal Asymmetry (Enobio EEG) | M313: =LEFT(E313,1) | N313: =MID(E313,3,10) | O313: =IF(F313="Stimulus",IF(LEFT(G313,8)="Baseline",G313,IF(LEFT(G313,12)="Commercial_1","C1","C2")),IF(G313="KeyScene","KeyScene",IF(LEFT(J313,12)="Commercial_1","EndScene_C1","EndScene_C2"))) | P313: =IF(COUNTIFS(Artifact!$B$2:$B$385,B313,Artifact!$K$2:$K$385,">25")+COUNTIFS(Log!$A$2:$A$49,B313,Log!$H$2:$H$49,"Red")+COUNTIFS(Log!$A$2:$A$49,B313,Log!$I$2:$I$49,"Red")>0,"No","Yes") | Q313: =IF(COUNTIFS(Artifact!$B$2:$B$385,B313,Artifact!$K$2:$K$385,">15")+COUNTIFS(Log!$A$2:$A$49,B313,Log!$H$2:$H$49,"Red")+COUNTIFS(Log!$A$2:$A$49,B313,Log!$I$2:$I$49,"Red")>0,"No","Yes")

Sheet Default
A1: Study Name | B1: Respondent Name | C1: Gender | D1: Age | E1: Group | F1: Type | G1: Label | H1: Start (ms) | I1: Duration (ms) | J1: Parent Stimulus | K1: Mean Frontal Asymmetry Alpha | L1: Algorithm Device Name | M1: Version | N1: Order | O1: Role | P1: Keep | Q1: Keep15
A2: SIMULATED Commercial FA Study | B2: P01 | C2: F | D2: 22 | E2: B_C2first | F2: Stimulus | G2: Baseline_1 | H2: 35000 | I2: 60000 | J2: Baseline_1 | K2: 0.5144 | L2: Frontal Asymmetry (Enobio EEG) | M2: =LEFT(E2,1) | N2: =MID(E2,3,10) | O2: =IF(F2="Stimulus",IF(LEFT(G2,8)="Baseline",G2,IF(LEFT(G2,12)="Commercial_1","C1","C2")),IF(G2="KeyScene","KeyScene",IF(LEFT(J2,12)="Commercial_1","EndScene_C1","EndScene_C2"))) | P2: =IF(COUNTIFS(Artifact!$B$2:$B$385,B2,Artifact!$K$2:$K$385,">25")+COUNTIFS(Log!$A$2:$A$49,B2,Log!$H$2:$H$49,"Red")+COUNTIFS(Log!$A$2:$A$49,B2,Log!$I$2:$I$49,"Red")>0,"No","Yes") | Q2: =IF(COUNTIFS(Artifact!$B$2:$B$385,B2,Artifact!$K$2:$K$385,">15")+COUNTIFS(Log!$A$2:$A$49,B2,Log!$H$2:$H$49,"Red")+COUNTIFS(Log!$A$2:$A$49,B2,Log!$I$2:$I$49,"Red")>0,"No","Yes")
A3: SIMULATED Commercial FA Study | B3: P01 | C3: F | D3: 22 | E3: B_C2first | F3: Stimulus | G3: Commercial_2 | H3: 95000 | I3: 60000 | J3: Commercial_2 | K3: 0.4972 | L3: Frontal Asymmetry (Enobio EEG) | M3: =LEFT(E3,1) | N3: =MID(E3,3,10) | O3: =IF(F3="Stimulus",IF(LEFT(G3,8)="Baseline",G3,IF(LEFT(G3,12)="Commercial_1","C1","C2")),IF(G3="KeyScene","KeyScene",IF(LEFT(J3,12)="Commercial_1","EndScene_C1","EndScene_C2"))) | P3: =IF(COUNTIFS(Artifact!$B$2:$B$385,B3,Artifact!$K$2:$K$385,">25")+COUNTIFS(Log!$A$2:$A$49,B3,Log!$H$2:$H$49,"Red")+COUNTIFS(Log!$A$2:$A$49,B3,Log!$I$2:$I$49,"Red")>0,"No","Yes") | Q3: =IF(COUNTIFS(Artifact!$B$2:$B$385,B3,Artifact!$K$2:$K$385,">15")+COUNTIFS(Log!$A$2:$A$49,B3,Log!$H$2:$H$49,"Red")+COUNTIFS(Log!$A$2:$A$49,B3,Log!$I$2:$I$49,"Red")>0,"No","Yes")
A4: SIMULATED Commercial FA Study | B4: P01 | C4: F | D4: 22 | E4: B_C2first | F4: Stimulus | G4: Baseline_2 | H4: 203000 | I4: 60000 | J4: Baseline_2 | K4: 0.4845 | L4: Frontal Asymmetry (Enobio EEG) | M4: =LEFT(E4,1) | N4: =MID(E4,3,10) | O4: =IF(F4="Stimulus",IF(LEFT(G4,8)="Baseline",G4,IF(LEFT(G4,12)="Commercial_1","C1","C2")),IF(G4="KeyScene","KeyScene",IF(LEFT(J4,12)="Commercial_1","EndScene_C1","EndScene_C2"))) | P4: =IF(COUNTIFS(Artifact!$B$2:$B$385,B4,Artifact!$K$2:$K$385,">25")+COUNTIFS(Log!$A$2:$A$49,B4,Log!$H$2:$H$49,"Red")+COUNTIFS(Log!$A$2:$A$49,B4,Log!$I$2:$I$49,"Red")>0,"No","Yes") | Q4: =IF(COUNTIFS(Artifact!$B$2:$B$385,B4,Artifact!$K$2:$K$385,">15")+COUNTIFS(Log!$A$2:$A$49,B4,Log!$H$2:$H$49,"Red")+COUNTIFS(Log!$A$2:$A$49,B4,Log!$I$2:$I$49,"Red")>0,"No","Yes")
A5: SIMULATED Commercial FA Study | B5: P01 | C5: F | D5: 22 | E5: B_C2first | F5: Stimulus | G5: Commercial_1B | H5: 263000 | I5: 54000 | J5: Commercial_1B | K5: 0.5385 | L5: Frontal Asymmetry (Enobio EEG) | M5: =LEFT(E5,1) | N5: =MID(E5,3,10) | O5: =IF(F5="Stimulus",IF(LEFT(G5,8)="Baseline",G5,IF(LEFT(G5,12)="Commercial_1","C1","C2")),IF(G5="KeyScene","KeyScene",IF(LEFT(J5,12)="Commercial_1","EndScene_C1","EndScene_C2"))) | P5: =IF(COUNTIFS(Artifact!$B$2:$B$385,B5,Artifact!$K$2:$K$385,">25")+COUNTIFS(Log!$A$2:$A$49,B5,Log!$H$2:$H$49,"Red")+COUNTIFS(Log!$A$2:$A$49,B5,Log!$I$2:$I$49,"Red")>0,"No","Yes") | Q5: =IF(COUNTIFS(Artifact!$B$2:$B$385,B5,Artifact!$K$2:$K$385,">15")+COUNTIFS(Log!$A$2:$A$49,B5,Log!$H$2:$H$49,"Red")+COUNTIFS(Log!$A$2:$A$49,B5,Log!$I$2:$I$49,"Red")>0,"No","Yes")
A6: SIMULATED Commercial FA Study | B6: P01 | C6: F | D6: 22 | E6: B_C2first | F6: Annotation | G6: EndScene | H6: 145000 | I6: 10000 | J6: Commercial_2 | K6: 0.5426 | L6: Frontal Asymmetry (Enobio EEG) | M6: =LEFT(E6,1) | N6: =MID(E6,3,10) | O6: =IF(F6="Stimulus",IF(LEFT(G6,8)="Baseline",G6,IF(LEFT(G6,12)="Commercial_1","C1","C2")),IF(G6="KeyScene","KeyScene",IF(LEFT(J6,12)="Commercial_1","EndScene_C1","EndScene_C2"))) | P6: =IF(COUNTIFS(Artifact!$B$2:$B$385,B6,Artifact!$K$2:$K$385,">25")+COUNTIFS(Log!$A$2:$A$49,B6,Log!$H$2:$H$49,"Red")+COUNTIFS(Log!$A$2:$A$49,B6,Log!$I$2:$I$49,"Red")>0,"No","Yes") | Q6: =IF(COUNTIFS(Artifact!$B$2:$B$385,B6,Artifact!$K$2:$K$385,">15")+COUNTIFS(Log!$A$2:$A$49,B6,Log!$H$2:$H$49,"Red")+COUNTIFS(Log!$A$2:$A$49,B6,Log!$I$2:$I$49,"Red")>0,"No","Yes")
A7: SIMULATED Commercial FA Study | B7: P01 | C7: F | D7: 22 | E7: B_C2first | F7: Annotation | G7: EndScene | H7: 307000 | I7: 10000 | J7: Commercial_1B | K7: 0.5988 | L7: Frontal Asymmetry (Enobio EEG) | M7: =LEFT(E7,1) | N7: =MID(E7,3,10) | O7: =IF(F7="Stimulus",IF(LEFT(G7,8)="Baseline",G7,IF(LEFT(G7,12)="Commercial_1","C1","C2")),IF(G7="KeyScene","KeyScene",IF(LEFT(J7,12)="Commercial_1","EndScene_C1","EndScene_C2"))) | P7: =IF(COUNTIFS(Artifact!$B$2:$B$385,B7,Artifact!$K$2:$K$385,">25")+COUNTIFS(Log!$A$2:$A$49,B7,Log!$H$2:$H$49,"Red")+COUNTIFS(Log!$A$2:$A$49,B7,Log!$I$2:$I$49,"Red")>0,"No","Yes") | Q7: =IF(COUNTIFS(Artifact!$B$2:$B$385,B7,Artifact!$K$2:$K$385,">15")+COUNTIFS(Log!$A$2:$A$49,B7,Log!$H$2:$H$49,"Red")+COUNTIFS(Log!$A$2:$A$49,B7,Log!$I$2:$I$49,"Red")>0,"No","Yes")
A8: SIMULATED Commercial FA Study | B8: P02 | C8: F | D8: 22 | E8: A_C2first | F8: Stimulus | G8: Baseline_1 | H8: 35000 | I8: 60000 | J8: Baseline_1 | K8: 0.6723 | L8: Frontal Asymmetry (Enobio EEG) | M8: =LEFT(E8,1) | N8: =MID(E8,3,10) | O8: =IF(F8="Stimulus",IF(LEFT(G8,8)="Baseline",G8,IF(LEFT(G8,12)="Commercial_1","C1","C2")),IF(G8="KeyScene","KeyScene",IF(LEFT(J8,12)="Commercial_1","EndScene_C1","EndScene_C2"))) | P8: =IF(COUNTIFS(Artifact!$B$2:$B$385,B8,Artifact!$K$2:$K$385,">25")+COUNTIFS(Log!$A$2:$A$49,B8,Log!$H$2:$H$49,"Red")+COUNTIFS(Log!$A$2:$A$49,B8,Log!$I$2:$I$49,"Red")>0,"No","Yes") | Q8: =IF(COUNTIFS(Artifact!$B$2:$B$385,B8,Artifact!$K$2:$K$385,">15")+COUNTIFS(Log!$A$2:$A$49,B8,Log!$H$2:$H$49,"Red")+COUNTIFS(Log!$A$2:$A$49,B8,Log!$I$2:$I$49,"Red")>0,"No","Yes")
A9: SIMULATED Commercial FA Study | B9: P02 | C9: F | D9: 22 | E9: A_C2first | F9: Stimulus | G9: Commercial_2 | H9: 95000 | I9: 60000 | J9: Commercial_2 | K9: 0.6684 | L9: Frontal Asymmetry (Enobio EEG) | M9: =LEFT(E9,1) | N9: =MID(E9,3,10) | O9: =IF(F9="Stimulus",IF(LEFT(G9,8)="Baseline",G9,IF(LEFT(G9,12)="Commercial_1","C1","C2")),IF(G9="KeyScene","KeyScene",IF(LEFT(J9,12)="Commercial_1","EndScene_C1","EndScene_C2"))) | P9: =IF(COUNTIFS(Artifact!$B$2:$B$385,B9,Artifact!$K$2:$K$385,">25")+COUNTIFS(Log!$A$2:$A$49,B9,Log!$H$2:$H$49,"Red")+COUNTIFS(Log!$A$2:$A$49,B9,Log!$I$2:$I$49,"Red")>0,"No","Yes") | Q9: =IF(COUNTIFS(Artifact!$B$2:$B$385,B9,Artifact!$K$2:$K$385,">15")+COUNTIFS(Log!$A$2:$A$49,B9,Log!$H$2:$H$49,"Red")+COUNTIFS(Log!$A$2:$A$49,B9,Log!$I$2:$I$49,"Red")>0,"No","Yes")
A10: SIMULATED Commercial FA Study | B10: P02 | C10: F | D10: 22 | E10: A_C2first | F10: Stimulus | G10: Baseline_2 | H10: 197000 | I10: 60000 | J10: Baseline_2 | K10: 0.6154 | L10: Frontal Asymmetry (Enobio EEG) | M10: =LEFT(E10,1) | N10: =MID(E10,3,10) | O10: =IF(F10="Stimulus",IF(LEFT(G10,8)="Baseline",G10,IF(LEFT(G10,12)="Commercial_1","C1","C2")),IF(G10="KeyScene","KeyScene",IF(LEFT(J10,12)="Commercial_1","EndScene_C1","EndScene_C2"))) | P10: =IF(COUNTIFS(Artifact!$B$2:$B$385,B10,Artifact!$K$2:$K$385,">25")+COUNTIFS(Log!$A$2:$A$49,B10,Log!$H$2:$H$49,"Red")+COUNTIFS(Log!$A$2:$A$49,B10,Log!$I$2:$I$49,"Red")>0,"No","Yes") | Q10: =IF(COUNTIFS(Artifact!$B$2:$B$385,B10,Artifact!$K$2:$K$385,">15")+COUNTIFS(Log!$A$2:$A$49,B10,Log!$H$2:$H$49,"Red")+COUNTIFS(Log!$A$2:$A$49,B10,Log!$I$2:$I$49,"Red")>0,"No","Yes")
A11: SIMULATED Commercial FA Study | B11: P02 | C11: F | D11: 22 | E11: A_C2first | F11: Stimulus | G11: Commercial_1A | H11: 257000 | I11: 60000 | J11: Commercial_1A | K11: 0.5911 | L11: Frontal Asymmetry (Enobio EEG) | M11: =LEFT(E11,1) | N11: =MID(E11,3,10) | O11: =IF(F11="Stimulus",IF(LEFT(G11,8)="Baseline",G11,IF(LEFT(G11,12)="Commercial_1","C1","C2")),IF(G11="KeyScene","KeyScene",IF(LEFT(J11,12)="Commercial_1","EndScene_C1","EndScene_C2"))) | P11: =IF(COUNTIFS(Artifact!$B$2:$B$385,B11,Artifact!$K$2:$K$385,">25")+COUNTIFS(Log!$A$2:$A$49,B11,Log!$H$2:$H$49,"Red")+COUNTIFS(Log!$A$2:$A$49,B11,Log!$I$2:$I$49,"Red")>0,"No","Yes") | Q11: =IF(COUNTIFS(Artifact!$B$2:$B$385,B11,Artifact!$K$2:$K$385,">15")+COUNTIFS(Log!$A$2:$A$49,B11,Log!$H$2:$H$49,"Red")+COUNTIFS(Log!$A$2:$A$49,B11,Log!$I$2:$I$49,"Red")>0,"No","Yes")
A12: SIMULATED Commercial FA Study | B12: P02 | C12: F | D12: 22 | E12: A_C2first | F12: Annotation | G12: EndScene | H12: 145000 | I12: 10000 | J12: Commercial_2 | K12: 0.7472 | L12: Frontal Asymmetry (Enobio EEG) | M12: =LEFT(E12,1) | N12: =MID(E12,3,10) | O12: =IF(F12="Stimulus",IF(LEFT(G12,8)="Baseline",G12,IF(LEFT(G12,12)="Commercial_1","C1","C2")),IF(G12="KeyScene","KeyScene",IF(LEFT(J12,12)="Commercial_1","EndScene_C1","EndScene_C2"))) | P12: =IF(COUNTIFS(Artifact!$B$2:$B$385,B12,Artifact!$K$2:$K$385,">25")+COUNTIFS(Log!$A$2:$A$49,B12,Log!$H$2:$H$49,"Red")+COUNTIFS(Log!$A$2:$A$49,B12,Log!$I$2:$I$49,"Red")>0,"No","Yes") | Q12: =IF(COUNTIFS(Artifact!$B$2:$B$385,B12,Artifact!$K$2:$K$385,">15")+COUNTIFS(Log!$A$2:$A$49,B12,Log!$H$2:$H$49,"Red")+COUNTIFS(Log!$A$2:$A$49,B12,Log!$I$2:$I$49,"Red")>0,"No","Yes")
A13: SIMULATED Commercial FA Study | B13: P02 | C13: F | D13: 22 | E13: A_C2first | F13: Annotation | G13: KeyScene | H13: 289000 | I13: 6000 | J13: Commercial_1A | K13: 0.5858 | L13: Frontal Asymmetry (Enobio EEG) | M13: =LEFT(E13,1) | N13: =MID(E13,3,10) | O13: =IF(F13="Stimulus",IF(LEFT(G13,8)="Baseline",G13,IF(LEFT(G13,12)="Commercial_1","C1","C2")),IF(G13="KeyScene","KeyScene",IF(LEFT(J13,12)="Commercial_1","EndScene_C1","EndScene_C2"))) | P13: =IF(COUNTIFS(Artifact!$B$2:$B$385,B13,Artifact!$K$2:$K$385,">25")+COUNTIFS(Log!$A$2:$A$49,B13,Log!$H$2:$H$49,"Red")+COUNTIFS(Log!$A$2:$A$49,B13,Log!$I$2:$I$49,"Red")>0,"No","Yes") | Q13: =IF(COUNTIFS(Artifact!$B$2:$B$385,B13,Artifact!$K$2:$K$385,">15")+COUNTIFS(Log!$A$2:$A$49,B13,Log!$H$2:$H$49,"Red")+COUNTIFS(Log!$A$2:$A$49,B13,Log!$I$2:$I$49,"Red")>0,"No","Yes")
... A313: SIMULATED Commercial FA Study | B313: P48 | C313: F | D313: 21 | E313: B_C1first | F313: Annotation | G313: EndScene | H313: 299000 | I313: 10000 | J313: Commercial_2 | K313: 0.5591 | L313: Frontal Asymmetry (Enobio EEG) | M313: =LEFT(E313,1) | N313: =MID(E313,3,10) | O313: =IF(F313="Stimulus",IF(LEFT(G313,8)="Baseline",G313,IF(LEFT(G313,12)="Commercial_1","C1","C2")),IF(G313="KeyScene","KeyScene",IF(LEFT(J313,12)="Commercial_1","EndScene_C1","EndScene_C2"))) | P313: =IF(COUNTIFS(Artifact!$B$2:$B$385,B313,Artifact!$K$2:$K$385,">25")+COUNTIFS(Log!$A$2:$A$49,B313,Log!$H$2:$H$49,"Red")+COUNTIFS(Log!$A$2:$A$49,B313,Log!$I$2:$I$49,"Red")>0,"No","Yes") | Q313: =IF(COUNTIFS(Artifact!$B$2:$B$385,B313,Artifact!$K$2:$K$385,">15")+COUNTIFS(Log!$A$2:$A$49,B313,Log!$H$2:$H$49,"Red")+COUNTIFS(Log!$A$2:$A$49,B313,Log!$I$2:$I$49,"Red")>0,"No","Yes")

Sheet Artifact
A1: Study Name | B1: Respondent Name | C1: Group | D1: Label | E1: Channel | F1: Electrode (assumed) | G1: Duration (ms) | H1: Samples expected | I1: Samples recorded | J1: Samples removed | K1: Percent removed (%) | L1: Percent recalculated | M1: Gap samples (expected - recorded)
A2: SIMULATED Commercial FA Study | B2: P01 | C2: B_C2first | D2: Baseline_1 | E2: Ch5 | F2: F3 | G2: 60000 | H2: 30000 | I2: 30000 | J2: 1251 | K2: 4.17 | L2: =100*J2/I2 | M2: =H2-I2
A3: SIMULATED Commercial FA Study | B3: P01 | C3: B_C2first | D3: Baseline_1 | E3: Ch6 | F3: F4 | G3: 60000 | H3: 30000 | I3: 30000 | J3: 1011 | K3: 3.37 | L3: =100*J3/I3 | M3: =H3-I3
A4: SIMULATED Commercial FA Study | B4: P01 | C4: B_C2first | D4: Commercial_2 | E4: Ch5 | F4: F3 | G4: 60000 | H4: 30000 | I4: 30000 | J4: 156 | K4: 0.52 | L4: =100*J4/I4 | M4: =H4-I4
A5: SIMULATED Commercial FA Study | B5: P01 | C5: B_C2first | D5: Commercial_2 | E5: Ch6 | F5: F4 | G5: 60000 | H5: 30000 | I5: 30000 | J5: 159 | K5: 0.53 | L5: =100*J5/I5 | M5: =H5-I5
A6: SIMULATED Commercial FA Study | B6: P01 | C6: B_C2first | D6: Baseline_2 | E6: Ch5 | F6: F3 | G6: 60000 | H6: 30000 | I6: 30000 | J6: 696 | K6: 2.32 | L6: =100*J6/I6 | M6: =H6-I6
A7: SIMULATED Commercial FA Study | B7: P01 | C7: B_C2first | D7: Baseline_2 | E7: Ch6 | F7: F4 | G7: 60000 | H7: 30000 | I7: 30000 | J7: 675 | K7: 2.25 | L7: =100*J7/I7 | M7: =H7-I7
A8: SIMULATED Commercial FA Study | B8: P01 | C8: B_C2first | D8: Commercial_1B | E8: Ch5 | F8: F3 | G8: 54000 | H8: 27000 | I8: 27000 | J8: 103 | K8: 0.38 | L8: =100*J8/I8 | M8: =H8-I8
A9: SIMULATED Commercial FA Study | B9: P01 | C9: B_C2first | D9: Commercial_1B | E9: Ch6 | F9: F4 | G9: 54000 | H9: 27000 | I9: 27000 | J9: 143 | K9: 0.53 | L9: =100*J9/I9 | M9: =H9-I9
A10: SIMULATED Commercial FA Study | B10: P02 | C10: A_C2first | D10: Baseline_1 | E10: Ch5 | F10: F3 | G10: 60000 | H10: 30000 | I10: 30000 | J10: 546 | K10: 1.82 | L10: =100*J10/I10 | M10: =H10-I10
A11: SIMULATED Commercial FA Study | B11: P02 | C11: A_C2first | D11: Baseline_1 | E11: Ch6 | F11: F4 | G11: 60000 | H11: 30000 | I11: 30000 | J11: 576 | K11: 1.92 | L11: =100*J11/I11 | M11: =H11-I11
A12: SIMULATED Commercial FA Study | B12: P02 | C12: A_C2first | D12: Commercial_2 | E12: Ch5 | F12: F3 | G12: 60000 | H12: 30000 | I12: 30000 | J12: 378 | K12: 1.26 | L12: =100*J12/I12 | M12: =H12-I12
A13: SIMULATED Commercial FA Study | B13: P02 | C13: A_C2first | D13: Commercial_2 | E13: Ch6 | F13: F4 | G13: 60000 | H13: 30000 | I13: 30000 | J13: 339 | K13: 1.13 | L13: =100*J13/I13 | M13: =H13-I13
... A385: SIMULATED Commercial FA Study | B385: P48 | C385: B_C1first | D385: Commercial_2 | E385: Ch6 | F385: F4 | G385: 60000 | H385: 30000 | I385: 30000 | J385: 420 | K385: 1.4 | L385: =100*J385/I385 | M385: =H385-I385

Sheet Log
A1: Respondent Name | B1: Session Date | C1: Operator | D1: Version | E1: Order | F1: Cap size | G1: Connection | H1: NIC2 quality F3 before recording | I1: NIC2 quality F4 before recording | J1: Gel used | K1: Setup minutes | L1: Incidents | M1: Data complete | N1: Decision note
A2: P01 | B2: 2027-02-01 | C2: Operator_1 | D2: B | E2: C2first | F2: S | G2: USB | H2: Yellow | I2: Green | J2: Yes | K2: 21 | L2: F4 Red at the first check; hair parted, gel added, electrode pressed for 10 s; F4 Green before recording | M2: Yes | N2: Keep: Yellow at the last impedance check is within the lab target (below 10 kOhm)
A3: P02 | B3: 2027-02-01 | C3: Operator_1 | D3: A | E3: C2first | F3: L | G3: USB | H3: Green | I3: Green | J3: Yes | K3: 17 | L3: None | M3: Yes
A4: P03 | B4: 2027-02-01 | C4: Operator_1 | D4: B | E4: C1first | F4: M | G4: USB | H4: Green | I4: Green | J4: Yes | K4: 22 | L4: F4 Red at the first check; hair parted, gel added, electrode pressed for 10 s; F4 Green before recording | M4: Yes
A5: P04 | B5: 2027-02-02 | C5: Operator_2 | D5: A | E5: C1first | F5: M | G5: USB | H5: Green | I5: Green | J5: Yes | K5: 14 | L5: Fidgeting and frequent blinking; reminded once to sit still | M5: Yes | N5: Keep: largest percent removed 22.83 (F4, Baseline_1) is below the 25 percent rule; dropped in the 15 percent sensitivity analysis
A6: P05 | B6: 2027-02-02 | C6: Operator_2 | D6: A | E6: C1first | F6: M | G6: USB | H6: Green | I6: Green | J6: Yes | K6: 10 | L6: Participant asked a question during the first rating slide | M6: Yes
A7: P06 | B7: 2027-02-02 | C7: Operator_2 | D7: B | E7: C2first | F7: M | G7: USB | H7: Green | I7: Green | J7: Yes | K7: 17 | L7: None | M7: Yes
A8: P07 | B8: 2027-02-03 | C8: Operator_1 | D8: B | E8: C1first | F8: M | G8: USB | H8: Green | I8: Green | J8: Yes | K8: 21 | L8: F4 Red at the first check; hair parted, gel added, electrode pressed for 10 s; F4 Green before recording | M8: Yes
A9: P08 | B9: 2027-02-03 | C9: Operator_1 | D9: A | E9: C2first | F9: L | G9: USB | H9: Green | I9: Green | J9: Yes | K9: 14 | L9: Participant asked a question during the first rating slide | M9: Yes
A10: P09 | B10: 2027-02-03 | C10: Operator_1 | D10: A | E10: C1first | F10: M | G10: USB | H10: Green | I10: Green | J10: Yes | K10: 19 | L10: Participant asked a question during the first rating slide | M10: Yes
A11: P10 | B11: 2027-02-04 | C11: Operator_2 | D11: B | E11: C1first | F11: L | G11: USB | H11: Yellow | I11: Green | J11: Yes | K11: 21 | L11: Participant sneezed during Baseline_2; live marker set | M11: Yes | N11: Keep: Yellow at the last impedance check is within the lab target (below 10 kOhm)
A12: P11 | B12: 2027-02-04 | C12: Operator_2 | D12: A | E12: C2first | F12: M | G12: USB | H12: Yellow | I12: Green | J12: Yes | K12: 15 | L12: Participant asked a question during the first rating slide | M12: Yes | N12: Keep: Yellow at the last impedance check is within the lab target (below 10 kOhm)
A13: P12 | B13: 2027-02-04 | C13: Operator_2 | D13: B | E13: C2first | F13: M | G13: USB | H13: Green | I13: Green | J13: Yes | K13: 16 | L13: Participant asked a question during the first rating slide | M13: Yes
A14: P13 | B14: 2027-02-05 | C14: Operator_1 | D14: A | E14: C1first | F14: M | G14: USB | H14: Yellow | I14: Green | J14: Yes | K14: 13 | L14: None | M14: Yes | N14: Keep: Yellow at the last impedance check is within the lab target (below 10 kOhm)
A15: P14 | B15: 2027-02-05 | C15: Operator_1 | D15: A | E15: C2first | F15: L | G15: USB | H15: Yellow | I15: Yellow | J15: Yes | K15: 16 | L15: None | M15: Yes | N15: Keep: Yellow at the last impedance check is within the lab target (below 10 kOhm)
A16: P15 | B16: 2027-02-05 | C16: Operator_1 | D16: B | E16: C1first | F16: M | G16: USB | H16: Green | I16: Green | J16: Yes | K16: 23 | L16: F3 Red at the first check; hair parted, gel added, electrode pressed for 10 s; F3 Green before recording | M16: Yes
A17: P16 | B17: 2027-02-08 | C17: Operator_2 | D17: B | E17: C2first | F17: M | G17: USB | H17: Green | I17: Green | J17: Yes | K17: 15 | L17: Phone vibrated in a bag at the start of Baseline_1; bag moved out of the room | M17: Yes
A18: P17 | B18: 2027-02-08 | C18: Operator_2 | D18: B | E18: C2first | F18: M | G18: USB | H18: Green | I18: Yellow | J18: Yes | K18: 19 | L18: Participant asked a question during the first rating slide | M18: Yes | N18: Keep: Yellow at the last impedance check is within the lab target (below 10 kOhm)
A19: P18 | B19: 2027-02-08 | C19: Operator_2 | D19: A | E19: C2first | F19: S | G19: USB | H19: Green | I19: Green | J19: Yes | K19: 16 | L19: Fidgeting and frequent blinking; reminded once to sit still | M19: Yes | N19: Keep: largest percent removed 17.28 (F4, Commercial_1A) is below the 25 percent rule; dropped in the 15 percent sensitivity analysis
A20: P19 | B20: 2027-02-09 | C20: Operator_1 | D20: B | E20: C1first | F20: M | G20: USB | H20: Green | I20: Yellow | J20: Yes | K20: 25 | L20: None | M20: Yes | N20: Keep: Yellow at the last impedance check is within the lab target (below 10 kOhm)
A21: P20 | B21: 2027-02-09 | C21: Operator_1 | D21: A | E21: C1first | F21: M | G21: USB | H21: Green | I21: Yellow | J21: Yes | K21: 13 | L21: None | M21: Yes | N21: Keep: Yellow at the last impedance check is within the lab target (below 10 kOhm)
A22: P21 | B22: 2027-02-09 | C22: Operator_1 | D22: B | E22: C2first | F22: L | G22: USB | H22: Green | I22: Green | J22: Yes | K22: 16 | L22: Door noise in the hallway during the second commercial | M22: Yes
A23: P22 | B23: 2027-02-10 | C23: Operator_2 | D23: B | E23: C1first | F23: S | G23: USB | H23: Green | I23: Green | J23: Yes | K23: 18 | L23: Fidgeting and frequent blinking; reminded once to sit still | M23: Yes | N23: Keep: largest percent removed 19.79 (F4, Baseline_1) is below the 25 percent rule; dropped in the 15 percent sensitivity analysis
A24: P23 | B24: 2027-02-10 | C24: Operator_2 | D24: A | E24: C2first | F24: L | G24: USB | H24: Yellow | I24: Yellow | J24: Yes | K24: 10 | L24: None | M24: Yes | N24: Keep: Yellow at the last impedance check is within the lab target (below 10 kOhm)
A25: P24 | B25: 2027-02-10 | C25: Operator_2 | D25: A | E25: C1first | F25: M | G25: USB | H25: Yellow | I25: Green | J25: Yes | K25: 14 | L25: Participant adjusted the chin strap between the two commercials | M25: Yes | N25: Keep: Yellow at the last impedance check is within the lab target (below 10 kOhm)
A26: P25 | B26: 2027-02-11 | C26: Operator_1 | D26: B | E26: C1first | F26: M | G26: USB | H26: Green | I26: Yellow | J26: Yes | K26: 17 | L26: Participant sneezed during Baseline_2; live marker set | M26: Yes | N26: Keep: Yellow at the last impedance check is within the lab target (below 10 kOhm)
A27: P26 | B27: 2027-02-11 | C27: Operator_1 | D27: B | E27: C2first | F27: M | G27: USB | H27: Green | I27: Yellow | J27: Yes | K27: 19 | L27: None | M27: Yes | N27: Keep: Yellow at the last impedance check is within the lab target (below 10 kOhm)
A28: P27 | B28: 2027-02-11 | C28: Operator_1 | D28: A | E28: C2first | F28: M | G28: USB | H28: Green | I28: Red | J28: Yes | K28: 34 | L28: F4 Red in NIC2 Liveview at every check: electrode re-seated, hair parted, gel added twice, F4 and F3 leads swapped (the fault stayed at the F4 site); recorded because the participant was present; F4 Red before recording | M28: Yes | N28: EXCLUDE: Red NIC2 quality at F4 that could not be fixed (rule written before collection); the artifact report also shows 41.78 percent of F4 samples removed in Commercial_1A
A29: P28 | B29: 2027-02-12 | C29: Operator_2 | D29: A | E29: C1first | F29: L | G29: USB | H29: Yellow | I29: Green | J29: Yes | K29: 13 | L29: Participant adjusted the chin strap between the two commercials | M29: Yes | N29: Keep: Yellow at the last impedance check is within the lab target (below 10 kOhm)
A30: P29 | B30: 2027-02-12 | C30: Operator_2 | D30: B | E30: C1first | F30: S | G30: USB | H30: Green | I30: Green | J30: Yes | K30: 17 | L30: None | M30: Yes
A31: P30 | B31: 2027-02-12 | C31: Operator_2 | D31: A | E31: C2first | F31: M | G31: USB | H31: Yellow | I31: Green | J31: Yes | K31: 18 | L31: Door noise in the hallway during the second commercial | M31: Yes | N31: Keep: Yellow at the last impedance check is within the lab target (below 10 kOhm)
A32: P31 | B32: 2027-02-15 | C32: Operator_1 | D32: A | E32: C1first | F32: S | G32: USB | H32: Green | I32: Green | J32: Yes | K32: 15 | L32: F3 Red at the first check; hair parted, gel added, electrode pressed for 10 s; F3 Green before recording | M32: Yes
A33: P32 | B33: 2027-02-15 | C33: Operator_1 | D33: B | E33: C2first | F33: S | G33: USB | H33: Green | I33: Green | J33: Yes | K33: 14 | L33: Fidgeting and frequent blinking; reminded once to sit still | M33: Yes | N33: Keep: largest percent removed 21.01 (F3, Commercial_1B) is below the 25 percent rule; dropped in the 15 percent sensitivity analysis
A34: P33 | B34: 2027-02-15 | C34: Operator_1 | D34: B | E34: C1first | F34: M | G34: USB | H34: Green | I34: Green | J34: Yes | K34: 12 | L34: None | M34: Yes
A35: P34 | B35: 2027-02-16 | C35: Operator_2 | D35: A | E35: C1first | F35: S | G35: USB | H35: Green | I35: Green | J35: Yes | K35: 16 | L35: Participant sneezed during Baseline_2; live marker set | M35: Yes
A36: P35 | B36: 2027-02-16 | C36: Operator_2 | D36: A | E36: C2first | F36: M | G36: USB | H36: Yellow | I36: Green | J36: Yes | K36: 18 | L36: Door noise in the hallway during the second commercial | M36: Yes | N36: Keep: Yellow at the last impedance check is within the lab target (below 10 kOhm)
A37: P36 | B37: 2027-02-16 | C37: Operator_2 | D37: B | E37: C2first | F37: L | G37: USB | H37: Green | I37: Green | J37: Yes | K37: 15 | L37: None | M37: Yes
A38: P37 | B38: 2027-02-17 | C38: Operator_1 | D38: A | E38: C1first | F38: L | G38: USB | H38: Green | I38: Green | J38: Yes | K38: 19 | L38: Door noise in the hallway during the second commercial | M38: Yes
A39: P38 | B39: 2027-02-17 | C39: Operator_1 | D39: A | E39: C2first | F39: S | G39: USB | H39: Green | I39: Green | J39: Yes | K39: 22 | L39: F4 Red at the first check; hair parted, gel added, electrode pressed for 10 s; F4 Green before recording | M39: Yes
A40: P39 | B40: 2027-02-17 | C40: Operator_1 | D40: B | E40: C2first | F40: M | G40: USB | H40: Yellow | I40: Green | J40: Yes | K40: 20 | L40: F4 Red at the first check; hair parted, gel added, electrode pressed for 10 s; F4 Green before recording | M40: Yes | N40: Keep: Yellow at the last impedance check is within the lab target (below 10 kOhm)
...

Sheet Survey
A1: Study Name | B1: Respondent Name | C1: Group | D1: Gender | E1: Age | F1: Liking_Commercial_1_1to7 | G1: Liking_Commercial_2_1to7 | H1: KeyScene_Recall | I1: Brand_Named_Correctly
A2: SIMULATED Commercial FA Study | B2: P01 | C2: B_C2first | D2: F | E2: 22 | F2: 7 | G2: 5 | H2: NA | I2: No
A3: SIMULATED Commercial FA Study | B3: P02 | C3: A_C2first | D3: F | E3: 22 | F3: 4 | G3: 7 | H3: No | I3: Yes
A4: SIMULATED Commercial FA Study | B4: P03 | C4: B_C1first | D4: M | E4: 26 | F4: 7 | G4: 7 | H4: NA | I4: Yes
A5: SIMULATED Commercial FA Study | B5: P04 | C5: A_C1first | D5: M | E5: 22 | F5: 6 | G5: 4 | H5: Yes | I5: Yes
A6: SIMULATED Commercial FA Study | B6: P05 | C6: A_C1first | D6: M | E6: 19 | F6: 5 | G6: 6 | H6: Yes | I6: Yes
A7: SIMULATED Commercial FA Study | B7: P06 | C7: B_C2first | D7: M | E7: 25 | F7: 4 | G7: 4 | H7: NA | I7: Yes
A8: SIMULATED Commercial FA Study | B8: P07 | C8: B_C1first | D8: M | E8: 24 | F8: 7 | G8: 7 | H8: NA | I8: Yes
A9: SIMULATED Commercial FA Study | B9: P08 | C9: A_C2first | D9: F | E9: 20 | F9: 6 | G9: 6 | H9: Yes | I9: Yes
A10: SIMULATED Commercial FA Study | B10: P09 | C10: A_C1first | D10: F | E10: 24 | F10: 6 | G10: 5 | H10: Yes | I10: Yes
A11: SIMULATED Commercial FA Study | B11: P10 | C11: B_C1first | D11: F | E11: 20 | F11: 4 | G11: 4 | H11: NA | I11: Yes
A12: SIMULATED Commercial FA Study | B12: P11 | C12: A_C2first | D12: F | E12: 21 | F12: 7 | G12: 7 | H12: Yes | I12: Yes
A13: SIMULATED Commercial FA Study | B13: P12 | C13: B_C2first | D13: M | E13: 24 | F13: 6 | G13: 4 | H13: NA | I13: Yes
... A49: SIMULATED Commercial FA Study | B49: P48 | C49: B_C1first | D49: F | E49: 21 | F49: 4 | G49: 3 | H49: NA | I49: Yes

Sheet Screening
A1: Exclusion screening, one row per respondent. SIMULATED data.
A2: Largest percent of samples removed at F3 and at F4 over the two baselines and two commercials (array formulas MAX(IF(...))), the Red count from the session log, and the decision under the 25 percent rule and the 15 percent sensitivity rule.
A4: Respondent Name | B4: Version | C4: Largest percent removed, F3 | D4: Largest percent removed, F4 | E4: Largest of the two | F4: Red at F3 or F4 before recording (count) | G4: Decision (25 percent rule) | H4: Decision (15 percent rule)
A5: P01 | B5: =INDEX(Data!$M$2:$M$313,MATCH($A5,Data!$B$2:$B$313,0)) | C5: {=MAX(IF((Artifact!$B$2:$B$385=$A5)*(Artifact!$F$2:$F$385="F3"),Artifact!$K$2:$K$385))} | D5: {=MAX(IF((Artifact!$B$2:$B$385=$A5)*(Artifact!$F$2:$F$385="F4"),Artifact!$K$2:$K$385))} | E5: =MAX(C5:D5) | F5: =COUNTIFS(Log!$A$2:$A$49,$A5,Log!$H$2:$H$49,"Red")+COUNTIFS(Log!$A$2:$A$49,$A5,Log!$I$2:$I$49,"Red") | G5: =IF(OR(E5>25,F5>0),"Exclude","Keep") | H5: =IF(OR(E5>15,F5>0),"Exclude","Keep")
A6: P02 | B6: =INDEX(Data!$M$2:$M$313,MATCH($A6,Data!$B$2:$B$313,0)) | C6: {=MAX(IF((Artifact!$B$2:$B$385=$A6)*(Artifact!$F$2:$F$385="F3"),Artifact!$K$2:$K$385))} | D6: {=MAX(IF((Artifact!$B$2:$B$385=$A6)*(Artifact!$F$2:$F$385="F4"),Artifact!$K$2:$K$385))} | E6: =MAX(C6:D6) | F6: =COUNTIFS(Log!$A$2:$A$49,$A6,Log!$H$2:$H$49,"Red")+COUNTIFS(Log!$A$2:$A$49,$A6,Log!$I$2:$I$49,"Red") | G6: =IF(OR(E6>25,F6>0),"Exclude","Keep") | H6: =IF(OR(E6>15,F6>0),"Exclude","Keep")
A7: P03 | B7: =INDEX(Data!$M$2:$M$313,MATCH($A7,Data!$B$2:$B$313,0)) | C7: {=MAX(IF((Artifact!$B$2:$B$385=$A7)*(Artifact!$F$2:$F$385="F3"),Artifact!$K$2:$K$385))} | D7: {=MAX(IF((Artifact!$B$2:$B$385=$A7)*(Artifact!$F$2:$F$385="F4"),Artifact!$K$2:$K$385))} | E7: =MAX(C7:D7) | F7: =COUNTIFS(Log!$A$2:$A$49,$A7,Log!$H$2:$H$49,"Red")+COUNTIFS(Log!$A$2:$A$49,$A7,Log!$I$2:$I$49,"Red") | G7: =IF(OR(E7>25,F7>0),"Exclude","Keep") | H7: =IF(OR(E7>15,F7>0),"Exclude","Keep")
A8: P04 | B8: =INDEX(Data!$M$2:$M$313,MATCH($A8,Data!$B$2:$B$313,0)) | C8: {=MAX(IF((Artifact!$B$2:$B$385=$A8)*(Artifact!$F$2:$F$385="F3"),Artifact!$K$2:$K$385))} | D8: {=MAX(IF((Artifact!$B$2:$B$385=$A8)*(Artifact!$F$2:$F$385="F4"),Artifact!$K$2:$K$385))} | E8: =MAX(C8:D8) | F8: =COUNTIFS(Log!$A$2:$A$49,$A8,Log!$H$2:$H$49,"Red")+COUNTIFS(Log!$A$2:$A$49,$A8,Log!$I$2:$I$49,"Red") | G8: =IF(OR(E8>25,F8>0),"Exclude","Keep") | H8: =IF(OR(E8>15,F8>0),"Exclude","Keep")
A9: P05 | B9: =INDEX(Data!$M$2:$M$313,MATCH($A9,Data!$B$2:$B$313,0)) | C9: {=MAX(IF((Artifact!$B$2:$B$385=$A9)*(Artifact!$F$2:$F$385="F3"),Artifact!$K$2:$K$385))} | D9: {=MAX(IF((Artifact!$B$2:$B$385=$A9)*(Artifact!$F$2:$F$385="F4"),Artifact!$K$2:$K$385))} | E9: =MAX(C9:D9) | F9: =COUNTIFS(Log!$A$2:$A$49,$A9,Log!$H$2:$H$49,"Red")+COUNTIFS(Log!$A$2:$A$49,$A9,Log!$I$2:$I$49,"Red") | G9: =IF(OR(E9>25,F9>0),"Exclude","Keep") | H9: =IF(OR(E9>15,F9>0),"Exclude","Keep")
A10: P06 | B10: =INDEX(Data!$M$2:$M$313,MATCH($A10,Data!$B$2:$B$313,0)) | C10: {=MAX(IF((Artifact!$B$2:$B$385=$A10)*(Artifact!$F$2:$F$385="F3"),Artifact!$K$2:$K$385))} | D10: {=MAX(IF((Artifact!$B$2:$B$385=$A10)*(Artifact!$F$2:$F$385="F4"),Artifact!$K$2:$K$385))} | E10: =MAX(C10:D10) | F10: =COUNTIFS(Log!$A$2:$A$49,$A10,Log!$H$2:$H$49,"Red")+COUNTIFS(Log!$A$2:$A$49,$A10,Log!$I$2:$I$49,"Red") | G10: =IF(OR(E10>25,F10>0),"Exclude","Keep") | H10: =IF(OR(E10>15,F10>0),"Exclude","Keep")
A11: P07 | B11: =INDEX(Data!$M$2:$M$313,MATCH($A11,Data!$B$2:$B$313,0)) | C11: {=MAX(IF((Artifact!$B$2:$B$385=$A11)*(Artifact!$F$2:$F$385="F3"),Artifact!$K$2:$K$385))} | D11: {=MAX(IF((Artifact!$B$2:$B$385=$A11)*(Artifact!$F$2:$F$385="F4"),Artifact!$K$2:$K$385))} | E11: =MAX(C11:D11) | F11: =COUNTIFS(Log!$A$2:$A$49,$A11,Log!$H$2:$H$49,"Red")+COUNTIFS(Log!$A$2:$A$49,$A11,Log!$I$2:$I$49,"Red") | G11: =IF(OR(E11>25,F11>0),"Exclude","Keep") | H11: =IF(OR(E11>15,F11>0),"Exclude","Keep")
A12: P08 | B12: =INDEX(Data!$M$2:$M$313,MATCH($A12,Data!$B$2:$B$313,0)) | C12: {=MAX(IF((Artifact!$B$2:$B$385=$A12)*(Artifact!$F$2:$F$385="F3"),Artifact!$K$2:$K$385))} | D12: {=MAX(IF((Artifact!$B$2:$B$385=$A12)*(Artifact!$F$2:$F$385="F4"),Artifact!$K$2:$K$385))} | E12: =MAX(C12:D12) | F12: =COUNTIFS(Log!$A$2:$A$49,$A12,Log!$H$2:$H$49,"Red")+COUNTIFS(Log!$A$2:$A$49,$A12,Log!$I$2:$I$49,"Red") | G12: =IF(OR(E12>25,F12>0),"Exclude","Keep") | H12: =IF(OR(E12>15,F12>0),"Exclude","Keep")
A13: P09 | B13: =INDEX(Data!$M$2:$M$313,MATCH($A13,Data!$B$2:$B$313,0)) | C13: {=MAX(IF((Artifact!$B$2:$B$385=$A13)*(Artifact!$F$2:$F$385="F3"),Artifact!$K$2:$K$385))} | D13: {=MAX(IF((Artifact!$B$2:$B$385=$A13)*(Artifact!$F$2:$F$385="F4"),Artifact!$K$2:$K$385))} | E13: =MAX(C13:D13) | F13: =COUNTIFS(Log!$A$2:$A$49,$A13,Log!$H$2:$H$49,"Red")+COUNTIFS(Log!$A$2:$A$49,$A13,Log!$I$2:$I$49,"Red") | G13: =IF(OR(E13>25,F13>0),"Exclude","Keep") | H13: =IF(OR(E13>15,F13>0),"Exclude","Keep")
A14: P10 | B14: =INDEX(Data!$M$2:$M$313,MATCH($A14,Data!$B$2:$B$313,0)) | C14: {=MAX(IF((Artifact!$B$2:$B$385=$A14)*(Artifact!$F$2:$F$385="F3"),Artifact!$K$2:$K$385))} | D14: {=MAX(IF((Artifact!$B$2:$B$385=$A14)*(Artifact!$F$2:$F$385="F4"),Artifact!$K$2:$K$385))} | E14: =MAX(C14:D14) | F14: =COUNTIFS(Log!$A$2:$A$49,$A14,Log!$H$2:$H$49,"Red")+COUNTIFS(Log!$A$2:$A$49,$A14,Log!$I$2:$I$49,"Red") | G14: =IF(OR(E14>25,F14>0),"Exclude","Keep") | H14: =IF(OR(E14>15,F14>0),"Exclude","Keep")
A15: P11 | B15: =INDEX(Data!$M$2:$M$313,MATCH($A15,Data!$B$2:$B$313,0)) | C15: {=MAX(IF((Artifact!$B$2:$B$385=$A15)*(Artifact!$F$2:$F$385="F3"),Artifact!$K$2:$K$385))} | D15: {=MAX(IF((Artifact!$B$2:$B$385=$A15)*(Artifact!$F$2:$F$385="F4"),Artifact!$K$2:$K$385))} | E15: =MAX(C15:D15) | F15: =COUNTIFS(Log!$A$2:$A$49,$A15,Log!$H$2:$H$49,"Red")+COUNTIFS(Log!$A$2:$A$49,$A15,Log!$I$2:$I$49,"Red") | G15: =IF(OR(E15>25,F15>0),"Exclude","Keep") | H15: =IF(OR(E15>15,F15>0),"Exclude","Keep")
A16: P12 | B16: =INDEX(Data!$M$2:$M$313,MATCH($A16,Data!$B$2:$B$313,0)) | C16: {=MAX(IF((Artifact!$B$2:$B$385=$A16)*(Artifact!$F$2:$F$385="F3"),Artifact!$K$2:$K$385))} | D16: {=MAX(IF((Artifact!$B$2:$B$385=$A16)*(Artifact!$F$2:$F$385="F4"),Artifact!$K$2:$K$385))} | E16: =MAX(C16:D16) | F16: =COUNTIFS(Log!$A$2:$A$49,$A16,Log!$H$2:$H$49,"Red")+COUNTIFS(Log!$A$2:$A$49,$A16,Log!$I$2:$I$49,"Red") | G16: =IF(OR(E16>25,F16>0),"Exclude","Keep") | H16: =IF(OR(E16>15,F16>0),"Exclude","Keep")
... A52: P48 | B52: =INDEX(Data!$M$2:$M$313,MATCH($A52,Data!$B$2:$B$313,0)) | C52: {=MAX(IF((Artifact!$B$2:$B$385=$A52)*(Artifact!$F$2:$F$385="F3"),Artifact!$K$2:$K$385))} | D52: {=MAX(IF((Artifact!$B$2:$B$385=$A52)*(Artifact!$F$2:$F$385="F4"),Artifact!$K$2:$K$385))} | E52: =MAX(C52:D52) | F52: =COUNTIFS(Log!$A$2:$A$49,$A52,Log!$H$2:$H$49,"Red")+COUNTIFS(Log!$A$2:$A$49,$A52,Log!$I$2:$I$49,"Red") | G52: =IF(OR(E52>25,F52>0),"Exclude","Keep") | H52: =IF(OR(E52>15,F52>0),"Exclude","Keep")
A54: Respondents excluded (25 percent rule) | E54: =COUNTIF(G5:G52,"Exclude")
A55: Respondents excluded (15 percent rule) | E55: =COUNTIF(H5:H52,"Exclude")
A56: Kept, Version A (25 percent rule) | E56: =COUNTIFS(B5:B52,"A",G5:G52,"Keep")
A57: Kept, Version B (25 percent rule) | E57: =COUNTIFS(B5:B52,"B",G5:G52,"Keep")
A58: Kept, Version A (15 percent rule) | E58: =COUNTIFS(B5:B52,"A",H5:H52,"Keep")
A59: Kept, Version B (15 percent rule) | E59: =COUNTIFS(B5:B52,"B",H5:H52,"Keep")
A60: Artifact report rows with a stream gap (recorded < expected) | E60: =COUNTIF(Artifact!$M$2:$M$385,">0")

Sheet Summary
A1: Raw FA by segment and version, kept respondents (Keep = Yes). SIMULATED data.
A2: Role names the part of the design (C1 = Commercial_1A or Commercial_1B; EndScene_C1 = the EndScene annotation whose Parent Stimulus is Commercial_1A or Commercial_1B). Version * = both versions. Columns D and E use AVERAGEIFS and STDEV.S(IF(...)).
A4: Role | B4: Version | C4: n | D4: Mean FA | E4: SD FA
A5: Baseline_1 | B5: A | C5: =COUNTIFS(Data!$O$2:$O$313,$A5,Data!$M$2:$M$313,$B5,Data!$P$2:$P$313,"Yes") | D5: =AVERAGEIFS(Data!$K$2:$K$313,Data!$O$2:$O$313,$A5,Data!$M$2:$M$313,$B5,Data!$P$2:$P$313,"Yes") | E5: {=_xlfn.STDEV.S(IF((Data!$O$2:$O$313=$A5)*(Data!$M$2:$M$313=$B5)*(Data!$P$2:$P$313="Yes"),Data!$K$2:$K$313))}
A6: Baseline_1 | B6: B | C6: =COUNTIFS(Data!$O$2:$O$313,$A6,Data!$M$2:$M$313,$B6,Data!$P$2:$P$313,"Yes") | D6: =AVERAGEIFS(Data!$K$2:$K$313,Data!$O$2:$O$313,$A6,Data!$M$2:$M$313,$B6,Data!$P$2:$P$313,"Yes") | E6: {=_xlfn.STDEV.S(IF((Data!$O$2:$O$313=$A6)*(Data!$M$2:$M$313=$B6)*(Data!$P$2:$P$313="Yes"),Data!$K$2:$K$313))}
A7: Baseline_1 | B7: * | C7: =COUNTIFS(Data!$O$2:$O$313,$A7,Data!$M$2:$M$313,$B7,Data!$P$2:$P$313,"Yes") | D7: =AVERAGEIFS(Data!$K$2:$K$313,Data!$O$2:$O$313,$A7,Data!$M$2:$M$313,$B7,Data!$P$2:$P$313,"Yes") | E7: {=_xlfn.STDEV.S(IF((Data!$O$2:$O$313=$A7)*(Data!$P$2:$P$313="Yes"),Data!$K$2:$K$313))}
A8: Baseline_2 | B8: A | C8: =COUNTIFS(Data!$O$2:$O$313,$A8,Data!$M$2:$M$313,$B8,Data!$P$2:$P$313,"Yes") | D8: =AVERAGEIFS(Data!$K$2:$K$313,Data!$O$2:$O$313,$A8,Data!$M$2:$M$313,$B8,Data!$P$2:$P$313,"Yes") | E8: {=_xlfn.STDEV.S(IF((Data!$O$2:$O$313=$A8)*(Data!$M$2:$M$313=$B8)*(Data!$P$2:$P$313="Yes"),Data!$K$2:$K$313))}
A9: Baseline_2 | B9: B | C9: =COUNTIFS(Data!$O$2:$O$313,$A9,Data!$M$2:$M$313,$B9,Data!$P$2:$P$313,"Yes") | D9: =AVERAGEIFS(Data!$K$2:$K$313,Data!$O$2:$O$313,$A9,Data!$M$2:$M$313,$B9,Data!$P$2:$P$313,"Yes") | E9: {=_xlfn.STDEV.S(IF((Data!$O$2:$O$313=$A9)*(Data!$M$2:$M$313=$B9)*(Data!$P$2:$P$313="Yes"),Data!$K$2:$K$313))}
A10: Baseline_2 | B10: * | C10: =COUNTIFS(Data!$O$2:$O$313,$A10,Data!$M$2:$M$313,$B10,Data!$P$2:$P$313,"Yes") | D10: =AVERAGEIFS(Data!$K$2:$K$313,Data!$O$2:$O$313,$A10,Data!$M$2:$M$313,$B10,Data!$P$2:$P$313,"Yes") | E10: {=_xlfn.STDEV.S(IF((Data!$O$2:$O$313=$A10)*(Data!$P$2:$P$313="Yes"),Data!$K$2:$K$313))}
A11: C1 | B11: A | C11: =COUNTIFS(Data!$O$2:$O$313,$A11,Data!$M$2:$M$313,$B11,Data!$P$2:$P$313,"Yes") | D11: =AVERAGEIFS(Data!$K$2:$K$313,Data!$O$2:$O$313,$A11,Data!$M$2:$M$313,$B11,Data!$P$2:$P$313,"Yes") | E11: {=_xlfn.STDEV.S(IF((Data!$O$2:$O$313=$A11)*(Data!$M$2:$M$313=$B11)*(Data!$P$2:$P$313="Yes"),Data!$K$2:$K$313))}
A12: C1 | B12: B | C12: =COUNTIFS(Data!$O$2:$O$313,$A12,Data!$M$2:$M$313,$B12,Data!$P$2:$P$313,"Yes") | D12: =AVERAGEIFS(Data!$K$2:$K$313,Data!$O$2:$O$313,$A12,Data!$M$2:$M$313,$B12,Data!$P$2:$P$313,"Yes") | E12: {=_xlfn.STDEV.S(IF((Data!$O$2:$O$313=$A12)*(Data!$M$2:$M$313=$B12)*(Data!$P$2:$P$313="Yes"),Data!$K$2:$K$313))}
A13: C1 | B13: * | C13: =COUNTIFS(Data!$O$2:$O$313,$A13,Data!$M$2:$M$313,$B13,Data!$P$2:$P$313,"Yes") | D13: =AVERAGEIFS(Data!$K$2:$K$313,Data!$O$2:$O$313,$A13,Data!$M$2:$M$313,$B13,Data!$P$2:$P$313,"Yes") | E13: {=_xlfn.STDEV.S(IF((Data!$O$2:$O$313=$A13)*(Data!$P$2:$P$313="Yes"),Data!$K$2:$K$313))}
A14: C2 | B14: A | C14: =COUNTIFS(Data!$O$2:$O$313,$A14,Data!$M$2:$M$313,$B14,Data!$P$2:$P$313,"Yes") | D14: =AVERAGEIFS(Data!$K$2:$K$313,Data!$O$2:$O$313,$A14,Data!$M$2:$M$313,$B14,Data!$P$2:$P$313,"Yes") | E14: {=_xlfn.STDEV.S(IF((Data!$O$2:$O$313=$A14)*(Data!$M$2:$M$313=$B14)*(Data!$P$2:$P$313="Yes"),Data!$K$2:$K$313))}
A15: C2 | B15: B | C15: =COUNTIFS(Data!$O$2:$O$313,$A15,Data!$M$2:$M$313,$B15,Data!$P$2:$P$313,"Yes") | D15: =AVERAGEIFS(Data!$K$2:$K$313,Data!$O$2:$O$313,$A15,Data!$M$2:$M$313,$B15,Data!$P$2:$P$313,"Yes") | E15: {=_xlfn.STDEV.S(IF((Data!$O$2:$O$313=$A15)*(Data!$M$2:$M$313=$B15)*(Data!$P$2:$P$313="Yes"),Data!$K$2:$K$313))}
A16: C2 | B16: * | C16: =COUNTIFS(Data!$O$2:$O$313,$A16,Data!$M$2:$M$313,$B16,Data!$P$2:$P$313,"Yes") | D16: =AVERAGEIFS(Data!$K$2:$K$313,Data!$O$2:$O$313,$A16,Data!$M$2:$M$313,$B16,Data!$P$2:$P$313,"Yes") | E16: {=_xlfn.STDEV.S(IF((Data!$O$2:$O$313=$A16)*(Data!$P$2:$P$313="Yes"),Data!$K$2:$K$313))}
A17: KeyScene | B17: A | C17: =COUNTIFS(Data!$O$2:$O$313,$A17,Data!$M$2:$M$313,$B17,Data!$P$2:$P$313,"Yes") | D17: =AVERAGEIFS(Data!$K$2:$K$313,Data!$O$2:$O$313,$A17,Data!$M$2:$M$313,$B17,Data!$P$2:$P$313,"Yes") | E17: {=_xlfn.STDEV.S(IF((Data!$O$2:$O$313=$A17)*(Data!$M$2:$M$313=$B17)*(Data!$P$2:$P$313="Yes"),Data!$K$2:$K$313))}
A18: EndScene_C1 | B18: A | C18: =COUNTIFS(Data!$O$2:$O$313,$A18,Data!$M$2:$M$313,$B18,Data!$P$2:$P$313,"Yes") | D18: =AVERAGEIFS(Data!$K$2:$K$313,Data!$O$2:$O$313,$A18,Data!$M$2:$M$313,$B18,Data!$P$2:$P$313,"Yes") | E18: {=_xlfn.STDEV.S(IF((Data!$O$2:$O$313=$A18)*(Data!$M$2:$M$313=$B18)*(Data!$P$2:$P$313="Yes"),Data!$K$2:$K$313))}
A19: EndScene_C1 | B19: B | C19: =COUNTIFS(Data!$O$2:$O$313,$A19,Data!$M$2:$M$313,$B19,Data!$P$2:$P$313,"Yes") | D19: =AVERAGEIFS(Data!$K$2:$K$313,Data!$O$2:$O$313,$A19,Data!$M$2:$M$313,$B19,Data!$P$2:$P$313,"Yes") | E19: {=_xlfn.STDEV.S(IF((Data!$O$2:$O$313=$A19)*(Data!$M$2:$M$313=$B19)*(Data!$P$2:$P$313="Yes"),Data!$K$2:$K$313))}
A20: EndScene_C1 | B20: * | C20: =COUNTIFS(Data!$O$2:$O$313,$A20,Data!$M$2:$M$313,$B20,Data!$P$2:$P$313,"Yes") | D20: =AVERAGEIFS(Data!$K$2:$K$313,Data!$O$2:$O$313,$A20,Data!$M$2:$M$313,$B20,Data!$P$2:$P$313,"Yes") | E20: {=_xlfn.STDEV.S(IF((Data!$O$2:$O$313=$A20)*(Data!$P$2:$P$313="Yes"),Data!$K$2:$K$313))}
A21: EndScene_C2 | B21: A | C21: =COUNTIFS(Data!$O$2:$O$313,$A21,Data!$M$2:$M$313,$B21,Data!$P$2:$P$313,"Yes") | D21: =AVERAGEIFS(Data!$K$2:$K$313,Data!$O$2:$O$313,$A21,Data!$M$2:$M$313,$B21,Data!$P$2:$P$313,"Yes") | E21: {=_xlfn.STDEV.S(IF((Data!$O$2:$O$313=$A21)*(Data!$M$2:$M$313=$B21)*(Data!$P$2:$P$313="Yes"),Data!$K$2:$K$313))}
A22: EndScene_C2 | B22: B | C22: =COUNTIFS(Data!$O$2:$O$313,$A22,Data!$M$2:$M$313,$B22,Data!$P$2:$P$313,"Yes") | D22: =AVERAGEIFS(Data!$K$2:$K$313,Data!$O$2:$O$313,$A22,Data!$M$2:$M$313,$B22,Data!$P$2:$P$313,"Yes") | E22: {=_xlfn.STDEV.S(IF((Data!$O$2:$O$313=$A22)*(Data!$M$2:$M$313=$B22)*(Data!$P$2:$P$313="Yes"),Data!$K$2:$K$313))}
A23: EndScene_C2 | B23: * | C23: =COUNTIFS(Data!$O$2:$O$313,$A23,Data!$M$2:$M$313,$B23,Data!$P$2:$P$313,"Yes") | D23: =AVERAGEIFS(Data!$K$2:$K$313,Data!$O$2:$O$313,$A23,Data!$M$2:$M$313,$B23,Data!$P$2:$P$313,"Yes") | E23: {=_xlfn.STDEV.S(IF((Data!$O$2:$O$313=$A23)*(Data!$P$2:$P$313="Yes"),Data!$K$2:$K$313))}
A25: Array formulas (column E): Excel 365 evaluates them with Enter; Excel 2019 or older needs Ctrl+Shift+Enter after editing. The text NA in the FA column (a segment with no clean window) is ignored by AVERAGEIFS and COUNTIFS counts the row; no kept respondent has an NA.

Sheet H1
A1: H1. FA during the KeyScene minus FA during the baseline before Commercial_1A, Version A, kept respondents. SIMULATED data.
A2: One row per kept Version A respondent; rows 5 to 24 are also kept under the 15 percent rule, rows 25 to 26 are dropped by it. Column D picks Baseline_1 or Baseline_2, whichever came right before Commercial_1A. Columns G to I repeat the computation on the Default sheet (notebook default channels Ch1 and Ch7).
A4: Respondent Name | B4: Order | C4: Keep15 | D4: Baseline before Commercial_1A (FA) | E4: KeyScene (FA) | F4: Change (KeyScene minus baseline) | G4: DEFAULT channels: baseline | H4: DEFAULT channels: KeyScene | I4: DEFAULT channels: change | K4: Statistic | L4: Value | M4: Formula shown | N4: Note
A5: P02 | B5: =INDEX(Data!$N$2:$N$313,MATCH($A5,Data!$B$2:$B$313,0)) | C5: =INDEX(Data!$Q$2:$Q$313,MATCH($A5,Data!$B$2:$B$313,0)) | D5: =IF($B5="C1first",SUMIFS(Data!$K$2:$K$313,Data!$B$2:$B$313,$A5,Data!$O$2:$O$313,"Baseline_1"),SUMIFS(Data!$K$2:$K$313,Data!$B$2:$B$313,$A5,Data!$O$2:$O$313,"Baseline_2")) | E5: =SUMIFS(Data!$K$2:$K$313,Data!$B$2:$B$313,$A5,Data!$O$2:$O$313,"KeyScene") | F5: =E5-D5 | G5: =IF($B5="C1first",SUMIFS(Default!$K$2:$K$313,Default!$B$2:$B$313,$A5,Default!$O$2:$O$313,"Baseline_1"),SUMIFS(Default!$K$2:$K$313,Default!$B$2:$B$313,$A5,Default!$O$2:$O$313,"Baseline_2")) | H5: =SUMIFS(Default!$K$2:$K$313,Default!$B$2:$B$313,$A5,Default!$O$2:$O$313,"KeyScene") | I5: =H5-G5 | K5: H1: one sample t on the change (= paired t), Version A, n = 22
A6: P05 | B6: =INDEX(Data!$N$2:$N$313,MATCH($A6,Data!$B$2:$B$313,0)) | C6: =INDEX(Data!$Q$2:$Q$313,MATCH($A6,Data!$B$2:$B$313,0)) | D6: =IF($B6="C1first",SUMIFS(Data!$K$2:$K$313,Data!$B$2:$B$313,$A6,Data!$O$2:$O$313,"Baseline_1"),SUMIFS(Data!$K$2:$K$313,Data!$B$2:$B$313,$A6,Data!$O$2:$O$313,"Baseline_2")) | E6: =SUMIFS(Data!$K$2:$K$313,Data!$B$2:$B$313,$A6,Data!$O$2:$O$313,"KeyScene") | F6: =E6-D6 | G6: =IF($B6="C1first",SUMIFS(Default!$K$2:$K$313,Default!$B$2:$B$313,$A6,Default!$O$2:$O$313,"Baseline_1"),SUMIFS(Default!$K$2:$K$313,Default!$B$2:$B$313,$A6,Default!$O$2:$O$313,"Baseline_2")) | H6: =SUMIFS(Default!$K$2:$K$313,Default!$B$2:$B$313,$A6,Default!$O$2:$O$313,"KeyScene") | I6: =H6-G6 | K6: Baseline mean (FA) | L6: =AVERAGE(D5:D26) | M6: =AVERAGE(D5:D26) | N6: AVERAGE of the reference column
A7: P08 | B7: =INDEX(Data!$N$2:$N$313,MATCH($A7,Data!$B$2:$B$313,0)) | C7: =INDEX(Data!$Q$2:$Q$313,MATCH($A7,Data!$B$2:$B$313,0)) | D7: =IF($B7="C1first",SUMIFS(Data!$K$2:$K$313,Data!$B$2:$B$313,$A7,Data!$O$2:$O$313,"Baseline_1"),SUMIFS(Data!$K$2:$K$313,Data!$B$2:$B$313,$A7,Data!$O$2:$O$313,"Baseline_2")) | E7: =SUMIFS(Data!$K$2:$K$313,Data!$B$2:$B$313,$A7,Data!$O$2:$O$313,"KeyScene") | F7: =E7-D7 | G7: =IF($B7="C1first",SUMIFS(Default!$K$2:$K$313,Default!$B$2:$B$313,$A7,Default!$O$2:$O$313,"Baseline_1"),SUMIFS(Default!$K$2:$K$313,Default!$B$2:$B$313,$A7,Default!$O$2:$O$313,"Baseline_2")) | H7: =SUMIFS(Default!$K$2:$K$313,Default!$B$2:$B$313,$A7,Default!$O$2:$O$313,"KeyScene") | I7: =H7-G7 | K7: Baseline SD | L7: =_xlfn.STDEV.S(D5:D26) | M7: =STDEV.S(D5:D26) | N7: STDEV.S = sample standard deviation
A8: P09 | B8: =INDEX(Data!$N$2:$N$313,MATCH($A8,Data!$B$2:$B$313,0)) | C8: =INDEX(Data!$Q$2:$Q$313,MATCH($A8,Data!$B$2:$B$313,0)) | D8: =IF($B8="C1first",SUMIFS(Data!$K$2:$K$313,Data!$B$2:$B$313,$A8,Data!$O$2:$O$313,"Baseline_1"),SUMIFS(Data!$K$2:$K$313,Data!$B$2:$B$313,$A8,Data!$O$2:$O$313,"Baseline_2")) | E8: =SUMIFS(Data!$K$2:$K$313,Data!$B$2:$B$313,$A8,Data!$O$2:$O$313,"KeyScene") | F8: =E8-D8 | G8: =IF($B8="C1first",SUMIFS(Default!$K$2:$K$313,Default!$B$2:$B$313,$A8,Default!$O$2:$O$313,"Baseline_1"),SUMIFS(Default!$K$2:$K$313,Default!$B$2:$B$313,$A8,Default!$O$2:$O$313,"Baseline_2")) | H8: =SUMIFS(Default!$K$2:$K$313,Default!$B$2:$B$313,$A8,Default!$O$2:$O$313,"KeyScene") | I8: =H8-G8 | K8: KeyScene mean (FA) | L8: =AVERAGE(E5:E26) | M8: =AVERAGE(E5:E26)
A9: P11 | B9: =INDEX(Data!$N$2:$N$313,MATCH($A9,Data!$B$2:$B$313,0)) | C9: =INDEX(Data!$Q$2:$Q$313,MATCH($A9,Data!$B$2:$B$313,0)) | D9: =IF($B9="C1first",SUMIFS(Data!$K$2:$K$313,Data!$B$2:$B$313,$A9,Data!$O$2:$O$313,"Baseline_1"),SUMIFS(Data!$K$2:$K$313,Data!$B$2:$B$313,$A9,Data!$O$2:$O$313,"Baseline_2")) | E9: =SUMIFS(Data!$K$2:$K$313,Data!$B$2:$B$313,$A9,Data!$O$2:$O$313,"KeyScene") | F9: =E9-D9 | G9: =IF($B9="C1first",SUMIFS(Default!$K$2:$K$313,Default!$B$2:$B$313,$A9,Default!$O$2:$O$313,"Baseline_1"),SUMIFS(Default!$K$2:$K$313,Default!$B$2:$B$313,$A9,Default!$O$2:$O$313,"Baseline_2")) | H9: =SUMIFS(Default!$K$2:$K$313,Default!$B$2:$B$313,$A9,Default!$O$2:$O$313,"KeyScene") | I9: =H9-G9 | K9: KeyScene SD | L9: =_xlfn.STDEV.S(E5:E26) | M9: =STDEV.S(E5:E26)
A10: P13 | B10: =INDEX(Data!$N$2:$N$313,MATCH($A10,Data!$B$2:$B$313,0)) | C10: =INDEX(Data!$Q$2:$Q$313,MATCH($A10,Data!$B$2:$B$313,0)) | D10: =IF($B10="C1first",SUMIFS(Data!$K$2:$K$313,Data!$B$2:$B$313,$A10,Data!$O$2:$O$313,"Baseline_1"),SUMIFS(Data!$K$2:$K$313,Data!$B$2:$B$313,$A10,Data!$O$2:$O$313,"Baseline_2")) | E10: =SUMIFS(Data!$K$2:$K$313,Data!$B$2:$B$313,$A10,Data!$O$2:$O$313,"KeyScene") | F10: =E10-D10 | G10: =IF($B10="C1first",SUMIFS(Default!$K$2:$K$313,Default!$B$2:$B$313,$A10,Default!$O$2:$O$313,"Baseline_1"),SUMIFS(Default!$K$2:$K$313,Default!$B$2:$B$313,$A10,Default!$O$2:$O$313,"Baseline_2")) | H10: =SUMIFS(Default!$K$2:$K$313,Default!$B$2:$B$313,$A10,Default!$O$2:$O$313,"KeyScene") | I10: =H10-G10 | K10: n (respondents) | L10: =COUNT(F5:F26) | M10: =COUNT(F5:F26) | N10: COUNT of the change column; must equal the check below
A11: P14 | B11: =INDEX(Data!$N$2:$N$313,MATCH($A11,Data!$B$2:$B$313,0)) | C11: =INDEX(Data!$Q$2:$Q$313,MATCH($A11,Data!$B$2:$B$313,0)) | D11: =IF($B11="C1first",SUMIFS(Data!$K$2:$K$313,Data!$B$2:$B$313,$A11,Data!$O$2:$O$313,"Baseline_1"),SUMIFS(Data!$K$2:$K$313,Data!$B$2:$B$313,$A11,Data!$O$2:$O$313,"Baseline_2")) | E11: =SUMIFS(Data!$K$2:$K$313,Data!$B$2:$B$313,$A11,Data!$O$2:$O$313,"KeyScene") | F11: =E11-D11 | G11: =IF($B11="C1first",SUMIFS(Default!$K$2:$K$313,Default!$B$2:$B$313,$A11,Default!$O$2:$O$313,"Baseline_1"),SUMIFS(Default!$K$2:$K$313,Default!$B$2:$B$313,$A11,Default!$O$2:$O$313,"Baseline_2")) | H11: =SUMIFS(Default!$K$2:$K$313,Default!$B$2:$B$313,$A11,Default!$O$2:$O$313,"KeyScene") | I11: =H11-G11 | K11: Mean change, KeyScene minus Baseline | L11: =AVERAGE(F5:F26) | M11: =AVERAGE(F5:F26)
A12: P20 | B12: =INDEX(Data!$N$2:$N$313,MATCH($A12,Data!$B$2:$B$313,0)) | C12: =INDEX(Data!$Q$2:$Q$313,MATCH($A12,Data!$B$2:$B$313,0)) | D12: =IF($B12="C1first",SUMIFS(Data!$K$2:$K$313,Data!$B$2:$B$313,$A12,Data!$O$2:$O$313,"Baseline_1"),SUMIFS(Data!$K$2:$K$313,Data!$B$2:$B$313,$A12,Data!$O$2:$O$313,"Baseline_2")) | E12: =SUMIFS(Data!$K$2:$K$313,Data!$B$2:$B$313,$A12,Data!$O$2:$O$313,"KeyScene") | F12: =E12-D12 | G12: =IF($B12="C1first",SUMIFS(Default!$K$2:$K$313,Default!$B$2:$B$313,$A12,Default!$O$2:$O$313,"Baseline_1"),SUMIFS(Default!$K$2:$K$313,Default!$B$2:$B$313,$A12,Default!$O$2:$O$313,"Baseline_2")) | H12: =SUMIFS(Default!$K$2:$K$313,Default!$B$2:$B$313,$A12,Default!$O$2:$O$313,"KeyScene") | I12: =H12-G12 | K12: SD of the changes | L12: =_xlfn.STDEV.S(F5:F26) | M12: =STDEV.S(F5:F26) | N12: the SD that matters in a paired design
