Workbook

Sheet README
A1: SIMULATED ANALYSIS REPORT WORKBOOK (Workshop 8)
A2: SIMULATED DATA for teaching (seed 20271231). No real person was recorded; ALTAVO and BRENLOW are invented brands. Built by make_excel_workbook.py from analysis_ready_long.csv (Workshop 7) and checked against analysis_full.R (Workshop 8).
A3: Study: SIMULATED Multimodal Ad Study. 24 participants (P01 to P24), analysis sample 22 (include = 1). Baseline (60 s), Ad_A (ALTAVO) and Ad_B (BRENLOW), 30 s each, counterbalanced; AOIs Logo, Product, Headline; AFFDEX; Shimmer GSR; survey.
A4: This workbook is the Excel route through the descriptive statistics, the Q5 paired tests, and the Holm correction of analysis_full.R.
A6: Sheets
A7: Data analysis_ready_long.csv as the Text Import leaves it (header in row 1, 72 rows), plus the key column AD (orange)
A8: AOI_long one row per participant, ad, and AOI (144 rows): the dwell values stacked into ONE column with INDEX and MATCH
A9: Descriptives n, mean, SD, median, quartiles, IQR, and percent at zero by ad and AOI (and by stimulus for FEA, GSR, liking)
A10: Pivot the summary a PivotTable gives (Average of dwell by AOI and ad), built with AVERAGEIFS and COUNTIFS so that it can be checked
A11: Q5 Joy, Engagement, and Brow Furrow, Ad_A versus Ad_B: paired T.TEST, d_z, and its approximate 95% CI
A12: Holm the Holm correction of the three Q5 p values, step by step, next to the Bonferroni correction
A13: Check every Excel result next to the value R produced, with OK or CHECK
... A17: The walkthrough excel_walkthrough.md explains every formula with its cell address.

Sheet Data
A1: participant_id | B1: stimulus | C1: ad_position | D1: order | E1: gender | F1: age | G1: include | H1: exclusion_reason | I1: et_quality_pct | J1: face_quality_pct | K1: gsr_quality_pct | L1: gsr_signal_pct | M1: gsr_valid | N1: gsr_peaks_per_min | O1: gsr_peak_count | P1: gsr_avg_amp_us | Q1: joy_pct | R1: engagement_pct | S1: browfurrow_pct | T1: logo_fixated | U1: logo_ttff_ms | V1: logo_fix_count | W1: logo_revisits | X1: logo_gaze_dwell_ms | Y1: logo_gaze_dwell_pct | Z1: product_gaze_dwell_pct | AA1: headline_gaze_dwell_pct | AB1: liking | AC1: recall_correct | AD1: key = participant|stimulus
A2: P01 | B2: Baseline | C2: NA | D2: AB | E2: Male | F2: 20 | G2: 1 | I2: 92 | J2: 93 | K2: 100 | L2: 100 | M2: 1 | N2: 1 | O2: 1 | P2: 0.0698 | Q2: 0 | R2: 0 | S2: 0 | T2: NA | U2: NA | V2: NA | W2: NA | X2: NA | Y2: NA | Z2: NA | AA2: NA | AB2: NA | AC2: NA | AD2: =A2&"|"&B2
A3: P01 | B3: Ad_A | C3: 1 | D3: AB | E3: Male | F3: 20 | G3: 1 | I3: 95 | J3: 93 | K3: 100 | L3: 100 | M3: 1 | N3: 6 | O3: 3 | P3: 0.2082 | Q3: 0 | R3: 0 | S3: 0 | T3: 0 | U3: NA | V3: 0 | W3: 0 | X3: 0 | Y3: 0 | Z3: 41.33 | AA3: 9.22 | AB3: 4 | AC3: 0 | AD3: =A3&"|"&B3
A4: P01 | B4: Ad_B | C4: 2 | D4: AB | E4: Male | F4: 20 | G4: 1 | I4: 95 | J4: 91 | K4: 100 | L4: 100 | M4: 1 | N4: 6 | O4: 3 | P4: 0.1469 | Q4: 0 | R4: 0 | S4: 0 | T4: 1 | U4: 21102 | V4: 1 | W4: 0 | X4: 217 | Y4: 0.72 | Z4: 43.83 | AA4: 7.44 | AB4: 5 | AC4: 1 | AD4: =A4&"|"&B4
A5: P02 | B5: Baseline | C5: NA | D5: BA | E5: Female | F5: 21 | G5: 1 | I5: 96 | J5: 99 | K5: 100 | L5: 100 | M5: 1 | N5: 0 | O5: 0 | P5: NA | Q5: 1.83 | R5: 4.83 | S5: 0 | T5: NA | U5: NA | V5: NA | W5: NA | X5: NA | Y5: NA | Z5: NA | AA5: NA | AB5: NA | AC5: NA | AD5: =A5&"|"&B5
A6: P02 | B6: Ad_A | C6: 2 | D6: BA | E6: Female | F6: 21 | G6: 1 | I6: 94 | J6: 97 | K6: 100 | L6: 100 | M6: 1 | N6: 4 | O6: 2 | P6: 0.1116 | Q6: 3.44 | R6: 3.44 | S6: 0 | T6: 0 | U6: NA | V6: 0 | W6: 0 | X6: 0 | Y6: 0 | Z6: 40.44 | AA6: 30.39 | AB6: 5 | AC6: 0 | AD6: =A6&"|"&B6
A7: P02 | B7: Ad_B | C7: 1 | D7: BA | E7: Female | F7: 21 | G7: 1 | I7: 94 | J7: 98 | K7: 99 | L7: 100 | M7: 1 | N7: 0 | O7: 0 | P7: NA | Q7: 13.22 | R7: 13.56 | S7: 0 | T7: 1 | U7: 14270 | V7: 3 | W7: 0 | X7: 733 | Y7: 2.44 | Z7: 48.78 | AA7: 18.61 | AB7: 6 | AC7: 0 | AD7: =A7&"|"&B7
A8: P03 | B8: Baseline | C8: NA | D8: AB | E8: Male | F8: 21 | G8: 1 | I8: 96 | J8: 98 | K8: 100 | L8: 100 | M8: 1 | N8: 2 | O8: 2 | P8: 0.0599 | Q8: 0 | R8: 3.06 | S8: 0 | T8: NA | U8: NA | V8: NA | W8: NA | X8: NA | Y8: NA | Z8: NA | AA8: NA | AB8: NA | AC8: NA | AD8: =A8&"|"&B8
A9: P03 | B9: Ad_A | C9: 1 | D9: AB | E9: Male | F9: 21 | G9: 1 | I9: 96 | J9: 97 | K9: 100 | L9: 100 | M9: 1 | N9: 22 | O9: 11 | P9: 0.158 | Q9: 26.44 | R9: 27 | S9: 0 | T9: 1 | U9: 24871 | V9: 4 | W9: 0 | X9: 1450 | Y9: 4.83 | Z9: 53.33 | AA9: 8 | AB9: 5 | AC9: 1 | AD9: =A9&"|"&B9
A10: P03 | B10: Ad_B | C10: 2 | D10: AB | E10: Male | F10: 21 | G10: 1 | I10: 95 | J10: 98 | K10: 100 | L10: 100 | M10: 1 | N10: 16 | O10: 8 | P10: 0.1617 | Q10: 3.44 | R10: 3.89 | S10: 0 | T10: 0 | U10: NA | V10: 0 | W10: 0 | X10: 0 | Y10: 0 | Z10: 33.06 | AA10: 16.89 | AB10: 6 | AC10: 0 | AD10: =A10&"|"&B10
A11: P04 | B11: Baseline | C11: NA | D11: BA | E11: Female | F11: 22 | G11: 1 | I11: 95 | J11: 90 | K11: 100 | L11: 100 | M11: 1 | N11: 5 | O11: 5 | P11: 0.17 | Q11: 0 | R11: 1.11 | S11: 0.78 | T11: NA | U11: NA | V11: NA | W11: NA | X11: NA | Y11: NA | Z11: NA | AA11: NA | AB11: NA | AC11: NA | AD11: =A11&"|"&B11
A12: P04 | B12: Ad_A | C12: 2 | D12: BA | E12: Female | F12: 22 | G12: 1 | I12: 94 | J12: 90 | K12: 100 | L12: 100 | M12: 1 | N12: 0 | O12: 0 | P12: NA | Q12: 17.22 | R12: 17.33 | S12: 0 | T12: 0 | U12: NA | V12: 0 | W12: 0 | X12: 0 | Y12: 0 | Z12: 48.39 | AA12: 14.06 | AB12: 6 | AC12: 1 | AD12: =A12&"|"&B12
A13: P04 | B13: Ad_B | C13: 1 | D13: BA | E13: Female | F13: 22 | G13: 1 | I13: 94 | J13: 90 | K13: 99 | L13: 100 | M13: 1 | N13: 8 | O13: 4 | P13: 0.2299 | Q13: 0 | R13: 6.33 | S13: 0 | T13: 1 | U13: 19900 | V13: 2 | W13: 1 | X13: 317 | Y13: 1.06 | Z13: 45.61 | AA13: 22.17 | AB13: 4 | AC13: 1 | AD13: =A13&"|"&B13
A14: P05 | B14: Baseline | C14: NA | D14: AB | E14: Female | F14: 20 | G14: 1 | I14: 94 | J14: 96 | K14: 100 | L14: 100 | M14: 1 | N14: 6 | O14: 6 | P14: 0.3076 | Q14: 0 | R14: 0 | S14: 0 | T14: NA | U14: NA | V14: NA | W14: NA | X14: NA | Y14: NA | Z14: NA | AA14: NA | AB14: NA | AC14: NA | AD14: =A14&"|"&B14
A15: P05 | B15: Ad_A | C15: 1 | D15: AB | E15: Female | F15: 20 | G15: 1 | I15: 94 | J15: 95 | K15: 100 | L15: 100 | M15: 1 | N15: 12 | O15: 6 | P15: 0.082 | Q15: 9.11 | R15: 9.78 | S15: 0 | T15: 1 | U15: 9729 | V15: 3 | W15: 1 | X15: 1183 | Y15: 3.94 | Z15: 28.83 | AA15: 20.22 | AB15: 5 | AC15: 0 | AD15: =A15&"|"&B15
A16: P05 | B16: Ad_B | C16: 2 | D16: AB | E16: Female | F16: 20 | G16: 1 | I16: 94 | J16: 95 | K16: 26 | L16: 26.04 | M16: 0 | N16: NA | O16: NA | P16: NA | Q16: 21.67 | R16: 22.33 | S16: 0 | T16: 1 | U16: 19927 | V16: 2 | W16: 0 | X16: 550 | Y16: 1.83 | Z16: 41.89 | AA16: 23.83 | AB16: 3 | AC16: 1 | AD16: =A16&"|"&B16
A17: P06 | B17: Baseline | C17: NA | D17: BA | E17: Female | F17: 26 | G17: 1 | I17: 96 | J17: 98 | K17: 100 | L17: 100 | M17: 1 | N17: 1 | O17: 1 | P17: 0.0616 | Q17: 0 | R17: 4.22 | S17: 0 | T17: NA | U17: NA | V17: NA | W17: NA | X17: NA | Y17: NA | Z17: NA | AA17: NA | AB17: NA | AC17: NA | AD17: =A17&"|"&B17
A18: P06 | B18: Ad_A | C18: 2 | D18: BA | E18: Female | F18: 26 | G18: 1 | I18: 95 | J18: 96 | K18: 100 | L18: 100 | M18: 1 | N18: 4 | O18: 2 | P18: 0.091 | Q18: 10.22 | R18: 13.11 | S18: 0 | T18: 0 | U18: NA | V18: 0 | W18: 0 | X18: 0 | Y18: 0 | Z18: 52.22 | AA18: 17 | AB18: 4 | AC18: 0 | AD18: =A18&"|"&B18
A19: P06 | B19: Ad_B | C19: 1 | D19: BA | E19: Female | F19: 26 | G19: 1 | I19: 95 | J19: 97 | K19: 100 | L19: 100 | M19: 1 | N19: 2 | O19: 1 | P19: 0.1239 | Q19: 17.56 | R19: 19.44 | S19: 0 | T19: 1 | U19: 18355 | V19: 2 | W19: 1 | X19: 633 | Y19: 2.11 | Z19: 50.28 | AA19: 24 | AB19: 6 | AC19: 0 | AD19: =A19&"|"&B19
A20: P07 | B20: Baseline | C20: NA | D20: AB | E20: Female | F20: 23 | G20: 1 | I20: 97 | J20: 94 | K20: 100 | L20: 100 | M20: 1 | N20: 2 | O20: 2 | P20: 0.2542 | Q20: 0 | R20: 0.94 | S20: 0 | T20: NA | U20: NA | V20: NA | W20: NA | X20: NA | Y20: NA | Z20: NA | AA20: NA | AB20: NA | AC20: NA | AD20: =A20&"|"&B20
A21: P07 | B21: Ad_A | C21: 1 | D21: AB | E21: Female | F21: 23 | G21: 1 | I21: 97 | J21: 93 | K21: 100 | L21: 100 | M21: 1 | N21: 6 | O21: 3 | P21: 0.2421 | Q21: 7 | R21: 8.89 | S21: 0 | T21: 1 | U21: 5573 | V21: 6 | W21: 2 | X21: 1383 | Y21: 4.61 | Z21: 22.83 | AA21: 19.17 | AB21: 6 | AC21: 1 | AD21: =A21&"|"&B21
A22: P07 | B22: Ad_B | C22: 2 | D22: AB | E22: Female | F22: 23 | G22: 1 | I22: 96 | J22: 93 | K22: 100 | L22: 100 | M22: 1 | N22: 2 | O22: 1 | P22: 0.1754 | Q22: 0 | R22: 0 | S22: 0 | T22: 1 | U22: 29792 | V22: 1 | W22: 0 | X22: 233 | Y22: 0.78 | Z22: 38.89 | AA22: 26.28 | AB22: 4 | AC22: 1 | AD22: =A22&"|"&B22
A23: P08 | B23: Baseline | C23: NA | D23: BA | E23: Female | F23: 21 | G23: 1 | I23: 96 | J23: 95 | K23: 100 | L23: 100 | M23: 1 | N23: 0 | O23: 0 | P23: NA | Q23: 0 | R23: 0 | S23: 0 | T23: NA | U23: NA | V23: NA | W23: NA | X23: NA | Y23: NA | Z23: NA | AA23: NA | AB23: NA | AC23: NA | AD23: =A23&"|"&B23
A24: P08 | B24: Ad_A | C24: 2 | D24: BA | E24: Female | F24: 21 | G24: 1 | I24: 96 | J24: 96 | K24: 100 | L24: 100 | M24: 1 | N24: 6 | O24: 3 | P24: 0.1088 | Q24: 0 | R24: 2.56 | S24: 0 | T24: 1 | U24: 7869 | V24: 1 | W24: 0 | X24: 200 | Y24: 0.67 | Z24: 55.44 | AA24: 23.89 | AB24: 3 | AC24: 1 | AD24: =A24&"|"&B24
A25: P08 | B25: Ad_B | C25: 1 | D25: BA | E25: Female | F25: 21 | G25: 1 | I25: 96 | J25: 95 | K25: 100 | L25: 100 | M25: 1 | N25: 10 | O25: 5 | P25: 0.1343 | Q25: 0 | R25: 0 | S25: 0 | T25: 1 | U25: 1093 | V25: 4 | W25: 0 | X25: 1100 | Y25: 3.67 | Z25: 50.39 | AA25: 23.33 | AB25: 5 | AC25: 0 | AD25: =A25&"|"&B25
A26: P09 | B26: Baseline | C26: NA | D26: AB | E26: Female | F26: 20 | G26: 1 | I26: 95 | J26: 93 | K26: 100 | L26: 100 | M26: 1 | N26: 3 | O26: 3 | P26: 0.1238 | Q26: 0 | R26: 2.33 | S26: 0 | T26: NA | U26: NA | V26: NA | W26: NA | X26: NA | Y26: NA | Z26: NA | AA26: NA | AB26: NA | AC26: NA | AD26: =A26&"|"&B26
A27: P09 | B27: Ad_A | C27: 1 | D27: AB | E27: Female | F27: 20 | G27: 1 | I27: 97 | J27: 93 | K27: 100 | L27: 100 | M27: 1 | N27: 4 | O27: 2 | P27: 0.1443 | Q27: 2.56 | R27: 2.56 | S27: 0 | T27: 0 | U27: NA | V27: 0 | W27: 0 | X27: 0 | Y27: 0 | Z27: 44.44 | AA27: 16.78 | AB27: 5 | AC27: 1 | AD27: =A27&"|"&B27
A28: P09 | B28: Ad_B | C28: 2 | D28: AB | E28: Female | F28: 20 | G28: 1 | I28: 95 | J28: 92 | K28: 100 | L28: 100 | M28: 1 | N28: 10 | O28: 5 | P28: 0.1693 | Q28: 13.11 | R28: 18.22 | S28: 0 | T28: 1 | U28: 20136 | V28: 1 | W28: 0 | X28: 533 | Y28: 1.78 | Z28: 43.61 | AA28: 9.17 | AB28: 3 | AC28: 0 | AD28: =A28&"|"&B28
A29: P10 | B29: Baseline | C29: NA | D29: BA | E29: Male | F29: 23 | G29: 1 | I29: 96 | J29: 97 | K29: 100 | L29: 100 | M29: 1 | N29: 2 | O29: 2 | P29: 0.1483 | Q29: 0 | R29: 4.83 | S29: 0 | T29: NA | U29: NA | V29: NA | W29: NA | X29: NA | Y29: NA | Z29: NA | AA29: NA | AB29: NA | AC29: NA | AD29: =A29&"|"&B29
A30: P10 | B30: Ad_A | C30: 2 | D30: BA | E30: Male | F30: 23 | G30: 1 | I30: 95 | J30: 98 | K30: 100 | L30: 100 | M30: 1 | N30: 6 | O30: 3 | P30: 0.0945 | Q30: 0 | R30: 3.56 | S30: 0 | T30: 1 | U30: 16492 | V30: 5 | W30: 2 | X30: 1917 | Y30: 6.39 | Z30: 47.39 | AA30: 13.17 | AB30: 5 | AC30: 1 | AD30: =A30&"|"&B30
A31: P10 | B31: Ad_B | C31: 1 | D31: BA | E31: Male | F31: 23 | G31: 1 | I31: 95 | J31: 97 | K31: 100 | L31: 100 | M31: 1 | N31: 8 | O31: 4 | P31: 0.1322 | Q31: 0 | R31: 2.56 | S31: 0 | T31: 0 | U31: NA | V31: 0 | W31: 0 | X31: 0 | Y31: 0 | Z31: 42.67 | AA31: 20.44 | AB31: 4 | AC31: 1 | AD31: =A31&"|"&B31
A32: P11 | B32: Baseline | C32: NA | D32: AB | E32: Female | F32: 24 | G32: 1 | I32: 96 | J32: 98 | K32: 100 | L32: 100 | M32: 1 | N32: 5 | O32: 5 | P32: 0.1853 | Q32: 0 | R32: 1.44 | S32: 1.67 | T32: NA | U32: NA | V32: NA | W32: NA | X32: NA | Y32: NA | Z32: NA | AA32: NA | AB32: NA | AC32: NA | AD32: =A32&"|"&B32
A33: P11 | B33: Ad_A | C33: 1 | D33: AB | E33: Female | F33: 24 | G33: 1 | I33: 95 | J33: 98 | K33: 100 | L33: 100 | M33: 1 | N33: 26 | O33: 13 | P33: 0.1987 | Q33: 19.89 | R33: 20.67 | S33: 0 | T33: 1 | U33: 1591 | V33: 1 | W33: 0 | X33: 133 | Y33: 0.44 | Z33: 48.11 | AA33: 25.72 | AB33: 5 | AC33: 1 | AD33: =A33&"|"&B33
A34: P11 | B34: Ad_B | C34: 2 | D34: AB | E34: Female | F34: 24 | G34: 1 | I34: 96 | J34: 98 | K34: 100 | L34: 100 | M34: 1 | N34: 18 | O34: 9 | P34: 0.2315 | Q34: 27 | R34: 28.44 | S34: 0 | T34: 1 | U34: 1629 | V34: 4 | W34: 3 | X34: 1083 | Y34: 3.61 | Z34: 46.78 | AA34: 11.44 | AB34: 4 | AC34: 1 | AD34: =A34&"|"&B34
A35: P12 | B35: Baseline | C35: NA | D35: BA | E35: Male | F35: 23 | G35: 1 | I35: 95 | J35: 96 | K35: 91 | L35: 91.3283 | M35: 1 | N35: 4.38 | O35: 4 | P35: 0.1796 | Q35: 0 | R35: 1.33 | S35: 0 | T35: NA | U35: NA | V35: NA | W35: NA | X35: NA | Y35: NA | Z35: NA | AA35: NA | AB35: NA | AC35: NA | AD35: =A35&"|"&B35
A36: P12 | B36: Ad_A | C36: 2 | D36: BA | E36: Male | F36: 23 | G36: 1 | I36: 97 | J36: 96 | K36: 100 | L36: 100 | M36: 1 | N36: 2 | O36: 1 | P36: 0.1769 | Q36: 26.89 | R36: 34.67 | S36: 0 | T36: 0 | U36: NA | V36: 0 | W36: 0 | X36: 0 | Y36: 0 | Z36: 42.06 | AA36: 23.56 | AB36: 5 | AC36: 0 | AD36: =A36&"|"&B36
A37: P12 | B37: Ad_B | C37: 1 | D37: BA | E37: Male | F37: 23 | G37: 1 | I37: 94 | J37: 96 | K37: 100 | L37: 100 | M37: 1 | N37: 4 | O37: 2 | P37: 0.1921 | Q37: 20.11 | R37: 25.56 | S37: 2.89 | T37: 1 | U37: 7245 | V37: 2 | W37: 0 | X37: 450 | Y37: 1.5 | Z37: 31.11 | AA37: 15.61 | AB37: 5 | AC37: 1 | AD37: =A37&"|"&B37
A38: P13 | B38: Baseline | C38: NA | D38: AB | E38: Male | F38: 20 | G38: 1 | I38: 97 | J38: 94 | K38: 100 | L38: 100 | M38: 1 | N38: 0 | O38: 0 | P38: NA | Q38: 0 | R38: 2.06 | S38: 0 | T38: NA | U38: NA | V38: NA | W38: NA | X38: NA | Y38: NA | Z38: NA | AA38: NA | AB38: NA | AC38: NA | AD38: =A38&"|"&B38
A39: P13 | B39: Ad_A | C39: 1 | D39: AB | E39: Male | F39: 20 | G39: 1 | I39: 95 | J39: 92 | K39: 100 | L39: 100 | M39: 1 | N39: 2 | O39: 1 | P39: 0.2273 | Q39: 14.56 | R39: 18.67 | S39: 0 | T39: 1 | U39: 9338 | V39: 12 | W39: 2 | X39: 3333 | Y39: 11.11 | Z39: 44.5 | AA39: 10.06 | AB39: 2 | AC39: 1 | AD39: =A39&"|"&B39
A40: P13 | B40: Ad_B | C40: 2 | D40: AB | E40: Male | F40: 20 | G40: 1 | I40: 97 | J40: 93 | K40: 100 | L40: 100 | M40: 1 | N40: 0 | O40: 0 | P40: NA | Q40: 1.33 | R40: 1.44 | S40: 0 | T40: 0 | U40: NA | V40: 0 | W40: 0 | X40: 0 | Y40: 0 | Z40: 33.72 | AA40: 21.33 | AB40: 1 | AC40: 0 | AD40: =A40&"|"&B40
...

Sheet AOI_long
A1: participant_id | B1: ad | C1: AOI | D1: include (from Data) | E1: gaze dwell (% of ad)
A2: P01 | B2: Ad_A | C2: Logo | D2: =INDEX(Data!$G$2:$G$73,MATCH(A2&"|"&B2,Data!$AD$2:$AD$73,0)) | E2: =IF(C2="Logo",INDEX(Data!$Y$2:$Y$73,MATCH(A2&"|"&B2,Data!$AD$2:$AD$73,0)),IF(C2="Product",INDEX(Data!$Z$2:$Z$73,MATCH(A2&"|"&B2,Data!$AD$2:$AD$73,0)),INDEX(Data!$AA$2:$AA$73,MATCH(A2&"|"&B2,Data!$AD$2:$AD$73,0)))) | G2: Checks
A3: P01 | B3: Ad_A | C3: Product | D3: =INDEX(Data!$G$2:$G$73,MATCH(A3&"|"&B3,Data!$AD$2:$AD$73,0)) | E3: =IF(C3="Logo",INDEX(Data!$Y$2:$Y$73,MATCH(A3&"|"&B3,Data!$AD$2:$AD$73,0)),IF(C3="Product",INDEX(Data!$Z$2:$Z$73,MATCH(A3&"|"&B3,Data!$AD$2:$AD$73,0)),INDEX(Data!$AA$2:$AA$73,MATCH(A3&"|"&B3,Data!$AD$2:$AD$73,0)))) | G3: Rows (24 participants x 2 ads x 3 AOIs) | H3: =COUNTA(A2:A145)
A4: P01 | B4: Ad_A | C4: Headline | D4: =INDEX(Data!$G$2:$G$73,MATCH(A4&"|"&B4,Data!$AD$2:$AD$73,0)) | E4: =IF(C4="Logo",INDEX(Data!$Y$2:$Y$73,MATCH(A4&"|"&B4,Data!$AD$2:$AD$73,0)),IF(C4="Product",INDEX(Data!$Z$2:$Z$73,MATCH(A4&"|"&B4,Data!$AD$2:$AD$73,0)),INDEX(Data!$AA$2:$AA$73,MATCH(A4&"|"&B4,Data!$AD$2:$AD$73,0)))) | G4: Lookups that failed (#N/A) | H4: =SUMPRODUCT(--ISNA(D2:E145))
A5: P01 | B5: Ad_B | C5: Logo | D5: =INDEX(Data!$G$2:$G$73,MATCH(A5&"|"&B5,Data!$AD$2:$AD$73,0)) | E5: =IF(C5="Logo",INDEX(Data!$Y$2:$Y$73,MATCH(A5&"|"&B5,Data!$AD$2:$AD$73,0)),IF(C5="Product",INDEX(Data!$Z$2:$Z$73,MATCH(A5&"|"&B5,Data!$AD$2:$AD$73,0)),INDEX(Data!$AA$2:$AA$73,MATCH(A5&"|"&B5,Data!$AD$2:$AD$73,0)))) | G5: Rows with include = 1 (22 x 6) | H5: =COUNTIF(D2:D145,1)
A6: P01 | B6: Ad_B | C6: Product | D6: =INDEX(Data!$G$2:$G$73,MATCH(A6&"|"&B6,Data!$AD$2:$AD$73,0)) | E6: =IF(C6="Logo",INDEX(Data!$Y$2:$Y$73,MATCH(A6&"|"&B6,Data!$AD$2:$AD$73,0)),IF(C6="Product",INDEX(Data!$Z$2:$Z$73,MATCH(A6&"|"&B6,Data!$AD$2:$AD$73,0)),INDEX(Data!$AA$2:$AA$73,MATCH(A6&"|"&B6,Data!$AD$2:$AD$73,0))))
A7: P01 | B7: Ad_B | C7: Headline | D7: =INDEX(Data!$G$2:$G$73,MATCH(A7&"|"&B7,Data!$AD$2:$AD$73,0)) | E7: =IF(C7="Logo",INDEX(Data!$Y$2:$Y$73,MATCH(A7&"|"&B7,Data!$AD$2:$AD$73,0)),IF(C7="Product",INDEX(Data!$Z$2:$Z$73,MATCH(A7&"|"&B7,Data!$AD$2:$AD$73,0)),INDEX(Data!$AA$2:$AA$73,MATCH(A7&"|"&B7,Data!$AD$2:$AD$73,0))))
A8: P02 | B8: Ad_A | C8: Logo | D8: =INDEX(Data!$G$2:$G$73,MATCH(A8&"|"&B8,Data!$AD$2:$AD$73,0)) | E8: =IF(C8="Logo",INDEX(Data!$Y$2:$Y$73,MATCH(A8&"|"&B8,Data!$AD$2:$AD$73,0)),IF(C8="Product",INDEX(Data!$Z$2:$Z$73,MATCH(A8&"|"&B8,Data!$AD$2:$AD$73,0)),INDEX(Data!$AA$2:$AA$73,MATCH(A8&"|"&B8,Data!$AD$2:$AD$73,0))))
A9: P02 | B9: Ad_A | C9: Product | D9: =INDEX(Data!$G$2:$G$73,MATCH(A9&"|"&B9,Data!$AD$2:$AD$73,0)) | E9: =IF(C9="Logo",INDEX(Data!$Y$2:$Y$73,MATCH(A9&"|"&B9,Data!$AD$2:$AD$73,0)),IF(C9="Product",INDEX(Data!$Z$2:$Z$73,MATCH(A9&"|"&B9,Data!$AD$2:$AD$73,0)),INDEX(Data!$AA$2:$AA$73,MATCH(A9&"|"&B9,Data!$AD$2:$AD$73,0))))
A10: P02 | B10: Ad_A | C10: Headline | D10: =INDEX(Data!$G$2:$G$73,MATCH(A10&"|"&B10,Data!$AD$2:$AD$73,0)) | E10: =IF(C10="Logo",INDEX(Data!$Y$2:$Y$73,MATCH(A10&"|"&B10,Data!$AD$2:$AD$73,0)),IF(C10="Product",INDEX(Data!$Z$2:$Z$73,MATCH(A10&"|"&B10,Data!$AD$2:$AD$73,0)),INDEX(Data!$AA$2:$AA$73,MATCH(A10&"|"&B10,Data!$AD$2:$AD$73,0))))
A11: P02 | B11: Ad_B | C11: Logo | D11: =INDEX(Data!$G$2:$G$73,MATCH(A11&"|"&B11,Data!$AD$2:$AD$73,0)) | E11: =IF(C11="Logo",INDEX(Data!$Y$2:$Y$73,MATCH(A11&"|"&B11,Data!$AD$2:$AD$73,0)),IF(C11="Product",INDEX(Data!$Z$2:$Z$73,MATCH(A11&"|"&B11,Data!$AD$2:$AD$73,0)),INDEX(Data!$AA$2:$AA$73,MATCH(A11&"|"&B11,Data!$AD$2:$AD$73,0))))
A12: P02 | B12: Ad_B | C12: Product | D12: =INDEX(Data!$G$2:$G$73,MATCH(A12&"|"&B12,Data!$AD$2:$AD$73,0)) | E12: =IF(C12="Logo",INDEX(Data!$Y$2:$Y$73,MATCH(A12&"|"&B12,Data!$AD$2:$AD$73,0)),IF(C12="Product",INDEX(Data!$Z$2:$Z$73,MATCH(A12&"|"&B12,Data!$AD$2:$AD$73,0)),INDEX(Data!$AA$2:$AA$73,MATCH(A12&"|"&B12,Data!$AD$2:$AD$73,0))))
A13: P02 | B13: Ad_B | C13: Headline | D13: =INDEX(Data!$G$2:$G$73,MATCH(A13&"|"&B13,Data!$AD$2:$AD$73,0)) | E13: =IF(C13="Logo",INDEX(Data!$Y$2:$Y$73,MATCH(A13&"|"&B13,Data!$AD$2:$AD$73,0)),IF(C13="Product",INDEX(Data!$Z$2:$Z$73,MATCH(A13&"|"&B13,Data!$AD$2:$AD$73,0)),INDEX(Data!$AA$2:$AA$73,MATCH(A13&"|"&B13,Data!$AD$2:$AD$73,0))))
A14: P03 | B14: Ad_A | C14: Logo | D14: =INDEX(Data!$G$2:$G$73,MATCH(A14&"|"&B14,Data!$AD$2:$AD$73,0)) | E14: =IF(C14="Logo",INDEX(Data!$Y$2:$Y$73,MATCH(A14&"|"&B14,Data!$AD$2:$AD$73,0)),IF(C14="Product",INDEX(Data!$Z$2:$Z$73,MATCH(A14&"|"&B14,Data!$AD$2:$AD$73,0)),INDEX(Data!$AA$2:$AA$73,MATCH(A14&"|"&B14,Data!$AD$2:$AD$73,0))))
A15: P03 | B15: Ad_A | C15: Product | D15: =INDEX(Data!$G$2:$G$73,MATCH(A15&"|"&B15,Data!$AD$2:$AD$73,0)) | E15: =IF(C15="Logo",INDEX(Data!$Y$2:$Y$73,MATCH(A15&"|"&B15,Data!$AD$2:$AD$73,0)),IF(C15="Product",INDEX(Data!$Z$2:$Z$73,MATCH(A15&"|"&B15,Data!$AD$2:$AD$73,0)),INDEX(Data!$AA$2:$AA$73,MATCH(A15&"|"&B15,Data!$AD$2:$AD$73,0))))
A16: P03 | B16: Ad_A | C16: Headline | D16: =INDEX(Data!$G$2:$G$73,MATCH(A16&"|"&B16,Data!$AD$2:$AD$73,0)) | E16: =IF(C16="Logo",INDEX(Data!$Y$2:$Y$73,MATCH(A16&"|"&B16,Data!$AD$2:$AD$73,0)),IF(C16="Product",INDEX(Data!$Z$2:$Z$73,MATCH(A16&"|"&B16,Data!$AD$2:$AD$73,0)),INDEX(Data!$AA$2:$AA$73,MATCH(A16&"|"&B16,Data!$AD$2:$AD$73,0))))
A17: P03 | B17: Ad_B | C17: Logo | D17: =INDEX(Data!$G$2:$G$73,MATCH(A17&"|"&B17,Data!$AD$2:$AD$73,0)) | E17: =IF(C17="Logo",INDEX(Data!$Y$2:$Y$73,MATCH(A17&"|"&B17,Data!$AD$2:$AD$73,0)),IF(C17="Product",INDEX(Data!$Z$2:$Z$73,MATCH(A17&"|"&B17,Data!$AD$2:$AD$73,0)),INDEX(Data!$AA$2:$AA$73,MATCH(A17&"|"&B17,Data!$AD$2:$AD$73,0))))
... A145: P24 | B145: Ad_B | C145: Headline | D145: =INDEX(Data!$G$2:$G$73,MATCH(A145&"|"&B145,Data!$AD$2:$AD$73,0)) | E145: =IF(C145="Logo",INDEX(Data!$Y$2:$Y$73,MATCH(A145&"|"&B145,Data!$AD$2:$AD$73,0)),IF(C145="Product",INDEX(Data!$Z$2:$Z$73,MATCH(A145&"|"&B145,Data!$AD$2:$AD$73,0)),INDEX(Data!$AA$2:$AA$73,MATCH(A145&"|"&B145,Data!$AD$2:$AD$73,0))))

Sheet Descriptives
A1: Descriptive statistics, analysis sample (include = 1). Gaze dwell from AOI_long; facial expressions, GSR (valid only, rule R3), and liking from Data. SD, median, and quartiles are array formulas.
A3: A. Gaze dwell by ad and AOI (from AOI_long)
A4: Measure | B4: Ad or stimulus | C4: AOI | D4: n | E4: Mean | F4: SD | G4: Median | H4: Q1 | I4: Q3 | J4: IQR | K4: % at zero
A5: Gaze dwell (% of ad) | B5: Ad_A | C5: Logo | D5: =COUNTIFS(AOI_long!$B$2:$B$145,B5,AOI_long!$C$2:$C$145,C5,AOI_long!$D$2:$D$145,1) | E5: =AVERAGEIFS(AOI_long!$E$2:$E$145,AOI_long!$B$2:$B$145,B5,AOI_long!$C$2:$C$145,C5,AOI_long!$D$2:$D$145,1) | F5: {=_xlfn.STDEV.S(IF((AOI_long!$B$2:$B$145=B5)*(AOI_long!$C$2:$C$145=C5)*(AOI_long!$D$2:$D$145=1),AOI_long!$E$2:$E$145))} | G5: {=MEDIAN(IF((AOI_long!$B$2:$B$145=B5)*(AOI_long!$C$2:$C$145=C5)*(AOI_long!$D$2:$D$145=1),AOI_long!$E$2:$E$145))} | H5: {=_xlfn.QUARTILE.INC(IF((AOI_long!$B$2:$B$145=B5)*(AOI_long!$C$2:$C$145=C5)*(AOI_long!$D$2:$D$145=1),AOI_long!$E$2:$E$145),1)} | I5: {=_xlfn.QUARTILE.INC(IF((AOI_long!$B$2:$B$145=B5)*(AOI_long!$C$2:$C$145=C5)*(AOI_long!$D$2:$D$145=1),AOI_long!$E$2:$E$145),3)} | J5: =I5-H5 | K5: =100*COUNTIFS(AOI_long!$B$2:$B$145,B5,AOI_long!$C$2:$C$145,C5,AOI_long!$D$2:$D$145,1,AOI_long!$E$2:$E$145,0)/D5
A6: Gaze dwell (% of ad) | B6: Ad_A | C6: Product | D6: =COUNTIFS(AOI_long!$B$2:$B$145,B6,AOI_long!$C$2:$C$145,C6,AOI_long!$D$2:$D$145,1) | E6: =AVERAGEIFS(AOI_long!$E$2:$E$145,AOI_long!$B$2:$B$145,B6,AOI_long!$C$2:$C$145,C6,AOI_long!$D$2:$D$145,1) | F6: {=_xlfn.STDEV.S(IF((AOI_long!$B$2:$B$145=B6)*(AOI_long!$C$2:$C$145=C6)*(AOI_long!$D$2:$D$145=1),AOI_long!$E$2:$E$145))} | G6: {=MEDIAN(IF((AOI_long!$B$2:$B$145=B6)*(AOI_long!$C$2:$C$145=C6)*(AOI_long!$D$2:$D$145=1),AOI_long!$E$2:$E$145))} | H6: {=_xlfn.QUARTILE.INC(IF((AOI_long!$B$2:$B$145=B6)*(AOI_long!$C$2:$C$145=C6)*(AOI_long!$D$2:$D$145=1),AOI_long!$E$2:$E$145),1)} | I6: {=_xlfn.QUARTILE.INC(IF((AOI_long!$B$2:$B$145=B6)*(AOI_long!$C$2:$C$145=C6)*(AOI_long!$D$2:$D$145=1),AOI_long!$E$2:$E$145),3)} | J6: =I6-H6 | K6: =100*COUNTIFS(AOI_long!$B$2:$B$145,B6,AOI_long!$C$2:$C$145,C6,AOI_long!$D$2:$D$145,1,AOI_long!$E$2:$E$145,0)/D6
A7: Gaze dwell (% of ad) | B7: Ad_A | C7: Headline | D7: =COUNTIFS(AOI_long!$B$2:$B$145,B7,AOI_long!$C$2:$C$145,C7,AOI_long!$D$2:$D$145,1) | E7: =AVERAGEIFS(AOI_long!$E$2:$E$145,AOI_long!$B$2:$B$145,B7,AOI_long!$C$2:$C$145,C7,AOI_long!$D$2:$D$145,1) | F7: {=_xlfn.STDEV.S(IF((AOI_long!$B$2:$B$145=B7)*(AOI_long!$C$2:$C$145=C7)*(AOI_long!$D$2:$D$145=1),AOI_long!$E$2:$E$145))} | G7: {=MEDIAN(IF((AOI_long!$B$2:$B$145=B7)*(AOI_long!$C$2:$C$145=C7)*(AOI_long!$D$2:$D$145=1),AOI_long!$E$2:$E$145))} | H7: {=_xlfn.QUARTILE.INC(IF((AOI_long!$B$2:$B$145=B7)*(AOI_long!$C$2:$C$145=C7)*(AOI_long!$D$2:$D$145=1),AOI_long!$E$2:$E$145),1)} | I7: {=_xlfn.QUARTILE.INC(IF((AOI_long!$B$2:$B$145=B7)*(AOI_long!$C$2:$C$145=C7)*(AOI_long!$D$2:$D$145=1),AOI_long!$E$2:$E$145),3)} | J7: =I7-H7 | K7: =100*COUNTIFS(AOI_long!$B$2:$B$145,B7,AOI_long!$C$2:$C$145,C7,AOI_long!$D$2:$D$145,1,AOI_long!$E$2:$E$145,0)/D7
A8: Gaze dwell (% of ad) | B8: Ad_B | C8: Logo | D8: =COUNTIFS(AOI_long!$B$2:$B$145,B8,AOI_long!$C$2:$C$145,C8,AOI_long!$D$2:$D$145,1) | E8: =AVERAGEIFS(AOI_long!$E$2:$E$145,AOI_long!$B$2:$B$145,B8,AOI_long!$C$2:$C$145,C8,AOI_long!$D$2:$D$145,1) | F8: {=_xlfn.STDEV.S(IF((AOI_long!$B$2:$B$145=B8)*(AOI_long!$C$2:$C$145=C8)*(AOI_long!$D$2:$D$145=1),AOI_long!$E$2:$E$145))} | G8: {=MEDIAN(IF((AOI_long!$B$2:$B$145=B8)*(AOI_long!$C$2:$C$145=C8)*(AOI_long!$D$2:$D$145=1),AOI_long!$E$2:$E$145))} | H8: {=_xlfn.QUARTILE.INC(IF((AOI_long!$B$2:$B$145=B8)*(AOI_long!$C$2:$C$145=C8)*(AOI_long!$D$2:$D$145=1),AOI_long!$E$2:$E$145),1)} | I8: {=_xlfn.QUARTILE.INC(IF((AOI_long!$B$2:$B$145=B8)*(AOI_long!$C$2:$C$145=C8)*(AOI_long!$D$2:$D$145=1),AOI_long!$E$2:$E$145),3)} | J8: =I8-H8 | K8: =100*COUNTIFS(AOI_long!$B$2:$B$145,B8,AOI_long!$C$2:$C$145,C8,AOI_long!$D$2:$D$145,1,AOI_long!$E$2:$E$145,0)/D8
A9: Gaze dwell (% of ad) | B9: Ad_B | C9: Product | D9: =COUNTIFS(AOI_long!$B$2:$B$145,B9,AOI_long!$C$2:$C$145,C9,AOI_long!$D$2:$D$145,1) | E9: =AVERAGEIFS(AOI_long!$E$2:$E$145,AOI_long!$B$2:$B$145,B9,AOI_long!$C$2:$C$145,C9,AOI_long!$D$2:$D$145,1) | F9: {=_xlfn.STDEV.S(IF((AOI_long!$B$2:$B$145=B9)*(AOI_long!$C$2:$C$145=C9)*(AOI_long!$D$2:$D$145=1),AOI_long!$E$2:$E$145))} | G9: {=MEDIAN(IF((AOI_long!$B$2:$B$145=B9)*(AOI_long!$C$2:$C$145=C9)*(AOI_long!$D$2:$D$145=1),AOI_long!$E$2:$E$145))} | H9: {=_xlfn.QUARTILE.INC(IF((AOI_long!$B$2:$B$145=B9)*(AOI_long!$C$2:$C$145=C9)*(AOI_long!$D$2:$D$145=1),AOI_long!$E$2:$E$145),1)} | I9: {=_xlfn.QUARTILE.INC(IF((AOI_long!$B$2:$B$145=B9)*(AOI_long!$C$2:$C$145=C9)*(AOI_long!$D$2:$D$145=1),AOI_long!$E$2:$E$145),3)} | J9: =I9-H9 | K9: =100*COUNTIFS(AOI_long!$B$2:$B$145,B9,AOI_long!$C$2:$C$145,C9,AOI_long!$D$2:$D$145,1,AOI_long!$E$2:$E$145,0)/D9
A10: Gaze dwell (% of ad) | B10: Ad_B | C10: Headline | D10: =COUNTIFS(AOI_long!$B$2:$B$145,B10,AOI_long!$C$2:$C$145,C10,AOI_long!$D$2:$D$145,1) | E10: =AVERAGEIFS(AOI_long!$E$2:$E$145,AOI_long!$B$2:$B$145,B10,AOI_long!$C$2:$C$145,C10,AOI_long!$D$2:$D$145,1) | F10: {=_xlfn.STDEV.S(IF((AOI_long!$B$2:$B$145=B10)*(AOI_long!$C$2:$C$145=C10)*(AOI_long!$D$2:$D$145=1),AOI_long!$E$2:$E$145))} | G10: {=MEDIAN(IF((AOI_long!$B$2:$B$145=B10)*(AOI_long!$C$2:$C$145=C10)*(AOI_long!$D$2:$D$145=1),AOI_long!$E$2:$E$145))} | H10: {=_xlfn.QUARTILE.INC(IF((AOI_long!$B$2:$B$145=B10)*(AOI_long!$C$2:$C$145=C10)*(AOI_long!$D$2:$D$145=1),AOI_long!$E$2:$E$145),1)} | I10: {=_xlfn.QUARTILE.INC(IF((AOI_long!$B$2:$B$145=B10)*(AOI_long!$C$2:$C$145=C10)*(AOI_long!$D$2:$D$145=1),AOI_long!$E$2:$E$145),3)} | J10: =I10-H10 | K10: =100*COUNTIFS(AOI_long!$B$2:$B$145,B10,AOI_long!$C$2:$C$145,C10,AOI_long!$D$2:$D$145,1,AOI_long!$E$2:$E$145,0)/D10
A12: B. Facial expressions by stimulus (from Data)
A13: Measure | B13: Ad or stimulus | C13: AOI | D13: n | E13: Mean | F13: SD | G13: Median | H13: Q1 | I13: Q3 | J13: IQR | K13: % at zero
A14: Joy (% of time) | B14: Baseline | D14: =COUNTIFS(Data!$B$2:$B$73,B14,Data!$G$2:$G$73,1) | E14: =AVERAGEIFS(Data!$Q$2:$Q$73,Data!$B$2:$B$73,B14,Data!$G$2:$G$73,1) | F14: {=_xlfn.STDEV.S(IF((Data!$B$2:$B$73=B14)*(Data!$G$2:$G$73=1),Data!$Q$2:$Q$73))} | G14: {=MEDIAN(IF((Data!$B$2:$B$73=B14)*(Data!$G$2:$G$73=1),Data!$Q$2:$Q$73))} | H14: {=_xlfn.QUARTILE.INC(IF((Data!$B$2:$B$73=B14)*(Data!$G$2:$G$73=1),Data!$Q$2:$Q$73),1)} | I14: {=_xlfn.QUARTILE.INC(IF((Data!$B$2:$B$73=B14)*(Data!$G$2:$G$73=1),Data!$Q$2:$Q$73),3)} | J14: =I14-H14 | K14: =100*COUNTIFS(Data!$B$2:$B$73,B14,Data!$G$2:$G$73,1,Data!$Q$2:$Q$73,0)/D14
A15: Joy (% of time) | B15: Ad_A | D15: =COUNTIFS(Data!$B$2:$B$73,B15,Data!$G$2:$G$73,1) | E15: =AVERAGEIFS(Data!$Q$2:$Q$73,Data!$B$2:$B$73,B15,Data!$G$2:$G$73,1) | F15: {=_xlfn.STDEV.S(IF((Data!$B$2:$B$73=B15)*(Data!$G$2:$G$73=1),Data!$Q$2:$Q$73))} | G15: {=MEDIAN(IF((Data!$B$2:$B$73=B15)*(Data!$G$2:$G$73=1),Data!$Q$2:$Q$73))} | H15: {=_xlfn.QUARTILE.INC(IF((Data!$B$2:$B$73=B15)*(Data!$G$2:$G$73=1),Data!$Q$2:$Q$73),1)} | I15: {=_xlfn.QUARTILE.INC(IF((Data!$B$2:$B$73=B15)*(Data!$G$2:$G$73=1),Data!$Q$2:$Q$73),3)} | J15: =I15-H15 | K15: =100*COUNTIFS(Data!$B$2:$B$73,B15,Data!$G$2:$G$73,1,Data!$Q$2:$Q$73,0)/D15
A16: Joy (% of time) | B16: Ad_B | D16: =COUNTIFS(Data!$B$2:$B$73,B16,Data!$G$2:$G$73,1) | E16: =AVERAGEIFS(Data!$Q$2:$Q$73,Data!$B$2:$B$73,B16,Data!$G$2:$G$73,1) | F16: {=_xlfn.STDEV.S(IF((Data!$B$2:$B$73=B16)*(Data!$G$2:$G$73=1),Data!$Q$2:$Q$73))} | G16: {=MEDIAN(IF((Data!$B$2:$B$73=B16)*(Data!$G$2:$G$73=1),Data!$Q$2:$Q$73))} | H16: {=_xlfn.QUARTILE.INC(IF((Data!$B$2:$B$73=B16)*(Data!$G$2:$G$73=1),Data!$Q$2:$Q$73),1)} | I16: {=_xlfn.QUARTILE.INC(IF((Data!$B$2:$B$73=B16)*(Data!$G$2:$G$73=1),Data!$Q$2:$Q$73),3)} | J16: =I16-H16 | K16: =100*COUNTIFS(Data!$B$2:$B$73,B16,Data!$G$2:$G$73,1,Data!$Q$2:$Q$73,0)/D16
A17: Engagement (% of time) | B17: Baseline | D17: =COUNTIFS(Data!$B$2:$B$73,B17,Data!$G$2:$G$73,1) | E17: =AVERAGEIFS(Data!$R$2:$R$73,Data!$B$2:$B$73,B17,Data!$G$2:$G$73,1) | F17: {=_xlfn.STDEV.S(IF((Data!$B$2:$B$73=B17)*(Data!$G$2:$G$73=1),Data!$R$2:$R$73))} | G17: {=MEDIAN(IF((Data!$B$2:$B$73=B17)*(Data!$G$2:$G$73=1),Data!$R$2:$R$73))} | H17: {=_xlfn.QUARTILE.INC(IF((Data!$B$2:$B$73=B17)*(Data!$G$2:$G$73=1),Data!$R$2:$R$73),1)} | I17: {=_xlfn.QUARTILE.INC(IF((Data!$B$2:$B$73=B17)*(Data!$G$2:$G$73=1),Data!$R$2:$R$73),3)} | J17: =I17-H17 | K17: =100*COUNTIFS(Data!$B$2:$B$73,B17,Data!$G$2:$G$73,1,Data!$R$2:$R$73,0)/D17
A18: Engagement (% of time) | B18: Ad_A | D18: =COUNTIFS(Data!$B$2:$B$73,B18,Data!$G$2:$G$73,1) | E18: =AVERAGEIFS(Data!$R$2:$R$73,Data!$B$2:$B$73,B18,Data!$G$2:$G$73,1) | F18: {=_xlfn.STDEV.S(IF((Data!$B$2:$B$73=B18)*(Data!$G$2:$G$73=1),Data!$R$2:$R$73))} | G18: {=MEDIAN(IF((Data!$B$2:$B$73=B18)*(Data!$G$2:$G$73=1),Data!$R$2:$R$73))} | H18: {=_xlfn.QUARTILE.INC(IF((Data!$B$2:$B$73=B18)*(Data!$G$2:$G$73=1),Data!$R$2:$R$73),1)} | I18: {=_xlfn.QUARTILE.INC(IF((Data!$B$2:$B$73=B18)*(Data!$G$2:$G$73=1),Data!$R$2:$R$73),3)} | J18: =I18-H18 | K18: =100*COUNTIFS(Data!$B$2:$B$73,B18,Data!$G$2:$G$73,1,Data!$R$2:$R$73,0)/D18
A19: Engagement (% of time) | B19: Ad_B | D19: =COUNTIFS(Data!$B$2:$B$73,B19,Data!$G$2:$G$73,1) | E19: =AVERAGEIFS(Data!$R$2:$R$73,Data!$B$2:$B$73,B19,Data!$G$2:$G$73,1) | F19: {=_xlfn.STDEV.S(IF((Data!$B$2:$B$73=B19)*(Data!$G$2:$G$73=1),Data!$R$2:$R$73))} | G19: {=MEDIAN(IF((Data!$B$2:$B$73=B19)*(Data!$G$2:$G$73=1),Data!$R$2:$R$73))} | H19: {=_xlfn.QUARTILE.INC(IF((Data!$B$2:$B$73=B19)*(Data!$G$2:$G$73=1),Data!$R$2:$R$73),1)} | I19: {=_xlfn.QUARTILE.INC(IF((Data!$B$2:$B$73=B19)*(Data!$G$2:$G$73=1),Data!$R$2:$R$73),3)} | J19: =I19-H19 | K19: =100*COUNTIFS(Data!$B$2:$B$73,B19,Data!$G$2:$G$73,1,Data!$R$2:$R$73,0)/D19
A20: Brow Furrow (% of time) | B20: Baseline | D20: =COUNTIFS(Data!$B$2:$B$73,B20,Data!$G$2:$G$73,1) | E20: =AVERAGEIFS(Data!$S$2:$S$73,Data!$B$2:$B$73,B20,Data!$G$2:$G$73,1) | F20: {=_xlfn.STDEV.S(IF((Data!$B$2:$B$73=B20)*(Data!$G$2:$G$73=1),Data!$S$2:$S$73))} | G20: {=MEDIAN(IF((Data!$B$2:$B$73=B20)*(Data!$G$2:$G$73=1),Data!$S$2:$S$73))} | H20: {=_xlfn.QUARTILE.INC(IF((Data!$B$2:$B$73=B20)*(Data!$G$2:$G$73=1),Data!$S$2:$S$73),1)} | I20: {=_xlfn.QUARTILE.INC(IF((Data!$B$2:$B$73=B20)*(Data!$G$2:$G$73=1),Data!$S$2:$S$73),3)} | J20: =I20-H20 | K20: =100*COUNTIFS(Data!$B$2:$B$73,B20,Data!$G$2:$G$73,1,Data!$S$2:$S$73,0)/D20
A21: Brow Furrow (% of time) | B21: Ad_A | D21: =COUNTIFS(Data!$B$2:$B$73,B21,Data!$G$2:$G$73,1) | E21: =AVERAGEIFS(Data!$S$2:$S$73,Data!$B$2:$B$73,B21,Data!$G$2:$G$73,1) | F21: {=_xlfn.STDEV.S(IF((Data!$B$2:$B$73=B21)*(Data!$G$2:$G$73=1),Data!$S$2:$S$73))} | G21: {=MEDIAN(IF((Data!$B$2:$B$73=B21)*(Data!$G$2:$G$73=1),Data!$S$2:$S$73))} | H21: {=_xlfn.QUARTILE.INC(IF((Data!$B$2:$B$73=B21)*(Data!$G$2:$G$73=1),Data!$S$2:$S$73),1)} | I21: {=_xlfn.QUARTILE.INC(IF((Data!$B$2:$B$73=B21)*(Data!$G$2:$G$73=1),Data!$S$2:$S$73),3)} | J21: =I21-H21 | K21: =100*COUNTIFS(Data!$B$2:$B$73,B21,Data!$G$2:$G$73,1,Data!$S$2:$S$73,0)/D21
A22: Brow Furrow (% of time) | B22: Ad_B | D22: =COUNTIFS(Data!$B$2:$B$73,B22,Data!$G$2:$G$73,1) | E22: =AVERAGEIFS(Data!$S$2:$S$73,Data!$B$2:$B$73,B22,Data!$G$2:$G$73,1) | F22: {=_xlfn.STDEV.S(IF((Data!$B$2:$B$73=B22)*(Data!$G$2:$G$73=1),Data!$S$2:$S$73))} | G22: {=MEDIAN(IF((Data!$B$2:$B$73=B22)*(Data!$G$2:$G$73=1),Data!$S$2:$S$73))} | H22: {=_xlfn.QUARTILE.INC(IF((Data!$B$2:$B$73=B22)*(Data!$G$2:$G$73=1),Data!$S$2:$S$73),1)} | I22: {=_xlfn.QUARTILE.INC(IF((Data!$B$2:$B$73=B22)*(Data!$G$2:$G$73=1),Data!$S$2:$S$73),3)} | J22: =I22-H22 | K22: =100*COUNTIFS(Data!$B$2:$B$73,B22,Data!$G$2:$G$73,1,Data!$S$2:$S$73,0)/D22
A24: C. GSR Peaks Per Minute by stimulus, valid GSR only (rule R3) (from Data)
A25: Measure | B25: Ad or stimulus | C25: AOI | D25: n | E25: Mean | F25: SD | G25: Median | H25: Q1 | I25: Q3 | J25: IQR | K25: % at zero
A26: GSR Peaks Per Minute | B26: Baseline | D26: =COUNTIFS(Data!$B$2:$B$73,B26,Data!$G$2:$G$73,1,Data!$M$2:$M$73,1) | E26: =AVERAGEIFS(Data!$N$2:$N$73,Data!$B$2:$B$73,B26,Data!$G$2:$G$73,1,Data!$M$2:$M$73,1) | F26: {=_xlfn.STDEV.S(IF((Data!$B$2:$B$73=B26)*(Data!$G$2:$G$73=1)*(Data!$M$2:$M$73=1),Data!$N$2:$N$73))} | G26: {=MEDIAN(IF((Data!$B$2:$B$73=B26)*(Data!$G$2:$G$73=1)*(Data!$M$2:$M$73=1),Data!$N$2:$N$73))} | H26: {=_xlfn.QUARTILE.INC(IF((Data!$B$2:$B$73=B26)*(Data!$G$2:$G$73=1)*(Data!$M$2:$M$73=1),Data!$N$2:$N$73),1)} | I26: {=_xlfn.QUARTILE.INC(IF((Data!$B$2:$B$73=B26)*(Data!$G$2:$G$73=1)*(Data!$M$2:$M$73=1),Data!$N$2:$N$73),3)} | J26: =I26-H26 | K26: =100*COUNTIFS(Data!$B$2:$B$73,B26,Data!$G$2:$G$73,1,Data!$M$2:$M$73,1,Data!$N$2:$N$73,0)/D26
A27: GSR Peaks Per Minute | B27: Ad_A | D27: =COUNTIFS(Data!$B$2:$B$73,B27,Data!$G$2:$G$73,1,Data!$M$2:$M$73,1) | E27: =AVERAGEIFS(Data!$N$2:$N$73,Data!$B$2:$B$73,B27,Data!$G$2:$G$73,1,Data!$M$2:$M$73,1) | F27: {=_xlfn.STDEV.S(IF((Data!$B$2:$B$73=B27)*(Data!$G$2:$G$73=1)*(Data!$M$2:$M$73=1),Data!$N$2:$N$73))} | G27: {=MEDIAN(IF((Data!$B$2:$B$73=B27)*(Data!$G$2:$G$73=1)*(Data!$M$2:$M$73=1),Data!$N$2:$N$73))} | H27: {=_xlfn.QUARTILE.INC(IF((Data!$B$2:$B$73=B27)*(Data!$G$2:$G$73=1)*(Data!$M$2:$M$73=1),Data!$N$2:$N$73),1)} | I27: {=_xlfn.QUARTILE.INC(IF((Data!$B$2:$B$73=B27)*(Data!$G$2:$G$73=1)*(Data!$M$2:$M$73=1),Data!$N$2:$N$73),3)} | J27: =I27-H27 | K27: =100*COUNTIFS(Data!$B$2:$B$73,B27,Data!$G$2:$G$73,1,Data!$M$2:$M$73,1,Data!$N$2:$N$73,0)/D27
A28: GSR Peaks Per Minute | B28: Ad_B | D28: =COUNTIFS(Data!$B$2:$B$73,B28,Data!$G$2:$G$73,1,Data!$M$2:$M$73,1) | E28: =AVERAGEIFS(Data!$N$2:$N$73,Data!$B$2:$B$73,B28,Data!$G$2:$G$73,1,Data!$M$2:$M$73,1) | F28: {=_xlfn.STDEV.S(IF((Data!$B$2:$B$73=B28)*(Data!$G$2:$G$73=1)*(Data!$M$2:$M$73=1),Data!$N$2:$N$73))} | G28: {=MEDIAN(IF((Data!$B$2:$B$73=B28)*(Data!$G$2:$G$73=1)*(Data!$M$2:$M$73=1),Data!$N$2:$N$73))} | H28: {=_xlfn.QUARTILE.INC(IF((Data!$B$2:$B$73=B28)*(Data!$G$2:$G$73=1)*(Data!$M$2:$M$73=1),Data!$N$2:$N$73),1)} | I28: {=_xlfn.QUARTILE.INC(IF((Data!$B$2:$B$73=B28)*(Data!$G$2:$G$73=1)*(Data!$M$2:$M$73=1),Data!$N$2:$N$73),3)} | J28: =I28-H28 | K28: =100*COUNTIFS(Data!$B$2:$B$73,B28,Data!$G$2:$G$73,1,Data!$M$2:$M$73,1,Data!$N$2:$N$73,0)/D28
A30: D. Liking by ad (from Data)
A31: Measure | B31: Ad or stimulus | C31: AOI | D31: n | E31: Mean | F31: SD | G31: Median | H31: Q1 | I31: Q3 | J31: IQR | K31: % at zero
A32: Liking (1 to 7) | B32: Ad_A | D32: =COUNTIFS(Data!$B$2:$B$73,B32,Data!$G$2:$G$73,1) | E32: =AVERAGEIFS(Data!$AB$2:$AB$73,Data!$B$2:$B$73,B32,Data!$G$2:$G$73,1) | F32: {=_xlfn.STDEV.S(IF((Data!$B$2:$B$73=B32)*(Data!$G$2:$G$73=1),Data!$AB$2:$AB$73))} | G32: {=MEDIAN(IF((Data!$B$2:$B$73=B32)*(Data!$G$2:$G$73=1),Data!$AB$2:$AB$73))} | H32: {=_xlfn.QUARTILE.INC(IF((Data!$B$2:$B$73=B32)*(Data!$G$2:$G$73=1),Data!$AB$2:$AB$73),1)} | I32: {=_xlfn.QUARTILE.INC(IF((Data!$B$2:$B$73=B32)*(Data!$G$2:$G$73=1),Data!$AB$2:$AB$73),3)} | J32: =I32-H32
A33: Liking (1 to 7) | B33: Ad_B | D33: =COUNTIFS(Data!$B$2:$B$73,B33,Data!$G$2:$G$73,1) | E33: =AVERAGEIFS(Data!$AB$2:$AB$73,Data!$B$2:$B$73,B33,Data!$G$2:$G$73,1) | F33: {=_xlfn.STDEV.S(IF((Data!$B$2:$B$73=B33)*(Data!$G$2:$G$73=1),Data!$AB$2:$AB$73))} | G33: {=MEDIAN(IF((Data!$B$2:$B$73=B33)*(Data!$G$2:$G$73=1),Data!$AB$2:$AB$73))} | H33: {=_xlfn.QUARTILE.INC(IF((Data!$B$2:$B$73=B33)*(Data!$G$2:$G$73=1),Data!$AB$2:$AB$73),1)} | I33: {=_xlfn.QUARTILE.INC(IF((Data!$B$2:$B$73=B33)*(Data!$G$2:$G$73=1),Data!$AB$2:$AB$73),3)} | J33: =I33-H33

Sheet Pivot
A1: PivotTable style summary: Average of gaze dwell (% of ad) by AOI (rows) and ad (columns), include = 1. Built with AVERAGEIFS and COUNTIFS so that it can be checked; a real PivotTable gives the same numbers.
A3: AOI | B3: Ad_A | C3: Ad_B | D3: Grand average | E3: Count Ad_A | F3: Count Ad_B
A4: Logo | B4: =AVERAGEIFS(AOI_long!$E$2:$E$145,AOI_long!$C$2:$C$145,$A4,AOI_long!$B$2:$B$145,B$3,AOI_long!$D$2:$D$145,1) | C4: =AVERAGEIFS(AOI_long!$E$2:$E$145,AOI_long!$C$2:$C$145,$A4,AOI_long!$B$2:$B$145,C$3,AOI_long!$D$2:$D$145,1) | D4: =AVERAGEIFS(AOI_long!$E$2:$E$145,AOI_long!$C$2:$C$145,$A4,AOI_long!$D$2:$D$145,1) | E4: =COUNTIFS(AOI_long!$C$2:$C$145,$A4,AOI_long!$B$2:$B$145,"Ad_A",AOI_long!$D$2:$D$145,1) | F4: =COUNTIFS(AOI_long!$C$2:$C$145,$A4,AOI_long!$B$2:$B$145,"Ad_B",AOI_long!$D$2:$D$145,1)
A5: Product | B5: =AVERAGEIFS(AOI_long!$E$2:$E$145,AOI_long!$C$2:$C$145,$A5,AOI_long!$B$2:$B$145,B$3,AOI_long!$D$2:$D$145,1) | C5: =AVERAGEIFS(AOI_long!$E$2:$E$145,AOI_long!$C$2:$C$145,$A5,AOI_long!$B$2:$B$145,C$3,AOI_long!$D$2:$D$145,1) | D5: =AVERAGEIFS(AOI_long!$E$2:$E$145,AOI_long!$C$2:$C$145,$A5,AOI_long!$D$2:$D$145,1) | E5: =COUNTIFS(AOI_long!$C$2:$C$145,$A5,AOI_long!$B$2:$B$145,"Ad_A",AOI_long!$D$2:$D$145,1) | F5: =COUNTIFS(AOI_long!$C$2:$C$145,$A5,AOI_long!$B$2:$B$145,"Ad_B",AOI_long!$D$2:$D$145,1)
A6: Headline | B6: =AVERAGEIFS(AOI_long!$E$2:$E$145,AOI_long!$C$2:$C$145,$A6,AOI_long!$B$2:$B$145,B$3,AOI_long!$D$2:$D$145,1) | C6: =AVERAGEIFS(AOI_long!$E$2:$E$145,AOI_long!$C$2:$C$145,$A6,AOI_long!$B$2:$B$145,C$3,AOI_long!$D$2:$D$145,1) | D6: =AVERAGEIFS(AOI_long!$E$2:$E$145,AOI_long!$C$2:$C$145,$A6,AOI_long!$D$2:$D$145,1) | E6: =COUNTIFS(AOI_long!$C$2:$C$145,$A6,AOI_long!$B$2:$B$145,"Ad_A",AOI_long!$D$2:$D$145,1) | F6: =COUNTIFS(AOI_long!$C$2:$C$145,$A6,AOI_long!$B$2:$B$145,"Ad_B",AOI_long!$D$2:$D$145,1)
A7: Grand average | B7: =AVERAGEIFS(AOI_long!$E$2:$E$145,AOI_long!$B$2:$B$145,B$3,AOI_long!$D$2:$D$145,1) | C7: =AVERAGEIFS(AOI_long!$E$2:$E$145,AOI_long!$B$2:$B$145,C$3,AOI_long!$D$2:$D$145,1)
A9: To build the real PivotTable: click any cell of AOI_long, Insert > PivotTable > New Worksheet > OK; drag AOI to Rows, ad to Columns, gaze dwell (% of ad) to Values; right click a value, Value Field Settings, change Sum to Average; drag include (from Data) to Filters and keep only 1. Excel sorts the rows A to Z (Headline, Logo, Product).

Sheet Q5
A1: Q5: facial expressions, Ad_A versus Ad_B (paired). Roster: the 22 participants with include = 1 (static list, checked on the Check sheet). Values from Data with INDEX and MATCH on the key column.
A3: participant_id | B3: Joy Ad_A | C3: Joy Ad_B | D3: Joy Ad_A minus Ad_B | E3: Engagement Ad_A | F3: Engagement Ad_B | G3: Engagement Ad_A minus Ad_B | H3: Brow Furrow Ad_A | I3: Brow Furrow Ad_B | J3: Brow Furrow Ad_A minus Ad_B
A4: P01 | B4: =INDEX(Data!$Q$2:$Q$73,MATCH($A4&"|Ad_A",Data!$AD$2:$AD$73,0)) | C4: =INDEX(Data!$Q$2:$Q$73,MATCH($A4&"|Ad_B",Data!$AD$2:$AD$73,0)) | D4: =B4-C4 | E4: =INDEX(Data!$R$2:$R$73,MATCH($A4&"|Ad_A",Data!$AD$2:$AD$73,0)) | F4: =INDEX(Data!$R$2:$R$73,MATCH($A4&"|Ad_B",Data!$AD$2:$AD$73,0)) | G4: =E4-F4 | H4: =INDEX(Data!$S$2:$S$73,MATCH($A4&"|Ad_A",Data!$AD$2:$AD$73,0)) | I4: =INDEX(Data!$S$2:$S$73,MATCH($A4&"|Ad_B",Data!$AD$2:$AD$73,0)) | J4: =H4-I4
A5: P02 | B5: =INDEX(Data!$Q$2:$Q$73,MATCH($A5&"|Ad_A",Data!$AD$2:$AD$73,0)) | C5: =INDEX(Data!$Q$2:$Q$73,MATCH($A5&"|Ad_B",Data!$AD$2:$AD$73,0)) | D5: =B5-C5 | E5: =INDEX(Data!$R$2:$R$73,MATCH($A5&"|Ad_A",Data!$AD$2:$AD$73,0)) | F5: =INDEX(Data!$R$2:$R$73,MATCH($A5&"|Ad_B",Data!$AD$2:$AD$73,0)) | G5: =E5-F5 | H5: =INDEX(Data!$S$2:$S$73,MATCH($A5&"|Ad_A",Data!$AD$2:$AD$73,0)) | I5: =INDEX(Data!$S$2:$S$73,MATCH($A5&"|Ad_B",Data!$AD$2:$AD$73,0)) | J5: =H5-I5
A6: P03 | B6: =INDEX(Data!$Q$2:$Q$73,MATCH($A6&"|Ad_A",Data!$AD$2:$AD$73,0)) | C6: =INDEX(Data!$Q$2:$Q$73,MATCH($A6&"|Ad_B",Data!$AD$2:$AD$73,0)) | D6: =B6-C6 | E6: =INDEX(Data!$R$2:$R$73,MATCH($A6&"|Ad_A",Data!$AD$2:$AD$73,0)) | F6: =INDEX(Data!$R$2:$R$73,MATCH($A6&"|Ad_B",Data!$AD$2:$AD$73,0)) | G6: =E6-F6 | H6: =INDEX(Data!$S$2:$S$73,MATCH($A6&"|Ad_A",Data!$AD$2:$AD$73,0)) | I6: =INDEX(Data!$S$2:$S$73,MATCH($A6&"|Ad_B",Data!$AD$2:$AD$73,0)) | J6: =H6-I6
A7: P04 | B7: =INDEX(Data!$Q$2:$Q$73,MATCH($A7&"|Ad_A",Data!$AD$2:$AD$73,0)) | C7: =INDEX(Data!$Q$2:$Q$73,MATCH($A7&"|Ad_B",Data!$AD$2:$AD$73,0)) | D7: =B7-C7 | E7: =INDEX(Data!$R$2:$R$73,MATCH($A7&"|Ad_A",Data!$AD$2:$AD$73,0)) | F7: =INDEX(Data!$R$2:$R$73,MATCH($A7&"|Ad_B",Data!$AD$2:$AD$73,0)) | G7: =E7-F7 | H7: =INDEX(Data!$S$2:$S$73,MATCH($A7&"|Ad_A",Data!$AD$2:$AD$73,0)) | I7: =INDEX(Data!$S$2:$S$73,MATCH($A7&"|Ad_B",Data!$AD$2:$AD$73,0)) | J7: =H7-I7
A8: P05 | B8: =INDEX(Data!$Q$2:$Q$73,MATCH($A8&"|Ad_A",Data!$AD$2:$AD$73,0)) | C8: =INDEX(Data!$Q$2:$Q$73,MATCH($A8&"|Ad_B",Data!$AD$2:$AD$73,0)) | D8: =B8-C8 | E8: =INDEX(Data!$R$2:$R$73,MATCH($A8&"|Ad_A",Data!$AD$2:$AD$73,0)) | F8: =INDEX(Data!$R$2:$R$73,MATCH($A8&"|Ad_B",Data!$AD$2:$AD$73,0)) | G8: =E8-F8 | H8: =INDEX(Data!$S$2:$S$73,MATCH($A8&"|Ad_A",Data!$AD$2:$AD$73,0)) | I8: =INDEX(Data!$S$2:$S$73,MATCH($A8&"|Ad_B",Data!$AD$2:$AD$73,0)) | J8: =H8-I8
A9: P06 | B9: =INDEX(Data!$Q$2:$Q$73,MATCH($A9&"|Ad_A",Data!$AD$2:$AD$73,0)) | C9: =INDEX(Data!$Q$2:$Q$73,MATCH($A9&"|Ad_B",Data!$AD$2:$AD$73,0)) | D9: =B9-C9 | E9: =INDEX(Data!$R$2:$R$73,MATCH($A9&"|Ad_A",Data!$AD$2:$AD$73,0)) | F9: =INDEX(Data!$R$2:$R$73,MATCH($A9&"|Ad_B",Data!$AD$2:$AD$73,0)) | G9: =E9-F9 | H9: =INDEX(Data!$S$2:$S$73,MATCH($A9&"|Ad_A",Data!$AD$2:$AD$73,0)) | I9: =INDEX(Data!$S$2:$S$73,MATCH($A9&"|Ad_B",Data!$AD$2:$AD$73,0)) | J9: =H9-I9
A10: P07 | B10: =INDEX(Data!$Q$2:$Q$73,MATCH($A10&"|Ad_A",Data!$AD$2:$AD$73,0)) | C10: =INDEX(Data!$Q$2:$Q$73,MATCH($A10&"|Ad_B",Data!$AD$2:$AD$73,0)) | D10: =B10-C10 | E10: =INDEX(Data!$R$2:$R$73,MATCH($A10&"|Ad_A",Data!$AD$2:$AD$73,0)) | F10: =INDEX(Data!$R$2:$R$73,MATCH($A10&"|Ad_B",Data!$AD$2:$AD$73,0)) | G10: =E10-F10 | H10: =INDEX(Data!$S$2:$S$73,MATCH($A10&"|Ad_A",Data!$AD$2:$AD$73,0)) | I10: =INDEX(Data!$S$2:$S$73,MATCH($A10&"|Ad_B",Data!$AD$2:$AD$73,0)) | J10: =H10-I10
A11: P08 | B11: =INDEX(Data!$Q$2:$Q$73,MATCH($A11&"|Ad_A",Data!$AD$2:$AD$73,0)) | C11: =INDEX(Data!$Q$2:$Q$73,MATCH($A11&"|Ad_B",Data!$AD$2:$AD$73,0)) | D11: =B11-C11 | E11: =INDEX(Data!$R$2:$R$73,MATCH($A11&"|Ad_A",Data!$AD$2:$AD$73,0)) | F11: =INDEX(Data!$R$2:$R$73,MATCH($A11&"|Ad_B",Data!$AD$2:$AD$73,0)) | G11: =E11-F11 | H11: =INDEX(Data!$S$2:$S$73,MATCH($A11&"|Ad_A",Data!$AD$2:$AD$73,0)) | I11: =INDEX(Data!$S$2:$S$73,MATCH($A11&"|Ad_B",Data!$AD$2:$AD$73,0)) | J11: =H11-I11
A12: P09 | B12: =INDEX(Data!$Q$2:$Q$73,MATCH($A12&"|Ad_A",Data!$AD$2:$AD$73,0)) | C12: =INDEX(Data!$Q$2:$Q$73,MATCH($A12&"|Ad_B",Data!$AD$2:$AD$73,0)) | D12: =B12-C12 | E12: =INDEX(Data!$R$2:$R$73,MATCH($A12&"|Ad_A",Data!$AD$2:$AD$73,0)) | F12: =INDEX(Data!$R$2:$R$73,MATCH($A12&"|Ad_B",Data!$AD$2:$AD$73,0)) | G12: =E12-F12 | H12: =INDEX(Data!$S$2:$S$73,MATCH($A12&"|Ad_A",Data!$AD$2:$AD$73,0)) | I12: =INDEX(Data!$S$2:$S$73,MATCH($A12&"|Ad_B",Data!$AD$2:$AD$73,0)) | J12: =H12-I12
A13: P10 | B13: =INDEX(Data!$Q$2:$Q$73,MATCH($A13&"|Ad_A",Data!$AD$2:$AD$73,0)) | C13: =INDEX(Data!$Q$2:$Q$73,MATCH($A13&"|Ad_B",Data!$AD$2:$AD$73,0)) | D13: =B13-C13 | E13: =INDEX(Data!$R$2:$R$73,MATCH($A13&"|Ad_A",Data!$AD$2:$AD$73,0)) | F13: =INDEX(Data!$R$2:$R$73,MATCH($A13&"|Ad_B",Data!$AD$2:$AD$73,0)) | G13: =E13-F13 | H13: =INDEX(Data!$S$2:$S$73,MATCH($A13&"|Ad_A",Data!$AD$2:$AD$73,0)) | I13: =INDEX(Data!$S$2:$S$73,MATCH($A13&"|Ad_B",Data!$AD$2:$AD$73,0)) | J13: =H13-I13
A14: P11 | B14: =INDEX(Data!$Q$2:$Q$73,MATCH($A14&"|Ad_A",Data!$AD$2:$AD$73,0)) | C14: =INDEX(Data!$Q$2:$Q$73,MATCH($A14&"|Ad_B",Data!$AD$2:$AD$73,0)) | D14: =B14-C14 | E14: =INDEX(Data!$R$2:$R$73,MATCH($A14&"|Ad_A",Data!$AD$2:$AD$73,0)) | F14: =INDEX(Data!$R$2:$R$73,MATCH($A14&"|Ad_B",Data!$AD$2:$AD$73,0)) | G14: =E14-F14 | H14: =INDEX(Data!$S$2:$S$73,MATCH($A14&"|Ad_A",Data!$AD$2:$AD$73,0)) | I14: =INDEX(Data!$S$2:$S$73,MATCH($A14&"|Ad_B",Data!$AD$2:$AD$73,0)) | J14: =H14-I14
A15: P12 | B15: =INDEX(Data!$Q$2:$Q$73,MATCH($A15&"|Ad_A",Data!$AD$2:$AD$73,0)) | C15: =INDEX(Data!$Q$2:$Q$73,MATCH($A15&"|Ad_B",Data!$AD$2:$AD$73,0)) | D15: =B15-C15 | E15: =INDEX(Data!$R$2:$R$73,MATCH($A15&"|Ad_A",Data!$AD$2:$AD$73,0)) | F15: =INDEX(Data!$R$2:$R$73,MATCH($A15&"|Ad_B",Data!$AD$2:$AD$73,0)) | G15: =E15-F15 | H15: =INDEX(Data!$S$2:$S$73,MATCH($A15&"|Ad_A",Data!$AD$2:$AD$73,0)) | I15: =INDEX(Data!$S$2:$S$73,MATCH($A15&"|Ad_B",Data!$AD$2:$AD$73,0)) | J15: =H15-I15
... A25: P24 | B25: =INDEX(Data!$Q$2:$Q$73,MATCH($A25&"|Ad_A",Data!$AD$2:$AD$73,0)) | C25: =INDEX(Data!$Q$2:$Q$73,MATCH($A25&"|Ad_B",Data!$AD$2:$AD$73,0)) | D25: =B25-C25 | E25: =INDEX(Data!$R$2:$R$73,MATCH($A25&"|Ad_A",Data!$AD$2:$AD$73,0)) | F25: =INDEX(Data!$R$2:$R$73,MATCH($A25&"|Ad_B",Data!$AD$2:$AD$73,0)) | G25: =E25-F25 | H25: =INDEX(Data!$S$2:$S$73,MATCH($A25&"|Ad_A",Data!$AD$2:$AD$73,0)) | I25: =INDEX(Data!$S$2:$S$73,MATCH($A25&"|Ad_B",Data!$AD$2:$AD$73,0)) | J25: =H25-I25
A28: Joy: paired t test, Ad_A minus Ad_B | E28: Engagement: paired t test, Ad_A minus Ad_B | I28: Brow Furrow: paired t test, Ad_A minus Ad_B
A29: Ad_A mean | B29: =AVERAGE(B4:B25) | E29: Ad_A mean | F29: =AVERAGE(E4:E25) | I29: Ad_A mean | J29: =AVERAGE(H4:H25)
A30: Ad_A SD | B30: =_xlfn.STDEV.S(B4:B25) | E30: Ad_A SD | F30: =_xlfn.STDEV.S(E4:E25) | I30: Ad_A SD | J30: =_xlfn.STDEV.S(H4:H25)
A31: Ad_B mean | B31: =AVERAGE(C4:C25) | E31: Ad_B mean | F31: =AVERAGE(F4:F25) | I31: Ad_B mean | J31: =AVERAGE(I4:I25)
A32: Ad_B SD | B32: =_xlfn.STDEV.S(C4:C25) | E32: Ad_B SD | F32: =_xlfn.STDEV.S(F4:F25) | I32: Ad_B SD | J32: =_xlfn.STDEV.S(I4:I25)
A33: n (participants) | B33: =COUNT(D4:D25) | E33: n (participants) | F33: =COUNT(G4:G25) | I33: n (participants) | J33: =COUNT(J4:J25)
A34: Mean difference | B34: =AVERAGE(D4:D25) | E34: Mean difference | F34: =AVERAGE(G4:G25) | I34: Mean difference | J34: =AVERAGE(J4:J25)
A35: SD of the differences | B35: =_xlfn.STDEV.S(D4:D25) | E35: SD of the differences | F35: =_xlfn.STDEV.S(G4:G25) | I35: SD of the differences | J35: =_xlfn.STDEV.S(J4:J25)
A36: SE of the mean difference | B36: =B35/SQRT(B33) | E36: SE of the mean difference | F36: =F35/SQRT(F33) | I36: SE of the mean difference | J36: =J35/SQRT(J33)
A37: t | B37: =B34/B36 | E37: t | F37: =F34/F36 | I37: t | J37: =J34/J36
A38: df | B38: =B33-1 | E38: df | F38: =F33-1 | I38: df | J38: =J33-1
A39: p, two tailed (T.TEST, paired) | B39: =_xlfn.T.TEST(B4:B25,C4:C25,2,1) | E39: p, two tailed (T.TEST, paired) | F39: =_xlfn.T.TEST(E4:E25,F4:F25,2,1) | I39: p, two tailed (T.TEST, paired) | J39: =_xlfn.T.TEST(H4:H25,I4:I25,2,1)
A40: p from t (T.DIST.2T) | B40: =_xlfn.T.DIST.2T(ABS(B37),B38) | E40: p from t (T.DIST.2T) | F40: =_xlfn.T.DIST.2T(ABS(F37),F38) | I40: p from t (T.DIST.2T) | J40: =_xlfn.T.DIST.2T(ABS(J37),J38)
A41: Critical t (95%) | B41: =_xlfn.T.INV.2T(0.05,B38) | E41: Critical t (95%) | F41: =_xlfn.T.INV.2T(0.05,F38) | I41: Critical t (95%) | J41: =_xlfn.T.INV.2T(0.05,J38)
A42: Mean difference, 95% CI lower | B42: =B34-B41*B36 | E42: Mean difference, 95% CI lower | F42: =F34-F41*F36 | I42: Mean difference, 95% CI lower | J42: =J34-J41*J36
A43: Mean difference, 95% CI upper | B43: =B34+B41*B36 | E43: Mean difference, 95% CI upper | F43: =F34+F41*F36 | I43: Mean difference, 95% CI upper | J43: =J34+J41*J36
A44: Cohen's d_z | B44: =B34/B35 | E44: Cohen's d_z | F44: =F34/F35 | I44: Cohen's d_z | J44: =J34/J35
A45: SE of d_z (approximation) | B45: =SQRT(1/B33+B44^2/(2*B33)) | E45: SE of d_z (approximation) | F45: =SQRT(1/F33+F44^2/(2*F33)) | I45: SE of d_z (approximation) | J45: =SQRT(1/J33+J44^2/(2*J33))
A46: d_z 95% CI lower (approximation) | B46: =B44-1.96*B45 | E46: d_z 95% CI lower (approximation) | F46: =F44-1.96*F45 | I46: d_z 95% CI lower (approximation) | J46: =J44-1.96*J45
A47: d_z 95% CI upper (approximation) | B47: =B44+1.96*B45 | E47: d_z 95% CI upper (approximation) | F47: =F44+1.96*F45 | I47: d_z 95% CI upper (approximation) | J47: =J44+1.96*J45
A48: Ad_A higher (count) | B48: =COUNTIF(D4:D25,">0") | E48: Ad_A higher (count) | F48: =COUNTIF(G4:G25,">0") | I48: Ad_A higher (count) | J48: =COUNTIF(J4:J25,">0")
A49: Ad_B higher (count) | B49: =COUNTIF(D4:D25,"<0") | E49: Ad_B higher (count) | F49: =COUNTIF(G4:G25,"<0") | I49: Ad_B higher (count) | J49: =COUNTIF(J4:J25,"<0")
A50: No difference (count) | B50: =COUNTIF(D4:D25,0) | E50: No difference (count) | F50: =COUNTIF(G4:G25,0) | I50: No difference (count) | J50: =COUNTIF(J4:J25,0)
A51: Zero in both ads (count) | B51: =COUNTIFS(B4:B25,0,C4:C25,0) | E51: Zero in both ads (count) | F51: =COUNTIFS(E4:E25,0,F4:F25,0) | I51: Zero in both ads (count) | J51: =COUNTIFS(H4:H25,0,I4:I25,0)

Sheet Holm
A1: Holm correction of the three Q5 p values (family: Joy, Engagement, Brow Furrow). Holm keeps the chance of at least one false positive in the family at .05 and is never less powerful than Bonferroni.
A3: Test | B3: p (from Q5) | C3: Rank (smallest = 1) | D3: Multiplier (m - rank + 1) | E3: p x multiplier | F3: Holm adjusted p | G3: Bonferroni p | H3: Decision at .05 | J3: m (tests in the family) | K3: =COUNT(B4:B6)
A4: Joy | B4: =Q5!B39 | C4: =_xlfn.RANK.EQ(B4,$B$4:$B$6,1) | D4: =$K$3-C4+1 | E4: =B4*D4 | F4: =INDEX($E$11:$E$13,C4) | G4: =MIN(1,$K$3*B4) | H4: =IF(F4<0.05,"significant","not significant")
A5: Engagement | B5: =Q5!F39 | C5: =_xlfn.RANK.EQ(B5,$B$4:$B$6,1) | D5: =$K$3-C5+1 | E5: =B5*D5 | F5: =INDEX($E$11:$E$13,C5) | G5: =MIN(1,$K$3*B5) | H5: =IF(F5<0.05,"significant","not significant")
A6: Brow Furrow | B6: =Q5!J39 | C6: =_xlfn.RANK.EQ(B6,$B$4:$B$6,1) | D6: =$K$3-C6+1 | E6: =B6*D6 | F6: =INDEX($E$11:$E$13,C6) | G6: =MIN(1,$K$3*B6) | H6: =IF(F6<0.05,"significant","not significant")
A9: Step by step, from the smallest p to the largest
A10: Step k | B10: k-th smallest p (SMALL) | C10: Multiplier (m - k + 1) | D10: p x multiplier | E10: Holm adjusted (running maximum, at most 1)
A11: 1 | B11: =SMALL($B$4:$B$6,A11) | C11: =$K$3-A11+1 | D11: =B11*C11 | E11: =MIN(1,D11)
A12: 2 | B12: =SMALL($B$4:$B$6,A12) | C12: =$K$3-A12+1 | D12: =B12*C12 | E12: =MIN(1,MAX(E11,D12))
A13: 3 | B13: =SMALL($B$4:$B$6,A13) | C13: =$K$3-A13+1 | D13: =B13*C13 | E13: =MIN(1,MAX(E12,D13))
A15: Read the table: sort the p values from smallest to largest; multiply the smallest by m, the next by m - 1, and so on; each adjusted value is at least as large as the one before it (the running maximum) and never above 1. Compare the adjusted p with .05.
A16: p x multiplier (column E, rows 4 to 6) is not yet the Holm p: the running maximum in the step table can raise it (Joy's product 0.30919 is raised to 0.33096, the adjusted value before it).

Sheet Check
A1: Excel results next to the values that analysis_full.R produced (SIMULATED data). Tolerance: half a unit in the last printed decimal.
A3: Result | B3: Excel | C3: R | D3: Difference | E3: Tolerance | F3: Status
A4: AOI_long: AOI_long rows | B4: =AOI_long!H3 | C4: 144 | D4: =B4-C4 | E4: 1e-09 | F4: =IF(ABS(D4)<=E4,"OK","CHECK")
A5: AOI_long: AOI_long failed lookups | B5: =AOI_long!H4 | C5: 0 | D5: =B5-C5 | E5: 1e-09 | F5: =IF(ABS(D5)<=E5,"OK","CHECK")
A6: AOI_long: AOI_long rows with include = 1 | B6: =AOI_long!H5 | C6: 132 | D6: =B6-C6 | E6: 1e-09 | F6: =IF(ABS(D6)<=E6,"OK","CHECK")
A7: Descriptives: n, Gaze dwell (% of ad), Ad_A | B7: =Descriptives!D5 | C7: 22 | D7: =B7-C7 | E7: 1e-09 | F7: =IF(ABS(D7)<=E7,"OK","CHECK")
A8: Descriptives: mean, Gaze dwell (% of ad), Ad_A | B8: =Descriptives!E5 | C8: 1.7822727 | D8: =B8-C8 | E8: 0.0005 | F8: =IF(ABS(D8)<=E8,"OK","CHECK")
A9: Descriptives: SD, Gaze dwell (% of ad), Ad_A | B9: =Descriptives!F5 | C9: 2.820444 | D9: =B9-C9 | E9: 0.0005 | F9: =IF(ABS(D9)<=E9,"OK","CHECK")
A10: Descriptives: median, Gaze dwell (% of ad), Ad_A | B10: =Descriptives!G5 | C10: 0.525 | D10: =B10-C10 | E10: 0.0005 | F10: =IF(ABS(D10)<=E10,"OK","CHECK")
A11: Descriptives: Q1, Gaze dwell (% of ad), Ad_A | B11: =Descriptives!H5 | C11: 0 | D11: =B11-C11 | E11: 0.0005 | F11: =IF(ABS(D11)<=E11,"OK","CHECK")
A12: Descriptives: Q3, Gaze dwell (% of ad), Ad_A | B12: =Descriptives!I5 | C12: 2.095 | D12: =B12-C12 | E12: 0.0005 | F12: =IF(ABS(D12)<=E12,"OK","CHECK")
A13: Descriptives: IQR, Gaze dwell (% of ad), Ad_A | B13: =Descriptives!J5 | C13: 2.095 | D13: =B13-C13 | E13: 0.0005 | F13: =IF(ABS(D13)<=E13,"OK","CHECK")
A14: Descriptives: % at zero, Gaze dwell (% of ad), Ad_A | B14: =Descriptives!K5 | C14: 45.454545 | D14: =B14-C14 | E14: 0.005 | F14: =IF(ABS(D14)<=E14,"OK","CHECK")
A15: Descriptives: n, Gaze dwell (% of ad), Ad_A | B15: =Descriptives!D6 | C15: 22 | D15: =B15-C15 | E15: 1e-09 | F15: =IF(ABS(D15)<=E15,"OK","CHECK")
A16: Descriptives: mean, Gaze dwell (% of ad), Ad_A | B16: =Descriptives!E6 | C16: 42.584091 | D16: =B16-C16 | E16: 0.0005 | F16: =IF(ABS(D16)<=E16,"OK","CHECK")
A17: Descriptives: SD, Gaze dwell (% of ad), Ad_A | B17: =Descriptives!F6 | C17: 8.4224098 | D17: =B17-C17 | E17: 0.0005 | F17: =IF(ABS(D17)<=E17,"OK","CHECK")
A18: Descriptives: median, Gaze dwell (% of ad), Ad_A | B18: =Descriptives!G6 | C18: 43.885 | D18: =B18-C18 | E18: 0.0005 | F18: =IF(ABS(D18)<=E18,"OK","CHECK")
A19: Descriptives: Q1, Gaze dwell (% of ad), Ad_A | B19: =Descriptives!H6 | C19: 38.4 | D19: =B19-C19 | E19: 0.0005 | F19: =IF(ABS(D19)<=E19,"OK","CHECK")
A20: Descriptives: Q3, Gaze dwell (% of ad), Ad_A | B20: =Descriptives!I6 | C20: 48.155 | D20: =B20-C20 | E20: 0.0005 | F20: =IF(ABS(D20)<=E20,"OK","CHECK")
A21: Descriptives: IQR, Gaze dwell (% of ad), Ad_A | B21: =Descriptives!J6 | C21: 9.755 | D21: =B21-C21 | E21: 0.0005 | F21: =IF(ABS(D21)<=E21,"OK","CHECK")
A22: Descriptives: % at zero, Gaze dwell (% of ad), Ad_A | B22: =Descriptives!K6 | C22: 0 | D22: =B22-C22 | E22: 0.005 | F22: =IF(ABS(D22)<=E22,"OK","CHECK")
A23: Descriptives: n, Gaze dwell (% of ad), Ad_A | B23: =Descriptives!D7 | C23: 22 | D23: =B23-C23 | E23: 1e-09 | F23: =IF(ABS(D23)<=E23,"OK","CHECK")
A24: Descriptives: mean, Gaze dwell (% of ad), Ad_A | B24: =Descriptives!E7 | C24: 17.844091 | D24: =B24-C24 | E24: 0.0005 | F24: =IF(ABS(D24)<=E24,"OK","CHECK")
A25: Descriptives: SD, Gaze dwell (% of ad), Ad_A | B25: =Descriptives!F7 | C25: 7.1191477 | D25: =B25-C25 | E25: 0.0005 | F25: =IF(ABS(D25)<=E25,"OK","CHECK")
A26: Descriptives: median, Gaze dwell (% of ad), Ad_A | B26: =Descriptives!G7 | C26: 19.195 | D26: =B26-C26 | E26: 0.0005 | F26: =IF(ABS(D26)<=E26,"OK","CHECK")
A27: Descriptives: Q1, Gaze dwell (% of ad), Ad_A | B27: =Descriptives!H7 | C27: 13.3925 | D27: =B27-C27 | E27: 0.0005 | F27: =IF(ABS(D27)<=E27,"OK","CHECK")
A28: Descriptives: Q3, Gaze dwell (% of ad), Ad_A | B28: =Descriptives!I7 | C28: 22.93 | D28: =B28-C28 | E28: 0.0005 | F28: =IF(ABS(D28)<=E28,"OK","CHECK")
A29: Descriptives: IQR, Gaze dwell (% of ad), Ad_A | B29: =Descriptives!J7 | C29: 9.5375 | D29: =B29-C29 | E29: 0.0005 | F29: =IF(ABS(D29)<=E29,"OK","CHECK")
A30: Descriptives: % at zero, Gaze dwell (% of ad), Ad_A | B30: =Descriptives!K7 | C30: 0 | D30: =B30-C30 | E30: 0.005 | F30: =IF(ABS(D30)<=E30,"OK","CHECK")
A31: Descriptives: n, Gaze dwell (% of ad), Ad_B | B31: =Descriptives!D8 | C31: 22 | D31: =B31-C31 | E31: 1e-09 | F31: =IF(ABS(D31)<=E31,"OK","CHECK")
A32: Descriptives: mean, Gaze dwell (% of ad), Ad_B | B32: =Descriptives!E8 | C32: 1.3963636 | D32: =B32-C32 | E32: 0.0005 | F32: =IF(ABS(D32)<=E32,"OK","CHECK")
A33: Descriptives: SD, Gaze dwell (% of ad), Ad_B | B33: =Descriptives!F8 | C33: 1.8912897 | D33: =B33-C33 | E33: 0.0005 | F33: =IF(ABS(D33)<=E33,"OK","CHECK")
A34: Descriptives: median, Gaze dwell (% of ad), Ad_B | B34: =Descriptives!G8 | C34: 0.75 | D34: =B34-C34 | E34: 0.0005 | F34: =IF(ABS(D34)<=E34,"OK","CHECK")
A35: Descriptives: Q1, Gaze dwell (% of ad), Ad_B | B35: =Descriptives!H8 | C35: 0 | D35: =B35-C35 | E35: 0.0005 | F35: =IF(ABS(D35)<=E35,"OK","CHECK")
A36: Descriptives: Q3, Gaze dwell (% of ad), Ad_B | B36: =Descriptives!I8 | C36: 2.04 | D36: =B36-C36 | E36: 0.0005 | F36: =IF(ABS(D36)<=E36,"OK","CHECK")
A37: Descriptives: IQR, Gaze dwell (% of ad), Ad_B | B37: =Descriptives!J8 | C37: 2.04 | D37: =B37-C37 | E37: 0.0005 | F37: =IF(ABS(D37)<=E37,"OK","CHECK")
A38: Descriptives: % at zero, Gaze dwell (% of ad), Ad_B | B38: =Descriptives!K8 | C38: 45.454545 | D38: =B38-C38 | E38: 0.005 | F38: =IF(ABS(D38)<=E38,"OK","CHECK")
A39: Descriptives: n, Gaze dwell (% of ad), Ad_B | B39: =Descriptives!D9 | C39: 22 | D39: =B39-C39 | E39: 1e-09 | F39: =IF(ABS(D39)<=E39,"OK","CHECK")
A40: Descriptives: mean, Gaze dwell (% of ad), Ad_B | B40: =Descriptives!E9 | C40: 41.344091 | D40: =B40-C40 | E40: 0.0005 | F40: =IF(ABS(D40)<=E40,"OK","CHECK")
A41: Descriptives: SD, Gaze dwell (% of ad), Ad_B | B41: =Descriptives!F9 | C41: 6.1683483 | D41: =B41-C41 | E41: 0.0005 | F41: =IF(ABS(D41)<=E41,"OK","CHECK")
...
