Workbook

Sheet README
A1: SIMULATED DATA PREPARATION WORKBOOK (Workshop 7)
A2: SIMULATED DATA for teaching (seed 20271231). No real person was recorded. Built by make_simulated_data.py, prepare_data.R, analysis.R, and make_excel_workbook.py.
A3: Study: SIMULATED Multimodal Ad Study. 24 participants (P01 to P24), Baseline (60 s), Ad_A and Ad_B (30 s, counterbalanced), survey.
A4: This workbook is the Excel route through the core steps of prepare_data.R and the H3 test of analysis.R.
A6: Sheets
A7: GSR_Import GSRPeakMetrics.csv as the Text Import leaves it (header in row 1), plus helper columns P to U (orange)
A8: SessionLog the lab session log (the key table: recording name -> participant, Use recording), plus the key in column M
A9: Survey MERGED_SURVEY_RESPONSE_MATRIX.txt (tab separated), plus helper columns V to AC and Cronbach's alpha
A10: DataQuality the _DataQuality.txt file (tab separated), plus helper columns I to M
A11: Keys the problem keys made visible with LEN, CODE, EXACT, TRIM, UPPER
A12: Merged one row per participant and stimulus (72 rows): INDEX and MATCH joins, rules R2 and R3
A13: Pivot the summary a PivotTable gives (built with AVERAGEIFS and COUNTIFS so that it can be checked)
... A19: The walkthrough excel_walkthrough.md explains every formula with its cell address.

Sheet SessionLog
A1: Participant ID | B1: iMotions respondent name | C1: Recording | D1: Session date | E1: Start time | F1: Seat | G1: Computer | H1: Operator | I1: Order (typed in Group) | J1: Shimmer unit | K1: Aurora calibration | L1: Use recording | M1: Notes | N1: Key = UPPER(TRIM(name))
A2: P01 | B2: P01 | C2: 1 | D2: 2026-11-16 | E2: 09:11 | F2: 1 | G2: Lab desktop (Key 0002) | H2: Operator_1 | I2: AB | J2: Shimmer3-8956 | K2: Good | L2: Yes | N2: =UPPER(TRIM(B2))
A3: P02 | B3: P02 | C3: 1 | D3: 2026-11-16 | E3: 10:36 | F3: 1 | G3: Lab desktop (Key 0002) | H3: Operator_1 | I3: BA | J3: Shimmer3-B | K3: Good | L3: Yes | N3: =UPPER(TRIM(B3))
A4: P03 | B4: P03 | C4: 1 | D4: 2026-11-16 | E4: 12:10 | F4: 1 | G4: Lab desktop (Key 0002) | H4: Operator_1 | I4: AB | J4: Shimmer3-B | K4: Good | L4: Yes | N4: =UPPER(TRIM(B4))
A5: P04 | B5: P04 | C5: 1 | D5: 2026-11-16 | E5: 13:33 | F5: 1 | G5: Lab desktop (Key 0002) | H5: Operator_1 | I5: BA | J5: Shimmer3-8956 | K5: Failed | L5: No | M5: Aurora calibration failed (gaze not tracked in the live view). Recording stopped 23 s into Baseline. Recalibrated and recorded again as P04_rerun. Do not use this recording. | N5: =UPPER(TRIM(B5))
A6: P04 | B6: P04_rerun | C6: 2 | D6: 2026-11-16 | E6: 13:46 | F6: 1 | G6: Lab desktop (Key 0002) | H6: Operator_1 | I6: BA | J6: Shimmer3-8956 | K6: Good after recalibration | L6: Yes | M6: Rerun of P04 after recalibration (Baseline had not finished, so no ad was seen twice). Use this recording as P04. | N6: =UPPER(TRIM(B6))
A7: P05 | B7: P05 | C7: 1 | D7: 2026-11-16 | E7: 15:07 | F7: 1 | G7: Lab desktop (Key 0002) | H7: Operator_1 | I7: AB | J7: Shimmer3-B | K7: Good | L7: Yes | M7: Shimmer3-B low battery warning during Ad_B; GSR signal lost about 8 s into Ad_B and did not return. Keep; GSR from Ad_B on is missing. | N7: =UPPER(TRIM(B7))
A8: P06 | B8: P06 | C8: 1 | D8: 2026-11-17 | E8: 09:00 | F8: 1 | G8: Lab desktop (Key 0002) | H8: Operator_1 | I8: BA | J8: Shimmer3-B | K8: Good | L8: Yes | N8: =UPPER(TRIM(B8))
A9: P07 | B9: P07 | C9: 1 | D9: 2026-11-17 | E9: 10:39 | F9: 1 | G9: Lab desktop (Key 0002) | H9: Operator_1 | I9: AB | J9: Shimmer3-B | K9: Good | L9: Yes | N9: =UPPER(TRIM(B9))
A10: P08 | B10: P08 | C10: 1 | D10: 2026-11-17 | E10: 12:09 | F10: 1 | G10: Lab desktop (Key 0002) | H10: Operator_1 | I10: BA | J10: Shimmer3-8956 | K10: Good | L10: Yes | N10: =UPPER(TRIM(B10))
A11: P09 | B11: P09 | C11: 1 | D11: 2026-11-17 | E11: 13:36 | F11: 1 | G11: Lab desktop (Key 0002) | H11: Operator_1 | I11: AB | J11: Shimmer3-8956 | K11: Good | L11: Yes | M11: Arrived 10 minutes late. | N11: =UPPER(TRIM(B11))
A12: P10 | B12: P10 | C12: 1 | D12: 2026-11-17 | E12: 15:09 | F12: 1 | G12: Lab desktop (Key 0002) | H12: Operator_1 | I12: BA | J12: Shimmer3-B | K12: Good | L12: Yes | N12: =UPPER(TRIM(B12))
A13: P11 | B13: P11 | C13: 1 | D13: 2026-11-18 | E13: 09:10 | F13: 1 | G13: Lab desktop (Key 0002) | H13: Operator_1 | I13: AB | J13: Shimmer3-B | K13: Good | L13: Yes | N13: =UPPER(TRIM(B13))
A14: P12 | B14: P12 | C14: 1 | D14: 2026-11-18 | E14: 10:37 | F14: 1 | G14: Lab desktop (Key 0002) | H14: Operator_1 | I14: BA | J14: Shimmer3-8956 | K14: Good | L14: Yes | M14: Short Bluetooth dropout of the Shimmer during Baseline (a few seconds); signal returned. | N14: =UPPER(TRIM(B14))
A15: P13 | B15: P13 | C15: 1 | D15: 2026-11-18 | E15: 12:11 | F15: 1 | G15: Lab desktop (Key 0002) | H15: Operator_2 | I15: AB | J15: Shimmer3-8956 | K15: Good | L15: Yes | N15: =UPPER(TRIM(B15))
A16: P14 | B16: P14 | C16: 1 | D16: 2026-11-18 | E16: 13:32 | F16: 1 | G16: Lab desktop (Key 0002) | H16: Operator_2 | I16: BA | J16: Shimmer3-B | K16: Good | L16: Yes | M16: Left handed; Shimmer on the right hand. | N16: =UPPER(TRIM(B16))
A17: P15 | B17: P15 | C17: 1 | D17: 2026-11-18 | E17: 15:04 | F17: 1 | G17: Lab desktop (Key 0002) | H17: Operator_2 | I17: AB | J17: Shimmer3-B | K17: Good | L17: Yes | N17: =UPPER(TRIM(B17))
A18: P16 | B18: P16 | C18: 1 | D18: 2026-11-19 | E18: 09:06 | F18: 1 | G18: Lab desktop (Key 0002) | H18: Operator_2 | I18: BA | J18: Shimmer3-8956 | K18: Good | L18: Yes | N18: =UPPER(TRIM(B18))
A19: P17 | B19: P17 | C19: 1 | D19: 2026-11-19 | E19: 10:33 | F19: 1 | G19: Lab desktop (Key 0002) | H19: Operator_2 | I19: AB | J19: Shimmer3-8956 | K19: Good | L19: Yes | N19: =UPPER(TRIM(B19))
A20: P18 | B20: P18 | C20: 1 | D20: 2026-11-19 | E20: 12:06 | F20: 1 | G20: Lab desktop (Key 0002) | H20: Operator_2 | I20: BA | J20: Shimmer3-B | K20: Fair (2 attempts) | L20: Yes | M20: Wears glasses; reflections on the left lens; gaze lost often in the second ad. | N20: =UPPER(TRIM(B20))
A21: P19 | B21: P19 | C21: 1 | D21: 2026-11-19 | E21: 13:40 | F21: 1 | G21: Lab desktop (Key 0002) | H21: Operator_2 | I21: AB | J21: Shimmer3-B | K21: Good | L21: Yes | N21: =UPPER(TRIM(B21))
A22: P20 | B22: P20 | C22: 1 | D22: 2026-11-19 | E22: 15:00 | F22: 1 | G22: Lab desktop (Key 0002) | H22: Operator_2 | I22: BA | J22: Shimmer3-8956 | K22: Good | L22: Yes | N22: =UPPER(TRIM(B22))
A23: P21 | B23: P21 | C23: 1 | D23: 2026-11-20 | E23: 09:08 | F23: 1 | G23: Lab desktop (Key 0002) | H23: Operator_2 | I23: AB | J23: Shimmer3-8956 | K23: Good | L23: Yes | M23: Rested chin on hand during both ads; reminded once to sit back. | N23: =UPPER(TRIM(B23))
A24: P22 | B24: P22 | C24: 1 | D24: 2026-11-20 | E24: 10:39 | F24: 1 | G24: Lab desktop (Key 0002) | H24: Operator_2 | I24: BA | J24: Shimmer3-B | K24: Good | L24: Yes | M24: Started in a hurry (next participant waiting). | N24: =UPPER(TRIM(B24))
A25: P23 | B25: P23 | C25: 1 | D25: 2026-11-20 | E25: 12:02 | F25: 1 | G25: Lab desktop (Key 0002) | H25: Operator_2 | I25: AB | J25: Shimmer3-B | K25: Good | L25: Yes | N25: =UPPER(TRIM(B25))
A26: P24 | B26: P24 | C26: 1 | D26: 2026-11-20 | E26: 13:36 | F26: 1 | G26: Lab desktop (Key 0002) | H26: Operator_2 | I26: BA | J26: Shimmer3-8956 | K26: Good | L26: Yes | N26: =UPPER(TRIM(B26))

Sheet GSR_Import
A1: Study Name | B1: Respondent Name | C1: Gender | D1: Age | E1: Group | F1: Type | G1: Label | H1: Start (ms) | I1: Duration (ms) | J1: Signal Duration (ms) | K1: Parent Stimulus | L1: Has Peaks | M1: Peak Count | N1: Peaks Per Minute | O1: Average Peak Amplitude (microSiemens) | P1: Key = UPPER(TRIM()) | Q1: Participant | R1: Use recording | S1: Lookup key | T1: Signal share | U1: GSR valid (R3)
A2: SIMULATED Multimodal Ad Study | B2: P01 | C2: MALE | D2: 20 | E2: AB | F2: Stimulus | G2: Ad_A | H2: 80197 | I2: 30000 | J2: 30000 | K2: Ad_A | L2: 1 | M2: 3 | N2: 6 | O2: 0.2082 | P2: =UPPER(TRIM(B2)) | Q2: =IFERROR(INDEX(SessionLog!$A$2:$A$26,MATCH(P2,SessionLog!$N$2:$N$26,0)),"NOT FOUND") | R2: =IFERROR(INDEX(SessionLog!$L$2:$L$26,MATCH(P2,SessionLog!$N$2:$N$26,0)),"NOT FOUND") | S2: =IF(R2="Yes",Q2&"|"&F2&"|"&G2&"|"&K2,"DROP") | T2: =IF(I2>0,J2/I2,0) | U2: =IF(T2>=0.8,1,0)
A3: SIMULATED Multimodal Ad Study | B3: P01 | C3: MALE | D3: 20 | E3: AB | F3: Stimulus | G3: Ad_B | H3: 110268 | I3: 30000 | J3: 30000 | K3: Ad_B | L3: 1 | M3: 3 | N3: 6 | O3: 0.1469 | P3: =UPPER(TRIM(B3)) | Q3: =IFERROR(INDEX(SessionLog!$A$2:$A$26,MATCH(P3,SessionLog!$N$2:$N$26,0)),"NOT FOUND") | R3: =IFERROR(INDEX(SessionLog!$L$2:$L$26,MATCH(P3,SessionLog!$N$2:$N$26,0)),"NOT FOUND") | S3: =IF(R3="Yes",Q3&"|"&F3&"|"&G3&"|"&K3,"DROP") | T3: =IF(I3>0,J3/I3,0) | U3: =IF(T3>=0.8,1,0)
A4: SIMULATED Multimodal Ad Study | B4: P01 | C4: MALE | D4: 20 | E4: AB | F4: Stimulus | G4: Baseline | H4: 20126 | I4: 60000 | J4: 60000 | K4: Baseline | L4: 1 | M4: 1 | N4: 1 | O4: 0.0698 | P4: =UPPER(TRIM(B4)) | Q4: =IFERROR(INDEX(SessionLog!$A$2:$A$26,MATCH(P4,SessionLog!$N$2:$N$26,0)),"NOT FOUND") | R4: =IFERROR(INDEX(SessionLog!$L$2:$L$26,MATCH(P4,SessionLog!$N$2:$N$26,0)),"NOT FOUND") | S4: =IF(R4="Yes",Q4&"|"&F4&"|"&G4&"|"&K4,"DROP") | T4: =IF(I4>0,J4/I4,0) | U4: =IF(T4>=0.8,1,0)
A5: SIMULATED Multimodal Ad Study | B5: P01 | C5: MALE | D5: 20 | E5: AB | F5: Stimulus | G5: Instructions | H5: 18 | I5: 20078 | J5: 20078 | K5: Instructions | L5: 1 | M5: 1 | N5: 2.988 | O5: 0.149 | P5: =UPPER(TRIM(B5)) | Q5: =IFERROR(INDEX(SessionLog!$A$2:$A$26,MATCH(P5,SessionLog!$N$2:$N$26,0)),"NOT FOUND") | R5: =IFERROR(INDEX(SessionLog!$L$2:$L$26,MATCH(P5,SessionLog!$N$2:$N$26,0)),"NOT FOUND") | S5: =IF(R5="Yes",Q5&"|"&F5&"|"&G5&"|"&K5,"DROP") | T5: =IF(I5>0,J5/I5,0) | U5: =IF(T5>=0.8,1,0)
A6: SIMULATED Multimodal Ad Study | B6: P01 | C6: MALE | D6: 20 | E6: AB | F6: Stimulus | G6: Questionnaire | H6: 140318 | I6: 136885 | J6: 136885 | K6: Questionnaire | L6: 1 | M6: 4 | N6: 1.753 | O6: 0.1184 | P6: =UPPER(TRIM(B6)) | Q6: =IFERROR(INDEX(SessionLog!$A$2:$A$26,MATCH(P6,SessionLog!$N$2:$N$26,0)),"NOT FOUND") | R6: =IFERROR(INDEX(SessionLog!$L$2:$L$26,MATCH(P6,SessionLog!$N$2:$N$26,0)),"NOT FOUND") | S6: =IF(R6="Yes",Q6&"|"&F6&"|"&G6&"|"&K6,"DROP") | T6: =IF(I6>0,J6/I6,0) | U6: =IF(T6>=0.8,1,0)
A7: SIMULATED Multimodal Ad Study | B7: P01 | C7: MALE | D7: 20 | E7: AB | F7: Annotation | G7: EndCard | H7: 105197 | I7: 5000 | J7: 5000 | K7: Ad_A | L7: 0 | M7: 0 | N7: 0 | O7: NA | P7: =UPPER(TRIM(B7)) | Q7: =IFERROR(INDEX(SessionLog!$A$2:$A$26,MATCH(P7,SessionLog!$N$2:$N$26,0)),"NOT FOUND") | R7: =IFERROR(INDEX(SessionLog!$L$2:$L$26,MATCH(P7,SessionLog!$N$2:$N$26,0)),"NOT FOUND") | S7: =IF(R7="Yes",Q7&"|"&F7&"|"&G7&"|"&K7,"DROP") | T7: =IF(I7>0,J7/I7,0) | U7: =IF(T7>=0.8,1,0)
A8: SIMULATED Multimodal Ad Study | B8: P01 | C8: MALE | D8: 20 | E8: AB | F8: Annotation | G8: EndCard | H8: 135268 | I8: 5000 | J8: 5000 | K8: Ad_B | L8: 1 | M8: 1 | N8: 12 | O8: 0.0863 | P8: =UPPER(TRIM(B8)) | Q8: =IFERROR(INDEX(SessionLog!$A$2:$A$26,MATCH(P8,SessionLog!$N$2:$N$26,0)),"NOT FOUND") | R8: =IFERROR(INDEX(SessionLog!$L$2:$L$26,MATCH(P8,SessionLog!$N$2:$N$26,0)),"NOT FOUND") | S8: =IF(R8="Yes",Q8&"|"&F8&"|"&G8&"|"&K8,"DROP") | T8: =IF(I8>0,J8/I8,0) | U8: =IF(T8>=0.8,1,0)
A9: SIMULATED Multimodal Ad Study | B9: P02 | C9: FEMALE | D9: 21 | E9: BA | F9: Stimulus | G9: Ad_A | H9: 106389 | I9: 30000 | J9: 30000 | K9: Ad_A | L9: 1 | M9: 2 | N9: 4 | O9: 0.1116 | P9: =UPPER(TRIM(B9)) | Q9: =IFERROR(INDEX(SessionLog!$A$2:$A$26,MATCH(P9,SessionLog!$N$2:$N$26,0)),"NOT FOUND") | R9: =IFERROR(INDEX(SessionLog!$L$2:$L$26,MATCH(P9,SessionLog!$N$2:$N$26,0)),"NOT FOUND") | S9: =IF(R9="Yes",Q9&"|"&F9&"|"&G9&"|"&K9,"DROP") | T9: =IF(I9>0,J9/I9,0) | U9: =IF(T9>=0.8,1,0)
A10: SIMULATED Multimodal Ad Study | B10: P02 | C10: FEMALE | D10: 21 | E10: BA | F10: Stimulus | G10: Ad_B | H10: 76315 | I10: 30000 | J10: 30000 | K10: Ad_B | L10: 0 | M10: 0 | N10: 0 | O10: NA | P10: =UPPER(TRIM(B10)) | Q10: =IFERROR(INDEX(SessionLog!$A$2:$A$26,MATCH(P10,SessionLog!$N$2:$N$26,0)),"NOT FOUND") | R10: =IFERROR(INDEX(SessionLog!$L$2:$L$26,MATCH(P10,SessionLog!$N$2:$N$26,0)),"NOT FOUND") | S10: =IF(R10="Yes",Q10&"|"&F10&"|"&G10&"|"&K10,"DROP") | T10: =IF(I10>0,J10/I10,0) | U10: =IF(T10>=0.8,1,0)
A11: SIMULATED Multimodal Ad Study | B11: P02 | C11: FEMALE | D11: 21 | E11: BA | F11: Stimulus | G11: Baseline | H11: 16250 | I11: 60000 | J11: 60000 | K11: Baseline | L11: 0 | M11: 0 | N11: 0 | O11: NA | P11: =UPPER(TRIM(B11)) | Q11: =IFERROR(INDEX(SessionLog!$A$2:$A$26,MATCH(P11,SessionLog!$N$2:$N$26,0)),"NOT FOUND") | R11: =IFERROR(INDEX(SessionLog!$L$2:$L$26,MATCH(P11,SessionLog!$N$2:$N$26,0)),"NOT FOUND") | S11: =IF(R11="Yes",Q11&"|"&F11&"|"&G11&"|"&K11,"DROP") | T11: =IF(I11>0,J11/I11,0) | U11: =IF(T11>=0.8,1,0)
A12: SIMULATED Multimodal Ad Study | B12: P02 | C12: FEMALE | D12: 21 | E12: BA | F12: Stimulus | G12: Instructions | H12: 22 | I12: 16186 | J12: 16186 | K12: Instructions | L12: 0 | M12: 0 | N12: 0 | O12: NA | P12: =UPPER(TRIM(B12)) | Q12: =IFERROR(INDEX(SessionLog!$A$2:$A$26,MATCH(P12,SessionLog!$N$2:$N$26,0)),"NOT FOUND") | R12: =IFERROR(INDEX(SessionLog!$L$2:$L$26,MATCH(P12,SessionLog!$N$2:$N$26,0)),"NOT FOUND") | S12: =IF(R12="Yes",Q12&"|"&F12&"|"&G12&"|"&K12,"DROP") | T12: =IF(I12>0,J12/I12,0) | U12: =IF(T12>=0.8,1,0)
A13: SIMULATED Multimodal Ad Study | B13: P02 | C13: FEMALE | D13: 21 | E13: BA | F13: Stimulus | G13: Questionnaire | H13: 136421 | I13: 95173 | J13: 95173 | K13: Questionnaire | L13: 1 | M13: 4 | N13: 2.522 | O13: 0.2783 | P13: =UPPER(TRIM(B13)) | Q13: =IFERROR(INDEX(SessionLog!$A$2:$A$26,MATCH(P13,SessionLog!$N$2:$N$26,0)),"NOT FOUND") | R13: =IFERROR(INDEX(SessionLog!$L$2:$L$26,MATCH(P13,SessionLog!$N$2:$N$26,0)),"NOT FOUND") | S13: =IF(R13="Yes",Q13&"|"&F13&"|"&G13&"|"&K13,"DROP") | T13: =IF(I13>0,J13/I13,0) | U13: =IF(T13>=0.8,1,0)
A14: SIMULATED Multimodal Ad Study | B14: P02 | C14: FEMALE | D14: 21 | E14: BA | F14: Annotation | G14: EndCard | H14: 131389 | I14: 5000 | J14: 5000 | K14: Ad_A | L14: 1 | M14: 1 | N14: 12 | O14: 0.08 | P14: =UPPER(TRIM(B14)) | Q14: =IFERROR(INDEX(SessionLog!$A$2:$A$26,MATCH(P14,SessionLog!$N$2:$N$26,0)),"NOT FOUND") | R14: =IFERROR(INDEX(SessionLog!$L$2:$L$26,MATCH(P14,SessionLog!$N$2:$N$26,0)),"NOT FOUND") | S14: =IF(R14="Yes",Q14&"|"&F14&"|"&G14&"|"&K14,"DROP") | T14: =IF(I14>0,J14/I14,0) | U14: =IF(T14>=0.8,1,0)
A15: SIMULATED Multimodal Ad Study | B15: P02 | C15: FEMALE | D15: 21 | E15: BA | F15: Annotation | G15: EndCard | H15: 101315 | I15: 5000 | J15: 5000 | K15: Ad_B | L15: 0 | M15: 0 | N15: 0 | O15: NA | P15: =UPPER(TRIM(B15)) | Q15: =IFERROR(INDEX(SessionLog!$A$2:$A$26,MATCH(P15,SessionLog!$N$2:$N$26,0)),"NOT FOUND") | R15: =IFERROR(INDEX(SessionLog!$L$2:$L$26,MATCH(P15,SessionLog!$N$2:$N$26,0)),"NOT FOUND") | S15: =IF(R15="Yes",Q15&"|"&F15&"|"&G15&"|"&K15,"DROP") | T15: =IF(I15>0,J15/I15,0) | U15: =IF(T15>=0.8,1,0)
A16: SIMULATED Multimodal Ad Study | B16: P03 | C16: MALE | D16: 21 | E16: AB | F16: Stimulus | G16: Ad_A | H16: 87922 | I16: 30000 | J16: 30000 | K16: Ad_A | L16: 1 | M16: 11 | N16: 22 | O16: 0.158 | P16: =UPPER(TRIM(B16)) | Q16: =IFERROR(INDEX(SessionLog!$A$2:$A$26,MATCH(P16,SessionLog!$N$2:$N$26,0)),"NOT FOUND") | R16: =IFERROR(INDEX(SessionLog!$L$2:$L$26,MATCH(P16,SessionLog!$N$2:$N$26,0)),"NOT FOUND") | S16: =IF(R16="Yes",Q16&"|"&F16&"|"&G16&"|"&K16,"DROP") | T16: =IF(I16>0,J16/I16,0) | U16: =IF(T16>=0.8,1,0)
A17: SIMULATED Multimodal Ad Study | B17: P03 | C17: MALE | D17: 21 | E17: AB | F17: Stimulus | G17: Ad_B | H17: 118011 | I17: 30000 | J17: 30000 | K17: Ad_B | L17: 1 | M17: 8 | N17: 16 | O17: 0.1617 | P17: =UPPER(TRIM(B17)) | Q17: =IFERROR(INDEX(SessionLog!$A$2:$A$26,MATCH(P17,SessionLog!$N$2:$N$26,0)),"NOT FOUND") | R17: =IFERROR(INDEX(SessionLog!$L$2:$L$26,MATCH(P17,SessionLog!$N$2:$N$26,0)),"NOT FOUND") | S17: =IF(R17="Yes",Q17&"|"&F17&"|"&G17&"|"&K17,"DROP") | T17: =IF(I17>0,J17/I17,0) | U17: =IF(T17>=0.8,1,0)
A18: SIMULATED Multimodal Ad Study | B18: P03 | C18: MALE | D18: 21 | E18: AB | F18: Stimulus | G18: Baseline | H18: 27838 | I18: 60000 | J18: 60000 | K18: Baseline | L18: 1 | M18: 2 | N18: 2 | O18: 0.0599 | P18: =UPPER(TRIM(B18)) | Q18: =IFERROR(INDEX(SessionLog!$A$2:$A$26,MATCH(P18,SessionLog!$N$2:$N$26,0)),"NOT FOUND") | R18: =IFERROR(INDEX(SessionLog!$L$2:$L$26,MATCH(P18,SessionLog!$N$2:$N$26,0)),"NOT FOUND") | S18: =IF(R18="Yes",Q18&"|"&F18&"|"&G18&"|"&K18,"DROP") | T18: =IF(I18>0,J18/I18,0) | U18: =IF(T18>=0.8,1,0)
A19: SIMULATED Multimodal Ad Study | B19: P03 | C19: MALE | D19: 21 | E19: AB | F19: Stimulus | G19: Instructions | H19: 29 | I19: 27765 | J19: 27765 | K19: Instructions | L19: 1 | M19: 2 | N19: 4.322 | O19: 0.182 | P19: =UPPER(TRIM(B19)) | Q19: =IFERROR(INDEX(SessionLog!$A$2:$A$26,MATCH(P19,SessionLog!$N$2:$N$26,0)),"NOT FOUND") | R19: =IFERROR(INDEX(SessionLog!$L$2:$L$26,MATCH(P19,SessionLog!$N$2:$N$26,0)),"NOT FOUND") | S19: =IF(R19="Yes",Q19&"|"&F19&"|"&G19&"|"&K19,"DROP") | T19: =IF(I19>0,J19/I19,0) | U19: =IF(T19>=0.8,1,0)
A20: SIMULATED Multimodal Ad Study | B20: P03 | C20: MALE | D20: 21 | E20: AB | F20: Stimulus | G20: Questionnaire | H20: 148055 | I20: 111565 | J20: 111565 | K20: Questionnaire | L20: 1 | M20: 6 | N20: 3.227 | O20: 0.2739 | P20: =UPPER(TRIM(B20)) | Q20: =IFERROR(INDEX(SessionLog!$A$2:$A$26,MATCH(P20,SessionLog!$N$2:$N$26,0)),"NOT FOUND") | R20: =IFERROR(INDEX(SessionLog!$L$2:$L$26,MATCH(P20,SessionLog!$N$2:$N$26,0)),"NOT FOUND") | S20: =IF(R20="Yes",Q20&"|"&F20&"|"&G20&"|"&K20,"DROP") | T20: =IF(I20>0,J20/I20,0) | U20: =IF(T20>=0.8,1,0)
A21: SIMULATED Multimodal Ad Study | B21: P03 | C21: MALE | D21: 21 | E21: AB | F21: Annotation | G21: EndCard | H21: 112922 | I21: 5000 | J21: 5000 | K21: Ad_A | L21: 1 | M21: 3 | N21: 36 | O21: 0.2457 | P21: =UPPER(TRIM(B21)) | Q21: =IFERROR(INDEX(SessionLog!$A$2:$A$26,MATCH(P21,SessionLog!$N$2:$N$26,0)),"NOT FOUND") | R21: =IFERROR(INDEX(SessionLog!$L$2:$L$26,MATCH(P21,SessionLog!$N$2:$N$26,0)),"NOT FOUND") | S21: =IF(R21="Yes",Q21&"|"&F21&"|"&G21&"|"&K21,"DROP") | T21: =IF(I21>0,J21/I21,0) | U21: =IF(T21>=0.8,1,0)
A22: SIMULATED Multimodal Ad Study | B22: P03 | C22: MALE | D22: 21 | E22: AB | F22: Annotation | G22: EndCard | H22: 143011 | I22: 5000 | J22: 5000 | K22: Ad_B | L22: 1 | M22: 1 | N22: 12 | O22: 0.0726 | P22: =UPPER(TRIM(B22)) | Q22: =IFERROR(INDEX(SessionLog!$A$2:$A$26,MATCH(P22,SessionLog!$N$2:$N$26,0)),"NOT FOUND") | R22: =IFERROR(INDEX(SessionLog!$L$2:$L$26,MATCH(P22,SessionLog!$N$2:$N$26,0)),"NOT FOUND") | S22: =IF(R22="Yes",Q22&"|"&F22&"|"&G22&"|"&K22,"DROP") | T22: =IF(I22>0,J22/I22,0) | U22: =IF(T22>=0.8,1,0)
A23: SIMULATED Multimodal Ad Study | B23: P04 | C23: FEMALE | D23: 22 | E23: BA | F23: Stimulus | G23: Baseline | H23: 13727 | I23: 23585 | J23: 23585 | K23: Baseline | L23: 1 | M23: 3 | N23: 7.632 | O23: 0.1326 | P23: =UPPER(TRIM(B23)) | Q23: =IFERROR(INDEX(SessionLog!$A$2:$A$26,MATCH(P23,SessionLog!$N$2:$N$26,0)),"NOT FOUND") | R23: =IFERROR(INDEX(SessionLog!$L$2:$L$26,MATCH(P23,SessionLog!$N$2:$N$26,0)),"NOT FOUND") | S23: =IF(R23="Yes",Q23&"|"&F23&"|"&G23&"|"&K23,"DROP") | T23: =IF(I23>0,J23/I23,0) | U23: =IF(T23>=0.8,1,0)
A24: SIMULATED Multimodal Ad Study | B24: P04 | C24: FEMALE | D24: 22 | E24: BA | F24: Stimulus | G24: Instructions | H24: 39 | I24: 13648 | J24: 13648 | K24: Instructions | L24: 1 | M24: 1 | N24: 4.396 | O24: 0.2811 | P24: =UPPER(TRIM(B24)) | Q24: =IFERROR(INDEX(SessionLog!$A$2:$A$26,MATCH(P24,SessionLog!$N$2:$N$26,0)),"NOT FOUND") | R24: =IFERROR(INDEX(SessionLog!$L$2:$L$26,MATCH(P24,SessionLog!$N$2:$N$26,0)),"NOT FOUND") | S24: =IF(R24="Yes",Q24&"|"&F24&"|"&G24&"|"&K24,"DROP") | T24: =IF(I24>0,J24/I24,0) | U24: =IF(T24>=0.8,1,0)
A25: SIMULATED Multimodal Ad Study | B25: P04_rerun | C25: FEMALE | D25: 22 | E25: BA | F25: Stimulus | G25: Ad_A | H25: 107234 | I25: 30000 | J25: 30000 | K25: Ad_A | L25: 0 | M25: 0 | N25: 0 | O25: NA | P25: =UPPER(TRIM(B25)) | Q25: =IFERROR(INDEX(SessionLog!$A$2:$A$26,MATCH(P25,SessionLog!$N$2:$N$26,0)),"NOT FOUND") | R25: =IFERROR(INDEX(SessionLog!$L$2:$L$26,MATCH(P25,SessionLog!$N$2:$N$26,0)),"NOT FOUND") | S25: =IF(R25="Yes",Q25&"|"&F25&"|"&G25&"|"&K25,"DROP") | T25: =IF(I25>0,J25/I25,0) | U25: =IF(T25>=0.8,1,0)
A26: SIMULATED Multimodal Ad Study | B26: P04_rerun | C26: FEMALE | D26: 22 | E26: BA | F26: Stimulus | G26: Ad_B | H26: 77182 | I26: 30000 | J26: 30000 | K26: Ad_B | L26: 1 | M26: 4 | N26: 8 | O26: 0.2299 | P26: =UPPER(TRIM(B26)) | Q26: =IFERROR(INDEX(SessionLog!$A$2:$A$26,MATCH(P26,SessionLog!$N$2:$N$26,0)),"NOT FOUND") | R26: =IFERROR(INDEX(SessionLog!$L$2:$L$26,MATCH(P26,SessionLog!$N$2:$N$26,0)),"NOT FOUND") | S26: =IF(R26="Yes",Q26&"|"&F26&"|"&G26&"|"&K26,"DROP") | T26: =IF(I26>0,J26/I26,0) | U26: =IF(T26>=0.8,1,0)
A27: SIMULATED Multimodal Ad Study | B27: P04_rerun | C27: FEMALE | D27: 22 | E27: BA | F27: Stimulus | G27: Baseline | H27: 17098 | I27: 60000 | J27: 60000 | K27: Baseline | L27: 1 | M27: 5 | N27: 5 | O27: 0.17 | P27: =UPPER(TRIM(B27)) | Q27: =IFERROR(INDEX(SessionLog!$A$2:$A$26,MATCH(P27,SessionLog!$N$2:$N$26,0)),"NOT FOUND") | R27: =IFERROR(INDEX(SessionLog!$L$2:$L$26,MATCH(P27,SessionLog!$N$2:$N$26,0)),"NOT FOUND") | S27: =IF(R27="Yes",Q27&"|"&F27&"|"&G27&"|"&K27,"DROP") | T27: =IF(I27>0,J27/I27,0) | U27: =IF(T27>=0.8,1,0)
A28: SIMULATED Multimodal Ad Study | B28: P04_rerun | C28: FEMALE | D28: 22 | E28: BA | F28: Stimulus | G28: Instructions | H28: 28 | I28: 17024 | J28: 17024 | K28: Instructions | L28: 1 | M28: 1 | N28: 3.524 | O28: 0.0839 | P28: =UPPER(TRIM(B28)) | Q28: =IFERROR(INDEX(SessionLog!$A$2:$A$26,MATCH(P28,SessionLog!$N$2:$N$26,0)),"NOT FOUND") | R28: =IFERROR(INDEX(SessionLog!$L$2:$L$26,MATCH(P28,SessionLog!$N$2:$N$26,0)),"NOT FOUND") | S28: =IF(R28="Yes",Q28&"|"&F28&"|"&G28&"|"&K28,"DROP") | T28: =IF(I28>0,J28/I28,0) | U28: =IF(T28>=0.8,1,0)
A29: SIMULATED Multimodal Ad Study | B29: P04_rerun | C29: FEMALE | D29: 22 | E29: BA | F29: Stimulus | G29: Questionnaire | H29: 137272 | I29: 149547 | J29: 149547 | K29: Questionnaire | L29: 1 | M29: 12 | N29: 4.815 | O29: 0.1544 | P29: =UPPER(TRIM(B29)) | Q29: =IFERROR(INDEX(SessionLog!$A$2:$A$26,MATCH(P29,SessionLog!$N$2:$N$26,0)),"NOT FOUND") | R29: =IFERROR(INDEX(SessionLog!$L$2:$L$26,MATCH(P29,SessionLog!$N$2:$N$26,0)),"NOT FOUND") | S29: =IF(R29="Yes",Q29&"|"&F29&"|"&G29&"|"&K29,"DROP") | T29: =IF(I29>0,J29/I29,0) | U29: =IF(T29>=0.8,1,0)
A30: SIMULATED Multimodal Ad Study | B30: P04_rerun | C30: FEMALE | D30: 22 | E30: BA | F30: Annotation | G30: EndCard | H30: 132234 | I30: 5000 | J30: 5000 | K30: Ad_A | L30: 0 | M30: 0 | N30: 0 | O30: NA | P30: =UPPER(TRIM(B30)) | Q30: =IFERROR(INDEX(SessionLog!$A$2:$A$26,MATCH(P30,SessionLog!$N$2:$N$26,0)),"NOT FOUND") | R30: =IFERROR(INDEX(SessionLog!$L$2:$L$26,MATCH(P30,SessionLog!$N$2:$N$26,0)),"NOT FOUND") | S30: =IF(R30="Yes",Q30&"|"&F30&"|"&G30&"|"&K30,"DROP") | T30: =IF(I30>0,J30/I30,0) | U30: =IF(T30>=0.8,1,0)
A31: SIMULATED Multimodal Ad Study | B31: P04_rerun | C31: FEMALE | D31: 22 | E31: BA | F31: Annotation | G31: EndCard | H31: 102182 | I31: 5000 | J31: 5000 | K31: Ad_B | L31: 0 | M31: 0 | N31: 0 | O31: NA | P31: =UPPER(TRIM(B31)) | Q31: =IFERROR(INDEX(SessionLog!$A$2:$A$26,MATCH(P31,SessionLog!$N$2:$N$26,0)),"NOT FOUND") | R31: =IFERROR(INDEX(SessionLog!$L$2:$L$26,MATCH(P31,SessionLog!$N$2:$N$26,0)),"NOT FOUND") | S31: =IF(R31="Yes",Q31&"|"&F31&"|"&G31&"|"&K31,"DROP") | T31: =IF(I31>0,J31/I31,0) | U31: =IF(T31>=0.8,1,0)
A32: SIMULATED Multimodal Ad Study | B32: P05 | C32: FEMALE | D32: 20 | E32: AB | F32: Stimulus | G32: Ad_A | H32: 78150 | I32: 30000 | J32: 30000 | K32: Ad_A | L32: 1 | M32: 6 | N32: 12 | O32: 0.082 | P32: =UPPER(TRIM(B32)) | Q32: =IFERROR(INDEX(SessionLog!$A$2:$A$26,MATCH(P32,SessionLog!$N$2:$N$26,0)),"NOT FOUND") | R32: =IFERROR(INDEX(SessionLog!$L$2:$L$26,MATCH(P32,SessionLog!$N$2:$N$26,0)),"NOT FOUND") | S32: =IF(R32="Yes",Q32&"|"&F32&"|"&G32&"|"&K32,"DROP") | T32: =IF(I32>0,J32/I32,0) | U32: =IF(T32>=0.8,1,0)
A33: SIMULATED Multimodal Ad Study | B33: P05 | C33: FEMALE | D33: 20 | E33: AB | F33: Stimulus | G33: Ad_B | H33: 108252 | I33: 30000 | J33: 7812 | K33: Ad_B | L33: 1 | M33: 1 | N33: 7.68 | O33: 0.2694 | P33: =UPPER(TRIM(B33)) | Q33: =IFERROR(INDEX(SessionLog!$A$2:$A$26,MATCH(P33,SessionLog!$N$2:$N$26,0)),"NOT FOUND") | R33: =IFERROR(INDEX(SessionLog!$L$2:$L$26,MATCH(P33,SessionLog!$N$2:$N$26,0)),"NOT FOUND") | S33: =IF(R33="Yes",Q33&"|"&F33&"|"&G33&"|"&K33,"DROP") | T33: =IF(I33>0,J33/I33,0) | U33: =IF(T33>=0.8,1,0)
A34: SIMULATED Multimodal Ad Study | B34: P05 | C34: FEMALE | D34: 20 | E34: AB | F34: Stimulus | G34: Baseline | H34: 18034 | I34: 60000 | J34: 60000 | K34: Baseline | L34: 1 | M34: 6 | N34: 6 | O34: 0.3076 | P34: =UPPER(TRIM(B34)) | Q34: =IFERROR(INDEX(SessionLog!$A$2:$A$26,MATCH(P34,SessionLog!$N$2:$N$26,0)),"NOT FOUND") | R34: =IFERROR(INDEX(SessionLog!$L$2:$L$26,MATCH(P34,SessionLog!$N$2:$N$26,0)),"NOT FOUND") | S34: =IF(R34="Yes",Q34&"|"&F34&"|"&G34&"|"&K34,"DROP") | T34: =IF(I34>0,J34/I34,0) | U34: =IF(T34>=0.8,1,0)
A35: SIMULATED Multimodal Ad Study | B35: P05 | C35: FEMALE | D35: 20 | E35: AB | F35: Stimulus | G35: Instructions | H35: 17 | I35: 17988 | J35: 17988 | K35: Instructions | L35: 1 | M35: 1 | N35: 3.336 | O35: 0.1312 | P35: =UPPER(TRIM(B35)) | Q35: =IFERROR(INDEX(SessionLog!$A$2:$A$26,MATCH(P35,SessionLog!$N$2:$N$26,0)),"NOT FOUND") | R35: =IFERROR(INDEX(SessionLog!$L$2:$L$26,MATCH(P35,SessionLog!$N$2:$N$26,0)),"NOT FOUND") | S35: =IF(R35="Yes",Q35&"|"&F35&"|"&G35&"|"&K35,"DROP") | T35: =IF(I35>0,J35/I35,0) | U35: =IF(T35>=0.8,1,0)
A36: SIMULATED Multimodal Ad Study | B36: P05 | C36: FEMALE | D36: 20 | E36: AB | F36: Stimulus | G36: Questionnaire | H36: 138299 | I36: 153662 | J36: 0 | K36: Questionnaire | L36: 0 | M36: 0 | N36: NA | O36: NA | P36: =UPPER(TRIM(B36)) | Q36: =IFERROR(INDEX(SessionLog!$A$2:$A$26,MATCH(P36,SessionLog!$N$2:$N$26,0)),"NOT FOUND") | R36: =IFERROR(INDEX(SessionLog!$L$2:$L$26,MATCH(P36,SessionLog!$N$2:$N$26,0)),"NOT FOUND") | S36: =IF(R36="Yes",Q36&"|"&F36&"|"&G36&"|"&K36,"DROP") | T36: =IF(I36>0,J36/I36,0) | U36: =IF(T36>=0.8,1,0)
A37: SIMULATED Multimodal Ad Study | B37: P05 | C37: FEMALE | D37: 20 | E37: AB | F37: Annotation | G37: EndCard | H37: 103150 | I37: 5000 | J37: 5000 | K37: Ad_A | L37: 0 | M37: 0 | N37: 0 | O37: NA | P37: =UPPER(TRIM(B37)) | Q37: =IFERROR(INDEX(SessionLog!$A$2:$A$26,MATCH(P37,SessionLog!$N$2:$N$26,0)),"NOT FOUND") | R37: =IFERROR(INDEX(SessionLog!$L$2:$L$26,MATCH(P37,SessionLog!$N$2:$N$26,0)),"NOT FOUND") | S37: =IF(R37="Yes",Q37&"|"&F37&"|"&G37&"|"&K37,"DROP") | T37: =IF(I37>0,J37/I37,0) | U37: =IF(T37>=0.8,1,0)
A38: SIMULATED Multimodal Ad Study | B38: P05 | C38: FEMALE | D38: 20 | E38: AB | F38: Annotation | G38: EndCard | H38: 133252 | I38: 5000 | J38: 0 | K38: Ad_B | L38: 0 | M38: 0 | N38: NA | O38: NA | P38: =UPPER(TRIM(B38)) | Q38: =IFERROR(INDEX(SessionLog!$A$2:$A$26,MATCH(P38,SessionLog!$N$2:$N$26,0)),"NOT FOUND") | R38: =IFERROR(INDEX(SessionLog!$L$2:$L$26,MATCH(P38,SessionLog!$N$2:$N$26,0)),"NOT FOUND") | S38: =IF(R38="Yes",Q38&"|"&F38&"|"&G38&"|"&K38,"DROP") | T38: =IF(I38>0,J38/I38,0) | U38: =IF(T38>=0.8,1,0)
A39: SIMULATED Multimodal Ad Study | B39: P06 | C39: FEMALE | D39: 26 | E39: BA | F39: Stimulus | G39: Ad_A | H39: 116781 | I39: 30000 | J39: 30000 | K39: Ad_A | L39: 1 | M39: 2 | N39: 4 | O39: 0.091 | P39: =UPPER(TRIM(B39)) | Q39: =IFERROR(INDEX(SessionLog!$A$2:$A$26,MATCH(P39,SessionLog!$N$2:$N$26,0)),"NOT FOUND") | R39: =IFERROR(INDEX(SessionLog!$L$2:$L$26,MATCH(P39,SessionLog!$N$2:$N$26,0)),"NOT FOUND") | S39: =IF(R39="Yes",Q39&"|"&F39&"|"&G39&"|"&K39,"DROP") | T39: =IF(I39>0,J39/I39,0) | U39: =IF(T39>=0.8,1,0)
A40: SIMULATED Multimodal Ad Study | B40: P06 | C40: FEMALE | D40: 26 | E40: BA | F40: Stimulus | G40: Ad_B | H40: 86693 | I40: 30000 | J40: 30000 | K40: Ad_B | L40: 1 | M40: 1 | N40: 2 | O40: 0.1239 | P40: =UPPER(TRIM(B40)) | Q40: =IFERROR(INDEX(SessionLog!$A$2:$A$26,MATCH(P40,SessionLog!$N$2:$N$26,0)),"NOT FOUND") | R40: =IFERROR(INDEX(SessionLog!$L$2:$L$26,MATCH(P40,SessionLog!$N$2:$N$26,0)),"NOT FOUND") | S40: =IF(R40="Yes",Q40&"|"&F40&"|"&G40&"|"&K40,"DROP") | T40: =IF(I40>0,J40/I40,0) | U40: =IF(T40>=0.8,1,0)
...

Sheet Survey
A1: STUDY | B1: RESPONDENT | C1: GENDER | D1: AGE | E1: GROUP | F1: LABELID_Questionnaire_Liking_A,Question1 "How much did you like the hiking ad? (1 = not at all, 7 = very much)" | G1: LABELVALUE_Questionnaire_Liking_A,Question1 "How much did you like the hiking ad? (1 = not at all, 7 = very much)" | H1: LABELID_Questionnaire_Liking_B,Question1 "How much did you like the cycling ad? (1 = not at all, 7 = very much)" | I1: LABELVALUE_Questionnaire_Liking_B,Question1 "How much did you like the cycling ad? (1 = not at all, 7 = very much)" | J1: LABELID_Questionnaire_Recall_A,Question1 "Which brand was advertised in the hiking ad?" | K1: LABELVALUE_Questionnaire_Recall_A,Question1 "Which brand was advertised in the hiking ad?" | L1: LABELID_Questionnaire_Recall_B,Question1 "Which brand was advertised in the cycling ad?" | M1: LABELVALUE_Questionnaire_Recall_B,Question1 "Which brand was advertised in the cycling ad?" | N1: LABELID_Questionnaire_ATT_1,Question1 "I like reusable water bottles. (1 = strongly disagree, 7 = strongly agree)" | O1: LABELVALUE_Questionnaire_ATT_1,Question1 "I like reusable water bottles. (1 = strongly disagree, 7 = strongly agree)" | P1: LABELID_Questionnaire_ATT_2,Question1 "Buying a reusable water bottle is a smart choice. (1 = strongly disagree, 7 = strongly agree)" | Q1: LABELVALUE_Questionnaire_ATT_2,Question1 "Buying a reusable water bottle is a smart choice. (1 = strongly disagree, 7 = strongly agree)" | R1: LABELID_Questionnaire_ATT_3R,Question1 "Reusable water bottles are a waste of money. (1 = strongly disagree, 7 = strongly agree)" | S1: LABELVALUE_Questionnaire_ATT_3R,Question1 "Reusable water bottles are a waste of money. (1 = strongly disagree, 7 = strongly agree)" | T1: LABELID_Questionnaire_PI,Question1 "How likely are you to buy a reusable water bottle in the next three months? (1 = very unlikely, 7 = very likely)" | U1: LABELVALUE_Questionnaire_PI,Question1 "How likely are you to buy a reusable water bottle in the next three months? (1 = very unlikely, 7 = very likely)" | V1: Key = UPPER(TRIM()) | W1: Participant | X1: Recall_A correct | Y1: Recall_B correct | Z1: ATT_3 recoded | AA1: Attitude | AB1: Sum (recoded) | AC1: Sum (not recoded) | AE1: Cronbach's alpha (k = 3)
A2: SIMULATED Multimodal Ad Study | B2: P01 | C2: MALE | D2: 20 | E2: AB | F2: Label4 | G2: 4 | H2: Label5 | I2: 5 | J2: Label4 | K2: 4 | L2: Label2 | M2: 2 | N2: Label5 | O2: 5 | P2: Label4 | Q2: 4 | R2: Label5 | S2: 5 | T2: Label3 | U2: 3 | V2: =UPPER(TRIM(B2)) | W2: =IFERROR(INDEX(SessionLog!$A$2:$A$26,MATCH(V2,SessionLog!$N$2:$N$26,0)),"NOT FOUND") | X2: =IF(K2=1,1,0) | Y2: =IF(M2=2,1,0) | Z2: =8-S2 | AA2: =AVERAGE(O2,Q2,Z2) | AB2: =O2+Q2+Z2 | AC2: =O2+Q2+S2 | AE2: With ATT_3R recoded | AF2: =3/2*(1-(_xlfn.VAR.S(O2:O25)+_xlfn.VAR.S(Q2:Q25)+_xlfn.VAR.S(Z2:Z25))/_xlfn.VAR.S(AB2:AB25))
A3: SIMULATED Multimodal Ad Study | B3: P02 | C3: FEMALE | D3: 21 | E3: BA | F3: Label5 | G3: 5 | H3: Label6 | I3: 6 | J3: Label5 | K3: 5 | L3: Label5 | M3: 5 | N3: Label4 | O3: 4 | P3: Label4 | Q3: 4 | R3: Label3 | S3: 3 | T3: Label3 | U3: 3 | V3: =UPPER(TRIM(B3)) | W3: =IFERROR(INDEX(SessionLog!$A$2:$A$26,MATCH(V3,SessionLog!$N$2:$N$26,0)),"NOT FOUND") | X3: =IF(K3=1,1,0) | Y3: =IF(M3=2,1,0) | Z3: =8-S3 | AA3: =AVERAGE(O3,Q3,Z3) | AB3: =O3+Q3+Z3 | AC3: =O3+Q3+S3 | AE3: Without recoding (the mistake) | AF3: =3/2*(1-(_xlfn.VAR.S(O2:O25)+_xlfn.VAR.S(Q2:Q25)+_xlfn.VAR.S(S2:S25))/_xlfn.VAR.S(AC2:AC25))
A4: SIMULATED Multimodal Ad Study | B4: P03 | C4: MALE | D4: 21 | E4: AB | F4: Label5 | G4: 5 | H4: Label6 | I4: 6 | J4: Label1 | K4: 1 | L4: Label1 | M4: 1 | N4: Label6 | O4: 6 | P4: Label6 | Q4: 6 | R4: Label2 | S4: 2 | T4: Label4 | U4: 4 | V4: =UPPER(TRIM(B4)) | W4: =IFERROR(INDEX(SessionLog!$A$2:$A$26,MATCH(V4,SessionLog!$N$2:$N$26,0)),"NOT FOUND") | X4: =IF(K4=1,1,0) | Y4: =IF(M4=2,1,0) | Z4: =8-S4 | AA4: =AVERAGE(O4,Q4,Z4) | AB4: =O4+Q4+Z4 | AC4: =O4+Q4+S4
A5: SIMULATED Multimodal Ad Study | B5: P04_rerun | C5: FEMALE | D5: 22 | E5: BA | F5: Label6 | G5: 6 | H5: Label4 | I5: 4 | J5: Label1 | K5: 1 | L5: Label2 | M5: 2 | N5: Label4 | O5: 4 | P5: Label5 | Q5: 5 | R5: Label4 | S5: 4 | T5: Label3 | U5: 3 | V5: =UPPER(TRIM(B5)) | W5: =IFERROR(INDEX(SessionLog!$A$2:$A$26,MATCH(V5,SessionLog!$N$2:$N$26,0)),"NOT FOUND") | X5: =IF(K5=1,1,0) | Y5: =IF(M5=2,1,0) | Z5: =8-S5 | AA5: =AVERAGE(O5,Q5,Z5) | AB5: =O5+Q5+Z5 | AC5: =O5+Q5+S5
A6: SIMULATED Multimodal Ad Study | B6: P05 | C6: FEMALE | D6: 20 | E6: AB | F6: Label5 | G6: 5 | H6: Label3 | I6: 3 | J6: Label5 | K6: 5 | L6: Label2 | M6: 2 | N6: Label5 | O6: 5 | P6: Label5 | Q6: 5 | R6: Label3 | S6: 3 | T6: Label5 | U6: 5 | V6: =UPPER(TRIM(B6)) | W6: =IFERROR(INDEX(SessionLog!$A$2:$A$26,MATCH(V6,SessionLog!$N$2:$N$26,0)),"NOT FOUND") | X6: =IF(K6=1,1,0) | Y6: =IF(M6=2,1,0) | Z6: =8-S6 | AA6: =AVERAGE(O6,Q6,Z6) | AB6: =O6+Q6+Z6 | AC6: =O6+Q6+S6
A7: SIMULATED Multimodal Ad Study | B7: P06 | C7: FEMALE | D7: 26 | E7: BA | F7: Label4 | G7: 4 | H7: Label6 | I7: 6 | J7: Label5 | K7: 5 | L7: Label1 | M7: 1 | N7: Label5 | O7: 5 | P7: Label4 | Q7: 4 | R7: Label4 | S7: 4 | T7: Label2 | U7: 2 | V7: =UPPER(TRIM(B7)) | W7: =IFERROR(INDEX(SessionLog!$A$2:$A$26,MATCH(V7,SessionLog!$N$2:$N$26,0)),"NOT FOUND") | X7: =IF(K7=1,1,0) | Y7: =IF(M7=2,1,0) | Z7: =8-S7 | AA7: =AVERAGE(O7,Q7,Z7) | AB7: =O7+Q7+Z7 | AC7: =O7+Q7+S7
A8: SIMULATED Multimodal Ad Study | B8: p07 | C8: FEMALE | D8: 23 | E8: AB | F8: Label6 | G8: 6 | H8: Label4 | I8: 4 | J8: Label1 | K8: 1 | L8: Label2 | M8: 2 | N8: Label7 | O8: 7 | P8: Label6 | Q8: 6 | R8: Label1 | S8: 1 | T8: Label5 | U8: 5 | V8: =UPPER(TRIM(B8)) | W8: =IFERROR(INDEX(SessionLog!$A$2:$A$26,MATCH(V8,SessionLog!$N$2:$N$26,0)),"NOT FOUND") | X8: =IF(K8=1,1,0) | Y8: =IF(M8=2,1,0) | Z8: =8-S8 | AA8: =AVERAGE(O8,Q8,Z8) | AB8: =O8+Q8+Z8 | AC8: =O8+Q8+S8
A9: SIMULATED Multimodal Ad Study | B9: P08 | C9: FEMALE | D9: 21 | E9: BA | F9: Label3 | G9: 3 | H9: Label5 | I9: 5 | J9: Label1 | K9: 1 | L9: Label1 | M9: 1 | N9: Label6 | O9: 6 | P9: Label5 | Q9: 5 | R9: Label3 | S9: 3 | T9: Label5 | U9: 5 | V9: =UPPER(TRIM(B9)) | W9: =IFERROR(INDEX(SessionLog!$A$2:$A$26,MATCH(V9,SessionLog!$N$2:$N$26,0)),"NOT FOUND") | X9: =IF(K9=1,1,0) | Y9: =IF(M9=2,1,0) | Z9: =8-S9 | AA9: =AVERAGE(O9,Q9,Z9) | AB9: =O9+Q9+Z9 | AC9: =O9+Q9+S9
A10: SIMULATED Multimodal Ad Study | B10: P09 | C10: FEMALE | D10: 20 | E10: AB | F10: Label5 | G10: 5 | H10: Label3 | I10: 3 | J10: Label1 | K10: 1 | L10: Label5 | M10: 5 | N10: Label5 | O10: 5 | P10: Label5 | Q10: 5 | R10: Label4 | S10: 4 | T10: Label1 | U10: 1 | V10: =UPPER(TRIM(B10)) | W10: =IFERROR(INDEX(SessionLog!$A$2:$A$26,MATCH(V10,SessionLog!$N$2:$N$26,0)),"NOT FOUND") | X10: =IF(K10=1,1,0) | Y10: =IF(M10=2,1,0) | Z10: =8-S10 | AA10: =AVERAGE(O10,Q10,Z10) | AB10: =O10+Q10+Z10 | AC10: =O10+Q10+S10
A11: SIMULATED Multimodal Ad Study | B11: P10 | C11: MALE | D11: 23 | E11: BA | F11: Label5 | G11: 5 | H11: Label4 | I11: 4 | J11: Label1 | K11: 1 | L11: Label2 | M11: 2 | N11: Label4 | O11: 4 | P11: Label4 | Q11: 4 | R11: Label4 | S11: 4 | T11: Label4 | U11: 4 | V11: =UPPER(TRIM(B11)) | W11: =IFERROR(INDEX(SessionLog!$A$2:$A$26,MATCH(V11,SessionLog!$N$2:$N$26,0)),"NOT FOUND") | X11: =IF(K11=1,1,0) | Y11: =IF(M11=2,1,0) | Z11: =8-S11 | AA11: =AVERAGE(O11,Q11,Z11) | AB11: =O11+Q11+Z11 | AC11: =O11+Q11+S11
A12: SIMULATED Multimodal Ad Study | B12: P11 | C12: FEMALE | D12: 24 | E12: AB | F12: Label5 | G12: 5 | H12: Label4 | I12: 4 | J12: Label1 | K12: 1 | L12: Label2 | M12: 2 | N12: Label2 | O12: 2 | P12: Label3 | Q12: 3 | R12: Label5 | S12: 5 | T12: Label2 | U12: 2 | V12: =UPPER(TRIM(B12)) | W12: =IFERROR(INDEX(SessionLog!$A$2:$A$26,MATCH(V12,SessionLog!$N$2:$N$26,0)),"NOT FOUND") | X12: =IF(K12=1,1,0) | Y12: =IF(M12=2,1,0) | Z12: =8-S12 | AA12: =AVERAGE(O12,Q12,Z12) | AB12: =O12+Q12+Z12 | AC12: =O12+Q12+S12
A13: SIMULATED Multimodal Ad Study | B13: P12 | C13: MALE | D13: 23 | E13: BA | F13: Label5 | G13: 5 | H13: Label5 | I13: 5 | J13: Label4 | K13: 4 | L13: Label2 | M13: 2 | N13: Label3 | O13: 3 | P13: Label3 | Q13: 3 | R13: Label5 | S13: 5 | T13: Label1 | U13: 1 | V13: =UPPER(TRIM(B13)) | W13: =IFERROR(INDEX(SessionLog!$A$2:$A$26,MATCH(V13,SessionLog!$N$2:$N$26,0)),"NOT FOUND") | X13: =IF(K13=1,1,0) | Y13: =IF(M13=2,1,0) | Z13: =8-S13 | AA13: =AVERAGE(O13,Q13,Z13) | AB13: =O13+Q13+Z13 | AC13: =O13+Q13+S13
A14: SIMULATED Multimodal Ad Study | B14: P13 | C14: MALE | D14: 20 | E14: AB | F14: Label2 | G14: 2 | H14: Label1 | I14: 1 | J14: Label1 | K14: 1 | L14: Label5 | M14: 5 | N14: Label3 | O14: 3 | P14: Label4 | Q14: 4 | R14: Label6 | S14: 6 | T14: Label4 | U14: 4 | V14: =UPPER(TRIM(B14)) | W14: =IFERROR(INDEX(SessionLog!$A$2:$A$26,MATCH(V14,SessionLog!$N$2:$N$26,0)),"NOT FOUND") | X14: =IF(K14=1,1,0) | Y14: =IF(M14=2,1,0) | Z14: =8-S14 | AA14: =AVERAGE(O14,Q14,Z14) | AB14: =O14+Q14+Z14 | AC14: =O14+Q14+S14
A15: SIMULATED Multimodal Ad Study | B15: P14 | C15: FEMALE | D15: 21 | E15: BA | F15: Label5 | G15: 5 | H15: Label4 | I15: 4 | J15: Label1 | K15: 1 | L15: Label1 | M15: 1 | N15: Label5 | O15: 5 | P15: Label5 | Q15: 5 | R15: Label2 | S15: 2 | T15: Label5 | U15: 5 | V15: =UPPER(TRIM(B15)) | W15: =IFERROR(INDEX(SessionLog!$A$2:$A$26,MATCH(V15,SessionLog!$N$2:$N$26,0)),"NOT FOUND") | X15: =IF(K15=1,1,0) | Y15: =IF(M15=2,1,0) | Z15: =8-S15 | AA15: =AVERAGE(O15,Q15,Z15) | AB15: =O15+Q15+Z15 | AC15: =O15+Q15+S15
... A25: SIMULATED Multimodal Ad Study | B25: P24 | C25: FEMALE | D25: 19 | E25: BA | F25: Label6 | G25: 6 | H25: Label5 | I25: 5 | J25: Label1 | K25: 1 | L25: Label2 | M25: 2 | N25: Label5 | O25: 5 | P25: Label5 | Q25: 5 | R25: Label4 | S25: 4 | T25: Label2 | U25: 2 | V25: =UPPER(TRIM(B25)) | W25: =IFERROR(INDEX(SessionLog!$A$2:$A$26,MATCH(V25,SessionLog!$N$2:$N$26,0)),"NOT FOUND") | X25: =IF(K25=1,1,0) | Y25: =IF(M25=2,1,0) | Z25: =8-S25 | AA25: =AVERAGE(O25,Q25,Z25) | AB25: =O25+Q25+Z25 | AC25: =O25+Q25+S25

Sheet DataQuality
A1: Respondent_Name | B1: Stim_Name | C1: Eye tracking_SamplingRate | D1: Eye tracking_Quality | E1: Affectiva AFFDEX_SamplingRate | F1: Affectiva AFFDEX_Quality | G1: Shimmer GSR_SamplingRate | H1: Shimmer GSR_Quality | I1: Key = UPPER(TRIM()) | J1: Participant | K1: Use recording | L1: Lookup key | M1: LEN of the raw name
A2: P01 | B2: Instructions | C2: 60 | D2: 99 | E2: 29 | F2: 91 | G2: 127 | H2: 100 | I2: =UPPER(TRIM(A2)) | J2: =IFERROR(INDEX(SessionLog!$A$2:$A$26,MATCH(I2,SessionLog!$N$2:$N$26,0)),"NOT FOUND") | K2: =IFERROR(INDEX(SessionLog!$L$2:$L$26,MATCH(I2,SessionLog!$N$2:$N$26,0)),"NOT FOUND") | L2: =IF(K2="Yes",J2&"|"&B2,"DROP") | M2: =LEN(A2)
A3: P01 | B3: Baseline | C3: 60 | D3: 92 | E3: 30 | F3: 93 | G3: 128 | H3: 100 | I3: =UPPER(TRIM(A3)) | J3: =IFERROR(INDEX(SessionLog!$A$2:$A$26,MATCH(I3,SessionLog!$N$2:$N$26,0)),"NOT FOUND") | K3: =IFERROR(INDEX(SessionLog!$L$2:$L$26,MATCH(I3,SessionLog!$N$2:$N$26,0)),"NOT FOUND") | L3: =IF(K3="Yes",J3&"|"&B3,"DROP") | M3: =LEN(A3)
A4: P01 | B4: Ad_A | C4: 60 | D4: 95 | E4: 29 | F4: 93 | G4: 128 | H4: 100 | I4: =UPPER(TRIM(A4)) | J4: =IFERROR(INDEX(SessionLog!$A$2:$A$26,MATCH(I4,SessionLog!$N$2:$N$26,0)),"NOT FOUND") | K4: =IFERROR(INDEX(SessionLog!$L$2:$L$26,MATCH(I4,SessionLog!$N$2:$N$26,0)),"NOT FOUND") | L4: =IF(K4="Yes",J4&"|"&B4,"DROP") | M4: =LEN(A4)
A5: P01 | B5: Ad_B | C5: 60 | D5: 95 | E5: 29 | F5: 91 | G5: 127 | H5: 100 | I5: =UPPER(TRIM(A5)) | J5: =IFERROR(INDEX(SessionLog!$A$2:$A$26,MATCH(I5,SessionLog!$N$2:$N$26,0)),"NOT FOUND") | K5: =IFERROR(INDEX(SessionLog!$L$2:$L$26,MATCH(I5,SessionLog!$N$2:$N$26,0)),"NOT FOUND") | L5: =IF(K5="Yes",J5&"|"&B5,"DROP") | M5: =LEN(A5)
A6: P01 | B6: Questionnaire | C6: 59 | D6: 99 | E6: 29 | F6: 93 | G6: 127 | H6: 100 | I6: =UPPER(TRIM(A6)) | J6: =IFERROR(INDEX(SessionLog!$A$2:$A$26,MATCH(I6,SessionLog!$N$2:$N$26,0)),"NOT FOUND") | K6: =IFERROR(INDEX(SessionLog!$L$2:$L$26,MATCH(I6,SessionLog!$N$2:$N$26,0)),"NOT FOUND") | L6: =IF(K6="Yes",J6&"|"&B6,"DROP") | M6: =LEN(A6)
A7: P02 | B7: Instructions | C7: 60 | D7: 95 | E7: 30 | F7: 95 | G7: 127 | H7: 100 | I7: =UPPER(TRIM(A7)) | J7: =IFERROR(INDEX(SessionLog!$A$2:$A$26,MATCH(I7,SessionLog!$N$2:$N$26,0)),"NOT FOUND") | K7: =IFERROR(INDEX(SessionLog!$L$2:$L$26,MATCH(I7,SessionLog!$N$2:$N$26,0)),"NOT FOUND") | L7: =IF(K7="Yes",J7&"|"&B7,"DROP") | M7: =LEN(A7)
A8: P02 | B8: Baseline | C8: 60 | D8: 96 | E8: 29 | F8: 99 | G8: 127 | H8: 100 | I8: =UPPER(TRIM(A8)) | J8: =IFERROR(INDEX(SessionLog!$A$2:$A$26,MATCH(I8,SessionLog!$N$2:$N$26,0)),"NOT FOUND") | K8: =IFERROR(INDEX(SessionLog!$L$2:$L$26,MATCH(I8,SessionLog!$N$2:$N$26,0)),"NOT FOUND") | L8: =IF(K8="Yes",J8&"|"&B8,"DROP") | M8: =LEN(A8)
A9: P02 | B9: Ad_B | C9: 60 | D9: 94 | E9: 30 | F9: 98 | G9: 126 | H9: 99 | I9: =UPPER(TRIM(A9)) | J9: =IFERROR(INDEX(SessionLog!$A$2:$A$26,MATCH(I9,SessionLog!$N$2:$N$26,0)),"NOT FOUND") | K9: =IFERROR(INDEX(SessionLog!$L$2:$L$26,MATCH(I9,SessionLog!$N$2:$N$26,0)),"NOT FOUND") | L9: =IF(K9="Yes",J9&"|"&B9,"DROP") | M9: =LEN(A9)
A10: P02 | B10: Ad_A | C10: 60 | D10: 94 | E10: 29 | F10: 97 | G10: 127 | H10: 100 | I10: =UPPER(TRIM(A10)) | J10: =IFERROR(INDEX(SessionLog!$A$2:$A$26,MATCH(I10,SessionLog!$N$2:$N$26,0)),"NOT FOUND") | K10: =IFERROR(INDEX(SessionLog!$L$2:$L$26,MATCH(I10,SessionLog!$N$2:$N$26,0)),"NOT FOUND") | L10: =IF(K10="Yes",J10&"|"&B10,"DROP") | M10: =LEN(A10)
A11: P02 | B11: Questionnaire | C11: 60 | D11: 96 | E11: 29 | F11: 99 | G11: 127 | H11: 100 | I11: =UPPER(TRIM(A11)) | J11: =IFERROR(INDEX(SessionLog!$A$2:$A$26,MATCH(I11,SessionLog!$N$2:$N$26,0)),"NOT FOUND") | K11: =IFERROR(INDEX(SessionLog!$L$2:$L$26,MATCH(I11,SessionLog!$N$2:$N$26,0)),"NOT FOUND") | L11: =IF(K11="Yes",J11&"|"&B11,"DROP") | M11: =LEN(A11)
A12: P03 | B12: Instructions | C12: 60 | D12: 98 | E12: 29 | F12: 97 | G12: 125 | H12: 99 | I12: =UPPER(TRIM(A12)) | J12: =IFERROR(INDEX(SessionLog!$A$2:$A$26,MATCH(I12,SessionLog!$N$2:$N$26,0)),"NOT FOUND") | K12: =IFERROR(INDEX(SessionLog!$L$2:$L$26,MATCH(I12,SessionLog!$N$2:$N$26,0)),"NOT FOUND") | L12: =IF(K12="Yes",J12&"|"&B12,"DROP") | M12: =LEN(A12)
A13: P03 | B13: Baseline | C13: 60 | D13: 96 | E13: 30 | F13: 98 | G13: 127 | H13: 100 | I13: =UPPER(TRIM(A13)) | J13: =IFERROR(INDEX(SessionLog!$A$2:$A$26,MATCH(I13,SessionLog!$N$2:$N$26,0)),"NOT FOUND") | K13: =IFERROR(INDEX(SessionLog!$L$2:$L$26,MATCH(I13,SessionLog!$N$2:$N$26,0)),"NOT FOUND") | L13: =IF(K13="Yes",J13&"|"&B13,"DROP") | M13: =LEN(A13)
... A123: P24 | B123: Questionnaire | C123: 59 | D123: 96 | E123: 29 | F123: 93 | G123: 126 | H123: 100 | I123: =UPPER(TRIM(A123)) | J123: =IFERROR(INDEX(SessionLog!$A$2:$A$26,MATCH(I123,SessionLog!$N$2:$N$26,0)),"NOT FOUND") | K123: =IFERROR(INDEX(SessionLog!$L$2:$L$26,MATCH(I123,SessionLog!$N$2:$N$26,0)),"NOT FOUND") | L123: =IF(K123="Yes",J123&"|"&B123,"DROP") | M123: =LEN(A123)

Sheet Keys
A1: The problem keys, made visible. Each raw key is a live reference to the cell where it sits in the imported data.
A3: Where | B3: Raw key (reference) | C3: LEN | D3: CODE of the last character | E3: EXACT match in the session log | F3: MATCH finds it (ignores case) | G3: UPPER(TRIM()) | H3: Participant | I3: Use recording
A4: DataQuality, column A | B4: =DataQuality!A34 | C4: =LEN(B4) | D4: =CODE(RIGHT(B4,1)) | E4: =SUMPRODUCT(--EXACT(B4,SessionLog!$B$2:$B$26))>0 | F4: =ISNUMBER(MATCH(B4,SessionLog!$B$2:$B$26,0)) | G4: =UPPER(TRIM(B4)) | H4: =IFERROR(INDEX(SessionLog!$A$2:$A$26,MATCH(G4,SessionLog!$N$2:$N$26,0)),"NOT FOUND") | I4: =IFERROR(INDEX(SessionLog!$L$2:$L$26,MATCH(G4,SessionLog!$N$2:$N$26,0)),"NOT FOUND")
A5: Survey, column B | B5: =Survey!B8 | C5: =LEN(B5) | D5: =CODE(RIGHT(B5,1)) | E5: =SUMPRODUCT(--EXACT(B5,SessionLog!$B$2:$B$26))>0 | F5: =ISNUMBER(MATCH(B5,SessionLog!$B$2:$B$26,0)) | G5: =UPPER(TRIM(B5)) | H5: =IFERROR(INDEX(SessionLog!$A$2:$A$26,MATCH(G5,SessionLog!$N$2:$N$26,0)),"NOT FOUND") | I5: =IFERROR(INDEX(SessionLog!$L$2:$L$26,MATCH(G5,SessionLog!$N$2:$N$26,0)),"NOT FOUND")
A6: GSR_Import, column B | B6: =GSR_Import!B23 | C6: =LEN(B6) | D6: =CODE(RIGHT(B6,1)) | E6: =SUMPRODUCT(--EXACT(B6,SessionLog!$B$2:$B$26))>0 | F6: =ISNUMBER(MATCH(B6,SessionLog!$B$2:$B$26,0)) | G6: =UPPER(TRIM(B6)) | H6: =IFERROR(INDEX(SessionLog!$A$2:$A$26,MATCH(G6,SessionLog!$N$2:$N$26,0)),"NOT FOUND") | I6: =IFERROR(INDEX(SessionLog!$L$2:$L$26,MATCH(G6,SessionLog!$N$2:$N$26,0)),"NOT FOUND")
A7: GSR_Import, column B | B7: =GSR_Import!B27 | C7: =LEN(B7) | D7: =CODE(RIGHT(B7,1)) | E7: =SUMPRODUCT(--EXACT(B7,SessionLog!$B$2:$B$26))>0 | F7: =ISNUMBER(MATCH(B7,SessionLog!$B$2:$B$26,0)) | G7: =UPPER(TRIM(B7)) | H7: =IFERROR(INDEX(SessionLog!$A$2:$A$26,MATCH(G7,SessionLog!$N$2:$N$26,0)),"NOT FOUND") | I7: =IFERROR(INDEX(SessionLog!$L$2:$L$26,MATCH(G7,SessionLog!$N$2:$N$26,0)),"NOT FOUND")
A8: GSR_Import, column B (a normal key) | B8: =GSR_Import!B4 | C8: =LEN(B8) | D8: =CODE(RIGHT(B8,1)) | E8: =SUMPRODUCT(--EXACT(B8,SessionLog!$B$2:$B$26))>0 | F8: =ISNUMBER(MATCH(B8,SessionLog!$B$2:$B$26,0)) | G8: =UPPER(TRIM(B8)) | H8: =IFERROR(INDEX(SessionLog!$A$2:$A$26,MATCH(G8,SessionLog!$N$2:$N$26,0)),"NOT FOUND") | I8: =IFERROR(INDEX(SessionLog!$L$2:$L$26,MATCH(G8,SessionLog!$N$2:$N$26,0)),"NOT FOUND")
A10: Read row by row: LEN 4 and CODE 32 reveal the trailing space; EXACT is FALSE for p07 although MATCH finds it, because Excel lookups ignore upper and lower case (R joins do not). TRIM and UPPER give every row a key that the session log knows; the Use recording column then says which recording of P04 to keep.

Sheet Merged
A1: participant_id | B1: stimulus | C1: GSR lookup key | D1: GSR Peaks Per Minute (as exported) | E1: GSR valid (R3) | F1: GSR Peaks Per Minute (analysis) | G1: DQ lookup key | H1: Eye tracking quality (%) | I1: Face quality (%) | J1: Eye tracking minimum, ads | K1: Face minimum, ads | L1: include (R2) | M1: liking | N1: recall_correct
A2: P01 | B2: Baseline | C2: =A2&"|Stimulus|"&B2&"|"&B2 | D2: =INDEX(GSR_Import!$N$2:$N$171,MATCH(C2,GSR_Import!$S$2:$S$171,0)) | E2: =INDEX(GSR_Import!$U$2:$U$171,MATCH(C2,GSR_Import!$S$2:$S$171,0)) | F2: =IF(E2=1,D2,"") | G2: =A2&"|"&B2 | H2: =INDEX(DataQuality!$D$2:$D$123,MATCH(G2,DataQuality!$L$2:$L$123,0)) | I2: =INDEX(DataQuality!$F$2:$F$123,MATCH(G2,DataQuality!$L$2:$L$123,0)) | J2: =MIN(INDEX(DataQuality!$D$2:$D$123,MATCH(A2&"|Ad_A",DataQuality!$L$2:$L$123,0)),INDEX(DataQuality!$D$2:$D$123,MATCH(A2&"|Ad_B",DataQuality!$L$2:$L$123,0))) | K2: =MIN(INDEX(DataQuality!$F$2:$F$123,MATCH(A2&"|Ad_A",DataQuality!$L$2:$L$123,0)),INDEX(DataQuality!$F$2:$F$123,MATCH(A2&"|Ad_B",DataQuality!$L$2:$L$123,0))) | L2: =IF(AND(J2>=90,K2>=80),1,0) | M2: =IF(B2="Ad_A",INDEX(Survey!$G$2:$G$25,MATCH(A2,Survey!$W$2:$W$25,0)),IF(B2="Ad_B",INDEX(Survey!$I$2:$I$25,MATCH(A2,Survey!$W$2:$W$25,0)),"")) | N2: =IF(B2="Ad_A",INDEX(Survey!$X$2:$X$25,MATCH(A2,Survey!$W$2:$W$25,0)),IF(B2="Ad_B",INDEX(Survey!$Y$2:$Y$25,MATCH(A2,Survey!$W$2:$W$25,0)),"")) | P2: Checks
A3: P01 | B3: Ad_A | C3: =A3&"|Stimulus|"&B3&"|"&B3 | D3: =INDEX(GSR_Import!$N$2:$N$171,MATCH(C3,GSR_Import!$S$2:$S$171,0)) | E3: =INDEX(GSR_Import!$U$2:$U$171,MATCH(C3,GSR_Import!$S$2:$S$171,0)) | F3: =IF(E3=1,D3,"") | G3: =A3&"|"&B3 | H3: =INDEX(DataQuality!$D$2:$D$123,MATCH(G3,DataQuality!$L$2:$L$123,0)) | I3: =INDEX(DataQuality!$F$2:$F$123,MATCH(G3,DataQuality!$L$2:$L$123,0)) | J3: =MIN(INDEX(DataQuality!$D$2:$D$123,MATCH(A3&"|Ad_A",DataQuality!$L$2:$L$123,0)),INDEX(DataQuality!$D$2:$D$123,MATCH(A3&"|Ad_B",DataQuality!$L$2:$L$123,0))) | K3: =MIN(INDEX(DataQuality!$F$2:$F$123,MATCH(A3&"|Ad_A",DataQuality!$L$2:$L$123,0)),INDEX(DataQuality!$F$2:$F$123,MATCH(A3&"|Ad_B",DataQuality!$L$2:$L$123,0))) | L3: =IF(AND(J3>=90,K3>=80),1,0) | M3: =IF(B3="Ad_A",INDEX(Survey!$G$2:$G$25,MATCH(A3,Survey!$W$2:$W$25,0)),IF(B3="Ad_B",INDEX(Survey!$I$2:$I$25,MATCH(A3,Survey!$W$2:$W$25,0)),"")) | N3: =IF(B3="Ad_A",INDEX(Survey!$X$2:$X$25,MATCH(A3,Survey!$W$2:$W$25,0)),IF(B3="Ad_B",INDEX(Survey!$Y$2:$Y$25,MATCH(A3,Survey!$W$2:$W$25,0)),"")) | P3: Rows (participant x stimulus) | Q3: =COUNTA(A2:A73)
A4: P01 | B4: Ad_B | C4: =A4&"|Stimulus|"&B4&"|"&B4 | D4: =INDEX(GSR_Import!$N$2:$N$171,MATCH(C4,GSR_Import!$S$2:$S$171,0)) | E4: =INDEX(GSR_Import!$U$2:$U$171,MATCH(C4,GSR_Import!$S$2:$S$171,0)) | F4: =IF(E4=1,D4,"") | G4: =A4&"|"&B4 | H4: =INDEX(DataQuality!$D$2:$D$123,MATCH(G4,DataQuality!$L$2:$L$123,0)) | I4: =INDEX(DataQuality!$F$2:$F$123,MATCH(G4,DataQuality!$L$2:$L$123,0)) | J4: =MIN(INDEX(DataQuality!$D$2:$D$123,MATCH(A4&"|Ad_A",DataQuality!$L$2:$L$123,0)),INDEX(DataQuality!$D$2:$D$123,MATCH(A4&"|Ad_B",DataQuality!$L$2:$L$123,0))) | K4: =MIN(INDEX(DataQuality!$F$2:$F$123,MATCH(A4&"|Ad_A",DataQuality!$L$2:$L$123,0)),INDEX(DataQuality!$F$2:$F$123,MATCH(A4&"|Ad_B",DataQuality!$L$2:$L$123,0))) | L4: =IF(AND(J4>=90,K4>=80),1,0) | M4: =IF(B4="Ad_A",INDEX(Survey!$G$2:$G$25,MATCH(A4,Survey!$W$2:$W$25,0)),IF(B4="Ad_B",INDEX(Survey!$I$2:$I$25,MATCH(A4,Survey!$W$2:$W$25,0)),"")) | N4: =IF(B4="Ad_A",INDEX(Survey!$X$2:$X$25,MATCH(A4,Survey!$W$2:$W$25,0)),IF(B4="Ad_B",INDEX(Survey!$Y$2:$Y$25,MATCH(A4,Survey!$W$2:$W$25,0)),"")) | P4: Lookups that failed (#N/A) in D, H, I | Q4: =SUMPRODUCT(--ISNA(D2:D73))+SUMPRODUCT(--ISNA(H2:H73))+SUMPRODUCT(--ISNA(I2:I73))
A5: P02 | B5: Baseline | C5: =A5&"|Stimulus|"&B5&"|"&B5 | D5: =INDEX(GSR_Import!$N$2:$N$171,MATCH(C5,GSR_Import!$S$2:$S$171,0)) | E5: =INDEX(GSR_Import!$U$2:$U$171,MATCH(C5,GSR_Import!$S$2:$S$171,0)) | F5: =IF(E5=1,D5,"") | G5: =A5&"|"&B5 | H5: =INDEX(DataQuality!$D$2:$D$123,MATCH(G5,DataQuality!$L$2:$L$123,0)) | I5: =INDEX(DataQuality!$F$2:$F$123,MATCH(G5,DataQuality!$L$2:$L$123,0)) | J5: =MIN(INDEX(DataQuality!$D$2:$D$123,MATCH(A5&"|Ad_A",DataQuality!$L$2:$L$123,0)),INDEX(DataQuality!$D$2:$D$123,MATCH(A5&"|Ad_B",DataQuality!$L$2:$L$123,0))) | K5: =MIN(INDEX(DataQuality!$F$2:$F$123,MATCH(A5&"|Ad_A",DataQuality!$L$2:$L$123,0)),INDEX(DataQuality!$F$2:$F$123,MATCH(A5&"|Ad_B",DataQuality!$L$2:$L$123,0))) | L5: =IF(AND(J5>=90,K5>=80),1,0) | M5: =IF(B5="Ad_A",INDEX(Survey!$G$2:$G$25,MATCH(A5,Survey!$W$2:$W$25,0)),IF(B5="Ad_B",INDEX(Survey!$I$2:$I$25,MATCH(A5,Survey!$W$2:$W$25,0)),"")) | N5: =IF(B5="Ad_A",INDEX(Survey!$X$2:$X$25,MATCH(A5,Survey!$W$2:$W$25,0)),IF(B5="Ad_B",INDEX(Survey!$Y$2:$Y$25,MATCH(A5,Survey!$W$2:$W$25,0)),"")) | P5: Participants with include = 1 | Q5: =COUNTIFS(B2:B73,"Baseline",L2:L73,1)
A6: P02 | B6: Ad_A | C6: =A6&"|Stimulus|"&B6&"|"&B6 | D6: =INDEX(GSR_Import!$N$2:$N$171,MATCH(C6,GSR_Import!$S$2:$S$171,0)) | E6: =INDEX(GSR_Import!$U$2:$U$171,MATCH(C6,GSR_Import!$S$2:$S$171,0)) | F6: =IF(E6=1,D6,"") | G6: =A6&"|"&B6 | H6: =INDEX(DataQuality!$D$2:$D$123,MATCH(G6,DataQuality!$L$2:$L$123,0)) | I6: =INDEX(DataQuality!$F$2:$F$123,MATCH(G6,DataQuality!$L$2:$L$123,0)) | J6: =MIN(INDEX(DataQuality!$D$2:$D$123,MATCH(A6&"|Ad_A",DataQuality!$L$2:$L$123,0)),INDEX(DataQuality!$D$2:$D$123,MATCH(A6&"|Ad_B",DataQuality!$L$2:$L$123,0))) | K6: =MIN(INDEX(DataQuality!$F$2:$F$123,MATCH(A6&"|Ad_A",DataQuality!$L$2:$L$123,0)),INDEX(DataQuality!$F$2:$F$123,MATCH(A6&"|Ad_B",DataQuality!$L$2:$L$123,0))) | L6: =IF(AND(J6>=90,K6>=80),1,0) | M6: =IF(B6="Ad_A",INDEX(Survey!$G$2:$G$25,MATCH(A6,Survey!$W$2:$W$25,0)),IF(B6="Ad_B",INDEX(Survey!$I$2:$I$25,MATCH(A6,Survey!$W$2:$W$25,0)),"")) | N6: =IF(B6="Ad_A",INDEX(Survey!$X$2:$X$25,MATCH(A6,Survey!$W$2:$W$25,0)),IF(B6="Ad_B",INDEX(Survey!$Y$2:$Y$25,MATCH(A6,Survey!$W$2:$W$25,0)),"")) | P6: Stimulus rows with GSR not valid | Q6: =COUNTIF(E2:E73,0)
A7: P02 | B7: Ad_B | C7: =A7&"|Stimulus|"&B7&"|"&B7 | D7: =INDEX(GSR_Import!$N$2:$N$171,MATCH(C7,GSR_Import!$S$2:$S$171,0)) | E7: =INDEX(GSR_Import!$U$2:$U$171,MATCH(C7,GSR_Import!$S$2:$S$171,0)) | F7: =IF(E7=1,D7,"") | G7: =A7&"|"&B7 | H7: =INDEX(DataQuality!$D$2:$D$123,MATCH(G7,DataQuality!$L$2:$L$123,0)) | I7: =INDEX(DataQuality!$F$2:$F$123,MATCH(G7,DataQuality!$L$2:$L$123,0)) | J7: =MIN(INDEX(DataQuality!$D$2:$D$123,MATCH(A7&"|Ad_A",DataQuality!$L$2:$L$123,0)),INDEX(DataQuality!$D$2:$D$123,MATCH(A7&"|Ad_B",DataQuality!$L$2:$L$123,0))) | K7: =MIN(INDEX(DataQuality!$F$2:$F$123,MATCH(A7&"|Ad_A",DataQuality!$L$2:$L$123,0)),INDEX(DataQuality!$F$2:$F$123,MATCH(A7&"|Ad_B",DataQuality!$L$2:$L$123,0))) | L7: =IF(AND(J7>=90,K7>=80),1,0) | M7: =IF(B7="Ad_A",INDEX(Survey!$G$2:$G$25,MATCH(A7,Survey!$W$2:$W$25,0)),IF(B7="Ad_B",INDEX(Survey!$I$2:$I$25,MATCH(A7,Survey!$W$2:$W$25,0)),"")) | N7: =IF(B7="Ad_A",INDEX(Survey!$X$2:$X$25,MATCH(A7,Survey!$W$2:$W$25,0)),IF(B7="Ad_B",INDEX(Survey!$Y$2:$Y$25,MATCH(A7,Survey!$W$2:$W$25,0)),""))
A8: P03 | B8: Baseline | C8: =A8&"|Stimulus|"&B8&"|"&B8 | D8: =INDEX(GSR_Import!$N$2:$N$171,MATCH(C8,GSR_Import!$S$2:$S$171,0)) | E8: =INDEX(GSR_Import!$U$2:$U$171,MATCH(C8,GSR_Import!$S$2:$S$171,0)) | F8: =IF(E8=1,D8,"") | G8: =A8&"|"&B8 | H8: =INDEX(DataQuality!$D$2:$D$123,MATCH(G8,DataQuality!$L$2:$L$123,0)) | I8: =INDEX(DataQuality!$F$2:$F$123,MATCH(G8,DataQuality!$L$2:$L$123,0)) | J8: =MIN(INDEX(DataQuality!$D$2:$D$123,MATCH(A8&"|Ad_A",DataQuality!$L$2:$L$123,0)),INDEX(DataQuality!$D$2:$D$123,MATCH(A8&"|Ad_B",DataQuality!$L$2:$L$123,0))) | K8: =MIN(INDEX(DataQuality!$F$2:$F$123,MATCH(A8&"|Ad_A",DataQuality!$L$2:$L$123,0)),INDEX(DataQuality!$F$2:$F$123,MATCH(A8&"|Ad_B",DataQuality!$L$2:$L$123,0))) | L8: =IF(AND(J8>=90,K8>=80),1,0) | M8: =IF(B8="Ad_A",INDEX(Survey!$G$2:$G$25,MATCH(A8,Survey!$W$2:$W$25,0)),IF(B8="Ad_B",INDEX(Survey!$I$2:$I$25,MATCH(A8,Survey!$W$2:$W$25,0)),"")) | N8: =IF(B8="Ad_A",INDEX(Survey!$X$2:$X$25,MATCH(A8,Survey!$W$2:$W$25,0)),IF(B8="Ad_B",INDEX(Survey!$Y$2:$Y$25,MATCH(A8,Survey!$W$2:$W$25,0)),""))
A9: P03 | B9: Ad_A | C9: =A9&"|Stimulus|"&B9&"|"&B9 | D9: =INDEX(GSR_Import!$N$2:$N$171,MATCH(C9,GSR_Import!$S$2:$S$171,0)) | E9: =INDEX(GSR_Import!$U$2:$U$171,MATCH(C9,GSR_Import!$S$2:$S$171,0)) | F9: =IF(E9=1,D9,"") | G9: =A9&"|"&B9 | H9: =INDEX(DataQuality!$D$2:$D$123,MATCH(G9,DataQuality!$L$2:$L$123,0)) | I9: =INDEX(DataQuality!$F$2:$F$123,MATCH(G9,DataQuality!$L$2:$L$123,0)) | J9: =MIN(INDEX(DataQuality!$D$2:$D$123,MATCH(A9&"|Ad_A",DataQuality!$L$2:$L$123,0)),INDEX(DataQuality!$D$2:$D$123,MATCH(A9&"|Ad_B",DataQuality!$L$2:$L$123,0))) | K9: =MIN(INDEX(DataQuality!$F$2:$F$123,MATCH(A9&"|Ad_A",DataQuality!$L$2:$L$123,0)),INDEX(DataQuality!$F$2:$F$123,MATCH(A9&"|Ad_B",DataQuality!$L$2:$L$123,0))) | L9: =IF(AND(J9>=90,K9>=80),1,0) | M9: =IF(B9="Ad_A",INDEX(Survey!$G$2:$G$25,MATCH(A9,Survey!$W$2:$W$25,0)),IF(B9="Ad_B",INDEX(Survey!$I$2:$I$25,MATCH(A9,Survey!$W$2:$W$25,0)),"")) | N9: =IF(B9="Ad_A",INDEX(Survey!$X$2:$X$25,MATCH(A9,Survey!$W$2:$W$25,0)),IF(B9="Ad_B",INDEX(Survey!$Y$2:$Y$25,MATCH(A9,Survey!$W$2:$W$25,0)),""))
A10: P03 | B10: Ad_B | C10: =A10&"|Stimulus|"&B10&"|"&B10 | D10: =INDEX(GSR_Import!$N$2:$N$171,MATCH(C10,GSR_Import!$S$2:$S$171,0)) | E10: =INDEX(GSR_Import!$U$2:$U$171,MATCH(C10,GSR_Import!$S$2:$S$171,0)) | F10: =IF(E10=1,D10,"") | G10: =A10&"|"&B10 | H10: =INDEX(DataQuality!$D$2:$D$123,MATCH(G10,DataQuality!$L$2:$L$123,0)) | I10: =INDEX(DataQuality!$F$2:$F$123,MATCH(G10,DataQuality!$L$2:$L$123,0)) | J10: =MIN(INDEX(DataQuality!$D$2:$D$123,MATCH(A10&"|Ad_A",DataQuality!$L$2:$L$123,0)),INDEX(DataQuality!$D$2:$D$123,MATCH(A10&"|Ad_B",DataQuality!$L$2:$L$123,0))) | K10: =MIN(INDEX(DataQuality!$F$2:$F$123,MATCH(A10&"|Ad_A",DataQuality!$L$2:$L$123,0)),INDEX(DataQuality!$F$2:$F$123,MATCH(A10&"|Ad_B",DataQuality!$L$2:$L$123,0))) | L10: =IF(AND(J10>=90,K10>=80),1,0) | M10: =IF(B10="Ad_A",INDEX(Survey!$G$2:$G$25,MATCH(A10,Survey!$W$2:$W$25,0)),IF(B10="Ad_B",INDEX(Survey!$I$2:$I$25,MATCH(A10,Survey!$W$2:$W$25,0)),"")) | N10: =IF(B10="Ad_A",INDEX(Survey!$X$2:$X$25,MATCH(A10,Survey!$W$2:$W$25,0)),IF(B10="Ad_B",INDEX(Survey!$Y$2:$Y$25,MATCH(A10,Survey!$W$2:$W$25,0)),""))
A11: P04 | B11: Baseline | C11: =A11&"|Stimulus|"&B11&"|"&B11 | D11: =INDEX(GSR_Import!$N$2:$N$171,MATCH(C11,GSR_Import!$S$2:$S$171,0)) | E11: =INDEX(GSR_Import!$U$2:$U$171,MATCH(C11,GSR_Import!$S$2:$S$171,0)) | F11: =IF(E11=1,D11,"") | G11: =A11&"|"&B11 | H11: =INDEX(DataQuality!$D$2:$D$123,MATCH(G11,DataQuality!$L$2:$L$123,0)) | I11: =INDEX(DataQuality!$F$2:$F$123,MATCH(G11,DataQuality!$L$2:$L$123,0)) | J11: =MIN(INDEX(DataQuality!$D$2:$D$123,MATCH(A11&"|Ad_A",DataQuality!$L$2:$L$123,0)),INDEX(DataQuality!$D$2:$D$123,MATCH(A11&"|Ad_B",DataQuality!$L$2:$L$123,0))) | K11: =MIN(INDEX(DataQuality!$F$2:$F$123,MATCH(A11&"|Ad_A",DataQuality!$L$2:$L$123,0)),INDEX(DataQuality!$F$2:$F$123,MATCH(A11&"|Ad_B",DataQuality!$L$2:$L$123,0))) | L11: =IF(AND(J11>=90,K11>=80),1,0) | M11: =IF(B11="Ad_A",INDEX(Survey!$G$2:$G$25,MATCH(A11,Survey!$W$2:$W$25,0)),IF(B11="Ad_B",INDEX(Survey!$I$2:$I$25,MATCH(A11,Survey!$W$2:$W$25,0)),"")) | N11: =IF(B11="Ad_A",INDEX(Survey!$X$2:$X$25,MATCH(A11,Survey!$W$2:$W$25,0)),IF(B11="Ad_B",INDEX(Survey!$Y$2:$Y$25,MATCH(A11,Survey!$W$2:$W$25,0)),""))
A12: P04 | B12: Ad_A | C12: =A12&"|Stimulus|"&B12&"|"&B12 | D12: =INDEX(GSR_Import!$N$2:$N$171,MATCH(C12,GSR_Import!$S$2:$S$171,0)) | E12: =INDEX(GSR_Import!$U$2:$U$171,MATCH(C12,GSR_Import!$S$2:$S$171,0)) | F12: =IF(E12=1,D12,"") | G12: =A12&"|"&B12 | H12: =INDEX(DataQuality!$D$2:$D$123,MATCH(G12,DataQuality!$L$2:$L$123,0)) | I12: =INDEX(DataQuality!$F$2:$F$123,MATCH(G12,DataQuality!$L$2:$L$123,0)) | J12: =MIN(INDEX(DataQuality!$D$2:$D$123,MATCH(A12&"|Ad_A",DataQuality!$L$2:$L$123,0)),INDEX(DataQuality!$D$2:$D$123,MATCH(A12&"|Ad_B",DataQuality!$L$2:$L$123,0))) | K12: =MIN(INDEX(DataQuality!$F$2:$F$123,MATCH(A12&"|Ad_A",DataQuality!$L$2:$L$123,0)),INDEX(DataQuality!$F$2:$F$123,MATCH(A12&"|Ad_B",DataQuality!$L$2:$L$123,0))) | L12: =IF(AND(J12>=90,K12>=80),1,0) | M12: =IF(B12="Ad_A",INDEX(Survey!$G$2:$G$25,MATCH(A12,Survey!$W$2:$W$25,0)),IF(B12="Ad_B",INDEX(Survey!$I$2:$I$25,MATCH(A12,Survey!$W$2:$W$25,0)),"")) | N12: =IF(B12="Ad_A",INDEX(Survey!$X$2:$X$25,MATCH(A12,Survey!$W$2:$W$25,0)),IF(B12="Ad_B",INDEX(Survey!$Y$2:$Y$25,MATCH(A12,Survey!$W$2:$W$25,0)),""))
A13: P04 | B13: Ad_B | C13: =A13&"|Stimulus|"&B13&"|"&B13 | D13: =INDEX(GSR_Import!$N$2:$N$171,MATCH(C13,GSR_Import!$S$2:$S$171,0)) | E13: =INDEX(GSR_Import!$U$2:$U$171,MATCH(C13,GSR_Import!$S$2:$S$171,0)) | F13: =IF(E13=1,D13,"") | G13: =A13&"|"&B13 | H13: =INDEX(DataQuality!$D$2:$D$123,MATCH(G13,DataQuality!$L$2:$L$123,0)) | I13: =INDEX(DataQuality!$F$2:$F$123,MATCH(G13,DataQuality!$L$2:$L$123,0)) | J13: =MIN(INDEX(DataQuality!$D$2:$D$123,MATCH(A13&"|Ad_A",DataQuality!$L$2:$L$123,0)),INDEX(DataQuality!$D$2:$D$123,MATCH(A13&"|Ad_B",DataQuality!$L$2:$L$123,0))) | K13: =MIN(INDEX(DataQuality!$F$2:$F$123,MATCH(A13&"|Ad_A",DataQuality!$L$2:$L$123,0)),INDEX(DataQuality!$F$2:$F$123,MATCH(A13&"|Ad_B",DataQuality!$L$2:$L$123,0))) | L13: =IF(AND(J13>=90,K13>=80),1,0) | M13: =IF(B13="Ad_A",INDEX(Survey!$G$2:$G$25,MATCH(A13,Survey!$W$2:$W$25,0)),IF(B13="Ad_B",INDEX(Survey!$I$2:$I$25,MATCH(A13,Survey!$W$2:$W$25,0)),"")) | N13: =IF(B13="Ad_A",INDEX(Survey!$X$2:$X$25,MATCH(A13,Survey!$W$2:$W$25,0)),IF(B13="Ad_B",INDEX(Survey!$Y$2:$Y$25,MATCH(A13,Survey!$W$2:$W$25,0)),""))
A14: P05 | B14: Baseline | C14: =A14&"|Stimulus|"&B14&"|"&B14 | D14: =INDEX(GSR_Import!$N$2:$N$171,MATCH(C14,GSR_Import!$S$2:$S$171,0)) | E14: =INDEX(GSR_Import!$U$2:$U$171,MATCH(C14,GSR_Import!$S$2:$S$171,0)) | F14: =IF(E14=1,D14,"") | G14: =A14&"|"&B14 | H14: =INDEX(DataQuality!$D$2:$D$123,MATCH(G14,DataQuality!$L$2:$L$123,0)) | I14: =INDEX(DataQuality!$F$2:$F$123,MATCH(G14,DataQuality!$L$2:$L$123,0)) | J14: =MIN(INDEX(DataQuality!$D$2:$D$123,MATCH(A14&"|Ad_A",DataQuality!$L$2:$L$123,0)),INDEX(DataQuality!$D$2:$D$123,MATCH(A14&"|Ad_B",DataQuality!$L$2:$L$123,0))) | K14: =MIN(INDEX(DataQuality!$F$2:$F$123,MATCH(A14&"|Ad_A",DataQuality!$L$2:$L$123,0)),INDEX(DataQuality!$F$2:$F$123,MATCH(A14&"|Ad_B",DataQuality!$L$2:$L$123,0))) | L14: =IF(AND(J14>=90,K14>=80),1,0) | M14: =IF(B14="Ad_A",INDEX(Survey!$G$2:$G$25,MATCH(A14,Survey!$W$2:$W$25,0)),IF(B14="Ad_B",INDEX(Survey!$I$2:$I$25,MATCH(A14,Survey!$W$2:$W$25,0)),"")) | N14: =IF(B14="Ad_A",INDEX(Survey!$X$2:$X$25,MATCH(A14,Survey!$W$2:$W$25,0)),IF(B14="Ad_B",INDEX(Survey!$Y$2:$Y$25,MATCH(A14,Survey!$W$2:$W$25,0)),""))
