Workbook

Sheet README
A1: SIMULATED facial expression analysis workbook (teaching material)
A3: Every number in this workbook is SIMULATED. It was generated by make_simulated_data.py (seed 20265798) to resemble
A4: the FEA Metrics Export of the iMotions FEA thresholding R Notebook for one video commercial: a 60 s Baseline,
A5: a 60 s Commercial cut into six 10 s bins (Bin_01 to Bin_06), and a 15 s Recovery, recorded with the lab webcam
A6: and processed with Affectiva AFFDEX. No real viewer was recorded.
A8: Sheets:
A9: Data FEA Metrics Export as imported (rows 2 to 1729). NA is kept as text, as iMotions writes it.
A10: Helper columns L and M: Keep (Data quality >= 80), Present (1 when Percent of time present > 0).
A11: Summary Mean, SD, median, viewers with the expression present, and segments by expression and interval,
A12: built with COUNTIFS, AVERAGEIFS, and array formulas. Engagement is a raw mean score.
A13: H1 Joy, Commercial versus Baseline. One row per kept respondent; paired t test (T.TEST type 1), d_z,
A14: viewers with any Joy, exact McNemar test, and a hand computed Wilcoxon signed rank summary.
... A31: Sheets named H1 and H3 look like cell addresses, so formulas that point at them quote the name: 'H1'!L10.

Sheet Data
A1: Study Name | B1: Respondent Name | C1: Interval type | D1: Interval label | E1: Interval duration (s) | F1: Expression | G1: Threshold | H1: Percent of time present | I1: Number of segments | J1: Mean raw score (0-100) | K1: Data quality (%) | L1: Keep | M1: Present
A2: SIMULATED_FEA_Commercial_Study | B2: V01 | C2: Stimulus | D2: Baseline | E2: 60 | F2: Joy | G2: 50 | H2: 0 | I2: 0 | J2: NA | K2: 96.2 | L2: =IF(K2>=80,"Yes","No") | M2: =IF(ISNUMBER(H2),IF(H2>0,1,0),"")
A3: SIMULATED_FEA_Commercial_Study | B3: V01 | C3: Stimulus | D3: Baseline | E3: 60 | F3: Surprise | G3: 50 | H3: 2.89 | I3: 2 | J3: NA | K3: 96.2 | L3: =IF(K3>=80,"Yes","No") | M3: =IF(ISNUMBER(H3),IF(H3>0,1,0),"")
A4: SIMULATED_FEA_Commercial_Study | B4: V01 | C4: Stimulus | D4: Baseline | E4: 60 | F4: Brow Furrow | G4: 50 | H4: 0 | I4: 0 | J4: NA | K4: 96.2 | L4: =IF(K4>=80,"Yes","No") | M4: =IF(ISNUMBER(H4),IF(H4>0,1,0),"")
A5: SIMULATED_FEA_Commercial_Study | B5: V01 | C5: Stimulus | D5: Baseline | E5: 60 | F5: Positive Valence | G5: 50 | H5: 0 | I5: 0 | J5: NA | K5: 96.2 | L5: =IF(K5>=80,"Yes","No") | M5: =IF(ISNUMBER(H5),IF(H5>0,1,0),"")
A6: SIMULATED_FEA_Commercial_Study | B6: V01 | C6: Stimulus | D6: Baseline | E6: 60 | F6: Negative Valence | G6: -50 | H6: 0 | I6: 0 | J6: NA | K6: 96.2 | L6: =IF(K6>=80,"Yes","No") | M6: =IF(ISNUMBER(H6),IF(H6>0,1,0),"")
A7: SIMULATED_FEA_Commercial_Study | B7: V01 | C7: Stimulus | D7: Baseline | E7: 60 | F7: Engagement | G7: NA | H7: NA | I7: NA | J7: 6.14 | K7: 96.2 | L7: =IF(K7>=80,"Yes","No") | M7: =IF(ISNUMBER(H7),IF(H7>0,1,0),"")
A8: SIMULATED_FEA_Commercial_Study | B8: V01 | C8: Stimulus | D8: Commercial | E8: 60 | F8: Joy | G8: 50 | H8: 17.33 | I8: 5 | J8: NA | K8: 96.2 | L8: =IF(K8>=80,"Yes","No") | M8: =IF(ISNUMBER(H8),IF(H8>0,1,0),"")
A9: SIMULATED_FEA_Commercial_Study | B9: V01 | C9: Stimulus | D9: Commercial | E9: 60 | F9: Surprise | G9: 50 | H9: 6.61 | I9: 4 | J9: NA | K9: 96.2 | L9: =IF(K9>=80,"Yes","No") | M9: =IF(ISNUMBER(H9),IF(H9>0,1,0),"")
A10: SIMULATED_FEA_Commercial_Study | B10: V01 | C10: Stimulus | D10: Commercial | E10: 60 | F10: Brow Furrow | G10: 50 | H10: 0 | I10: 0 | J10: NA | K10: 96.2 | L10: =IF(K10>=80,"Yes","No") | M10: =IF(ISNUMBER(H10),IF(H10>0,1,0),"")
A11: SIMULATED_FEA_Commercial_Study | B11: V01 | C11: Stimulus | D11: Commercial | E11: 60 | F11: Positive Valence | G11: 50 | H11: 16.72 | I11: 6 | J11: NA | K11: 96.2 | L11: =IF(K11>=80,"Yes","No") | M11: =IF(ISNUMBER(H11),IF(H11>0,1,0),"")
A12: SIMULATED_FEA_Commercial_Study | B12: V01 | C12: Stimulus | D12: Commercial | E12: 60 | F12: Negative Valence | G12: -50 | H12: 0 | I12: 0 | J12: NA | K12: 96.2 | L12: =IF(K12>=80,"Yes","No") | M12: =IF(ISNUMBER(H12),IF(H12>0,1,0),"")
A13: SIMULATED_FEA_Commercial_Study | B13: V01 | C13: Stimulus | D13: Commercial | E13: 60 | F13: Engagement | G13: NA | H13: NA | I13: NA | J13: 16.96 | K13: 96.2 | L13: =IF(K13>=80,"Yes","No") | M13: =IF(ISNUMBER(H13),IF(H13>0,1,0),"")
A14: SIMULATED_FEA_Commercial_Study | B14: V01 | C14: Stimulus | D14: Recovery | E14: 15 | F14: Joy | G14: 50 | H14: 11.33 | I14: 1 | J14: NA | K14: 96.2 | L14: =IF(K14>=80,"Yes","No") | M14: =IF(ISNUMBER(H14),IF(H14>0,1,0),"")
A15: SIMULATED_FEA_Commercial_Study | B15: V01 | C15: Stimulus | D15: Recovery | E15: 15 | F15: Surprise | G15: 50 | H15: 0 | I15: 0 | J15: NA | K15: 96.2 | L15: =IF(K15>=80,"Yes","No") | M15: =IF(ISNUMBER(H15),IF(H15>0,1,0),"")
A16: SIMULATED_FEA_Commercial_Study | B16: V01 | C16: Stimulus | D16: Recovery | E16: 15 | F16: Brow Furrow | G16: 50 | H16: 0 | I16: 0 | J16: NA | K16: 96.2 | L16: =IF(K16>=80,"Yes","No") | M16: =IF(ISNUMBER(H16),IF(H16>0,1,0),"")
A17: SIMULATED_FEA_Commercial_Study | B17: V01 | C17: Stimulus | D17: Recovery | E17: 15 | F17: Positive Valence | G17: 50 | H17: 10.44 | I17: 1 | J17: NA | K17: 96.2 | L17: =IF(K17>=80,"Yes","No") | M17: =IF(ISNUMBER(H17),IF(H17>0,1,0),"")
A18: SIMULATED_FEA_Commercial_Study | B18: V01 | C18: Stimulus | D18: Recovery | E18: 15 | F18: Negative Valence | G18: -50 | H18: 0 | I18: 0 | J18: NA | K18: 96.2 | L18: =IF(K18>=80,"Yes","No") | M18: =IF(ISNUMBER(H18),IF(H18>0,1,0),"")
A19: SIMULATED_FEA_Commercial_Study | B19: V01 | C19: Stimulus | D19: Recovery | E19: 15 | F19: Engagement | G19: NA | H19: NA | I19: NA | J19: 8.58 | K19: 96.2 | L19: =IF(K19>=80,"Yes","No") | M19: =IF(ISNUMBER(H19),IF(H19>0,1,0),"")
A20: SIMULATED_FEA_Commercial_Study | B20: V01 | C20: Annotation | D20: Bin_01 | E20: 10 | F20: Joy | G20: 50 | H20: 0 | I20: 0 | J20: NA | K20: 96.2 | L20: =IF(K20>=80,"Yes","No") | M20: =IF(ISNUMBER(H20),IF(H20>0,1,0),"")
A21: SIMULATED_FEA_Commercial_Study | B21: V01 | C21: Annotation | D21: Bin_01 | E21: 10 | F21: Surprise | G21: 50 | H21: 0 | I21: 0 | J21: NA | K21: 96.2 | L21: =IF(K21>=80,"Yes","No") | M21: =IF(ISNUMBER(H21),IF(H21>0,1,0),"")
A22: SIMULATED_FEA_Commercial_Study | B22: V01 | C22: Annotation | D22: Bin_01 | E22: 10 | F22: Brow Furrow | G22: 50 | H22: 0 | I22: 0 | J22: NA | K22: 96.2 | L22: =IF(K22>=80,"Yes","No") | M22: =IF(ISNUMBER(H22),IF(H22>0,1,0),"")
A23: SIMULATED_FEA_Commercial_Study | B23: V01 | C23: Annotation | D23: Bin_01 | E23: 10 | F23: Positive Valence | G23: 50 | H23: 0 | I23: 0 | J23: NA | K23: 96.2 | L23: =IF(K23>=80,"Yes","No") | M23: =IF(ISNUMBER(H23),IF(H23>0,1,0),"")
A24: SIMULATED_FEA_Commercial_Study | B24: V01 | C24: Annotation | D24: Bin_01 | E24: 10 | F24: Negative Valence | G24: -50 | H24: 0 | I24: 0 | J24: NA | K24: 96.2 | L24: =IF(K24>=80,"Yes","No") | M24: =IF(ISNUMBER(H24),IF(H24>0,1,0),"")
A25: SIMULATED_FEA_Commercial_Study | B25: V01 | C25: Annotation | D25: Bin_01 | E25: 10 | F25: Engagement | G25: NA | H25: NA | I25: NA | J25: 1.66 | K25: 96.2 | L25: =IF(K25>=80,"Yes","No") | M25: =IF(ISNUMBER(H25),IF(H25>0,1,0),"")
A26: SIMULATED_FEA_Commercial_Study | B26: V01 | C26: Annotation | D26: Bin_02 | E26: 10 | F26: Joy | G26: 50 | H26: 42 | I26: 1 | J26: NA | K26: 96.2 | L26: =IF(K26>=80,"Yes","No") | M26: =IF(ISNUMBER(H26),IF(H26>0,1,0),"")
A27: SIMULATED_FEA_Commercial_Study | B27: V01 | C27: Annotation | D27: Bin_02 | E27: 10 | F27: Surprise | G27: 50 | H27: 0 | I27: 0 | J27: NA | K27: 96.2 | L27: =IF(K27>=80,"Yes","No") | M27: =IF(ISNUMBER(H27),IF(H27>0,1,0),"")
A28: SIMULATED_FEA_Commercial_Study | B28: V01 | C28: Annotation | D28: Bin_02 | E28: 10 | F28: Brow Furrow | G28: 50 | H28: 0 | I28: 0 | J28: NA | K28: 96.2 | L28: =IF(K28>=80,"Yes","No") | M28: =IF(ISNUMBER(H28),IF(H28>0,1,0),"")
A29: SIMULATED_FEA_Commercial_Study | B29: V01 | C29: Annotation | D29: Bin_02 | E29: 10 | F29: Positive Valence | G29: 50 | H29: 37.33 | I29: 1 | J29: NA | K29: 96.2 | L29: =IF(K29>=80,"Yes","No") | M29: =IF(ISNUMBER(H29),IF(H29>0,1,0),"")
A30: SIMULATED_FEA_Commercial_Study | B30: V01 | C30: Annotation | D30: Bin_02 | E30: 10 | F30: Negative Valence | G30: -50 | H30: 0 | I30: 0 | J30: NA | K30: 96.2 | L30: =IF(K30>=80,"Yes","No") | M30: =IF(ISNUMBER(H30),IF(H30>0,1,0),"")
A31: SIMULATED_FEA_Commercial_Study | B31: V01 | C31: Annotation | D31: Bin_02 | E31: 10 | F31: Engagement | G31: NA | H31: NA | I31: NA | J31: 22.78 | K31: 96.2 | L31: =IF(K31>=80,"Yes","No") | M31: =IF(ISNUMBER(H31),IF(H31>0,1,0),"")
A32: SIMULATED_FEA_Commercial_Study | B32: V01 | C32: Annotation | D32: Bin_03 | E32: 10 | F32: Joy | G32: 50 | H32: 9.33 | I32: 1 | J32: NA | K32: 96.2 | L32: =IF(K32>=80,"Yes","No") | M32: =IF(ISNUMBER(H32),IF(H32>0,1,0),"")
A33: SIMULATED_FEA_Commercial_Study | B33: V01 | C33: Annotation | D33: Bin_03 | E33: 10 | F33: Surprise | G33: 50 | H33: 18.33 | I33: 2 | J33: NA | K33: 96.2 | L33: =IF(K33>=80,"Yes","No") | M33: =IF(ISNUMBER(H33),IF(H33>0,1,0),"")
A34: SIMULATED_FEA_Commercial_Study | B34: V01 | C34: Annotation | D34: Bin_03 | E34: 10 | F34: Brow Furrow | G34: 50 | H34: 0 | I34: 0 | J34: NA | K34: 96.2 | L34: =IF(K34>=80,"Yes","No") | M34: =IF(ISNUMBER(H34),IF(H34>0,1,0),"")
A35: SIMULATED_FEA_Commercial_Study | B35: V01 | C35: Annotation | D35: Bin_03 | E35: 10 | F35: Positive Valence | G35: 50 | H35: 8.67 | I35: 1 | J35: NA | K35: 96.2 | L35: =IF(K35>=80,"Yes","No") | M35: =IF(ISNUMBER(H35),IF(H35>0,1,0),"")
A36: SIMULATED_FEA_Commercial_Study | B36: V01 | C36: Annotation | D36: Bin_03 | E36: 10 | F36: Negative Valence | G36: -50 | H36: 0 | I36: 0 | J36: NA | K36: 96.2 | L36: =IF(K36>=80,"Yes","No") | M36: =IF(ISNUMBER(H36),IF(H36>0,1,0),"")
A37: SIMULATED_FEA_Commercial_Study | B37: V01 | C37: Annotation | D37: Bin_03 | E37: 10 | F37: Engagement | G37: NA | H37: NA | I37: NA | J37: 24.35 | K37: 96.2 | L37: =IF(K37>=80,"Yes","No") | M37: =IF(ISNUMBER(H37),IF(H37>0,1,0),"")
A38: SIMULATED_FEA_Commercial_Study | B38: V01 | C38: Annotation | D38: Bin_04 | E38: 10 | F38: Joy | G38: 50 | H38: 4.33 | I38: 1 | J38: NA | K38: 96.2 | L38: =IF(K38>=80,"Yes","No") | M38: =IF(ISNUMBER(H38),IF(H38>0,1,0),"")
A39: SIMULATED_FEA_Commercial_Study | B39: V01 | C39: Annotation | D39: Bin_04 | E39: 10 | F39: Surprise | G39: 50 | H39: 13.67 | I39: 1 | J39: NA | K39: 96.2 | L39: =IF(K39>=80,"Yes","No") | M39: =IF(ISNUMBER(H39),IF(H39>0,1,0),"")
A40: SIMULATED_FEA_Commercial_Study | B40: V01 | C40: Annotation | D40: Bin_04 | E40: 10 | F40: Brow Furrow | G40: 50 | H40: 0 | I40: 0 | J40: NA | K40: 96.2 | L40: =IF(K40>=80,"Yes","No") | M40: =IF(ISNUMBER(H40),IF(H40>0,1,0),"")
...

Sheet Summary
A1: Descriptive table by expression and interval (kept respondents only). SIMULATED data.
A2: n = kept respondents with a row; Mean, SD, and Median are of Percent of time present; Viewers present = respondents whose Percent of time present is above 0; Mean segments = Number of segments. Engagement (second table) is a raw mean score.
A4: Expression | B4: Interval | C4: n | D4: Mean time present (%) | E4: SD (%) | F4: Median (%) | G4: Viewers present (n) | H4: Viewers present (%) | I4: Mean segments
A5: Joy | B5: Baseline | C5: =COUNTIFS(Data!$F$2:$F$1729,$A5,Data!$D$2:$D$1729,$B5,Data!$L$2:$L$1729,"Yes") | D5: =AVERAGEIFS(Data!$H$2:$H$1729,Data!$F$2:$F$1729,$A5,Data!$D$2:$D$1729,$B5,Data!$L$2:$L$1729,"Yes") | E5: {=_xlfn.STDEV.S(IF((Data!$F$2:$F$1729=$A5)*(Data!$D$2:$D$1729=$B5)*(Data!$L$2:$L$1729="Yes"),Data!$H$2:$H$1729))} | F5: {=MEDIAN(IF((Data!$F$2:$F$1729=$A5)*(Data!$D$2:$D$1729=$B5)*(Data!$L$2:$L$1729="Yes"),Data!$H$2:$H$1729))} | G5: =COUNTIFS(Data!$F$2:$F$1729,$A5,Data!$D$2:$D$1729,$B5,Data!$L$2:$L$1729,"Yes",Data!$H$2:$H$1729,">0") | H5: =100*G5/C5 | I5: =AVERAGEIFS(Data!$I$2:$I$1729,Data!$F$2:$F$1729,$A5,Data!$D$2:$D$1729,$B5,Data!$L$2:$L$1729,"Yes")
A6: Joy | B6: Commercial | C6: =COUNTIFS(Data!$F$2:$F$1729,$A6,Data!$D$2:$D$1729,$B6,Data!$L$2:$L$1729,"Yes") | D6: =AVERAGEIFS(Data!$H$2:$H$1729,Data!$F$2:$F$1729,$A6,Data!$D$2:$D$1729,$B6,Data!$L$2:$L$1729,"Yes") | E6: {=_xlfn.STDEV.S(IF((Data!$F$2:$F$1729=$A6)*(Data!$D$2:$D$1729=$B6)*(Data!$L$2:$L$1729="Yes"),Data!$H$2:$H$1729))} | F6: {=MEDIAN(IF((Data!$F$2:$F$1729=$A6)*(Data!$D$2:$D$1729=$B6)*(Data!$L$2:$L$1729="Yes"),Data!$H$2:$H$1729))} | G6: =COUNTIFS(Data!$F$2:$F$1729,$A6,Data!$D$2:$D$1729,$B6,Data!$L$2:$L$1729,"Yes",Data!$H$2:$H$1729,">0") | H6: =100*G6/C6 | I6: =AVERAGEIFS(Data!$I$2:$I$1729,Data!$F$2:$F$1729,$A6,Data!$D$2:$D$1729,$B6,Data!$L$2:$L$1729,"Yes")
A7: Joy | B7: Recovery | C7: =COUNTIFS(Data!$F$2:$F$1729,$A7,Data!$D$2:$D$1729,$B7,Data!$L$2:$L$1729,"Yes") | D7: =AVERAGEIFS(Data!$H$2:$H$1729,Data!$F$2:$F$1729,$A7,Data!$D$2:$D$1729,$B7,Data!$L$2:$L$1729,"Yes") | E7: {=_xlfn.STDEV.S(IF((Data!$F$2:$F$1729=$A7)*(Data!$D$2:$D$1729=$B7)*(Data!$L$2:$L$1729="Yes"),Data!$H$2:$H$1729))} | F7: {=MEDIAN(IF((Data!$F$2:$F$1729=$A7)*(Data!$D$2:$D$1729=$B7)*(Data!$L$2:$L$1729="Yes"),Data!$H$2:$H$1729))} | G7: =COUNTIFS(Data!$F$2:$F$1729,$A7,Data!$D$2:$D$1729,$B7,Data!$L$2:$L$1729,"Yes",Data!$H$2:$H$1729,">0") | H7: =100*G7/C7 | I7: =AVERAGEIFS(Data!$I$2:$I$1729,Data!$F$2:$F$1729,$A7,Data!$D$2:$D$1729,$B7,Data!$L$2:$L$1729,"Yes")
A8: Joy | B8: Bin_01 | C8: =COUNTIFS(Data!$F$2:$F$1729,$A8,Data!$D$2:$D$1729,$B8,Data!$L$2:$L$1729,"Yes") | D8: =AVERAGEIFS(Data!$H$2:$H$1729,Data!$F$2:$F$1729,$A8,Data!$D$2:$D$1729,$B8,Data!$L$2:$L$1729,"Yes") | E8: {=_xlfn.STDEV.S(IF((Data!$F$2:$F$1729=$A8)*(Data!$D$2:$D$1729=$B8)*(Data!$L$2:$L$1729="Yes"),Data!$H$2:$H$1729))} | F8: {=MEDIAN(IF((Data!$F$2:$F$1729=$A8)*(Data!$D$2:$D$1729=$B8)*(Data!$L$2:$L$1729="Yes"),Data!$H$2:$H$1729))} | G8: =COUNTIFS(Data!$F$2:$F$1729,$A8,Data!$D$2:$D$1729,$B8,Data!$L$2:$L$1729,"Yes",Data!$H$2:$H$1729,">0") | H8: =100*G8/C8 | I8: =AVERAGEIFS(Data!$I$2:$I$1729,Data!$F$2:$F$1729,$A8,Data!$D$2:$D$1729,$B8,Data!$L$2:$L$1729,"Yes")
A9: Joy | B9: Bin_02 | C9: =COUNTIFS(Data!$F$2:$F$1729,$A9,Data!$D$2:$D$1729,$B9,Data!$L$2:$L$1729,"Yes") | D9: =AVERAGEIFS(Data!$H$2:$H$1729,Data!$F$2:$F$1729,$A9,Data!$D$2:$D$1729,$B9,Data!$L$2:$L$1729,"Yes") | E9: {=_xlfn.STDEV.S(IF((Data!$F$2:$F$1729=$A9)*(Data!$D$2:$D$1729=$B9)*(Data!$L$2:$L$1729="Yes"),Data!$H$2:$H$1729))} | F9: {=MEDIAN(IF((Data!$F$2:$F$1729=$A9)*(Data!$D$2:$D$1729=$B9)*(Data!$L$2:$L$1729="Yes"),Data!$H$2:$H$1729))} | G9: =COUNTIFS(Data!$F$2:$F$1729,$A9,Data!$D$2:$D$1729,$B9,Data!$L$2:$L$1729,"Yes",Data!$H$2:$H$1729,">0") | H9: =100*G9/C9 | I9: =AVERAGEIFS(Data!$I$2:$I$1729,Data!$F$2:$F$1729,$A9,Data!$D$2:$D$1729,$B9,Data!$L$2:$L$1729,"Yes")
A10: Joy | B10: Bin_03 | C10: =COUNTIFS(Data!$F$2:$F$1729,$A10,Data!$D$2:$D$1729,$B10,Data!$L$2:$L$1729,"Yes") | D10: =AVERAGEIFS(Data!$H$2:$H$1729,Data!$F$2:$F$1729,$A10,Data!$D$2:$D$1729,$B10,Data!$L$2:$L$1729,"Yes") | E10: {=_xlfn.STDEV.S(IF((Data!$F$2:$F$1729=$A10)*(Data!$D$2:$D$1729=$B10)*(Data!$L$2:$L$1729="Yes"),Data!$H$2:$H$1729))} | F10: {=MEDIAN(IF((Data!$F$2:$F$1729=$A10)*(Data!$D$2:$D$1729=$B10)*(Data!$L$2:$L$1729="Yes"),Data!$H$2:$H$1729))} | G10: =COUNTIFS(Data!$F$2:$F$1729,$A10,Data!$D$2:$D$1729,$B10,Data!$L$2:$L$1729,"Yes",Data!$H$2:$H$1729,">0") | H10: =100*G10/C10 | I10: =AVERAGEIFS(Data!$I$2:$I$1729,Data!$F$2:$F$1729,$A10,Data!$D$2:$D$1729,$B10,Data!$L$2:$L$1729,"Yes")
A11: Joy | B11: Bin_04 | C11: =COUNTIFS(Data!$F$2:$F$1729,$A11,Data!$D$2:$D$1729,$B11,Data!$L$2:$L$1729,"Yes") | D11: =AVERAGEIFS(Data!$H$2:$H$1729,Data!$F$2:$F$1729,$A11,Data!$D$2:$D$1729,$B11,Data!$L$2:$L$1729,"Yes") | E11: {=_xlfn.STDEV.S(IF((Data!$F$2:$F$1729=$A11)*(Data!$D$2:$D$1729=$B11)*(Data!$L$2:$L$1729="Yes"),Data!$H$2:$H$1729))} | F11: {=MEDIAN(IF((Data!$F$2:$F$1729=$A11)*(Data!$D$2:$D$1729=$B11)*(Data!$L$2:$L$1729="Yes"),Data!$H$2:$H$1729))} | G11: =COUNTIFS(Data!$F$2:$F$1729,$A11,Data!$D$2:$D$1729,$B11,Data!$L$2:$L$1729,"Yes",Data!$H$2:$H$1729,">0") | H11: =100*G11/C11 | I11: =AVERAGEIFS(Data!$I$2:$I$1729,Data!$F$2:$F$1729,$A11,Data!$D$2:$D$1729,$B11,Data!$L$2:$L$1729,"Yes")
A12: Joy | B12: Bin_05 | C12: =COUNTIFS(Data!$F$2:$F$1729,$A12,Data!$D$2:$D$1729,$B12,Data!$L$2:$L$1729,"Yes") | D12: =AVERAGEIFS(Data!$H$2:$H$1729,Data!$F$2:$F$1729,$A12,Data!$D$2:$D$1729,$B12,Data!$L$2:$L$1729,"Yes") | E12: {=_xlfn.STDEV.S(IF((Data!$F$2:$F$1729=$A12)*(Data!$D$2:$D$1729=$B12)*(Data!$L$2:$L$1729="Yes"),Data!$H$2:$H$1729))} | F12: {=MEDIAN(IF((Data!$F$2:$F$1729=$A12)*(Data!$D$2:$D$1729=$B12)*(Data!$L$2:$L$1729="Yes"),Data!$H$2:$H$1729))} | G12: =COUNTIFS(Data!$F$2:$F$1729,$A12,Data!$D$2:$D$1729,$B12,Data!$L$2:$L$1729,"Yes",Data!$H$2:$H$1729,">0") | H12: =100*G12/C12 | I12: =AVERAGEIFS(Data!$I$2:$I$1729,Data!$F$2:$F$1729,$A12,Data!$D$2:$D$1729,$B12,Data!$L$2:$L$1729,"Yes")
A13: Joy | B13: Bin_06 | C13: =COUNTIFS(Data!$F$2:$F$1729,$A13,Data!$D$2:$D$1729,$B13,Data!$L$2:$L$1729,"Yes") | D13: =AVERAGEIFS(Data!$H$2:$H$1729,Data!$F$2:$F$1729,$A13,Data!$D$2:$D$1729,$B13,Data!$L$2:$L$1729,"Yes") | E13: {=_xlfn.STDEV.S(IF((Data!$F$2:$F$1729=$A13)*(Data!$D$2:$D$1729=$B13)*(Data!$L$2:$L$1729="Yes"),Data!$H$2:$H$1729))} | F13: {=MEDIAN(IF((Data!$F$2:$F$1729=$A13)*(Data!$D$2:$D$1729=$B13)*(Data!$L$2:$L$1729="Yes"),Data!$H$2:$H$1729))} | G13: =COUNTIFS(Data!$F$2:$F$1729,$A13,Data!$D$2:$D$1729,$B13,Data!$L$2:$L$1729,"Yes",Data!$H$2:$H$1729,">0") | H13: =100*G13/C13 | I13: =AVERAGEIFS(Data!$I$2:$I$1729,Data!$F$2:$F$1729,$A13,Data!$D$2:$D$1729,$B13,Data!$L$2:$L$1729,"Yes")
A14: Surprise | B14: Baseline | C14: =COUNTIFS(Data!$F$2:$F$1729,$A14,Data!$D$2:$D$1729,$B14,Data!$L$2:$L$1729,"Yes") | D14: =AVERAGEIFS(Data!$H$2:$H$1729,Data!$F$2:$F$1729,$A14,Data!$D$2:$D$1729,$B14,Data!$L$2:$L$1729,"Yes") | E14: {=_xlfn.STDEV.S(IF((Data!$F$2:$F$1729=$A14)*(Data!$D$2:$D$1729=$B14)*(Data!$L$2:$L$1729="Yes"),Data!$H$2:$H$1729))} | F14: {=MEDIAN(IF((Data!$F$2:$F$1729=$A14)*(Data!$D$2:$D$1729=$B14)*(Data!$L$2:$L$1729="Yes"),Data!$H$2:$H$1729))} | G14: =COUNTIFS(Data!$F$2:$F$1729,$A14,Data!$D$2:$D$1729,$B14,Data!$L$2:$L$1729,"Yes",Data!$H$2:$H$1729,">0") | H14: =100*G14/C14 | I14: =AVERAGEIFS(Data!$I$2:$I$1729,Data!$F$2:$F$1729,$A14,Data!$D$2:$D$1729,$B14,Data!$L$2:$L$1729,"Yes")
A15: Surprise | B15: Commercial | C15: =COUNTIFS(Data!$F$2:$F$1729,$A15,Data!$D$2:$D$1729,$B15,Data!$L$2:$L$1729,"Yes") | D15: =AVERAGEIFS(Data!$H$2:$H$1729,Data!$F$2:$F$1729,$A15,Data!$D$2:$D$1729,$B15,Data!$L$2:$L$1729,"Yes") | E15: {=_xlfn.STDEV.S(IF((Data!$F$2:$F$1729=$A15)*(Data!$D$2:$D$1729=$B15)*(Data!$L$2:$L$1729="Yes"),Data!$H$2:$H$1729))} | F15: {=MEDIAN(IF((Data!$F$2:$F$1729=$A15)*(Data!$D$2:$D$1729=$B15)*(Data!$L$2:$L$1729="Yes"),Data!$H$2:$H$1729))} | G15: =COUNTIFS(Data!$F$2:$F$1729,$A15,Data!$D$2:$D$1729,$B15,Data!$L$2:$L$1729,"Yes",Data!$H$2:$H$1729,">0") | H15: =100*G15/C15 | I15: =AVERAGEIFS(Data!$I$2:$I$1729,Data!$F$2:$F$1729,$A15,Data!$D$2:$D$1729,$B15,Data!$L$2:$L$1729,"Yes")
A16: Surprise | B16: Recovery | C16: =COUNTIFS(Data!$F$2:$F$1729,$A16,Data!$D$2:$D$1729,$B16,Data!$L$2:$L$1729,"Yes") | D16: =AVERAGEIFS(Data!$H$2:$H$1729,Data!$F$2:$F$1729,$A16,Data!$D$2:$D$1729,$B16,Data!$L$2:$L$1729,"Yes") | E16: {=_xlfn.STDEV.S(IF((Data!$F$2:$F$1729=$A16)*(Data!$D$2:$D$1729=$B16)*(Data!$L$2:$L$1729="Yes"),Data!$H$2:$H$1729))} | F16: {=MEDIAN(IF((Data!$F$2:$F$1729=$A16)*(Data!$D$2:$D$1729=$B16)*(Data!$L$2:$L$1729="Yes"),Data!$H$2:$H$1729))} | G16: =COUNTIFS(Data!$F$2:$F$1729,$A16,Data!$D$2:$D$1729,$B16,Data!$L$2:$L$1729,"Yes",Data!$H$2:$H$1729,">0") | H16: =100*G16/C16 | I16: =AVERAGEIFS(Data!$I$2:$I$1729,Data!$F$2:$F$1729,$A16,Data!$D$2:$D$1729,$B16,Data!$L$2:$L$1729,"Yes")
... A49: Negative Valence | B49: Bin_06 | C49: =COUNTIFS(Data!$F$2:$F$1729,$A49,Data!$D$2:$D$1729,$B49,Data!$L$2:$L$1729,"Yes") | D49: =AVERAGEIFS(Data!$H$2:$H$1729,Data!$F$2:$F$1729,$A49,Data!$D$2:$D$1729,$B49,Data!$L$2:$L$1729,"Yes") | E49: {=_xlfn.STDEV.S(IF((Data!$F$2:$F$1729=$A49)*(Data!$D$2:$D$1729=$B49)*(Data!$L$2:$L$1729="Yes"),Data!$H$2:$H$1729))} | F49: {=MEDIAN(IF((Data!$F$2:$F$1729=$A49)*(Data!$D$2:$D$1729=$B49)*(Data!$L$2:$L$1729="Yes"),Data!$H$2:$H$1729))} | G49: =COUNTIFS(Data!$F$2:$F$1729,$A49,Data!$D$2:$D$1729,$B49,Data!$L$2:$L$1729,"Yes",Data!$H$2:$H$1729,">0") | H49: =100*G49/C49 | I49: =AVERAGEIFS(Data!$I$2:$I$1729,Data!$F$2:$F$1729,$A49,Data!$D$2:$D$1729,$B49,Data!$L$2:$L$1729,"Yes")
A51: Engagement: raw mean score (0 to 100), kept respondents. Not thresholded.
A52: Expression | B52: Interval | C52: n | D52: Mean raw score | E52: SD | F52: Median
A53: Engagement | B53: Baseline | C53: =COUNTIFS(Data!$F$2:$F$1729,$A53,Data!$D$2:$D$1729,$B53,Data!$L$2:$L$1729,"Yes",Data!$J$2:$J$1729,">=0") | D53: =AVERAGEIFS(Data!$J$2:$J$1729,Data!$F$2:$F$1729,$A53,Data!$D$2:$D$1729,$B53,Data!$L$2:$L$1729,"Yes") | E53: {=_xlfn.STDEV.S(IF((Data!$F$2:$F$1729=$A53)*(Data!$D$2:$D$1729=$B53)*(Data!$L$2:$L$1729="Yes"),Data!$J$2:$J$1729))} | F53: {=MEDIAN(IF((Data!$F$2:$F$1729=$A53)*(Data!$D$2:$D$1729=$B53)*(Data!$L$2:$L$1729="Yes"),Data!$J$2:$J$1729))}
A54: Engagement | B54: Commercial | C54: =COUNTIFS(Data!$F$2:$F$1729,$A54,Data!$D$2:$D$1729,$B54,Data!$L$2:$L$1729,"Yes",Data!$J$2:$J$1729,">=0") | D54: =AVERAGEIFS(Data!$J$2:$J$1729,Data!$F$2:$F$1729,$A54,Data!$D$2:$D$1729,$B54,Data!$L$2:$L$1729,"Yes") | E54: {=_xlfn.STDEV.S(IF((Data!$F$2:$F$1729=$A54)*(Data!$D$2:$D$1729=$B54)*(Data!$L$2:$L$1729="Yes"),Data!$J$2:$J$1729))} | F54: {=MEDIAN(IF((Data!$F$2:$F$1729=$A54)*(Data!$D$2:$D$1729=$B54)*(Data!$L$2:$L$1729="Yes"),Data!$J$2:$J$1729))}
A55: Engagement | B55: Recovery | C55: =COUNTIFS(Data!$F$2:$F$1729,$A55,Data!$D$2:$D$1729,$B55,Data!$L$2:$L$1729,"Yes",Data!$J$2:$J$1729,">=0") | D55: =AVERAGEIFS(Data!$J$2:$J$1729,Data!$F$2:$F$1729,$A55,Data!$D$2:$D$1729,$B55,Data!$L$2:$L$1729,"Yes") | E55: {=_xlfn.STDEV.S(IF((Data!$F$2:$F$1729=$A55)*(Data!$D$2:$D$1729=$B55)*(Data!$L$2:$L$1729="Yes"),Data!$J$2:$J$1729))} | F55: {=MEDIAN(IF((Data!$F$2:$F$1729=$A55)*(Data!$D$2:$D$1729=$B55)*(Data!$L$2:$L$1729="Yes"),Data!$J$2:$J$1729))}
A56: Engagement | B56: Bin_01 | C56: =COUNTIFS(Data!$F$2:$F$1729,$A56,Data!$D$2:$D$1729,$B56,Data!$L$2:$L$1729,"Yes",Data!$J$2:$J$1729,">=0") | D56: =AVERAGEIFS(Data!$J$2:$J$1729,Data!$F$2:$F$1729,$A56,Data!$D$2:$D$1729,$B56,Data!$L$2:$L$1729,"Yes") | E56: {=_xlfn.STDEV.S(IF((Data!$F$2:$F$1729=$A56)*(Data!$D$2:$D$1729=$B56)*(Data!$L$2:$L$1729="Yes"),Data!$J$2:$J$1729))} | F56: {=MEDIAN(IF((Data!$F$2:$F$1729=$A56)*(Data!$D$2:$D$1729=$B56)*(Data!$L$2:$L$1729="Yes"),Data!$J$2:$J$1729))}
A57: Engagement | B57: Bin_02 | C57: =COUNTIFS(Data!$F$2:$F$1729,$A57,Data!$D$2:$D$1729,$B57,Data!$L$2:$L$1729,"Yes",Data!$J$2:$J$1729,">=0") | D57: =AVERAGEIFS(Data!$J$2:$J$1729,Data!$F$2:$F$1729,$A57,Data!$D$2:$D$1729,$B57,Data!$L$2:$L$1729,"Yes") | E57: {=_xlfn.STDEV.S(IF((Data!$F$2:$F$1729=$A57)*(Data!$D$2:$D$1729=$B57)*(Data!$L$2:$L$1729="Yes"),Data!$J$2:$J$1729))} | F57: {=MEDIAN(IF((Data!$F$2:$F$1729=$A57)*(Data!$D$2:$D$1729=$B57)*(Data!$L$2:$L$1729="Yes"),Data!$J$2:$J$1729))}
A58: Engagement | B58: Bin_03 | C58: =COUNTIFS(Data!$F$2:$F$1729,$A58,Data!$D$2:$D$1729,$B58,Data!$L$2:$L$1729,"Yes",Data!$J$2:$J$1729,">=0") | D58: =AVERAGEIFS(Data!$J$2:$J$1729,Data!$F$2:$F$1729,$A58,Data!$D$2:$D$1729,$B58,Data!$L$2:$L$1729,"Yes") | E58: {=_xlfn.STDEV.S(IF((Data!$F$2:$F$1729=$A58)*(Data!$D$2:$D$1729=$B58)*(Data!$L$2:$L$1729="Yes"),Data!$J$2:$J$1729))} | F58: {=MEDIAN(IF((Data!$F$2:$F$1729=$A58)*(Data!$D$2:$D$1729=$B58)*(Data!$L$2:$L$1729="Yes"),Data!$J$2:$J$1729))}
A59: Engagement | B59: Bin_04 | C59: =COUNTIFS(Data!$F$2:$F$1729,$A59,Data!$D$2:$D$1729,$B59,Data!$L$2:$L$1729,"Yes",Data!$J$2:$J$1729,">=0") | D59: =AVERAGEIFS(Data!$J$2:$J$1729,Data!$F$2:$F$1729,$A59,Data!$D$2:$D$1729,$B59,Data!$L$2:$L$1729,"Yes") | E59: {=_xlfn.STDEV.S(IF((Data!$F$2:$F$1729=$A59)*(Data!$D$2:$D$1729=$B59)*(Data!$L$2:$L$1729="Yes"),Data!$J$2:$J$1729))} | F59: {=MEDIAN(IF((Data!$F$2:$F$1729=$A59)*(Data!$D$2:$D$1729=$B59)*(Data!$L$2:$L$1729="Yes"),Data!$J$2:$J$1729))}
A60: Engagement | B60: Bin_05 | C60: =COUNTIFS(Data!$F$2:$F$1729,$A60,Data!$D$2:$D$1729,$B60,Data!$L$2:$L$1729,"Yes",Data!$J$2:$J$1729,">=0") | D60: =AVERAGEIFS(Data!$J$2:$J$1729,Data!$F$2:$F$1729,$A60,Data!$D$2:$D$1729,$B60,Data!$L$2:$L$1729,"Yes") | E60: {=_xlfn.STDEV.S(IF((Data!$F$2:$F$1729=$A60)*(Data!$D$2:$D$1729=$B60)*(Data!$L$2:$L$1729="Yes"),Data!$J$2:$J$1729))} | F60: {=MEDIAN(IF((Data!$F$2:$F$1729=$A60)*(Data!$D$2:$D$1729=$B60)*(Data!$L$2:$L$1729="Yes"),Data!$J$2:$J$1729))}
A61: Engagement | B61: Bin_06 | C61: =COUNTIFS(Data!$F$2:$F$1729,$A61,Data!$D$2:$D$1729,$B61,Data!$L$2:$L$1729,"Yes",Data!$J$2:$J$1729,">=0") | D61: =AVERAGEIFS(Data!$J$2:$J$1729,Data!$F$2:$F$1729,$A61,Data!$D$2:$D$1729,$B61,Data!$L$2:$L$1729,"Yes") | E61: {=_xlfn.STDEV.S(IF((Data!$F$2:$F$1729=$A61)*(Data!$D$2:$D$1729=$B61)*(Data!$L$2:$L$1729="Yes"),Data!$J$2:$J$1729))} | F61: {=MEDIAN(IF((Data!$F$2:$F$1729=$A61)*(Data!$D$2:$D$1729=$B61)*(Data!$L$2:$L$1729="Yes"),Data!$J$2:$J$1729))}
A63: Array formulas (SD and Median columns): Excel 365 evaluates them with Enter; Excel 2019 or older needs Ctrl+Shift+Enter after editing.
A66: Chart table: mean Joy Percent of time present by interval
A67: Interval | B67: Mean Joy (%)
A68: Baseline | B68: =D5
A69: Commercial | B69: =D6
A70: Recovery | B70: =D7
A71: Bin_01 | B71: =D8
A72: Bin_02 | B72: =D9
A73: Bin_03 | B73: =D10
A74: Bin_04 | B74: =D11
A75: Bin_05 | B75: =D12
A76: Bin_06 | B76: =D13

Sheet H1
A1: H1. Joy Percent of time present, Commercial versus Baseline, kept respondents. SIMULATED data.
A2: One row per kept respondent. Columns C and D pull the two values from the Data sheet with SUMIFS (each respondent has exactly one Joy row per interval). Difference is Commercial minus Baseline, rounded to 2 decimals so tied differences tie.
A4: Respondent Name | B4: Data quality (%) | C4: Baseline Joy (%) | D4: Commercial Joy (%) | E4: Difference (Commercial minus Baseline) | F4: Absolute difference | G4: Rank of absolute difference (zeros left out) | H4: Sign of difference | I4: Tie term (c^2 - 1) | K4: Statistic | L4: Value | M4: Formula shown | N4: Note
A5: V01 | B5: =INDEX(Data!$K$2:$K$1729,MATCH($A5,Data!$B$2:$B$1729,0)) | C5: =SUMIFS(Data!$H$2:$H$1729,Data!$B$2:$B$1729,$A5,Data!$F$2:$F$1729,"Joy",Data!$D$2:$D$1729,"Baseline") | D5: =SUMIFS(Data!$H$2:$H$1729,Data!$B$2:$B$1729,$A5,Data!$F$2:$F$1729,"Joy",Data!$D$2:$D$1729,"Commercial") | E5: =ROUND(D5-C5,2) | F5: =ABS(E5) | G5: =IF(E5=0,"",_xlfn.RANK.AVG(F5,$F$5:$F$34,1)-COUNTIF($E$5:$E$34,0)) | H5: =SIGN(E5) | I5: =IF(E5=0,0,COUNTIF($F$5:$F$34,F5)^2-1) | K5: Paired t test and d_z: Joy Percent of time present
A6: V02 | B6: =INDEX(Data!$K$2:$K$1729,MATCH($A6,Data!$B$2:$B$1729,0)) | C6: =SUMIFS(Data!$H$2:$H$1729,Data!$B$2:$B$1729,$A6,Data!$F$2:$F$1729,"Joy",Data!$D$2:$D$1729,"Baseline") | D6: =SUMIFS(Data!$H$2:$H$1729,Data!$B$2:$B$1729,$A6,Data!$F$2:$F$1729,"Joy",Data!$D$2:$D$1729,"Commercial") | E6: =ROUND(D6-C6,2) | F6: =ABS(E6) | G6: =IF(E6=0,"",_xlfn.RANK.AVG(F6,$F$5:$F$34,1)-COUNTIF($E$5:$E$34,0)) | H6: =SIGN(E6) | I6: =IF(E6=0,0,COUNTIF($F$5:$F$34,F6)^2-1) | K6: Baseline mean (%) | L6: =AVERAGE(C5:C34) | M6: =AVERAGE(C5:C34) | N6: AVERAGE of the Baseline column
A7: V03 | B7: =INDEX(Data!$K$2:$K$1729,MATCH($A7,Data!$B$2:$B$1729,0)) | C7: =SUMIFS(Data!$H$2:$H$1729,Data!$B$2:$B$1729,$A7,Data!$F$2:$F$1729,"Joy",Data!$D$2:$D$1729,"Baseline") | D7: =SUMIFS(Data!$H$2:$H$1729,Data!$B$2:$B$1729,$A7,Data!$F$2:$F$1729,"Joy",Data!$D$2:$D$1729,"Commercial") | E7: =ROUND(D7-C7,2) | F7: =ABS(E7) | G7: =IF(E7=0,"",_xlfn.RANK.AVG(F7,$F$5:$F$34,1)-COUNTIF($E$5:$E$34,0)) | H7: =SIGN(E7) | I7: =IF(E7=0,0,COUNTIF($F$5:$F$34,F7)^2-1) | K7: Baseline SD (%) | L7: =_xlfn.STDEV.S(C5:C34) | M7: =STDEV.S(C5:C34) | N7: STDEV.S = sample standard deviation
A8: V04 | B8: =INDEX(Data!$K$2:$K$1729,MATCH($A8,Data!$B$2:$B$1729,0)) | C8: =SUMIFS(Data!$H$2:$H$1729,Data!$B$2:$B$1729,$A8,Data!$F$2:$F$1729,"Joy",Data!$D$2:$D$1729,"Baseline") | D8: =SUMIFS(Data!$H$2:$H$1729,Data!$B$2:$B$1729,$A8,Data!$F$2:$F$1729,"Joy",Data!$D$2:$D$1729,"Commercial") | E8: =ROUND(D8-C8,2) | F8: =ABS(E8) | G8: =IF(E8=0,"",_xlfn.RANK.AVG(F8,$F$5:$F$34,1)-COUNTIF($E$5:$E$34,0)) | H8: =SIGN(E8) | I8: =IF(E8=0,0,COUNTIF($F$5:$F$34,F8)^2-1) | K8: Commercial mean (%) | L8: =AVERAGE(D5:D34) | M8: =AVERAGE(D5:D34)
A9: V05 | B9: =INDEX(Data!$K$2:$K$1729,MATCH($A9,Data!$B$2:$B$1729,0)) | C9: =SUMIFS(Data!$H$2:$H$1729,Data!$B$2:$B$1729,$A9,Data!$F$2:$F$1729,"Joy",Data!$D$2:$D$1729,"Baseline") | D9: =SUMIFS(Data!$H$2:$H$1729,Data!$B$2:$B$1729,$A9,Data!$F$2:$F$1729,"Joy",Data!$D$2:$D$1729,"Commercial") | E9: =ROUND(D9-C9,2) | F9: =ABS(E9) | G9: =IF(E9=0,"",_xlfn.RANK.AVG(F9,$F$5:$F$34,1)-COUNTIF($E$5:$E$34,0)) | H9: =SIGN(E9) | I9: =IF(E9=0,0,COUNTIF($F$5:$F$34,F9)^2-1) | K9: Commercial SD (%) | L9: =_xlfn.STDEV.S(D5:D34) | M9: =STDEV.S(D5:D34)
A10: V06 | B10: =INDEX(Data!$K$2:$K$1729,MATCH($A10,Data!$B$2:$B$1729,0)) | C10: =SUMIFS(Data!$H$2:$H$1729,Data!$B$2:$B$1729,$A10,Data!$F$2:$F$1729,"Joy",Data!$D$2:$D$1729,"Baseline") | D10: =SUMIFS(Data!$H$2:$H$1729,Data!$B$2:$B$1729,$A10,Data!$F$2:$F$1729,"Joy",Data!$D$2:$D$1729,"Commercial") | E10: =ROUND(D10-C10,2) | F10: =ABS(E10) | G10: =IF(E10=0,"",_xlfn.RANK.AVG(F10,$F$5:$F$34,1)-COUNTIF($E$5:$E$34,0)) | H10: =SIGN(E10) | I10: =IF(E10=0,0,COUNTIF($F$5:$F$34,F10)^2-1) | K10: n pairs | L10: =COUNT(E5:E34) | M10: =COUNT(E5:E34) | N10: COUNT of the difference column; must equal the check row below
A11: V08 | B11: =INDEX(Data!$K$2:$K$1729,MATCH($A11,Data!$B$2:$B$1729,0)) | C11: =SUMIFS(Data!$H$2:$H$1729,Data!$B$2:$B$1729,$A11,Data!$F$2:$F$1729,"Joy",Data!$D$2:$D$1729,"Baseline") | D11: =SUMIFS(Data!$H$2:$H$1729,Data!$B$2:$B$1729,$A11,Data!$F$2:$F$1729,"Joy",Data!$D$2:$D$1729,"Commercial") | E11: =ROUND(D11-C11,2) | F11: =ABS(E11) | G11: =IF(E11=0,"",_xlfn.RANK.AVG(F11,$F$5:$F$34,1)-COUNTIF($E$5:$E$34,0)) | H11: =SIGN(E11) | I11: =IF(E11=0,0,COUNTIF($F$5:$F$34,F11)^2-1) | K11: Mean difference, Commercial minus Baseline (%) | L11: =AVERAGE(E5:E34) | M11: =AVERAGE(E5:E34)
A12: V09 | B12: =INDEX(Data!$K$2:$K$1729,MATCH($A12,Data!$B$2:$B$1729,0)) | C12: =SUMIFS(Data!$H$2:$H$1729,Data!$B$2:$B$1729,$A12,Data!$F$2:$F$1729,"Joy",Data!$D$2:$D$1729,"Baseline") | D12: =SUMIFS(Data!$H$2:$H$1729,Data!$B$2:$B$1729,$A12,Data!$F$2:$F$1729,"Joy",Data!$D$2:$D$1729,"Commercial") | E12: =ROUND(D12-C12,2) | F12: =ABS(E12) | G12: =IF(E12=0,"",_xlfn.RANK.AVG(F12,$F$5:$F$34,1)-COUNTIF($E$5:$E$34,0)) | H12: =SIGN(E12) | I12: =IF(E12=0,0,COUNTIF($F$5:$F$34,F12)^2-1) | K12: SD of the differences (%) | L12: =_xlfn.STDEV.S(E5:E34) | M12: =STDEV.S(E5:E34) | N12: the SD that matters in a paired test
A13: V10 | B13: =INDEX(Data!$K$2:$K$1729,MATCH($A13,Data!$B$2:$B$1729,0)) | C13: =SUMIFS(Data!$H$2:$H$1729,Data!$B$2:$B$1729,$A13,Data!$F$2:$F$1729,"Joy",Data!$D$2:$D$1729,"Baseline") | D13: =SUMIFS(Data!$H$2:$H$1729,Data!$B$2:$B$1729,$A13,Data!$F$2:$F$1729,"Joy",Data!$D$2:$D$1729,"Commercial") | E13: =ROUND(D13-C13,2) | F13: =ABS(E13) | G13: =IF(E13=0,"",_xlfn.RANK.AVG(F13,$F$5:$F$34,1)-COUNTIF($E$5:$E$34,0)) | H13: =SIGN(E13) | I13: =IF(E13=0,0,COUNTIF($F$5:$F$34,F13)^2-1) | K13: SE of the mean difference | L13: =L12/SQRT(L10) | M13: =L12/SQRT(L10) | N13: SD of differences / sqrt(n)
A14: V11 | B14: =INDEX(Data!$K$2:$K$1729,MATCH($A14,Data!$B$2:$B$1729,0)) | C14: =SUMIFS(Data!$H$2:$H$1729,Data!$B$2:$B$1729,$A14,Data!$F$2:$F$1729,"Joy",Data!$D$2:$D$1729,"Baseline") | D14: =SUMIFS(Data!$H$2:$H$1729,Data!$B$2:$B$1729,$A14,Data!$F$2:$F$1729,"Joy",Data!$D$2:$D$1729,"Commercial") | E14: =ROUND(D14-C14,2) | F14: =ABS(E14) | G14: =IF(E14=0,"",_xlfn.RANK.AVG(F14,$F$5:$F$34,1)-COUNTIF($E$5:$E$34,0)) | H14: =SIGN(E14) | I14: =IF(E14=0,0,COUNTIF($F$5:$F$34,F14)^2-1) | K14: Paired t | L14: =L11/L13 | M14: =L11/L13 | N14: t = mean difference / SE
A15: V12 | B15: =INDEX(Data!$K$2:$K$1729,MATCH($A15,Data!$B$2:$B$1729,0)) | C15: =SUMIFS(Data!$H$2:$H$1729,Data!$B$2:$B$1729,$A15,Data!$F$2:$F$1729,"Joy",Data!$D$2:$D$1729,"Baseline") | D15: =SUMIFS(Data!$H$2:$H$1729,Data!$B$2:$B$1729,$A15,Data!$F$2:$F$1729,"Joy",Data!$D$2:$D$1729,"Commercial") | E15: =ROUND(D15-C15,2) | F15: =ABS(E15) | G15: =IF(E15=0,"",_xlfn.RANK.AVG(F15,$F$5:$F$34,1)-COUNTIF($E$5:$E$34,0)) | H15: =SIGN(E15) | I15: =IF(E15=0,0,COUNTIF($F$5:$F$34,F15)^2-1) | K15: df | L15: =L10-1 | M15: =L10-1 | N15: n pairs minus 1
A16: V13 | B16: =INDEX(Data!$K$2:$K$1729,MATCH($A16,Data!$B$2:$B$1729,0)) | C16: =SUMIFS(Data!$H$2:$H$1729,Data!$B$2:$B$1729,$A16,Data!$F$2:$F$1729,"Joy",Data!$D$2:$D$1729,"Baseline") | D16: =SUMIFS(Data!$H$2:$H$1729,Data!$B$2:$B$1729,$A16,Data!$F$2:$F$1729,"Joy",Data!$D$2:$D$1729,"Commercial") | E16: =ROUND(D16-C16,2) | F16: =ABS(E16) | G16: =IF(E16=0,"",_xlfn.RANK.AVG(F16,$F$5:$F$34,1)-COUNTIF($E$5:$E$34,0)) | H16: =SIGN(E16) | I16: =IF(E16=0,0,COUNTIF($F$5:$F$34,F16)^2-1) | K16: p, two tailed (T.TEST type 1) | L16: =_xlfn.T.TEST(C5:C34,D5:D34,2,1) | M16: =T.TEST(C5:C34,D5:D34,2,1) | N16: tails = 2, type = 1 means paired
A17: V14 | B17: =INDEX(Data!$K$2:$K$1729,MATCH($A17,Data!$B$2:$B$1729,0)) | C17: =SUMIFS(Data!$H$2:$H$1729,Data!$B$2:$B$1729,$A17,Data!$F$2:$F$1729,"Joy",Data!$D$2:$D$1729,"Baseline") | D17: =SUMIFS(Data!$H$2:$H$1729,Data!$B$2:$B$1729,$A17,Data!$F$2:$F$1729,"Joy",Data!$D$2:$D$1729,"Commercial") | E17: =ROUND(D17-C17,2) | F17: =ABS(E17) | G17: =IF(E17=0,"",_xlfn.RANK.AVG(F17,$F$5:$F$34,1)-COUNTIF($E$5:$E$34,0)) | H17: =SIGN(E17) | I17: =IF(E17=0,0,COUNTIF($F$5:$F$34,F17)^2-1) | K17: p from the hand computed t | L17: =_xlfn.T.DIST.2T(ABS(L14),L15) | M17: =T.DIST.2T(ABS(L14),L15) | N17: should match the T.TEST cell
A18: V15 | B18: =INDEX(Data!$K$2:$K$1729,MATCH($A18,Data!$B$2:$B$1729,0)) | C18: =SUMIFS(Data!$H$2:$H$1729,Data!$B$2:$B$1729,$A18,Data!$F$2:$F$1729,"Joy",Data!$D$2:$D$1729,"Baseline") | D18: =SUMIFS(Data!$H$2:$H$1729,Data!$B$2:$B$1729,$A18,Data!$F$2:$F$1729,"Joy",Data!$D$2:$D$1729,"Commercial") | E18: =ROUND(D18-C18,2) | F18: =ABS(E18) | G18: =IF(E18=0,"",_xlfn.RANK.AVG(F18,$F$5:$F$34,1)-COUNTIF($E$5:$E$34,0)) | H18: =SIGN(E18) | I18: =IF(E18=0,0,COUNTIF($F$5:$F$34,F18)^2-1) | K18: Critical t (95%) | L18: =_xlfn.T.INV.2T(0.05,L15) | M18: =T.INV.2T(0.05,L15) | N18: two tailed, alpha = .05
A19: V16 | B19: =INDEX(Data!$K$2:$K$1729,MATCH($A19,Data!$B$2:$B$1729,0)) | C19: =SUMIFS(Data!$H$2:$H$1729,Data!$B$2:$B$1729,$A19,Data!$F$2:$F$1729,"Joy",Data!$D$2:$D$1729,"Baseline") | D19: =SUMIFS(Data!$H$2:$H$1729,Data!$B$2:$B$1729,$A19,Data!$F$2:$F$1729,"Joy",Data!$D$2:$D$1729,"Commercial") | E19: =ROUND(D19-C19,2) | F19: =ABS(E19) | G19: =IF(E19=0,"",_xlfn.RANK.AVG(F19,$F$5:$F$34,1)-COUNTIF($E$5:$E$34,0)) | H19: =SIGN(E19) | I19: =IF(E19=0,0,COUNTIF($F$5:$F$34,F19)^2-1) | K19: Mean difference 95% CI lower | L19: =L11-L18*L13 | M19: =L11-L18*L13
A20: V17 | B20: =INDEX(Data!$K$2:$K$1729,MATCH($A20,Data!$B$2:$B$1729,0)) | C20: =SUMIFS(Data!$H$2:$H$1729,Data!$B$2:$B$1729,$A20,Data!$F$2:$F$1729,"Joy",Data!$D$2:$D$1729,"Baseline") | D20: =SUMIFS(Data!$H$2:$H$1729,Data!$B$2:$B$1729,$A20,Data!$F$2:$F$1729,"Joy",Data!$D$2:$D$1729,"Commercial") | E20: =ROUND(D20-C20,2) | F20: =ABS(E20) | G20: =IF(E20=0,"",_xlfn.RANK.AVG(F20,$F$5:$F$34,1)-COUNTIF($E$5:$E$34,0)) | H20: =SIGN(E20) | I20: =IF(E20=0,0,COUNTIF($F$5:$F$34,F20)^2-1) | K20: Mean difference 95% CI upper | L20: =L11+L18*L13 | M20: =L11+L18*L13
A21: V18 | B21: =INDEX(Data!$K$2:$K$1729,MATCH($A21,Data!$B$2:$B$1729,0)) | C21: =SUMIFS(Data!$H$2:$H$1729,Data!$B$2:$B$1729,$A21,Data!$F$2:$F$1729,"Joy",Data!$D$2:$D$1729,"Baseline") | D21: =SUMIFS(Data!$H$2:$H$1729,Data!$B$2:$B$1729,$A21,Data!$F$2:$F$1729,"Joy",Data!$D$2:$D$1729,"Commercial") | E21: =ROUND(D21-C21,2) | F21: =ABS(E21) | G21: =IF(E21=0,"",_xlfn.RANK.AVG(F21,$F$5:$F$34,1)-COUNTIF($E$5:$E$34,0)) | H21: =SIGN(E21) | I21: =IF(E21=0,0,COUNTIF($F$5:$F$34,F21)^2-1) | K21: Cohen's d_z | L21: =L11/L12 | M21: =L11/L12 | N21: d_z = mean difference / SD of differences
A22: V20 | B22: =INDEX(Data!$K$2:$K$1729,MATCH($A22,Data!$B$2:$B$1729,0)) | C22: =SUMIFS(Data!$H$2:$H$1729,Data!$B$2:$B$1729,$A22,Data!$F$2:$F$1729,"Joy",Data!$D$2:$D$1729,"Baseline") | D22: =SUMIFS(Data!$H$2:$H$1729,Data!$B$2:$B$1729,$A22,Data!$F$2:$F$1729,"Joy",Data!$D$2:$D$1729,"Commercial") | E22: =ROUND(D22-C22,2) | F22: =ABS(E22) | G22: =IF(E22=0,"",_xlfn.RANK.AVG(F22,$F$5:$F$34,1)-COUNTIF($E$5:$E$34,0)) | H22: =SIGN(E22) | I22: =IF(E22=0,0,COUNTIF($F$5:$F$34,F22)^2-1) | K22: SE of d_z (approximation) | L22: =SQRT(1/L10+L21^2/(2*L10)) | M22: =SQRT(1/L10+L21^2/(2*L10)) | N22: sqrt(1/n + d_z^2 / (2 n))
A23: V21 | B23: =INDEX(Data!$K$2:$K$1729,MATCH($A23,Data!$B$2:$B$1729,0)) | C23: =SUMIFS(Data!$H$2:$H$1729,Data!$B$2:$B$1729,$A23,Data!$F$2:$F$1729,"Joy",Data!$D$2:$D$1729,"Baseline") | D23: =SUMIFS(Data!$H$2:$H$1729,Data!$B$2:$B$1729,$A23,Data!$F$2:$F$1729,"Joy",Data!$D$2:$D$1729,"Commercial") | E23: =ROUND(D23-C23,2) | F23: =ABS(E23) | G23: =IF(E23=0,"",_xlfn.RANK.AVG(F23,$F$5:$F$34,1)-COUNTIF($E$5:$E$34,0)) | H23: =SIGN(E23) | I23: =IF(E23=0,0,COUNTIF($F$5:$F$34,F23)^2-1) | K23: d_z 95% CI lower | L23: =L21-1.96*L22 | M23: =L21-1.96*L22 | N23: large sample approximation; R uses the noncentral t interval
A24: V22 | B24: =INDEX(Data!$K$2:$K$1729,MATCH($A24,Data!$B$2:$B$1729,0)) | C24: =SUMIFS(Data!$H$2:$H$1729,Data!$B$2:$B$1729,$A24,Data!$F$2:$F$1729,"Joy",Data!$D$2:$D$1729,"Baseline") | D24: =SUMIFS(Data!$H$2:$H$1729,Data!$B$2:$B$1729,$A24,Data!$F$2:$F$1729,"Joy",Data!$D$2:$D$1729,"Commercial") | E24: =ROUND(D24-C24,2) | F24: =ABS(E24) | G24: =IF(E24=0,"",_xlfn.RANK.AVG(F24,$F$5:$F$34,1)-COUNTIF($E$5:$E$34,0)) | H24: =SIGN(E24) | I24: =IF(E24=0,0,COUNTIF($F$5:$F$34,F24)^2-1) | K24: d_z 95% CI upper | L24: =L21+1.96*L22 | M24: =L21+1.96*L22
A25: V23 | B25: =INDEX(Data!$K$2:$K$1729,MATCH($A25,Data!$B$2:$B$1729,0)) | C25: =SUMIFS(Data!$H$2:$H$1729,Data!$B$2:$B$1729,$A25,Data!$F$2:$F$1729,"Joy",Data!$D$2:$D$1729,"Baseline") | D25: =SUMIFS(Data!$H$2:$H$1729,Data!$B$2:$B$1729,$A25,Data!$F$2:$F$1729,"Joy",Data!$D$2:$D$1729,"Commercial") | E25: =ROUND(D25-C25,2) | F25: =ABS(E25) | G25: =IF(E25=0,"",_xlfn.RANK.AVG(F25,$F$5:$F$34,1)-COUNTIF($E$5:$E$34,0)) | H25: =SIGN(E25) | I25: =IF(E25=0,0,COUNTIF($F$5:$F$34,F25)^2-1) | K25: Correlation of the two columns | L25: =CORREL(C5:C34,D5:D34) | M25: =CORREL(C5:C34,D5:D34) | N25: within respondent correlation
A26: V24 | B26: =INDEX(Data!$K$2:$K$1729,MATCH($A26,Data!$B$2:$B$1729,0)) | C26: =SUMIFS(Data!$H$2:$H$1729,Data!$B$2:$B$1729,$A26,Data!$F$2:$F$1729,"Joy",Data!$D$2:$D$1729,"Baseline") | D26: =SUMIFS(Data!$H$2:$H$1729,Data!$B$2:$B$1729,$A26,Data!$F$2:$F$1729,"Joy",Data!$D$2:$D$1729,"Commercial") | E26: =ROUND(D26-C26,2) | F26: =ABS(E26) | G26: =IF(E26=0,"",_xlfn.RANK.AVG(F26,$F$5:$F$34,1)-COUNTIF($E$5:$E$34,0)) | H26: =SIGN(E26) | I26: =IF(E26=0,0,COUNTIF($F$5:$F$34,F26)^2-1)
A27: V25 | B27: =INDEX(Data!$K$2:$K$1729,MATCH($A27,Data!$B$2:$B$1729,0)) | C27: =SUMIFS(Data!$H$2:$H$1729,Data!$B$2:$B$1729,$A27,Data!$F$2:$F$1729,"Joy",Data!$D$2:$D$1729,"Baseline") | D27: =SUMIFS(Data!$H$2:$H$1729,Data!$B$2:$B$1729,$A27,Data!$F$2:$F$1729,"Joy",Data!$D$2:$D$1729,"Commercial") | E27: =ROUND(D27-C27,2) | F27: =ABS(E27) | G27: =IF(E27=0,"",_xlfn.RANK.AVG(F27,$F$5:$F$34,1)-COUNTIF($E$5:$E$34,0)) | H27: =SIGN(E27) | I27: =IF(E27=0,0,COUNTIF($F$5:$F$34,F27)^2-1) | K27: Viewers with any Joy present (Percent of time present above 0)
A28: V26 | B28: =INDEX(Data!$K$2:$K$1729,MATCH($A28,Data!$B$2:$B$1729,0)) | C28: =SUMIFS(Data!$H$2:$H$1729,Data!$B$2:$B$1729,$A28,Data!$F$2:$F$1729,"Joy",Data!$D$2:$D$1729,"Baseline") | D28: =SUMIFS(Data!$H$2:$H$1729,Data!$B$2:$B$1729,$A28,Data!$F$2:$F$1729,"Joy",Data!$D$2:$D$1729,"Commercial") | E28: =ROUND(D28-C28,2) | F28: =ABS(E28) | G28: =IF(E28=0,"",_xlfn.RANK.AVG(F28,$F$5:$F$34,1)-COUNTIF($E$5:$E$34,0)) | H28: =SIGN(E28) | I28: =IF(E28=0,0,COUNTIF($F$5:$F$34,F28)^2-1) | K28: Viewers with Joy, Baseline | L28: =COUNTIF(C5:C34,">0") | M28: =COUNTIF(C5:C34,">0") | N28: COUNTIF counts the numbers above 0
A29: V27 | B29: =INDEX(Data!$K$2:$K$1729,MATCH($A29,Data!$B$2:$B$1729,0)) | C29: =SUMIFS(Data!$H$2:$H$1729,Data!$B$2:$B$1729,$A29,Data!$F$2:$F$1729,"Joy",Data!$D$2:$D$1729,"Baseline") | D29: =SUMIFS(Data!$H$2:$H$1729,Data!$B$2:$B$1729,$A29,Data!$F$2:$F$1729,"Joy",Data!$D$2:$D$1729,"Commercial") | E29: =ROUND(D29-C29,2) | F29: =ABS(E29) | G29: =IF(E29=0,"",_xlfn.RANK.AVG(F29,$F$5:$F$34,1)-COUNTIF($E$5:$E$34,0)) | H29: =SIGN(E29) | I29: =IF(E29=0,0,COUNTIF($F$5:$F$34,F29)^2-1) | K29: Viewers with Joy, Commercial | L29: =COUNTIF(D5:D34,">0") | M29: =COUNTIF(D5:D34,">0")
A30: V28 | B30: =INDEX(Data!$K$2:$K$1729,MATCH($A30,Data!$B$2:$B$1729,0)) | C30: =SUMIFS(Data!$H$2:$H$1729,Data!$B$2:$B$1729,$A30,Data!$F$2:$F$1729,"Joy",Data!$D$2:$D$1729,"Baseline") | D30: =SUMIFS(Data!$H$2:$H$1729,Data!$B$2:$B$1729,$A30,Data!$F$2:$F$1729,"Joy",Data!$D$2:$D$1729,"Commercial") | E30: =ROUND(D30-C30,2) | F30: =ABS(E30) | G30: =IF(E30=0,"",_xlfn.RANK.AVG(F30,$F$5:$F$34,1)-COUNTIF($E$5:$E$34,0)) | H30: =SIGN(E30) | I30: =IF(E30=0,0,COUNTIF($F$5:$F$34,F30)^2-1) | K30: Percent of viewers with Joy, Baseline | L30: =100*L28/L10 | M30: =100*L28/L10
A31: V29 | B31: =INDEX(Data!$K$2:$K$1729,MATCH($A31,Data!$B$2:$B$1729,0)) | C31: =SUMIFS(Data!$H$2:$H$1729,Data!$B$2:$B$1729,$A31,Data!$F$2:$F$1729,"Joy",Data!$D$2:$D$1729,"Baseline") | D31: =SUMIFS(Data!$H$2:$H$1729,Data!$B$2:$B$1729,$A31,Data!$F$2:$F$1729,"Joy",Data!$D$2:$D$1729,"Commercial") | E31: =ROUND(D31-C31,2) | F31: =ABS(E31) | G31: =IF(E31=0,"",_xlfn.RANK.AVG(F31,$F$5:$F$34,1)-COUNTIF($E$5:$E$34,0)) | H31: =SIGN(E31) | I31: =IF(E31=0,0,COUNTIF($F$5:$F$34,F31)^2-1) | K31: Percent of viewers with Joy, Commercial | L31: =100*L29/L10 | M31: =100*L29/L10
A32: V30 | B32: =INDEX(Data!$K$2:$K$1729,MATCH($A32,Data!$B$2:$B$1729,0)) | C32: =SUMIFS(Data!$H$2:$H$1729,Data!$B$2:$B$1729,$A32,Data!$F$2:$F$1729,"Joy",Data!$D$2:$D$1729,"Baseline") | D32: =SUMIFS(Data!$H$2:$H$1729,Data!$B$2:$B$1729,$A32,Data!$F$2:$F$1729,"Joy",Data!$D$2:$D$1729,"Commercial") | E32: =ROUND(D32-C32,2) | F32: =ABS(E32) | G32: =IF(E32=0,"",_xlfn.RANK.AVG(F32,$F$5:$F$34,1)-COUNTIF($E$5:$E$34,0)) | H32: =SIGN(E32) | I32: =IF(E32=0,0,COUNTIF($F$5:$F$34,F32)^2-1) | K32: Joy at Baseline only (Joy at Baseline, none in the Commercial) | L32: =SUMPRODUCT((C5:C34>0)*(D5:D34=0)) | M32: =SUMPRODUCT((C5:C34>0)*(D5:D34=0)) | N32: discordant pair type 1
A33: V31 | B33: =INDEX(Data!$K$2:$K$1729,MATCH($A33,Data!$B$2:$B$1729,0)) | C33: =SUMIFS(Data!$H$2:$H$1729,Data!$B$2:$B$1729,$A33,Data!$F$2:$F$1729,"Joy",Data!$D$2:$D$1729,"Baseline") | D33: =SUMIFS(Data!$H$2:$H$1729,Data!$B$2:$B$1729,$A33,Data!$F$2:$F$1729,"Joy",Data!$D$2:$D$1729,"Commercial") | E33: =ROUND(D33-C33,2) | F33: =ABS(E33) | G33: =IF(E33=0,"",_xlfn.RANK.AVG(F33,$F$5:$F$34,1)-COUNTIF($E$5:$E$34,0)) | H33: =SIGN(E33) | I33: =IF(E33=0,0,COUNTIF($F$5:$F$34,F33)^2-1) | K33: Joy in the Commercial only | L33: =SUMPRODUCT((C5:C34=0)*(D5:D34>0)) | M33: =SUMPRODUCT((C5:C34=0)*(D5:D34>0)) | N33: discordant pair type 2
A34: V32 | B34: =INDEX(Data!$K$2:$K$1729,MATCH($A34,Data!$B$2:$B$1729,0)) | C34: =SUMIFS(Data!$H$2:$H$1729,Data!$B$2:$B$1729,$A34,Data!$F$2:$F$1729,"Joy",Data!$D$2:$D$1729,"Baseline") | D34: =SUMIFS(Data!$H$2:$H$1729,Data!$B$2:$B$1729,$A34,Data!$F$2:$F$1729,"Joy",Data!$D$2:$D$1729,"Commercial") | E34: =ROUND(D34-C34,2) | F34: =ABS(E34) | G34: =IF(E34=0,"",_xlfn.RANK.AVG(F34,$F$5:$F$34,1)-COUNTIF($E$5:$E$34,0)) | H34: =SIGN(E34) | I34: =IF(E34=0,0,COUNTIF($F$5:$F$34,F34)^2-1) | K34: Exact McNemar p, two tailed | L34: =MIN(1,2*_xlfn.BINOM.DIST(MIN(L32,L33),L32+L33,0.5,TRUE)) | M34: =MIN(1,2*BINOM.DIST(MIN(L32,L33),L32+L33,0.5,TRUE)) | N34: binomial test of the discordant pairs
K36: Wilcoxon signed rank test by hand (normal approximation with tie and continuity correction, as in R)
K37: Differences above 0 (count) | L37: =COUNTIF(E5:E34,">0") | M37: =COUNTIF(E5:E34,">0")
K38: Differences below 0 (count) | L38: =COUNTIF(E5:E34,"<0") | M38: =COUNTIF(E5:E34,"<0")
K39: Differences equal to 0 (count) | L39: =COUNTIF(E5:E34,0) | M39: =COUNTIF(E5:E34,0) | N39: zero differences are dropped
K40: Nonzero differences | L40: =L37+L38 | M40: =L37+L38
K41: V = sum of ranks of positive differences | L41: =SUMIFS(G5:G34,H5:H34,1) | M41: =SUMIFS(G5:G34,H5:H34,1) | N41: this is the V that R prints
K42: Sum of ranks of negative differences | L42: =SUMIFS(G5:G34,H5:H34,-1) | M42: =SUMIFS(G5:G34,H5:H34,-1)
...

Sheet Bins
A1: H2. Joy Percent of time present across the six 10 s bins, kept respondents. SIMULATED data.
A2: Columns B to G pull each respondent's Joy value for the bin with SUMIFS. The rows under the roster give the proportion of viewers with Joy present (COUNTIFS on Data), the mean, and the Friedman rank sums. The block on the right tests the bin factor.
A4: Respondent Name | B4: Bin_01 | C4: Bin_02 | D4: Bin_03 | E4: Bin_04 | F4: Bin_05 | G4: Bin_06 | H4: Commercial Joy (%) | I4: Respondent mean over the bins | J4: Rank Bin_01 | K4: Rank Bin_02 | L4: Rank Bin_03 | M4: Rank Bin_04 | N4: Rank Bin_05 | O4: Rank Bin_06 | P4: Tie term | R4: Statistic | S4: Value | T4: Formula shown | U4: Note
A5: V01 | B5: =SUMIFS(Data!$H$2:$H$1729,Data!$B$2:$B$1729,$A5,Data!$F$2:$F$1729,"Joy",Data!$D$2:$D$1729,B$4) | C5: =SUMIFS(Data!$H$2:$H$1729,Data!$B$2:$B$1729,$A5,Data!$F$2:$F$1729,"Joy",Data!$D$2:$D$1729,C$4) | D5: =SUMIFS(Data!$H$2:$H$1729,Data!$B$2:$B$1729,$A5,Data!$F$2:$F$1729,"Joy",Data!$D$2:$D$1729,D$4) | E5: =SUMIFS(Data!$H$2:$H$1729,Data!$B$2:$B$1729,$A5,Data!$F$2:$F$1729,"Joy",Data!$D$2:$D$1729,E$4) | F5: =SUMIFS(Data!$H$2:$H$1729,Data!$B$2:$B$1729,$A5,Data!$F$2:$F$1729,"Joy",Data!$D$2:$D$1729,F$4) | G5: =SUMIFS(Data!$H$2:$H$1729,Data!$B$2:$B$1729,$A5,Data!$F$2:$F$1729,"Joy",Data!$D$2:$D$1729,G$4) | H5: =SUMIFS(Data!$H$2:$H$1729,Data!$B$2:$B$1729,$A5,Data!$F$2:$F$1729,"Joy",Data!$D$2:$D$1729,"Commercial") | I5: =AVERAGE(B5:G5) | J5: =_xlfn.RANK.AVG(B5,$B5:$G5,1) | K5: =_xlfn.RANK.AVG(C5,$B5:$G5,1) | L5: =_xlfn.RANK.AVG(D5,$B5:$G5,1) | M5: =_xlfn.RANK.AVG(E5,$B5:$G5,1) | N5: =_xlfn.RANK.AVG(F5,$B5:$G5,1) | O5: =_xlfn.RANK.AVG(G5,$B5:$G5,1) | P5: =SUMPRODUCT(COUNTIF($B5:$G5,$B5:$G5)^2-1) | R5: Repeated measures ANOVA by hand (its F equals the mixed model F test for this balanced design)
A6: V02 | B6: =SUMIFS(Data!$H$2:$H$1729,Data!$B$2:$B$1729,$A6,Data!$F$2:$F$1729,"Joy",Data!$D$2:$D$1729,B$4) | C6: =SUMIFS(Data!$H$2:$H$1729,Data!$B$2:$B$1729,$A6,Data!$F$2:$F$1729,"Joy",Data!$D$2:$D$1729,C$4) | D6: =SUMIFS(Data!$H$2:$H$1729,Data!$B$2:$B$1729,$A6,Data!$F$2:$F$1729,"Joy",Data!$D$2:$D$1729,D$4) | E6: =SUMIFS(Data!$H$2:$H$1729,Data!$B$2:$B$1729,$A6,Data!$F$2:$F$1729,"Joy",Data!$D$2:$D$1729,E$4) | F6: =SUMIFS(Data!$H$2:$H$1729,Data!$B$2:$B$1729,$A6,Data!$F$2:$F$1729,"Joy",Data!$D$2:$D$1729,F$4) | G6: =SUMIFS(Data!$H$2:$H$1729,Data!$B$2:$B$1729,$A6,Data!$F$2:$F$1729,"Joy",Data!$D$2:$D$1729,G$4) | H6: =SUMIFS(Data!$H$2:$H$1729,Data!$B$2:$B$1729,$A6,Data!$F$2:$F$1729,"Joy",Data!$D$2:$D$1729,"Commercial") | I6: =AVERAGE(B6:G6) | J6: =_xlfn.RANK.AVG(B6,$B6:$G6,1) | K6: =_xlfn.RANK.AVG(C6,$B6:$G6,1) | L6: =_xlfn.RANK.AVG(D6,$B6:$G6,1) | M6: =_xlfn.RANK.AVG(E6,$B6:$G6,1) | N6: =_xlfn.RANK.AVG(F6,$B6:$G6,1) | O6: =_xlfn.RANK.AVG(G6,$B6:$G6,1) | P6: =SUMPRODUCT(COUNTIF($B6:$G6,$B6:$G6)^2-1) | R6: Respondents (n) | S6: =COUNT(I5:I34) | T6: =COUNT(I5:I34)
A7: V03 | B7: =SUMIFS(Data!$H$2:$H$1729,Data!$B$2:$B$1729,$A7,Data!$F$2:$F$1729,"Joy",Data!$D$2:$D$1729,B$4) | C7: =SUMIFS(Data!$H$2:$H$1729,Data!$B$2:$B$1729,$A7,Data!$F$2:$F$1729,"Joy",Data!$D$2:$D$1729,C$4) | D7: =SUMIFS(Data!$H$2:$H$1729,Data!$B$2:$B$1729,$A7,Data!$F$2:$F$1729,"Joy",Data!$D$2:$D$1729,D$4) | E7: =SUMIFS(Data!$H$2:$H$1729,Data!$B$2:$B$1729,$A7,Data!$F$2:$F$1729,"Joy",Data!$D$2:$D$1729,E$4) | F7: =SUMIFS(Data!$H$2:$H$1729,Data!$B$2:$B$1729,$A7,Data!$F$2:$F$1729,"Joy",Data!$D$2:$D$1729,F$4) | G7: =SUMIFS(Data!$H$2:$H$1729,Data!$B$2:$B$1729,$A7,Data!$F$2:$F$1729,"Joy",Data!$D$2:$D$1729,G$4) | H7: =SUMIFS(Data!$H$2:$H$1729,Data!$B$2:$B$1729,$A7,Data!$F$2:$F$1729,"Joy",Data!$D$2:$D$1729,"Commercial") | I7: =AVERAGE(B7:G7) | J7: =_xlfn.RANK.AVG(B7,$B7:$G7,1) | K7: =_xlfn.RANK.AVG(C7,$B7:$G7,1) | L7: =_xlfn.RANK.AVG(D7,$B7:$G7,1) | M7: =_xlfn.RANK.AVG(E7,$B7:$G7,1) | N7: =_xlfn.RANK.AVG(F7,$B7:$G7,1) | O7: =_xlfn.RANK.AVG(G7,$B7:$G7,1) | P7: =SUMPRODUCT(COUNTIF($B7:$G7,$B7:$G7)^2-1) | R7: Bins (k) | S7: =COUNTA(B4:G4) | T7: =COUNTA(B4:G4)
A8: V04 | B8: =SUMIFS(Data!$H$2:$H$1729,Data!$B$2:$B$1729,$A8,Data!$F$2:$F$1729,"Joy",Data!$D$2:$D$1729,B$4) | C8: =SUMIFS(Data!$H$2:$H$1729,Data!$B$2:$B$1729,$A8,Data!$F$2:$F$1729,"Joy",Data!$D$2:$D$1729,C$4) | D8: =SUMIFS(Data!$H$2:$H$1729,Data!$B$2:$B$1729,$A8,Data!$F$2:$F$1729,"Joy",Data!$D$2:$D$1729,D$4) | E8: =SUMIFS(Data!$H$2:$H$1729,Data!$B$2:$B$1729,$A8,Data!$F$2:$F$1729,"Joy",Data!$D$2:$D$1729,E$4) | F8: =SUMIFS(Data!$H$2:$H$1729,Data!$B$2:$B$1729,$A8,Data!$F$2:$F$1729,"Joy",Data!$D$2:$D$1729,F$4) | G8: =SUMIFS(Data!$H$2:$H$1729,Data!$B$2:$B$1729,$A8,Data!$F$2:$F$1729,"Joy",Data!$D$2:$D$1729,G$4) | H8: =SUMIFS(Data!$H$2:$H$1729,Data!$B$2:$B$1729,$A8,Data!$F$2:$F$1729,"Joy",Data!$D$2:$D$1729,"Commercial") | I8: =AVERAGE(B8:G8) | J8: =_xlfn.RANK.AVG(B8,$B8:$G8,1) | K8: =_xlfn.RANK.AVG(C8,$B8:$G8,1) | L8: =_xlfn.RANK.AVG(D8,$B8:$G8,1) | M8: =_xlfn.RANK.AVG(E8,$B8:$G8,1) | N8: =_xlfn.RANK.AVG(F8,$B8:$G8,1) | O8: =_xlfn.RANK.AVG(G8,$B8:$G8,1) | P8: =SUMPRODUCT(COUNTIF($B8:$G8,$B8:$G8)^2-1) | R8: Grand mean Joy (%) | S8: =AVERAGE(B5:G34) | T8: =AVERAGE(B5:G34)
A9: V05 | B9: =SUMIFS(Data!$H$2:$H$1729,Data!$B$2:$B$1729,$A9,Data!$F$2:$F$1729,"Joy",Data!$D$2:$D$1729,B$4) | C9: =SUMIFS(Data!$H$2:$H$1729,Data!$B$2:$B$1729,$A9,Data!$F$2:$F$1729,"Joy",Data!$D$2:$D$1729,C$4) | D9: =SUMIFS(Data!$H$2:$H$1729,Data!$B$2:$B$1729,$A9,Data!$F$2:$F$1729,"Joy",Data!$D$2:$D$1729,D$4) | E9: =SUMIFS(Data!$H$2:$H$1729,Data!$B$2:$B$1729,$A9,Data!$F$2:$F$1729,"Joy",Data!$D$2:$D$1729,E$4) | F9: =SUMIFS(Data!$H$2:$H$1729,Data!$B$2:$B$1729,$A9,Data!$F$2:$F$1729,"Joy",Data!$D$2:$D$1729,F$4) | G9: =SUMIFS(Data!$H$2:$H$1729,Data!$B$2:$B$1729,$A9,Data!$F$2:$F$1729,"Joy",Data!$D$2:$D$1729,G$4) | H9: =SUMIFS(Data!$H$2:$H$1729,Data!$B$2:$B$1729,$A9,Data!$F$2:$F$1729,"Joy",Data!$D$2:$D$1729,"Commercial") | I9: =AVERAGE(B9:G9) | J9: =_xlfn.RANK.AVG(B9,$B9:$G9,1) | K9: =_xlfn.RANK.AVG(C9,$B9:$G9,1) | L9: =_xlfn.RANK.AVG(D9,$B9:$G9,1) | M9: =_xlfn.RANK.AVG(E9,$B9:$G9,1) | N9: =_xlfn.RANK.AVG(F9,$B9:$G9,1) | O9: =_xlfn.RANK.AVG(G9,$B9:$G9,1) | P9: =SUMPRODUCT(COUNTIF($B9:$G9,$B9:$G9)^2-1) | R9: SS total | S9: =DEVSQ(B5:G34) | T9: =DEVSQ(B5:G34) | U9: sum of squared deviations from the grand mean
A10: V06 | B10: =SUMIFS(Data!$H$2:$H$1729,Data!$B$2:$B$1729,$A10,Data!$F$2:$F$1729,"Joy",Data!$D$2:$D$1729,B$4) | C10: =SUMIFS(Data!$H$2:$H$1729,Data!$B$2:$B$1729,$A10,Data!$F$2:$F$1729,"Joy",Data!$D$2:$D$1729,C$4) | D10: =SUMIFS(Data!$H$2:$H$1729,Data!$B$2:$B$1729,$A10,Data!$F$2:$F$1729,"Joy",Data!$D$2:$D$1729,D$4) | E10: =SUMIFS(Data!$H$2:$H$1729,Data!$B$2:$B$1729,$A10,Data!$F$2:$F$1729,"Joy",Data!$D$2:$D$1729,E$4) | F10: =SUMIFS(Data!$H$2:$H$1729,Data!$B$2:$B$1729,$A10,Data!$F$2:$F$1729,"Joy",Data!$D$2:$D$1729,F$4) | G10: =SUMIFS(Data!$H$2:$H$1729,Data!$B$2:$B$1729,$A10,Data!$F$2:$F$1729,"Joy",Data!$D$2:$D$1729,G$4) | H10: =SUMIFS(Data!$H$2:$H$1729,Data!$B$2:$B$1729,$A10,Data!$F$2:$F$1729,"Joy",Data!$D$2:$D$1729,"Commercial") | I10: =AVERAGE(B10:G10) | J10: =_xlfn.RANK.AVG(B10,$B10:$G10,1) | K10: =_xlfn.RANK.AVG(C10,$B10:$G10,1) | L10: =_xlfn.RANK.AVG(D10,$B10:$G10,1) | M10: =_xlfn.RANK.AVG(E10,$B10:$G10,1) | N10: =_xlfn.RANK.AVG(F10,$B10:$G10,1) | O10: =_xlfn.RANK.AVG(G10,$B10:$G10,1) | P10: =SUMPRODUCT(COUNTIF($B10:$G10,$B10:$G10)^2-1) | R10: SS bins | S10: =S6*DEVSQ(B41:G41) | T10: =S6*DEVSQ(B41:G41) | U10: n x squared deviations of the six bin means
A11: V08 | B11: =SUMIFS(Data!$H$2:$H$1729,Data!$B$2:$B$1729,$A11,Data!$F$2:$F$1729,"Joy",Data!$D$2:$D$1729,B$4) | C11: =SUMIFS(Data!$H$2:$H$1729,Data!$B$2:$B$1729,$A11,Data!$F$2:$F$1729,"Joy",Data!$D$2:$D$1729,C$4) | D11: =SUMIFS(Data!$H$2:$H$1729,Data!$B$2:$B$1729,$A11,Data!$F$2:$F$1729,"Joy",Data!$D$2:$D$1729,D$4) | E11: =SUMIFS(Data!$H$2:$H$1729,Data!$B$2:$B$1729,$A11,Data!$F$2:$F$1729,"Joy",Data!$D$2:$D$1729,E$4) | F11: =SUMIFS(Data!$H$2:$H$1729,Data!$B$2:$B$1729,$A11,Data!$F$2:$F$1729,"Joy",Data!$D$2:$D$1729,F$4) | G11: =SUMIFS(Data!$H$2:$H$1729,Data!$B$2:$B$1729,$A11,Data!$F$2:$F$1729,"Joy",Data!$D$2:$D$1729,G$4) | H11: =SUMIFS(Data!$H$2:$H$1729,Data!$B$2:$B$1729,$A11,Data!$F$2:$F$1729,"Joy",Data!$D$2:$D$1729,"Commercial") | I11: =AVERAGE(B11:G11) | J11: =_xlfn.RANK.AVG(B11,$B11:$G11,1) | K11: =_xlfn.RANK.AVG(C11,$B11:$G11,1) | L11: =_xlfn.RANK.AVG(D11,$B11:$G11,1) | M11: =_xlfn.RANK.AVG(E11,$B11:$G11,1) | N11: =_xlfn.RANK.AVG(F11,$B11:$G11,1) | O11: =_xlfn.RANK.AVG(G11,$B11:$G11,1) | P11: =SUMPRODUCT(COUNTIF($B11:$G11,$B11:$G11)^2-1) | R11: SS respondents | S11: =S7*DEVSQ(I5:I34) | T11: =S7*DEVSQ(I5:I34) | U11: k x squared deviations of the respondent means
A12: V09 | B12: =SUMIFS(Data!$H$2:$H$1729,Data!$B$2:$B$1729,$A12,Data!$F$2:$F$1729,"Joy",Data!$D$2:$D$1729,B$4) | C12: =SUMIFS(Data!$H$2:$H$1729,Data!$B$2:$B$1729,$A12,Data!$F$2:$F$1729,"Joy",Data!$D$2:$D$1729,C$4) | D12: =SUMIFS(Data!$H$2:$H$1729,Data!$B$2:$B$1729,$A12,Data!$F$2:$F$1729,"Joy",Data!$D$2:$D$1729,D$4) | E12: =SUMIFS(Data!$H$2:$H$1729,Data!$B$2:$B$1729,$A12,Data!$F$2:$F$1729,"Joy",Data!$D$2:$D$1729,E$4) | F12: =SUMIFS(Data!$H$2:$H$1729,Data!$B$2:$B$1729,$A12,Data!$F$2:$F$1729,"Joy",Data!$D$2:$D$1729,F$4) | G12: =SUMIFS(Data!$H$2:$H$1729,Data!$B$2:$B$1729,$A12,Data!$F$2:$F$1729,"Joy",Data!$D$2:$D$1729,G$4) | H12: =SUMIFS(Data!$H$2:$H$1729,Data!$B$2:$B$1729,$A12,Data!$F$2:$F$1729,"Joy",Data!$D$2:$D$1729,"Commercial") | I12: =AVERAGE(B12:G12) | J12: =_xlfn.RANK.AVG(B12,$B12:$G12,1) | K12: =_xlfn.RANK.AVG(C12,$B12:$G12,1) | L12: =_xlfn.RANK.AVG(D12,$B12:$G12,1) | M12: =_xlfn.RANK.AVG(E12,$B12:$G12,1) | N12: =_xlfn.RANK.AVG(F12,$B12:$G12,1) | O12: =_xlfn.RANK.AVG(G12,$B12:$G12,1) | P12: =SUMPRODUCT(COUNTIF($B12:$G12,$B12:$G12)^2-1) | R12: SS error | S12: =S9-S10-S11 | T12: =S9-S10-S11
A13: V10 | B13: =SUMIFS(Data!$H$2:$H$1729,Data!$B$2:$B$1729,$A13,Data!$F$2:$F$1729,"Joy",Data!$D$2:$D$1729,B$4) | C13: =SUMIFS(Data!$H$2:$H$1729,Data!$B$2:$B$1729,$A13,Data!$F$2:$F$1729,"Joy",Data!$D$2:$D$1729,C$4) | D13: =SUMIFS(Data!$H$2:$H$1729,Data!$B$2:$B$1729,$A13,Data!$F$2:$F$1729,"Joy",Data!$D$2:$D$1729,D$4) | E13: =SUMIFS(Data!$H$2:$H$1729,Data!$B$2:$B$1729,$A13,Data!$F$2:$F$1729,"Joy",Data!$D$2:$D$1729,E$4) | F13: =SUMIFS(Data!$H$2:$H$1729,Data!$B$2:$B$1729,$A13,Data!$F$2:$F$1729,"Joy",Data!$D$2:$D$1729,F$4) | G13: =SUMIFS(Data!$H$2:$H$1729,Data!$B$2:$B$1729,$A13,Data!$F$2:$F$1729,"Joy",Data!$D$2:$D$1729,G$4) | H13: =SUMIFS(Data!$H$2:$H$1729,Data!$B$2:$B$1729,$A13,Data!$F$2:$F$1729,"Joy",Data!$D$2:$D$1729,"Commercial") | I13: =AVERAGE(B13:G13) | J13: =_xlfn.RANK.AVG(B13,$B13:$G13,1) | K13: =_xlfn.RANK.AVG(C13,$B13:$G13,1) | L13: =_xlfn.RANK.AVG(D13,$B13:$G13,1) | M13: =_xlfn.RANK.AVG(E13,$B13:$G13,1) | N13: =_xlfn.RANK.AVG(F13,$B13:$G13,1) | O13: =_xlfn.RANK.AVG(G13,$B13:$G13,1) | P13: =SUMPRODUCT(COUNTIF($B13:$G13,$B13:$G13)^2-1) | R13: df bins | S13: =S7-1 | T13: =S7-1
A14: V11 | B14: =SUMIFS(Data!$H$2:$H$1729,Data!$B$2:$B$1729,$A14,Data!$F$2:$F$1729,"Joy",Data!$D$2:$D$1729,B$4) | C14: =SUMIFS(Data!$H$2:$H$1729,Data!$B$2:$B$1729,$A14,Data!$F$2:$F$1729,"Joy",Data!$D$2:$D$1729,C$4) | D14: =SUMIFS(Data!$H$2:$H$1729,Data!$B$2:$B$1729,$A14,Data!$F$2:$F$1729,"Joy",Data!$D$2:$D$1729,D$4) | E14: =SUMIFS(Data!$H$2:$H$1729,Data!$B$2:$B$1729,$A14,Data!$F$2:$F$1729,"Joy",Data!$D$2:$D$1729,E$4) | F14: =SUMIFS(Data!$H$2:$H$1729,Data!$B$2:$B$1729,$A14,Data!$F$2:$F$1729,"Joy",Data!$D$2:$D$1729,F$4) | G14: =SUMIFS(Data!$H$2:$H$1729,Data!$B$2:$B$1729,$A14,Data!$F$2:$F$1729,"Joy",Data!$D$2:$D$1729,G$4) | H14: =SUMIFS(Data!$H$2:$H$1729,Data!$B$2:$B$1729,$A14,Data!$F$2:$F$1729,"Joy",Data!$D$2:$D$1729,"Commercial") | I14: =AVERAGE(B14:G14) | J14: =_xlfn.RANK.AVG(B14,$B14:$G14,1) | K14: =_xlfn.RANK.AVG(C14,$B14:$G14,1) | L14: =_xlfn.RANK.AVG(D14,$B14:$G14,1) | M14: =_xlfn.RANK.AVG(E14,$B14:$G14,1) | N14: =_xlfn.RANK.AVG(F14,$B14:$G14,1) | O14: =_xlfn.RANK.AVG(G14,$B14:$G14,1) | P14: =SUMPRODUCT(COUNTIF($B14:$G14,$B14:$G14)^2-1) | R14: df error | S14: =(S6-1)*(S7-1) | T14: =(S6-1)*(S7-1) | U14: equals the Satterthwaite df of the mixed model here
A15: V12 | B15: =SUMIFS(Data!$H$2:$H$1729,Data!$B$2:$B$1729,$A15,Data!$F$2:$F$1729,"Joy",Data!$D$2:$D$1729,B$4) | C15: =SUMIFS(Data!$H$2:$H$1729,Data!$B$2:$B$1729,$A15,Data!$F$2:$F$1729,"Joy",Data!$D$2:$D$1729,C$4) | D15: =SUMIFS(Data!$H$2:$H$1729,Data!$B$2:$B$1729,$A15,Data!$F$2:$F$1729,"Joy",Data!$D$2:$D$1729,D$4) | E15: =SUMIFS(Data!$H$2:$H$1729,Data!$B$2:$B$1729,$A15,Data!$F$2:$F$1729,"Joy",Data!$D$2:$D$1729,E$4) | F15: =SUMIFS(Data!$H$2:$H$1729,Data!$B$2:$B$1729,$A15,Data!$F$2:$F$1729,"Joy",Data!$D$2:$D$1729,F$4) | G15: =SUMIFS(Data!$H$2:$H$1729,Data!$B$2:$B$1729,$A15,Data!$F$2:$F$1729,"Joy",Data!$D$2:$D$1729,G$4) | H15: =SUMIFS(Data!$H$2:$H$1729,Data!$B$2:$B$1729,$A15,Data!$F$2:$F$1729,"Joy",Data!$D$2:$D$1729,"Commercial") | I15: =AVERAGE(B15:G15) | J15: =_xlfn.RANK.AVG(B15,$B15:$G15,1) | K15: =_xlfn.RANK.AVG(C15,$B15:$G15,1) | L15: =_xlfn.RANK.AVG(D15,$B15:$G15,1) | M15: =_xlfn.RANK.AVG(E15,$B15:$G15,1) | N15: =_xlfn.RANK.AVG(F15,$B15:$G15,1) | O15: =_xlfn.RANK.AVG(G15,$B15:$G15,1) | P15: =SUMPRODUCT(COUNTIF($B15:$G15,$B15:$G15)^2-1) | R15: MS bins | S15: =S10/S13 | T15: =S10/S13
A16: V13 | B16: =SUMIFS(Data!$H$2:$H$1729,Data!$B$2:$B$1729,$A16,Data!$F$2:$F$1729,"Joy",Data!$D$2:$D$1729,B$4) | C16: =SUMIFS(Data!$H$2:$H$1729,Data!$B$2:$B$1729,$A16,Data!$F$2:$F$1729,"Joy",Data!$D$2:$D$1729,C$4) | D16: =SUMIFS(Data!$H$2:$H$1729,Data!$B$2:$B$1729,$A16,Data!$F$2:$F$1729,"Joy",Data!$D$2:$D$1729,D$4) | E16: =SUMIFS(Data!$H$2:$H$1729,Data!$B$2:$B$1729,$A16,Data!$F$2:$F$1729,"Joy",Data!$D$2:$D$1729,E$4) | F16: =SUMIFS(Data!$H$2:$H$1729,Data!$B$2:$B$1729,$A16,Data!$F$2:$F$1729,"Joy",Data!$D$2:$D$1729,F$4) | G16: =SUMIFS(Data!$H$2:$H$1729,Data!$B$2:$B$1729,$A16,Data!$F$2:$F$1729,"Joy",Data!$D$2:$D$1729,G$4) | H16: =SUMIFS(Data!$H$2:$H$1729,Data!$B$2:$B$1729,$A16,Data!$F$2:$F$1729,"Joy",Data!$D$2:$D$1729,"Commercial") | I16: =AVERAGE(B16:G16) | J16: =_xlfn.RANK.AVG(B16,$B16:$G16,1) | K16: =_xlfn.RANK.AVG(C16,$B16:$G16,1) | L16: =_xlfn.RANK.AVG(D16,$B16:$G16,1) | M16: =_xlfn.RANK.AVG(E16,$B16:$G16,1) | N16: =_xlfn.RANK.AVG(F16,$B16:$G16,1) | O16: =_xlfn.RANK.AVG(G16,$B16:$G16,1) | P16: =SUMPRODUCT(COUNTIF($B16:$G16,$B16:$G16)^2-1) | R16: MS error | S16: =S12/S14 | T16: =S12/S14 | U16: equals the residual variance of the mixed model
A17: V14 | B17: =SUMIFS(Data!$H$2:$H$1729,Data!$B$2:$B$1729,$A17,Data!$F$2:$F$1729,"Joy",Data!$D$2:$D$1729,B$4) | C17: =SUMIFS(Data!$H$2:$H$1729,Data!$B$2:$B$1729,$A17,Data!$F$2:$F$1729,"Joy",Data!$D$2:$D$1729,C$4) | D17: =SUMIFS(Data!$H$2:$H$1729,Data!$B$2:$B$1729,$A17,Data!$F$2:$F$1729,"Joy",Data!$D$2:$D$1729,D$4) | E17: =SUMIFS(Data!$H$2:$H$1729,Data!$B$2:$B$1729,$A17,Data!$F$2:$F$1729,"Joy",Data!$D$2:$D$1729,E$4) | F17: =SUMIFS(Data!$H$2:$H$1729,Data!$B$2:$B$1729,$A17,Data!$F$2:$F$1729,"Joy",Data!$D$2:$D$1729,F$4) | G17: =SUMIFS(Data!$H$2:$H$1729,Data!$B$2:$B$1729,$A17,Data!$F$2:$F$1729,"Joy",Data!$D$2:$D$1729,G$4) | H17: =SUMIFS(Data!$H$2:$H$1729,Data!$B$2:$B$1729,$A17,Data!$F$2:$F$1729,"Joy",Data!$D$2:$D$1729,"Commercial") | I17: =AVERAGE(B17:G17) | J17: =_xlfn.RANK.AVG(B17,$B17:$G17,1) | K17: =_xlfn.RANK.AVG(C17,$B17:$G17,1) | L17: =_xlfn.RANK.AVG(D17,$B17:$G17,1) | M17: =_xlfn.RANK.AVG(E17,$B17:$G17,1) | N17: =_xlfn.RANK.AVG(F17,$B17:$G17,1) | O17: =_xlfn.RANK.AVG(G17,$B17:$G17,1) | P17: =SUMPRODUCT(COUNTIF($B17:$G17,$B17:$G17)^2-1) | R17: F | S17: =S15/S16 | T17: =S15/S16
