Workbook

Sheet README
A1: SIMULATED ad test workbook (teaching material)
A3: Every number in this workbook is SIMULATED. It was generated by make_simulated_data.py (seed 20268242) to
A4: resemble a two commercial test in the style of the iMotions demonstration study DEMO - SonyBravia:
A5: each respondent watched BOTH commercials (Commercial_1_Balls, Commercial_2_Paint, 60 s each) on a
A6: monitor with the Smart Eye Aurora tracker. No real viewer was recorded.
A8: Sheets:
A9: Data Individual AOI metrics export as imported (rows 2 to 241). NA is kept as text, as iMotions writes it.
A10: Helper columns Z to AD: Keep (Valid data >= 70), Position (first or second viewing),
A11: Dwell_pct_clean (NA counts as 0), Fixated (1 or 0), Fix_count_clean (NA counts as 0).
A12: Summary Mean, SD, n by AOI and commercial, built with COUNTIFS, AVERAGEIFS, STDEV.S(IF(...)).
A13: ProductTV H1. One row per kept respondent; paired t test (T.TEST type 1), hand computed t, d_z, CI;
A14: simple order effect estimate.
... A27: analysis_output.txt (its console output), results_text.md (model paragraphs).

Sheet Data
A1: Study Name | B1: Respondent Name | C1: Gender | D1: Age | E1: Group | F1: Session Date | G1: Stimulus | H1: AOI Name | I1: Stimulus duration | J1: AOI duration (ms) | K1: AOI duration (%) | L1: Valid data | M1: Gaze Hit time AOI (ms) | N1: Gaze Dwell count | O1: Gaze Dwell time (ms) | P1: Dwells with fixations | Q1: Revisit count | R1: Fixation count | S1: TTFF AOI (ms) | T1: TTFF parent (ms) | U1: TTFF max. (ms) | V1: Dwell time (ms) | W1: Dwell time (%) | X1: Fixation duration (ms) | Y1: First fixation duration (ms) | Z1: Keep | AA1: Position | AB1: Dwell_pct_clean | AC1: Fixated | AD1: Fix_count_clean
A2: SIMULATED_AdTest_Balls_vs_Paint | B2: R01 | C2: F | D2: 45 | E2: A | F2: 2026-10-19 | G2: Commercial_1_Balls | H2: Product_TV | I2: 60000 | J2: 14000 | K2: 23.33 | L2: 92.6 | M2: 932 | N2: 2 | O2: 3122 | P2: 1 | Q2: 0 | R2: 9 | S2: 1068 | T2: 13068 | U2: 13068 | V2: 2730 | W2: 19.5 | X2: 303 | Y2: 282 | Z2: =IF(L2>=70,"Yes","No") | AA2: =IF(OR(AND(E2="A",G2="Commercial_1_Balls"),AND(E2="B",G2="Commercial_2_Paint")),"first","second") | AB2: =IF(ISNUMBER(W2),W2,0) | AC2: =IF(ISNUMBER(S2),1,0) | AD2: =IF(ISNUMBER(R2),R2,0)
A3: SIMULATED_AdTest_Balls_vs_Paint | B3: R01 | C3: F | D3: 45 | E3: A | F3: 2026-10-19 | G3: Commercial_1_Balls | H3: Brand_Logo | I3: 60000 | J3: 5000 | K3: 8.33 | L3: 92.6 | M3: 530 | N3: 1 | O3: 2164 | P3: 1 | Q3: 0 | R3: 4 | S3: 766 | T3: 55766 | U3: 55766 | V3: 1903 | W3: 38.06 | X3: 476 | Y3: 228 | Z3: =IF(L3>=70,"Yes","No") | AA3: =IF(OR(AND(E3="A",G3="Commercial_1_Balls"),AND(E3="B",G3="Commercial_2_Paint")),"first","second") | AB3: =IF(ISNUMBER(W3),W3,0) | AC3: =IF(ISNUMBER(S3),1,0) | AD3: =IF(ISNUMBER(R3),R3,0)
A4: SIMULATED_AdTest_Balls_vs_Paint | B4: R01 | C4: F | D4: 45 | E4: A | F4: 2026-10-19 | G4: Commercial_1_Balls | H4: Tagline_Text | I4: 60000 | J4: 4000 | K4: 6.67 | L4: 92.6 | M4: 783 | N4: 2 | O4: 861 | P4: 1 | Q4: 0 | R4: 2 | S4: 1081 | T4: 57081 | U4: 57081 | V4: 784 | W4: 19.6 | X4: 392 | Y4: 266 | Z4: =IF(L4>=70,"Yes","No") | AA4: =IF(OR(AND(E4="A",G4="Commercial_1_Balls"),AND(E4="B",G4="Commercial_2_Paint")),"first","second") | AB4: =IF(ISNUMBER(W4),W4,0) | AC4: =IF(ISNUMBER(S4),1,0) | AD4: =IF(ISNUMBER(R4),R4,0)
A5: SIMULATED_AdTest_Balls_vs_Paint | B5: R01 | C5: F | D5: 45 | E5: A | F5: 2026-10-19 | G5: Commercial_1_Balls | H5: Hero_Element | I5: 60000 | J5: 40000 | K5: 66.67 | L5: 92.6 | M5: 347 | N5: 2 | O5: 20787 | P5: 2 | Q5: 1 | R5: 83 | S5: 589 | T5: 2589 | U5: 2589 | V5: 19068 | W5: 47.67 | X5: 230 | Y5: 273 | Z5: =IF(L5>=70,"Yes","No") | AA5: =IF(OR(AND(E5="A",G5="Commercial_1_Balls"),AND(E5="B",G5="Commercial_2_Paint")),"first","second") | AB5: =IF(ISNUMBER(W5),W5,0) | AC5: =IF(ISNUMBER(S5),1,0) | AD5: =IF(ISNUMBER(R5),R5,0)
A6: SIMULATED_AdTest_Balls_vs_Paint | B6: R01 | C6: F | D6: 45 | E6: A | F6: 2026-10-19 | G6: Commercial_2_Paint | H6: Product_TV | I6: 60000 | J6: 20000 | K6: 33.33 | L6: 92.6 | M6: 2119 | N6: 3 | O6: 5534 | P6: 2 | Q6: 1 | R6: 15 | S6: 2319 | T6: 11319 | U6: 11319 | V6: 4971 | W6: 24.86 | X6: 331 | Y6: 331 | Z6: =IF(L6>=70,"Yes","No") | AA6: =IF(OR(AND(E6="A",G6="Commercial_1_Balls"),AND(E6="B",G6="Commercial_2_Paint")),"first","second") | AB6: =IF(ISNUMBER(W6),W6,0) | AC6: =IF(ISNUMBER(S6),1,0) | AD6: =IF(ISNUMBER(R6),R6,0)
A7: SIMULATED_AdTest_Balls_vs_Paint | B7: R01 | C7: F | D7: 45 | E7: A | F7: 2026-10-19 | G7: Commercial_2_Paint | H7: Brand_Logo | I7: 60000 | J7: 5000 | K7: 8.33 | L7: 92.6 | M7: 646 | N7: 1 | O7: 2990 | P7: 1 | Q7: 0 | R7: 7 | S7: 920 | T7: 55920 | U7: 55920 | V7: 2690 | W7: 53.8 | X7: 384 | Y7: 210 | Z7: =IF(L7>=70,"Yes","No") | AA7: =IF(OR(AND(E7="A",G7="Commercial_1_Balls"),AND(E7="B",G7="Commercial_2_Paint")),"first","second") | AB7: =IF(ISNUMBER(W7),W7,0) | AC7: =IF(ISNUMBER(S7),1,0) | AD7: =IF(ISNUMBER(R7),R7,0)
A8: SIMULATED_AdTest_Balls_vs_Paint | B8: R01 | C8: F | D8: 45 | E8: A | F8: 2026-10-19 | G8: Commercial_2_Paint | H8: Tagline_Text | I8: 60000 | J8: 4000 | K8: 6.67 | L8: 92.6 | M8: 680 | N8: 1 | O8: 957 | P8: 1 | Q8: 0 | R8: 4 | S8: 821 | T8: 56821 | U8: 56821 | V8: 928 | W8: 23.2 | X8: 232 | Y8: 201 | Z8: =IF(L8>=70,"Yes","No") | AA8: =IF(OR(AND(E8="A",G8="Commercial_1_Balls"),AND(E8="B",G8="Commercial_2_Paint")),"first","second") | AB8: =IF(ISNUMBER(W8),W8,0) | AC8: =IF(ISNUMBER(S8),1,0) | AD8: =IF(ISNUMBER(R8),R8,0)
A9: SIMULATED_AdTest_Balls_vs_Paint | B9: R01 | C9: F | D9: 45 | E9: A | F9: 2026-10-19 | G9: Commercial_2_Paint | H9: Hero_Element | I9: 60000 | J9: 32000 | K9: 53.33 | L9: 92.6 | M9: 386 | N9: 3 | O9: 19378 | P9: 3 | Q9: 2 | R9: 55 | S9: 591 | T9: 3591 | U9: 3591 | V9: 17821 | W9: 55.69 | X9: 324 | Y9: 192 | Z9: =IF(L9>=70,"Yes","No") | AA9: =IF(OR(AND(E9="A",G9="Commercial_1_Balls"),AND(E9="B",G9="Commercial_2_Paint")),"first","second") | AB9: =IF(ISNUMBER(W9),W9,0) | AC9: =IF(ISNUMBER(S9),1,0) | AD9: =IF(ISNUMBER(R9),R9,0)
A10: SIMULATED_AdTest_Balls_vs_Paint | B10: R02 | C10: M | D10: 22 | E10: B | F10: 2026-10-19 | G10: Commercial_1_Balls | H10: Product_TV | I10: 60000 | J10: 14000 | K10: 23.33 | L10: 90.1 | M10: 720 | N10: 2 | O10: 5195 | P10: 2 | Q10: 1 | R10: 22 | S10: 931 | T10: 12931 | U10: 12931 | V10: 4540 | W10: 32.43 | X10: 206 | Y10: 173 | Z10: =IF(L10>=70,"Yes","No") | AA10: =IF(OR(AND(E10="A",G10="Commercial_1_Balls"),AND(E10="B",G10="Commercial_2_Paint")),"first","second") | AB10: =IF(ISNUMBER(W10),W10,0) | AC10: =IF(ISNUMBER(S10),1,0) | AD10: =IF(ISNUMBER(R10),R10,0)
A11: SIMULATED_AdTest_Balls_vs_Paint | B11: R02 | C11: M | D11: 22 | E11: B | F11: 2026-10-19 | G11: Commercial_1_Balls | H11: Brand_Logo | I11: 60000 | J11: 5000 | K11: 8.33 | L11: 90.1 | M11: 542 | N11: 1 | O11: 1766 | P11: 1 | Q11: 0 | R11: 5 | S11: 785 | T11: 55785 | U11: 55785 | V11: 1548 | W11: 30.96 | X11: 310 | Y11: 419 | Z11: =IF(L11>=70,"Yes","No") | AA11: =IF(OR(AND(E11="A",G11="Commercial_1_Balls"),AND(E11="B",G11="Commercial_2_Paint")),"first","second") | AB11: =IF(ISNUMBER(W11),W11,0) | AC11: =IF(ISNUMBER(S11),1,0) | AD11: =IF(ISNUMBER(R11),R11,0)
A12: SIMULATED_AdTest_Balls_vs_Paint | B12: R02 | C12: M | D12: 22 | E12: B | F12: 2026-10-19 | G12: Commercial_1_Balls | H12: Tagline_Text | I12: 60000 | J12: 4000 | K12: 6.67 | L12: 90.1 | M12: 1316 | N12: 3 | O12: 1410 | P12: 2 | Q12: 1 | R12: 4 | S12: 1582 | T12: 57582 | U12: 57582 | V12: 1276 | W12: 31.9 | X12: 319 | Y12: 245 | Z12: =IF(L12>=70,"Yes","No") | AA12: =IF(OR(AND(E12="A",G12="Commercial_1_Balls"),AND(E12="B",G12="Commercial_2_Paint")),"first","second") | AB12: =IF(ISNUMBER(W12),W12,0) | AC12: =IF(ISNUMBER(S12),1,0) | AD12: =IF(ISNUMBER(R12),R12,0)
A13: SIMULATED_AdTest_Balls_vs_Paint | B13: R02 | C13: M | D13: 22 | E13: B | F13: 2026-10-19 | G13: Commercial_1_Balls | H13: Hero_Element | I13: 60000 | J13: 40000 | K13: 66.67 | L13: 90.1 | M13: 333 | N13: 7 | O13: 17025 | P13: 6 | Q13: 5 | R13: 50 | S13: 469 | T13: 2469 | U13: 2469 | V13: 15561 | W13: 38.9 | X13: 311 | Y13: 128 | Z13: =IF(L13>=70,"Yes","No") | AA13: =IF(OR(AND(E13="A",G13="Commercial_1_Balls"),AND(E13="B",G13="Commercial_2_Paint")),"first","second") | AB13: =IF(ISNUMBER(W13),W13,0) | AC13: =IF(ISNUMBER(S13),1,0) | AD13: =IF(ISNUMBER(R13),R13,0)
... A55: SIMULATED_AdTest_Balls_vs_Paint | B55: R07 | C55: F | D55: 26 | E55: A | F55: 2026-10-19 | G55: Commercial_2_Paint | H55: Brand_Logo | I55: 60000 | J55: 5000 | K55: 8.33 | L55: 92.3 | M55: 513 | N55: 2 | O55: 1477 | P55: 2 | Q55: 1 | R55: 3 | S55: 675 | T55: 55675 | U55: 55675 | V55: 1427 | W55: 28.54 | X55: 476 | Y55: 267 | Z55: =IF(L55>=70,"Yes","No") | AA55: =IF(OR(AND(E55="A",G55="Commercial_1_Balls"),AND(E55="B",G55="Commercial_2_Paint")),"first","second") | AB55: =IF(ISNUMBER(W55),W55,0) | AC55: =IF(ISNUMBER(S55),1,0) | AD55: =IF(ISNUMBER(R55),R55,0)
A56: SIMULATED_AdTest_Balls_vs_Paint | B56: R07 | C56: F | D56: 26 | E56: A | F56: 2026-10-19 | G56: Commercial_2_Paint | H56: Tagline_Text | I56: 60000 | J56: 4000 | K56: 6.67 | L56: 92.3 | M56: NA | N56: NA | O56: NA | P56: NA | Q56: NA | R56: NA | S56: NA | T56: NA | U56: 60000 | V56: NA | W56: NA | X56: NA | Y56: NA | Z56: =IF(L56>=70,"Yes","No") | AA56: =IF(OR(AND(E56="A",G56="Commercial_1_Balls"),AND(E56="B",G56="Commercial_2_Paint")),"first","second") | AB56: =IF(ISNUMBER(W56),W56,0) | AC56: =IF(ISNUMBER(S56),1,0) | AD56: =IF(ISNUMBER(R56),R56,0)
A57: SIMULATED_AdTest_Balls_vs_Paint | B57: R07 | C57: F | D57: 26 | E57: A | F57: 2026-10-19 | G57: Commercial_2_Paint | H57: Hero_Element | I57: 60000 | J57: 32000 | K57: 53.33 | L57: 92.3 | M57: 778 | N57: 4 | O57: 14329 | P57: 4 | Q57: 3 | R57: 43 | S57: 933 | T57: 3933 | U57: 3933 | V57: 13856 | W57: 43.3 | X57: 322 | Y57: 286 | Z57: =IF(L57>=70,"Yes","No") | AA57: =IF(OR(AND(E57="A",G57="Commercial_1_Balls"),AND(E57="B",G57="Commercial_2_Paint")),"first","second") | AB57: =IF(ISNUMBER(W57),W57,0) | AC57: =IF(ISNUMBER(S57),1,0) | AD57: =IF(ISNUMBER(R57),R57,0)
A58: SIMULATED_AdTest_Balls_vs_Paint | B58: R08 | C58: F | D58: 38 | E58: B | F58: 2026-10-19 | G58: Commercial_1_Balls | H58: Product_TV | I58: 60000 | J58: 14000 | K58: 23.33 | L58: 98 | M58: 1176 | N58: 2 | O58: 4839 | P58: 2 | Q58: 1 | R58: 18 | S58: 1258 | T58: 13258 | U58: 13258 | V58: 4215 | W58: 30.11 | X58: 234 | Y58: 217 | Z58: =IF(L58>=70,"Yes","No") | AA58: =IF(OR(AND(E58="A",G58="Commercial_1_Balls"),AND(E58="B",G58="Commercial_2_Paint")),"first","second") | AB58: =IF(ISNUMBER(W58),W58,0) | AC58: =IF(ISNUMBER(S58),1,0) | AD58: =IF(ISNUMBER(R58),R58,0)
A59: SIMULATED_AdTest_Balls_vs_Paint | B59: R08 | C59: F | D59: 38 | E59: B | F59: 2026-10-19 | G59: Commercial_1_Balls | H59: Brand_Logo | I59: 60000 | J59: 5000 | K59: 8.33 | L59: 98 | M59: 368 | N59: 1 | O59: 2428 | P59: 1 | Q59: 0 | R59: 14 | S59: 581 | T59: 55581 | U59: 55581 | V59: 2306 | W59: 46.12 | X59: 165 | Y59: 199 | Z59: =IF(L59>=70,"Yes","No") | AA59: =IF(OR(AND(E59="A",G59="Commercial_1_Balls"),AND(E59="B",G59="Commercial_2_Paint")),"first","second") | AB59: =IF(ISNUMBER(W59),W59,0) | AC59: =IF(ISNUMBER(S59),1,0) | AD59: =IF(ISNUMBER(R59),R59,0)
A60: SIMULATED_AdTest_Balls_vs_Paint | B60: R08 | C60: F | D60: 38 | E60: B | F60: 2026-10-19 | G60: Commercial_1_Balls | H60: Tagline_Text | I60: 60000 | J60: 4000 | K60: 6.67 | L60: 98 | M60: 1080 | N60: 1 | O60: 1149 | P60: 1 | Q60: 0 | R60: 3 | S60: 1286 | T60: 57286 | U60: 57286 | V60: 1018 | W60: 25.45 | X60: 339 | Y60: 287 | Z60: =IF(L60>=70,"Yes","No") | AA60: =IF(OR(AND(E60="A",G60="Commercial_1_Balls"),AND(E60="B",G60="Commercial_2_Paint")),"first","second") | AB60: =IF(ISNUMBER(W60),W60,0) | AC60: =IF(ISNUMBER(S60),1,0) | AD60: =IF(ISNUMBER(R60),R60,0)
A61: SIMULATED_AdTest_Balls_vs_Paint | B61: R08 | C61: F | D61: 38 | E61: B | F61: 2026-10-19 | G61: Commercial_1_Balls | H61: Hero_Element | I61: 60000 | J61: 40000 | K61: 66.67 | L61: 98 | M61: 478 | N61: 3 | O61: 15441 | P61: 3 | Q61: 2 | R61: 52 | S61: 663 | T61: 2663 | U61: 2663 | V61: 14465 | W61: 36.16 | X61: 278 | Y61: 231 | Z61: =IF(L61>=70,"Yes","No") | AA61: =IF(OR(AND(E61="A",G61="Commercial_1_Balls"),AND(E61="B",G61="Commercial_2_Paint")),"first","second") | AB61: =IF(ISNUMBER(W61),W61,0) | AC61: =IF(ISNUMBER(S61),1,0) | AD61: =IF(ISNUMBER(R61),R61,0)
A62: SIMULATED_AdTest_Balls_vs_Paint | B62: R08 | C62: F | D62: 38 | E62: B | F62: 2026-10-19 | G62: Commercial_2_Paint | H62: Product_TV | I62: 60000 | J62: 20000 | K62: 33.33 | L62: 98 | M62: 747 | N62: 3 | O62: 4138 | P62: 2 | Q62: 1 | R62: 12 | S62: 837 | T62: 9837 | U62: 9837 | V62: 3889 | W62: 19.45 | X62: 324 | Y62: 399 | Z62: =IF(L62>=70,"Yes","No") | AA62: =IF(OR(AND(E62="A",G62="Commercial_1_Balls"),AND(E62="B",G62="Commercial_2_Paint")),"first","second") | AB62: =IF(ISNUMBER(W62),W62,0) | AC62: =IF(ISNUMBER(S62),1,0) | AD62: =IF(ISNUMBER(R62),R62,0)
A63: SIMULATED_AdTest_Balls_vs_Paint | B63: R08 | C63: F | D63: 38 | E63: B | F63: 2026-10-19 | G63: Commercial_2_Paint | H63: Brand_Logo | I63: 60000 | J63: 5000 | K63: 8.33 | L63: 98 | M63: 524 | N63: 3 | O63: 1459 | P63: 3 | Q63: 2 | R63: 4 | S63: 703 | T63: 55703 | U63: 55703 | V63: 1362 | W63: 27.24 | X63: 340 | Y63: 383 | Z63: =IF(L63>=70,"Yes","No") | AA63: =IF(OR(AND(E63="A",G63="Commercial_1_Balls"),AND(E63="B",G63="Commercial_2_Paint")),"first","second") | AB63: =IF(ISNUMBER(W63),W63,0) | AC63: =IF(ISNUMBER(S63),1,0) | AD63: =IF(ISNUMBER(R63),R63,0)
A64: SIMULATED_AdTest_Balls_vs_Paint | B64: R08 | C64: F | D64: 38 | E64: B | F64: 2026-10-19 | G64: Commercial_2_Paint | H64: Tagline_Text | I64: 60000 | J64: 4000 | K64: 6.67 | L64: 98 | M64: 959 | N64: 1 | O64: 2411 | P64: 1 | Q64: 0 | R64: 8 | S64: 1222 | T64: 57222 | U64: 57222 | V64: 2340 | W64: 58.5 | X64: 292 | Y64: 163 | Z64: =IF(L64>=70,"Yes","No") | AA64: =IF(OR(AND(E64="A",G64="Commercial_1_Balls"),AND(E64="B",G64="Commercial_2_Paint")),"first","second") | AB64: =IF(ISNUMBER(W64),W64,0) | AC64: =IF(ISNUMBER(S64),1,0) | AD64: =IF(ISNUMBER(R64),R64,0)
A65: SIMULATED_AdTest_Balls_vs_Paint | B65: R08 | C65: F | D65: 38 | E65: B | F65: 2026-10-19 | G65: Commercial_2_Paint | H65: Hero_Element | I65: 60000 | J65: 32000 | K65: 53.33 | L65: 98 | M65: 270 | N65: 2 | O65: 12962 | P65: 2 | Q65: 1 | R65: 40 | S65: 428 | T65: 3428 | U65: 3428 | V65: 11512 | W65: 35.98 | X65: 288 | Y65: 233 | Z65: =IF(L65>=70,"Yes","No") | AA65: =IF(OR(AND(E65="A",G65="Commercial_1_Balls"),AND(E65="B",G65="Commercial_2_Paint")),"first","second") | AB65: =IF(ISNUMBER(W65),W65,0) | AC65: =IF(ISNUMBER(S65),1,0) | AD65: =IF(ISNUMBER(R65),R65,0)
A66: SIMULATED_AdTest_Balls_vs_Paint | B66: R09 | C66: M | D66: 30 | E66: A | F66: 2026-10-19 | G66: Commercial_1_Balls | H66: Product_TV | I66: 60000 | J66: 14000 | K66: 23.33 | L66: 85.6 | M66: 1512 | N66: 2 | O66: 2004 | P66: 1 | Q66: 0 | R66: 6 | S66: 1730 | T66: 13730 | U66: 13730 | V66: 1891 | W66: 13.51 | X66: 315 | Y66: 350 | Z66: =IF(L66>=70,"Yes","No") | AA66: =IF(OR(AND(E66="A",G66="Commercial_1_Balls"),AND(E66="B",G66="Commercial_2_Paint")),"first","second") | AB66: =IF(ISNUMBER(W66),W66,0) | AC66: =IF(ISNUMBER(S66),1,0) | AD66: =IF(ISNUMBER(R66),R66,0)
A67: SIMULATED_AdTest_Balls_vs_Paint | B67: R09 | C67: M | D67: 30 | E67: A | F67: 2026-10-19 | G67: Commercial_1_Balls | H67: Brand_Logo | I67: 60000 | J67: 5000 | K67: 8.33 | L67: 85.6 | M67: 1088 | N67: 1 | O67: 1773 | P67: 1 | Q67: 0 | R67: 5 | S67: 1237 | T67: 56237 | U67: 56237 | V67: 1549 | W67: 30.98 | X67: 310 | Y67: 230 | Z67: =IF(L67>=70,"Yes","No") | AA67: =IF(OR(AND(E67="A",G67="Commercial_1_Balls"),AND(E67="B",G67="Commercial_2_Paint")),"first","second") | AB67: =IF(ISNUMBER(W67),W67,0) | AC67: =IF(ISNUMBER(S67),1,0) | AD67: =IF(ISNUMBER(R67),R67,0)
A68: SIMULATED_AdTest_Balls_vs_Paint | B68: R09 | C68: M | D68: 30 | E68: A | F68: 2026-10-19 | G68: Commercial_1_Balls | H68: Tagline_Text | I68: 60000 | J68: 4000 | K68: 6.67 | L68: 85.6 | M68: 1376 | N68: 2 | O68: 2435 | P68: 2 | Q68: 1 | R68: 9 | S68: 1593 | T68: 57593 | U68: 57593 | V68: 2166 | W68: 54.15 | X68: 241 | Y68: 446 | Z68: =IF(L68>=70,"Yes","No") | AA68: =IF(OR(AND(E68="A",G68="Commercial_1_Balls"),AND(E68="B",G68="Commercial_2_Paint")),"first","second") | AB68: =IF(ISNUMBER(W68),W68,0) | AC68: =IF(ISNUMBER(S68),1,0) | AD68: =IF(ISNUMBER(R68),R68,0)
... A70: SIMULATED_AdTest_Balls_vs_Paint | B70: R09 | C70: M | D70: 30 | E70: A | F70: 2026-10-19 | G70: Commercial_2_Paint | H70: Product_TV | I70: 60000 | J70: 20000 | K70: 33.33 | L70: 85.6 | M70: 656 | N70: 2 | O70: 5243 | P70: 2 | Q70: 1 | R70: 17 | S70: 903 | T70: 9903 | U70: 9903 | V70: 4974 | W70: 24.87 | X70: 293 | Y70: 426 | Z70: =IF(L70>=70,"Yes","No") | AA70: =IF(OR(AND(E70="A",G70="Commercial_1_Balls"),AND(E70="B",G70="Commercial_2_Paint")),"first","second") | AB70: =IF(ISNUMBER(W70),W70,0) | AC70: =IF(ISNUMBER(S70),1,0) | AD70: =IF(ISNUMBER(R70),R70,0)
A71: SIMULATED_AdTest_Balls_vs_Paint | B71: R09 | C71: M | D71: 30 | E71: A | F71: 2026-10-19 | G71: Commercial_2_Paint | H71: Brand_Logo | I71: 60000 | J71: 5000 | K71: 8.33 | L71: 85.6 | M71: 3881 | N71: 1 | O71: 127 | P71: NA | Q71: NA | R71: NA | S71: NA | T71: NA | U71: 60000 | V71: NA | W71: NA | X71: NA | Y71: NA | Z71: =IF(L71>=70,"Yes","No") | AA71: =IF(OR(AND(E71="A",G71="Commercial_1_Balls"),AND(E71="B",G71="Commercial_2_Paint")),"first","second") | AB71: =IF(ISNUMBER(W71),W71,0) | AC71: =IF(ISNUMBER(S71),1,0) | AD71: =IF(ISNUMBER(R71),R71,0)
A72: SIMULATED_AdTest_Balls_vs_Paint | B72: R09 | C72: M | D72: 30 | E72: A | F72: 2026-10-19 | G72: Commercial_2_Paint | H72: Tagline_Text | I72: 60000 | J72: 4000 | K72: 6.67 | L72: 85.6 | M72: 1116 | N72: 1 | O72: 958 | P72: 1 | Q72: 0 | R72: 5 | S72: 1303 | T72: 57303 | U72: 57303 | V72: 900 | W72: 22.5 | X72: 180 | Y72: 267 | Z72: =IF(L72>=70,"Yes","No") | AA72: =IF(OR(AND(E72="A",G72="Commercial_1_Balls"),AND(E72="B",G72="Commercial_2_Paint")),"first","second") | AB72: =IF(ISNUMBER(W72),W72,0) | AC72: =IF(ISNUMBER(S72),1,0) | AD72: =IF(ISNUMBER(R72),R72,0)
A73: SIMULATED_AdTest_Balls_vs_Paint | B73: R09 | C73: M | D73: 30 | E73: A | F73: 2026-10-19 | G73: Commercial_2_Paint | H73: Hero_Element | I73: 60000 | J73: 32000 | K73: 53.33 | L73: 85.6 | M73: 717 | N73: 4 | O73: 20025 | P73: 3 | Q73: 2 | R73: 66 | S73: 937 | T73: 3937 | U73: 3937 | V73: 18628 | W73: 58.21 | X73: 282 | Y73: 463 | Z73: =IF(L73>=70,"Yes","No") | AA73: =IF(OR(AND(E73="A",G73="Commercial_1_Balls"),AND(E73="B",G73="Commercial_2_Paint")),"first","second") | AB73: =IF(ISNUMBER(W73),W73,0) | AC73: =IF(ISNUMBER(S73),1,0) | AD73: =IF(ISNUMBER(R73),R73,0)
A74: SIMULATED_AdTest_Balls_vs_Paint | B74: R10 | C74: M | D74: 28 | E74: B | F74: 2026-10-19 | G74: Commercial_1_Balls | H74: Product_TV | I74: 60000 | J74: 14000 | K74: 23.33 | L74: 89 | M74: 708 | N74: 1 | O74: 1828 | P74: 1 | Q74: 0 | R74: 6 | S74: 996 | T74: 12996 | U74: 12996 | V74: 1672 | W74: 11.94 | X74: 279 | Y74: 221 | Z74: =IF(L74>=70,"Yes","No") | AA74: =IF(OR(AND(E74="A",G74="Commercial_1_Balls"),AND(E74="B",G74="Commercial_2_Paint")),"first","second") | AB74: =IF(ISNUMBER(W74),W74,0) | AC74: =IF(ISNUMBER(S74),1,0) | AD74: =IF(ISNUMBER(R74),R74,0)
A75: SIMULATED_AdTest_Balls_vs_Paint | B75: R10 | C75: M | D75: 28 | E75: B | F75: 2026-10-19 | G75: Commercial_1_Balls | H75: Brand_Logo | I75: 60000 | J75: 5000 | K75: 8.33 | L75: 89 | M75: 429 | N75: 1 | O75: 1024 | P75: 1 | Q75: 0 | R75: 4 | S75: 581 | T75: 55581 | U75: 55581 | V75: 891 | W75: 17.82 | X75: 223 | Y75: 356 | Z75: =IF(L75>=70,"Yes","No") | AA75: =IF(OR(AND(E75="A",G75="Commercial_1_Balls"),AND(E75="B",G75="Commercial_2_Paint")),"first","second") | AB75: =IF(ISNUMBER(W75),W75,0) | AC75: =IF(ISNUMBER(S75),1,0) | AD75: =IF(ISNUMBER(R75),R75,0)
A76: SIMULATED_AdTest_Balls_vs_Paint | B76: R10 | C76: M | D76: 28 | E76: B | F76: 2026-10-19 | G76: Commercial_1_Balls | H76: Tagline_Text | I76: 60000 | J76: 4000 | K76: 6.67 | L76: 89 | M76: 736 | N76: 1 | O76: 1111 | P76: 1 | Q76: 0 | R76: 3 | S76: 987 | T76: 56987 | U76: 56987 | V76: 1013 | W76: 25.32 | X76: 338 | Y76: 317 | Z76: =IF(L76>=70,"Yes","No") | AA76: =IF(OR(AND(E76="A",G76="Commercial_1_Balls"),AND(E76="B",G76="Commercial_2_Paint")),"first","second") | AB76: =IF(ISNUMBER(W76),W76,0) | AC76: =IF(ISNUMBER(S76),1,0) | AD76: =IF(ISNUMBER(R76),R76,0)
A77: SIMULATED_AdTest_Balls_vs_Paint | B77: R10 | C77: M | D77: 28 | E77: B | F77: 2026-10-19 | G77: Commercial_1_Balls | H77: Hero_Element | I77: 60000 | J77: 40000 | K77: 66.67 | L77: 89 | M77: 558 | N77: 6 | O77: 30245 | P77: 6 | Q77: 5 | R77: 124 | S77: 643 | T77: 2643 | U77: 2643 | V77: 26522 | W77: 66.31 | X77: 214 | Y77: 182 | Z77: =IF(L77>=70,"Yes","No") | AA77: =IF(OR(AND(E77="A",G77="Commercial_1_Balls"),AND(E77="B",G77="Commercial_2_Paint")),"first","second") | AB77: =IF(ISNUMBER(W77),W77,0) | AC77: =IF(ISNUMBER(S77),1,0) | AD77: =IF(ISNUMBER(R77),R77,0)
A78: SIMULATED_AdTest_Balls_vs_Paint | B78: R10 | C78: M | D78: 28 | E78: B | F78: 2026-10-19 | G78: Commercial_2_Paint | H78: Product_TV | I78: 60000 | J78: 20000 | K78: 33.33 | L78: 89 | M78: 876 | N78: 2 | O78: 2730 | P78: 2 | Q78: 1 | R78: 14 | S78: 1094 | T78: 10094 | U78: 10094 | V78: 2516 | W78: 12.58 | X78: 180 | Y78: 245 | Z78: =IF(L78>=70,"Yes","No") | AA78: =IF(OR(AND(E78="A",G78="Commercial_1_Balls"),AND(E78="B",G78="Commercial_2_Paint")),"first","second") | AB78: =IF(ISNUMBER(W78),W78,0) | AC78: =IF(ISNUMBER(S78),1,0) | AD78: =IF(ISNUMBER(R78),R78,0)
A79: SIMULATED_AdTest_Balls_vs_Paint | B79: R10 | C79: M | D79: 28 | E79: B | F79: 2026-10-19 | G79: Commercial_2_Paint | H79: Brand_Logo | I79: 60000 | J79: 5000 | K79: 8.33 | L79: 89 | M79: NA | N79: NA | O79: NA | P79: NA | Q79: NA | R79: NA | S79: NA | T79: NA | U79: 60000 | V79: NA | W79: NA | X79: NA | Y79: NA | Z79: =IF(L79>=70,"Yes","No") | AA79: =IF(OR(AND(E79="A",G79="Commercial_1_Balls"),AND(E79="B",G79="Commercial_2_Paint")),"first","second") | AB79: =IF(ISNUMBER(W79),W79,0) | AC79: =IF(ISNUMBER(S79),1,0) | AD79: =IF(ISNUMBER(R79),R79,0)
A80: SIMULATED_AdTest_Balls_vs_Paint | B80: R10 | C80: M | D80: 28 | E80: B | F80: 2026-10-19 | G80: Commercial_2_Paint | H80: Tagline_Text | I80: 60000 | J80: 4000 | K80: 6.67 | L80: 89 | M80: 608 | N80: 2 | O80: 1174 | P80: 2 | Q80: 1 | R80: 7 | S80: 886 | T80: 56886 | U80: 56886 | V80: 1107 | W80: 27.68 | X80: 158 | Y80: 249 | Z80: =IF(L80>=70,"Yes","No") | AA80: =IF(OR(AND(E80="A",G80="Commercial_1_Balls"),AND(E80="B",G80="Commercial_2_Paint")),"first","second") | AB80: =IF(ISNUMBER(W80),W80,0) | AC80: =IF(ISNUMBER(S80),1,0) | AD80: =IF(ISNUMBER(R80),R80,0)
A81: SIMULATED_AdTest_Balls_vs_Paint | B81: R10 | C81: M | D81: 28 | E81: B | F81: 2026-10-19 | G81: Commercial_2_Paint | H81: Hero_Element | I81: 60000 | J81: 32000 | K81: 53.33 | L81: 89 | M81: 238 | N81: 5 | O81: 15229 | P81: 5 | Q81: 4 | R81: 43 | S81: 483 | T81: 3483 | U81: 3483 | V81: 13588 | W81: 42.46 | X81: 316 | Y81: 214 | Z81: =IF(L81>=70,"Yes","No") | AA81: =IF(OR(AND(E81="A",G81="Commercial_1_Balls"),AND(E81="B",G81="Commercial_2_Paint")),"first","second") | AB81: =IF(ISNUMBER(W81),W81,0) | AC81: =IF(ISNUMBER(S81),1,0) | AD81: =IF(ISNUMBER(R81),R81,0)
A82: SIMULATED_AdTest_Balls_vs_Paint | B82: R11 | C82: F | D82: 21 | E82: A | F82: 2026-10-19 | G82: Commercial_1_Balls | H82: Product_TV | I82: 60000 | J82: 14000 | K82: 23.33 | L82: 89.7 | M82: 429 | N82: 1 | O82: 3539 | P82: 1 | Q82: 0 | R82: 9 | S82: 582 | T82: 12582 | U82: 12582 | V82: 3371 | W82: 24.08 | X82: 375 | Y82: 343 | Z82: =IF(L82>=70,"Yes","No") | AA82: =IF(OR(AND(E82="A",G82="Commercial_1_Balls"),AND(E82="B",G82="Commercial_2_Paint")),"first","second") | AB82: =IF(ISNUMBER(W82),W82,0) | AC82: =IF(ISNUMBER(S82),1,0) | AD82: =IF(ISNUMBER(R82),R82,0)
...

Sheet Summary
A1: Descriptive table by AOI and commercial (kept respondents only). SIMULATED data.
A2: n = kept respondents with a row for the AOI; Respondent ratio = percent who fixated the AOI; TTFF statistics use fixators only; dwell and fixation count statistics count never fixated AOIs as 0.
A4: AOI | B4: Stimulus | C4: n | D4: Respondent ratio (%) | E4: n with TTFF | F4: TTFF AOI mean (ms) | G4: TTFF AOI SD (ms) | H4: Dwell time mean (%) | I4: Dwell time SD (%) | J4: Fixation count mean
A5: Product_TV | B5: Commercial_1_Balls | C5: =COUNTIFS(Data!$G$2:$G$241,$B5,Data!$H$2:$H$241,$A5,Data!$Z$2:$Z$241,"Yes") | D5: =100*AVERAGEIFS(Data!$AC$2:$AC$241,Data!$G$2:$G$241,$B5,Data!$H$2:$H$241,$A5,Data!$Z$2:$Z$241,"Yes") | E5: =COUNTIFS(Data!$G$2:$G$241,$B5,Data!$H$2:$H$241,$A5,Data!$Z$2:$Z$241,"Yes",Data!$S$2:$S$241,">0") | F5: =AVERAGEIFS(Data!$S$2:$S$241,Data!$G$2:$G$241,$B5,Data!$H$2:$H$241,$A5,Data!$Z$2:$Z$241,"Yes") | G5: {=_xlfn.STDEV.S(IF((Data!$G$2:$G$241=$B5)*(Data!$H$2:$H$241=$A5)*(Data!$Z$2:$Z$241="Yes")*ISNUMBER(Data!$S$2:$S$241),Data!$S$2:$S$241))} | H5: =AVERAGEIFS(Data!$AB$2:$AB$241,Data!$G$2:$G$241,$B5,Data!$H$2:$H$241,$A5,Data!$Z$2:$Z$241,"Yes") | I5: {=_xlfn.STDEV.S(IF((Data!$G$2:$G$241=$B5)*(Data!$H$2:$H$241=$A5)*(Data!$Z$2:$Z$241="Yes"),Data!$AB$2:$AB$241))} | J5: =AVERAGEIFS(Data!$AD$2:$AD$241,Data!$G$2:$G$241,$B5,Data!$H$2:$H$241,$A5,Data!$Z$2:$Z$241,"Yes")
A6: Product_TV | B6: Commercial_2_Paint | C6: =COUNTIFS(Data!$G$2:$G$241,$B6,Data!$H$2:$H$241,$A6,Data!$Z$2:$Z$241,"Yes") | D6: =100*AVERAGEIFS(Data!$AC$2:$AC$241,Data!$G$2:$G$241,$B6,Data!$H$2:$H$241,$A6,Data!$Z$2:$Z$241,"Yes") | E6: =COUNTIFS(Data!$G$2:$G$241,$B6,Data!$H$2:$H$241,$A6,Data!$Z$2:$Z$241,"Yes",Data!$S$2:$S$241,">0") | F6: =AVERAGEIFS(Data!$S$2:$S$241,Data!$G$2:$G$241,$B6,Data!$H$2:$H$241,$A6,Data!$Z$2:$Z$241,"Yes") | G6: {=_xlfn.STDEV.S(IF((Data!$G$2:$G$241=$B6)*(Data!$H$2:$H$241=$A6)*(Data!$Z$2:$Z$241="Yes")*ISNUMBER(Data!$S$2:$S$241),Data!$S$2:$S$241))} | H6: =AVERAGEIFS(Data!$AB$2:$AB$241,Data!$G$2:$G$241,$B6,Data!$H$2:$H$241,$A6,Data!$Z$2:$Z$241,"Yes") | I6: {=_xlfn.STDEV.S(IF((Data!$G$2:$G$241=$B6)*(Data!$H$2:$H$241=$A6)*(Data!$Z$2:$Z$241="Yes"),Data!$AB$2:$AB$241))} | J6: =AVERAGEIFS(Data!$AD$2:$AD$241,Data!$G$2:$G$241,$B6,Data!$H$2:$H$241,$A6,Data!$Z$2:$Z$241,"Yes")
A7: Brand_Logo | B7: Commercial_1_Balls | C7: =COUNTIFS(Data!$G$2:$G$241,$B7,Data!$H$2:$H$241,$A7,Data!$Z$2:$Z$241,"Yes") | D7: =100*AVERAGEIFS(Data!$AC$2:$AC$241,Data!$G$2:$G$241,$B7,Data!$H$2:$H$241,$A7,Data!$Z$2:$Z$241,"Yes") | E7: =COUNTIFS(Data!$G$2:$G$241,$B7,Data!$H$2:$H$241,$A7,Data!$Z$2:$Z$241,"Yes",Data!$S$2:$S$241,">0") | F7: =AVERAGEIFS(Data!$S$2:$S$241,Data!$G$2:$G$241,$B7,Data!$H$2:$H$241,$A7,Data!$Z$2:$Z$241,"Yes") | G7: {=_xlfn.STDEV.S(IF((Data!$G$2:$G$241=$B7)*(Data!$H$2:$H$241=$A7)*(Data!$Z$2:$Z$241="Yes")*ISNUMBER(Data!$S$2:$S$241),Data!$S$2:$S$241))} | H7: =AVERAGEIFS(Data!$AB$2:$AB$241,Data!$G$2:$G$241,$B7,Data!$H$2:$H$241,$A7,Data!$Z$2:$Z$241,"Yes") | I7: {=_xlfn.STDEV.S(IF((Data!$G$2:$G$241=$B7)*(Data!$H$2:$H$241=$A7)*(Data!$Z$2:$Z$241="Yes"),Data!$AB$2:$AB$241))} | J7: =AVERAGEIFS(Data!$AD$2:$AD$241,Data!$G$2:$G$241,$B7,Data!$H$2:$H$241,$A7,Data!$Z$2:$Z$241,"Yes")
A8: Brand_Logo | B8: Commercial_2_Paint | C8: =COUNTIFS(Data!$G$2:$G$241,$B8,Data!$H$2:$H$241,$A8,Data!$Z$2:$Z$241,"Yes") | D8: =100*AVERAGEIFS(Data!$AC$2:$AC$241,Data!$G$2:$G$241,$B8,Data!$H$2:$H$241,$A8,Data!$Z$2:$Z$241,"Yes") | E8: =COUNTIFS(Data!$G$2:$G$241,$B8,Data!$H$2:$H$241,$A8,Data!$Z$2:$Z$241,"Yes",Data!$S$2:$S$241,">0") | F8: =AVERAGEIFS(Data!$S$2:$S$241,Data!$G$2:$G$241,$B8,Data!$H$2:$H$241,$A8,Data!$Z$2:$Z$241,"Yes") | G8: {=_xlfn.STDEV.S(IF((Data!$G$2:$G$241=$B8)*(Data!$H$2:$H$241=$A8)*(Data!$Z$2:$Z$241="Yes")*ISNUMBER(Data!$S$2:$S$241),Data!$S$2:$S$241))} | H8: =AVERAGEIFS(Data!$AB$2:$AB$241,Data!$G$2:$G$241,$B8,Data!$H$2:$H$241,$A8,Data!$Z$2:$Z$241,"Yes") | I8: {=_xlfn.STDEV.S(IF((Data!$G$2:$G$241=$B8)*(Data!$H$2:$H$241=$A8)*(Data!$Z$2:$Z$241="Yes"),Data!$AB$2:$AB$241))} | J8: =AVERAGEIFS(Data!$AD$2:$AD$241,Data!$G$2:$G$241,$B8,Data!$H$2:$H$241,$A8,Data!$Z$2:$Z$241,"Yes")
A9: Tagline_Text | B9: Commercial_1_Balls | C9: =COUNTIFS(Data!$G$2:$G$241,$B9,Data!$H$2:$H$241,$A9,Data!$Z$2:$Z$241,"Yes") | D9: =100*AVERAGEIFS(Data!$AC$2:$AC$241,Data!$G$2:$G$241,$B9,Data!$H$2:$H$241,$A9,Data!$Z$2:$Z$241,"Yes") | E9: =COUNTIFS(Data!$G$2:$G$241,$B9,Data!$H$2:$H$241,$A9,Data!$Z$2:$Z$241,"Yes",Data!$S$2:$S$241,">0") | F9: =AVERAGEIFS(Data!$S$2:$S$241,Data!$G$2:$G$241,$B9,Data!$H$2:$H$241,$A9,Data!$Z$2:$Z$241,"Yes") | G9: {=_xlfn.STDEV.S(IF((Data!$G$2:$G$241=$B9)*(Data!$H$2:$H$241=$A9)*(Data!$Z$2:$Z$241="Yes")*ISNUMBER(Data!$S$2:$S$241),Data!$S$2:$S$241))} | H9: =AVERAGEIFS(Data!$AB$2:$AB$241,Data!$G$2:$G$241,$B9,Data!$H$2:$H$241,$A9,Data!$Z$2:$Z$241,"Yes") | I9: {=_xlfn.STDEV.S(IF((Data!$G$2:$G$241=$B9)*(Data!$H$2:$H$241=$A9)*(Data!$Z$2:$Z$241="Yes"),Data!$AB$2:$AB$241))} | J9: =AVERAGEIFS(Data!$AD$2:$AD$241,Data!$G$2:$G$241,$B9,Data!$H$2:$H$241,$A9,Data!$Z$2:$Z$241,"Yes")
A10: Tagline_Text | B10: Commercial_2_Paint | C10: =COUNTIFS(Data!$G$2:$G$241,$B10,Data!$H$2:$H$241,$A10,Data!$Z$2:$Z$241,"Yes") | D10: =100*AVERAGEIFS(Data!$AC$2:$AC$241,Data!$G$2:$G$241,$B10,Data!$H$2:$H$241,$A10,Data!$Z$2:$Z$241,"Yes") | E10: =COUNTIFS(Data!$G$2:$G$241,$B10,Data!$H$2:$H$241,$A10,Data!$Z$2:$Z$241,"Yes",Data!$S$2:$S$241,">0") | F10: =AVERAGEIFS(Data!$S$2:$S$241,Data!$G$2:$G$241,$B10,Data!$H$2:$H$241,$A10,Data!$Z$2:$Z$241,"Yes") | G10: {=_xlfn.STDEV.S(IF((Data!$G$2:$G$241=$B10)*(Data!$H$2:$H$241=$A10)*(Data!$Z$2:$Z$241="Yes")*ISNUMBER(Data!$S$2:$S$241),Data!$S$2:$S$241))} | H10: =AVERAGEIFS(Data!$AB$2:$AB$241,Data!$G$2:$G$241,$B10,Data!$H$2:$H$241,$A10,Data!$Z$2:$Z$241,"Yes") | I10: {=_xlfn.STDEV.S(IF((Data!$G$2:$G$241=$B10)*(Data!$H$2:$H$241=$A10)*(Data!$Z$2:$Z$241="Yes"),Data!$AB$2:$AB$241))} | J10: =AVERAGEIFS(Data!$AD$2:$AD$241,Data!$G$2:$G$241,$B10,Data!$H$2:$H$241,$A10,Data!$Z$2:$Z$241,"Yes")
A11: Hero_Element | B11: Commercial_1_Balls | C11: =COUNTIFS(Data!$G$2:$G$241,$B11,Data!$H$2:$H$241,$A11,Data!$Z$2:$Z$241,"Yes") | D11: =100*AVERAGEIFS(Data!$AC$2:$AC$241,Data!$G$2:$G$241,$B11,Data!$H$2:$H$241,$A11,Data!$Z$2:$Z$241,"Yes") | E11: =COUNTIFS(Data!$G$2:$G$241,$B11,Data!$H$2:$H$241,$A11,Data!$Z$2:$Z$241,"Yes",Data!$S$2:$S$241,">0") | F11: =AVERAGEIFS(Data!$S$2:$S$241,Data!$G$2:$G$241,$B11,Data!$H$2:$H$241,$A11,Data!$Z$2:$Z$241,"Yes") | G11: {=_xlfn.STDEV.S(IF((Data!$G$2:$G$241=$B11)*(Data!$H$2:$H$241=$A11)*(Data!$Z$2:$Z$241="Yes")*ISNUMBER(Data!$S$2:$S$241),Data!$S$2:$S$241))} | H11: =AVERAGEIFS(Data!$AB$2:$AB$241,Data!$G$2:$G$241,$B11,Data!$H$2:$H$241,$A11,Data!$Z$2:$Z$241,"Yes") | I11: {=_xlfn.STDEV.S(IF((Data!$G$2:$G$241=$B11)*(Data!$H$2:$H$241=$A11)*(Data!$Z$2:$Z$241="Yes"),Data!$AB$2:$AB$241))} | J11: =AVERAGEIFS(Data!$AD$2:$AD$241,Data!$G$2:$G$241,$B11,Data!$H$2:$H$241,$A11,Data!$Z$2:$Z$241,"Yes")
A12: Hero_Element | B12: Commercial_2_Paint | C12: =COUNTIFS(Data!$G$2:$G$241,$B12,Data!$H$2:$H$241,$A12,Data!$Z$2:$Z$241,"Yes") | D12: =100*AVERAGEIFS(Data!$AC$2:$AC$241,Data!$G$2:$G$241,$B12,Data!$H$2:$H$241,$A12,Data!$Z$2:$Z$241,"Yes") | E12: =COUNTIFS(Data!$G$2:$G$241,$B12,Data!$H$2:$H$241,$A12,Data!$Z$2:$Z$241,"Yes",Data!$S$2:$S$241,">0") | F12: =AVERAGEIFS(Data!$S$2:$S$241,Data!$G$2:$G$241,$B12,Data!$H$2:$H$241,$A12,Data!$Z$2:$Z$241,"Yes") | G12: {=_xlfn.STDEV.S(IF((Data!$G$2:$G$241=$B12)*(Data!$H$2:$H$241=$A12)*(Data!$Z$2:$Z$241="Yes")*ISNUMBER(Data!$S$2:$S$241),Data!$S$2:$S$241))} | H12: =AVERAGEIFS(Data!$AB$2:$AB$241,Data!$G$2:$G$241,$B12,Data!$H$2:$H$241,$A12,Data!$Z$2:$Z$241,"Yes") | I12: {=_xlfn.STDEV.S(IF((Data!$G$2:$G$241=$B12)*(Data!$H$2:$H$241=$A12)*(Data!$Z$2:$Z$241="Yes"),Data!$AB$2:$AB$241))} | J12: =AVERAGEIFS(Data!$AD$2:$AD$241,Data!$G$2:$G$241,$B12,Data!$H$2:$H$241,$A12,Data!$Z$2:$Z$241,"Yes")
A14: Array formulas (columns G and I): Excel 365 evaluates them with Enter; Excel 2019 or older needs Ctrl+Shift+Enter after editing.
A16: Chart table: mean Dwell time (%) by AOI and commercial
A17: AOI | B17: Balls | C17: Paint
A18: Product_TV | B18: =H5 | C18: =H6
A19: Brand_Logo | B19: =H7 | C19: =H8
A20: Tagline_Text | B20: =H9 | C20: =H10
A21: Hero_Element | B21: =H11 | C21: =H12

Sheet ProductTV
A1: H1. Product_TV Dwell time (%), Balls versus Paint, kept respondents. SIMULATED data.
A2: One row per kept respondent. Columns D and E pull the two dwell shares from the Data sheet with SUMIFS (each respondent has exactly one Product_TV row per commercial). Difference is Paint minus Balls.
A4: Respondent Name | B4: Group (order) | C4: Valid data | D4: Balls Dwell time (%) | E4: Paint Dwell time (%) | F4: Difference (Paint minus Balls) | G4: Paint seen | I4: Statistic | J4: Value | K4: Formula shown | L4: Note
A5: R01 | B5: =INDEX(Data!$E$2:$E$241,MATCH($A5,Data!$B$2:$B$241,0)) | C5: =INDEX(Data!$L$2:$L$241,MATCH($A5,Data!$B$2:$B$241,0)) | D5: =SUMIFS(Data!$AB$2:$AB$241,Data!$B$2:$B$241,$A5,Data!$H$2:$H$241,"Product_TV",Data!$G$2:$G$241,"Commercial_1_Balls") | E5: =SUMIFS(Data!$AB$2:$AB$241,Data!$B$2:$B$241,$A5,Data!$H$2:$H$241,"Product_TV",Data!$G$2:$G$241,"Commercial_2_Paint") | F5: =E5-D5 | G5: =IF(B5="A","second","first") | I5: Paired t test and d_z: Product_TV Dwell time (%)
A6: R02 | B6: =INDEX(Data!$E$2:$E$241,MATCH($A6,Data!$B$2:$B$241,0)) | C6: =INDEX(Data!$L$2:$L$241,MATCH($A6,Data!$B$2:$B$241,0)) | D6: =SUMIFS(Data!$AB$2:$AB$241,Data!$B$2:$B$241,$A6,Data!$H$2:$H$241,"Product_TV",Data!$G$2:$G$241,"Commercial_1_Balls") | E6: =SUMIFS(Data!$AB$2:$AB$241,Data!$B$2:$B$241,$A6,Data!$H$2:$H$241,"Product_TV",Data!$G$2:$G$241,"Commercial_2_Paint") | F6: =E6-D6 | G6: =IF(B6="A","second","first") | I6: Balls mean (%) | J6: =AVERAGE(D5:D33) | K6: =AVERAGE(D5:D33) | L6: AVERAGE of the Balls column
A7: R03 | B7: =INDEX(Data!$E$2:$E$241,MATCH($A7,Data!$B$2:$B$241,0)) | C7: =INDEX(Data!$L$2:$L$241,MATCH($A7,Data!$B$2:$B$241,0)) | D7: =SUMIFS(Data!$AB$2:$AB$241,Data!$B$2:$B$241,$A7,Data!$H$2:$H$241,"Product_TV",Data!$G$2:$G$241,"Commercial_1_Balls") | E7: =SUMIFS(Data!$AB$2:$AB$241,Data!$B$2:$B$241,$A7,Data!$H$2:$H$241,"Product_TV",Data!$G$2:$G$241,"Commercial_2_Paint") | F7: =E7-D7 | G7: =IF(B7="A","second","first") | I7: Balls SD (%) | J7: =_xlfn.STDEV.S(D5:D33) | K7: =STDEV.S(D5:D33) | L7: STDEV.S = sample standard deviation
A8: R04 | B8: =INDEX(Data!$E$2:$E$241,MATCH($A8,Data!$B$2:$B$241,0)) | C8: =INDEX(Data!$L$2:$L$241,MATCH($A8,Data!$B$2:$B$241,0)) | D8: =SUMIFS(Data!$AB$2:$AB$241,Data!$B$2:$B$241,$A8,Data!$H$2:$H$241,"Product_TV",Data!$G$2:$G$241,"Commercial_1_Balls") | E8: =SUMIFS(Data!$AB$2:$AB$241,Data!$B$2:$B$241,$A8,Data!$H$2:$H$241,"Product_TV",Data!$G$2:$G$241,"Commercial_2_Paint") | F8: =E8-D8 | G8: =IF(B8="A","second","first") | I8: Paint mean (%) | J8: =AVERAGE(E5:E33) | K8: =AVERAGE(E5:E33)
A9: R05 | B9: =INDEX(Data!$E$2:$E$241,MATCH($A9,Data!$B$2:$B$241,0)) | C9: =INDEX(Data!$L$2:$L$241,MATCH($A9,Data!$B$2:$B$241,0)) | D9: =SUMIFS(Data!$AB$2:$AB$241,Data!$B$2:$B$241,$A9,Data!$H$2:$H$241,"Product_TV",Data!$G$2:$G$241,"Commercial_1_Balls") | E9: =SUMIFS(Data!$AB$2:$AB$241,Data!$B$2:$B$241,$A9,Data!$H$2:$H$241,"Product_TV",Data!$G$2:$G$241,"Commercial_2_Paint") | F9: =E9-D9 | G9: =IF(B9="A","second","first") | I9: Paint SD (%) | J9: =_xlfn.STDEV.S(E5:E33) | K9: =STDEV.S(E5:E33)
A10: R06 | B10: =INDEX(Data!$E$2:$E$241,MATCH($A10,Data!$B$2:$B$241,0)) | C10: =INDEX(Data!$L$2:$L$241,MATCH($A10,Data!$B$2:$B$241,0)) | D10: =SUMIFS(Data!$AB$2:$AB$241,Data!$B$2:$B$241,$A10,Data!$H$2:$H$241,"Product_TV",Data!$G$2:$G$241,"Commercial_1_Balls") | E10: =SUMIFS(Data!$AB$2:$AB$241,Data!$B$2:$B$241,$A10,Data!$H$2:$H$241,"Product_TV",Data!$G$2:$G$241,"Commercial_2_Paint") | F10: =E10-D10 | G10: =IF(B10="A","second","first") | I10: n pairs | J10: =COUNT(F5:F33) | K10: =COUNT(F5:F33) | L10: COUNT of the difference column; must equal the check row below
A11: R07 | B11: =INDEX(Data!$E$2:$E$241,MATCH($A11,Data!$B$2:$B$241,0)) | C11: =INDEX(Data!$L$2:$L$241,MATCH($A11,Data!$B$2:$B$241,0)) | D11: =SUMIFS(Data!$AB$2:$AB$241,Data!$B$2:$B$241,$A11,Data!$H$2:$H$241,"Product_TV",Data!$G$2:$G$241,"Commercial_1_Balls") | E11: =SUMIFS(Data!$AB$2:$AB$241,Data!$B$2:$B$241,$A11,Data!$H$2:$H$241,"Product_TV",Data!$G$2:$G$241,"Commercial_2_Paint") | F11: =E11-D11 | G11: =IF(B11="A","second","first") | I11: Mean difference, Paint minus Balls (%) | J11: =AVERAGE(F5:F33) | K11: =AVERAGE(F5:F33)
A12: R08 | B12: =INDEX(Data!$E$2:$E$241,MATCH($A12,Data!$B$2:$B$241,0)) | C12: =INDEX(Data!$L$2:$L$241,MATCH($A12,Data!$B$2:$B$241,0)) | D12: =SUMIFS(Data!$AB$2:$AB$241,Data!$B$2:$B$241,$A12,Data!$H$2:$H$241,"Product_TV",Data!$G$2:$G$241,"Commercial_1_Balls") | E12: =SUMIFS(Data!$AB$2:$AB$241,Data!$B$2:$B$241,$A12,Data!$H$2:$H$241,"Product_TV",Data!$G$2:$G$241,"Commercial_2_Paint") | F12: =E12-D12 | G12: =IF(B12="A","second","first") | I12: SD of the differences (%) | J12: =_xlfn.STDEV.S(F5:F33) | K12: =STDEV.S(F5:F33) | L12: the SD that matters in a paired test
A13: R09 | B13: =INDEX(Data!$E$2:$E$241,MATCH($A13,Data!$B$2:$B$241,0)) | C13: =INDEX(Data!$L$2:$L$241,MATCH($A13,Data!$B$2:$B$241,0)) | D13: =SUMIFS(Data!$AB$2:$AB$241,Data!$B$2:$B$241,$A13,Data!$H$2:$H$241,"Product_TV",Data!$G$2:$G$241,"Commercial_1_Balls") | E13: =SUMIFS(Data!$AB$2:$AB$241,Data!$B$2:$B$241,$A13,Data!$H$2:$H$241,"Product_TV",Data!$G$2:$G$241,"Commercial_2_Paint") | F13: =E13-D13 | G13: =IF(B13="A","second","first") | I13: SE of the mean difference | J13: =J12/SQRT(J10) | K13: =J12/SQRT(J10) | L13: SD of differences / sqrt(n)
A14: R10 | B14: =INDEX(Data!$E$2:$E$241,MATCH($A14,Data!$B$2:$B$241,0)) | C14: =INDEX(Data!$L$2:$L$241,MATCH($A14,Data!$B$2:$B$241,0)) | D14: =SUMIFS(Data!$AB$2:$AB$241,Data!$B$2:$B$241,$A14,Data!$H$2:$H$241,"Product_TV",Data!$G$2:$G$241,"Commercial_1_Balls") | E14: =SUMIFS(Data!$AB$2:$AB$241,Data!$B$2:$B$241,$A14,Data!$H$2:$H$241,"Product_TV",Data!$G$2:$G$241,"Commercial_2_Paint") | F14: =E14-D14 | G14: =IF(B14="A","second","first") | I14: Paired t | J14: =J11/J13 | K14: =J11/J13 | L14: t = mean difference / SE
A15: R11 | B15: =INDEX(Data!$E$2:$E$241,MATCH($A15,Data!$B$2:$B$241,0)) | C15: =INDEX(Data!$L$2:$L$241,MATCH($A15,Data!$B$2:$B$241,0)) | D15: =SUMIFS(Data!$AB$2:$AB$241,Data!$B$2:$B$241,$A15,Data!$H$2:$H$241,"Product_TV",Data!$G$2:$G$241,"Commercial_1_Balls") | E15: =SUMIFS(Data!$AB$2:$AB$241,Data!$B$2:$B$241,$A15,Data!$H$2:$H$241,"Product_TV",Data!$G$2:$G$241,"Commercial_2_Paint") | F15: =E15-D15 | G15: =IF(B15="A","second","first") | I15: df | J15: =J10-1 | K15: =J10-1 | L15: n pairs minus 1
A16: R12 | B16: =INDEX(Data!$E$2:$E$241,MATCH($A16,Data!$B$2:$B$241,0)) | C16: =INDEX(Data!$L$2:$L$241,MATCH($A16,Data!$B$2:$B$241,0)) | D16: =SUMIFS(Data!$AB$2:$AB$241,Data!$B$2:$B$241,$A16,Data!$H$2:$H$241,"Product_TV",Data!$G$2:$G$241,"Commercial_1_Balls") | E16: =SUMIFS(Data!$AB$2:$AB$241,Data!$B$2:$B$241,$A16,Data!$H$2:$H$241,"Product_TV",Data!$G$2:$G$241,"Commercial_2_Paint") | F16: =E16-D16 | G16: =IF(B16="A","second","first") | I16: p, two tailed (T.TEST type 1) | J16: =_xlfn.T.TEST(D5:D33,E5:E33,2,1) | K16: =T.TEST(D5:D33,E5:E33,2,1) | L16: tails = 2, type = 1 means paired
A17: R13 | B17: =INDEX(Data!$E$2:$E$241,MATCH($A17,Data!$B$2:$B$241,0)) | C17: =INDEX(Data!$L$2:$L$241,MATCH($A17,Data!$B$2:$B$241,0)) | D17: =SUMIFS(Data!$AB$2:$AB$241,Data!$B$2:$B$241,$A17,Data!$H$2:$H$241,"Product_TV",Data!$G$2:$G$241,"Commercial_1_Balls") | E17: =SUMIFS(Data!$AB$2:$AB$241,Data!$B$2:$B$241,$A17,Data!$H$2:$H$241,"Product_TV",Data!$G$2:$G$241,"Commercial_2_Paint") | F17: =E17-D17 | G17: =IF(B17="A","second","first") | I17: p from the hand computed t | J17: =_xlfn.T.DIST.2T(ABS(J14),J15) | K17: =T.DIST.2T(ABS(J14),J15) | L17: should match the T.TEST cell
A18: R14 | B18: =INDEX(Data!$E$2:$E$241,MATCH($A18,Data!$B$2:$B$241,0)) | C18: =INDEX(Data!$L$2:$L$241,MATCH($A18,Data!$B$2:$B$241,0)) | D18: =SUMIFS(Data!$AB$2:$AB$241,Data!$B$2:$B$241,$A18,Data!$H$2:$H$241,"Product_TV",Data!$G$2:$G$241,"Commercial_1_Balls") | E18: =SUMIFS(Data!$AB$2:$AB$241,Data!$B$2:$B$241,$A18,Data!$H$2:$H$241,"Product_TV",Data!$G$2:$G$241,"Commercial_2_Paint") | F18: =E18-D18 | G18: =IF(B18="A","second","first") | I18: Critical t (95%) | J18: =_xlfn.T.INV.2T(0.05,J15) | K18: =T.INV.2T(0.05,J15) | L18: two tailed, alpha = .05
A19: R15 | B19: =INDEX(Data!$E$2:$E$241,MATCH($A19,Data!$B$2:$B$241,0)) | C19: =INDEX(Data!$L$2:$L$241,MATCH($A19,Data!$B$2:$B$241,0)) | D19: =SUMIFS(Data!$AB$2:$AB$241,Data!$B$2:$B$241,$A19,Data!$H$2:$H$241,"Product_TV",Data!$G$2:$G$241,"Commercial_1_Balls") | E19: =SUMIFS(Data!$AB$2:$AB$241,Data!$B$2:$B$241,$A19,Data!$H$2:$H$241,"Product_TV",Data!$G$2:$G$241,"Commercial_2_Paint") | F19: =E19-D19 | G19: =IF(B19="A","second","first") | I19: Mean difference 95% CI lower | J19: =J11-J18*J13 | K19: =J11-J18*J13
A20: R16 | B20: =INDEX(Data!$E$2:$E$241,MATCH($A20,Data!$B$2:$B$241,0)) | C20: =INDEX(Data!$L$2:$L$241,MATCH($A20,Data!$B$2:$B$241,0)) | D20: =SUMIFS(Data!$AB$2:$AB$241,Data!$B$2:$B$241,$A20,Data!$H$2:$H$241,"Product_TV",Data!$G$2:$G$241,"Commercial_1_Balls") | E20: =SUMIFS(Data!$AB$2:$AB$241,Data!$B$2:$B$241,$A20,Data!$H$2:$H$241,"Product_TV",Data!$G$2:$G$241,"Commercial_2_Paint") | F20: =E20-D20 | G20: =IF(B20="A","second","first") | I20: Mean difference 95% CI upper | J20: =J11+J18*J13 | K20: =J11+J18*J13
A21: R17 | B21: =INDEX(Data!$E$2:$E$241,MATCH($A21,Data!$B$2:$B$241,0)) | C21: =INDEX(Data!$L$2:$L$241,MATCH($A21,Data!$B$2:$B$241,0)) | D21: =SUMIFS(Data!$AB$2:$AB$241,Data!$B$2:$B$241,$A21,Data!$H$2:$H$241,"Product_TV",Data!$G$2:$G$241,"Commercial_1_Balls") | E21: =SUMIFS(Data!$AB$2:$AB$241,Data!$B$2:$B$241,$A21,Data!$H$2:$H$241,"Product_TV",Data!$G$2:$G$241,"Commercial_2_Paint") | F21: =E21-D21 | G21: =IF(B21="A","second","first") | I21: Cohen's d_z | J21: =J11/J12 | K21: =J11/J12 | L21: d_z = mean difference / SD of differences
A22: R18 | B22: =INDEX(Data!$E$2:$E$241,MATCH($A22,Data!$B$2:$B$241,0)) | C22: =INDEX(Data!$L$2:$L$241,MATCH($A22,Data!$B$2:$B$241,0)) | D22: =SUMIFS(Data!$AB$2:$AB$241,Data!$B$2:$B$241,$A22,Data!$H$2:$H$241,"Product_TV",Data!$G$2:$G$241,"Commercial_1_Balls") | E22: =SUMIFS(Data!$AB$2:$AB$241,Data!$B$2:$B$241,$A22,Data!$H$2:$H$241,"Product_TV",Data!$G$2:$G$241,"Commercial_2_Paint") | F22: =E22-D22 | G22: =IF(B22="A","second","first") | I22: SE of d_z (approximation) | J22: =SQRT(1/J10+J21^2/(2*J10)) | K22: =SQRT(1/J10+J21^2/(2*J10)) | L22: sqrt(1/n + d_z^2 / (2 n))
A23: R19 | B23: =INDEX(Data!$E$2:$E$241,MATCH($A23,Data!$B$2:$B$241,0)) | C23: =INDEX(Data!$L$2:$L$241,MATCH($A23,Data!$B$2:$B$241,0)) | D23: =SUMIFS(Data!$AB$2:$AB$241,Data!$B$2:$B$241,$A23,Data!$H$2:$H$241,"Product_TV",Data!$G$2:$G$241,"Commercial_1_Balls") | E23: =SUMIFS(Data!$AB$2:$AB$241,Data!$B$2:$B$241,$A23,Data!$H$2:$H$241,"Product_TV",Data!$G$2:$G$241,"Commercial_2_Paint") | F23: =E23-D23 | G23: =IF(B23="A","second","first") | I23: d_z 95% CI lower | J23: =J21-1.96*J22 | K23: =J21-1.96*J22 | L23: large sample approximation; R uses the noncentral t interval
A24: R20 | B24: =INDEX(Data!$E$2:$E$241,MATCH($A24,Data!$B$2:$B$241,0)) | C24: =INDEX(Data!$L$2:$L$241,MATCH($A24,Data!$B$2:$B$241,0)) | D24: =SUMIFS(Data!$AB$2:$AB$241,Data!$B$2:$B$241,$A24,Data!$H$2:$H$241,"Product_TV",Data!$G$2:$G$241,"Commercial_1_Balls") | E24: =SUMIFS(Data!$AB$2:$AB$241,Data!$B$2:$B$241,$A24,Data!$H$2:$H$241,"Product_TV",Data!$G$2:$G$241,"Commercial_2_Paint") | F24: =E24-D24 | G24: =IF(B24="A","second","first") | I24: d_z 95% CI upper | J24: =J21+1.96*J22 | K24: =J21+1.96*J22
A25: R21 | B25: =INDEX(Data!$E$2:$E$241,MATCH($A25,Data!$B$2:$B$241,0)) | C25: =INDEX(Data!$L$2:$L$241,MATCH($A25,Data!$B$2:$B$241,0)) | D25: =SUMIFS(Data!$AB$2:$AB$241,Data!$B$2:$B$241,$A25,Data!$H$2:$H$241,"Product_TV",Data!$G$2:$G$241,"Commercial_1_Balls") | E25: =SUMIFS(Data!$AB$2:$AB$241,Data!$B$2:$B$241,$A25,Data!$H$2:$H$241,"Product_TV",Data!$G$2:$G$241,"Commercial_2_Paint") | F25: =E25-D25 | G25: =IF(B25="A","second","first") | I25: Correlation of the two columns | J25: =CORREL(D5:D33,E5:E33) | K25: =CORREL(D5:D33,E5:E33) | L25: within respondent correlation
A26: R22 | B26: =INDEX(Data!$E$2:$E$241,MATCH($A26,Data!$B$2:$B$241,0)) | C26: =INDEX(Data!$L$2:$L$241,MATCH($A26,Data!$B$2:$B$241,0)) | D26: =SUMIFS(Data!$AB$2:$AB$241,Data!$B$2:$B$241,$A26,Data!$H$2:$H$241,"Product_TV",Data!$G$2:$G$241,"Commercial_1_Balls") | E26: =SUMIFS(Data!$AB$2:$AB$241,Data!$B$2:$B$241,$A26,Data!$H$2:$H$241,"Product_TV",Data!$G$2:$G$241,"Commercial_2_Paint") | F26: =E26-D26 | G26: =IF(B26="A","second","first")
A27: R24 | B27: =INDEX(Data!$E$2:$E$241,MATCH($A27,Data!$B$2:$B$241,0)) | C27: =INDEX(Data!$L$2:$L$241,MATCH($A27,Data!$B$2:$B$241,0)) | D27: =SUMIFS(Data!$AB$2:$AB$241,Data!$B$2:$B$241,$A27,Data!$H$2:$H$241,"Product_TV",Data!$G$2:$G$241,"Commercial_1_Balls") | E27: =SUMIFS(Data!$AB$2:$AB$241,Data!$B$2:$B$241,$A27,Data!$H$2:$H$241,"Product_TV",Data!$G$2:$G$241,"Commercial_2_Paint") | F27: =E27-D27 | G27: =IF(B27="A","second","first") | I27: Order effect (simple within respondent estimate)
A28: R25 | B28: =INDEX(Data!$E$2:$E$241,MATCH($A28,Data!$B$2:$B$241,0)) | C28: =INDEX(Data!$L$2:$L$241,MATCH($A28,Data!$B$2:$B$241,0)) | D28: =SUMIFS(Data!$AB$2:$AB$241,Data!$B$2:$B$241,$A28,Data!$H$2:$H$241,"Product_TV",Data!$G$2:$G$241,"Commercial_1_Balls") | E28: =SUMIFS(Data!$AB$2:$AB$241,Data!$B$2:$B$241,$A28,Data!$H$2:$H$241,"Product_TV",Data!$G$2:$G$241,"Commercial_2_Paint") | F28: =E28-D28 | G28: =IF(B28="A","second","first") | I28: Mean difference, Group A (Paint seen second) | J28: =AVERAGEIFS(F5:F33,B5:B33,"A") | K28: =AVERAGEIFS(F5:F33,B5:B33,"A") | L28: difference = commercial effect + order effect
A29: R26 | B29: =INDEX(Data!$E$2:$E$241,MATCH($A29,Data!$B$2:$B$241,0)) | C29: =INDEX(Data!$L$2:$L$241,MATCH($A29,Data!$B$2:$B$241,0)) | D29: =SUMIFS(Data!$AB$2:$AB$241,Data!$B$2:$B$241,$A29,Data!$H$2:$H$241,"Product_TV",Data!$G$2:$G$241,"Commercial_1_Balls") | E29: =SUMIFS(Data!$AB$2:$AB$241,Data!$B$2:$B$241,$A29,Data!$H$2:$H$241,"Product_TV",Data!$G$2:$G$241,"Commercial_2_Paint") | F29: =E29-D29 | G29: =IF(B29="A","second","first") | I29: Mean difference, Group B (Paint seen first) | J29: =AVERAGEIFS(F5:F33,B5:B33,"B") | K29: =AVERAGEIFS(F5:F33,B5:B33,"B") | L29: difference = commercial effect - order effect
A30: R27 | B30: =INDEX(Data!$E$2:$E$241,MATCH($A30,Data!$B$2:$B$241,0)) | C30: =INDEX(Data!$L$2:$L$241,MATCH($A30,Data!$B$2:$B$241,0)) | D30: =SUMIFS(Data!$AB$2:$AB$241,Data!$B$2:$B$241,$A30,Data!$H$2:$H$241,"Product_TV",Data!$G$2:$G$241,"Commercial_1_Balls") | E30: =SUMIFS(Data!$AB$2:$AB$241,Data!$B$2:$B$241,$A30,Data!$H$2:$H$241,"Product_TV",Data!$G$2:$G$241,"Commercial_2_Paint") | F30: =E30-D30 | G30: =IF(B30="A","second","first") | I30: n, Group A | J30: =COUNTIF(B5:B33,"A") | K30: =COUNTIF(B5:B33,"A")
A31: R28 | B31: =INDEX(Data!$E$2:$E$241,MATCH($A31,Data!$B$2:$B$241,0)) | C31: =INDEX(Data!$L$2:$L$241,MATCH($A31,Data!$B$2:$B$241,0)) | D31: =SUMIFS(Data!$AB$2:$AB$241,Data!$B$2:$B$241,$A31,Data!$H$2:$H$241,"Product_TV",Data!$G$2:$G$241,"Commercial_1_Balls") | E31: =SUMIFS(Data!$AB$2:$AB$241,Data!$B$2:$B$241,$A31,Data!$H$2:$H$241,"Product_TV",Data!$G$2:$G$241,"Commercial_2_Paint") | F31: =E31-D31 | G31: =IF(B31="A","second","first") | I31: n, Group B | J31: =COUNTIF(B5:B33,"B") | K31: =COUNTIF(B5:B33,"B")
A32: R29 | B32: =INDEX(Data!$E$2:$E$241,MATCH($A32,Data!$B$2:$B$241,0)) | C32: =INDEX(Data!$L$2:$L$241,MATCH($A32,Data!$B$2:$B$241,0)) | D32: =SUMIFS(Data!$AB$2:$AB$241,Data!$B$2:$B$241,$A32,Data!$H$2:$H$241,"Product_TV",Data!$G$2:$G$241,"Commercial_1_Balls") | E32: =SUMIFS(Data!$AB$2:$AB$241,Data!$B$2:$B$241,$A32,Data!$H$2:$H$241,"Product_TV",Data!$G$2:$G$241,"Commercial_2_Paint") | F32: =E32-D32 | G32: =IF(B32="A","second","first") | I32: Order effect (second minus first) | J32: =(J28-J29)/2 | K32: =(J28-J29)/2 | L32: same as the lmer coefficient for order_position here; Excel cannot fit the mixed model
A33: R30 | B33: =INDEX(Data!$E$2:$E$241,MATCH($A33,Data!$B$2:$B$241,0)) | C33: =INDEX(Data!$L$2:$L$241,MATCH($A33,Data!$B$2:$B$241,0)) | D33: =SUMIFS(Data!$AB$2:$AB$241,Data!$B$2:$B$241,$A33,Data!$H$2:$H$241,"Product_TV",Data!$G$2:$G$241,"Commercial_1_Balls") | E33: =SUMIFS(Data!$AB$2:$AB$241,Data!$B$2:$B$241,$A33,Data!$H$2:$H$241,"Product_TV",Data!$G$2:$G$241,"Commercial_2_Paint") | F33: =E33-D33 | G33: =IF(B33="A","second","first") | I33: Commercial effect (Paint minus Balls), order adjusted | J33: =(J28+J29)/2 | K33: =(J28+J29)/2 | L33: average of the two group differences
I35: Checks
I36: Kept respondents with a Product_TV row for Balls in Data | J36: =COUNTIFS(Data!$G$2:$G$241,"Commercial_1_Balls",Data!$H$2:$H$241,"Product_TV",Data!$Z$2:$Z$241,"Yes") | K36: =COUNTIFS(Data!$G$2:$G$241,"Commercial_1_Balls",Data!$H$2:$H$241,"Product_TV",Data!$Z$2:$Z$241,"Yes") | L36: must equal n pairs; if not, the roster in column A is out of date
I37: Smallest Valid data in column C | J37: =MIN(C5:C33) | K37: =MIN(C5:C33) | L37: must be at least 70
I40: Chart table: mean dwell share with 95% CI half width
I41: Commercial | J41: Mean dwell (%) | K41: CI half width
I42: Balls | J42: =J6 | K42: =_xlfn.CONFIDENCE.T(0.05,J7,J10)
I43: Paint | J43: =J8 | K43: =_xlfn.CONFIDENCE.T(0.05,J9,J10)

Sheet BrandLogo
A1: H2. Brand_Logo TTFF AOI (ms), Balls versus Paint, respondents with a TTFF in both commercials. SIMULATED data.
A2: A respondent who never fixated the logo has NA, which cannot enter a paired test, so the roster below lists only kept respondents with a number in BOTH commercials. TTFF AOI counts from the start of the end card. Difference is Paint minus Balls.
A4: Respondent Name | B4: Group (order) | C4: Balls TTFF AOI (ms) | D4: Paint TTFF AOI (ms) | E4: Difference (Paint minus Balls) | G4: Statistic | H4: Value | I4: Formula shown | J4: Note
A5: R01 | B5: =INDEX(Data!$E$2:$E$241,MATCH($A5,Data!$B$2:$B$241,0)) | C5: =SUMIFS(Data!$S$2:$S$241,Data!$B$2:$B$241,$A5,Data!$H$2:$H$241,"Brand_Logo",Data!$G$2:$G$241,"Commercial_1_Balls") | D5: =SUMIFS(Data!$S$2:$S$241,Data!$B$2:$B$241,$A5,Data!$H$2:$H$241,"Brand_Logo",Data!$G$2:$G$241,"Commercial_2_Paint") | E5: =D5-C5 | G5: Paired t test and d_z: Brand_Logo TTFF AOI (ms)
A6: R02 | B6: =INDEX(Data!$E$2:$E$241,MATCH($A6,Data!$B$2:$B$241,0)) | C6: =SUMIFS(Data!$S$2:$S$241,Data!$B$2:$B$241,$A6,Data!$H$2:$H$241,"Brand_Logo",Data!$G$2:$G$241,"Commercial_1_Balls") | D6: =SUMIFS(Data!$S$2:$S$241,Data!$B$2:$B$241,$A6,Data!$H$2:$H$241,"Brand_Logo",Data!$G$2:$G$241,"Commercial_2_Paint") | E6: =D6-C6 | G6: Balls mean (ms) | H6: =AVERAGE(C5:C29) | I6: =AVERAGE(C5:C29) | J6: AVERAGE of the Balls column
A7: R03 | B7: =INDEX(Data!$E$2:$E$241,MATCH($A7,Data!$B$2:$B$241,0)) | C7: =SUMIFS(Data!$S$2:$S$241,Data!$B$2:$B$241,$A7,Data!$H$2:$H$241,"Brand_Logo",Data!$G$2:$G$241,"Commercial_1_Balls") | D7: =SUMIFS(Data!$S$2:$S$241,Data!$B$2:$B$241,$A7,Data!$H$2:$H$241,"Brand_Logo",Data!$G$2:$G$241,"Commercial_2_Paint") | E7: =D7-C7 | G7: Balls SD (ms) | H7: =_xlfn.STDEV.S(C5:C29) | I7: =STDEV.S(C5:C29) | J7: STDEV.S = sample standard deviation
A8: R04 | B8: =INDEX(Data!$E$2:$E$241,MATCH($A8,Data!$B$2:$B$241,0)) | C8: =SUMIFS(Data!$S$2:$S$241,Data!$B$2:$B$241,$A8,Data!$H$2:$H$241,"Brand_Logo",Data!$G$2:$G$241,"Commercial_1_Balls") | D8: =SUMIFS(Data!$S$2:$S$241,Data!$B$2:$B$241,$A8,Data!$H$2:$H$241,"Brand_Logo",Data!$G$2:$G$241,"Commercial_2_Paint") | E8: =D8-C8 | G8: Paint mean (ms) | H8: =AVERAGE(D5:D29) | I8: =AVERAGE(D5:D29)
A9: R05 | B9: =INDEX(Data!$E$2:$E$241,MATCH($A9,Data!$B$2:$B$241,0)) | C9: =SUMIFS(Data!$S$2:$S$241,Data!$B$2:$B$241,$A9,Data!$H$2:$H$241,"Brand_Logo",Data!$G$2:$G$241,"Commercial_1_Balls") | D9: =SUMIFS(Data!$S$2:$S$241,Data!$B$2:$B$241,$A9,Data!$H$2:$H$241,"Brand_Logo",Data!$G$2:$G$241,"Commercial_2_Paint") | E9: =D9-C9 | G9: Paint SD (ms) | H9: =_xlfn.STDEV.S(D5:D29) | I9: =STDEV.S(D5:D29)
A10: R06 | B10: =INDEX(Data!$E$2:$E$241,MATCH($A10,Data!$B$2:$B$241,0)) | C10: =SUMIFS(Data!$S$2:$S$241,Data!$B$2:$B$241,$A10,Data!$H$2:$H$241,"Brand_Logo",Data!$G$2:$G$241,"Commercial_1_Balls") | D10: =SUMIFS(Data!$S$2:$S$241,Data!$B$2:$B$241,$A10,Data!$H$2:$H$241,"Brand_Logo",Data!$G$2:$G$241,"Commercial_2_Paint") | E10: =D10-C10 | G10: n pairs | H10: =COUNT(E5:E29) | I10: =COUNT(E5:E29) | J10: pairs only: respondents with a TTFF in both commercials
A11: R07 | B11: =INDEX(Data!$E$2:$E$241,MATCH($A11,Data!$B$2:$B$241,0)) | C11: =SUMIFS(Data!$S$2:$S$241,Data!$B$2:$B$241,$A11,Data!$H$2:$H$241,"Brand_Logo",Data!$G$2:$G$241,"Commercial_1_Balls") | D11: =SUMIFS(Data!$S$2:$S$241,Data!$B$2:$B$241,$A11,Data!$H$2:$H$241,"Brand_Logo",Data!$G$2:$G$241,"Commercial_2_Paint") | E11: =D11-C11 | G11: Mean difference, Paint minus Balls (ms) | H11: =AVERAGE(E5:E29) | I11: =AVERAGE(E5:E29)
A12: R08 | B12: =INDEX(Data!$E$2:$E$241,MATCH($A12,Data!$B$2:$B$241,0)) | C12: =SUMIFS(Data!$S$2:$S$241,Data!$B$2:$B$241,$A12,Data!$H$2:$H$241,"Brand_Logo",Data!$G$2:$G$241,"Commercial_1_Balls") | D12: =SUMIFS(Data!$S$2:$S$241,Data!$B$2:$B$241,$A12,Data!$H$2:$H$241,"Brand_Logo",Data!$G$2:$G$241,"Commercial_2_Paint") | E12: =D12-C12 | G12: SD of the differences (ms) | H12: =_xlfn.STDEV.S(E5:E29) | I12: =STDEV.S(E5:E29) | J12: the SD that matters in a paired test
A13: R11 | B13: =INDEX(Data!$E$2:$E$241,MATCH($A13,Data!$B$2:$B$241,0)) | C13: =SUMIFS(Data!$S$2:$S$241,Data!$B$2:$B$241,$A13,Data!$H$2:$H$241,"Brand_Logo",Data!$G$2:$G$241,"Commercial_1_Balls") | D13: =SUMIFS(Data!$S$2:$S$241,Data!$B$2:$B$241,$A13,Data!$H$2:$H$241,"Brand_Logo",Data!$G$2:$G$241,"Commercial_2_Paint") | E13: =D13-C13 | G13: SE of the mean difference | H13: =H12/SQRT(H10) | I13: =H12/SQRT(H10) | J13: SD of differences / sqrt(n)
A14: R12 | B14: =INDEX(Data!$E$2:$E$241,MATCH($A14,Data!$B$2:$B$241,0)) | C14: =SUMIFS(Data!$S$2:$S$241,Data!$B$2:$B$241,$A14,Data!$H$2:$H$241,"Brand_Logo",Data!$G$2:$G$241,"Commercial_1_Balls") | D14: =SUMIFS(Data!$S$2:$S$241,Data!$B$2:$B$241,$A14,Data!$H$2:$H$241,"Brand_Logo",Data!$G$2:$G$241,"Commercial_2_Paint") | E14: =D14-C14 | G14: Paired t | H14: =H11/H13 | I14: =H11/H13 | J14: t = mean difference / SE
A15: R13 | B15: =INDEX(Data!$E$2:$E$241,MATCH($A15,Data!$B$2:$B$241,0)) | C15: =SUMIFS(Data!$S$2:$S$241,Data!$B$2:$B$241,$A15,Data!$H$2:$H$241,"Brand_Logo",Data!$G$2:$G$241,"Commercial_1_Balls") | D15: =SUMIFS(Data!$S$2:$S$241,Data!$B$2:$B$241,$A15,Data!$H$2:$H$241,"Brand_Logo",Data!$G$2:$G$241,"Commercial_2_Paint") | E15: =D15-C15 | G15: df | H15: =H10-1 | I15: =H10-1 | J15: n pairs minus 1
A16: R14 | B16: =INDEX(Data!$E$2:$E$241,MATCH($A16,Data!$B$2:$B$241,0)) | C16: =SUMIFS(Data!$S$2:$S$241,Data!$B$2:$B$241,$A16,Data!$H$2:$H$241,"Brand_Logo",Data!$G$2:$G$241,"Commercial_1_Balls") | D16: =SUMIFS(Data!$S$2:$S$241,Data!$B$2:$B$241,$A16,Data!$H$2:$H$241,"Brand_Logo",Data!$G$2:$G$241,"Commercial_2_Paint") | E16: =D16-C16 | G16: p, two tailed (T.TEST type 1) | H16: =_xlfn.T.TEST(C5:C29,D5:D29,2,1) | I16: =T.TEST(C5:C29,D5:D29,2,1) | J16: tails = 2, type = 1 means paired
A17: R15 | B17: =INDEX(Data!$E$2:$E$241,MATCH($A17,Data!$B$2:$B$241,0)) | C17: =SUMIFS(Data!$S$2:$S$241,Data!$B$2:$B$241,$A17,Data!$H$2:$H$241,"Brand_Logo",Data!$G$2:$G$241,"Commercial_1_Balls") | D17: =SUMIFS(Data!$S$2:$S$241,Data!$B$2:$B$241,$A17,Data!$H$2:$H$241,"Brand_Logo",Data!$G$2:$G$241,"Commercial_2_Paint") | E17: =D17-C17 | G17: p from the hand computed t | H17: =_xlfn.T.DIST.2T(ABS(H14),H15) | I17: =T.DIST.2T(ABS(H14),H15) | J17: should match the T.TEST cell
A18: R16 | B18: =INDEX(Data!$E$2:$E$241,MATCH($A18,Data!$B$2:$B$241,0)) | C18: =SUMIFS(Data!$S$2:$S$241,Data!$B$2:$B$241,$A18,Data!$H$2:$H$241,"Brand_Logo",Data!$G$2:$G$241,"Commercial_1_Balls") | D18: =SUMIFS(Data!$S$2:$S$241,Data!$B$2:$B$241,$A18,Data!$H$2:$H$241,"Brand_Logo",Data!$G$2:$G$241,"Commercial_2_Paint") | E18: =D18-C18 | G18: Critical t (95%) | H18: =_xlfn.T.INV.2T(0.05,H15) | I18: =T.INV.2T(0.05,H15) | J18: two tailed, alpha = .05
A19: R17 | B19: =INDEX(Data!$E$2:$E$241,MATCH($A19,Data!$B$2:$B$241,0)) | C19: =SUMIFS(Data!$S$2:$S$241,Data!$B$2:$B$241,$A19,Data!$H$2:$H$241,"Brand_Logo",Data!$G$2:$G$241,"Commercial_1_Balls") | D19: =SUMIFS(Data!$S$2:$S$241,Data!$B$2:$B$241,$A19,Data!$H$2:$H$241,"Brand_Logo",Data!$G$2:$G$241,"Commercial_2_Paint") | E19: =D19-C19 | G19: Mean difference 95% CI lower | H19: =H11-H18*H13 | I19: =H11-H18*H13
A20: R18 | B20: =INDEX(Data!$E$2:$E$241,MATCH($A20,Data!$B$2:$B$241,0)) | C20: =SUMIFS(Data!$S$2:$S$241,Data!$B$2:$B$241,$A20,Data!$H$2:$H$241,"Brand_Logo",Data!$G$2:$G$241,"Commercial_1_Balls") | D20: =SUMIFS(Data!$S$2:$S$241,Data!$B$2:$B$241,$A20,Data!$H$2:$H$241,"Brand_Logo",Data!$G$2:$G$241,"Commercial_2_Paint") | E20: =D20-C20 | G20: Mean difference 95% CI upper | H20: =H11+H18*H13 | I20: =H11+H18*H13
A21: R19 | B21: =INDEX(Data!$E$2:$E$241,MATCH($A21,Data!$B$2:$B$241,0)) | C21: =SUMIFS(Data!$S$2:$S$241,Data!$B$2:$B$241,$A21,Data!$H$2:$H$241,"Brand_Logo",Data!$G$2:$G$241,"Commercial_1_Balls") | D21: =SUMIFS(Data!$S$2:$S$241,Data!$B$2:$B$241,$A21,Data!$H$2:$H$241,"Brand_Logo",Data!$G$2:$G$241,"Commercial_2_Paint") | E21: =D21-C21 | G21: Cohen's d_z | H21: =H11/H12 | I21: =H11/H12 | J21: d_z = mean difference / SD of differences
A22: R20 | B22: =INDEX(Data!$E$2:$E$241,MATCH($A22,Data!$B$2:$B$241,0)) | C22: =SUMIFS(Data!$S$2:$S$241,Data!$B$2:$B$241,$A22,Data!$H$2:$H$241,"Brand_Logo",Data!$G$2:$G$241,"Commercial_1_Balls") | D22: =SUMIFS(Data!$S$2:$S$241,Data!$B$2:$B$241,$A22,Data!$H$2:$H$241,"Brand_Logo",Data!$G$2:$G$241,"Commercial_2_Paint") | E22: =D22-C22 | G22: SE of d_z (approximation) | H22: =SQRT(1/H10+H21^2/(2*H10)) | I22: =SQRT(1/H10+H21^2/(2*H10)) | J22: sqrt(1/n + d_z^2 / (2 n))
A23: R21 | B23: =INDEX(Data!$E$2:$E$241,MATCH($A23,Data!$B$2:$B$241,0)) | C23: =SUMIFS(Data!$S$2:$S$241,Data!$B$2:$B$241,$A23,Data!$H$2:$H$241,"Brand_Logo",Data!$G$2:$G$241,"Commercial_1_Balls") | D23: =SUMIFS(Data!$S$2:$S$241,Data!$B$2:$B$241,$A23,Data!$H$2:$H$241,"Brand_Logo",Data!$G$2:$G$241,"Commercial_2_Paint") | E23: =D23-C23 | G23: d_z 95% CI lower | H23: =H21-1.96*H22 | I23: =H21-1.96*H22 | J23: large sample approximation; R uses the noncentral t interval
A24: R22 | B24: =INDEX(Data!$E$2:$E$241,MATCH($A24,Data!$B$2:$B$241,0)) | C24: =SUMIFS(Data!$S$2:$S$241,Data!$B$2:$B$241,$A24,Data!$H$2:$H$241,"Brand_Logo",Data!$G$2:$G$241,"Commercial_1_Balls") | D24: =SUMIFS(Data!$S$2:$S$241,Data!$B$2:$B$241,$A24,Data!$H$2:$H$241,"Brand_Logo",Data!$G$2:$G$241,"Commercial_2_Paint") | E24: =D24-C24 | G24: d_z 95% CI upper | H24: =H21+1.96*H22 | I24: =H21+1.96*H22
A25: R24 | B25: =INDEX(Data!$E$2:$E$241,MATCH($A25,Data!$B$2:$B$241,0)) | C25: =SUMIFS(Data!$S$2:$S$241,Data!$B$2:$B$241,$A25,Data!$H$2:$H$241,"Brand_Logo",Data!$G$2:$G$241,"Commercial_1_Balls") | D25: =SUMIFS(Data!$S$2:$S$241,Data!$B$2:$B$241,$A25,Data!$H$2:$H$241,"Brand_Logo",Data!$G$2:$G$241,"Commercial_2_Paint") | E25: =D25-C25 | G25: Correlation of the two columns | H25: =CORREL(C5:C29,D5:D29) | I25: =CORREL(C5:C29,D5:D29) | J25: within respondent correlation
A26: R25 | B26: =INDEX(Data!$E$2:$E$241,MATCH($A26,Data!$B$2:$B$241,0)) | C26: =SUMIFS(Data!$S$2:$S$241,Data!$B$2:$B$241,$A26,Data!$H$2:$H$241,"Brand_Logo",Data!$G$2:$G$241,"Commercial_1_Balls") | D26: =SUMIFS(Data!$S$2:$S$241,Data!$B$2:$B$241,$A26,Data!$H$2:$H$241,"Brand_Logo",Data!$G$2:$G$241,"Commercial_2_Paint") | E26: =D26-C26
A27: R26 | B27: =INDEX(Data!$E$2:$E$241,MATCH($A27,Data!$B$2:$B$241,0)) | C27: =SUMIFS(Data!$S$2:$S$241,Data!$B$2:$B$241,$A27,Data!$H$2:$H$241,"Brand_Logo",Data!$G$2:$G$241,"Commercial_1_Balls") | D27: =SUMIFS(Data!$S$2:$S$241,Data!$B$2:$B$241,$A27,Data!$H$2:$H$241,"Brand_Logo",Data!$G$2:$G$241,"Commercial_2_Paint") | E27: =D27-C27 | G27: Respondent ratio (kept respondents who fixated the logo)
A28: R28 | B28: =INDEX(Data!$E$2:$E$241,MATCH($A28,Data!$B$2:$B$241,0)) | C28: =SUMIFS(Data!$S$2:$S$241,Data!$B$2:$B$241,$A28,Data!$H$2:$H$241,"Brand_Logo",Data!$G$2:$G$241,"Commercial_1_Balls") | D28: =SUMIFS(Data!$S$2:$S$241,Data!$B$2:$B$241,$A28,Data!$H$2:$H$241,"Brand_Logo",Data!$G$2:$G$241,"Commercial_2_Paint") | E28: =D28-C28 | G28: Kept respondents with a Brand_Logo row, Balls | H28: =COUNTIFS(Data!$H$2:$H$241,"Brand_Logo",Data!$Z$2:$Z$241,"Yes",Data!$G$2:$G$241,"Commercial_1_Balls") | I28: =COUNTIFS(Data!$H$2:$H$241,"Brand_Logo",Data!$Z$2:$Z$241,"Yes",Data!$G$2:$G$241,"Commercial_1_Balls")
