Workbook

Sheet README
A1: Pilot GSR and heart rate workbook (REAL data, shared with permission)
A3: Source: 001_PILOT01.csv, the Sensor Data export of the Workshop 4 pilot recorded on the lab computer on October 12, 2026 (iMotions Lab 11.1.47136.14, study "W4 Pilot - Shimmer test").
A4: The respondent is the lab director, who agreed to share his own recording as practice data. A real participant's export is identifiable data and is never published.
A5: One respondent: every number here DESCRIBES a recording. Nothing is tested.
A7: Sheets
A8: Rules: the artifact rule of Kleckner et al. (2018). Blue cells are inputs you may change to see what happens.
A9: Stimuli: start and end of each stimulus (StartMedia and EndMedia rows of the export, in ms since the recording started).
A10: Shimmer: the 13,426 Shimmer rows (EventSource for the Shimmer = 1). Columns A to G are copied from the export; H to K are formulas.
A11: Peaks: the 14 peaks GSR Peak Detection found, located with formulas, and whether each falls inside the artifact margin.
A12: Summary: peaks, Peaks Per Minute, mean tonic level, and mean heart rate per stimulus, all as formulas.
A13: Check: the workbook against the output of pilot_analysis.R. Every row should read OK.
A14: iMotions_Check: the workbook against iMotions' own GSR Metrics export (GSRPeakMetrics.csv). Every row should read OK.
... A24: Legend: blue text = input value copied from the export or chosen by you; black text = formula.

Sheet Rules
A1: Rule | B1: Value | C1: Unit | D1: Source
A2: Minimum valid conductance | B2: 0.05 | C2: microsiemens | D2: Kleckner et al. (2018), Table I
A3: Maximum valid conductance | B3: 60 | C3: microsiemens | D3: Kleckner et al. (2018), Table I
A4: Maximum rate of change | B4: 10 | C4: microsiemens per second | D4: Kleckner et al. (2018), Table I
A5: Margin around invalid data | B5: 5000 | C5: milliseconds | D5: Kleckner et al. (2018), Table I (5 s)

Sheet Stimuli
A1: Stimulus | B1: Start_ms | C1: End_ms | D1: Length_s
A2: 01 Quiet baseline (60s) | B2: 173.442 | C2: 60183.422 | D2: =(C2-B2)/1000 -> 60.00998
A3: 02 e.l.f. - Power Grip Styling (30.03s) | B3: 60221.093 | C3: 90293.936 | D3: =(C3-B3)/1000 -> 30.072844
A4: 03 Quiet recovery (15s) | B4: 90363.459 | C4: 105374.05 | D4: =(C4-B4)/1000 -> 15.010595

Sheet Shimmer
A1: Timestamp_ms | B1: GSR_Conductance_uS | C1: Heart_Rate_bpm | D1: IBI_ms | E1: Tonic_uS | F1: Peak_Occurrence | G1: Peak_Amplitude_uS | H1: Stimulus | I1: Rate_uS_per_s | J1: Breaks_rule | K1: Peak_number
A2: 151.9305 | B2: 1.6432234 | C2: 81 | D2: -1 | E2: 1.640293 | F2: 0 | G2: 0 | H2: =IF(AND(A2>=Stimuli!$B$2,A2<=Stimuli!$C$2),Stimuli!$A$2,IF(AND(A2>=Stimuli!$B$3,A2<=Stimuli!$C$3),Stimuli!$A$3,IF(AND(A2>=Stimuli!$B$4,A2<=Stimuli!$C$4),Stimuli!$A$4,""))) | J2: =IF(OR(B2<Rules!$B$2,B2>Rules!$B$3,FALSE(),OR(B3<Rules!$B$2,B3>Rules!$B$3,ABS(I3)>Rules!$B$4)),1,0) -> 0 | K2: =IF(F2=1,COUNTIF($F$2:F2,1),"")
A3: 159.743 | B3: 1.6373626 | C3: 81 | D3: -1 | E3: 1.640293 | F3: 0 | G3: 0 | H3: =IF(AND(A3>=Stimuli!$B$2,A3<=Stimuli!$C$2),Stimuli!$A$2,IF(AND(A3>=Stimuli!$B$3,A3<=Stimuli!$C$3),Stimuli!$A$3,IF(AND(A3>=Stimuli!$B$4,A3<=Stimuli!$C$4),Stimuli!$A$4,""))) | I3: =(B3-B2)/((A3-A2)/1000) -> -0.75018315 | J3: =IF(OR(B3<Rules!$B$2,B3>Rules!$B$3,ABS(I3)>Rules!$B$4,OR(B4<Rules!$B$2,B4>Rules!$B$3,ABS(I4)>Rules!$B$4)),1,0) -> 0 | K3: =IF(F3=1,COUNTIF($F$2:F3,1),"")
A4: 167.5555 | B4: 1.6432234 | C4: 81 | D4: -1 | E4: 1.640293 | F4: 0 | G4: 0 | H4: =IF(AND(A4>=Stimuli!$B$2,A4<=Stimuli!$C$2),Stimuli!$A$2,IF(AND(A4>=Stimuli!$B$3,A4<=Stimuli!$C$3),Stimuli!$A$3,IF(AND(A4>=Stimuli!$B$4,A4<=Stimuli!$C$4),Stimuli!$A$4,""))) | I4: =(B4-B3)/((A4-A3)/1000) -> 0.75018315 | J4: =IF(OR(B4<Rules!$B$2,B4>Rules!$B$3,ABS(I4)>Rules!$B$4,OR(B5<Rules!$B$2,B5>Rules!$B$3,ABS(I5)>Rules!$B$4)),1,0) -> 0 | K4: =IF(F4=1,COUNTIF($F$2:F4,1),"")
A5: 175.368 | B5: 1.6388278 | C5: 81 | D5: -1 | E5: 1.640293 | F5: 0 | G5: 0 | H5: =IF(AND(A5>=Stimuli!$B$2,A5<=Stimuli!$C$2),Stimuli!$A$2,IF(AND(A5>=Stimuli!$B$3,A5<=Stimuli!$C$3),Stimuli!$A$3,IF(AND(A5>=Stimuli!$B$4,A5<=Stimuli!$C$4),Stimuli!$A$4,""))) -> 01 Quiet baseline (60s) | I5: =(B5-B4)/((A5-A4)/1000) -> -0.56263736 | J5: =IF(OR(B5<Rules!$B$2,B5>Rules!$B$3,ABS(I5)>Rules!$B$4,OR(B6<Rules!$B$2,B6>Rules!$B$3,ABS(I6)>Rules!$B$4)),1,0) -> 0 | K5: =IF(F5=1,COUNTIF($F$2:F5,1),"")
A6: 183.1805 | B6: 1.6417582 | C6: 81 | D6: -1 | E6: 1.640293 | F6: 0 | G6: 0 | H6: =IF(AND(A6>=Stimuli!$B$2,A6<=Stimuli!$C$2),Stimuli!$A$2,IF(AND(A6>=Stimuli!$B$3,A6<=Stimuli!$C$3),Stimuli!$A$3,IF(AND(A6>=Stimuli!$B$4,A6<=Stimuli!$C$4),Stimuli!$A$4,""))) -> 01 Quiet baseline (60s) | I6: =(B6-B5)/((A6-A5)/1000) -> 0.37509158 | J6: =IF(OR(B6<Rules!$B$2,B6>Rules!$B$3,ABS(I6)>Rules!$B$4,OR(B7<Rules!$B$2,B7>Rules!$B$3,ABS(I7)>Rules!$B$4)),1,0) -> 0 | K6: =IF(F6=1,COUNTIF($F$2:F6,1),"")
A7: 190.993 | B7: 1.6388278 | C7: 81 | D7: -1 | E7: 1.640293 | F7: 0 | G7: 0 | H7: =IF(AND(A7>=Stimuli!$B$2,A7<=Stimuli!$C$2),Stimuli!$A$2,IF(AND(A7>=Stimuli!$B$3,A7<=Stimuli!$C$3),Stimuli!$A$3,IF(AND(A7>=Stimuli!$B$4,A7<=Stimuli!$C$4),Stimuli!$A$4,""))) -> 01 Quiet baseline (60s) | I7: =(B7-B6)/((A7-A6)/1000) -> -0.37509158 | J7: =IF(OR(B7<Rules!$B$2,B7>Rules!$B$3,ABS(I7)>Rules!$B$4,OR(B8<Rules!$B$2,B8>Rules!$B$3,ABS(I8)>Rules!$B$4)),1,0) -> 0 | K7: =IF(F7=1,COUNTIF($F$2:F7,1),"")
A8: 198.8055 | B8: 1.6417582 | C8: 81 | D8: -1 | E8: 1.640293 | F8: 0 | G8: 0 | H8: =IF(AND(A8>=Stimuli!$B$2,A8<=Stimuli!$C$2),Stimuli!$A$2,IF(AND(A8>=Stimuli!$B$3,A8<=Stimuli!$C$3),Stimuli!$A$3,IF(AND(A8>=Stimuli!$B$4,A8<=Stimuli!$C$4),Stimuli!$A$4,""))) -> 01 Quiet baseline (60s) | I8: =(B8-B7)/((A8-A7)/1000) -> 0.37509158 | J8: =IF(OR(B8<Rules!$B$2,B8>Rules!$B$3,ABS(I8)>Rules!$B$4,OR(B9<Rules!$B$2,B9>Rules!$B$3,ABS(I9)>Rules!$B$4)),1,0) -> 0 | K8: =IF(F8=1,COUNTIF($F$2:F8,1),"")
A9: 206.618 | B9: 1.640293 | C9: 81 | D9: -1 | E9: 1.640293 | F9: 0 | G9: 0 | H9: =IF(AND(A9>=Stimuli!$B$2,A9<=Stimuli!$C$2),Stimuli!$A$2,IF(AND(A9>=Stimuli!$B$3,A9<=Stimuli!$C$3),Stimuli!$A$3,IF(AND(A9>=Stimuli!$B$4,A9<=Stimuli!$C$4),Stimuli!$A$4,""))) -> 01 Quiet baseline (60s) | I9: =(B9-B8)/((A9-A8)/1000) -> -0.18754579 | J9: =IF(OR(B9<Rules!$B$2,B9>Rules!$B$3,ABS(I9)>Rules!$B$4,OR(B10<Rules!$B$2,B10>Rules!$B$3,ABS(I10)>Rules!$B$4)),1,0) -> 0 | K9: =IF(F9=1,COUNTIF($F$2:F9,1),"")
A10: 214.4305 | B10: 1.640293 | C10: 81 | D10: -1 | E10: 1.640293 | F10: 0 | G10: 0 | H10: =IF(AND(A10>=Stimuli!$B$2,A10<=Stimuli!$C$2),Stimuli!$A$2,IF(AND(A10>=Stimuli!$B$3,A10<=Stimuli!$C$3),Stimuli!$A$3,IF(AND(A10>=Stimuli!$B$4,A10<=Stimuli!$C$4),Stimuli!$A$4,""))) -> 01 Quiet baseline (60s) | I10: =(B10-B9)/((A10-A9)/1000) -> 0 | J10: =IF(OR(B10<Rules!$B$2,B10>Rules!$B$3,ABS(I10)>Rules!$B$4,OR(B11<Rules!$B$2,B11>Rules!$B$3,ABS(I11)>Rules!$B$4)),1,0) -> 0 | K10: =IF(F10=1,COUNTIF($F$2:F10,1),"")
A11: 222.243 | B11: 1.6417582 | C11: 81 | D11: -1 | E11: 1.640293 | F11: 0 | G11: 0 | H11: =IF(AND(A11>=Stimuli!$B$2,A11<=Stimuli!$C$2),Stimuli!$A$2,IF(AND(A11>=Stimuli!$B$3,A11<=Stimuli!$C$3),Stimuli!$A$3,IF(AND(A11>=Stimuli!$B$4,A11<=Stimuli!$C$4),Stimuli!$A$4,""))) -> 01 Quiet baseline (60s) | I11: =(B11-B10)/((A11-A10)/1000) -> 0.18754579 | J11: =IF(OR(B11<Rules!$B$2,B11>Rules!$B$3,ABS(I11)>Rules!$B$4,OR(B12<Rules!$B$2,B12>Rules!$B$3,ABS(I12)>Rules!$B$4)),1,0) -> 0 | K11: =IF(F11=1,COUNTIF($F$2:F11,1),"")
A12: 230.0555 | B12: 1.6388278 | C12: 81 | D12: -1 | E12: 1.640293 | F12: 0 | G12: 0 | H12: =IF(AND(A12>=Stimuli!$B$2,A12<=Stimuli!$C$2),Stimuli!$A$2,IF(AND(A12>=Stimuli!$B$3,A12<=Stimuli!$C$3),Stimuli!$A$3,IF(AND(A12>=Stimuli!$B$4,A12<=Stimuli!$C$4),Stimuli!$A$4,""))) -> 01 Quiet baseline (60s) | I12: =(B12-B11)/((A12-A11)/1000) -> -0.37509158 | J12: =IF(OR(B12<Rules!$B$2,B12>Rules!$B$3,ABS(I12)>Rules!$B$4,OR(B13<Rules!$B$2,B13>Rules!$B$3,ABS(I13)>Rules!$B$4)),1,0) -> 0 | K12: =IF(F12=1,COUNTIF($F$2:F12,1),"")
A13: 237.868 | B13: 1.6417582 | C13: 81 | D13: -1 | E13: 1.640293 | F13: 0 | G13: 0 | H13: =IF(AND(A13>=Stimuli!$B$2,A13<=Stimuli!$C$2),Stimuli!$A$2,IF(AND(A13>=Stimuli!$B$3,A13<=Stimuli!$C$3),Stimuli!$A$3,IF(AND(A13>=Stimuli!$B$4,A13<=Stimuli!$C$4),Stimuli!$A$4,""))) -> 01 Quiet baseline (60s) | I13: =(B13-B12)/((A13-A12)/1000) -> 0.37509158 | J13: =IF(OR(B13<Rules!$B$2,B13>Rules!$B$3,ABS(I13)>Rules!$B$4,OR(B14<Rules!$B$2,B14>Rules!$B$3,ABS(I14)>Rules!$B$4)),1,0) -> 0 | K13: =IF(F13=1,COUNTIF($F$2:F13,1),"")
A14: 245.6805 | B14: 1.6388278 | C14: 81 | D14: -1 | E14: 1.640293 | F14: 0 | G14: 0 | H14: =IF(AND(A14>=Stimuli!$B$2,A14<=Stimuli!$C$2),Stimuli!$A$2,IF(AND(A14>=Stimuli!$B$3,A14<=Stimuli!$C$3),Stimuli!$A$3,IF(AND(A14>=Stimuli!$B$4,A14<=Stimuli!$C$4),Stimuli!$A$4,""))) -> 01 Quiet baseline (60s) | I14: =(B14-B13)/((A14-A13)/1000) -> -0.37509158 | J14: =IF(OR(B14<Rules!$B$2,B14>Rules!$B$3,ABS(I14)>Rules!$B$4,OR(B15<Rules!$B$2,B15>Rules!$B$3,ABS(I15)>Rules!$B$4)),1,0) -> 0 | K14: =IF(F14=1,COUNTIF($F$2:F14,1),"")
... A13426: 105362.87 | B13426: 1.9040293 | C13426: 83 | D13426: -1 | E13426: 1.9142857 | F13426: 0 | G13426: 0 | H13426: =IF(AND(A13426>=Stimuli!$B$2,A13426<=Stimuli!$C$2),Stimuli!$A$2,IF(AND(A13426>=Stimuli!$B$3,A13426<=Stimuli!$C$3),Stimuli!$A$3,IF(AND(A13426>=Stimuli!$B$4,A13426<=Stimuli!$C$4),Stimuli!$A$4,""))) -> 03 Quiet recovery (15s) | I13426: =(B13426-B13425)/((A13426-A13425)/1000) -> 0.93772894 | J13426: =IF(OR(B13426<Rules!$B$2,B13426>Rules!$B$3,ABS(I13426)>Rules!$B$4,OR(B13427<Rules!$B$2,B13427>Rules!$B$3,ABS(I13427)>Rules!$B$4)),1,0) -> 0 | K13426: =IF(F13426=1,COUNTIF($F$2:F13426,1),"")
A13427: 105370.68 | B13427: 1.8952381 | C13427: 83 | D13427: -1 | E13427: 1.9142857 | F13427: 0 | G13427: 0 | H13427: =IF(AND(A13427>=Stimuli!$B$2,A13427<=Stimuli!$C$2),Stimuli!$A$2,IF(AND(A13427>=Stimuli!$B$3,A13427<=Stimuli!$C$3),Stimuli!$A$3,IF(AND(A13427>=Stimuli!$B$4,A13427<=Stimuli!$C$4),Stimuli!$A$4,""))) -> 03 Quiet recovery (15s) | I13427: =(B13427-B13426)/((A13427-A13426)/1000) -> -1.1252747 | J13427: =IF(OR(B13427<Rules!$B$2,B13427>Rules!$B$3,ABS(I13427)>Rules!$B$4),1,0) -> 0 | K13427: =IF(F13427=1,COUNTIF($F$2:F13427,1),"")

Sheet Peaks
A1: Peak | B1: Peak_time_ms | C1: Peak_time_s | D1: Amplitude_uS | E1: Stimulus | F1: Rule_breaks_within_margin | G1: Inside_artifact_margin
A2: 1 | B2: =INDEX(Shimmer!$A$2:$A$13427,MATCH(A2,Shimmer!$K$2:$K$13427,0)) -> 5386.3055 | C2: =B2/1000 -> 5.3863055 | D2: =INDEX(Shimmer!$G$2:$G$13427,MATCH(A2,Shimmer!$K$2:$K$13427,0)) -> 0.15531136 | E2: =INDEX(Shimmer!$H$2:$H$13427,MATCH(A2,Shimmer!$K$2:$K$13427,0)) -> 01 Quiet baseline (60s) | F2: =COUNTIFS(Shimmer!$A$2:$A$13427,">="&(B2-Rules!$B$5),Shimmer!$A$2:$A$13427,"<="&(B2+Rules!$B$5),Shimmer!$J$2:$J$13427,1) -> 0 | G2: =IF(F2>0,1,0) -> 0
A3: 2 | B3: =INDEX(Shimmer!$A$2:$A$13427,MATCH(A3,Shimmer!$K$2:$K$13427,0)) -> 11167.556 | C3: =B3/1000 -> 11.167556 | D3: =INDEX(Shimmer!$G$2:$G$13427,MATCH(A3,Shimmer!$K$2:$K$13427,0)) -> 0.023443223 | E3: =INDEX(Shimmer!$H$2:$H$13427,MATCH(A3,Shimmer!$K$2:$K$13427,0)) -> 01 Quiet baseline (60s) | F3: =COUNTIFS(Shimmer!$A$2:$A$13427,">="&(B3-Rules!$B$5),Shimmer!$A$2:$A$13427,"<="&(B3+Rules!$B$5),Shimmer!$J$2:$J$13427,1) -> 0 | G3: =IF(F3>0,1,0) -> 0
A4: 3 | B4: =INDEX(Shimmer!$A$2:$A$13427,MATCH(A4,Shimmer!$K$2:$K$13427,0)) -> 20698.805 | C4: =B4/1000 -> 20.698805 | D4: =INDEX(Shimmer!$G$2:$G$13427,MATCH(A4,Shimmer!$K$2:$K$13427,0)) -> 0.023443223 | E4: =INDEX(Shimmer!$H$2:$H$13427,MATCH(A4,Shimmer!$K$2:$K$13427,0)) -> 01 Quiet baseline (60s) | F4: =COUNTIFS(Shimmer!$A$2:$A$13427,">="&(B4-Rules!$B$5),Shimmer!$A$2:$A$13427,"<="&(B4+Rules!$B$5),Shimmer!$J$2:$J$13427,1) -> 17 | G4: =IF(F4>0,1,0) -> 1
A5: 4 | B5: =INDEX(Shimmer!$A$2:$A$13427,MATCH(A5,Shimmer!$K$2:$K$13427,0)) -> 28245.68 | C5: =B5/1000 -> 28.24568 | D5: =INDEX(Shimmer!$G$2:$G$13427,MATCH(A5,Shimmer!$K$2:$K$13427,0)) -> 0.0058608059 | E5: =INDEX(Shimmer!$H$2:$H$13427,MATCH(A5,Shimmer!$K$2:$K$13427,0)) -> 01 Quiet baseline (60s) | F5: =COUNTIFS(Shimmer!$A$2:$A$13427,">="&(B5-Rules!$B$5),Shimmer!$A$2:$A$13427,"<="&(B5+Rules!$B$5),Shimmer!$J$2:$J$13427,1) -> 0 | G5: =IF(F5>0,1,0) -> 0
A6: 5 | B6: =INDEX(Shimmer!$A$2:$A$13427,MATCH(A6,Shimmer!$K$2:$K$13427,0)) -> 42206.618 | C6: =B6/1000 -> 42.206618 | D6: =INDEX(Shimmer!$G$2:$G$13427,MATCH(A6,Shimmer!$K$2:$K$13427,0)) -> 0.11575092 | E6: =INDEX(Shimmer!$H$2:$H$13427,MATCH(A6,Shimmer!$K$2:$K$13427,0)) -> 01 Quiet baseline (60s) | F6: =COUNTIFS(Shimmer!$A$2:$A$13427,">="&(B6-Rules!$B$5),Shimmer!$A$2:$A$13427,"<="&(B6+Rules!$B$5),Shimmer!$J$2:$J$13427,1) -> 0 | G6: =IF(F6>0,1,0) -> 0
A7: 6 | B7: =INDEX(Shimmer!$A$2:$A$13427,MATCH(A7,Shimmer!$K$2:$K$13427,0)) -> 43089.431 | C7: =B7/1000 -> 43.08943 | D7: =INDEX(Shimmer!$G$2:$G$13427,MATCH(A7,Shimmer!$K$2:$K$13427,0)) -> 0.082051282 | E7: =INDEX(Shimmer!$H$2:$H$13427,MATCH(A7,Shimmer!$K$2:$K$13427,0)) -> 01 Quiet baseline (60s) | F7: =COUNTIFS(Shimmer!$A$2:$A$13427,">="&(B7-Rules!$B$5),Shimmer!$A$2:$A$13427,"<="&(B7+Rules!$B$5),Shimmer!$J$2:$J$13427,1) -> 0 | G7: =IF(F7>0,1,0) -> 0
A8: 7 | B8: =INDEX(Shimmer!$A$2:$A$13427,MATCH(A8,Shimmer!$K$2:$K$13427,0)) -> 44823.806 | C8: =B8/1000 -> 44.823805 | D8: =INDEX(Shimmer!$G$2:$G$13427,MATCH(A8,Shimmer!$K$2:$K$13427,0)) -> 0.21391941 | E8: =INDEX(Shimmer!$H$2:$H$13427,MATCH(A8,Shimmer!$K$2:$K$13427,0)) -> 01 Quiet baseline (60s) | F8: =COUNTIFS(Shimmer!$A$2:$A$13427,">="&(B8-Rules!$B$5),Shimmer!$A$2:$A$13427,"<="&(B8+Rules!$B$5),Shimmer!$J$2:$J$13427,1) -> 0 | G8: =IF(F8>0,1,0) -> 0
A9: 8 | B9: =INDEX(Shimmer!$A$2:$A$13427,MATCH(A9,Shimmer!$K$2:$K$13427,0)) -> 51120.681 | C9: =B9/1000 -> 51.12068 | D9: =INDEX(Shimmer!$G$2:$G$13427,MATCH(A9,Shimmer!$K$2:$K$13427,0)) -> 0.032234432 | E9: =INDEX(Shimmer!$H$2:$H$13427,MATCH(A9,Shimmer!$K$2:$K$13427,0)) -> 01 Quiet baseline (60s) | F9: =COUNTIFS(Shimmer!$A$2:$A$13427,">="&(B9-Rules!$B$5),Shimmer!$A$2:$A$13427,"<="&(B9+Rules!$B$5),Shimmer!$J$2:$J$13427,1) -> 0 | G9: =IF(F9>0,1,0) -> 0
A10: 9 | B10: =INDEX(Shimmer!$A$2:$A$13427,MATCH(A10,Shimmer!$K$2:$K$13427,0)) -> 60550.368 | C10: =B10/1000 -> 60.550368 | D10: =INDEX(Shimmer!$G$2:$G$13427,MATCH(A10,Shimmer!$K$2:$K$13427,0)) -> 0.064468864 | E10: =INDEX(Shimmer!$H$2:$H$13427,MATCH(A10,Shimmer!$K$2:$K$13427,0)) -> 02 e.l.f. - Power Grip Styling (30.03s) | F10: =COUNTIFS(Shimmer!$A$2:$A$13427,">="&(B10-Rules!$B$5),Shimmer!$A$2:$A$13427,"<="&(B10+Rules!$B$5),Shimmer!$J$2:$J$13427,1) -> 0 | G10: =IF(F10>0,1,0) -> 0
A11: 10 | B11: =INDEX(Shimmer!$A$2:$A$13427,MATCH(A11,Shimmer!$K$2:$K$13427,0)) -> 63698.806 | C11: =B11/1000 -> 63.698805 | D11: =INDEX(Shimmer!$G$2:$G$13427,MATCH(A11,Shimmer!$K$2:$K$13427,0)) -> 0.20805861 | E11: =INDEX(Shimmer!$H$2:$H$13427,MATCH(A11,Shimmer!$K$2:$K$13427,0)) -> 02 e.l.f. - Power Grip Styling (30.03s) | F11: =COUNTIFS(Shimmer!$A$2:$A$13427,">="&(B11-Rules!$B$5),Shimmer!$A$2:$A$13427,"<="&(B11+Rules!$B$5),Shimmer!$J$2:$J$13427,1) -> 0 | G11: =IF(F11>0,1,0) -> 0
A12: 11 | B12: =INDEX(Shimmer!$A$2:$A$13427,MATCH(A12,Shimmer!$K$2:$K$13427,0)) -> 75659.743 | C12: =B12/1000 -> 75.659743 | D12: =INDEX(Shimmer!$G$2:$G$13427,MATCH(A12,Shimmer!$K$2:$K$13427,0)) -> 0.0087912088 | E12: =INDEX(Shimmer!$H$2:$H$13427,MATCH(A12,Shimmer!$K$2:$K$13427,0)) -> 02 e.l.f. - Power Grip Styling (30.03s) | F12: =COUNTIFS(Shimmer!$A$2:$A$13427,">="&(B12-Rules!$B$5),Shimmer!$A$2:$A$13427,"<="&(B12+Rules!$B$5),Shimmer!$J$2:$J$13427,1) -> 0 | G12: =IF(F12>0,1,0) -> 0
A13: 12 | B13: =INDEX(Shimmer!$A$2:$A$13427,MATCH(A13,Shimmer!$K$2:$K$13427,0)) -> 83972.243 | C13: =B13/1000 -> 83.972243 | D13: =INDEX(Shimmer!$G$2:$G$13427,MATCH(A13,Shimmer!$K$2:$K$13427,0)) -> 0.04981685 | E13: =INDEX(Shimmer!$H$2:$H$13427,MATCH(A13,Shimmer!$K$2:$K$13427,0)) -> 02 e.l.f. - Power Grip Styling (30.03s) | F13: =COUNTIFS(Shimmer!$A$2:$A$13427,">="&(B13-Rules!$B$5),Shimmer!$A$2:$A$13427,"<="&(B13+Rules!$B$5),Shimmer!$J$2:$J$13427,1) -> 0 | G13: =IF(F13>0,1,0) -> 0
... A15: 14 | B15: =INDEX(Shimmer!$A$2:$A$13427,MATCH(A15,Shimmer!$K$2:$K$13427,0)) -> 96167.556 | C15: =B15/1000 -> 96.167556 | D15: =INDEX(Shimmer!$G$2:$G$13427,MATCH(A15,Shimmer!$K$2:$K$13427,0)) -> 0.024908425 | E15: =INDEX(Shimmer!$H$2:$H$13427,MATCH(A15,Shimmer!$K$2:$K$13427,0)) -> 03 Quiet recovery (15s) | F15: =COUNTIFS(Shimmer!$A$2:$A$13427,">="&(B15-Rules!$B$5),Shimmer!$A$2:$A$13427,"<="&(B15+Rules!$B$5),Shimmer!$J$2:$J$13427,1) -> 0 | G15: =IF(F15>0,1,0) -> 0
A16: Total peaks | B16: =COUNT(B2:B15) -> 14
A17: Peaks inside the margin | B17: =SUM(G2:G15) -> 1
A18: Shimmer rows that break the rule | B18: =SUM(Shimmer!$J$2:$J$13427) -> 17

Sheet Summary
A1: Stimulus | B1: Length_s | C1: Peaks | D1: Peaks_per_min | E1: Peaks_after_rule | F1: Peaks_per_min_after_rule | G1: Mean_tonic_uS | H1: Mean_HR_bpm_clean | I1: Mean_HR_bpm_WRONG_with_codes | J1: Mean_IBI_ms | K1: HR_from_mean_IBI_bpm | L1: Rows_with_HR_code | M1: Mean_peak_amplitude_uS
A2: =Stimuli!A2 -> 01 Quiet baseline (60s) | B2: =Stimuli!D2 -> 60.00998 | C2: =COUNTIFS(Peaks!$E$2:$E$15,A2) -> 8 | D2: =C2/(B2/60) -> 7.9986695 | E2: =COUNTIFS(Peaks!$E$2:$E$15,A2,Peaks!$G$2:$G$15,0) -> 7 | F2: =E2/(B2/60) -> 6.9988358 | G2: =AVERAGEIFS(Shimmer!$E$2:$E$13427,Shimmer!$H$2:$H$13427,A2) -> 1.8041284 | H2: =AVERAGEIFS(Shimmer!$C$2:$C$13427,Shimmer!$H$2:$H$13427,A2,Shimmer!$C$2:$C$13427,">0") -> 79.629061 | I2: =AVERAGEIFS(Shimmer!$C$2:$C$13427,Shimmer!$H$2:$H$13427,A2) -> 77.102494 | J2: =AVERAGEIFS(Shimmer!$D$2:$D$13427,Shimmer!$H$2:$H$13427,A2,Shimmer!$D$2:$D$13427,">0") -> 752.60417 | K2: =60000/J2 -> 79.723183 | L2: =COUNTIFS(Shimmer!$H$2:$H$13427,A2,Shimmer!$C$2:$C$13427,"<=0") -> 240 | M2: =AVERAGEIFS(Peaks!$D$2:$D$15,Peaks!$E$2:$E$15,A2) -> 0.081501832
A3: =Stimuli!A3 -> 02 e.l.f. - Power Grip Styling (30.03s) | B3: =Stimuli!D3 -> 30.072844 | C3: =COUNTIFS(Peaks!$E$2:$E$15,A3) -> 4 | D3: =C3/(B3/60) -> 7.9806221 | E3: =COUNTIFS(Peaks!$E$2:$E$15,A3,Peaks!$G$2:$G$15,0) -> 4 | F3: =E3/(B3/60) -> 7.9806221 | G3: =AVERAGEIFS(Shimmer!$E$2:$E$13427,Shimmer!$H$2:$H$13427,A3) -> 2.0464958 | H3: =AVERAGEIFS(Shimmer!$C$2:$C$13427,Shimmer!$H$2:$H$13427,A3,Shimmer!$C$2:$C$13427,">0") -> 80.41812 | I3: =AVERAGEIFS(Shimmer!$C$2:$C$13427,Shimmer!$H$2:$H$13427,A3) -> 80.41812 | J3: =AVERAGEIFS(Shimmer!$D$2:$D$13427,Shimmer!$H$2:$H$13427,A3,Shimmer!$D$2:$D$13427,">0") -> 743.94531 | K3: =60000/J3 -> 80.65109 | L3: =COUNTIFS(Shimmer!$H$2:$H$13427,A3,Shimmer!$C$2:$C$13427,"<=0") -> 0 | M3: =AVERAGEIFS(Peaks!$D$2:$D$15,Peaks!$E$2:$E$15,A3) -> 0.082783883
A4: =Stimuli!A4 -> 03 Quiet recovery (15s) | B4: =Stimuli!D4 -> 15.010595 | C4: =COUNTIFS(Peaks!$E$2:$E$15,A4) -> 2 | D4: =C4/(B4/60) -> 7.9943534 | E4: =COUNTIFS(Peaks!$E$2:$E$15,A4,Peaks!$G$2:$G$15,0) -> 2 | F4: =E4/(B4/60) -> 7.9943534 | G4: =AVERAGEIFS(Shimmer!$E$2:$E$13427,Shimmer!$H$2:$H$13427,A4) -> 1.972423 | H4: =AVERAGEIFS(Shimmer!$C$2:$C$13427,Shimmer!$H$2:$H$13427,A4,Shimmer!$C$2:$C$13427,">0") -> 79.938317 | I4: =AVERAGEIFS(Shimmer!$C$2:$C$13427,Shimmer!$H$2:$H$13427,A4) -> 79.938317 | J4: =AVERAGEIFS(Shimmer!$D$2:$D$13427,Shimmer!$H$2:$H$13427,A4,Shimmer!$D$2:$D$13427,">0") -> 748.82812 | K4: =60000/J4 -> 80.125196 | L4: =COUNTIFS(Shimmer!$H$2:$H$13427,A4,Shimmer!$C$2:$C$13427,"<=0") -> 0 | M4: =AVERAGEIFS(Peaks!$D$2:$D$15,Peaks!$E$2:$E$15,A4) -> 0.07032967
A6: Read across row 2: the WRONG column keeps the -1 rows (Rows_with_HR_code) and pulls the baseline heart rate down. One respondent: these numbers describe; they test nothing.

Sheet Check
A1: Stimulus | B1: Measure | C1: pilot_analysis.R | D1: Workbook | E1: Difference | F1: Status
A2: =Summary!A2 -> 01 Quiet baseline (60s) | B2: Peaks | C2: 8 | D2: =Summary!C2 -> 8 | E2: =D2-C2 -> 0 | F2: =IF(ABS(E2)<=0.051,"OK","CHECK") -> OK
A3: =Summary!A2 -> 01 Quiet baseline (60s) | B3: Peaks_per_min | C3: 8 | D3: =Summary!D2 -> 7.9986695 | E3: =D3-C3 -> -0.0013304854 | F3: =IF(ABS(E3)<=0.051,"OK","CHECK") -> OK
A4: =Summary!A2 -> 01 Quiet baseline (60s) | B4: Peaks_after_rule | C4: 7 | D4: =Summary!E2 -> 7 | E4: =D4-C4 -> 0 | F4: =IF(ABS(E4)<=0.051,"OK","CHECK") -> OK
A5: =Summary!A2 -> 01 Quiet baseline (60s) | B5: Peaks_per_min_after_rule | C5: 7 | D5: =Summary!F2 -> 6.9988358 | E5: =D5-C5 -> -0.0011641747 | F5: =IF(ABS(E5)<=0.051,"OK","CHECK") -> OK
A6: =Summary!A2 -> 01 Quiet baseline (60s) | B6: Mean_tonic_uS | C6: 1.804 | D6: =Summary!G2 -> 1.8041284 | E6: =D6-C6 -> 0.00012835195 | F6: =IF(ABS(E6)<=0.051,"OK","CHECK") -> OK
A7: =Summary!A2 -> 01 Quiet baseline (60s) | B7: Mean_HR_bpm_clean | C7: 79.6 | D7: =Summary!H2 -> 79.629061 | E7: =D7-C7 -> 0.02906052 | F7: =IF(ABS(E7)<=0.051,"OK","CHECK") -> OK
A8: =Summary!A2 -> 01 Quiet baseline (60s) | B8: Mean_HR_bpm_WRONG_with_codes | C8: 77.1 | D8: =Summary!I2 -> 77.102494 | E8: =D8-C8 -> 0.0024937981 | F8: =IF(ABS(E8)<=0.051,"OK","CHECK") -> OK
A9: =Summary!A2 -> 01 Quiet baseline (60s) | B9: HR_from_mean_IBI_bpm | C9: 79.7 | D9: =Summary!K2 -> 79.723183 | E9: =D9-C9 -> 0.023183391 | F9: =IF(ABS(E9)<=0.051,"OK","CHECK") -> OK
A10: =Summary!A3 -> 02 e.l.f. - Power Grip Styling (30.03s) | B10: Peaks | C10: 4 | D10: =Summary!C3 -> 4 | E10: =D10-C10 -> 0 | F10: =IF(ABS(E10)<=0.051,"OK","CHECK") -> OK
A11: =Summary!A3 -> 02 e.l.f. - Power Grip Styling (30.03s) | B11: Peaks_per_min | C11: 7.98 | D11: =Summary!D3 -> 7.9806221 | E11: =D11-C11 -> 0.00062211842 | F11: =IF(ABS(E11)<=0.051,"OK","CHECK") -> OK
A12: =Summary!A3 -> 02 e.l.f. - Power Grip Styling (30.03s) | B12: Peaks_after_rule | C12: 4 | D12: =Summary!E3 -> 4 | E12: =D12-C12 -> 0 | F12: =IF(ABS(E12)<=0.051,"OK","CHECK") -> OK
A13: =Summary!A3 -> 02 e.l.f. - Power Grip Styling (30.03s) | B13: Peaks_per_min_after_rule | C13: 7.98 | D13: =Summary!F3 -> 7.9806221 | E13: =D13-C13 -> 0.00062211842 | F13: =IF(ABS(E13)<=0.051,"OK","CHECK") -> OK
A14: =Summary!A3 -> 02 e.l.f. - Power Grip Styling (30.03s) | B14: Mean_tonic_uS | C14: 2.046 | D14: =Summary!G3 -> 2.0464958 | E14: =D14-C14 -> 0.00049582822 | F14: =IF(ABS(E14)<=0.051,"OK","CHECK") -> OK
A15: =Summary!A3 -> 02 e.l.f. - Power Grip Styling (30.03s) | B15: Mean_HR_bpm_clean | C15: 80.4 | D15: =Summary!H3 -> 80.41812 | E15: =D15-C15 -> 0.018120281 | F15: =IF(ABS(E15)<=0.051,"OK","CHECK") -> OK
A16: =Summary!A3 -> 02 e.l.f. - Power Grip Styling (30.03s) | B16: Mean_HR_bpm_WRONG_with_codes | C16: 80.4 | D16: =Summary!I3 -> 80.41812 | E16: =D16-C16 -> 0.018120281 | F16: =IF(ABS(E16)<=0.051,"OK","CHECK") -> OK
A17: =Summary!A3 -> 02 e.l.f. - Power Grip Styling (30.03s) | B17: HR_from_mean_IBI_bpm | C17: 80.7 | D17: =Summary!K3 -> 80.65109 | E17: =D17-C17 -> -0.048910475 | F17: =IF(ABS(E17)<=0.051,"OK","CHECK") -> OK
A18: =Summary!A4 -> 03 Quiet recovery (15s) | B18: Peaks | C18: 2 | D18: =Summary!C4 -> 2 | E18: =D18-C18 -> 0 | F18: =IF(ABS(E18)<=0.051,"OK","CHECK") -> OK
A19: =Summary!A4 -> 03 Quiet recovery (15s) | B19: Peaks_per_min | C19: 7.99 | D19: =Summary!D4 -> 7.9943534 | E19: =D19-C19 -> 0.004353375 | F19: =IF(ABS(E19)<=0.051,"OK","CHECK") -> OK
A20: =Summary!A4 -> 03 Quiet recovery (15s) | B20: Peaks_after_rule | C20: 2 | D20: =Summary!E4 -> 2 | E20: =D20-C20 -> 0 | F20: =IF(ABS(E20)<=0.051,"OK","CHECK") -> OK
A21: =Summary!A4 -> 03 Quiet recovery (15s) | B21: Peaks_per_min_after_rule | C21: 7.99 | D21: =Summary!F4 -> 7.9943534 | E21: =D21-C21 -> 0.004353375 | F21: =IF(ABS(E21)<=0.051,"OK","CHECK") -> OK
A22: =Summary!A4 -> 03 Quiet recovery (15s) | B22: Mean_tonic_uS | C22: 1.972 | D22: =Summary!G4 -> 1.972423 | E22: =D22-C22 -> 0.00042298852 | F22: =IF(ABS(E22)<=0.051,"OK","CHECK") -> OK
A23: =Summary!A4 -> 03 Quiet recovery (15s) | B23: Mean_HR_bpm_clean | C23: 79.9 | D23: =Summary!H4 -> 79.938317 | E23: =D23-C23 -> 0.03831678 | F23: =IF(ABS(E23)<=0.051,"OK","CHECK") -> OK
A24: =Summary!A4 -> 03 Quiet recovery (15s) | B24: Mean_HR_bpm_WRONG_with_codes | C24: 79.9 | D24: =Summary!I4 -> 79.938317 | E24: =D24-C24 -> 0.03831678 | F24: =IF(ABS(E24)<=0.051,"OK","CHECK") -> OK
A25: =Summary!A4 -> 03 Quiet recovery (15s) | B25: HR_from_mean_IBI_bpm | C25: 80.1 | D25: =Summary!K4 -> 80.125196 | E25: =D25-C25 -> 0.025195618 | F25: =IF(ABS(E25)<=0.051,"OK","CHECK") -> OK
A27: The R values are rounded (1 to 3 decimals), so differences up to 0.05 are allowed.

Sheet iMotions_Check
A1: Stimulus | B1: Measure | C1: iMotions GSRPeakMetrics.csv | D1: Workbook | E1: Difference | F1: Status
A2: =Summary!A2 -> 01 Quiet baseline (60s) | B2: Peak Count | C2: 8 | D2: =Summary!C2 -> 8 | E2: =D2-C2 -> 0 | F2: =IF(ABS(E2)<=0,"OK","CHECK") -> OK
A3: =Summary!A2 -> 01 Quiet baseline (60s) | B3: Peaks Per Minute | C3: 8 | D3: =Summary!D2 -> 7.9986695 | E3: =D3-C3 -> -0.0013304854 | F3: =IF(ABS(E3)<=0.005,"OK","CHECK") -> OK
A4: =Summary!A2 -> 01 Quiet baseline (60s) | B4: Average Peak Amplitude (microsiemens) | C4: 0.0815 | D4: =Summary!M2 -> 0.081501832 | E4: =D4-C4 -> 1.8315018e-06 | F4: =IF(ABS(E4)<=0.00005,"OK","CHECK") -> OK
A5: =Summary!A3 -> 02 e.l.f. - Power Grip Styling (30.03s) | B5: Peak Count | C5: 4 | D5: =Summary!C3 -> 4 | E5: =D5-C5 -> 0 | F5: =IF(ABS(E5)<=0,"OK","CHECK") -> OK
A6: =Summary!A3 -> 02 e.l.f. - Power Grip Styling (30.03s) | B6: Peaks Per Minute | C6: 7.98 | D6: =Summary!D3 -> 7.9806221 | E6: =D6-C6 -> 0.00062211842 | F6: =IF(ABS(E6)<=0.005,"OK","CHECK") -> OK
A7: =Summary!A3 -> 02 e.l.f. - Power Grip Styling (30.03s) | B7: Average Peak Amplitude (microsiemens) | C7: 0.0828 | D7: =Summary!M3 -> 0.082783883 | E7: =D7-C7 -> -1.6117216e-05 | F7: =IF(ABS(E7)<=0.00005,"OK","CHECK") -> OK
A8: =Summary!A4 -> 03 Quiet recovery (15s) | B8: Peak Count | C8: 2 | D8: =Summary!C4 -> 2 | E8: =D8-C8 -> 0 | F8: =IF(ABS(E8)<=0,"OK","CHECK") -> OK
A9: =Summary!A4 -> 03 Quiet recovery (15s) | B9: Peaks Per Minute | C9: 7.99 | D9: =Summary!D4 -> 7.9943534 | E9: =D9-C9 -> 0.004353375 | F9: =IF(ABS(E9)<=0.005,"OK","CHECK") -> OK
A10: =Summary!A4 -> 03 Quiet recovery (15s) | B10: Average Peak Amplitude (microsiemens) | C10: 0.0703 | D10: =Summary!M4 -> 0.07032967 | E10: =D10-C10 -> 2.967033e-05 | F10: =IF(ABS(E10)<=0.00005,"OK","CHECK") -> OK
A12: iMotions rounds Peaks Per Minute to 2 decimals and amplitudes to 4, so small differences are allowed. Source: Export > R PROCESSING > GSR Metrics Export > Peak metrics, October 12, 2026.

Sheet Settings
A1: Setting | B1: Value | C1: Source
A2: selectedSensorName | B2: Shimmer||8956 GSR||Shimmer | C2: '#Sensor info' row for R Analysis GSR Peak Detection, export header
A3: lslChannel | C3: '#Sensor info' row for R Analysis GSR Peak Detection, export header
A4: phasic_length | B4: 8000 | C4: '#Sensor info' row for R Analysis GSR Peak Detection, export header
A5: lowpass_filter_frequency | B5: 5 | C5: '#Sensor info' row for R Analysis GSR Peak Detection, export header
A6: gap_length_threshold | B6: 4000 | C6: '#Sensor info' row for R Analysis GSR Peak Detection, export header
A7: remove_signal_jumps | B7: false | C7: '#Sensor info' row for R Analysis GSR Peak Detection, export header
A8: peak_onset_threshold | B8: 0.01 | C8: '#Sensor info' row for R Analysis GSR Peak Detection, export header
A9: peak_offset_threshold | B9: 0 | C9: '#Sensor info' row for R Analysis GSR Peak Detection, export header
A10: peak_amplitude_threshold | B10: 0.005 | C10: '#Sensor info' row for R Analysis GSR Peak Detection, export header
A11: minimum_peak_duration | B11: 500 | C11: '#Sensor info' row for R Analysis GSR Peak Detection, export header
A12: smoothing_filter | B12: median | C12: '#Sensor info' row for R Analysis GSR Peak Detection, export header
A13: Device | B13: Shimmer 8956 GSR | C13: '#Sensor info' row for R Analysis GSR Peak Detection, export header

Sheet Codebook
A1: Column | B1: Device | C1: Provided By | D1: Category | E1: Description | F1: Unit | G1: Short unit | H1: Instance | I1: Group | J1: Display name | K1: Data format | L1: Channel identifier
A2: Timestamp | C2: iMotions | D2: Timestamp | E2: iMotions synchronization timestamp. Relative to data recording start | F2: Millisecond | G2: ms | L2: iMotions_Synchronization_Timestamp
A3: EventSource | B3: SlideEvents | C3: iMotions | D3: Event Source | E3: Can be used to filter data from: SlideEvents | I3: Event Source | L3: Eventsource_Slideevents
A4: SlideEvent | B4: SlideEvents | C4: iMotions | D4: Slideshow | E4: Slide & Media events: Start/Stop | L4: SE_SlideEvent
A5: StimType | B5: SlideEvents | C5: iMotions | D5: Slideshow | E5: Type of stimulus | L5: SE_StimulusType
A6: Duration | B6: SlideEvents | C6: iMotions | D6: Slideshow | E6: Stimulus duration fx video length | F6: Millisecond | G6: ms | L6: SE_Duration
A7: CollectionPhase | B7: SlideEvents | C7: iMotions | D7: Slideshow | E7: Reason slide was changed | L7: SE_CollectionPhase
A8: SourceStimuliName | B8: SlideEvents | C8: iMotions | D8: Slideshow | E8: Name of stimulus | L8: SE_SourceStimuliName
A9: EventSource | B9: External Events API iMotions.SysMonitor SysLoadMeter (v1) | C9: iMotions | D9: Event Source | E9: Can be used to filter data from: External Events API iMotions.SysMonitor SysLoadMeter (v1) | I9: Event Source | L9: Eventsource_External_Events_API_Imotions.Sysmonitor_Sysloadmeter_(V1)
A10: CPU Sys | B10: External Events API iMotions.SysMonitor SysLoadMeter (v1) | C10: iMotions | D10: iMotions Event API | I10: Other | J10: CPU System % | L10: Api_CPU_Sys
A11: Memory Sys | B11: External Events API iMotions.SysMonitor SysLoadMeter (v1) | C11: iMotions | D11: iMotions Event API | I11: Other | J11: Memory System % | L11: Api_Memory_Sys
A12: CPU Proc | B12: External Events API iMotions.SysMonitor SysLoadMeter (v1) | C12: iMotions | D12: iMotions Event API | I12: Other | J12: CPU iMotions % | L12: Api_CPU_Proc
A13: Memory Proc | B13: External Events API iMotions.SysMonitor SysLoadMeter (v1) | C13: iMotions | D13: iMotions Event API | I13: Other | J13: Memory iMotions Mb | L13: Api_Memory_Proc
A14: EventSource | B14: R Analysis GSR Peak Detection | C14: iMotions | D14: Event Source | E14: Can be used to filter data from: R Analysis GSR Peak Detection | I14: Event Source | L14: Eventsource_R_Analysis_GSR_Peak_Detection
A15: GSR Raw | B15: R Analysis GSR Peak Detection | C15: iMotions | D15: GSR(GSR Peak Detection) | E15: Raw GSR conductance from the GSR sensor. | F15: Microsiemens | G15: <U+00B5>S | I15: GSR Peak Detection (Shimmer 8956 GSR) | J15: GSR Raw | L15: GSR_PD_Raw
A16: GSR Interpolated | B16: R Analysis GSR Peak Detection | C16: iMotions | D16: GSR(GSR Peak Detection) | E16: GSR conductance after linear interpolation for gaps shorter than the threshold. | F16: Microsiemens | G16: <U+00B5>S | I16: GSR Peak Detection (Shimmer 8956 GSR) | J16: GSR Interpolated | L16: GSR_PD_Interpolated
A17: Tonic Signal | B17: R Analysis GSR Peak Detection | C17: iMotions | D17: GSR(GSR Peak Detection) | E17: Slow varying tonic component of GSR conductance. | F17: Microsiemens | G17: <U+00B5>S | I17: GSR Peak Detection (Shimmer 8956 GSR) | J17: Tonic Signal | L17: GSR_PD_TonicSignal
A18: Phasic Signal | B18: R Analysis GSR Peak Detection | C18: iMotions | D18: GSR(GSR Peak Detection) | E18: Fast varying phasic component of GSR conductance. | F18: Microsiemens | G18: <U+00B5>S | I18: GSR Peak Detection (Shimmer 8956 GSR) | J18: Phasic Signal | L18: GSR_PD_PhasicSignal
A19: Peak Detected | B19: R Analysis GSR Peak Detection | C19: iMotions | D19: GSR(GSR Peak Detection) | E19: Binary signal, where GSR samples falling within the onset and offset of the detected GSR peak are assigned a value of 1. Samples outside peaks are assigned a value of 0. | I19: GSR Peak Detection (Shimmer 8956 GSR) | J19: Peak Detected | L19: GSR_PD_PeakDetected
A20: Peak Amplitude | B20: R Analysis GSR Peak Detection | C20: iMotions | D20: GSR(GSR Peak Detection) | E20: Amplitude of the GSR peak, i.e. the difference between the maximum value of the phasic signal during the peak and its value at the onset. | F20: Microsiemens | G20: <U+00B5>S | I20: GSR Peak Detection (Shimmer 8956 GSR) | J20: Peak Amplitude | L20: GSR_PD_PeakAmplitude
A21: Peak Occurrences | B21: R Analysis GSR Peak Detection | C21: iMotions | D21: GSR(GSR Peak Detection) | E21: Binary signal, where the maximum point of each detected GSR peak is assigned a value of 1. Other samples are assigned a value of 0. | I21: GSR Peak Detection (Shimmer 8956 GSR) | J21: Peak Occurrences | L21: GSR_PD_PeakOccurrences
A22: Signal Interpolation | B22: R Analysis GSR Peak Detection | C22: iMotions | D22: GSR(GSR Peak Detection) | E22: Binary signal, where GSR samples obtained by linear interpolation are assigned a value of 1. Other samples that are not obtained by linear interpolation are assigned a value of 0. | I22: GSR Peak Detection (Shimmer 8956 GSR) | J22: Signal Interpolation | L22: GSR_PD_SignalInterpolation
A23: EventSource | B23: Shimmer 8956 GSR | C23: iMotions | D23: Event Source | E23: Can be used to filter data from: Shimmer 8956 GSR | I23: Event Source | L23: Eventsource_Shimmer_8956_GSR
A24: SampleNumber | B24: Shimmer 8956 GSR | C24: iMotions | D24: Counter | F24: Index | I24: Other | L24: Imotions_Sample_Counter_Shimmer_GSR
A25: Timestamp RAW | B25: Shimmer 8956 GSR | C25: Shimmer | D25: Other(Timestamp) | E25: Shimmer device timestamp (unitless) for when data was sampled | F25: Index | H25: Shimmer | I25: Other | J25: Timestamp RAW | K25: Raw | L25: Other_Timestamp_RAW_Shimmer
A26: Timestamp CAL | B26: Shimmer 8956 GSR | C26: Shimmer | D26: Other(Timestamp) | E26: Shimmer device timestamp for when data was sampled | F26: Millisecond | G26: ms | H26: Shimmer | I26: Other | J26: Timestamp CAL | K26: Calibrated | L26: Other_Timestamp_CAL_Shimmer
A27: System Timestamp CAL | B27: Shimmer 8956 GSR | C27: Shimmer | D27: Other(Timestamp) | E27: Shimmer SDK system timestamp when sample arrived at computer | F27: Millisecond | G27: ms | H27: Shimmer | I27: Other | J27: System Timestamp CAL | K27: Calibrated | L27: Other_System_Timestamp_CAL_Shimmer
A28: Wide Range Accelerometer X RAW | B28: Shimmer 8956 GSR | C28: Shimmer | D28: Accelerometer(Data) | E28: Raw motion data (unitless) along the X-axis from Shimmer ADC | F28: Index | H28: Shimmer | I28: Other | J28: Wide Range Accelerometer X RAW | K28: Raw | L28: Accelerometer_X_RAW_Shimmer
A29: Wide Range Accelerometer X CAL | B29: Shimmer 8956 GSR | C29: Shimmer | D29: Accelerometer(Data) | E29: Motion along the X-axis | F29: Meters pr second squared | G29: m/s^2 | H29: Shimmer | I29: Accelerometer | J29: Accelerometer X | K29: Calibrated | L29: Accelerometer_X_Shimmer
A30: Wide Range Accelerometer Y RAW | B30: Shimmer 8956 GSR | C30: Shimmer | D30: Accelerometer(Data) | E30: Raw motion data (unitless) along the Y-axis from Shimmer ADC | F30: Index | H30: Shimmer | I30: Other | J30: Wide Range Accelerometer Y RAW | K30: Raw | L30: Accelerometer_Y_RAW_Shimmer
A31: Wide Range Accelerometer Y CAL | B31: Shimmer 8956 GSR | C31: Shimmer | D31: Accelerometer(Data) | E31: Motion along the Y-axis | F31: Meters pr second squared | G31: m/s^2 | H31: Shimmer | I31: Accelerometer | J31: Accelerometer Y | K31: Calibrated | L31: Accelerometer_Y_Shimmer
A32: Wide Range Accelerometer Z RAW | B32: Shimmer 8956 GSR | C32: Shimmer | D32: Accelerometer(Data) | E32: Raw motion data (unitless) along the Z-axis from Shimmer ADC | F32: Index | H32: Shimmer | I32: Other | J32: Wide Range Accelerometer Z RAW | K32: Raw | L32: Accelerometer_Z_RAW_Shimmer
A33: Wide Range Accelerometer Z CAL | B33: Shimmer 8956 GSR | C33: Shimmer | D33: Accelerometer(Data) | E33: Motion along the Z-axis | F33: Meters pr second squared | G33: m/s^2 | H33: Shimmer | I33: Accelerometer | J33: Accelerometer Z | K33: Calibrated | L33: Accelerometer_Z_Shimmer
A34: VSenseBatt RAW | B34: Shimmer 8956 GSR | C34: Shimmer | D34: Other(Battery) | E34: Raw battery voltage data (unitless) | F34: Index | H34: Shimmer | I34: Other | J34: VSenseBatt RAW | K34: Raw | L34: Other_Vsensebatt_RAW_Shimmer
A35: VSenseBatt CAL | B35: Shimmer 8956 GSR | C35: Shimmer | D35: Other(Battery) | E35: Battery voltage | F35: Millivolt | G35: mV | H35: Shimmer | I35: Other | J35: VSenseBatt CAL | K35: Calibrated | L35: Other_Vsensebatt_CAL_Shimmer
A36: Internal ADC A13 PPG RAW | B36: Shimmer 8956 GSR | C36: Shimmer | D36: PPG(Data) | E36: PPG blood volume pulse (unitless) | F36: Index | H36: Shimmer | I36: Other | J36: Internal ADC A13 PPG RAW | K36: Raw | L36: PPG_Blood_Volumepulse_RAW_Shimmer
A37: Internal ADC A13 PPG CAL | B37: Shimmer 8956 GSR | C37: Shimmer | D37: PPG(Data) | E37: PPG blood volume pulse | F37: Millivolt | G37: mV | H37: Shimmer | I37: PPG | J37: PPG | K37: Calibrated | L37: PPG_Blood_Volumepulse_CAL_Shimmer
A38: GSR RAW | B38: Shimmer 8956 GSR | C38: Shimmer | D38: Other | E38: Galvanic skin response (unitless) | F38: Index | H38: Shimmer | I38: Other | J38: GSR RAW | K38: Raw | L38: Other_GSR_RAW_Shimmer
A39: GSR Resistance CAL | B39: Shimmer 8956 GSR | C39: Shimmer | D39: GSR(Data) | E39: GSR skin resistance | F39: Kilo Ohm | G39: k<U+03A9> | H39: Shimmer | I39: GSR | J39: GSR Resistance | K39: Calibrated | L39: GSR_Resistance_CAL_Shimmer
A40: GSR Conductance CAL | B40: Shimmer 8956 GSR | C40: Shimmer | D40: GSR(Data) | E40: GSR skin conductance | F40: Micro Siemens | G40: <U+03BC>S | H40: Shimmer | I40: GSR | J40: GSR Conductance | K40: Calibrated | L40: GSR_Conductance_CAL_Shimmer
...
