Workbook

Sheet README
A1: SIMULATED shelf study workbook (teaching material)
A3: Every number in this workbook is SIMULATED. It was generated by make_simulated_data.py
A4: (seed 20261037) to mirror the iMotions In-Store Shopper Report (Sensodyne POSM versus
A5: no POSM, eye tracking glasses) in direction and rough size only. No real shopper was recorded.
A7: Sheets:
A8: Data Individual AOI metrics export as imported. NA is kept as text, as iMotions writes it.
A9: Helper columns Z to AC: Keep (Valid data >= 70), TTFF_s, Dwell_pct_clean, Fixated.
A10: Summary Mean, SD, n by AOI and condition, built with COUNTIFS, AVERAGEIFS, STDEV.S(IF(...)).
A11: Sensodyne The Sensodyne_Products rows for kept respondents, sorted by condition.
A12: Welch t test (T.TEST type 3), hand computed t, Cohen's d, 95 percent CI.
A13: Survey Purchase intent, brand recall, product chosen; T.TEST and CORREL with attention.
A14: Check Values from analysis.R to confirm your formulas.
... A21: Companion files: analysis_excel_walkthrough.md (step by step), analysis.R (same analysis in R).

Sheet Data
A1: Study Name | B1: Respondent Name | C1: Gender | D1: Age | E1: Group | F1: Session Date | G1: Stimulus | H1: AOI Name | I1: Stimulus duration | J1: AOI duration (ms) | K1: AOI duration (%) | L1: Valid data | M1: Gaze Hit time parent (ms) | N1: Gaze Dwell count | O1: Gaze Dwell time (ms) | P1: Dwells with fixations | Q1: Revisit count | R1: Fixation count | S1: TTFF AOI (ms) | T1: TTFF parent (ms) | U1: TTFF max. (ms) | V1: Dwell time (ms) | W1: Dwell time (%) | X1: Fixation duration (ms) | Y1: First fixation duration (ms) | Z1: Keep | AA1: TTFF_s | AB1: Dwell_pct_clean | AC1: Fixated
A2: SIMULATED_ShelfStudy_POSM_vs_NoPOSM | B2: P01 | C2: M | D2: 18-24 | E2: POSM | F2: 2026-10-12 | G2: Shelf_POSM_GazeMap | H2: Sensodyne_Products | I2: 124961 | J2: 124961 | K2: 100 | L2: 93.8 | M2: 2171 | N2: 6 | O2: 24087 | P2: 6 | Q2: 5 | R2: 84 | S2: 2356 | T2: 2356 | U2: 2356 | V2: 22576 | W2: 18.07 | X2: 269 | Y2: 281 | Z2: =IF(L2>=70,"Yes","No") | AA2: =IF(ISNUMBER(T2),T2/1000,"") | AB2: =IF(ISNUMBER(W2),W2,0) | AC2: =IF(ISNUMBER(T2),1,0)
A3: SIMULATED_ShelfStudy_POSM_vs_NoPOSM | B3: P01 | C3: M | D3: 18-24 | E3: POSM | F3: 2026-10-12 | G3: Shelf_POSM_GazeMap | H3: Sensodyne_POSM_Wing | I3: 124961 | J3: 124961 | K3: 100 | L3: 93.8 | M3: 903 | N3: 3 | O3: 4594 | P3: 2 | Q3: 1 | R3: 21 | S3: 1088 | T3: 1088 | U3: 1088 | V3: 4152 | W3: 3.32 | X3: 198 | Y3: 174 | Z3: =IF(L3>=70,"Yes","No") | AA3: =IF(ISNUMBER(T3),T3/1000,"") | AB3: =IF(ISNUMBER(W3),W3,0) | AC3: =IF(ISNUMBER(T3),1,0)
A4: SIMULATED_ShelfStudy_POSM_vs_NoPOSM | B4: P01 | C4: M | D4: 18-24 | E4: POSM | F4: 2026-10-12 | G4: Shelf_POSM_GazeMap | H4: Competitor_A | I4: 124961 | J4: 124961 | K4: 100 | L4: 93.8 | M4: 1500 | N4: 4 | O4: 13909 | P4: 4 | Q4: 3 | R4: 55 | S4: 1717 | T4: 1717 | U4: 1717 | V4: 12645 | W4: 10.12 | X4: 230 | Y4: 206 | Z4: =IF(L4>=70,"Yes","No") | AA4: =IF(ISNUMBER(T4),T4/1000,"") | AB4: =IF(ISNUMBER(W4),W4,0) | AC4: =IF(ISNUMBER(T4),1,0)
A5: SIMULATED_ShelfStudy_POSM_vs_NoPOSM | B5: P01 | C5: M | D5: 18-24 | E5: POSM | F5: 2026-10-12 | G5: Shelf_POSM_GazeMap | H5: Competitor_B | I5: 124961 | J5: 124961 | K5: 100 | L5: 93.8 | M5: 3929 | N5: 4 | O5: 10269 | P5: 2 | Q5: 1 | R5: 33 | S5: 4015 | T5: 4015 | U5: 4015 | V5: 9538 | W5: 7.63 | X5: 289 | Y5: 222 | Z5: =IF(L5>=70,"Yes","No") | AA5: =IF(ISNUMBER(T5),T5/1000,"") | AB5: =IF(ISNUMBER(W5),W5,0) | AC5: =IF(ISNUMBER(T5),1,0)
A6: SIMULATED_ShelfStudy_POSM_vs_NoPOSM | B6: P01 | C6: M | D6: 18-24 | E6: POSM | F6: 2026-10-12 | G6: Shelf_POSM_GazeMap | H6: Price_Tags | I6: 124961 | J6: 124961 | K6: 100 | L6: 93.8 | M6: 9960 | N6: 3 | O6: 7125 | P6: 3 | Q6: 2 | R6: 17 | S6: 10222 | T6: 10222 | U6: 10222 | V6: 6223 | W6: 4.98 | X6: 366 | Y6: 219 | Z6: =IF(L6>=70,"Yes","No") | AA6: =IF(ISNUMBER(T6),T6/1000,"") | AB6: =IF(ISNUMBER(W6),W6,0) | AC6: =IF(ISNUMBER(T6),1,0)
A7: SIMULATED_ShelfStudy_POSM_vs_NoPOSM | B7: P01 | C7: M | D7: 18-24 | E7: POSM | F7: 2026-10-12 | G7: Shelf_POSM_GazeMap | H7: Shelf_Other | I7: 124961 | J7: 124961 | K7: 100 | L7: 93.8 | M7: 1186 | N7: 2 | O7: 16763 | P7: 2 | Q7: 1 | R7: 65 | S7: 1405 | T7: 1405 | U7: 1405 | V7: 16249 | W7: 13 | X7: 250 | Y7: 207 | Z7: =IF(L7>=70,"Yes","No") | AA7: =IF(ISNUMBER(T7),T7/1000,"") | AB7: =IF(ISNUMBER(W7),W7,0) | AC7: =IF(ISNUMBER(T7),1,0)
A8: SIMULATED_ShelfStudy_POSM_vs_NoPOSM | B8: P02 | C8: M | D8: 25-34 | E8: NoPOSM | F8: 2026-10-12 | G8: Shelf_NoPOSM_GazeMap | H8: Sensodyne_Products | I8: 127813 | J8: 127813 | K8: 100 | L8: 77.5 | M8: 3053 | N8: 10 | O8: 30735 | P8: 8 | Q8: 7 | R8: 79 | S8: 3254 | T8: 3254 | U8: 3254 | V8: 27772 | W8: 21.73 | X8: 352 | Y8: 131 | Z8: =IF(L8>=70,"Yes","No") | AA8: =IF(ISNUMBER(T8),T8/1000,"") | AB8: =IF(ISNUMBER(W8),W8,0) | AC8: =IF(ISNUMBER(T8),1,0)
A9: SIMULATED_ShelfStudy_POSM_vs_NoPOSM | B9: P02 | C9: M | D9: 25-34 | E9: NoPOSM | F9: 2026-10-12 | G9: Shelf_NoPOSM_GazeMap | H9: Competitor_A | I9: 127813 | J9: 127813 | K9: 100 | L9: 77.5 | M9: 1310 | N9: 9 | O9: 33132 | P9: 9 | Q9: 8 | R9: 101 | S9: 1497 | T9: 1497 | U9: 1497 | V9: 31762 | W9: 24.85 | X9: 314 | Y9: 207 | Z9: =IF(L9>=70,"Yes","No") | AA9: =IF(ISNUMBER(T9),T9/1000,"") | AB9: =IF(ISNUMBER(W9),W9,0) | AC9: =IF(ISNUMBER(T9),1,0)
A10: SIMULATED_ShelfStudy_POSM_vs_NoPOSM | B10: P02 | C10: M | D10: 25-34 | E10: NoPOSM | F10: 2026-10-12 | G10: Shelf_NoPOSM_GazeMap | H10: Competitor_B | I10: 127813 | J10: 127813 | K10: 100 | L10: 77.5 | M10: 2374 | N10: 5 | O10: 26425 | P10: 5 | Q10: 4 | R10: 60 | S10: 2632 | T10: 2632 | U10: 2632 | V10: 24651 | W10: 19.29 | X10: 411 | Y10: 221 | Z10: =IF(L10>=70,"Yes","No") | AA10: =IF(ISNUMBER(T10),T10/1000,"") | AB10: =IF(ISNUMBER(W10),W10,0) | AC10: =IF(ISNUMBER(T10),1,0)
A11: SIMULATED_ShelfStudy_POSM_vs_NoPOSM | B11: P02 | C11: M | D11: 25-34 | E11: NoPOSM | F11: 2026-10-12 | G11: Shelf_NoPOSM_GazeMap | H11: Price_Tags | I11: 127813 | J11: 127813 | K11: 100 | L11: 77.5 | M11: 11137 | N11: 1 | O11: 107 | P11: NA | Q11: NA | R11: NA | S11: NA | T11: NA | U11: 127813 | V11: NA | W11: NA | X11: NA | Y11: NA | Z11: =IF(L11>=70,"Yes","No") | AA11: =IF(ISNUMBER(T11),T11/1000,"") | AB11: =IF(ISNUMBER(W11),W11,0) | AC11: =IF(ISNUMBER(T11),1,0)
A12: SIMULATED_ShelfStudy_POSM_vs_NoPOSM | B12: P02 | C12: M | D12: 25-34 | E12: NoPOSM | F12: 2026-10-12 | G12: Shelf_NoPOSM_GazeMap | H12: Shelf_Other | I12: 127813 | J12: 127813 | K12: 100 | L12: 77.5 | M12: 952 | N12: 3 | O12: 19617 | P12: 3 | Q12: 2 | R12: 100 | S12: 1196 | T12: 1196 | U12: 1196 | V12: 18824 | W12: 14.73 | X12: 188 | Y12: 262 | Z12: =IF(L12>=70,"Yes","No") | AA12: =IF(ISNUMBER(T12),T12/1000,"") | AB12: =IF(ISNUMBER(W12),W12,0) | AC12: =IF(ISNUMBER(T12),1,0)
A13: SIMULATED_ShelfStudy_POSM_vs_NoPOSM | B13: P03 | C13: F | D13: 25-34 | E13: POSM | F13: 2026-10-12 | G13: Shelf_POSM_GazeMap | H13: Sensodyne_Products | I13: 111190 | J13: 111190 | K13: 100 | L13: 84.1 | M13: 2247 | N13: 1 | O13: 17159 | P13: 1 | Q13: 0 | R13: 64 | S13: 2532 | T13: 2532 | U13: 2532 | V13: 16028 | W13: 14.41 | X13: 250 | Y13: 275 | Z13: =IF(L13>=70,"Yes","No") | AA13: =IF(ISNUMBER(T13),T13/1000,"") | AB13: =IF(ISNUMBER(W13),W13,0) | AC13: =IF(ISNUMBER(T13),1,0)
A14: SIMULATED_ShelfStudy_POSM_vs_NoPOSM | B14: P03 | C14: F | D14: 25-34 | E14: POSM | F14: 2026-10-12 | G14: Shelf_POSM_GazeMap | H14: Sensodyne_POSM_Wing | I14: 111190 | J14: 111190 | K14: 100 | L14: 84.1 | M14: 1712 | N14: 3 | O14: 17885 | P14: 3 | Q14: 2 | R14: 71 | S14: 1821 | T14: 1821 | U14: 1821 | V14: 15679 | W14: 14.1 | X14: 221 | Y14: 218 | Z14: =IF(L14>=70,"Yes","No") | AA14: =IF(ISNUMBER(T14),T14/1000,"") | AB14: =IF(ISNUMBER(W14),W14,0) | AC14: =IF(ISNUMBER(T14),1,0)
A15: SIMULATED_ShelfStudy_POSM_vs_NoPOSM | B15: P03 | C15: F | D15: 25-34 | E15: POSM | F15: 2026-10-12 | G15: Shelf_POSM_GazeMap | H15: Competitor_A | I15: 111190 | J15: 111190 | K15: 100 | L15: 84.1 | M15: 1484 | N15: 7 | O15: 25428 | P15: 7 | Q15: 6 | R15: 73 | S15: 1656 | T15: 1656 | U15: 1656 | V15: 22882 | W15: 20.58 | X15: 313 | Y15: 331 | Z15: =IF(L15>=70,"Yes","No") | AA15: =IF(ISNUMBER(T15),T15/1000,"") | AB15: =IF(ISNUMBER(W15),W15,0) | AC15: =IF(ISNUMBER(T15),1,0)
A16: SIMULATED_ShelfStudy_POSM_vs_NoPOSM | B16: P03 | C16: F | D16: 25-34 | E16: POSM | F16: 2026-10-12 | G16: Shelf_POSM_GazeMap | H16: Competitor_B | I16: 111190 | J16: 111190 | K16: 100 | L16: 84.1 | M16: 4149 | N16: 5 | O16: 15424 | P16: 4 | Q16: 3 | R16: 67 | S16: 4370 | T16: 4370 | U16: 4370 | V16: 13788 | W16: 12.4 | X16: 206 | Y16: 199 | Z16: =IF(L16>=70,"Yes","No") | AA16: =IF(ISNUMBER(T16),T16/1000,"") | AB16: =IF(ISNUMBER(W16),W16,0) | AC16: =IF(ISNUMBER(T16),1,0)
A17: SIMULATED_ShelfStudy_POSM_vs_NoPOSM | B17: P03 | C17: F | D17: 25-34 | E17: POSM | F17: 2026-10-12 | G17: Shelf_POSM_GazeMap | H17: Price_Tags | I17: 111190 | J17: 111190 | K17: 100 | L17: 84.1 | M17: 11673 | N17: 3 | O17: 16762 | P17: 2 | Q17: 1 | R17: 59 | S17: 11818 | T17: 11818 | U17: 11818 | V17: 15403 | W17: 13.85 | X17: 261 | Y17: 200 | Z17: =IF(L17>=70,"Yes","No") | AA17: =IF(ISNUMBER(T17),T17/1000,"") | AB17: =IF(ISNUMBER(W17),W17,0) | AC17: =IF(ISNUMBER(T17),1,0)
A18: SIMULATED_ShelfStudy_POSM_vs_NoPOSM | B18: P03 | C18: F | D18: 25-34 | E18: POSM | F18: 2026-10-12 | G18: Shelf_POSM_GazeMap | H18: Shelf_Other | I18: 111190 | J18: 111190 | K18: 100 | L18: 84.1 | M18: 925 | N18: 5 | O18: 15602 | P18: 4 | Q18: 3 | R18: 45 | S18: 1164 | T18: 1164 | U18: 1164 | V18: 14770 | W18: 13.28 | X18: 328 | Y18: 160 | Z18: =IF(L18>=70,"Yes","No") | AA18: =IF(ISNUMBER(T18),T18/1000,"") | AB18: =IF(ISNUMBER(W18),W18,0) | AC18: =IF(ISNUMBER(T18),1,0)
A19: SIMULATED_ShelfStudy_POSM_vs_NoPOSM | B19: P04 | C19: M | D19: 18-24 | E19: NoPOSM | F19: 2026-10-12 | G19: Shelf_NoPOSM_GazeMap | H19: Sensodyne_Products | I19: 128698 | J19: 128698 | K19: 100 | L19: 82 | M19: 2995 | N19: 5 | O19: 17823 | P19: 4 | Q19: 3 | R19: 54 | S19: 3263 | T19: 3263 | U19: 3263 | V19: 16081 | W19: 12.49 | X19: 298 | Y19: 202 | Z19: =IF(L19>=70,"Yes","No") | AA19: =IF(ISNUMBER(T19),T19/1000,"") | AB19: =IF(ISNUMBER(W19),W19,0) | AC19: =IF(ISNUMBER(T19),1,0)
A20: SIMULATED_ShelfStudy_POSM_vs_NoPOSM | B20: P04 | C20: M | D20: 18-24 | E20: NoPOSM | F20: 2026-10-12 | G20: Shelf_NoPOSM_GazeMap | H20: Competitor_A | I20: 128698 | J20: 128698 | K20: 100 | L20: 82 | M20: 1258 | N20: 3 | O20: 21250 | P20: 3 | Q20: 2 | R20: 67 | S20: 1340 | T20: 1340 | U20: 1340 | V20: 19933 | W20: 15.49 | X20: 298 | Y20: 288 | Z20: =IF(L20>=70,"Yes","No") | AA20: =IF(ISNUMBER(T20),T20/1000,"") | AB20: =IF(ISNUMBER(W20),W20,0) | AC20: =IF(ISNUMBER(T20),1,0)
A21: SIMULATED_ShelfStudy_POSM_vs_NoPOSM | B21: P04 | C21: M | D21: 18-24 | E21: NoPOSM | F21: 2026-10-12 | G21: Shelf_NoPOSM_GazeMap | H21: Competitor_B | I21: 128698 | J21: 128698 | K21: 100 | L21: 82 | M21: 5126 | N21: 5 | O21: 24911 | P21: 4 | Q21: 3 | R21: 53 | S21: 5215 | T21: 5215 | U21: 5215 | V21: 22254 | W21: 17.29 | X21: 420 | Y21: 184 | Z21: =IF(L21>=70,"Yes","No") | AA21: =IF(ISNUMBER(T21),T21/1000,"") | AB21: =IF(ISNUMBER(W21),W21,0) | AC21: =IF(ISNUMBER(T21),1,0)
A22: SIMULATED_ShelfStudy_POSM_vs_NoPOSM | B22: P04 | C22: M | D22: 18-24 | E22: NoPOSM | F22: 2026-10-12 | G22: Shelf_NoPOSM_GazeMap | H22: Price_Tags | I22: 128698 | J22: 128698 | K22: 100 | L22: 82 | M22: 15058 | N22: 5 | O22: 12166 | P22: 4 | Q22: 3 | R22: 53 | S22: 15274 | T22: 15274 | U22: 15274 | V22: 11197 | W22: 8.7 | X22: 211 | Y22: 119 | Z22: =IF(L22>=70,"Yes","No") | AA22: =IF(ISNUMBER(T22),T22/1000,"") | AB22: =IF(ISNUMBER(W22),W22,0) | AC22: =IF(ISNUMBER(T22),1,0)
A23: SIMULATED_ShelfStudy_POSM_vs_NoPOSM | B23: P04 | C23: M | D23: 18-24 | E23: NoPOSM | F23: 2026-10-12 | G23: Shelf_NoPOSM_GazeMap | H23: Shelf_Other | I23: 128698 | J23: 128698 | K23: 100 | L23: 82 | M23: 2338 | N23: 5 | O23: 17121 | P23: 4 | Q23: 3 | R23: 73 | S23: 2617 | T23: 2617 | U23: 2617 | V23: 15113 | W23: 11.74 | X23: 207 | Y23: 305 | Z23: =IF(L23>=70,"Yes","No") | AA23: =IF(ISNUMBER(T23),T23/1000,"") | AB23: =IF(ISNUMBER(W23),W23,0) | AC23: =IF(ISNUMBER(T23),1,0)
... A48: SIMULATED_ShelfStudy_POSM_vs_NoPOSM | B48: P09 | C48: M | D48: 25-34 | E48: POSM | F48: 2026-10-13 | G48: Shelf_POSM_GazeMap | H48: Competitor_A | I48: 139162 | J48: 139162 | K48: 100 | L48: 87 | M48: 2597 | N48: 4 | O48: 21463 | P48: 4 | Q48: 3 | R48: 61 | S48: 2722 | T48: 2722 | U48: 2722 | V48: 20105 | W48: 14.45 | X48: 330 | Y48: 196 | Z48: =IF(L48>=70,"Yes","No") | AA48: =IF(ISNUMBER(T48),T48/1000,"") | AB48: =IF(ISNUMBER(W48),W48,0) | AC48: =IF(ISNUMBER(T48),1,0)
A49: SIMULATED_ShelfStudy_POSM_vs_NoPOSM | B49: P09 | C49: M | D49: 25-34 | E49: POSM | F49: 2026-10-13 | G49: Shelf_POSM_GazeMap | H49: Competitor_B | I49: 139162 | J49: 139162 | K49: 100 | L49: 87 | M49: 4358 | N49: 1 | O49: 150 | P49: NA | Q49: NA | R49: NA | S49: NA | T49: NA | U49: 139162 | V49: NA | W49: NA | X49: NA | Y49: NA | Z49: =IF(L49>=70,"Yes","No") | AA49: =IF(ISNUMBER(T49),T49/1000,"") | AB49: =IF(ISNUMBER(W49),W49,0) | AC49: =IF(ISNUMBER(T49),1,0)
A50: SIMULATED_ShelfStudy_POSM_vs_NoPOSM | B50: P09 | C50: M | D50: 25-34 | E50: POSM | F50: 2026-10-13 | G50: Shelf_POSM_GazeMap | H50: Price_Tags | I50: 139162 | J50: 139162 | K50: 100 | L50: 87 | M50: 9138 | N50: 6 | O50: 19224 | P50: 5 | Q50: 4 | R50: 75 | S50: 9431 | T50: 9431 | U50: 9431 | V50: 17641 | W50: 12.68 | X50: 235 | Y50: 273 | Z50: =IF(L50>=70,"Yes","No") | AA50: =IF(ISNUMBER(T50),T50/1000,"") | AB50: =IF(ISNUMBER(W50),W50,0) | AC50: =IF(ISNUMBER(T50),1,0)
A51: SIMULATED_ShelfStudy_POSM_vs_NoPOSM | B51: P09 | C51: M | D51: 25-34 | E51: POSM | F51: 2026-10-13 | G51: Shelf_POSM_GazeMap | H51: Shelf_Other | I51: 139162 | J51: 139162 | K51: 100 | L51: 87 | M51: 623 | N51: 6 | O51: 31010 | P51: 5 | Q51: 4 | R51: 122 | S51: 787 | T51: 787 | U51: 787 | V51: 27507 | W51: 19.77 | X51: 225 | Y51: 367 | Z51: =IF(L51>=70,"Yes","No") | AA51: =IF(ISNUMBER(T51),T51/1000,"") | AB51: =IF(ISNUMBER(W51),W51,0) | AC51: =IF(ISNUMBER(T51),1,0)
A52: SIMULATED_ShelfStudy_POSM_vs_NoPOSM | B52: P10 | C52: F | D52: 18-24 | E52: NoPOSM | F52: 2026-10-13 | G52: Shelf_NoPOSM_GazeMap | H52: Sensodyne_Products | I52: 142738 | J52: 142738 | K52: 100 | L52: 87.4 | M52: 2176 | N52: 4 | O52: 11053 | P52: 3 | Q52: 2 | R52: 30 | S52: 2393 | T52: 2393 | U52: 2393 | V52: 9972 | W52: 6.99 | X52: 332 | Y52: 188 | Z52: =IF(L52>=70,"Yes","No") | AA52: =IF(ISNUMBER(T52),T52/1000,"") | AB52: =IF(ISNUMBER(W52),W52,0) | AC52: =IF(ISNUMBER(T52),1,0)
A53: SIMULATED_ShelfStudy_POSM_vs_NoPOSM | B53: P10 | C53: F | D53: 18-24 | E53: NoPOSM | F53: 2026-10-13 | G53: Shelf_NoPOSM_GazeMap | H53: Competitor_A | I53: 142738 | J53: 142738 | K53: 100 | L53: 87.4 | M53: 3200 | N53: 6 | O53: 17975 | P53: 6 | Q53: 5 | R53: 53 | S53: 3394 | T53: 3394 | U53: 3394 | V53: 16966 | W53: 11.89 | X53: 320 | Y53: 201 | Z53: =IF(L53>=70,"Yes","No") | AA53: =IF(ISNUMBER(T53),T53/1000,"") | AB53: =IF(ISNUMBER(W53),W53,0) | AC53: =IF(ISNUMBER(T53),1,0)
A54: SIMULATED_ShelfStudy_POSM_vs_NoPOSM | B54: P10 | C54: F | D54: 18-24 | E54: NoPOSM | F54: 2026-10-13 | G54: Shelf_NoPOSM_GazeMap | H54: Competitor_B | I54: 142738 | J54: 142738 | K54: 100 | L54: 87.4 | M54: 3537 | N54: 2 | O54: 12257 | P54: 2 | Q54: 1 | R54: 38 | S54: 3740 | T54: 3740 | U54: 3740 | V54: 11418 | W54: 8 | X54: 300 | Y54: 268 | Z54: =IF(L54>=70,"Yes","No") | AA54: =IF(ISNUMBER(T54),T54/1000,"") | AB54: =IF(ISNUMBER(W54),W54,0) | AC54: =IF(ISNUMBER(T54),1,0)
A55: SIMULATED_ShelfStudy_POSM_vs_NoPOSM | B55: P10 | C55: F | D55: 18-24 | E55: NoPOSM | F55: 2026-10-13 | G55: Shelf_NoPOSM_GazeMap | H55: Price_Tags | I55: 142738 | J55: 142738 | K55: 100 | L55: 87.4 | M55: 7931 | N55: 3 | O55: 11172 | P55: 3 | Q55: 2 | R55: 50 | S55: 8212 | T55: 8212 | U55: 8212 | V55: 10215 | W55: 7.16 | X55: 204 | Y55: 222 | Z55: =IF(L55>=70,"Yes","No") | AA55: =IF(ISNUMBER(T55),T55/1000,"") | AB55: =IF(ISNUMBER(W55),W55,0) | AC55: =IF(ISNUMBER(T55),1,0)
A56: SIMULATED_ShelfStudy_POSM_vs_NoPOSM | B56: P10 | C56: F | D56: 18-24 | E56: NoPOSM | F56: 2026-10-13 | G56: Shelf_NoPOSM_GazeMap | H56: Shelf_Other | I56: 142738 | J56: 142738 | K56: 100 | L56: 87.4 | M56: 1277 | N56: 5 | O56: 17474 | P56: 4 | Q56: 3 | R56: 67 | S56: 1486 | T56: 1486 | U56: 1486 | V56: 15823 | W56: 11.09 | X56: 236 | Y56: 141 | Z56: =IF(L56>=70,"Yes","No") | AA56: =IF(ISNUMBER(T56),T56/1000,"") | AB56: =IF(ISNUMBER(W56),W56,0) | AC56: =IF(ISNUMBER(T56),1,0)
A57: SIMULATED_ShelfStudy_POSM_vs_NoPOSM | B57: P11 | C57: F | D57: 45-59 | E57: POSM | F57: 2026-10-13 | G57: Shelf_POSM_GazeMap | H57: Sensodyne_Products | I57: 207664 | J57: 207664 | K57: 100 | L57: 80.5 | M57: 1374 | N57: 6 | O57: 21016 | P57: 6 | Q57: 5 | R57: 72 | S57: 1622 | T57: 1622 | U57: 1622 | V57: 20354 | W57: 9.8 | X57: 283 | Y57: 220 | Z57: =IF(L57>=70,"Yes","No") | AA57: =IF(ISNUMBER(T57),T57/1000,"") | AB57: =IF(ISNUMBER(W57),W57,0) | AC57: =IF(ISNUMBER(T57),1,0)
A58: SIMULATED_ShelfStudy_POSM_vs_NoPOSM | B58: P11 | C58: F | D58: 45-59 | E58: POSM | F58: 2026-10-13 | G58: Shelf_POSM_GazeMap | H58: Sensodyne_POSM_Wing | I58: 207664 | J58: 207664 | K58: 100 | L58: 80.5 | M58: 2554 | N58: 1 | O58: 7528 | P58: 1 | Q58: 0 | R58: 17 | S58: 2831 | T58: 2831 | U58: 2831 | V58: 6557 | W58: 3.16 | X58: 386 | Y58: 269 | Z58: =IF(L58>=70,"Yes","No") | AA58: =IF(ISNUMBER(T58),T58/1000,"") | AB58: =IF(ISNUMBER(W58),W58,0) | AC58: =IF(ISNUMBER(T58),1,0)
A59: SIMULATED_ShelfStudy_POSM_vs_NoPOSM | B59: P11 | C59: F | D59: 45-59 | E59: POSM | F59: 2026-10-13 | G59: Shelf_POSM_GazeMap | H59: Competitor_A | I59: 207664 | J59: 207664 | K59: 100 | L59: 80.5 | M59: 3181 | N59: 2 | O59: 24264 | P59: 2 | Q59: 1 | R59: 86 | S59: 3440 | T59: 3440 | U59: 3440 | V59: 23197 | W59: 11.17 | X59: 270 | Y59: 157 | Z59: =IF(L59>=70,"Yes","No") | AA59: =IF(ISNUMBER(T59),T59/1000,"") | AB59: =IF(ISNUMBER(W59),W59,0) | AC59: =IF(ISNUMBER(T59),1,0)
A60: SIMULATED_ShelfStudy_POSM_vs_NoPOSM | B60: P11 | C60: F | D60: 45-59 | E60: POSM | F60: 2026-10-13 | G60: Shelf_POSM_GazeMap | H60: Competitor_B | I60: 207664 | J60: 207664 | K60: 100 | L60: 80.5 | M60: 7425 | N60: 5 | O60: 16909 | P60: 5 | Q60: 4 | R60: 47 | S60: 7700 | T60: 7700 | U60: 7700 | V60: 16304 | W60: 7.85 | X60: 347 | Y60: 192 | Z60: =IF(L60>=70,"Yes","No") | AA60: =IF(ISNUMBER(T60),T60/1000,"") | AB60: =IF(ISNUMBER(W60),W60,0) | AC60: =IF(ISNUMBER(T60),1,0)
A61: SIMULATED_ShelfStudy_POSM_vs_NoPOSM | B61: P11 | C61: F | D61: 45-59 | E61: POSM | F61: 2026-10-13 | G61: Shelf_POSM_GazeMap | H61: Price_Tags | I61: 207664 | J61: 207664 | K61: 100 | L61: 80.5 | M61: 11429 | N61: 2 | O61: 7706 | P61: 2 | Q61: 1 | R61: 32 | S61: 11517 | T61: 11517 | U61: 11517 | V61: 7310 | W61: 3.52 | X61: 228 | Y61: 502 | Z61: =IF(L61>=70,"Yes","No") | AA61: =IF(ISNUMBER(T61),T61/1000,"") | AB61: =IF(ISNUMBER(W61),W61,0) | AC61: =IF(ISNUMBER(T61),1,0)
... A66: SIMULATED_ShelfStudy_POSM_vs_NoPOSM | B66: P12 | C66: M | D66: 45-59 | E66: NoPOSM | F66: 2026-10-13 | G66: Shelf_NoPOSM_GazeMap | H66: Price_Tags | I66: 157818 | J66: 157818 | K66: 100 | L66: 74.6 | M66: 8640 | N66: 2 | O66: 16925 | P66: 2 | Q66: 1 | R66: 48 | S66: 8739 | T66: 8739 | U66: 8739 | V66: 15051 | W66: 9.54 | X66: 314 | Y66: 190 | Z66: =IF(L66>=70,"Yes","No") | AA66: =IF(ISNUMBER(T66),T66/1000,"") | AB66: =IF(ISNUMBER(W66),W66,0) | AC66: =IF(ISNUMBER(T66),1,0)
A67: SIMULATED_ShelfStudy_POSM_vs_NoPOSM | B67: P12 | C67: M | D67: 45-59 | E67: NoPOSM | F67: 2026-10-13 | G67: Shelf_NoPOSM_GazeMap | H67: Shelf_Other | I67: 157818 | J67: 157818 | K67: 100 | L67: 74.6 | M67: NA | N67: NA | O67: NA | P67: NA | Q67: NA | R67: NA | S67: NA | T67: NA | U67: 157818 | V67: NA | W67: NA | X67: NA | Y67: NA | Z67: =IF(L67>=70,"Yes","No") | AA67: =IF(ISNUMBER(T67),T67/1000,"") | AB67: =IF(ISNUMBER(W67),W67,0) | AC67: =IF(ISNUMBER(T67),1,0)
A68: SIMULATED_ShelfStudy_POSM_vs_NoPOSM | B68: P13 | C68: F | D68: 35-44 | E68: POSM | F68: 2026-10-14 | G68: Shelf_POSM_GazeMap | H68: Sensodyne_Products | I68: 131329 | J68: 131329 | K68: 100 | L68: 89.9 | M68: 1065 | N68: 7 | O68: 40487 | P68: 7 | Q68: 6 | R68: 125 | S68: 1235 | T68: 1235 | U68: 1235 | V68: 36135 | W68: 27.51 | X68: 289 | Y68: 170 | Z68: =IF(L68>=70,"Yes","No") | AA68: =IF(ISNUMBER(T68),T68/1000,"") | AB68: =IF(ISNUMBER(W68),W68,0) | AC68: =IF(ISNUMBER(T68),1,0)
...

Sheet Summary
A1: Descriptive table by AOI and condition (kept respondents only). SIMULATED data.
A2: n = kept respondents with a row for the AOI; Respondent ratio = percent who fixated the AOI; TTFF statistics use fixators only; dwell statistics count never fixated AOIs as 0.
A4: AOI | B4: Condition | C4: n | D4: Respondent ratio (%) | E4: n with TTFF | F4: TTFF mean (s) | G4: TTFF SD (s) | H4: Dwell time mean (%) | I4: Dwell time SD (%) | J4: Fixation count mean
A5: Sensodyne_Products | B5: NoPOSM | C5: =COUNTIFS(Data!$E$2:$E$166,$B5,Data!$H$2:$H$166,$A5,Data!$Z$2:$Z$166,"Yes") | D5: =100*AVERAGEIFS(Data!$AC$2:$AC$166,Data!$E$2:$E$166,$B5,Data!$H$2:$H$166,$A5,Data!$Z$2:$Z$166,"Yes") | E5: =COUNTIFS(Data!$E$2:$E$166,$B5,Data!$H$2:$H$166,$A5,Data!$Z$2:$Z$166,"Yes",Data!$AA$2:$AA$166,">0") | F5: =AVERAGEIFS(Data!$AA$2:$AA$166,Data!$E$2:$E$166,$B5,Data!$H$2:$H$166,$A5,Data!$Z$2:$Z$166,"Yes") | G5: {=_xlfn.STDEV.S(IF((Data!$E$2:$E$166=$B5)*(Data!$H$2:$H$166=$A5)*(Data!$Z$2:$Z$166="Yes")*ISNUMBER(Data!$AA$2:$AA$166),Data!$AA$2:$AA$166))} | H5: =AVERAGEIFS(Data!$AB$2:$AB$166,Data!$E$2:$E$166,$B5,Data!$H$2:$H$166,$A5,Data!$Z$2:$Z$166,"Yes") | I5: {=_xlfn.STDEV.S(IF((Data!$E$2:$E$166=$B5)*(Data!$H$2:$H$166=$A5)*(Data!$Z$2:$Z$166="Yes"),Data!$AB$2:$AB$166))} | J5: =AVERAGEIFS(Data!$R$2:$R$166,Data!$E$2:$E$166,$B5,Data!$H$2:$H$166,$A5,Data!$Z$2:$Z$166,"Yes")
A6: Sensodyne_Products | B6: POSM | C6: =COUNTIFS(Data!$E$2:$E$166,$B6,Data!$H$2:$H$166,$A6,Data!$Z$2:$Z$166,"Yes") | D6: =100*AVERAGEIFS(Data!$AC$2:$AC$166,Data!$E$2:$E$166,$B6,Data!$H$2:$H$166,$A6,Data!$Z$2:$Z$166,"Yes") | E6: =COUNTIFS(Data!$E$2:$E$166,$B6,Data!$H$2:$H$166,$A6,Data!$Z$2:$Z$166,"Yes",Data!$AA$2:$AA$166,">0") | F6: =AVERAGEIFS(Data!$AA$2:$AA$166,Data!$E$2:$E$166,$B6,Data!$H$2:$H$166,$A6,Data!$Z$2:$Z$166,"Yes") | G6: {=_xlfn.STDEV.S(IF((Data!$E$2:$E$166=$B6)*(Data!$H$2:$H$166=$A6)*(Data!$Z$2:$Z$166="Yes")*ISNUMBER(Data!$AA$2:$AA$166),Data!$AA$2:$AA$166))} | H6: =AVERAGEIFS(Data!$AB$2:$AB$166,Data!$E$2:$E$166,$B6,Data!$H$2:$H$166,$A6,Data!$Z$2:$Z$166,"Yes") | I6: {=_xlfn.STDEV.S(IF((Data!$E$2:$E$166=$B6)*(Data!$H$2:$H$166=$A6)*(Data!$Z$2:$Z$166="Yes"),Data!$AB$2:$AB$166))} | J6: =AVERAGEIFS(Data!$R$2:$R$166,Data!$E$2:$E$166,$B6,Data!$H$2:$H$166,$A6,Data!$Z$2:$Z$166,"Yes")
A7: Sensodyne_POSM_Wing | B7: POSM | C7: =COUNTIFS(Data!$E$2:$E$166,$B7,Data!$H$2:$H$166,$A7,Data!$Z$2:$Z$166,"Yes") | D7: =100*AVERAGEIFS(Data!$AC$2:$AC$166,Data!$E$2:$E$166,$B7,Data!$H$2:$H$166,$A7,Data!$Z$2:$Z$166,"Yes") | E7: =COUNTIFS(Data!$E$2:$E$166,$B7,Data!$H$2:$H$166,$A7,Data!$Z$2:$Z$166,"Yes",Data!$AA$2:$AA$166,">0") | F7: =AVERAGEIFS(Data!$AA$2:$AA$166,Data!$E$2:$E$166,$B7,Data!$H$2:$H$166,$A7,Data!$Z$2:$Z$166,"Yes") | G7: {=_xlfn.STDEV.S(IF((Data!$E$2:$E$166=$B7)*(Data!$H$2:$H$166=$A7)*(Data!$Z$2:$Z$166="Yes")*ISNUMBER(Data!$AA$2:$AA$166),Data!$AA$2:$AA$166))} | H7: =AVERAGEIFS(Data!$AB$2:$AB$166,Data!$E$2:$E$166,$B7,Data!$H$2:$H$166,$A7,Data!$Z$2:$Z$166,"Yes") | I7: {=_xlfn.STDEV.S(IF((Data!$E$2:$E$166=$B7)*(Data!$H$2:$H$166=$A7)*(Data!$Z$2:$Z$166="Yes"),Data!$AB$2:$AB$166))} | J7: =AVERAGEIFS(Data!$R$2:$R$166,Data!$E$2:$E$166,$B7,Data!$H$2:$H$166,$A7,Data!$Z$2:$Z$166,"Yes")
A8: Competitor_A | B8: NoPOSM | C8: =COUNTIFS(Data!$E$2:$E$166,$B8,Data!$H$2:$H$166,$A8,Data!$Z$2:$Z$166,"Yes") | D8: =100*AVERAGEIFS(Data!$AC$2:$AC$166,Data!$E$2:$E$166,$B8,Data!$H$2:$H$166,$A8,Data!$Z$2:$Z$166,"Yes") | E8: =COUNTIFS(Data!$E$2:$E$166,$B8,Data!$H$2:$H$166,$A8,Data!$Z$2:$Z$166,"Yes",Data!$AA$2:$AA$166,">0") | F8: =AVERAGEIFS(Data!$AA$2:$AA$166,Data!$E$2:$E$166,$B8,Data!$H$2:$H$166,$A8,Data!$Z$2:$Z$166,"Yes") | G8: {=_xlfn.STDEV.S(IF((Data!$E$2:$E$166=$B8)*(Data!$H$2:$H$166=$A8)*(Data!$Z$2:$Z$166="Yes")*ISNUMBER(Data!$AA$2:$AA$166),Data!$AA$2:$AA$166))} | H8: =AVERAGEIFS(Data!$AB$2:$AB$166,Data!$E$2:$E$166,$B8,Data!$H$2:$H$166,$A8,Data!$Z$2:$Z$166,"Yes") | I8: {=_xlfn.STDEV.S(IF((Data!$E$2:$E$166=$B8)*(Data!$H$2:$H$166=$A8)*(Data!$Z$2:$Z$166="Yes"),Data!$AB$2:$AB$166))} | J8: =AVERAGEIFS(Data!$R$2:$R$166,Data!$E$2:$E$166,$B8,Data!$H$2:$H$166,$A8,Data!$Z$2:$Z$166,"Yes")
A9: Competitor_A | B9: POSM | C9: =COUNTIFS(Data!$E$2:$E$166,$B9,Data!$H$2:$H$166,$A9,Data!$Z$2:$Z$166,"Yes") | D9: =100*AVERAGEIFS(Data!$AC$2:$AC$166,Data!$E$2:$E$166,$B9,Data!$H$2:$H$166,$A9,Data!$Z$2:$Z$166,"Yes") | E9: =COUNTIFS(Data!$E$2:$E$166,$B9,Data!$H$2:$H$166,$A9,Data!$Z$2:$Z$166,"Yes",Data!$AA$2:$AA$166,">0") | F9: =AVERAGEIFS(Data!$AA$2:$AA$166,Data!$E$2:$E$166,$B9,Data!$H$2:$H$166,$A9,Data!$Z$2:$Z$166,"Yes") | G9: {=_xlfn.STDEV.S(IF((Data!$E$2:$E$166=$B9)*(Data!$H$2:$H$166=$A9)*(Data!$Z$2:$Z$166="Yes")*ISNUMBER(Data!$AA$2:$AA$166),Data!$AA$2:$AA$166))} | H9: =AVERAGEIFS(Data!$AB$2:$AB$166,Data!$E$2:$E$166,$B9,Data!$H$2:$H$166,$A9,Data!$Z$2:$Z$166,"Yes") | I9: {=_xlfn.STDEV.S(IF((Data!$E$2:$E$166=$B9)*(Data!$H$2:$H$166=$A9)*(Data!$Z$2:$Z$166="Yes"),Data!$AB$2:$AB$166))} | J9: =AVERAGEIFS(Data!$R$2:$R$166,Data!$E$2:$E$166,$B9,Data!$H$2:$H$166,$A9,Data!$Z$2:$Z$166,"Yes")
A10: Competitor_B | B10: NoPOSM | C10: =COUNTIFS(Data!$E$2:$E$166,$B10,Data!$H$2:$H$166,$A10,Data!$Z$2:$Z$166,"Yes") | D10: =100*AVERAGEIFS(Data!$AC$2:$AC$166,Data!$E$2:$E$166,$B10,Data!$H$2:$H$166,$A10,Data!$Z$2:$Z$166,"Yes") | E10: =COUNTIFS(Data!$E$2:$E$166,$B10,Data!$H$2:$H$166,$A10,Data!$Z$2:$Z$166,"Yes",Data!$AA$2:$AA$166,">0") | F10: =AVERAGEIFS(Data!$AA$2:$AA$166,Data!$E$2:$E$166,$B10,Data!$H$2:$H$166,$A10,Data!$Z$2:$Z$166,"Yes") | G10: {=_xlfn.STDEV.S(IF((Data!$E$2:$E$166=$B10)*(Data!$H$2:$H$166=$A10)*(Data!$Z$2:$Z$166="Yes")*ISNUMBER(Data!$AA$2:$AA$166),Data!$AA$2:$AA$166))} | H10: =AVERAGEIFS(Data!$AB$2:$AB$166,Data!$E$2:$E$166,$B10,Data!$H$2:$H$166,$A10,Data!$Z$2:$Z$166,"Yes") | I10: {=_xlfn.STDEV.S(IF((Data!$E$2:$E$166=$B10)*(Data!$H$2:$H$166=$A10)*(Data!$Z$2:$Z$166="Yes"),Data!$AB$2:$AB$166))} | J10: =AVERAGEIFS(Data!$R$2:$R$166,Data!$E$2:$E$166,$B10,Data!$H$2:$H$166,$A10,Data!$Z$2:$Z$166,"Yes")
A11: Competitor_B | B11: POSM | C11: =COUNTIFS(Data!$E$2:$E$166,$B11,Data!$H$2:$H$166,$A11,Data!$Z$2:$Z$166,"Yes") | D11: =100*AVERAGEIFS(Data!$AC$2:$AC$166,Data!$E$2:$E$166,$B11,Data!$H$2:$H$166,$A11,Data!$Z$2:$Z$166,"Yes") | E11: =COUNTIFS(Data!$E$2:$E$166,$B11,Data!$H$2:$H$166,$A11,Data!$Z$2:$Z$166,"Yes",Data!$AA$2:$AA$166,">0") | F11: =AVERAGEIFS(Data!$AA$2:$AA$166,Data!$E$2:$E$166,$B11,Data!$H$2:$H$166,$A11,Data!$Z$2:$Z$166,"Yes") | G11: {=_xlfn.STDEV.S(IF((Data!$E$2:$E$166=$B11)*(Data!$H$2:$H$166=$A11)*(Data!$Z$2:$Z$166="Yes")*ISNUMBER(Data!$AA$2:$AA$166),Data!$AA$2:$AA$166))} | H11: =AVERAGEIFS(Data!$AB$2:$AB$166,Data!$E$2:$E$166,$B11,Data!$H$2:$H$166,$A11,Data!$Z$2:$Z$166,"Yes") | I11: {=_xlfn.STDEV.S(IF((Data!$E$2:$E$166=$B11)*(Data!$H$2:$H$166=$A11)*(Data!$Z$2:$Z$166="Yes"),Data!$AB$2:$AB$166))} | J11: =AVERAGEIFS(Data!$R$2:$R$166,Data!$E$2:$E$166,$B11,Data!$H$2:$H$166,$A11,Data!$Z$2:$Z$166,"Yes")
A12: Price_Tags | B12: NoPOSM | C12: =COUNTIFS(Data!$E$2:$E$166,$B12,Data!$H$2:$H$166,$A12,Data!$Z$2:$Z$166,"Yes") | D12: =100*AVERAGEIFS(Data!$AC$2:$AC$166,Data!$E$2:$E$166,$B12,Data!$H$2:$H$166,$A12,Data!$Z$2:$Z$166,"Yes") | E12: =COUNTIFS(Data!$E$2:$E$166,$B12,Data!$H$2:$H$166,$A12,Data!$Z$2:$Z$166,"Yes",Data!$AA$2:$AA$166,">0") | F12: =AVERAGEIFS(Data!$AA$2:$AA$166,Data!$E$2:$E$166,$B12,Data!$H$2:$H$166,$A12,Data!$Z$2:$Z$166,"Yes") | G12: {=_xlfn.STDEV.S(IF((Data!$E$2:$E$166=$B12)*(Data!$H$2:$H$166=$A12)*(Data!$Z$2:$Z$166="Yes")*ISNUMBER(Data!$AA$2:$AA$166),Data!$AA$2:$AA$166))} | H12: =AVERAGEIFS(Data!$AB$2:$AB$166,Data!$E$2:$E$166,$B12,Data!$H$2:$H$166,$A12,Data!$Z$2:$Z$166,"Yes") | I12: {=_xlfn.STDEV.S(IF((Data!$E$2:$E$166=$B12)*(Data!$H$2:$H$166=$A12)*(Data!$Z$2:$Z$166="Yes"),Data!$AB$2:$AB$166))} | J12: =AVERAGEIFS(Data!$R$2:$R$166,Data!$E$2:$E$166,$B12,Data!$H$2:$H$166,$A12,Data!$Z$2:$Z$166,"Yes")
A13: Price_Tags | B13: POSM | C13: =COUNTIFS(Data!$E$2:$E$166,$B13,Data!$H$2:$H$166,$A13,Data!$Z$2:$Z$166,"Yes") | D13: =100*AVERAGEIFS(Data!$AC$2:$AC$166,Data!$E$2:$E$166,$B13,Data!$H$2:$H$166,$A13,Data!$Z$2:$Z$166,"Yes") | E13: =COUNTIFS(Data!$E$2:$E$166,$B13,Data!$H$2:$H$166,$A13,Data!$Z$2:$Z$166,"Yes",Data!$AA$2:$AA$166,">0") | F13: =AVERAGEIFS(Data!$AA$2:$AA$166,Data!$E$2:$E$166,$B13,Data!$H$2:$H$166,$A13,Data!$Z$2:$Z$166,"Yes") | G13: {=_xlfn.STDEV.S(IF((Data!$E$2:$E$166=$B13)*(Data!$H$2:$H$166=$A13)*(Data!$Z$2:$Z$166="Yes")*ISNUMBER(Data!$AA$2:$AA$166),Data!$AA$2:$AA$166))} | H13: =AVERAGEIFS(Data!$AB$2:$AB$166,Data!$E$2:$E$166,$B13,Data!$H$2:$H$166,$A13,Data!$Z$2:$Z$166,"Yes") | I13: {=_xlfn.STDEV.S(IF((Data!$E$2:$E$166=$B13)*(Data!$H$2:$H$166=$A13)*(Data!$Z$2:$Z$166="Yes"),Data!$AB$2:$AB$166))} | J13: =AVERAGEIFS(Data!$R$2:$R$166,Data!$E$2:$E$166,$B13,Data!$H$2:$H$166,$A13,Data!$Z$2:$Z$166,"Yes")
A14: Shelf_Other | B14: NoPOSM | C14: =COUNTIFS(Data!$E$2:$E$166,$B14,Data!$H$2:$H$166,$A14,Data!$Z$2:$Z$166,"Yes") | D14: =100*AVERAGEIFS(Data!$AC$2:$AC$166,Data!$E$2:$E$166,$B14,Data!$H$2:$H$166,$A14,Data!$Z$2:$Z$166,"Yes") | E14: =COUNTIFS(Data!$E$2:$E$166,$B14,Data!$H$2:$H$166,$A14,Data!$Z$2:$Z$166,"Yes",Data!$AA$2:$AA$166,">0") | F14: =AVERAGEIFS(Data!$AA$2:$AA$166,Data!$E$2:$E$166,$B14,Data!$H$2:$H$166,$A14,Data!$Z$2:$Z$166,"Yes") | G14: {=_xlfn.STDEV.S(IF((Data!$E$2:$E$166=$B14)*(Data!$H$2:$H$166=$A14)*(Data!$Z$2:$Z$166="Yes")*ISNUMBER(Data!$AA$2:$AA$166),Data!$AA$2:$AA$166))} | H14: =AVERAGEIFS(Data!$AB$2:$AB$166,Data!$E$2:$E$166,$B14,Data!$H$2:$H$166,$A14,Data!$Z$2:$Z$166,"Yes") | I14: {=_xlfn.STDEV.S(IF((Data!$E$2:$E$166=$B14)*(Data!$H$2:$H$166=$A14)*(Data!$Z$2:$Z$166="Yes"),Data!$AB$2:$AB$166))} | J14: =AVERAGEIFS(Data!$R$2:$R$166,Data!$E$2:$E$166,$B14,Data!$H$2:$H$166,$A14,Data!$Z$2:$Z$166,"Yes")
A15: Shelf_Other | B15: POSM | C15: =COUNTIFS(Data!$E$2:$E$166,$B15,Data!$H$2:$H$166,$A15,Data!$Z$2:$Z$166,"Yes") | D15: =100*AVERAGEIFS(Data!$AC$2:$AC$166,Data!$E$2:$E$166,$B15,Data!$H$2:$H$166,$A15,Data!$Z$2:$Z$166,"Yes") | E15: =COUNTIFS(Data!$E$2:$E$166,$B15,Data!$H$2:$H$166,$A15,Data!$Z$2:$Z$166,"Yes",Data!$AA$2:$AA$166,">0") | F15: =AVERAGEIFS(Data!$AA$2:$AA$166,Data!$E$2:$E$166,$B15,Data!$H$2:$H$166,$A15,Data!$Z$2:$Z$166,"Yes") | G15: {=_xlfn.STDEV.S(IF((Data!$E$2:$E$166=$B15)*(Data!$H$2:$H$166=$A15)*(Data!$Z$2:$Z$166="Yes")*ISNUMBER(Data!$AA$2:$AA$166),Data!$AA$2:$AA$166))} | H15: =AVERAGEIFS(Data!$AB$2:$AB$166,Data!$E$2:$E$166,$B15,Data!$H$2:$H$166,$A15,Data!$Z$2:$Z$166,"Yes") | I15: {=_xlfn.STDEV.S(IF((Data!$E$2:$E$166=$B15)*(Data!$H$2:$H$166=$A15)*(Data!$Z$2:$Z$166="Yes"),Data!$AB$2:$AB$166))} | J15: =AVERAGEIFS(Data!$R$2:$R$166,Data!$E$2:$E$166,$B15,Data!$H$2:$H$166,$A15,Data!$Z$2:$Z$166,"Yes")
A17: Array formulas (columns G and I): Excel 365 evaluates them with Enter; Excel 2019 or older needs Ctrl+Shift+Enter after editing.
A19: Chart table: mean Dwell time (%) by AOI and condition
A20: AOI | B20: NoPOSM | C20: POSM
A21: Sensodyne_Products | B21: =H5 | C21: =H6
A22: Sensodyne_POSM_Wing | B22: 0 | C22: =H7
A23: Competitor_A | B23: =H8 | C23: =H9
A24: Competitor_B | B24: =H10 | C24: =H11
A25: Price_Tags | B25: =H12 | C25: =H13
A26: Shelf_Other | B26: =H14 | C26: =H15

Sheet Sensodyne
A1: Sensodyne_Products rows, kept respondents, sorted by condition (POSM first). SIMULATED data.
A2: In Excel: Data sheet > filter AOI Name = Sensodyne_Products and Keep = Yes > copy the visible rows here > sort by Group. T.TEST needs two blocks of numbers, so each condition must be contiguous.
A4: Respondent Name | B4: Group | C4: Valid data | D4: TTFF parent (ms) | E4: TTFF_s | F4: Dwell time (%) | G4: Dwell_pct_clean | H4: Fixation count | J4: Statistic | K4: Value | L4: Formula shown | M4: Note
A5: P01 | B5: POSM | C5: 93.8 | D5: 2356 | E5: =IF(ISNUMBER(D5),D5/1000,"") | F5: 18.07 | G5: =IF(ISNUMBER(F5),F5,0) | H5: 84 | J5: Welch t test and Cohen's d: TTFF_s to Sensodyne_Products
A6: P03 | B6: POSM | C6: 84.1 | D6: 2532 | E6: =IF(ISNUMBER(D6),D6/1000,"") | F6: 14.41 | G6: =IF(ISNUMBER(F6),F6,0) | H6: 64 | J6: POSM mean (s) | K6: =AVERAGE(E5:E18) | L6: AVERAGE(E5:E18) | M6: AVERAGE of the POSM block
A7: P05 | B7: POSM | C7: 81.3 | D7: 2784 | E7: =IF(ISNUMBER(D7),D7/1000,"") | F7: 17.57 | G7: =IF(ISNUMBER(F7),F7,0) | H7: 134 | J7: POSM SD (s) | K7: =_xlfn.STDEV.S(E5:E18) | L7: _xlfn.STDEV.S(E5:E18) | M7: STDEV.S = sample standard deviation
A8: P07 | B8: POSM | C8: 86.8 | D8: 1759 | E8: =IF(ISNUMBER(D8),D8/1000,"") | F8: 8.91 | G8: =IF(ISNUMBER(F8),F8,0) | H8: 61 | J8: POSM n | K8: =COUNT(E5:E18) | L8: COUNT(E5:E18) | M8: COUNT ignores blanks and text, so never fixated rows drop out
A9: P09 | B9: POSM | C9: 87 | D9: 1907 | E9: =IF(ISNUMBER(D9),D9/1000,"") | F9: 15.4 | G9: =IF(ISNUMBER(F9),F9,0) | H9: 70 | J9: NoPOSM mean (s) | K9: =AVERAGE(E19:E33) | L9: AVERAGE(E19:E33)
A10: P11 | B10: POSM | C10: 80.5 | D10: 1622 | E10: =IF(ISNUMBER(D10),D10/1000,"") | F10: 9.8 | G10: =IF(ISNUMBER(F10),F10,0) | H10: 72 | J10: NoPOSM SD (s) | K10: =_xlfn.STDEV.S(E19:E33) | L10: _xlfn.STDEV.S(E19:E33)
A11: P13 | B11: POSM | C11: 89.9 | D11: 1235 | E11: =IF(ISNUMBER(D11),D11/1000,"") | F11: 27.51 | G11: =IF(ISNUMBER(F11),F11,0) | H11: 125 | J11: NoPOSM n | K11: =COUNT(E19:E33) | L11: COUNT(E19:E33)
A12: P15 | B12: POSM | C12: 87.6 | D12: 3064 | E12: =IF(ISNUMBER(D12),D12/1000,"") | F12: 25.24 | G12: =IF(ISNUMBER(F12),F12,0) | H12: 124 | J12: Difference POSM minus NoPOSM (s) | K12: =K6-K9 | L12: K6-K9
A13: P19 | B13: POSM | C13: 86.1 | D13: 2773 | E13: =IF(ISNUMBER(D13),D13/1000,"") | F13: 19.73 | G13: =IF(ISNUMBER(F13),F13,0) | H13: 106 | J13: Welch t | K13: =(K6-K9)/SQRT(K7^2/K8+K10^2/K11) | L13: (K6-K9)/SQRT(K7^2/K8+K10^2/K11) | M13: t = (M1 - M2) / sqrt(s1^2/n1 + s2^2/n2)
A14: P21 | B14: POSM | C14: 93.8 | D14: 4292 | E14: =IF(ISNUMBER(D14),D14/1000,"") | F14: 14.2 | G14: =IF(ISNUMBER(F14),F14,0) | H14: 46 | J14: Welch df | K14: =(K7^2/K8+K10^2/K11)^2/((K7^2/K8)^2/(K8-1)+(K10^2/K11)^2/(K11-1)) | L14: (K7^2/K8+K10^2/K11)^2/((K7^2/K8)^2/(K8-1)+(K10^2/K11)^2/(K11-1)) | M14: Welch Satterthwaite degrees of freedom
A15: P23 | B15: POSM | C15: 90.2 | D15: 1356 | E15: =IF(ISNUMBER(D15),D15/1000,"") | F15: 27.18 | G15: =IF(ISNUMBER(F15),F15,0) | H15: 103 | J15: p, two tailed (T.TEST type 3) | K15: =_xlfn.T.TEST(E5:E18,E19:E33,2,3) | L15: _xlfn.T.TEST(E5:E18,E19:E33,2,3) | M15: tails = 2, type = 3 means unequal variances (Welch)
A16: P25 | B16: POSM | C16: 88.3 | D16: 2302 | E16: =IF(ISNUMBER(D16),D16/1000,"") | F16: 17.61 | G16: =IF(ISNUMBER(F16),F16,0) | H16: 48 | J16: p from the hand computed t | K16: =_xlfn.T.DIST.2T(ABS(K13),K14) | L16: _xlfn.T.DIST.2T(ABS(K13),K14) | M16: should match the T.TEST cell
A17: P27 | B17: POSM | C17: 85.1 | D17: 2487 | E17: =IF(ISNUMBER(D17),D17/1000,"") | F17: 17.16 | G17: =IF(ISNUMBER(F17),F17,0) | H17: 104 | J17: Pooled SD | K17: =SQRT(((K8-1)*K7^2+(K11-1)*K10^2)/(K8+K11-2)) | L17: SQRT(((K8-1)*K7^2+(K11-1)*K10^2)/(K8+K11-2)) | M17: sp = sqrt(((n1 - 1) s1^2 + (n2 - 1) s2^2) / (n1 + n2 - 2))
A18: P29 | B18: POSM | C18: 79.8 | D18: 1059 | E18: =IF(ISNUMBER(D18),D18/1000,"") | F18: 25.27 | G18: =IF(ISNUMBER(F18),F18,0) | H18: 97 | J18: Cohen's d | K18: =K12/K17 | L18: K12/K17 | M18: d = (M1 - M2) / sp
A19: P02 | B19: NoPOSM | C19: 77.5 | D19: 3254 | E19: =IF(ISNUMBER(D19),D19/1000,"") | F19: 21.73 | G19: =IF(ISNUMBER(F19),F19,0) | H19: 79 | J19: SE of d (approximation) | K19: =SQRT((K8+K11)/(K8*K11)+K18^2/(2*(K8+K11))) | L19: SQRT((K8+K11)/(K8*K11)+K18^2/(2*(K8+K11))) | M19: sqrt((n1 + n2) / (n1 n2) + d^2 / (2 (n1 + n2)))
A20: P04 | B20: NoPOSM | C20: 82 | D20: 3263 | E20: =IF(ISNUMBER(D20),D20/1000,"") | F20: 12.49 | G20: =IF(ISNUMBER(F20),F20,0) | H20: 54 | J20: d 95% CI lower | K20: =K18-1.96*K19 | L20: K18-1.96*K19 | M20: large sample approximation; R uses the noncentral t interval
A21: P06 | B21: NoPOSM | C21: 78 | D21: 3169 | E21: =IF(ISNUMBER(D21),D21/1000,"") | F21: 12.29 | G21: =IF(ISNUMBER(F21),F21,0) | H21: 72 | J21: d 95% CI upper | K21: =K18+1.96*K19 | L21: K18+1.96*K19
A22: P08 | B22: NoPOSM | C22: 93.6 | D22: 4860 | E22: =IF(ISNUMBER(D22),D22/1000,"") | F22: 14.06 | G22: =IF(ISNUMBER(F22),F22,0) | H22: 62
A23: P10 | B23: NoPOSM | C23: 87.4 | D23: 2393 | E23: =IF(ISNUMBER(D23),D23/1000,"") | F23: 6.99 | G23: =IF(ISNUMBER(F23),F23,0) | H23: 30 | J23: Welch t test and Cohen's d: Dwell time (%) on Sensodyne_Products
A24: P12 | B24: NoPOSM | C24: 74.6 | D24: 3320 | E24: =IF(ISNUMBER(D24),D24/1000,"") | F24: 8.21 | G24: =IF(ISNUMBER(F24),F24,0) | H24: 60 | J24: POSM mean (%) | K24: =AVERAGE(G5:G18) | L24: AVERAGE(G5:G18) | M24: AVERAGE of the POSM block
A25: P14 | B25: NoPOSM | C25: 95.5 | D25: 5872 | E25: =IF(ISNUMBER(D25),D25/1000,"") | F25: 10.14 | G25: =IF(ISNUMBER(F25),F25,0) | H25: 51 | J25: POSM SD (%) | K25: =_xlfn.STDEV.S(G5:G18) | L25: _xlfn.STDEV.S(G5:G18) | M25: STDEV.S = sample standard deviation
A26: P16 | B26: NoPOSM | C26: 77.1 | D26: 2521 | E26: =IF(ISNUMBER(D26),D26/1000,"") | F26: 6.09 | G26: =IF(ISNUMBER(F26),F26,0) | H26: 28 | J26: POSM n | K26: =COUNT(G5:G18) | L26: COUNT(G5:G18) | M26: never fixated rows count as 0 here
A27: P18 | B27: NoPOSM | C27: 84.6 | D27: 3837 | E27: =IF(ISNUMBER(D27),D27/1000,"") | F27: 5.79 | G27: =IF(ISNUMBER(F27),F27,0) | H27: 41 | J27: NoPOSM mean (%) | K27: =AVERAGE(G19:G33) | L27: AVERAGE(G19:G33)
A28: P20 | B28: NoPOSM | C28: 82.4 | D28: 2660 | E28: =IF(ISNUMBER(D28),D28/1000,"") | F28: 5.91 | G28: =IF(ISNUMBER(F28),F28,0) | H28: 30 | J28: NoPOSM SD (%) | K28: =_xlfn.STDEV.S(G19:G33) | L28: _xlfn.STDEV.S(G19:G33)
A29: P22 | B29: NoPOSM | C29: 81.7 | D29: 4373 | E29: =IF(ISNUMBER(D29),D29/1000,"") | F29: 12.66 | G29: =IF(ISNUMBER(F29),F29,0) | H29: 77 | J29: NoPOSM n | K29: =COUNT(G19:G33) | L29: COUNT(G19:G33)
A30: P24 | B30: NoPOSM | C30: 94.1 | D30: 4646 | E30: =IF(ISNUMBER(D30),D30/1000,"") | F30: 14.6 | G30: =IF(ISNUMBER(F30),F30,0) | H30: 103 | J30: Difference POSM minus NoPOSM (%) | K30: =K24-K27 | L30: K24-K27
A31: P26 | B31: NoPOSM | C31: 82.2 | D31: 3715 | E31: =IF(ISNUMBER(D31),D31/1000,"") | F31: 8.49 | G31: =IF(ISNUMBER(F31),F31,0) | H31: 44 | J31: Welch t | K31: =(K24-K27)/SQRT(K25^2/K26+K28^2/K29) | L31: (K24-K27)/SQRT(K25^2/K26+K28^2/K29) | M31: t = (M1 - M2) / sqrt(s1^2/n1 + s2^2/n2)
A32: P28 | B32: NoPOSM | C32: 91.5 | D32: 3280 | E32: =IF(ISNUMBER(D32),D32/1000,"") | F32: 7.6 | G32: =IF(ISNUMBER(F32),F32,0) | H32: 56 | J32: Welch df | K32: =(K25^2/K26+K28^2/K29)^2/((K25^2/K26)^2/(K26-1)+(K28^2/K29)^2/(K29-1)) | L32: (K25^2/K26+K28^2/K29)^2/((K25^2/K26)^2/(K26-1)+(K28^2/K29)^2/(K29-1)) | M32: Welch Satterthwaite degrees of freedom
A33: P30 | B33: NoPOSM | C33: 83.7 | D33: 2659 | E33: =IF(ISNUMBER(D33),D33/1000,"") | F33: 14.28 | G33: =IF(ISNUMBER(F33),F33,0) | H33: 70 | J33: p, two tailed (T.TEST type 3) | K33: =_xlfn.T.TEST(G5:G18,G19:G33,2,3) | L33: _xlfn.T.TEST(G5:G18,G19:G33,2,3) | M33: tails = 2, type = 3 means unequal variances (Welch)
J34: p from the hand computed t | K34: =_xlfn.T.DIST.2T(ABS(K31),K32) | L34: _xlfn.T.DIST.2T(ABS(K31),K32) | M34: should match the T.TEST cell
J35: Pooled SD | K35: =SQRT(((K26-1)*K25^2+(K29-1)*K28^2)/(K26+K29-2)) | L35: SQRT(((K26-1)*K25^2+(K29-1)*K28^2)/(K26+K29-2)) | M35: sp = sqrt(((n1 - 1) s1^2 + (n2 - 1) s2^2) / (n1 + n2 - 2))
J36: Cohen's d | K36: =K30/K35 | L36: K30/K35 | M36: d = (M1 - M2) / sp
J37: SE of d (approximation) | K37: =SQRT((K26+K29)/(K26*K29)+K36^2/(2*(K26+K29))) | L37: SQRT((K26+K29)/(K26*K29)+K36^2/(2*(K26+K29))) | M37: sqrt((n1 + n2) / (n1 n2) + d^2 / (2 (n1 + n2)))
J38: d 95% CI lower | K38: =K36-1.96*K37 | L38: K36-1.96*K37 | M38: large sample approximation; R uses the noncentral t interval
J39: d 95% CI upper | K39: =K36+1.96*K37 | L39: K36+1.96*K37
J42: Chart table: mean TTFF_s with 95% CI half width
J43: Condition | K43: Mean TTFF (s) | L43: CI half width
...

Sheet Survey
A1: Survey after the glasses came off, joined to Sensodyne dwell share. SIMULATED data.
A3: Study Name | B3: Respondent Name | C3: Group | D3: Purchase_intent_Sensodyne_1to7 | E3: Brand_recall_Sensodyne | F3: Product_chosen | G3: Keep | H3: Sensodyne dwell (%) | I3: PI if kept | K3: Statistic | L3: Value
A4: SIMULATED_ShelfStudy_POSM_vs_NoPOSM | B4: P01 | C4: POSM | D4: 5 | E4: Yes | F4: Other | G4: =IF(ISNA(MATCH(B4,Sensodyne!$A$5:$A$40,0)),"No","Yes") | H4: =IFERROR(INDEX(Sensodyne!$G$5:$G$40,MATCH(B4,Sensodyne!$A$5:$A$40,0)),"") | I4: =IF(G4="Yes",D4,"") | K4: Purchase intent, POSM mean | L4: =AVERAGE(I4:I18)
A5: SIMULATED_ShelfStudy_POSM_vs_NoPOSM | B5: P03 | C5: POSM | D5: 4 | E5: Yes | F5: Sensodyne | G5: =IF(ISNA(MATCH(B5,Sensodyne!$A$5:$A$40,0)),"No","Yes") | H5: =IFERROR(INDEX(Sensodyne!$G$5:$G$40,MATCH(B5,Sensodyne!$A$5:$A$40,0)),"") | I5: =IF(G5="Yes",D5,"") | K5: Purchase intent, POSM SD | L5: =_xlfn.STDEV.S(I4:I18)
A6: SIMULATED_ShelfStudy_POSM_vs_NoPOSM | B6: P05 | C6: POSM | D6: 5 | E6: Yes | F6: Other | G6: =IF(ISNA(MATCH(B6,Sensodyne!$A$5:$A$40,0)),"No","Yes") | H6: =IFERROR(INDEX(Sensodyne!$G$5:$G$40,MATCH(B6,Sensodyne!$A$5:$A$40,0)),"") | I6: =IF(G6="Yes",D6,"") | K6: Purchase intent, POSM n | L6: =COUNT(I4:I18)
A7: SIMULATED_ShelfStudy_POSM_vs_NoPOSM | B7: P07 | C7: POSM | D7: 3 | E7: No | F7: Other | G7: =IF(ISNA(MATCH(B7,Sensodyne!$A$5:$A$40,0)),"No","Yes") | H7: =IFERROR(INDEX(Sensodyne!$G$5:$G$40,MATCH(B7,Sensodyne!$A$5:$A$40,0)),"") | I7: =IF(G7="Yes",D7,"") | K7: Purchase intent, NoPOSM mean | L7: =AVERAGE(I19:I33)
A8: SIMULATED_ShelfStudy_POSM_vs_NoPOSM | B8: P09 | C8: POSM | D8: 5 | E8: Yes | F8: Competitor_A | G8: =IF(ISNA(MATCH(B8,Sensodyne!$A$5:$A$40,0)),"No","Yes") | H8: =IFERROR(INDEX(Sensodyne!$G$5:$G$40,MATCH(B8,Sensodyne!$A$5:$A$40,0)),"") | I8: =IF(G8="Yes",D8,"") | K8: Purchase intent, NoPOSM SD | L8: =_xlfn.STDEV.S(I19:I33)
A9: SIMULATED_ShelfStudy_POSM_vs_NoPOSM | B9: P11 | C9: POSM | D9: 4 | E9: No | F9: Competitor_B | G9: =IF(ISNA(MATCH(B9,Sensodyne!$A$5:$A$40,0)),"No","Yes") | H9: =IFERROR(INDEX(Sensodyne!$G$5:$G$40,MATCH(B9,Sensodyne!$A$5:$A$40,0)),"") | I9: =IF(G9="Yes",D9,"") | K9: Purchase intent, NoPOSM n | L9: =COUNT(I19:I33)
A10: SIMULATED_ShelfStudy_POSM_vs_NoPOSM | B10: P13 | C10: POSM | D10: 6 | E10: Yes | F10: Sensodyne | G10: =IF(ISNA(MATCH(B10,Sensodyne!$A$5:$A$40,0)),"No","Yes") | H10: =IFERROR(INDEX(Sensodyne!$G$5:$G$40,MATCH(B10,Sensodyne!$A$5:$A$40,0)),"") | I10: =IF(G10="Yes",D10,"") | K10: p, Welch T.TEST (2 tails, type 3) | L10: =_xlfn.T.TEST(I4:I18,I19:I33,2,3)
A11: SIMULATED_ShelfStudy_POSM_vs_NoPOSM | B11: P15 | C11: POSM | D11: 6 | E11: Yes | F11: Sensodyne | G11: =IF(ISNA(MATCH(B11,Sensodyne!$A$5:$A$40,0)),"No","Yes") | H11: =IFERROR(INDEX(Sensodyne!$G$5:$G$40,MATCH(B11,Sensodyne!$A$5:$A$40,0)),"") | I11: =IF(G11="Yes",D11,"") | K11: Cohen's d (pooled SD) | L11: =(L4-L7)/SQRT(((L6-1)*L5^2+(L9-1)*L8^2)/(L6+L9-2))
A12: SIMULATED_ShelfStudy_POSM_vs_NoPOSM | B12: P17 | C12: POSM | D12: 6 | E12: Yes | F12: Competitor_A | G12: =IF(ISNA(MATCH(B12,Sensodyne!$A$5:$A$40,0)),"No","Yes") | H12: =IFERROR(INDEX(Sensodyne!$G$5:$G$40,MATCH(B12,Sensodyne!$A$5:$A$40,0)),"") | I12: =IF(G12="Yes",D12,"") | K12: Brand recall Yes, POSM (count) | L12: =COUNTIFS(C4:C33,"POSM",E4:E33,"Yes",G4:G33,"Yes")
A13: SIMULATED_ShelfStudy_POSM_vs_NoPOSM | B13: P19 | C13: POSM | D13: 5 | E13: Yes | F13: Other | G13: =IF(ISNA(MATCH(B13,Sensodyne!$A$5:$A$40,0)),"No","Yes") | H13: =IFERROR(INDEX(Sensodyne!$G$5:$G$40,MATCH(B13,Sensodyne!$A$5:$A$40,0)),"") | I13: =IF(G13="Yes",D13,"") | K13: Brand recall Yes, NoPOSM (count) | L13: =COUNTIFS(C4:C33,"NoPOSM",E4:E33,"Yes",G4:G33,"Yes")
A14: SIMULATED_ShelfStudy_POSM_vs_NoPOSM | B14: P21 | C14: POSM | D14: 4 | E14: Yes | F14: Sensodyne | G14: =IF(ISNA(MATCH(B14,Sensodyne!$A$5:$A$40,0)),"No","Yes") | H14: =IFERROR(INDEX(Sensodyne!$G$5:$G$40,MATCH(B14,Sensodyne!$A$5:$A$40,0)),"") | I14: =IF(G14="Yes",D14,"") | K14: Chose Sensodyne, POSM (count) | L14: =COUNTIFS(C4:C33,"POSM",F4:F33,"Sensodyne",G4:G33,"Yes")
A15: SIMULATED_ShelfStudy_POSM_vs_NoPOSM | B15: P23 | C15: POSM | D15: 7 | E15: Yes | F15: Competitor_A | G15: =IF(ISNA(MATCH(B15,Sensodyne!$A$5:$A$40,0)),"No","Yes") | H15: =IFERROR(INDEX(Sensodyne!$G$5:$G$40,MATCH(B15,Sensodyne!$A$5:$A$40,0)),"") | I15: =IF(G15="Yes",D15,"") | K15: Chose Sensodyne, NoPOSM (count) | L15: =COUNTIFS(C4:C33,"NoPOSM",F4:F33,"Sensodyne",G4:G33,"Yes")
A16: SIMULATED_ShelfStudy_POSM_vs_NoPOSM | B16: P25 | C16: POSM | D16: 5 | E16: Yes | F16: Sensodyne | G16: =IF(ISNA(MATCH(B16,Sensodyne!$A$5:$A$40,0)),"No","Yes") | H16: =IFERROR(INDEX(Sensodyne!$G$5:$G$40,MATCH(B16,Sensodyne!$A$5:$A$40,0)),"") | I16: =IF(G16="Yes",D16,"") | K16: CORREL: Sensodyne dwell (%) with purchase intent (kept) | L16: =CORREL(H4:H33,I4:I33)
A17: SIMULATED_ShelfStudy_POSM_vs_NoPOSM | B17: P27 | C17: POSM | D17: 5 | E17: Yes | F17: Sensodyne | G17: =IF(ISNA(MATCH(B17,Sensodyne!$A$5:$A$40,0)),"No","Yes") | H17: =IFERROR(INDEX(Sensodyne!$G$5:$G$40,MATCH(B17,Sensodyne!$A$5:$A$40,0)),"") | I17: =IF(G17="Yes",D17,"")
A18: SIMULATED_ShelfStudy_POSM_vs_NoPOSM | B18: P29 | C18: POSM | D18: 4 | E18: Yes | F18: Sensodyne | G18: =IF(ISNA(MATCH(B18,Sensodyne!$A$5:$A$40,0)),"No","Yes") | H18: =IFERROR(INDEX(Sensodyne!$G$5:$G$40,MATCH(B18,Sensodyne!$A$5:$A$40,0)),"") | I18: =IF(G18="Yes",D18,"")
A19: SIMULATED_ShelfStudy_POSM_vs_NoPOSM | B19: P02 | C19: NoPOSM | D19: 4 | E19: Yes | F19: Sensodyne | G19: =IF(ISNA(MATCH(B19,Sensodyne!$A$5:$A$40,0)),"No","Yes") | H19: =IFERROR(INDEX(Sensodyne!$G$5:$G$40,MATCH(B19,Sensodyne!$A$5:$A$40,0)),"") | I19: =IF(G19="Yes",D19,"")
A20: SIMULATED_ShelfStudy_POSM_vs_NoPOSM | B20: P04 | C20: NoPOSM | D20: 5 | E20: No | F20: Competitor_A | G20: =IF(ISNA(MATCH(B20,Sensodyne!$A$5:$A$40,0)),"No","Yes") | H20: =IFERROR(INDEX(Sensodyne!$G$5:$G$40,MATCH(B20,Sensodyne!$A$5:$A$40,0)),"") | I20: =IF(G20="Yes",D20,"")
A21: SIMULATED_ShelfStudy_POSM_vs_NoPOSM | B21: P06 | C21: NoPOSM | D21: 4 | E21: Yes | F21: Competitor_A | G21: =IF(ISNA(MATCH(B21,Sensodyne!$A$5:$A$40,0)),"No","Yes") | H21: =IFERROR(INDEX(Sensodyne!$G$5:$G$40,MATCH(B21,Sensodyne!$A$5:$A$40,0)),"") | I21: =IF(G21="Yes",D21,"")
A22: SIMULATED_ShelfStudy_POSM_vs_NoPOSM | B22: P08 | C22: NoPOSM | D22: 6 | E22: Yes | F22: Competitor_B | G22: =IF(ISNA(MATCH(B22,Sensodyne!$A$5:$A$40,0)),"No","Yes") | H22: =IFERROR(INDEX(Sensodyne!$G$5:$G$40,MATCH(B22,Sensodyne!$A$5:$A$40,0)),"") | I22: =IF(G22="Yes",D22,"")
A23: SIMULATED_ShelfStudy_POSM_vs_NoPOSM | B23: P10 | C23: NoPOSM | D23: 3 | E23: No | F23: Competitor_A | G23: =IF(ISNA(MATCH(B23,Sensodyne!$A$5:$A$40,0)),"No","Yes") | H23: =IFERROR(INDEX(Sensodyne!$G$5:$G$40,MATCH(B23,Sensodyne!$A$5:$A$40,0)),"") | I23: =IF(G23="Yes",D23,"")
A24: SIMULATED_ShelfStudy_POSM_vs_NoPOSM | B24: P12 | C24: NoPOSM | D24: 6 | E24: Yes | F24: Competitor_B | G24: =IF(ISNA(MATCH(B24,Sensodyne!$A$5:$A$40,0)),"No","Yes") | H24: =IFERROR(INDEX(Sensodyne!$G$5:$G$40,MATCH(B24,Sensodyne!$A$5:$A$40,0)),"") | I24: =IF(G24="Yes",D24,"")
A25: SIMULATED_ShelfStudy_POSM_vs_NoPOSM | B25: P14 | C25: NoPOSM | D25: 4 | E25: No | F25: Sensodyne | G25: =IF(ISNA(MATCH(B25,Sensodyne!$A$5:$A$40,0)),"No","Yes") | H25: =IFERROR(INDEX(Sensodyne!$G$5:$G$40,MATCH(B25,Sensodyne!$A$5:$A$40,0)),"") | I25: =IF(G25="Yes",D25,"")
A26: SIMULATED_ShelfStudy_POSM_vs_NoPOSM | B26: P16 | C26: NoPOSM | D26: 4 | E26: No | F26: Other | G26: =IF(ISNA(MATCH(B26,Sensodyne!$A$5:$A$40,0)),"No","Yes") | H26: =IFERROR(INDEX(Sensodyne!$G$5:$G$40,MATCH(B26,Sensodyne!$A$5:$A$40,0)),"") | I26: =IF(G26="Yes",D26,"")
A27: SIMULATED_ShelfStudy_POSM_vs_NoPOSM | B27: P18 | C27: NoPOSM | D27: 2 | E27: No | F27: Competitor_B | G27: =IF(ISNA(MATCH(B27,Sensodyne!$A$5:$A$40,0)),"No","Yes") | H27: =IFERROR(INDEX(Sensodyne!$G$5:$G$40,MATCH(B27,Sensodyne!$A$5:$A$40,0)),"") | I27: =IF(G27="Yes",D27,"")
A28: SIMULATED_ShelfStudy_POSM_vs_NoPOSM | B28: P20 | C28: NoPOSM | D28: 6 | E28: No | F28: Competitor_A | G28: =IF(ISNA(MATCH(B28,Sensodyne!$A$5:$A$40,0)),"No","Yes") | H28: =IFERROR(INDEX(Sensodyne!$G$5:$G$40,MATCH(B28,Sensodyne!$A$5:$A$40,0)),"") | I28: =IF(G28="Yes",D28,"")
... A33: SIMULATED_ShelfStudy_POSM_vs_NoPOSM | B33: P30 | C33: NoPOSM | D33: 3 | E33: Yes | F33: Sensodyne | G33: =IF(ISNA(MATCH(B33,Sensodyne!$A$5:$A$40,0)),"No","Yes") | H33: =IFERROR(INDEX(Sensodyne!$G$5:$G$40,MATCH(B33,Sensodyne!$A$5:$A$40,0)),"") | I33: =IF(G33="Yes",D33,"")

Sheet Check
A1: Reference values from analysis.R (SIMULATED data). Your Excel formulas should match to rounding.
A3: comparison | B3: m_posm | C3: m_noposm | D3: t | E3: df | F3: p | G3: d | H3: d_ci_low | I3: d_ci_high
A4: TTFF Sensodyne_Products (s) | B4: 2.252 | C4: 3.588 | D4: -3.911 | E4: 26.888 | F4: 0.001 | G4: -1.446 | H4: -2.259 | I4: -0.613
A5: TTFF max. Sensodyne_Products (s) | B5: 2.252 | C5: 3.588 | D5: -3.911 | E5: 26.888 | F5: 0.001 | G5: -1.446 | H5: -2.259 | I5: -0.613
A6: Dwell time (%) Sensodyne_Products | B6: 18.433 | C6: 10.755 | D6: 3.908 | E6: 23.868 | F6: 0.001 | G6: 1.468 | H6: 0.631 | I6: 2.283
A7: Competitor dwell (s) | B7: 35.985 | C7: 49.326 | D7: -2.323 | E7: 26.946 | F7: 0.028 | G7: -0.86 | H7: -1.616 | I7: -0.089
A8: Purchase intent (1 to 7) | B8: 4.857 | C8: 4.133 | D8: 1.627 | E8: 25.946 | F8: 0.116 | G8: 0.599 | H8: -0.152 | I8: 1.341
A10: Note: R reports the Cohen's d interval from the noncentral t distribution (effectsize package);
A11: the Excel sheet uses the large sample approximation, so the CI limits differ a little while d itself matches.
A13: aoi | B13: condition | C13: n | D13: resp_ratio_pct | E13: n_ttff | F13: ttff_mean_s | G13: ttff_sd_s | H13: dwell_mean_pct | I13: dwell_sd_pct | J13: dwell_mean_s | K13: fix_mean | L13: fix_sd
A14: Competitor_A | B14: NoPOSM | C14: 15 | D14: 100 | E14: 15 | F14: 1.97 | G14: 0.52 | H14: 17.38 | I14: 5.74 | J14: 25.57 | K14: 91.53 | L14: 37.45
A15: Competitor_A | B15: POSM | C15: 14 | D15: 100 | E15: 14 | F15: 2.86 | G15: 0.8 | H15: 14.81 | I15: 3.76 | J15: 21.07 | K15: 75.86 | L15: 24.35
A16: Competitor_B | B16: NoPOSM | C16: 15 | D16: 93.3 | E16: 14 | F16: 3.94 | G16: 1.43 | H16: 15.88 | I16: 8.37 | J16: 23.76 | K16: 83.4 | L16: 53.81
A17: Competitor_B | B17: POSM | C17: 14 | D17: 92.9 | E17: 13 | F17: 5.24 | G17: 1.21 | H17: 10.57 | I17: 4.2 | J17: 14.92 | K17: 55.64 | L17: 30.54
A18: Price_Tags | B18: NoPOSM | C18: 15 | D18: 66.7 | E18: 10 | F18: 8.76 | G18: 3.18 | H18: 5.21 | I18: 4.24 | J18: 7.65 | K18: 30.2 | L18: 24.88
A19: Price_Tags | B19: POSM | C19: 14 | D19: 100 | E19: 14 | F19: 8.82 | G19: 2.51 | H19: 8.37 | I19: 3.17 | J19: 11.45 | K19: 41.5 | L19: 18.88
A20: Sensodyne_POSM_Wing | B20: POSM | C20: 14 | D20: 100 | E20: 14 | F20: 1.92 | G20: 0.7 | H20: 6.26 | I20: 3.01 | J20: 8.56 | K20: 31.5 | L20: 18.65
A21: Sensodyne_Products | B21: NoPOSM | C21: 15 | D21: 100 | E21: 15 | F21: 3.59 | G21: 0.98 | H21: 10.76 | I21: 4.42 | J21: 16 | K21: 57.13 | L21: 21.04
A22: Sensodyne_Products | B22: POSM | C22: 14 | D22: 100 | E22: 14 | F22: 2.25 | G22: 0.86 | H22: 18.43 | I22: 5.98 | J22: 25.19 | K22: 88.43 | L22: 29
A23: Shelf_Other | B23: NoPOSM | C23: 15 | D23: 93.3 | E23: 14 | F23: 1.32 | G23: 0.66 | H23: 13.16 | I23: 7.48 | J23: 19.26 | K23: 73.2 | L23: 36.17
A24: Shelf_Other | B24: POSM | C24: 14 | D24: 92.9 | E24: 13 | F24: 1.32 | G24: 0.49 | H24: 15.25 | I24: 7.42 | J24: 23.21 | K24: 89 | L24: 60.85
